Workbook

Sheet СВОД
B2: АПК (Глобине) | C2: =АПК!J71*1.2 -> 644252.89
B3: Генплан благоустрій (Глобине) | C3: ='Генплан благоустрій'!J41*1.2 -> 336232.46
B4: Генплан дорога СПК (Глобине) | C4: ='Генплан дорога СПК'!J22*1.2 -> 0
B5: Генплан підпірна стінка (Глобине) | C5: ='Генплан підпірна стінка'!J11*1.2 -> 0
B6: Глобине-2 | C6: ='Глобине-2'!J135*1.2 -> 28339.152
B7: Котельна (Глобине) | C7: =Котельна!J121*1.2 -> 3243406.8
B8: Насосна Градирня (Глобине) | C8: ='Насосна Градирня'!J8*1.2 -> 0
B9: Пожежений резервуар (Глобине) | C9: ='Пожежений резервуар'!J70*1.2 -> 572938.12
B10: Пункт фасування та зберігання в бігбегах (Глобине) | C10: ='в бігбегах'!J42*1.2 -> 191514.37
B11: Резервуар для зберігання розчинника(Глобине) | C11: ='зберігання розчинника'!J32*1.2 -> 385480.5
B12: СПК (Глобине) | C12: =СПК!J207*1.2 -> 6797585.4
B13: Транспортна галерея (Глобине) | C13: ='Транспортна галерея'!J14*1.2 -> 12242.34
B14: Цех екстракції (Глобине) | C14: ='Цех екстракції'!J323*1.2 -> 2423352.9
C15: =SUM(C2:C14) -> 14635345

Sheet АПК
A1: Період | B1: Документ | C1: Аналітика Дт | D1: Аналітика Кт | E1: Дебет | H1: Кредит | K1: Поточне сальдо
E2: Рахунок | H2: Рахунок
A3: 01.06.2025 | B3: Переміщення товарів ІБ00-000538 від 01.06.2025 23:13:40 Перемещение ТМЦ | C3: Обл. НДС Круг 10 (6,05- 3760 3пс/А240с) Надходження товарів і послуг ІБ00-001657 від 01.04.2025 11:00:00 АПК (Глобине) | D3: Обл. НДС Круг 10 (6,05- 3760 3пс/А240с) Надходження товарів і послуг ІБ00-001657 від 01.04.2025 11:00:00 Транспортна галерея (Глобине) | E3: 205 | F3: 4098.41 | H3: 205 | K3: Д | L3: 338019.27
A4: 01.06.2025 | B4: Переміщення товарів ІБ00-000539 від 01.06.2025 23:13:41 Перемещение ТМЦ | C4: Обл. НДС Прокат арматурний №14 мм А500С, 12 м Надходження товарів і послуг ІБ00-000546 від 14.02.2025 10:00:00 АПК (Глобине) | D4: Обл. НДС Прокат арматурний №14 мм А500С, 12 м Надходження товарів і послуг ІБ00-000546 від 14.02.2025 10:00:00 Пункт фасування та зберігання в бігбегах (Глобине) | E4: 205 | F4: 2557.5 | H4: 205 | K4: Д | L4: 340576.77
A5: 02.06.2025 | B5: Вимога-накладна ІБ00-000437 від 02.06.2025 00:00:00 Списаны ТМЦ | C5: Обл. НДС Виробничий (Глобине-2) Глобине-2 Прямі материальні виробничі витрати крім зворотніх відходів | D5: Обл. НДС Круг 10 (6,05- 3760 3пс/А240с) Надходження товарів і послуг ІБ00-001657 від 01.04.2025 11:00:00 АПК (Глобине) | E5: 231 | H5: 205 | I5: 4098.41 | K5: Д | L5: 336478.36
A6: 02.06.2025 | B6: Вимога-накладна ІБ00-000437 від 02.06.2025 00:00:00 Списаны ТМЦ | C6: Обл. НДС Виробничий (Глобине-2) Глобине-2 Прямі материальні виробничі витрати крім зворотніх відходів | D6: Обл. НДС Прокат арматурний №14 мм А500С, 12 м Надходження товарів і послуг ІБ00-000546 від 14.02.2025 10:00:00 АПК (Глобине) | E6: 231 | H6: 205 | I6: 2557.5 | K6: Д | L6: 333920.86
A7: 02.06.2025 | B7: Вимога-накладна ІБ00-000438 від 02.06.2025 10:37:22 Списаны ТМЦ | C7: Обл. НДС Виробничий (Глобине-2) Глобине-2 Прямі материальні виробничі витрати крім зворотніх відходів | D7: Обл. НДС Пенетрон Адмікс 18кг/мішок Надходження товарів і послуг ІБ00-001456 від 04.04.2025 11:00:00 АПК (Глобине) | E7: 231 | H7: 205 | I7: 84882.6 | K7: Д | L7: 249038.26
A8: 02.06.2025 | B8: Вимога-накладна ІБ00-000439 від 02.06.2025 10:40:51 Списаны ТМЦ | C8: Обл. НДС Виробничий (Глобине-2) Глобине-2 Прямі материальні виробничі витрати крім зворотніх відходів | D8: Обл. НДС Труба Дн 89*3 Надходження товарів і послуг ІБ00-002202 від 01.05.2025 11:00:00 АПК (Глобине) | E8: 231 | H8: 205 | I8: 308.44 | K8: Д | L8: 248729.82
A9: 02.06.2025 | B9: Вимога-накладна ІБ00-000439 від 02.06.2025 10:40:51 Списаны ТМЦ | C9: Обл. НДС Виробничий (Глобине-2) Глобине-2 Прямі материальні виробничі витрати крім зворотніх відходів | D9: Обл. НДС Труба 159*5.0мм Надходження товарів і послуг ІБ00-002202 від 01.05.2025 11:00:00 АПК (Глобине) | E9: 231 | H9: 205 | I9: 715.58 | K9: Д | L9: 248014.24
A10: 02.06.2025 | B10: Вимога-накладна ІБ00-000439 від 02.06.2025 10:40:51 Списаны ТМЦ | C10: Обл. НДС Виробничий (Глобине-2) Глобине-2 Прямі материальні виробничі витрати крім зворотніх відходів | D10: Обл. НДС Труба 426*10,0мм Надходження товарів і послуг ІБ00-002202 від 01.05.2025 11:00:00 АПК (Глобине) | E10: 231 | H10: 205 | I10: 7094.14 | K10: Д | L10: 240920.1
A11: 02.06.2025 | B11: Вимога-накладна ІБ00-000439 від 02.06.2025 10:40:51 Списаны ТМЦ | C11: Обл. НДС Виробничий (Глобине-2) Глобине-2 Прямі материальні виробничі витрати крім зворотніх відходів | D11: Обл. НДС Труба 377*10,0 Надходження товарів і послуг ІБ00-002202 від 01.05.2025 11:00:00 АПК (Глобине) | E11: 231 | H11: 205 | I11: 2801.67 | K11: Д | L11: 238118.43
A12: 02.06.2025 | B12: Надходження товарів і послуг ІБ00-002710 від 02.06.2025 11:00:00 Оприходованы ТМЦ | C12: Обл. НДС Пісок з відсіву дроблення щебеню фр. 0-5мм. Надходження товарів і послуг ІБ00-002710 від 02.06.2025 11:00:00 АПК (Глобине) | D12: Енергія Логістик ТОВ №28/10-2024 ВІД 28/10/24_Глобине-2 Рахунок на оплату постачальника ІБ00-002242 від 02.06.2025 17:51:01 | E12: 205 | F12: 1959.83 | H12: 631 | K12: Д | L12: 240078.26
A13: 06.06.2025 | B13: Надходження товарів і послуг ІБ00-002834 від 06.06.2025 11:00:00 Оприходованы ТМЦ | C13: Обл. НДС Арматура № 8 А500С, L=12000 мм Надходження товарів і послуг ІБ00-002834 від 06.06.2025 11:00:00 АПК (Глобине) | D13: МЕТІНВЕСТ-СМЦ ТОВ №1778403/01/2023-С от 11.01.2023 РАХУНКИ_Глобино-2 Рахунок на оплату постачальника ІБ00-002368 від 06.06.2025 18:22:52 | E13: 205 | F13: 14729.59 | H13: 631 | K13: Д | L13: 254807.85
A14: 06.06.2025 | B14: Надходження товарів і послуг ІБ00-003218 від 06.06.2025 11:00:00 Оприходованы ТМЦ | C14: Обл. НДС Щебінь 40-70 Надходження товарів і послуг ІБ00-003218 від 06.06.2025 11:00:00 АПК (Глобине) | D14: Венкрас Авто ПП Договір 05/09/2024 від 05.09.2024_Глобине-2 Рахунок на оплату постачальника ІБ00-002690 від 06.06.2025 18:23:25 | E14: 205 | F14: 8425.67 | H14: 631 | K14: Д | L14: 263233.52
A15: 12.06.2025 | B15: Переміщення товарів ІБ00-000585 від 12.06.2025 11:10:00 Перемещение ТМЦ | C15: Обл. НДС Пісок з відсіву дроблення щебеню фр. 0-5мм. Надходження товарів і послуг ІБ00-003170 від 12.06.2025 11:00:00 АПК (Глобине) | D15: Обл. НДС Пісок з відсіву дроблення щебеню фр. 0-5мм. Надходження товарів і послуг ІБ00-003170 від 12.06.2025 11:00:00 Глобине-2 | E15: 205 | F15: 3947.17 | H15: 205 | K15: Д | L15: 267180.69
A16: 13.06.2025 | B16: Переміщення товарів ІБ00-000587 від 13.06.2025 11:10:00 Перемещение ТМЦ | C16: Обл. НДС Пісок з відсіву дроблення щебеню фр. 0-5мм. Надходження товарів і послуг ІБ00-003172 від 13.06.2025 11:00:00 АПК (Глобине) | D16: Обл. НДС Пісок з відсіву дроблення щебеню фр. 0-5мм. Надходження товарів і послуг ІБ00-003172 від 13.06.2025 11:00:00 Глобине-2 | E16: 205 | F16: 3930.66 | H16: 205 | K16: Д | L16: 271111.35
A17: 16.06.2025 | B17: Переміщення товарів ІБ00-000588 від 16.06.2025 11:10:00 Перемещение ТМЦ | C17: Обл. НДС Пісок з відсіву дроблення щебеню фр. 0-5мм. Надходження товарів і послуг ІБ00-003174 від 16.06.2025 11:00:00 АПК (Глобине) | D17: Обл. НДС Пісок з відсіву дроблення щебеню фр. 0-5мм. Надходження товарів і послуг ІБ00-003174 від 16.06.2025 11:00:00 Глобине-2 | E17: 205 | F17: 4218.5 | H17: 205 | K17: Д | L17: 275329.85
A18: 16.06.2025 | B18: Переміщення товарів ІБ00-000555 від 16.06.2025 11:15:00 Перемещение ТМЦ | C18: Обл. НДС Бетон С20/25 W6 F75 P4 Надходження товарів і послуг ІБ00-002956 від 16.06.2025 11:00:00 АПК (Глобине) | D18: Обл. НДС Бетон С20/25 W6 F75 P4 Надходження товарів і послуг ІБ00-002956 від 16.06.2025 11:00:00 Глобине-2 | E18: 205 | F18: 284497.52 | H18: 205 | K18: Д | L18: 559827.37
A19: 19.06.2025 | B19: Вимога-накладна ІБ00-000455 від 19.06.2025 10:28:26 Списаны ТМЦ | C19: Обл. НДС Виробничий (Глобине-2) Глобине-2 Прямі материальні виробничі витрати крім зворотніх відходів | D19: Обл. НДС Бетон С20/25 W6 F75 P4 Надходження товарів і послуг ІБ00-002451 від 26.05.2025 11:00:00 АПК (Глобине) | E19: 231 | H19: 205 | I19: 33111.63 | K19: Д | L19: 526715.74
A20: 19.06.2025 | B20: Вимога-накладна ІБ00-000455 від 19.06.2025 10:28:26 Списаны ТМЦ | C20: Обл. НДС Виробничий (Глобине-2) Глобине-2 Прямі материальні виробничі витрати крім зворотніх відходів | D20: Обл. НДС Бетон С20/25 W6 F75 P4 Надходження товарів і послуг ІБ00-002956 від 16.06.2025 11:00:00 АПК (Глобине) | E20: 231 | H20: 205 | I20: 6588.76 | K20: Д | L20: 520126.98
A21: 19.06.2025 | B21: Вимога-накладна ІБ00-000455 від 19.06.2025 10:28:26 Списаны ТМЦ | C21: Обл. НДС Виробничий (Глобине-2) Глобине-2 Прямі материальні виробничі витрати крім зворотніх відходів | D21: Обл. НДС Кутик 100*100*7мм ст. 3Пс МІРА Надходження товарів і послуг ІБ00-000851 від 03.03.2025 18:09:07 АПК (Глобине) | E21: 231 | H21: 205 | I21: 1936.67 | K21: Д | L21: 518190.31
A22: 19.06.2025 | B22: Вимога-накладна ІБ00-000455 від 19.06.2025 10:28:26 Списаны ТМЦ | C22: Обл. НДС Виробничий (Глобине-2) Глобине-2 Прямі материальні виробничі витрати крім зворотніх відходів | D22: Обл. НДС Труба 219*6 Надходження товарів і послуг ІБ00-002202 від 01.05.2025 11:00:00 АПК (Глобине) | E22: 231 | H22: 205 | I22: 588.09 | K22: Д | L22: 517602.22
A23: 19.06.2025 | B23: Переміщення товарів ІБ00-000570 від 19.06.2025 11:10:00 Перемещение ТМЦ | C23: Обл. НДС Бетон С 8/10 Р4 Надходження товарів і послуг ІБ00-003063 від 19.06.2025 11:00:00 АПК (Глобине) | D23: Обл. НДС Бетон С 8/10 Р4 Надходження товарів і послуг ІБ00-003063 від 19.06.2025 11:00:00 Глобине-2 | E23: 205 | F23: 15695.99 | H23: 205 | K23: Д | L23: 533298.21
A24: 20.06.2025 | B24: Переміщення товарів ІБ00-000576 від 20.06.2025 10:00:00 Перемещение ТМЦ | C24: Обл. НДС Бетон С20/25 W6 F75 P4 Надходження товарів і послуг ІБ00-002806 від 09.06.2025 11:00:00 АПК (Глобине) | D24: Обл. НДС Бетон С20/25 W6 F75 P4 Надходження товарів і послуг ІБ00-002806 від 09.06.2025 11:00:00 Пожежений резервуар (Глобине) | E24: 205 | F24: 10290.93 | H24: 205 | K24: Д | L24: 543589.14
A25: 20.06.2025 | B25: Переміщення товарів ІБ00-000576 від 20.06.2025 10:00:00 Перемещение ТМЦ | C25: Обл. НДС Пенетрон Адмікс 18кг/мішок/відро Надходження товарів і послуг ІБ00-001895 від 30.04.2025 11:00:00 АПК (Глобине) | D25: Обл. НДС Пенетрон Адмікс 18кг/мішок/відро Надходження товарів і послуг ІБ00-001895 від 30.04.2025 11:00:00 Пожежений резервуар (Глобине) | E25: 205 | F25: 4218.75 | H25: 205 | K25: Д | L25: 547807.89
A26: 20.06.2025 | B26: Переміщення товарів ІБ00-000576 від 20.06.2025 10:00:00 Перемещение ТМЦ | C26: Обл. НДС Шнур бентонітовий ГІДРОСТОП 15*25 Надходження товарів і послуг ІБ00-002192 від 01.05.2025 11:00:00 АПК (Глобине) | D26: Обл. НДС Шнур бентонітовий ГІДРОСТОП 15*25 Надходження товарів і послуг ІБ00-002192 від 01.05.2025 11:00:00 Пожежений резервуар (Глобине) | E26: 205 | F26: 4051.96 | H26: 205 | K26: Д | L26: 551859.85
A27: 20.06.2025 | B27: Переміщення товарів ІБ00-000576 від 20.06.2025 10:00:00 Перемещение ТМЦ | C27: Обл. НДС Профіль кріпильний 25*15мм Надходження товарів і послуг ІБ00-002192 від 01.05.2025 11:00:00 АПК (Глобине) | D27: Обл. НДС Профіль кріпильний 25*15мм Надходження товарів і послуг ІБ00-002192 від 01.05.2025 11:00:00 Пожежений резервуар (Глобине) | E27: 205 | F27: 826.01 | H27: 205 | K27: Д | L27: 552685.86
A28: 20.06.2025 | B28: Переміщення товарів ІБ00-000577 від 20.06.2025 10:00:00 Перемещение ТМЦ | C28: Обл. НДС Пісок з відсіву дроблення щебеню фр. 0-5мм. Надходження товарів і послуг ІБ00-002856 від 10.06.2025 11:00:00 АПК (Глобине) | D28: Обл. НДС Пісок з відсіву дроблення щебеню фр. 0-5мм. Надходження товарів і послуг ІБ00-002856 від 10.06.2025 11:00:00 Пункт фасування та зберігання в бігбегах (Глобине) | E28: 205 | F28: 2918.67 | H28: 205 | K28: Д | L28: 555604.53
A29: 20.06.2025 | B29: Переміщення товарів ІБ00-000578 від 20.06.2025 10:00:00 Перемещение ТМЦ | C29: Обл. НДС Пенебар SW-55 тип А 5м/рул Надходження товарів і послуг ІБ00-000649 від 17.02.2025 23:45:08 АПК (Глобине) | D29: Обл. НДС Пенебар SW-55 тип А 5м/рул Надходження товарів і послуг ІБ00-000649 від 17.02.2025 23:45:08 Резервуар для зберігання розчинника(Глобине) | E29: 205 | F29: 1187.5 | H29: 205 | K29: Д | L29: 556792.03
A30: 20.06.2025 | B30: Переміщення товарів ІБ00-000582 від 20.06.2025 10:00:00 Перемещение ТМЦ | C30: Обл. НДС Емульсія бітумна Igoflex-101 каністра 32л Надходження товарів і послуг ІБ00-001108 від 22.03.2024 17:34:05 Пункт фасування та зберігання в бігбегах (Глобине) | D30: Обл. НДС Емульсія бітумна Igoflex-101 каністра 32л Надходження товарів і послуг ІБ00-001108 від 22.03.2024 17:34:05 АПК (Глобине) | E30: 205 | H30: 205 | I30: 36573.95 | K30: Д | L30: 520218.08
A31: 20.06.2025 | B31: Надходження товарів і послуг ІБ00-003138 від 20.06.2025 11:00:00 Оприходованы ТМЦ | C31: Обл. НДС Шпонка гідроізоляційна ПО-2 20пог/м Надходження товарів і послуг ІБ00-003138 від 20.06.2025 11:00:00 АПК (Глобине) | D31: ПРОТЕКС УКРАЇНА Договір 9 від 11.12.2023_Глобине 2 Рахунок на оплату постачальника ІБ00-002600 від 20.06.2025 18:06:46 | E31: 205 | F31: 6500 | H31: 631 | K31: Д | L31: 526718.08
A32: 20.06.2025 | B32: Надходження товарів і послуг ІБ00-003138 від 20.06.2025 11:00:00 Оприходованы ТМЦ | C32: Обл. НДС Герметик поліуритановий 600 мл Надходження товарів і послуг ІБ00-003138 від 20.06.2025 11:00:00 АПК (Глобине) | D32: ПРОТЕКС УКРАЇНА Договір 9 від 11.12.2023_Глобине 2 Рахунок на оплату постачальника ІБ00-002600 від 20.06.2025 18:06:46 | E32: 205 | F32: 1412.5 | H32: 631 | K32: Д | L32: 528130.58
A33: 20.06.2025 | B33: Вимога-накладна ІБ00-000486 від 20.06.2025 18:07:02 Списаны ТМЦ | C33: Обл. НДС Виробничий (Глобине-2) Глобине-2 Прямі материальні виробничі витрати крім зворотніх відходів | D33: Обл. НДС Бетон С20/25 W6 F75 P4 Надходження товарів і послуг ІБ00-002806 від 09.06.2025 11:00:00 АПК (Глобине) | E33: 231 | H33: 205 | I33: 10290.93 | K33: Д | L33: 517839.65
A34: 20.06.2025 | B34: Вимога-накладна ІБ00-000486 від 20.06.2025 18:07:02 Списаны ТМЦ | C34: Обл. НДС Виробничий (Глобине-2) Глобине-2 Прямі материальні виробничі витрати крім зворотніх відходів | D34: Обл. НДС Бетон С20/25 W6 F75 P4 Надходження товарів і послуг ІБ00-002956 від 16.06.2025 11:00:00 АПК (Глобине) | E34: 231 | H34: 205 | I34: 267549.55 | K34: Д | L34: 250290.1
A35: 20.06.2025 | B35: Вимога-накладна ІБ00-000486 від 20.06.2025 18:07:02 Списаны ТМЦ | C35: Обл. НДС Виробничий (Глобине-2) Глобине-2 Прямі материальні виробничі витрати крім зворотніх відходів | D35: Обл. НДС Бетон С20/25 W6 F75 P4 Надходження товарів і послуг ІБ00-002956 від 16.06.2025 11:00:00 АПК (Глобине) | E35: 231 | H35: 205 | I35: 10359.21 | K35: Д | L35: 239930.89
A36: 20.06.2025 | B36: Вимога-накладна ІБ00-000486 від 20.06.2025 18:07:02 Списаны ТМЦ | C36: Обл. НДС Виробничий (Глобине-2) Глобине-2 Прямі материальні виробничі витрати крім зворотніх відходів | D36: Обл. НДС Плівка п/е рукав 1500*200 мкм Надходження товарів і послуг ІБ00-001528 від 26.03.2025 11:00:00 АПК (Глобине) | E36: 231 | H36: 205 | I36: 786.62 | K36: Д | L36: 239144.27
A37: 20.06.2025 | B37: Вимога-накладна ІБ00-000486 від 20.06.2025 18:07:02 Списаны ТМЦ | C37: Обл. НДС Виробничий (Глобине-2) Глобине-2 Прямі материальні виробничі витрати крім зворотніх відходів | D37: Обл. НДС Пенетрон Адмікс 18кг/мішок Надходження товарів і послуг ІБ00-001456 від 04.04.2025 11:00:00 АПК (Глобине) | E37: 231 | H37: 205 | I37: 43817.4 | K37: Д | L37: 195326.87
A38: 20.06.2025 | B38: Вимога-накладна ІБ00-000486 від 20.06.2025 18:07:02 Списаны ТМЦ | C38: Обл. НДС Виробничий (Глобине-2) Глобине-2 Прямі материальні виробничі витрати крім зворотніх відходів | D38: Обл. НДС Пенетрон Адмікс 18кг/мішок/відро Надходження товарів і послуг ІБ00-001895 від 30.04.2025 11:00:00 АПК (Глобине) | E38: 231 | H38: 205 | I38: 3840.75 | K38: Д | L38: 191486.12
A39: 20.06.2025 | B39: Вимога-накладна ІБ00-000486 від 20.06.2025 18:07:02 Списаны ТМЦ | C39: Обл. НДС Виробничий (Глобине-2) Глобине-2 Прямі материальні виробничі витрати крім зворотніх відходів | D39: Обл. НДС Пенетрон Адмікс 18кг/мішок/відро Надходження товарів і послуг ІБ00-001895 від 30.04.2025 11:00:00 АПК (Глобине) | E39: 231 | H39: 205 | I39: 4218.75 | K39: Д | L39: 187267.37
A40: 20.06.2025 | B40: Вимога-накладна ІБ00-000486 від 20.06.2025 18:07:02 Списаны ТМЦ | C40: Обл. НДС Виробничий (Глобине-2) Глобине-2 Прямі материальні виробничі витрати крім зворотніх відходів | D40: Обл. НДС Шнур бентонітовий ГІДРОСТОП 15*25 Надходження товарів і послуг ІБ00-002184 від 01.05.2025 11:00:00 АПК (Глобине) | E40: 231 | H40: 205 | I40: 7179.91 | K40: Д | L40: 180087.46
...

Sheet Генплан благоустрій
A1: Період | B1: Документ | C1: Аналітика Дт | D1: Аналітика Кт | E1: Дебет | H1: Кредит | K1: Поточне сальдо
E2: Рахунок | H2: Рахунок
A3: 18.06.2025 | B3: Переміщення товарів ІБ00-000563 від 18.06.2025 10:08:38 Перемещение ТМЦ | C3: Обл. НДС Пісок з відсіву дроблення щебеню фр. 0-5мм. Надходження товарів і послуг ІБ00-002156 від 09.05.2025 11:00:00 Генплан благоустрій (Глобине) | D3: Обл. НДС Пісок з відсіву дроблення щебеню фр. 0-5мм. Надходження товарів і послуг ІБ00-002156 від 09.05.2025 11:00:00 Генплан дорога СПК (Глобине) | E3: 205 | F3: 6729.25 | H3: 205 | K3: Д | L3: 6729.25
A4: 18.06.2025 | B4: Переміщення товарів ІБ00-000563 від 18.06.2025 10:08:38 Перемещение ТМЦ | C4: Обл. НДС Пісок з відсіву дроблення щебеню фр. 0-5мм. Надходження товарів і послуг ІБ00-002222 від 14.05.2025 11:00:00 Генплан благоустрій (Глобине) | D4: Обл. НДС Пісок з відсіву дроблення щебеню фр. 0-5мм. Надходження товарів і послуг ІБ00-002222 від 14.05.2025 11:00:00 Генплан дорога СПК (Глобине) | E4: 205 | F4: 1871.83 | H4: 205 | K4: Д | L4: 8601.08
A5: 18.06.2025 | B5: Переміщення товарів ІБ00-000563 від 18.06.2025 10:08:38 Перемещение ТМЦ | C5: Обл. НДС Пісок з відсіву дроблення щебеню фр. 0-5мм. Надходження товарів і послуг ІБ00-002305 від 19.05.2025 11:00:00 Генплан благоустрій (Глобине) | D5: Обл. НДС Пісок з відсіву дроблення щебеню фр. 0-5мм. Надходження товарів і послуг ІБ00-002305 від 19.05.2025 11:00:00 Генплан дорога СПК (Глобине) | E5: 205 | F5: 7555.17 | H5: 205 | K5: Д | L5: 16156.25
A6: 18.06.2025 | B6: Переміщення товарів ІБ00-000563 від 18.06.2025 10:08:38 Перемещение ТМЦ | C6: Обл. НДС Пісок з відсіву дроблення щебеню фр. 0-5мм. Надходження товарів і послуг ІБ00-002508 від 21.05.2025 11:00:00 Генплан благоустрій (Глобине) | D6: Обл. НДС Пісок з відсіву дроблення щебеню фр. 0-5мм. Надходження товарів і послуг ІБ00-002508 від 21.05.2025 11:00:00 Генплан дорога СПК (Глобине) | E6: 205 | F6: 7991.5 | H6: 205 | K6: Д | L6: 24147.75
A7: 18.06.2025 | B7: Переміщення товарів ІБ00-000563 від 18.06.2025 10:08:38 Перемещение ТМЦ | C7: Обл. НДС Пісок з відсіву дроблення щебеню фр. 0-5мм. Надходження товарів і послуг ІБ00-002716 від 22.05.2025 11:00:00 Генплан благоустрій (Глобине) | D7: Обл. НДС Пісок з відсіву дроблення щебеню фр. 0-5мм. Надходження товарів і послуг ІБ00-002716 від 22.05.2025 11:00:00 Генплан дорога СПК (Глобине) | E7: 205 | F7: 1904.83 | H7: 205 | K7: Д | L7: 26052.58
A8: 18.06.2025 | B8: Переміщення товарів ІБ00-000563 від 18.06.2025 10:08:38 Перемещение ТМЦ | C8: Обл. НДС Пісок з відсіву дроблення щебеню фр. 0-5мм. Надходження товарів і послуг ІБ00-002712 від 28.05.2025 11:00:00 Генплан благоустрій (Глобине) | D8: Обл. НДС Пісок з відсіву дроблення щебеню фр. 0-5мм. Надходження товарів і послуг ІБ00-002712 від 28.05.2025 11:00:00 Генплан дорога СПК (Глобине) | E8: 205 | F8: 5985.84 | H8: 205 | K8: Д | L8: 32038.42
A9: 18.06.2025 | B9: Переміщення товарів ІБ00-000563 від 18.06.2025 10:08:38 Перемещение ТМЦ | C9: Обл. НДС Пісок з відсіву дроблення щебеню фр. 0-5мм. Надходження товарів і послуг ІБ00-002713 від 29.05.2025 11:00:00 Генплан благоустрій (Глобине) | D9: Обл. НДС Пісок з відсіву дроблення щебеню фр. 0-5мм. Надходження товарів і послуг ІБ00-002713 від 29.05.2025 11:00:00 Генплан дорога СПК (Глобине) | E9: 205 | F9: 7921.83 | H9: 205 | K9: Д | L9: 39960.25
A10: 18.06.2025 | B10: Переміщення товарів ІБ00-000563 від 18.06.2025 10:08:38 Перемещение ТМЦ | C10: Обл. НДС Пісок з відсіву дроблення щебеню фр. 0-5мм. Надходження товарів і послуг ІБ00-002715 від 30.05.2025 11:00:00 Генплан благоустрій (Глобине) | D10: Обл. НДС Пісок з відсіву дроблення щебеню фр. 0-5мм. Надходження товарів і послуг ІБ00-002715 від 30.05.2025 11:00:00 Генплан дорога СПК (Глобине) | E10: 205 | F10: 932.89 | H10: 205 | K10: Д | L10: 40893.14
A11: 18.06.2025 | B11: Переміщення товарів ІБ00-000563 від 18.06.2025 10:08:38 Перемещение ТМЦ | C11: Обл. НДС Щебенево-піщана суміш фр 0-70 мм Надходження товарів і послуг ІБ00-002716 від 22.05.2025 11:00:00 Генплан благоустрій (Глобине) | D11: Обл. НДС Щебенево-піщана суміш фр 0-70 мм Надходження товарів і послуг ІБ00-002716 від 22.05.2025 11:00:00 Генплан дорога СПК (Глобине) | E11: 205 | F11: 5738.67 | H11: 205 | K11: Д | L11: 46631.81
A12: 18.06.2025 | B12: Переміщення товарів ІБ00-000563 від 18.06.2025 10:08:38 Перемещение ТМЦ | C12: Обл. НДС Щебенево-піщана суміш фр 0-70 мм Надходження товарів і послуг ІБ00-002708 від 26.05.2025 11:00:00 Генплан благоустрій (Глобине) | D12: Обл. НДС Щебенево-піщана суміш фр 0-70 мм Надходження товарів і послуг ІБ00-002708 від 26.05.2025 11:00:00 Генплан дорога СПК (Глобине) | E12: 205 | F12: 5941.33 | H12: 205 | K12: Д | L12: 52573.14
A13: 18.06.2025 | B13: Переміщення товарів ІБ00-000563 від 18.06.2025 10:08:38 Перемещение ТМЦ | C13: Обл. НДС Щебнево-пісчана суміш фр.0-70 мм Надходження товарів і послуг ІБ00-002633 від 24.05.2025 11:00:00 Генплан благоустрій (Глобине) | D13: Обл. НДС Щебнево-пісчана суміш фр.0-70 мм Надходження товарів і послуг ІБ00-002633 від 24.05.2025 11:00:00 Генплан дорога СПК (Глобине) | E13: 205 | F13: 11621.33 | H13: 205 | K13: Д | L13: 64194.47
A14: 18.06.2025 | B14: Переміщення товарів ІБ00-000563 від 18.06.2025 10:08:38 Перемещение ТМЦ | C14: Обл. НДС Геотекстиль термоскріплений F-50 300г/м.кв (шир. 5 м) Надходження товарів і послуг ІБ00-000821 від 03.03.2025 18:09:02 Генплан благоустрій (Глобине) | D14: Обл. НДС Геотекстиль термоскріплений F-50 300г/м.кв (шир. 5 м) Надходження товарів і послуг ІБ00-000821 від 03.03.2025 18:09:02 Генплан дорога СПК (Глобине) | E14: 205 | F14: 115686.08 | H14: 205 | K14: Д | L14: 179880.55
... A18: 18.06.2025 | B18: Переміщення товарів ІБ00-000564 від 18.06.2025 18:22:45 Перемещение ТМЦ | C18: Обл. НДС Щебенево-піщана суміш фр 0-70 мм Надходження товарів і послуг ІБ00-002968 від 01.06.2025 11:00:00 Генплан благоустрій (Глобине) | D18: Обл. НДС Щебенево-піщана суміш фр 0-70 мм Надходження товарів і послуг ІБ00-002968 від 01.06.2025 11:00:00 СПК (Глобине) | E18: 205 | F18: 12147 | H18: 205 | K18: Д | L18: 280193.72
A19: 19.06.2025 | B19: Вимога-накладна ІБ00-000453 від 19.06.2025 10:04:50 Списаны ТМЦ | C19: Обл. НДС Виробничий (Глобине-2) Глобине-2 Прямі материальні виробничі витрати крім зворотніх відходів | D19: Обл. НДС Пісок з відсіву дроблення щебеню фр. 0-5мм. Надходження товарів і послуг ІБ00-002156 від 09.05.2025 11:00:00 Генплан благоустрій (Глобине) | E19: 231 | H19: 205 | I19: 6729.25 | K19: Д | L19: 273464.47
A20: 19.06.2025 | B20: Вимога-накладна ІБ00-000453 від 19.06.2025 10:04:50 Списаны ТМЦ | C20: Обл. НДС Виробничий (Глобине-2) Глобине-2 Прямі материальні виробничі витрати крім зворотніх відходів | D20: Обл. НДС Пісок з відсіву дроблення щебеню фр. 0-5мм. Надходження товарів і послуг ІБ00-002222 від 14.05.2025 11:00:00 Генплан благоустрій (Глобине) | E20: 231 | H20: 205 | I20: 1871.83 | K20: Д | L20: 271592.64
A21: 19.06.2025 | B21: Вимога-накладна ІБ00-000453 від 19.06.2025 10:04:50 Списаны ТМЦ | C21: Обл. НДС Виробничий (Глобине-2) Глобине-2 Прямі материальні виробничі витрати крім зворотніх відходів | D21: Обл. НДС Пісок з відсіву дроблення щебеню фр. 0-5мм. Надходження товарів і послуг ІБ00-002305 від 19.05.2025 11:00:00 Генплан благоустрій (Глобине) | E21: 231 | H21: 205 | I21: 7555.17 | K21: Д | L21: 264037.47
A22: 19.06.2025 | B22: Вимога-накладна ІБ00-000453 від 19.06.2025 10:04:50 Списаны ТМЦ | C22: Обл. НДС Виробничий (Глобине-2) Глобине-2 Прямі материальні виробничі витрати крім зворотніх відходів | D22: Обл. НДС Пісок з відсіву дроблення щебеню фр. 0-5мм. Надходження товарів і послуг ІБ00-002508 від 21.05.2025 11:00:00 Генплан благоустрій (Глобине) | E22: 231 | H22: 205 | I22: 7991.5 | K22: Д | L22: 256045.97
A23: 19.06.2025 | B23: Вимога-накладна ІБ00-000453 від 19.06.2025 10:04:50 Списаны ТМЦ | C23: Обл. НДС Виробничий (Глобине-2) Глобине-2 Прямі материальні виробничі витрати крім зворотніх відходів | D23: Обл. НДС Пісок з відсіву дроблення щебеню фр. 0-5мм. Надходження товарів і послуг ІБ00-002716 від 22.05.2025 11:00:00 Генплан благоустрій (Глобине) | E23: 231 | H23: 205 | I23: 1904.83 | K23: Д | L23: 254141.14
A24: 19.06.2025 | B24: Вимога-накладна ІБ00-000453 від 19.06.2025 10:04:50 Списаны ТМЦ | C24: Обл. НДС Виробничий (Глобине-2) Глобине-2 Прямі материальні виробничі витрати крім зворотніх відходів | D24: Обл. НДС Пісок з відсіву дроблення щебеню фр. 0-5мм. Надходження товарів і послуг ІБ00-002712 від 28.05.2025 11:00:00 Генплан благоустрій (Глобине) | E24: 231 | H24: 205 | I24: 5985.84 | K24: Д | L24: 248155.3
A25: 19.06.2025 | B25: Вимога-накладна ІБ00-000453 від 19.06.2025 10:04:50 Списаны ТМЦ | C25: Обл. НДС Виробничий (Глобине-2) Глобине-2 Прямі материальні виробничі витрати крім зворотніх відходів | D25: Обл. НДС Пісок з відсіву дроблення щебеню фр. 0-5мм. Надходження товарів і послуг ІБ00-002713 від 29.05.2025 11:00:00 Генплан благоустрій (Глобине) | E25: 231 | H25: 205 | I25: 7921.83 | K25: Д | L25: 240233.47
A26: 19.06.2025 | B26: Вимога-накладна ІБ00-000453 від 19.06.2025 10:04:50 Списаны ТМЦ | C26: Обл. НДС Виробничий (Глобине-2) Глобине-2 Прямі материальні виробничі витрати крім зворотніх відходів | D26: Обл. НДС Пісок з відсіву дроблення щебеню фр. 0-5мм. Надходження товарів і послуг ІБ00-002715 від 30.05.2025 11:00:00 Генплан благоустрій (Глобине) | E26: 231 | H26: 205 | I26: 932.89 | K26: Д | L26: 239300.58
A27: 19.06.2025 | B27: Вимога-накладна ІБ00-000453 від 19.06.2025 10:04:50 Списаны ТМЦ | C27: Обл. НДС Виробничий (Глобине-2) Глобине-2 Прямі материальні виробничі витрати крім зворотніх відходів | D27: Обл. НДС Щебенево-піщана суміш фр 0-70 мм Надходження товарів і послуг ІБ00-001691 від 14.04.2025 11:04:21 Генплан благоустрій (Глобине) | E27: 231 | H27: 205 | I27: 13739.33 | K27: Д | L27: 225561.25
A28: 19.06.2025 | B28: Вимога-накладна ІБ00-000453 від 19.06.2025 10:04:50 Списаны ТМЦ | C28: Обл. НДС Виробничий (Глобине-2) Глобине-2 Прямі материальні виробничі витрати крім зворотніх відходів | D28: Обл. НДС Щебенево-піщана суміш фр 0-70 мм Надходження товарів і послуг ІБ00-001691 від 14.04.2025 11:04:21 Генплан благоустрій (Глобине) | E28: 231 | H28: 205 | I28: 13270.67 | K28: Д | L28: 212290.58
A29: 19.06.2025 | B29: Вимога-накладна ІБ00-000453 від 19.06.2025 10:04:50 Списаны ТМЦ | C29: Обл. НДС Виробничий (Глобине-2) Глобине-2 Прямі материальні виробничі витрати крім зворотніх відходів | D29: Обл. НДС Щебнево-пісчана суміш фр.0-70 мм Надходження товарів і послуг ІБ00-002633 від 24.05.2025 11:00:00 Генплан благоустрій (Глобине) | E29: 231 | H29: 205 | I29: 11621.33 | K29: Д | L29: 200669.25
A30: 19.06.2025 | B30: Вимога-накладна ІБ00-000453 від 19.06.2025 10:04:50 Списаны ТМЦ | C30: Обл. НДС Виробничий (Глобине-2) Глобине-2 Прямі материальні виробничі витрати крім зворотніх відходів | D30: Обл. НДС Щебенево-піщана суміш фр 0-70 мм Надходження товарів і послуг ІБ00-001691 від 14.04.2025 11:04:21 Генплан благоустрій (Глобине) | E30: 231 | H30: 205 | I30: 48883.17 | K30: Д | L30: 151786.08
... A37: 19.06.2025 | B37: Вимога-накладна ІБ00-000453 від 19.06.2025 10:04:50 Списаны ТМЦ | C37: Обл. НДС Виробничий (Глобине-2) Глобине-2 Прямі материальні виробничі витрати крім зворотніх відходів | D37: Обл. НДС Щебенево-піщана суміш фр 0-70 мм Надходження товарів і послуг ІБ00-002968 від 01.06.2025 11:00:00 Генплан благоустрій (Глобине) | E37: 231 | H37: 205 | I37: 6444 | K37: Д | L37: 115686.08
A38: 19.06.2025 | B38: Вимога-накладна ІБ00-000453 від 19.06.2025 10:04:50 Списаны ТМЦ | C38: Обл. НДС Виробничий (Глобине-2) Глобине-2 Прямі материальні виробничі витрати крім зворотніх відходів | D38: Обл. НДС Геотекстиль термоскріплений F-50 300г/м.кв (шир. 5 м) Надходження товарів і послуг ІБ00-000821 від 03.03.2025 18:09:02 Генплан благоустрій (Глобине) | E38: 231 | H38: 205 | I38: 115686.08
A39: Обороти за період та сальдо на кінець | E39: 280193.72 | H39: 280193.72 | L39: 0
J41: =SUBTOTAL(9,I19:J38) -> 280193.72

Sheet Генплан дорога СПК
A1: Період | B1: Документ | C1: Аналітика Дт | D1: Аналітика Кт | E1: Дебет | H1: Кредит | K1: Поточне сальдо
E2: Рахунок | H2: Рахунок
A3: 18.06.2025 | B3: Переміщення товарів ІБ00-000563 від 18.06.2025 10:08:38 Перемещение ТМЦ | C3: Обл. НДС Пісок з відсіву дроблення щебеню фр. 0-5мм. Надходження товарів і послуг ІБ00-002156 від 09.05.2025 11:00:00 Генплан благоустрій (Глобине) | D3: Обл. НДС Пісок з відсіву дроблення щебеню фр. 0-5мм. Надходження товарів і послуг ІБ00-002156 від 09.05.2025 11:00:00 Генплан дорога СПК (Глобине) | E3: 205 | H3: 205 | I3: 6729.25 | K3: Д | L3: 191125.34
A4: 18.06.2025 | B4: Переміщення товарів ІБ00-000563 від 18.06.2025 10:08:38 Перемещение ТМЦ | C4: Обл. НДС Пісок з відсіву дроблення щебеню фр. 0-5мм. Надходження товарів і послуг ІБ00-002222 від 14.05.2025 11:00:00 Генплан благоустрій (Глобине) | D4: Обл. НДС Пісок з відсіву дроблення щебеню фр. 0-5мм. Надходження товарів і послуг ІБ00-002222 від 14.05.2025 11:00:00 Генплан дорога СПК (Глобине) | E4: 205 | H4: 205 | I4: 1871.83 | K4: Д | L4: 189253.51
A5: 18.06.2025 | B5: Переміщення товарів ІБ00-000563 від 18.06.2025 10:08:38 Перемещение ТМЦ | C5: Обл. НДС Пісок з відсіву дроблення щебеню фр. 0-5мм. Надходження товарів і послуг ІБ00-002305 від 19.05.2025 11:00:00 Генплан благоустрій (Глобине) | D5: Обл. НДС Пісок з відсіву дроблення щебеню фр. 0-5мм. Надходження товарів і послуг ІБ00-002305 від 19.05.2025 11:00:00 Генплан дорога СПК (Глобине) | E5: 205 | H5: 205 | I5: 7555.17 | K5: Д | L5: 181698.34
A6: 18.06.2025 | B6: Переміщення товарів ІБ00-000563 від 18.06.2025 10:08:38 Перемещение ТМЦ | C6: Обл. НДС Пісок з відсіву дроблення щебеню фр. 0-5мм. Надходження товарів і послуг ІБ00-002508 від 21.05.2025 11:00:00 Генплан благоустрій (Глобине) | D6: Обл. НДС Пісок з відсіву дроблення щебеню фр. 0-5мм. Надходження товарів і послуг ІБ00-002508 від 21.05.2025 11:00:00 Генплан дорога СПК (Глобине) | E6: 205 | H6: 205 | I6: 7991.5 | K6: Д | L6: 173706.84
A7: 18.06.2025 | B7: Переміщення товарів ІБ00-000563 від 18.06.2025 10:08:38 Перемещение ТМЦ | C7: Обл. НДС Пісок з відсіву дроблення щебеню фр. 0-5мм. Надходження товарів і послуг ІБ00-002716 від 22.05.2025 11:00:00 Генплан благоустрій (Глобине) | D7: Обл. НДС Пісок з відсіву дроблення щебеню фр. 0-5мм. Надходження товарів і послуг ІБ00-002716 від 22.05.2025 11:00:00 Генплан дорога СПК (Глобине) | E7: 205 | H7: 205 | I7: 1904.83 | K7: Д | L7: 171802.01
A8: 18.06.2025 | B8: Переміщення товарів ІБ00-000563 від 18.06.2025 10:08:38 Перемещение ТМЦ | C8: Обл. НДС Пісок з відсіву дроблення щебеню фр. 0-5мм. Надходження товарів і послуг ІБ00-002712 від 28.05.2025 11:00:00 Генплан благоустрій (Глобине) | D8: Обл. НДС Пісок з відсіву дроблення щебеню фр. 0-5мм. Надходження товарів і послуг ІБ00-002712 від 28.05.2025 11:00:00 Генплан дорога СПК (Глобине) | E8: 205 | H8: 205 | I8: 5985.84 | K8: Д | L8: 165816.17
A9: 18.06.2025 | B9: Переміщення товарів ІБ00-000563 від 18.06.2025 10:08:38 Перемещение ТМЦ | C9: Обл. НДС Пісок з відсіву дроблення щебеню фр. 0-5мм. Надходження товарів і послуг ІБ00-002713 від 29.05.2025 11:00:00 Генплан благоустрій (Глобине) | D9: Обл. НДС Пісок з відсіву дроблення щебеню фр. 0-5мм. Надходження товарів і послуг ІБ00-002713 від 29.05.2025 11:00:00 Генплан дорога СПК (Глобине) | E9: 205 | H9: 205 | I9: 7921.83 | K9: Д | L9: 157894.34
A10: 18.06.2025 | B10: Переміщення товарів ІБ00-000563 від 18.06.2025 10:08:38 Перемещение ТМЦ | C10: Обл. НДС Пісок з відсіву дроблення щебеню фр. 0-5мм. Надходження товарів і послуг ІБ00-002715 від 30.05.2025 11:00:00 Генплан благоустрій (Глобине) | D10: Обл. НДС Пісок з відсіву дроблення щебеню фр. 0-5мм. Надходження товарів і послуг ІБ00-002715 від 30.05.2025 11:00:00 Генплан дорога СПК (Глобине) | E10: 205 | H10: 205 | I10: 932.89 | K10: Д | L10: 156961.45
A11: 18.06.2025 | B11: Переміщення товарів ІБ00-000563 від 18.06.2025 10:08:38 Перемещение ТМЦ | C11: Обл. НДС Щебенево-піщана суміш фр 0-70 мм Надходження товарів і послуг ІБ00-002716 від 22.05.2025 11:00:00 Генплан благоустрій (Глобине) | D11: Обл. НДС Щебенево-піщана суміш фр 0-70 мм Надходження товарів і послуг ІБ00-002716 від 22.05.2025 11:00:00 Генплан дорога СПК (Глобине) | E11: 205 | H11: 205 | I11: 5738.67 | K11: Д | L11: 151222.78
A12: 18.06.2025 | B12: Переміщення товарів ІБ00-000563 від 18.06.2025 10:08:38 Перемещение ТМЦ | C12: Обл. НДС Щебенево-піщана суміш фр 0-70 мм Надходження товарів і послуг ІБ00-002708 від 26.05.2025 11:00:00 Генплан благоустрій (Глобине) | D12: Обл. НДС Щебенево-піщана суміш фр 0-70 мм Надходження товарів і послуг ІБ00-002708 від 26.05.2025 11:00:00 Генплан дорога СПК (Глобине) | E12: 205 | H12: 205 | I12: 5941.33 | K12: Д | L12: 145281.45
A13: 18.06.2025 | B13: Переміщення товарів ІБ00-000563 від 18.06.2025 10:08:38 Перемещение ТМЦ | C13: Обл. НДС Щебнево-пісчана суміш фр.0-70 мм Надходження товарів і послуг ІБ00-002633 від 24.05.2025 11:00:00 Генплан благоустрій (Глобине) | D13: Обл. НДС Щебнево-пісчана суміш фр.0-70 мм Надходження товарів і послуг ІБ00-002633 від 24.05.2025 11:00:00 Генплан дорога СПК (Глобине) | E13: 205 | H13: 205 | I13: 11621.33 | K13: Д | L13: 133660.12
A14: 18.06.2025 | B14: Переміщення товарів ІБ00-000563 від 18.06.2025 10:08:38 Перемещение ТМЦ | C14: Обл. НДС Геотекстиль термоскріплений F-50 300г/м.кв (шир. 5 м) Надходження товарів і послуг ІБ00-000821 від 03.03.2025 18:09:02 Генплан благоустрій (Глобине) | D14: Обл. НДС Геотекстиль термоскріплений F-50 300г/м.кв (шир. 5 м) Надходження товарів і послуг ІБ00-000821 від 03.03.2025 18:09:02 Генплан дорога СПК (Глобине) | E14: 205 | H14: 205 | I14: 115686.08 | K14: Д | L14: 17974.04
A15: 23.06.2025 | B15: Надходження товарів і послуг ІБ00-003559 від 23.06.2025 11:00:00 Оприходованы ТМЦ | C15: Обл. НДС Щебнево-пісчана суміш фр.0-70 мм Надходження товарів і послуг ІБ00-003559 від 23.06.2025 11:00:00 Генплан дорога СПК (Глобине) | D15: Венкрас Авто ПП Договір 05/09/2024 від 05.09.2024_Глобине-2 Рахунок на оплату постачальника ІБ00-002919 від 23.06.2025 18:22:22 | E15: 205 | F15: 10296 | H15: 631 | K15: Д | L15: 28270.04
A16: 23.06.2025 | B16: Надходження дод. витрат ІБ00-000424 від 23.06.2025 11:10:00 Доп. расходы при поступлении товаров | C16: Обл. НДС Щебнево-пісчана суміш фр.0-70 мм Надходження товарів і послуг ІБ00-003559 від 23.06.2025 11:00:00 Генплан дорога СПК (Глобине) | D16: Венкрас Авто ПП Договір 05/09/2024 від 05.09.2024_Глобине-2 Рахунок на оплату постачальника ІБ00-002919 від 23.06.2025 18:22:22 | E16: 205 | F16: 10868 | H16: 631 | K16: Д | L16: 39138.04
A17: 24.06.2025 | B17: Надходження товарів і послуг ІБ00-003239 від 24.06.2025 11:00:00 Оприходованы ТМЦ | C17: Обл. НДС Щебнево-пісчана суміш фр.0-70 мм Надходження товарів і послуг ІБ00-003239 від 24.06.2025 11:00:00 Генплан дорога СПК (Глобине) | D17: Венкрас Авто ПП Договір 05/09/2024 від 05.09.2024_Глобине-2 Рахунок на оплату постачальника ІБ00-002704 від 24.06.2025 18:10:24 | E17: 205 | F17: 6177 | H17: 631 | K17: Д | L17: 45315.04
A18: 24.06.2025 | B18: Переміщення товарів ІБ00-000625 від 24.06.2025 11:15:00 Перемещение ТМЦ | C18: Обл. НДС Щебенево-піщана суміш фр 0-70 мм Надходження товарів і послуг ІБ00-003420 від 24.06.2025 11:00:00 Генплан дорога СПК (Глобине) | D18: Обл. НДС Щебенево-піщана суміш фр 0-70 мм Надходження товарів і послуг ІБ00-003420 від 24.06.2025 11:00:00 Глобине-2 | E18: 205 | F18: 23252.73 | H18: 205 | K18: Д | L18: 68567.77
A19: Обороти за період та сальдо на кінець | E19: 50593.73 | H19: 0 | K19: Д | L19: 68567.77
J22: 0

Sheet Генплан підпірна стінка
A1: Період | B1: Документ | C1: Аналітика Дт | D1: Аналітика Кт | E1: Дебет | H1: Кредит | K1: Поточне сальдо
E2: Рахунок | H2: Рахунок
A3: 01.06.2025 | B3: Переміщення товарів ІБ00-000541 від 01.06.2025 23:13:45 Перемещение ТМЦ | C3: Обл. НДС Бетон С20/25 W6 F75 P4 Надходження товарів і послуг ІБ00-002293 від 17.05.2025 11:00:00 Цех екстракції (Глобине) | D3: Обл. НДС Бетон С20/25 W6 F75 P4 Надходження товарів і послуг ІБ00-002293 від 17.05.2025 11:00:00 Генплан підпірна стінка (Глобине) | E3: 205 | H3: 205 | I3: 1495.18 | K3: Д | L3: 95462.4
A4: 01.06.2025 | B4: Переміщення товарів ІБ00-000542 від 01.06.2025 23:13:46 Перемещение ТМЦ | C4: Обл. НДС Цемент ПЦ ІІ/А-Ш 500 25кг 1пал/64шт Надходження товарів і послуг ІБ00-002038 від 01.04.2025 11:00:00 Транспортна галерея (Глобине) | D4: Обл. НДС Цемент ПЦ ІІ/А-Ш 500 25кг 1пал/64шт Надходження товарів і послуг ІБ00-002038 від 01.04.2025 11:00:00 Генплан підпірна стінка (Глобине) | E4: 205 | H4: 205 | I4: 4676.1 | K4: Д | L4: 90786.3
A5: 01.06.2025 | B5: Переміщення товарів ІБ00-000542 від 01.06.2025 23:13:46 Перемещение ТМЦ | C5: Обл. НДС Цемент ПЦ ІІ/А-Ш 500 25кг 1пал/64шт Надходження товарів і послуг ІБ00-002038 від 01.04.2025 11:00:00 Транспортна галерея (Глобине) | D5: Обл. НДС Цемент ПЦ ІІ/А-Ш 500 25кг 1пал/64шт Надходження товарів і послуг ІБ00-002038 від 01.04.2025 11:00:00 Генплан підпірна стінка (Глобине) | E5: 205 | H5: 205 | I5: 2413.95 | K5: Д | L5: 88372.35
A6: 01.06.2025 | B6: Переміщення товарів ІБ00-000542 від 01.06.2025 23:13:46 Перемещение ТМЦ | C6: Обл. НДС Цемент ПЦ ІІ/А-Ш 500 25кг 1пал/64шт Надходження товарів і послуг ІБ00-002038 від 01.04.2025 11:00:00 Транспортна галерея (Глобине) | D6: Обл. НДС Цемент ПЦ ІІ/А-Ш 500 25кг 1пал/64шт Надходження товарів і послуг ІБ00-002038 від 01.04.2025 11:00:00 Генплан підпірна стінка (Глобине) | E6: 205 | H6: 205 | I6: 3111.9 | K6: Д | L6: 85260.45
A7: 12.06.2025 | B7: Переміщення товарів ІБ00-000559 від 12.06.2025 10:26:04 Перемещение ТМЦ | C7: Обл. НДС Бетон С 30/35 W4 F75 Р4 Надходження товарів і послуг ІБ00-001961 від 30.04.2025 11:00:00 СПК (Глобине) | D7: Обл. НДС Бетон С 30/35 W4 F75 Р4 Надходження товарів і послуг ІБ00-001961 від 30.04.2025 11:00:00 Генплан підпірна стінка (Глобине) | E7: 205 | H7: 205 | I7: 11827.73 | K7: Д | L7: 73432.72
A8: 18.06.2025 | B8: Переміщення товарів ІБ00-000565 від 18.06.2025 10:11:53 Перемещение ТМЦ | C8: Обл. НДС Щебенево-піщана суміш фр 0-70 мм Надходження товарів і послуг ІБ00-001691 від 14.04.2025 11:04:21 Генплан благоустрій (Глобине) | D8: Обл. НДС Щебенево-піщана суміш фр 0-70 мм Надходження товарів і послуг ІБ00-001691 від 14.04.2025 11:04:21 Генплан підпірна стінка (Глобине) | E8: 205 | H8: 205 | I8: 62647.17 | K8: Д | L8: 10785.55
A9: Обороти за період та сальдо на кінець | E9: 0 | H9: 0 | K9: Д | L9: 10785.55
J11: 0

Sheet Глобине-2
A1: Період | B1: Документ | C1: Аналітика Дт | D1: Аналітика Кт | E1: Дебет | H1: Кредит | K1: Поточне сальдо
E2: Рахунок | H2: Рахунок
A3: 01.06.2025 | B3: Надходження товарів і послуг ІБ00-002831 від 01.06.2025 11:00:00 Оприходованы ТМЦ | C3: Обл. НДС Труба 80х80х4 мм ст 1-3пс, 12 м Надходження товарів і послуг ІБ00-002831 від 01.06.2025 11:00:00 Глобине-2 | D3: МЕТІНВЕСТ-СМЦ ТОВ №1778403/01/2023-С от 11.01.2023 РАХУНКИ_Глобино-2 Рахунок на оплату постачальника ІБ00-002203 від 27.05.2025 18:43:24 | E3: 205 | F3: 29952 | H3: 631 | K3: Д | L3: 440494.09
A4: 01.06.2025 | B4: Надходження товарів і послуг ІБ00-002831 від 01.06.2025 11:00:00 Оприходованы ТМЦ | C4: Обл. НДС Труба профільна 100*100*4 L=12000 мм ст1-3 сп/пс Надходження товарів і послуг ІБ00-002831 від 01.06.2025 11:00:00 Глобине-2 | D4: МЕТІНВЕСТ-СМЦ ТОВ №1778403/01/2023-С от 11.01.2023 РАХУНКИ_Глобино-2 Рахунок на оплату постачальника ІБ00-002203 від 27.05.2025 18:43:24 | E4: 205 | F4: 43156.76 | H4: 631 | K4: Д | L4: 483650.85
A5: 01.06.2025 | B5: Надходження товарів і послуг ІБ00-003563 від 01.06.2025 11:00:00 Оприходованы ТМЦ | C5: Обл. НДС Кисень газ 40л бал., 2.2 (5.1) Надходження товарів і послуг ІБ00-003563 від 01.06.2025 11:00:00 Глобине-2 | D5: Терещенко Т.В. ФОП Договір 02/01/2025 від 02.01.2025_Глобине-2 Рахунок на оплату постачальника ІБ00-002340 від 01.06.2025 23:13:21 | E5: 205 | F5: 6000 | H5: 631 | K5: Д | L5: 489650.85
A6: 01.06.2025 | B6: Переміщення товарів ІБ00-000531 від 01.06.2025 11:10:00 Перемещение ТМЦ | C6: Обл. НДС Труба 80х80х4 мм ст 1-3пс, 12 м Надходження товарів і послуг ІБ00-002831 від 01.06.2025 11:00:00 Котельна (Глобине) | D6: Обл. НДС Труба 80х80х4 мм ст 1-3пс, 12 м Надходження товарів і послуг ІБ00-002831 від 01.06.2025 11:00:00 Глобине-2 | E6: 205 | H6: 205 | I6: 9984 | K6: Д | L6: 479666.85
A7: 01.06.2025 | B7: Переміщення товарів ІБ00-000532 від 01.06.2025 11:10:00 Перемещение ТМЦ | C7: Обл. НДС Труба 80х80х4 мм ст 1-3пс, 12 м Надходження товарів і послуг ІБ00-002831 від 01.06.2025 11:00:00 Генплан митний склад (Глобине) | D7: Обл. НДС Труба 80х80х4 мм ст 1-3пс, 12 м Надходження товарів і послуг ІБ00-002831 від 01.06.2025 11:00:00 Глобине-2 | E7: 205 | H7: 205 | I7: 13478.4 | K7: Д | L7: 466188.45
A8: 01.06.2025 | B8: Переміщення товарів ІБ00-000533 від 01.06.2025 11:10:00 Перемещение ТМЦ | C8: Обл. НДС Труба профільна 100*100*4 L=12000 мм ст1-3 сп/пс Надходження товарів і послуг ІБ00-002831 від 01.06.2025 11:00:00 Резервуарний парк соєвої меляси (Глобине) | D8: Обл. НДС Труба профільна 100*100*4 L=12000 мм ст1-3 сп/пс Надходження товарів і послуг ІБ00-002831 від 01.06.2025 11:00:00 Глобине-2 | E8: 205 | H8: 205 | I8: 17389.17 | K8: Д | L8: 448799.28
A9: 01.06.2025 | B9: Переміщення товарів ІБ00-000534 від 01.06.2025 11:10:00 Перемещение ТМЦ | C9: Обл. НДС Труба 80х80х4 мм ст 1-3пс, 12 м Надходження товарів і послуг ІБ00-002831 від 01.06.2025 11:00:00 Резервуарний парк соєвої меляси (Глобине) | D9: Обл. НДС Труба 80х80х4 мм ст 1-3пс, 12 м Надходження товарів і послуг ІБ00-002831 від 01.06.2025 11:00:00 Глобине-2 | E9: 205 | H9: 205 | I9: 6489.6 | K9: Д | L9: 442309.68
A10: 01.06.2025 | B10: Переміщення товарів ІБ00-000535 від 01.06.2025 11:10:00 Перемещение ТМЦ | C10: Обл. НДС Труба профільна 100*100*4 L=12000 мм ст1-3 сп/пс Надходження товарів і послуг ІБ00-002831 від 01.06.2025 11:00:00 Резервуарний парк соєвої меляси (Глобине) | D10: Обл. НДС Труба профільна 100*100*4 L=12000 мм ст1-3 сп/пс Надходження товарів і послуг ІБ00-002831 від 01.06.2025 11:00:00 Глобине-2 | E10: 205 | H10: 205 | I10: 25767.59 | K10: Д | L10: 416542.09
A11: 04.06.2025 | B11: Авансовий звіт ІБ00-000132 від 04.06.2025 17:31:19 Оприходованы ТМЦ | C11: Обл. НДС Пістолет для герметика Авансовий звіт ІБ00-000132 від 04.06.2025 17:31:19 Глобине-2 | D11: Штиченко Олександр Володимирович | E11: 205 | F11: 610 | H11: 3721 | K11: Д | L11: 417152.09
A12: 04.06.2025 | B12: Авансовий звіт ІБ00-000132 від 04.06.2025 17:31:19 Оприходованы ТМЦ | C12: Обл. НДС Дюбель "потай" 6*60 100шт/уп Авансовий звіт ІБ00-000132 від 04.06.2025 17:31:19 Глобине-2 | D12: Штиченко Олександр Володимирович | E12: 205 | F12: 70 | H12: 3721 | K12: Д | L12: 417222.09
A13: 04.06.2025 | B13: Авансовий звіт ІБ00-000132 від 04.06.2025 17:31:19 Оприходованы ТМЦ | C13: Обл. НДС Бур SDS Plus 6*210 Авансовий звіт ІБ00-000132 від 04.06.2025 17:31:19 Глобине-2 | D13: Штиченко Олександр Володимирович | E13: 205 | F13: 68 | H13: 3721 | K13: Д | L13: 417290.09
A14: 04.06.2025 | B14: Авансовий звіт ІБ00-000132 від 04.06.2025 17:31:19 Оприходованы ТМЦ | C14: Обл. НДС Круг зачисний по металу 125 Авансовий звіт ІБ00-000132 від 04.06.2025 17:31:19 Глобине-2 | D14: Штиченко Олександр Володимирович | E14: 205 | F14: 165 | H14: 3721 | K14: Д | L14: 417455.09
A15: 04.06.2025 | B15: Авансовий звіт ІБ00-000132 від 04.06.2025 17:31:19 Оприходованы ТМЦ | C15: Обл. НДС Шнур Авансовий звіт ІБ00-000132 від 04.06.2025 17:31:19 Глобине-2 | D15: Штиченко Олександр Володимирович | E15: 205 | F15: 120 | H15: 3721 | K15: Д | L15: 417575.09
A16: 04.06.2025 | B16: Авансовий звіт ІБ00-000132 від 04.06.2025 17:31:19 Оприходованы ТМЦ | C16: Обл. НДС Колесо до тачки *125 Авансовий звіт ІБ00-000132 від 04.06.2025 17:31:19 Глобине-2 | D16: Штиченко Олександр Володимирович | E16: 205 | F16: 662 | H16: 3721 | K16: Д | L16: 418237.09
A17: 04.06.2025 | B17: Авансовий звіт ІБ00-000132 від 04.06.2025 17:31:19 Оприходованы ТМЦ | C17: Обл. НДС Болт М 8*30 Авансовий звіт ІБ00-000132 від 04.06.2025 17:31:19 Глобине-2 | D17: Штиченко Олександр Володимирович | E17: 205 | F17: 24 | H17: 3721 | K17: Д | L17: 418261.09
A18: 04.06.2025 | B18: Авансовий звіт ІБ00-000132 від 04.06.2025 17:31:19 Оприходованы ТМЦ | C18: Обл. НДС Шайба М8 Авансовий звіт ІБ00-000132 від 04.06.2025 17:31:19 Глобине-2 | D18: Штиченко Олександр Володимирович | E18: 205 | F18: 8 | H18: 3721 | K18: Д | L18: 418269.09
A19: 04.06.2025 | B19: Авансовий звіт ІБ00-000132 від 04.06.2025 17:31:19 Оприходованы ТМЦ | C19: Обл. НДС Гайка М 8 Авансовий звіт ІБ00-000132 від 04.06.2025 17:31:19 Глобине-2 | D19: Штиченко Олександр Володимирович | E19: 205 | F19: 6.4 | H19: 3721 | K19: Д | L19: 418275.49
A20: 04.06.2025 | B20: Авансовий звіт ІБ00-000132 від 04.06.2025 17:31:19 Оприходованы ТМЦ | C20: Обл. НДС вироби кріпильні та гвинтонарізні 50 Авансовий звіт ІБ00-000132 від 04.06.2025 17:31:19 Глобине-2 | D20: Штиченко Олександр Володимирович | E20: 205 | F20: 93 | H20: 3721 | K20: Д | L20: 418368.49
A21: 04.06.2025 | B21: Авансовий звіт ІБ00-000132 від 04.06.2025 17:31:19 Оприходованы ТМЦ | C21: Обл. НДС вироби кріпильні та гвинтонарізні 80 Авансовий звіт ІБ00-000132 від 04.06.2025 17:31:19 Глобине-2 | D21: Штиченко Олександр Володимирович | E21: 205 | F21: 61 | H21: 3721 | K21: Д | L21: 418429.49
A22: 04.06.2025 | B22: Авансовий звіт ІБ00-000132 від 04.06.2025 17:31:19 Оприходованы ТМЦ | C22: Обл. НДС вироби кріпильні та гвинтонарізні Авансовий звіт ІБ00-000132 від 04.06.2025 17:31:19 Глобине-2 | D22: Штиченко Олександр Володимирович | E22: 205 | F22: 61 | H22: 3721 | K22: Д | L22: 418490.49
... A29: 06.06.2025 | B29: Надходження товарів і послуг ІБ00-002837 від 06.06.2025 11:00:00 Оприходованы ТМЦ | C29: Обл. НДС Балка ІРЕ 300 міра L=12 S275JR Надходження товарів і послуг ІБ00-002837 від 06.06.2025 11:00:00 Глобине-2 | D29: МЕТІНВЕСТ-СМЦ ТОВ №1778403/01/2023-С от 11.01.2023 РАХУНКИ_Глобино-2 Рахунок на оплату постачальника ІБ00-002371 від 06.06.2025 18:22:56 | E29: 205 | F29: 68999.99 | H29: 631 | K29: Д | L29: 501148.55
A30: 06.06.2025 | B30: Переміщення товарів ІБ00-000536 від 06.06.2025 11:10:00 Перемещение ТМЦ | C30: Обл. НДС Балка ІРЕ 240 міра L=12 S275JR Надходження товарів і послуг ІБ00-002837 від 06.06.2025 11:00:00 Резервуарний парк соєвої меляси (Глобине) | D30: Обл. НДС Балка ІРЕ 240 міра L=12 S275JR Надходження товарів і послуг ІБ00-002837 від 06.06.2025 11:00:00 Глобине-2 | E30: 205 | H30: 205 | I30: 12666.67 | K30: Д | L30: 488481.88
A31: 06.06.2025 | B31: Переміщення товарів ІБ00-000537 від 06.06.2025 11:10:00 Перемещение ТМЦ | C31: Обл. НДС Балка ІРЕ 300 міра L=12 S275JR Надходження товарів і послуг ІБ00-002837 від 06.06.2025 11:00:00 СПК (Глобине) | D31: Обл. НДС Балка ІРЕ 300 міра L=12 S275JR Надходження товарів і послуг ІБ00-002837 від 06.06.2025 11:00:00 Глобине-2 | E31: 205 | H31: 205 | I31: 68999.99 | K31: Д | L31: 419481.89
A32: 09.06.2025 | B32: Повернення товарів постачальнику ІБ00-000019 від 09.06.2025 11:00:00 Возврат ТМЦ (Возврат поставщику. Неоплаченная часть.) | C32: МЕТІНВЕСТ-СМЦ ТОВ №1778403/01/2023-С от 11.01.2023 РАХУНКИ_Глобино-2 Рахунок на оплату постачальника ІБ00-002203 від 27.05.2025 18:43:24 | D32: Обл. НДС Дріт 5,0 мм Вр-1 Надходження товарів і послуг ІБ00-002608 від 23.05.2025 11:00:00 Глобине-2 | E32: 631 | H32: 205 | I32: 121388.32 | K32: Д | L32: 298093.57
A33: 09.06.2025 | B33: Надходження товарів і послуг ІБ00-002806 від 09.06.2025 11:00:00 Оприходованы ТМЦ | C33: Обл. НДС Бетон С20/25 W6 F75 P4 Надходження товарів і послуг ІБ00-002806 від 09.06.2025 11:00:00 Глобине-2 | D33: Кременчуцький річковий порт ПРАТ Договір 112/Б від 15.10.2024_Глобине-2 Надходження товарів і послуг ІБ00-002806 від 09.06.2025 11:00:00 | E33: 205 | F33: 84680 | H33: 631 | K33: Д | L33: 382773.57
A34: 09.06.2025 | B34: Надходження товарів і послуг ІБ00-002854 від 09.06.2025 11:00:00 Оприходованы ТМЦ | C34: Обл. НДС Грунт-емаль ПФ-012 Р сірий (кг) Надходження товарів і послуг ІБ00-002854 від 09.06.2025 11:00:00 Глобине-2 | D34: Синтез ЛКМ РАХУНКИ_Глобино-2 Рахунок на оплату постачальника ІБ00-002407 від 06.06.2025 18:23:07 | E34: 205 | F34: 4458.5 | H34: 631 | K34: Д | L34: 387232.07
A35: 09.06.2025 | B35: Надходження товарів і послуг ІБ00-002854 від 09.06.2025 11:00:00 Оприходованы ТМЦ | C35: Обл. НДС Грунт ГФ-021 сірий Надходження товарів і послуг ІБ00-002854 від 09.06.2025 11:00:00 Глобине-2 | D35: Синтез ЛКМ РАХУНКИ_Глобино-2 Рахунок на оплату постачальника ІБ00-002407 від 06.06.2025 18:23:07 | E35: 205 | F35: 12000 | H35: 631 | K35: Д | L35: 399232.07
A36: 09.06.2025 | B36: Надходження товарів і послуг ІБ00-002854 від 09.06.2025 11:00:00 Оприходованы ТМЦ | C36: Обл. НДС Розчинник "White Spirit" (л) Надходження товарів і послуг ІБ00-002854 від 09.06.2025 11:00:00 Глобине-2 | D36: Синтез ЛКМ РАХУНКИ_Глобино-2 Рахунок на оплату постачальника ІБ00-002407 від 06.06.2025 18:23:07 | E36: 205 | F36: 14447.4 | H36: 631 | K36: Д | L36: 413679.47
A37: 09.06.2025 | B37: Надходження дод. витрат ІБ00-000376 від 09.06.2025 11:05:00 Доп. расходы при поступлении товаров | C37: Обл. НДС Бетон С20/25 W6 F75 P4 Надходження товарів і послуг ІБ00-002806 від 09.06.2025 11:00:00 Глобине-2 | D37: Кременчуцький річковий порт ПРАТ Договір 112/Б від 15.10.2024_Глобине-2 Надходження дод. витрат ІБ00-000376 від 09.06.2025 11:05:00 | E37: 205 | F37: 25039.5 | H37: 631 | K37: Д | L37: 438718.97
A38: 09.06.2025 | B38: Переміщення товарів ІБ00-000525 від 09.06.2025 11:10:00 Перемещение ТМЦ | C38: Обл. НДС Бетон С20/25 W6 F75 P4 Надходження товарів і послуг ІБ00-002806 від 09.06.2025 11:00:00 Пожежений резервуар (Глобине) | D38: Обл. НДС Бетон С20/25 W6 F75 P4 Надходження товарів і послуг ІБ00-002806 від 09.06.2025 11:00:00 Глобине-2 | E38: 205 | H38: 205 | I38: 107827.78 | K38: Д | L38: 330891.19
A39: 09.06.2025 | B39: Переміщення товарів ІБ00-000526 від 09.06.2025 11:10:00 Перемещение ТМЦ | C39: Обл. НДС Бетон С20/25 W6 F75 P4 Надходження товарів і послуг ІБ00-002806 від 09.06.2025 11:00:00 Пункт фасування та зберігання в бігбегах (Глобине) | D39: Обл. НДС Бетон С20/25 W6 F75 P4 Надходження товарів і послуг ІБ00-002806 від 09.06.2025 11:00:00 Глобине-2 | E39: 205 | H39: 205 | I39: 1891.72 | K39: Д | L39: 328999.47
A40: 09.06.2025 | B40: Переміщення товарів ІБ00-000543 від 09.06.2025 11:10:00 Перемещение ТМЦ | C40: Обл. НДС Грунт-емаль ПФ-012 Р сірий (кг) Надходження товарів і послуг ІБ00-002854 від 09.06.2025 11:00:00 Котельна (Глобине) | D40: Обл. НДС Грунт-емаль ПФ-012 Р сірий (кг) Надходження товарів і послуг ІБ00-002854 від 09.06.2025 11:00:00 Глобине-2 | E40: 205 | H40: 205 | I40: 4458.5 | K40: Д | L40: 324540.97
A41: 09.06.2025 | B41: Переміщення товарів ІБ00-000543 від 09.06.2025 11:10:00 Перемещение ТМЦ | C41: Обл. НДС Розчинник "White Spirit" (л) Надходження товарів і послуг ІБ00-002854 від 09.06.2025 11:00:00 Котельна (Глобине) | D41: Обл. НДС Розчинник "White Spirit" (л) Надходження товарів і послуг ІБ00-002854 від 09.06.2025 11:00:00 Глобине-2 | E41: 205 | H41: 205 | I41: 1313.4 | K41: Д | L41: 323227.57
A42: 09.06.2025 | B42: Переміщення товарів ІБ00-000544 від 09.06.2025 11:10:00 Перемещение ТМЦ | C42: Обл. НДС Грунт ГФ-021 сірий Надходження товарів і послуг ІБ00-002854 від 09.06.2025 11:00:00 СПК (Глобине) | D42: Обл. НДС Грунт ГФ-021 сірий Надходження товарів і послуг ІБ00-002854 від 09.06.2025 11:00:00 Глобине-2 | E42: 205 | H42: 205 | I42: 12000 | K42: Д | L42: 311227.57
A43: 09.06.2025 | B43: Переміщення товарів ІБ00-000544 від 09.06.2025 11:10:00 Перемещение ТМЦ | C43: Обл. НДС Розчинник "White Spirit" (л) Надходження товарів і послуг ІБ00-002854 від 09.06.2025 11:00:00 СПК (Глобине) | D43: Обл. НДС Розчинник "White Spirit" (л) Надходження товарів і послуг ІБ00-002854 від 09.06.2025 11:00:00 Глобине-2 | E43: 205 | H43: 205 | I43: 13134 | K43: Д | L43: 298093.57
A44: 12.06.2025 | B44: Надходження товарів і послуг ІБ00-003170 від 12.06.2025 11:00:00 Оприходованы ТМЦ | C44: Обл. НДС Пісок з відсіву дроблення щебеню фр. 0-5мм. Надходження товарів і послуг ІБ00-003170 від 12.06.2025 11:00:00 Глобине-2 | D44: Енергія Логістик ТОВ №28/10-2024 ВІД 28/10/24_Глобине-2 Рахунок на оплату постачальника ІБ00-002664 від 12.06.2025 23:26:17 | E44: 205 | F44: 7954.83 | H44: 631 | K44: Д | L44: 306048.4
A45: 12.06.2025 | B45: Переміщення товарів ІБ00-000584 від 12.06.2025 11:10:00 Перемещение ТМЦ | C45: Обл. НДС Пісок з відсіву дроблення щебеню фр. 0-5мм. Надходження товарів і послуг ІБ00-003170 від 12.06.2025 11:00:00 Резервуар для зберігання розчинника(Глобине) | D45: Обл. НДС Пісок з відсіву дроблення щебеню фр. 0-5мм. Надходження товарів і послуг ІБ00-003170 від 12.06.2025 11:00:00 Глобине-2 | E45: 205 | H45: 205 | I45: 4007.66 | K45: Д | L45: 302040.74
A46: 12.06.2025 | B46: Переміщення товарів ІБ00-000585 від 12.06.2025 11:10:00 Перемещение ТМЦ | C46: Обл. НДС Пісок з відсіву дроблення щебеню фр. 0-5мм. Надходження товарів і послуг ІБ00-003170 від 12.06.2025 11:00:00 АПК (Глобине) | D46: Обл. НДС Пісок з відсіву дроблення щебеню фр. 0-5мм. Надходження товарів і послуг ІБ00-003170 від 12.06.2025 11:00:00 Глобине-2 | E46: 205 | H46: 205 | I46: 3947.17 | K46: Д | L46: 298093.57
...

Sheet Котельна
A1: Період | B1: Документ | C1: Аналітика Дт | D1: Аналітика Кт | E1: Дебет | H1: Кредит | K1: Поточне сальдо
E2: Рахунок | H2: Рахунок
A3: 01.06.2025 | B3: Переміщення товарів ІБ00-000531 від 01.06.2025 11:10:00 Перемещение ТМЦ | C3: Обл. НДС Труба 80х80х4 мм ст 1-3пс, 12 м Надходження товарів і послуг ІБ00-002831 від 01.06.2025 11:00:00 Котельна (Глобине) | D3: Обл. НДС Труба 80х80х4 мм ст 1-3пс, 12 м Надходження товарів і послуг ІБ00-002831 від 01.06.2025 11:00:00 Глобине-2 | E3: 205 | F3: 9984 | H3: 205 | K3: Д | L3: 3274014
A4: 02.06.2025 | B4: Надходження товарів і послуг ІБ00-003385 від 02.06.2025 11:00:00 Оприходованы ТМЦ | C4: Обл. НДС Розчинник Уайт-спіріт 0,8л Надходження товарів і послуг ІБ00-003385 від 02.06.2025 11:00:00 Котельна (Глобине) | D4: Лозовий Микола Миколайович ФОП РАХУНКИ_Глобино-2 Рахунок на оплату постачальника ІБ00-002334 від 01.06.2025 23:13:15 | E4: 205 | F4: 1540 | H4: 631 | K4: Д | L4: 3275554
A5: 02.06.2025 | B5: Надходження товарів і послуг ІБ00-003385 від 02.06.2025 11:00:00 Оприходованы ТМЦ | C5: Обл. НДС Розчинник Уайт-спіріт 0,4л Надходження товарів і послуг ІБ00-003385 від 02.06.2025 11:00:00 Котельна (Глобине) | D5: Лозовий Микола Миколайович ФОП РАХУНКИ_Глобино-2 Рахунок на оплату постачальника ІБ00-002334 від 01.06.2025 23:13:15 | E5: 205 | F5: 720 | H5: 631 | K5: Д | L5: 3276274
A6: 02.06.2025 | B6: Надходження товарів і послуг ІБ00-003385 від 02.06.2025 11:00:00 Оприходованы ТМЦ | C6: Обл. НДС Розчинник Уайт-спіріт 4 л (шт) Надходження товарів і послуг ІБ00-003385 від 02.06.2025 11:00:00 Котельна (Глобине) | D6: Лозовий Микола Миколайович ФОП РАХУНКИ_Глобино-2 Рахунок на оплату постачальника ІБ00-002334 від 01.06.2025 23:13:15 | E6: 205 | F6: 1185 | H6: 631 | K6: Д | L6: 3277459
A7: 02.06.2025 | B7: Надходження товарів і послуг ІБ00-003386 від 02.06.2025 11:00:00 Оприходованы ТМЦ | C7: Обл. НДС Розчинник Уайт-спіріт 4 л (шт) Надходження товарів і послуг ІБ00-003386 від 02.06.2025 11:00:00 Котельна (Глобине) | D7: Лозовий Микола Миколайович ФОП РАХУНКИ_Глобино-2 Рахунок на оплату постачальника ІБ00-002335 від 01.06.2025 23:13:16 | E7: 205 | F7: 395 | H7: 631 | K7: Д | L7: 3277854
A8: 02.06.2025 | B8: Надходження товарів і послуг ІБ00-003386 від 02.06.2025 11:00:00 Оприходованы ТМЦ | C8: Обл. НДС Розчинник Уайт-спіріт 0,8л Надходження товарів і послуг ІБ00-003386 від 02.06.2025 11:00:00 Котельна (Глобине) | D8: Лозовий Микола Миколайович ФОП РАХУНКИ_Глобино-2 Рахунок на оплату постачальника ІБ00-002335 від 01.06.2025 23:13:16 | E8: 205 | F8: 1280 | H8: 631 | K8: Д | L8: 3279134
A9: 02.06.2025 | B9: Надходження товарів і послуг ІБ00-003386 від 02.06.2025 11:00:00 Оприходованы ТМЦ | C9: Обл. НДС Перетворювач іржі Надходження товарів і послуг ІБ00-003386 від 02.06.2025 11:00:00 Котельна (Глобине) | D9: Лозовий Микола Миколайович ФОП РАХУНКИ_Глобино-2 Рахунок на оплату постачальника ІБ00-002335 від 01.06.2025 23:13:16 | E9: 205 | F9: 225 | H9: 631 | K9: Д | L9: 3279359
A10: 02.06.2025 | B10: Надходження товарів і послуг ІБ00-003386 від 02.06.2025 11:00:00 Оприходованы ТМЦ | C10: Обл. НДС Розчинник Уайт-спіріт 0,4л Надходження товарів і послуг ІБ00-003386 від 02.06.2025 11:00:00 Котельна (Глобине) | D10: Лозовий Микола Миколайович ФОП РАХУНКИ_Глобино-2 Рахунок на оплату постачальника ІБ00-002335 від 01.06.2025 23:13:16 | E10: 205 | F10: 520 | H10: 631 | K10: Д | L10: 3279879
A11: 02.06.2025 | B11: Надходження товарів і послуг ІБ00-003386 від 02.06.2025 11:00:00 Оприходованы ТМЦ | C11: Обл. НДС Сольвент, 4 л (3,3 кг) Надходження товарів і послуг ІБ00-003386 від 02.06.2025 11:00:00 Котельна (Глобине) | D11: Лозовий Микола Миколайович ФОП РАХУНКИ_Глобино-2 Рахунок на оплату постачальника ІБ00-002335 від 01.06.2025 23:13:16 | E11: 205 | F11: 1960 | H11: 631 | K11: Д | L11: 3281839
A12: 02.06.2025 | B12: Надходження товарів і послуг ІБ00-003386 від 02.06.2025 11:00:00 Оприходованы ТМЦ | C12: Обл. НДС Сольвент, 1,0 л (0,67 кг) Надходження товарів і послуг ІБ00-003386 від 02.06.2025 11:00:00 Котельна (Глобине) | D12: Лозовий Микола Миколайович ФОП РАХУНКИ_Глобино-2 Рахунок на оплату постачальника ІБ00-002335 від 01.06.2025 23:13:16 | E12: 205 | F12: 304 | H12: 631 | K12: Д | L12: 3282143
A13: 09.06.2025 | B13: Переміщення товарів ІБ00-000543 від 09.06.2025 11:10:00 Перемещение ТМЦ | C13: Обл. НДС Грунт-емаль ПФ-012 Р сірий (кг) Надходження товарів і послуг ІБ00-002854 від 09.06.2025 11:00:00 Котельна (Глобине) | D13: Обл. НДС Грунт-емаль ПФ-012 Р сірий (кг) Надходження товарів і послуг ІБ00-002854 від 09.06.2025 11:00:00 Глобине-2 | E13: 205 | F13: 4458.5 | H13: 205 | K13: Д | L13: 3286601.5
A14: 09.06.2025 | B14: Переміщення товарів ІБ00-000543 від 09.06.2025 11:10:00 Перемещение ТМЦ | C14: Обл. НДС Розчинник "White Spirit" (л) Надходження товарів і послуг ІБ00-002854 від 09.06.2025 11:00:00 Котельна (Глобине) | D14: Обл. НДС Розчинник "White Spirit" (л) Надходження товарів і послуг ІБ00-002854 від 09.06.2025 11:00:00 Глобине-2 | E14: 205 | F14: 1313.4 | H14: 205 | K14: Д | L14: 3287914.9
... A22: 17.06.2025 | B22: Надходження товарів і послуг ІБ00-003042 від 17.06.2025 11:00:00 Оприходованы ТМЦ (Зачет аванса поставщику) | C22: Обл. НДС Газоблок 300*200*600 шт Надходження товарів і послуг ІБ00-003042 від 17.06.2025 11:00:00 Котельна (Глобине) | D22: СТАНДАРТ БУД ГРУП РАХУНКИ_Глобино-2 Рахунок на оплату постачальника ІБ00-002463 від 13.06.2025 18:33:03 | E22: 205 | F22: 4195.61 | H22: 631 | K22: Д | L22: 3460828.2
A23: 19.06.2025 | B23: Вимога-накладна ІБ00-000451 від 19.06.2025 09:22:08 Списаны ТМЦ | C23: Обл. НДС Виробничий (Глобине-2) Глобине-2 Прямі материальні виробничі витрати крім зворотніх відходів | D23: Обл. НДС Сендвіч-панель ТПК стінова 150мм МВ 1000мм термо замок С0,5 PS/C 0.5 PS 4,95м трапеція 9006 срібл/тр Надходження товарів і послуг ІБ00-001144 від 17.03.2025 17:20:38 Котельна (Глобине) | E23: 231 | H23: 205 | I23: 6294.77 | K23: Д | L23: 3454533.4
A24: 19.06.2025 | B24: Вимога-накладна ІБ00-000451 від 19.06.2025 09:22:08 Списаны ТМЦ | C24: Обл. НДС Виробничий (Глобине-2) Глобине-2 Прямі материальні виробничі витрати крім зворотніх відходів | D24: Обл. НДС Сендвіч-панель ТПК стінова 150мм МВ 1000мм термо замок С0,5 PS/C 0.5 PS 6,29м трапеція 9006 срібл/тр Надходження товарів і послуг ІБ00-001144 від 17.03.2025 17:20:38 Котельна (Глобине) | E24: 231 | H24: 205 | I24: 7998.8 | K24: Д | L24: 3446534.6
