Workbook

Sheet Свод
B2: АПК (Глобине) | C2: 0
B3: Генплан митний склад (Глобине) | C3: ='ГП мытный'!J69*1.2 -> 637114.93
B4: Генплан підпірна стінка (Глобине) | C4: ='ГП Стена'!J23*1.2 -> 121113.76
B5: Глобине-2 | C5: ='Глобине-2'!J206*1.2 -> 26904.072
B6: Котельна (Глобине) | C6: =Котельна!J164*1.2 -> 900672.84
B7: Насосна Градирня (Глобине) | C7: ='Насосна '!J96*1.2 -> 107773.33
B8: Пожежений резервуар (Глобине) | C8: 0
B9: Пункт фасування та зберігання в бігбегах (Глобине) | C9: 0
B10: Резервуар для зберігання розчинника(Глобине) | C10: =розчинника!J31*1.2 -> 241612.43
B11: Резервуарний парк соєвої меляси (Глобине) | C11: =меляси!J38*1.2 -> 509111.24
B12: СПК (Глобине) | C12: =СПК!J270*1.2 -> 5641979.7
B13: Цех екстракції (Глобине) | C13: =екстракції!J719*1.2 -> 9190517.7
B14: Цех_Глобино | C14: =Цех_Глобино!J33*1.2 -> 585034.96
C15: =SUM(C2:C14) -> 17961835

Sheet АПК
A1: Період | B1: Документ | C1: Аналітика Дт | D1: Аналітика Кт | E1: Дебет | H1: Кредит | K1: Поточне сальдо
E2: Рахунок | H2: Рахунок
A3: 03.03.2025 | B3: Надходження товарів і послуг ІБ00-000851 від 03.03.2025 18:09:07 Оприходованы ТМЦ | C3: Обл. НДС Прокат сталевий круглий (кл. А240С) ф8мм, ст.3пс, міра 6м Надходження товарів і послуг ІБ00-000851 від 03.03.2025 18:09:07 АПК (Глобине) | D3: ВІКАНТ фірма ТОВ 10/04-1 від 10.04.2022_Глобине-2 Рахунок на оплату постачальника ІБ00-000686 від 27.02.2025 21:38:52 | E3: 205 | F3: 2666.67 | H3: 631 | K3: Д | L3: 12936.92
A4: 03.03.2025 | B4: Надходження товарів і послуг ІБ00-000851 від 03.03.2025 18:09:07 Оприходованы ТМЦ | C4: Обл. НДС Прокат сталевий круглий (кл. А240С) ф12мм, ст.3пс, міра 6м Надходження товарів і послуг ІБ00-000851 від 03.03.2025 18:09:07 АПК (Глобине) | D4: ВІКАНТ фірма ТОВ 10/04-1 від 10.04.2022_Глобине-2 Рахунок на оплату постачальника ІБ00-000686 від 27.02.2025 21:38:52 | E4: 205 | F4: 69200 | H4: 631 | K4: Д | L4: 82136.92
A5: 03.03.2025 | B5: Надходження товарів і послуг ІБ00-000851 від 03.03.2025 18:09:07 Оприходованы ТМЦ | C5: Обл. НДС Прокат арматурний №12 мм А500С 6м Надходження товарів і послуг ІБ00-000851 від 03.03.2025 18:09:07 АПК (Глобине) | D5: ВІКАНТ фірма ТОВ 10/04-1 від 10.04.2022_Глобине-2 Рахунок на оплату постачальника ІБ00-000686 від 27.02.2025 21:38:52 | E5: 205 | F5: 108420 | H5: 631 | K5: Д | L5: 190556.92
A6: 03.03.2025 | B6: Надходження товарів і послуг ІБ00-000851 від 03.03.2025 18:09:07 Оприходованы ТМЦ | C6: Обл. НДС Прокат арматурний №14 мм А500С, 12 м Надходження товарів і послуг ІБ00-000851 від 03.03.2025 18:09:07 АПК (Глобине) | D6: ВІКАНТ фірма ТОВ 10/04-1 від 10.04.2022_Глобине-2 Рахунок на оплату постачальника ІБ00-000686 від 27.02.2025 21:38:52 | E6: 205 | F6: 292500 | H6: 631 | K6: Д | L6: 483056.92
A7: 03.03.2025 | B7: Надходження товарів і послуг ІБ00-000851 від 03.03.2025 18:09:07 Оприходованы ТМЦ | C7: Обл. НДС Прокат арматурний №25 мм А500С 12м Надходження товарів і послуг ІБ00-000851 від 03.03.2025 18:09:07 АПК (Глобине) | D7: ВІКАНТ фірма ТОВ 10/04-1 від 10.04.2022_Глобине-2 Рахунок на оплату постачальника ІБ00-000686 від 27.02.2025 21:38:52 | E7: 205 | F7: 10686 | H7: 631 | K7: Д | L7: 493742.92
A8: 03.03.2025 | B8: Надходження товарів і послуг ІБ00-000851 від 03.03.2025 18:09:07 Оприходованы ТМЦ | C8: Обл. НДС Кутик 100*100*7мм ст. 3Пс МІРА Надходження товарів і послуг ІБ00-000851 від 03.03.2025 18:09:07 АПК (Глобине) | D8: ВІКАНТ фірма ТОВ 10/04-1 від 10.04.2022_Глобине-2 Рахунок на оплату постачальника ІБ00-000686 від 27.02.2025 21:38:52 | E8: 205 | F8: 7470 | H8: 631 | K8: Д | L8: 501212.92
A9: 03.03.2025 | B9: Надходження товарів і послуг ІБ00-000851 від 03.03.2025 18:09:07 Оприходованы ТМЦ | C9: Обл. НДС Дріт 1,2 мм термооброблений Надходження товарів і послуг ІБ00-000851 від 03.03.2025 18:09:07 АПК (Глобине) | D9: ВІКАНТ фірма ТОВ 10/04-1 від 10.04.2022_Глобине-2 Рахунок на оплату постачальника ІБ00-000686 від 27.02.2025 21:38:52 | E9: 205 | F9: 19415.5 | H9: 631 | K9: Д | L9: 520628.42
A10: 04.03.2025 | B10: Надходження товарів і послуг ІБ00-000819 від 04.03.2025 17:40:12 Оприходованы ТМЦ | C10: Обл. НДС Прокат арматурний №18 мм А500С Надходження товарів і послуг ІБ00-000819 від 04.03.2025 17:40:12 АПК (Глобине) | D10: ВІКАНТ фірма ТОВ 10/04-1 від 10.04.2022_Глобине-2 Рахунок на оплату постачальника ІБ00-000686 від 27.02.2025 21:38:52 | E10: 205 | F10: 538278 | H10: 631 | K10: Д | L10: 1058906.4
A11: 04.03.2025 | B11: Надходження товарів і послуг ІБ00-000820 від 04.03.2025 17:40:13 Оприходованы ТМЦ | C11: Обл. НДС Прокат арматурний №14 мм А500С, 12 м Надходження товарів і послуг ІБ00-000820 від 04.03.2025 17:40:13 АПК (Глобине) | D11: ВІКАНТ фірма ТОВ 10/04-1 від 10.04.2022_Глобине-2 Рахунок на оплату постачальника ІБ00-000686 від 27.02.2025 21:38:52 | E11: 205 | F11: 77220 | H11: 631 | K11: Д | L11: 1136126.4
A12: 04.03.2025 | B12: Надходження товарів і послуг ІБ00-000820 від 04.03.2025 17:40:13 Оприходованы ТМЦ | C12: Обл. НДС Прокат арматурний №18 мм А500С Надходження товарів і послуг ІБ00-000820 від 04.03.2025 17:40:13 АПК (Глобине) | D12: ВІКАНТ фірма ТОВ 10/04-1 від 10.04.2022_Глобине-2 Рахунок на оплату постачальника ІБ00-000686 від 27.02.2025 21:38:52 | E12: 205 | F12: 415480 | H12: 631 | K12: Д | L12: 1551606.4
A13: 05.03.2025 | B13: Надходження товарів і послуг ІБ00-001071 від 05.03.2025 18:40:09 Оприходованы ТМЦ | C13: Обл. НДС Щебінь 70-120 Надходження товарів і послуг ІБ00-001071 від 05.03.2025 18:40:09 АПК (Глобине) | D13: Венкрас Авто ПП Договір 05/09/2024 від 05.09.2024_Глобине-2 Рахунок на оплату постачальника ІБ00-000881 від 05.03.2025 18:40:08 | E13: 205 | F13: 104880 | H13: 631 | K13: Д | L13: 1656486.4
A14: 05.03.2025 | B14: Надходження дод. витрат ІБ00-000149 від 05.03.2025 18:40:10 Доп. расходы при поступлении товаров | C14: Обл. НДС Щебінь 70-120 Надходження товарів і послуг ІБ00-001071 від 05.03.2025 18:40:09 АПК (Глобине) | D14: Венкрас Авто ПП Договір 05/09/2024 від 05.09.2024_Глобине-2 Рахунок на оплату постачальника ІБ00-000881 від 05.03.2025 18:40:08 | E14: 205 | F14: 52440 | H14: 631 | K14: Д | L14: 1708926.4
... A26: 26.03.2025 | B26: Надходження товарів і послуг ІБ00-001528 від 26.03.2025 11:00:00 Оприходованы ТМЦ (Зачет аванса поставщику) | C26: Обл. НДС Плівка п/е рукав 1500*200 мкм Надходження товарів і послуг ІБ00-001528 від 26.03.2025 11:00:00 АПК (Глобине) | D26: ЗАВОД ПОЛІМЕРНИХ МАТЕРІАЛІВ "МІКРОН" ТОВ РАХУНКИ_Глобине 2 Рахунок на оплату постачальника ІБ00-000968 від 25.03.2025 09:00:00 | E26: 205 | F26: 11546.72 | H26: 631 | K26: Д | L26: 2034974.8
A27: 28.03.2025 | B27: Переміщення товарів ІБ00-000262 від 28.03.2025 10:00:00 Перемещение ТМЦ | C27: Обл. НДС Щебінь 80-120 Надходження товарів і послуг ІБ00-001121 від 06.03.2025 22:00:38 Генплан митний склад (Глобине) | D27: Обл. НДС Щебінь 80-120 Надходження товарів і послуг ІБ00-001121 від 06.03.2025 22:00:38 АПК (Глобине) | E27: 205 | H27: 205 | I27: 65840 | K27: Д | L27: 1969134.8
A28: 28.03.2025 | B28: Надходження товарів і послуг ІБ00-001377 від 28.03.2025 20:00:14 Оприходованы ТМЦ | C28: Обл. НДС Труба КАН тришар 110/2000 2,7мм Надходження товарів і послуг ІБ00-001377 від 28.03.2025 20:00:14 АПК (Глобине) | D28: Лук'янець Аліна Василівна ФОП РАХУНКИ_Глобине 2 Рахунок на оплату постачальника ІБ00-001089 від 28.03.2025 20:00:13 | E28: 205 | F28: 1470 | H28: 631 | K28: Д | L28: 1970604.8
A29: 28.03.2025 | B29: Надходження товарів і послуг ІБ00-001377 від 28.03.2025 20:00:14 Оприходованы ТМЦ | C29: Обл. НДС Труба КАН внутр 110/1500 Надходження товарів і послуг ІБ00-001377 від 28.03.2025 20:00:14 АПК (Глобине) | D29: Лук'янець Аліна Василівна ФОП РАХУНКИ_Глобине 2 Рахунок на оплату постачальника ІБ00-001089 від 28.03.2025 20:00:13 | E29: 205 | F29: 2046 | H29: 631 | K29: Д | L29: 1972650.8
A30: 28.03.2025 | B30: Надходження товарів і послуг ІБ00-001377 від 28.03.2025 20:00:14 Оприходованы ТМЦ | C30: Обл. НДС Труба КАН внутр 50/1000 1,8мм Надходження товарів і послуг ІБ00-001377 від 28.03.2025 20:00:14 АПК (Глобине) | D30: Лук'янець Аліна Василівна ФОП РАХУНКИ_Глобине 2 Рахунок на оплату постачальника ІБ00-001089 від 28.03.2025 20:00:13 | E30: 205 | F30: 444 | H30: 631 | K30: Д | L30: 1973094.8
A31: 28.03.2025 | B31: Надходження товарів і послуг ІБ00-001377 від 28.03.2025 20:00:14 Оприходованы ТМЦ | C31: Обл. НДС Коліно 110/90° внутр КАН Надходження товарів і послуг ІБ00-001377 від 28.03.2025 20:00:14 АПК (Глобине) | D31: Лук'янець Аліна Василівна ФОП РАХУНКИ_Глобине 2 Рахунок на оплату постачальника ІБ00-001089 від 28.03.2025 20:00:13 | E31: 205 | F31: 166 | H31: 631 | K31: Д | L31: 1973260.8
A32: 28.03.2025 | B32: Надходження товарів і послуг ІБ00-001377 від 28.03.2025 20:00:14 Оприходованы ТМЦ | C32: Обл. НДС Трійник 110/110/90° Надходження товарів і послуг ІБ00-001377 від 28.03.2025 20:00:14 АПК (Глобине) | D32: Лук'янець Аліна Василівна ФОП РАХУНКИ_Глобине 2 Рахунок на оплату постачальника ІБ00-001089 від 28.03.2025 20:00:13 | E32: 205 | F32: 385.5 | H32: 631 | K32: Д | L32: 1973646.3
A33: 28.03.2025 | B33: Надходження товарів і послуг ІБ00-001377 від 28.03.2025 20:00:14 Оприходованы ТМЦ | C33: Обл. НДС Трійник 110/50/90° Надходження товарів і послуг ІБ00-001377 від 28.03.2025 20:00:14 АПК (Глобине) | D33: Лук'янець Аліна Василівна ФОП РАХУНКИ_Глобине 2 Рахунок на оплату постачальника ІБ00-001089 від 28.03.2025 20:00:13 | E33: 205 | F33: 191 | H33: 631 | K33: Д | L33: 1973837.3
A34: 28.03.2025 | B34: Надходження товарів і послуг ІБ00-001377 від 28.03.2025 20:00:14 Оприходованы ТМЦ | C34: Обл. НДС Трійник 50/50/90° внутр Надходження товарів і послуг ІБ00-001377 від 28.03.2025 20:00:14 АПК (Глобине) | D34: Лук'янець Аліна Василівна ФОП РАХУНКИ_Глобине 2 Рахунок на оплату постачальника ІБ00-001089 від 28.03.2025 20:00:13 | E34: 205 | F34: 75 | H34: 631 | K34: Д | L34: 1973912.3
A35: 28.03.2025 | B35: Надходження товарів і послуг ІБ00-001377 від 28.03.2025 20:00:14 Оприходованы ТМЦ | C35: Обл. НДС Коліно каналіз. 50/90 Надходження товарів і послуг ІБ00-001377 від 28.03.2025 20:00:14 АПК (Глобине) | D35: Лук'янець Аліна Василівна ФОП РАХУНКИ_Глобине 2 Рахунок на оплату постачальника ІБ00-001089 від 28.03.2025 20:00:13 | E35: 205 | F35: 52 | H35: 631 | K35: Д | L35: 1973964.3
A36: 28.03.2025 | B36: Надходження товарів і послуг ІБ00-001377 від 28.03.2025 20:00:14 Оприходованы ТМЦ | C36: Обл. НДС Труба ППР 40*5,5 P16Ek SDR7.6 Надходження товарів і послуг ІБ00-001377 від 28.03.2025 20:00:14 АПК (Глобине) | D36: Лук'янець Аліна Василівна ФОП РАХУНКИ_Глобине 2 Рахунок на оплату постачальника ІБ00-001089 від 28.03.2025 20:00:13 | E36: 205 | F36: 1404 | H36: 631 | K36: Д | L36: 1975368.3
A37: 28.03.2025 | B37: Надходження товарів і послуг ІБ00-001377 від 28.03.2025 20:00:14 Оприходованы ТМЦ | C37: Обл. НДС Труба ППР 50*8,3 PN20Ek SDR6 Надходження товарів і послуг ІБ00-001377 від 28.03.2025 20:00:14 АПК (Глобине) | D37: Лук'янець Аліна Василівна ФОП РАХУНКИ_Глобине 2 Рахунок на оплату постачальника ІБ00-001089 від 28.03.2025 20:00:13 | E37: 205 | F37: 2445 | H37: 631 | K37: Д | L37: 1977813.3
A38: 28.03.2025 | B38: Надходження товарів і послуг ІБ00-001377 від 28.03.2025 20:00:14 Оприходованы ТМЦ | C38: Обл. НДС Кут ППР 40*90° Надходження товарів і послуг ІБ00-001377 від 28.03.2025 20:00:14 АПК (Глобине) | D38: Лук'янець Аліна Василівна ФОП РАХУНКИ_Глобине 2 Рахунок на оплату постачальника ІБ00-001089 від 28.03.2025 20:00:13 | E38: 205 | F38: 324 | H38: 631 | K38: Д | L38: 1978137.3
A39: 28.03.2025 | B39: Надходження товарів і послуг ІБ00-001377 від 28.03.2025 20:00:14 Оприходованы ТМЦ | C39: Обл. НДС Кут ППР 50*90° Надходження товарів і послуг ІБ00-001377 від 28.03.2025 20:00:14 АПК (Глобине) | D39: Лук'янець Аліна Василівна ФОП РАХУНКИ_Глобине 2 Рахунок на оплату постачальника ІБ00-001089 від 28.03.2025 20:00:13 | E39: 205 | F39: 420 | H39: 631 | K39: Д | L39: 1978557.3
A40: Обороти за період та сальдо на кінець | E40: 2034127.1 | H40: 65840 | K40: Д | L40: 1978557.3

Sheet ГП мытный
A1: Період | B1: Документ | C1: Аналітика Дт | D1: Аналітика Кт | E1: Дебет | H1: Кредит | K1: Поточне сальдо
E2: Рахунок | H2: Рахунок
A3: 06.03.2025 | B3: Переміщення товарів ІБ00-000221 від 06.03.2025 22:00:40 Перемещение ТМЦ | C3: Обл. НДС Щебінь 80-120 Надходження товарів і послуг ІБ00-001121 від 06.03.2025 22:00:38 Генплан митний склад (Глобине) | D3: Обл. НДС Щебінь 80-120 Надходження товарів і послуг ІБ00-001121 від 06.03.2025 22:00:38 Глобине-2 | E3: 205 | F3: 5115.77 | H3: 205 | K3: Д | L3: 5115.77
A4: 07.03.2025 | B4: Надходження товарів і послуг ІБ00-001122 від 07.03.2025 20:00:21 Оприходованы ТМЦ | C4: Обл. НДС Щебінь 80-120 Надходження товарів і послуг ІБ00-001122 від 07.03.2025 20:00:21 Генплан митний склад (Глобине) | D4: ДІОРИТ ТОВ №06/04-11 від 04.11.2024 Глобине-2 Рахунок на оплату постачальника ІБ00-000908 від 06.03.2025 22:00:37 | E4: 205 | F4: 71851.19 | H4: 631 | K4: Д | L4: 76966.96
A5: 10.03.2025 | B5: Надходження товарів і послуг ІБ00-001124 від 10.03.2025 20:00:32 Оприходованы ТМЦ | C5: Обл. НДС Щебінь 80-120 Надходження товарів і послуг ІБ00-001124 від 10.03.2025 20:00:32 Генплан митний склад (Глобине) | D5: ДІОРИТ ТОВ №06/04-11 від 04.11.2024 Глобине-2 Рахунок на оплату постачальника ІБ00-000908 від 06.03.2025 22:00:37 | E5: 205 | F5: 70672.66 | H5: 631 | K5: Д | L5: 147639.62
A6: 11.03.2025 | B6: Надходження товарів і послуг ІБ00-001123 від 11.03.2025 19:00:18 Оприходованы ТМЦ | C6: Обл. НДС Щебінь 80-120 Надходження товарів і послуг ІБ00-001123 від 11.03.2025 19:00:18 Генплан митний склад (Глобине) | D6: ДІОРИТ ТОВ №06/04-11 від 04.11.2024 Глобине-2 Рахунок на оплату постачальника ІБ00-000908 від 06.03.2025 22:00:37 | E6: 205 | F6: 71831.44 | H6: 631 | K6: Д | L6: 219471.06
A7: 12.03.2025 | B7: Переміщення товарів ІБ00-000200 від 12.03.2025 18:45:22 Перемещение ТМЦ | C7: Обл. НДС Провід ПВС 3*2,5 бухта 100м Надходження товарів і послуг ІБ00-001045 від 12.03.2025 18:45:21 Генплан митний склад (Глобине) | D7: Обл. НДС Провід ПВС 3*2,5 бухта 100м Надходження товарів і послуг ІБ00-001045 від 12.03.2025 18:45:21 Глобине-2 | E7: 205 | F7: 13384.35 | H7: 205 | K7: Д | L7: 232855.41
A8: 13.03.2025 | B8: Переміщення товарів ІБ00-000294 від 13.03.2025 11:10:00 Перемещение ТМЦ | C8: Обл. НДС Щебінь 10-20 Надходження товарів і послуг ІБ00-001478 від 13.03.2025 11:00:00 Генплан митний склад (Глобине) | D8: Обл. НДС Щебінь 10-20 Надходження товарів і послуг ІБ00-001478 від 13.03.2025 11:00:00 Глобине-2 | E8: 205 | F8: 38140.28 | H8: 205 | K8: Д | L8: 270995.69
A9: 14.03.2025 | B9: Надходження товарів і послуг ІБ00-001074 від 14.03.2025 17:50:42 Оприходованы ТМЦ | C9: Обл. НДС Завіса точена 20*100 прес Надходження товарів і послуг ІБ00-001074 від 14.03.2025 17:50:42 Генплан митний склад (Глобине) | D9: Моноліт - Центр" ТОВ Рахунки_Глобине-2 Рахунок на оплату постачальника ІБ00-000883 від 13.03.2025 18:54:58 | E9: 205 | F9: 633.6 | H9: 631 | K9: Д | L9: 271629.29
A10: 14.03.2025 | B10: Надходження товарів і послуг ІБ00-001074 від 14.03.2025 17:50:42 Оприходованы ТМЦ | C10: Обл. НДС Сітка рабиця д=2,0мм яч 50*50мм оц 2,0*10м Надходження товарів і послуг ІБ00-001074 від 14.03.2025 17:50:42 Генплан митний склад (Глобине) | D10: Моноліт - Центр" ТОВ Рахунки_Глобине-2 Рахунок на оплату постачальника ІБ00-000883 від 13.03.2025 18:54:58 | E10: 205 | F10: 35616.4 | H10: 631 | K10: Д | L10: 307245.69
A11: 14.03.2025 | B11: Надходження товарів і послуг ІБ00-001074 від 14.03.2025 17:50:42 Оприходованы ТМЦ | C11: Обл. НДС Прожектор LED200W 6000К 16000Lm Надходження товарів і послуг ІБ00-001074 від 14.03.2025 17:50:42 Генплан митний склад (Глобине) | D11: Моноліт - Центр" ТОВ Рахунки_Глобине-2 Рахунок на оплату постачальника ІБ00-000883 від 13.03.2025 18:54:58 | E11: 205 | F11: 16569.95 | H11: 631 | K11: Д | L11: 323815.64
A12: 14.03.2025 | B12: Надходження товарів і послуг ІБ00-001214 від 14.03.2025 17:51:06 Оприходованы ТМЦ (Зачет аванса поставщику) | C12: Обл. НДС Дріт колючо-ріжуч спіраль діам кільця=500мм/3скоби 10м Надходження товарів і послуг ІБ00-001214 від 14.03.2025 17:51:06 Генплан митний склад (Глобине) | D12: Сітка Захід Україна ТОВ Договір 19/09/24 від 19.09.2024_Глобине 2 Рахунок на оплату постачальника ІБ00-000851 від 12.03.2025 18:45:14 | E12: 205 | F12: 15750 | H12: 631 | K12: Д | L12: 339565.64
A13: 14.03.2025 | B13: Надходження товарів і послуг ІБ00-001214 від 14.03.2025 17:51:06 Оприходованы ТМЦ (Зачет аванса поставщику) | C13: Обл. НДС Наконечник Г-подібний 500мм 60*40мм/1,7мм оц 6005 зелений Надходження товарів і послуг ІБ00-001214 від 14.03.2025 17:51:06 Генплан митний склад (Глобине) | D13: Сітка Захід Україна ТОВ Договір 19/09/24 від 19.09.2024_Глобине 2 Рахунок на оплату постачальника ІБ00-000851 від 12.03.2025 18:45:14 | E13: 205 | F13: 7881.61 | H13: 631 | K13: Д | L13: 347447.25
A14: 14.03.2025 | B14: Надходження товарів і послуг ІБ00-001215 від 14.03.2025 17:51:07 Оприходованы ТМЦ (Зачет аванса поставщику) | C14: Обл. НДС Секція 200*50 мм 4,00мм/4,00 мм 2,43м/2,5 м оц зелений 6005 Надходження товарів і послуг ІБ00-001215 від 14.03.2025 17:51:07 Генплан митний склад (Глобине) | D14: Сітка Захід Україна ТОВ Договір 19/09/24 від 19.09.2024_Глобине 2 Рахунок на оплату постачальника ІБ00-000849 від 12.03.2025 18:45:13 | E14: 205 | F14: 33156.01 | H14: 631 | K14: Д | L14: 380603.26
... A36: 28.03.2025 | B36: Переміщення товарів ІБ00-000265 від 28.03.2025 10:00:00 Перемещение ТМЦ | C36: Обл. НДС Плита OSB 18 мм Надходження товарів і послуг ІБ00-000072 від 01.01.2025 18:00:10 Генплан митний склад (Глобине) | D36: Обл. НДС Плита OSB 18 мм Надходження товарів і послуг ІБ00-000072 від 01.01.2025 18:00:10 Котельна (Глобине) | E36: 205 | F36: 3596 | H36: 205 | K36: Д | L36: 631779.56
A37: 28.03.2025 | B37: Вимога-накладна ІБ00-000239 від 28.03.2025 20:00:00 Списаны ТМЦ | C37: Обл. НДС Виробничий (Глобине-2) Глобине-2 Прямі материальні виробничі витрати крім зворотніх відходів | D37: Обл. НДС Щебінь 80-120 Надходження товарів і послуг ІБ00-001121 від 06.03.2025 22:00:38 Генплан митний склад (Глобине) | E37: 231 | H37: 205 | I37: 70672.66 | K37: Д | L37: 561106.9
A38: 28.03.2025 | B38: Вимога-накладна ІБ00-000239 від 28.03.2025 20:00:00 Списаны ТМЦ | C38: Обл. НДС Виробничий (Глобине-2) Глобине-2 Прямі материальні виробничі витрати крім зворотніх відходів | D38: Обл. НДС Щебінь 80-120 Надходження товарів і послуг ІБ00-001121 від 06.03.2025 22:00:38 Генплан митний склад (Глобине) | E38: 231 | H38: 205 | I38: 283.11 | K38: Д | L38: 560823.79
A39: 28.03.2025 | B39: Вимога-накладна ІБ00-000239 від 28.03.2025 20:00:00 Списаны ТМЦ | C39: Обл. НДС Виробничий (Глобине-2) Глобине-2 Прямі материальні виробничі витрати крім зворотніх відходів | D39: Обл. НДС Щебінь 80-120 Надходження товарів і послуг ІБ00-001122 від 07.03.2025 20:00:21 Генплан митний склад (Глобине) | E39: 231 | H39: 205 | I39: 71548.33 | K39: Д | L39: 489275.46
A40: 28.03.2025 | B40: Вимога-накладна ІБ00-000239 від 28.03.2025 20:00:00 Списаны ТМЦ | C40: Обл. НДС Виробничий (Глобине-2) Глобине-2 Прямі материальні виробничі витрати крім зворотніх відходів | D40: Обл. НДС Щебінь 80-120 Надходження товарів і послуг ІБ00-001122 від 07.03.2025 20:00:21 Генплан митний склад (Глобине) | E40: 231 | H40: 205 | I40: 302.86 | K40: Д | L40: 488972.6
A41: 28.03.2025 | B41: Вимога-накладна ІБ00-000239 від 28.03.2025 20:00:00 Списаны ТМЦ | C41: Обл. НДС Виробничий (Глобине-2) Глобине-2 Прямі материальні виробничі витрати крім зворотніх відходів | D41: Обл. НДС Щебінь 80-120 Надходження товарів і послуг ІБ00-001124 від 10.03.2025 20:00:32 Генплан митний склад (Глобине) | E41: 231 | H41: 205 | I41: 4812.9 | K41: Д | L41: 484159.7
A42: 28.03.2025 | B42: Вимога-накладна ІБ00-000239 від 28.03.2025 20:00:00 Списаны ТМЦ | C42: Обл. НДС Виробничий (Глобине-2) Глобине-2 Прямі материальні виробничі витрати крім зворотніх відходів | D42: Обл. НДС Щебінь 80-120 Надходження товарів і послуг ІБ00-001124 від 10.03.2025 20:00:32 Генплан митний склад (Глобине) | E42: 231 | H42: 205 | I42: 65859.76 | K42: Д | L42: 418299.94
A43: 28.03.2025 | B43: Вимога-накладна ІБ00-000239 від 28.03.2025 20:00:00 Списаны ТМЦ | C43: Обл. НДС Виробничий (Глобине-2) Глобине-2 Прямі материальні виробничі витрати крім зворотніх відходів | D43: Обл. НДС Щебінь 80-120 Надходження товарів і послуг ІБ00-001123 від 11.03.2025 19:00:18 Генплан митний склад (Глобине) | E43: 231 | H43: 205 | I43: 5991.44 | K43: Д | L43: 412308.5
A44: 28.03.2025 | B44: Вимога-накладна ІБ00-000239 від 28.03.2025 20:00:00 Списаны ТМЦ | C44: Обл. НДС Виробничий (Глобине-2) Глобине-2 Прямі материальні виробничі витрати крім зворотніх відходів | D44: Обл. НДС Щебінь 80-120 Надходження товарів і послуг ІБ00-001123 від 11.03.2025 19:00:18 Генплан митний склад (Глобине) | E44: 231 | H44: 205 | I44: 65840 | K44: Д | L44: 346468.5
A45: 28.03.2025 | B45: Вимога-накладна ІБ00-000239 від 28.03.2025 20:00:00 Списаны ТМЦ | C45: Обл. НДС Виробничий (Глобине-2) Глобине-2 Прямі материальні виробничі витрати крім зворотніх відходів | D45: Обл. НДС Щебінь 10-20 Надходження товарів і послуг ІБ00-001478 від 13.03.2025 11:00:00 Генплан митний склад (Глобине) | E45: 231 | H45: 205 | I45: 38140.28 | K45: Д | L45: 308328.22
A46: 28.03.2025 | B46: Вимога-накладна ІБ00-000239 від 28.03.2025 20:00:00 Списаны ТМЦ | C46: Обл. НДС Виробничий (Глобине-2) Глобине-2 Прямі материальні виробничі витрати крім зворотніх відходів | D46: Обл. НДС Щебінь 10-20 Надходження товарів і послуг ІБ00-001193 від 21.03.2025 19:26:03 Генплан митний склад (Глобине) | E46: 231 | H46: 205 | I46: 15336 | K46: Д | L46: 292992.22
A47: 28.03.2025 | B47: Вимога-накладна ІБ00-000239 від 28.03.2025 20:00:00 Списаны ТМЦ | C47: Обл. НДС Виробничий (Глобине-2) Глобине-2 Прямі материальні виробничі витрати крім зворотніх відходів | D47: Обл. НДС Завіса точена 20*100 прес Надходження товарів і послуг ІБ00-001074 від 14.03.2025 17:50:42 Генплан митний склад (Глобине) | E47: 231 | H47: 205 | I47: 633.6 | K47: Д | L47: 292358.62
A48: 28.03.2025 | B48: Вимога-накладна ІБ00-000239 від 28.03.2025 20:00:00 Списаны ТМЦ | C48: Обл. НДС Виробничий (Глобине-2) Глобине-2 Прямі материальні виробничі витрати крім зворотніх відходів | D48: Обл. НДС Сітка рабиця д=2,0мм яч 50*50мм оц 2,0*10м Надходження товарів і послуг ІБ00-001074 від 14.03.2025 17:50:42 Генплан митний склад (Глобине) | E48: 231 | H48: 205 | I48: 35616.4 | K48: Д | L48: 256742.22
... A62: 28.03.2025 | B62: Вимога-накладна ІБ00-000239 від 28.03.2025 20:00:00 Списаны ТМЦ | C62: Обл. НДС Виробничий (Глобине-2) Глобине-2 Прямі материальні виробничі витрати крім зворотніх відходів | D62: Обл. НДС Провід ПВС 3*2,5 бухта 100м Надходження товарів і послуг ІБ00-001045 від 12.03.2025 18:45:21 Генплан митний склад (Глобине) | E62: 231 | H62: 205 | I62: 11153.62 | K62: Д | L62: 100850.45
A63: 28.03.2025 | B63: Надходження товарів і послуг ІБ00-001387 від 28.03.2025 20:00:20 Оприходованы ТМЦ | C63: Обл. НДС Щебінь 10-20 Надходження товарів і послуг ІБ00-001387 від 28.03.2025 20:00:20 Генплан митний склад (Глобине) | D63: Венкрас Авто ПП Договір 05/09/2024 від 05.09.2024_Глобине-2 Рахунок на оплату постачальника ІБ00-001094 від 28.03.2025 20:00:19 | E63: 205 | F63: 9310 | H63: 631 | K63: Д | L63: 110160.45
A64: 28.03.2025 | B64: Надходження дод. витрат ІБ00-000197 від 28.03.2025 20:00:21 Доп. расходы при поступлении товаров | C64: Обл. НДС Щебінь 10-20 Надходження товарів і послуг ІБ00-001387 від 28.03.2025 20:00:20 Генплан митний склад (Глобине) | D64: Венкрас Авто ПП Договір 05/09/2024 від 05.09.2024_Глобине-2 Рахунок на оплату постачальника ІБ00-001094 від 28.03.2025 20:00:19 | E64: 205 | F64: 5054 | H64: 631 | K64: Д | L64: 115214.45
A65: 28.03.2025 | B65: Надходження товарів і послуг ІБ00-001429 від 28.03.2025 20:00:27 Оприходованы ТМЦ (Зачет аванса поставщику) | C65: Обл. НДС Емаль ПФ-115 RAL 6005 Надходження товарів і послуг ІБ00-001429 від 28.03.2025 20:00:27 Генплан митний склад (Глобине) | D65: Синтез ЛКМ РАХУНКИ_Глобино-2 Рахунок на оплату постачальника ІБ00-001034 від 27.03.2025 18:14:41 | E65: 205 | F65: 591.65 | H65: 631 | K65: Д | L65: 115806.1
A66: 28.03.2025 | B66: Надходження товарів і послуг ІБ00-001429 від 28.03.2025 20:00:27 Оприходованы ТМЦ (Зачет аванса поставщику) | C66: Обл. НДС Розчинник "White Spirit" (л) Надходження товарів і послуг ІБ00-001429 від 28.03.2025 20:00:27 Генплан митний склад (Глобине) | D66: Синтез ЛКМ РАХУНКИ_Глобино-2 Рахунок на оплату постачальника ІБ00-001034 від 27.03.2025 18:14:41 | E66: 205 | F66: 3542 | H66: 631 | K66: Д | L66: 119348.1
A67: Обороти за період та сальдо на кінець | E67: 650277.21 | H67: 530929.11 | K67: Д | L67: 119348.1
J69: =SUBTOTAL(9,I19:J64) -> 530929.11

Sheet ГП Стена
A1: Період | B1: Документ | C1: Аналітика Дт | D1: Аналітика Кт | E1: Дебет | H1: Кредит | K1: Поточне сальдо
E2: Рахунок | H2: Рахунок
A3: 01.03.2025 | B3: Переміщення товарів ІБ00-000154 від 01.03.2025 18:15:00 Перемещение ТМЦ | C3: Обл. НДС Бетон С20/25 W6 F75 P4 доб-10 з фіброю Надходження товарів і послуг ІБ00-000752 від 01.03.2025 18:10:01 Генплан підпірна стінка (Глобине) | D3: Обл. НДС Бетон С20/25 W6 F75 P4 доб-10 з фіброю Надходження товарів і послуг ІБ00-000752 від 01.03.2025 18:10:01 Глобине-2 | E3: 205 | F3: 32716.13 | H3: 205 | K3: Д | L3: 99176.49
A4: 01.03.2025 | B4: Надходження товарів і послуг ІБ00-001072 від 01.03.2025 18:17:15 Оприходованы ТМЦ | C4: Обл. НДС Фібра поліпропілен 12мм Надходження товарів і послуг ІБ00-001072 від 01.03.2025 18:17:15 Генплан підпірна стінка (Глобине) | D4: ПРОТЕК-С ТОВ Дог поставки № 217 від 20.01.21 р. Рах_Глобине-2 Рахунок на оплату постачальника ІБ00-000882 від 01.03.2025 18:17:14 | E4: 205 | F4: 8491.5 | H4: 631 | K4: Д | L4: 107667.99
A5: 05.03.2025 | B5: Вимога-накладна ІБ00-000144 від 05.03.2025 00:00:00 Списаны ТМЦ | C5: Обл. НДС Виробничий (Глобине-2) Глобине-2 Прямі материальні виробничі витрати крім зворотніх відходів | D5: Обл. НДС Щебінь 20-40 Надходження товарів і послуг ІБ00-006317 від 18.12.2024 18:00:25 Генплан підпірна стінка (Глобине) | E5: 231 | H5: 205 | I5: 28317.33 | K5: Д | L5: 79350.66
A6: 05.03.2025 | B6: Вимога-накладна ІБ00-000144 від 05.03.2025 00:00:00 Списаны ТМЦ | C6: Обл. НДС Виробничий (Глобине-2) Глобине-2 Прямі материальні виробничі витрати крім зворотніх відходів | D6: Обл. НДС Щебінь 20-40 Надходження товарів і послуг ІБ00-000759 від 21.02.2025 18:26:12 Генплан підпірна стінка (Глобине) | E6: 231 | H6: 205 | I6: 1982.67 | K6: Д | L6: 77367.99
A7: 05.03.2025 | B7: Вимога-накладна ІБ00-000144 від 05.03.2025 00:00:00 Списаны ТМЦ | C7: Обл. НДС Виробничий (Глобине-2) Глобине-2 Прямі материальні виробничі витрати крім зворотніх відходів | D7: Обл. НДС Щебінь 20-40 Надходження товарів і послуг ІБ00-000759 від 21.02.2025 18:26:12 Генплан підпірна стінка (Глобине) | E7: 231 | H7: 205 | I7: 14090.66 | K7: Д | L7: 63277.33
A8: 05.03.2025 | B8: Вимога-накладна ІБ00-000144 від 05.03.2025 00:00:00 Списаны ТМЦ | C8: Обл. НДС Виробничий (Глобине-2) Глобине-2 Прямі материальні виробничі витрати крім зворотніх відходів | D8: Обл. НДС Щебінь 20-40 Надходження товарів і послуг ІБ00-000760 від 21.02.2025 18:26:15 Генплан підпірна стінка (Глобине) | E8: 231 | H8: 205 | I8: 8145.83 | K8: Д | L8: 55131.5
A9: 05.03.2025 | B9: Вимога-накладна ІБ00-000144 від 05.03.2025 00:00:00 Списаны ТМЦ | C9: Обл. НДС Виробничий (Глобине-2) Глобине-2 Прямі материальні виробничі витрати крім зворотніх відходів | D9: Обл. НДС Щебінь 20-40 Надходження товарів і послуг ІБ00-000761 від 22.02.2025 20:10:02 Генплан підпірна стінка (Глобине) | E9: 231 | H9: 205 | I9: 60 | K9: Д | L9: 55071.5
A10: 05.03.2025 | B10: Вимога-накладна ІБ00-000144 від 05.03.2025 00:00:00 Списаны ТМЦ | C10: Обл. НДС Виробничий (Глобине-2) Глобине-2 Прямі материальні виробничі витрати крім зворотніх відходів | D10: Обл. НДС Щебінь 40-70 Надходження товарів і послуг ІБ00-000486 від 24.01.2025 22:10:39 Генплан підпірна стінка (Глобине) | E10: 231 | H10: 205 | I10: 3864 | K10: Д | L10: 51207.5
A11: 05.03.2025 | B11: Вимога-накладна ІБ00-000144 від 05.03.2025 00:00:00 Списаны ТМЦ | C11: Обл. НДС Виробничий (Глобине-2) Глобине-2 Прямі материальні виробничі витрати крім зворотніх відходів | D11: Обл. НДС Щебінь 40-70 Надходження товарів і послуг ІБ00-000486 від 24.01.2025 22:10:39 Генплан підпірна стінка (Глобине) | E11: 231 | H11: 205 | I11: 4124.67 | K11: Д | L11: 47082.83
A12: 05.03.2025 | B12: Вимога-накладна ІБ00-000144 від 05.03.2025 00:00:00 Списаны ТМЦ | C12: Обл. НДС Виробничий (Глобине-2) Глобине-2 Прямі материальні виробничі витрати крім зворотніх відходів | D12: Обл. НДС Щебінь 40-70 Надходження товарів і послуг ІБ00-000485 від 25.01.2025 18:00:05 Генплан підпірна стінка (Глобине) | E12: 231 | H12: 205 | I12: 3864 | K12: Д | L12: 43218.83
A13: 05.03.2025 | B13: Вимога-накладна ІБ00-000144 від 05.03.2025 00:00:00 Списаны ТМЦ | C13: Обл. НДС Виробничий (Глобине-2) Глобине-2 Прямі материальні виробничі витрати крім зворотніх відходів | D13: Обл. НДС Пісок з відсіву дроблення щебеню фр. 0-5мм. Надходження товарів і послуг ІБ00-000257 від 27.01.2025 18:19:37 Генплан підпірна стінка (Глобине) | E13: 231 | H13: 205 | I13: 1250 | K13: Д | L13: 41968.83
A14: 13.03.2025 | B14: Переміщення товарів ІБ00-000213 від 13.03.2025 18:55:03 Перемещение ТМЦ | C14: Обл. НДС Бетон С20/25 W6 F75 P4 Надходження товарів і послуг ІБ00-001088 від 12.03.2025 18:45:33 Генплан підпірна стінка (Глобине) | D14: Обл. НДС Бетон С20/25 W6 F75 P4 Надходження товарів і послуг ІБ00-001088 від 12.03.2025 18:45:33 Глобине-2 | E14: 205 | F14: 1751.64 | H14: 205 | K14: Д | L14: 43720.47
A15: 13.03.2025 | B15: Переміщення товарів ІБ00-000213 від 13.03.2025 18:55:03 Перемещение ТМЦ | C15: Обл. НДС Бетон С20/25 W6 F75 P4 Надходження товарів і послуг ІБ00-001089 від 13.03.2025 18:55:01 Генплан підпірна стінка (Глобине) | D15: Обл. НДС Бетон С20/25 W6 F75 P4 Надходження товарів і послуг ІБ00-001089 від 13.03.2025 18:55:01 Глобине-2 | E15: 205 | F15: 125374.85 | H15: 205 | K15: Д | L15: 169095.32
A16: 18.03.2025 | B16: Переміщення товарів ІБ00-000301 від 18.03.2025 11:10:00 Перемещение ТМЦ | C16: Обл. НДС Щебінь 20-40 Надходження товарів і послуг ІБ00-001482 від 18.03.2025 11:00:00 Генплан підпірна стінка (Глобине) | D16: Обл. НДС Щебінь 20-40 Надходження товарів і послуг ІБ00-001482 від 18.03.2025 11:00:00 Глобине-2 | E16: 205 | F16: 27724.19 | H16: 205 | K16: Д | L16: 196819.51
A17: 28.03.2025 | B17: Вимога-накладна ІБ00-000227 від 28.03.2025 08:12:06 Списаны ТМЦ | C17: Обл. НДС Виробничий (Глобине-2) Глобине-2 Прямі материальні виробничі витрати крім зворотніх відходів | D17: Обл. НДС Бетон С20/25 W6 F75 P4 доб-10 з фіброю Надходження товарів і послуг ІБ00-000752 від 01.03.2025 18:10:01 Генплан підпірна стінка (Глобине) | E17: 231 | H17: 205 | I17: 32716.13 | K17: Д | L17: 164103.38
A18: 28.03.2025 | B18: Вимога-накладна ІБ00-000227 від 28.03.2025 08:12:06 Списаны ТМЦ | C18: Обл. НДС Виробничий (Глобине-2) Глобине-2 Прямі материальні виробничі витрати крім зворотніх відходів | D18: Обл. НДС Бетон С20/25 W6 F75 P4 Надходження товарів і послуг ІБ00-001088 від 12.03.2025 18:45:33 Генплан підпірна стінка (Глобине) | E18: 231 | H18: 205 | I18: 1751.64 | K18: Д | L18: 162351.74
A19: 28.03.2025 | B19: Списання товарів ІБ00-000159 від 28.03.2025 08:16:03 Списаны ТМЦ | C19: Обл. НДС Виробничий (Глобине-2) Глобине-2 Прямі материальні виробничі витрати крім зворотніх відходів | D19: Обл. НДС Шуруп г/к по дереву 3,5*55 мм Надходження товарів і послуг ІБ00-000200 від 21.01.2025 18:10:15 Генплан підпірна стінка (Глобине) | E19: 231 | H19: 205 | I19: 396.2 | K19: Д | L19: 161955.54
A20: 28.03.2025 | B20: Списання товарів ІБ00-000159 від 28.03.2025 08:16:03 Списаны ТМЦ | C20: Обл. НДС Виробничий (Глобине-2) Глобине-2 Прямі материальні виробничі витрати крім зворотніх відходів | D20: Обл. НДС Шуруп г/к по дереву 4,2*76 мм Надходження товарів і послуг ІБ00-000200 від 21.01.2025 18:10:15 Генплан підпірна стінка (Глобине) | E20: 231 | H20: 205 | I20: 365 | K20: Д | L20: 161590.54
A21: Обороти за період та сальдо на кінець | E21: 196058.31 | H21: 100928.13 | K21: Д | L21: 161590.54
J23: =SUBTOTAL(9,I5:J20) -> 100928.13

Sheet Глобине-2
A1: Період | B1: Документ | C1: Аналітика Дт | D1: Аналітика Кт | E1: Дебет | H1: Кредит | K1: Поточне сальдо
E2: Рахунок | H2: Рахунок
A3: 01.03.2025 | B3: Надходження товарів і послуг ІБ00-000751 від 01.03.2025 18:00:01 Оприходованы ТМЦ (Зачет аванса поставщику) | C3: Обл. НДС Бетон С20/25 W6 F75 P4 доб-10 Надходження товарів і послуг ІБ00-000751 від 01.03.2025 18:00:01 Глобине-2 | D3: Кременчуцький річковий порт ПРАТ Договір 112/Б від 15.10.2024_Глобине-2 Списання з банківського рахунку 00000002483 від 28.02.2025 16:06:07 | E3: 205 | F3: 98089 | H3: 631 | K3: Д | L3: 330496.68
A4: 01.03.2025 | B4: Надходження товарів і послуг ІБ00-000751 від 01.03.2025 18:00:01 Оприходованы ТМЦ (Зачет аванса поставщику) | C4: Обл. НДС Бетон С20/25 W6 F75 P4 доб-10 Надходження товарів і послуг ІБ00-000751 від 01.03.2025 18:00:01 Глобине-2 | D4: Кременчуцький річковий порт ПРАТ Договір 112/Б від 15.10.2024_Глобине-2 Списання з банківського рахунку 00000001686 від 07.02.2025 17:38:53 | E4: 205 | F4: 39681 | H4: 631 | K4: Д | L4: 370177.68
A5: 01.03.2025 | B5: Надходження дод. витрат ІБ00-000105 від 01.03.2025 18:00:02 Доп. расходы при поступлении товаров (Зачет аванса поставщику) | C5: Обл. НДС Бетон С20/25 W6 F75 P4 доб-10 Надходження товарів і послуг ІБ00-000751 від 01.03.2025 18:00:01 Глобине-2 | D5: Кременчуцький річковий порт ПРАТ Договір 112/Б від 15.10.2024_Глобине-2 Списання з банківського рахунку 00000002483 від 28.02.2025 16:06:07 | E5: 205 | F5: 41129.5 | H5: 631 | K5: Д | L5: 411307.18
A6: 01.03.2025 | B6: Переміщення товарів ІБ00-000151 від 01.03.2025 18:10:00 Перемещение ТМЦ | C6: Обл. НДС Бетон С20/25 W6 F75 P4 доб-10 Надходження товарів і послуг ІБ00-000545 від 15.02.2025 10:00:05 Резервуар для зберігання розчинника(Глобине) | D6: Обл. НДС Бетон С20/25 W6 F75 P4 доб-10 Надходження товарів і послуг ІБ00-000545 від 15.02.2025 10:00:05 Глобине-2 | E6: 205 | H6: 205 | I6: 3599.86 | K6: Д | L6: 407707.32
A7: 01.03.2025 | B7: Переміщення товарів ІБ00-000151 від 01.03.2025 18:10:00 Перемещение ТМЦ | C7: Обл. НДС Бетон С20/25 W6 F75 P4 доб-10 Надходження товарів і послуг ІБ00-000751 від 01.03.2025 18:00:01 Резервуар для зберігання розчинника(Глобине) | D7: Обл. НДС Бетон С20/25 W6 F75 P4 доб-10 Надходження товарів і послуг ІБ00-000751 від 01.03.2025 18:00:01 Глобине-2 | E7: 205 | H7: 205 | I7: 65702.79 | K7: Д | L7: 342004.53
A8: 01.03.2025 | B8: Переміщення товарів ІБ00-000152 від 01.03.2025 18:10:00 Перемещение ТМЦ | C8: Обл. НДС Бетон С20/25 W6 F75 P4 доб-10 Надходження товарів і послуг ІБ00-000751 від 01.03.2025 18:00:01 Резервуарний парк соєвої меляси (Глобине) | D8: Обл. НДС Бетон С20/25 W6 F75 P4 доб-10 Надходження товарів і послуг ІБ00-000751 від 01.03.2025 18:00:01 Глобине-2 | E8: 205 | H8: 205 | I8: 101894.93 | K8: Д | L8: 240109.6
A9: 01.03.2025 | B9: Переміщення товарів ІБ00-000153 від 01.03.2025 18:10:00 Перемещение ТМЦ | C9: Обл. НДС Бетон С20/25 W6 F75 P4 доб-10 Надходження товарів і послуг ІБ00-000751 від 01.03.2025 18:00:01 Котельна (Глобине) | D9: Обл. НДС Бетон С20/25 W6 F75 P4 доб-10 Надходження товарів і послуг ІБ00-000751 від 01.03.2025 18:00:01 Глобине-2 | E9: 205 | H9: 205 | I9: 7389.33 | K9: Д | L9: 232720.27
A10: 01.03.2025 | B10: Надходження товарів і послуг ІБ00-000752 від 01.03.2025 18:10:01 Оприходованы ТМЦ | C10: Обл. НДС Бетон С20/25 W6 F75 P4 доб-10 з фіброю Надходження товарів і послуг ІБ00-000752 від 01.03.2025 18:10:01 Глобине-2 | D10: Кременчуцький річковий порт ПРАТ Договір 112/Б від 15.10.2024_Глобине-2 Надходження товарів і послуг ІБ00-000752 від 01.03.2025 18:10:01 | E10: 205 | F10: 24160 | H10: 631 | K10: Д | L10: 256880.27
A11: 01.03.2025 | B11: Надходження дод. витрат ІБ00-000106 від 01.03.2025 18:10:02 Доп. расходы при поступлении товаров | C11: Обл. НДС Бетон С20/25 W6 F75 P4 доб-10 з фіброю Надходження товарів і послуг ІБ00-000752 від 01.03.2025 18:10:01 Глобине-2 | D11: Кременчуцький річковий порт ПРАТ Договір 112/Б від 15.10.2024_Глобине-2 Надходження дод. витрат ІБ00-000106 від 01.03.2025 18:10:02 | E11: 205 | F11: 9395 | H11: 631 | K11: Д | L11: 266275.27
A12: 01.03.2025 | B12: Переміщення товарів ІБ00-000154 від 01.03.2025 18:15:00 Перемещение ТМЦ | C12: Обл. НДС Бетон С20/25 W6 F75 P4 доб-10 з фіброю Надходження товарів і послуг ІБ00-000752 від 01.03.2025 18:10:01 Генплан підпірна стінка (Глобине) | D12: Обл. НДС Бетон С20/25 W6 F75 P4 доб-10 з фіброю Надходження товарів і послуг ІБ00-000752 від 01.03.2025 18:10:01 Глобине-2 | E12: 205 | H12: 205 | I12: 32716.13 | K12: Д | L12: 233559.14
A13: 01.03.2025 | B13: Переміщення товарів ІБ00-000155 від 01.03.2025 18:15:00 Перемещение ТМЦ | C13: Обл. НДС Бетон С20/25 W6 F75 P4 доб-10 з фіброю Надходження товарів і послуг ІБ00-000752 від 01.03.2025 18:10:01 Резервуарний парк соєвої меляси (Глобине) | D13: Обл. НДС Бетон С20/25 W6 F75 P4 доб-10 з фіброю Надходження товарів і послуг ІБ00-000752 від 01.03.2025 18:10:01 Глобине-2 | E13: 205 | H13: 205 | I13: 838.87 | K13: Д | L13: 232720.27
A14: 03.03.2025 | B14: Надходження товарів і послуг ІБ00-000755 від 03.03.2025 18:08:02 Оприходованы ТМЦ | C14: Обл. НДС Бетон С20/25 W6 F75 P4 доб-5 Надходження товарів і послуг ІБ00-000755 від 03.03.2025 18:08:02 Глобине-2 | D14: Кременчуцький річковий порт ПРАТ Договір 112/Б від 15.10.2024_Глобине-2 Надходження товарів і послуг ІБ00-000755 від 03.03.2025 18:08:02 | E14: 205 | F14: 26730 | H14: 631 | K14: Д | L14: 259450.27
A15: 03.03.2025 | B15: Надходження дод. витрат ІБ00-000107 від 03.03.2025 18:08:03 Доп. расходы при поступлении товаров | C15: Обл. НДС Бетон С20/25 W6 F75 P4 доб-5 Надходження товарів і послуг ІБ00-000755 від 03.03.2025 18:08:02 Глобине-2 | D15: Кременчуцький річковий порт ПРАТ Договір 112/Б від 15.10.2024_Глобине-2 Надходження дод. витрат ІБ00-000107 від 03.03.2025 18:08:03 | E15: 205 | F15: 10974.5 | H15: 631 | K15: Д | L15: 270424.77
A16: 03.03.2025 | B16: Переміщення товарів ІБ00-000156 від 03.03.2025 18:08:04 Перемещение ТМЦ | C16: Обл. НДС Бетон С20/25 W6 F75 P4 доб-5 Надходження товарів і послуг ІБ00-000755 від 03.03.2025 18:08:02 Насосна Градирня (Глобине) | D16: Обл. НДС Бетон С20/25 W6 F75 P4 доб-5 Надходження товарів і послуг ІБ00-000755 від 03.03.2025 18:08:02 Глобине-2 | E16: 205 | H16: 205 | I16: 6284.08 | K16: Д | L16: 264140.69
A17: 03.03.2025 | B17: Переміщення товарів ІБ00-000157 від 03.03.2025 18:08:05 Перемещение ТМЦ | C17: Обл. НДС Бетон С20/25 W6 F75 P4 доб-5 Надходження товарів і послуг ІБ00-000755 від 03.03.2025 18:08:02 Котельна (Глобине) | D17: Обл. НДС Бетон С20/25 W6 F75 P4 доб-5 Надходження товарів і послуг ІБ00-000755 від 03.03.2025 18:08:02 Глобине-2 | E17: 205 | H17: 205 | I17: 4189.39 | K17: Д | L17: 259951.3
A18: 03.03.2025 | B18: Переміщення товарів ІБ00-000158 від 03.03.2025 18:08:06 Перемещение ТМЦ | C18: Обл. НДС Бетон С20/25 W6 F75 P4 доб-5 Надходження товарів і послуг ІБ00-000755 від 03.03.2025 18:08:02 Цех екстракції (Глобине) | D18: Обл. НДС Бетон С20/25 W6 F75 P4 доб-5 Надходження товарів і послуг ІБ00-000755 від 03.03.2025 18:08:02 Глобине-2 | E18: 205 | H18: 205 | I18: 27231.03 | K18: Д | L18: 232720.27
A19: 03.03.2025 | B19: Авансовий звіт ІБ00-000046 від 03.03.2025 18:09:12 Оприходованы ТМЦ | C19: Обл. НДС Самонаріз 5,5х25 кріпл мет профілю легк мет констр-цій (9006 сріблястий (250шт.)) Авансовий звіт ІБ00-000046 від 03.03.2025 18:09:12 Глобине-2 | D19: Штиченко Олександр Володимирович | E19: 205 | F19: 200 | H19: 3721 | K19: Д | L19: 232920.27
A20: 03.03.2025 | B20: Авансовий звіт ІБ00-000046 від 03.03.2025 18:09:12 Оприходованы ТМЦ | C20: Обл. НДС Лампа A50 100W E27 Авансовий звіт ІБ00-000046 від 03.03.2025 18:09:12 Глобине-2 | D20: Штиченко Олександр Володимирович | E20: 205 | F20: 36 | H20: 3721 | K20: Д | L20: 232956.27
A21: 03.03.2025 | B21: Авансовий звіт ІБ00-000046 від 03.03.2025 18:09:12 Оприходованы ТМЦ | C21: Обл. НДС Шайба Авансовий звіт ІБ00-000046 від 03.03.2025 18:09:12 Глобине-2 | D21: Штиченко Олександр Володимирович | E21: 205 | F21: 60 | H21: 3721 | K21: Д | L21: 233016.27
A22: 03.03.2025 | B22: Авансовий звіт ІБ00-000046 від 03.03.2025 18:09:12 Оприходованы ТМЦ | C22: Обл. НДС Пензлик малярний Авансовий звіт ІБ00-000046 від 03.03.2025 18:09:12 Глобине-2 | D22: Штиченко Олександр Володимирович | E22: 205 | F22: 24 | H22: 3721 | K22: Д | L22: 233040.27
A23: 03.03.2025 | B23: Авансовий звіт ІБ00-000046 від 03.03.2025 18:09:12 Оприходованы ТМЦ | C23: Обл. НДС бочка 35л Авансовий звіт ІБ00-000046 від 03.03.2025 18:09:12 Глобине-2 | D23: Штиченко Олександр Володимирович | E23: 205 | F23: 378 | H23: 3721 | K23: Д | L23: 233418.27
A24: 03.03.2025 | B24: Авансовий звіт ІБ00-000046 від 03.03.2025 18:09:12 Оприходованы ТМЦ | C24: Обл. НДС Біта *8 мм Авансовий звіт ІБ00-000046 від 03.03.2025 18:09:12 Глобине-2 | D24: Штиченко Олександр Володимирович | E24: 205 | F24: 41 | H24: 3721 | K24: Д | L24: 233459.27
A25: 06.03.2025 | B25: Надходження товарів і послуг ІБ00-000862 від 06.03.2025 20:05:58 Оприходованы ТМЦ | C25: Обл. НДС Бетон С20/25 W6 F75 P4 Надходження товарів і послуг ІБ00-000862 від 06.03.2025 20:05:58 Глобине-2 | D25: Кременчуцький річковий порт ПРАТ Договір 112/Б від 15.10.2024_Глобине-2 Надходження товарів і послуг ІБ00-000862 від 06.03.2025 20:05:58 | E25: 205 | F25: 221920 | H25: 631 | K25: Д | L25: 455379.27
A26: 06.03.2025 | B26: Надходження дод. витрат ІБ00-000123 від 06.03.2025 20:05:59 Доп. расходы при поступлении товаров | C26: Обл. НДС Бетон С20/25 W6 F75 P4 Надходження товарів і послуг ІБ00-000862 від 06.03.2025 20:05:58 Глобине-2 | D26: Кременчуцький річковий порт ПРАТ Договір 112/Б від 15.10.2024_Глобине-2 Надходження дод. витрат ІБ00-000123 від 06.03.2025 20:05:59 | E26: 205 | F26: 59527 | H26: 631 | K26: Д | L26: 514906.27
A27: 06.03.2025 | B27: Переміщення товарів ІБ00-000167 від 06.03.2025 20:10:00 Перемещение ТМЦ | C27: Обл. НДС Бетон С20/25 W6 F75 P4 Надходження товарів і послуг ІБ00-000368 від 31.01.2025 16:00:16 Котельна (Глобине) | D27: Обл. НДС Бетон С20/25 W6 F75 P4 Надходження товарів і послуг ІБ00-000368 від 31.01.2025 16:00:16 Глобине-2 | E27: 205 | H27: 205 | I27: 1855.12 | K27: Д | L27: 513051.15
A28: 06.03.2025 | B28: Переміщення товарів ІБ00-000167 від 06.03.2025 20:10:00 Перемещение ТМЦ | C28: Обл. НДС Бетон С20/25 W6 F75 P4 Надходження товарів і послуг ІБ00-000862 від 06.03.2025 20:05:58 Котельна (Глобине) | D28: Обл. НДС Бетон С20/25 W6 F75 P4 Надходження товарів і послуг ІБ00-000862 від 06.03.2025 20:05:58 Глобине-2 | E28: 205 | H28: 205 | I28: 259227.5 | K28: Д | L28: 253823.65
A29: 06.03.2025 | B29: Переміщення товарів ІБ00-000168 від 06.03.2025 20:10:00 Перемещение ТМЦ | C29: Обл. НДС Бетон С20/25 W6 F75 P4 Надходження товарів і послуг ІБ00-000862 від 06.03.2025 20:05:58 Цех екстракції (Глобине) | D29: Обл. НДС Бетон С20/25 W6 F75 P4 Надходження товарів і послуг ІБ00-000862 від 06.03.2025 20:05:58 Глобине-2 | E29: 205 | H29: 205 | I29: 16664.63 | K29: Д | L29: 237159.02
A30: 06.03.2025 | B30: Переміщення товарів ІБ00-000169 від 06.03.2025 20:10:00 Перемещение ТМЦ | C30: Обл. НДС Бетон С20/25 W6 F75 P4 Надходження товарів і послуг ІБ00-000862 від 06.03.2025 20:05:58 Резервуарний парк соєвої меляси (Глобине) | D30: Обл. НДС Бетон С20/25 W6 F75 P4 Надходження товарів і послуг ІБ00-000862 від 06.03.2025 20:05:58 Глобине-2 | E30: 205 | H30: 205 | I30: 3703.25 | K30: Д | L30: 233455.77
A31: 06.03.2025 | B31: Надходження товарів і послуг ІБ00-001121 від 06.03.2025 22:00:38 Оприходованы ТМЦ | C31: Обл. НДС Щебінь 80-120 Надходження товарів і послуг ІБ00-001121 від 06.03.2025 22:00:38 Глобине-2 | D31: ДІОРИТ ТОВ №06/04-11 від 04.11.2024 Глобине-2 Рахунок на оплату постачальника ІБ00-000908 від 06.03.2025 22:00:37 | E31: 205 | F31: 70955.77 | H31: 631 | K31: Д | L31: 304411.54
A32: 06.03.2025 | B32: Переміщення товарів ІБ00-000220 від 06.03.2025 22:00:39 Перемещение ТМЦ | C32: Обл. НДС Щебінь 80-120 Надходження товарів і послуг ІБ00-001121 від 06.03.2025 22:00:38 АПК (Глобине) | D32: Обл. НДС Щебінь 80-120 Надходження товарів і послуг ІБ00-001121 від 06.03.2025 22:00:38 Глобине-2 | E32: 205 | H32: 205 | I32: 65840 | K32: Д | L32: 238571.54
A33: 06.03.2025 | B33: Переміщення товарів ІБ00-000221 від 06.03.2025 22:00:40 Перемещение ТМЦ | C33: Обл. НДС Щебінь 80-120 Надходження товарів і послуг ІБ00-001121 від 06.03.2025 22:00:38 Генплан митний склад (Глобине) | D33: Обл. НДС Щебінь 80-120 Надходження товарів і послуг ІБ00-001121 від 06.03.2025 22:00:38 Глобине-2 | E33: 205 | H33: 205 | I33: 5115.77 | K33: Д | L33: 233455.77
A34: 08.03.2025 | B34: Надходження товарів і послуг ІБ00-000960 від 08.03.2025 18:00:04 Оприходованы ТМЦ | C34: Обл. НДС Бетон С20/25 W6 F75 P4 Надходження товарів і послуг ІБ00-000960 від 08.03.2025 18:00:04 Глобине-2 | D34: Кременчуцький річковий порт ПРАТ Договір 112/Б від 15.10.2024_Глобине-2 Надходження товарів і послуг ІБ00-000960 від 08.03.2025 18:00:04 | E34: 205 | F34: 39420 | H34: 631 | K34: Д | L34: 272875.77
A35: 08.03.2025 | B35: Надходження дод. витрат ІБ00-000127 від 08.03.2025 18:00:05 Доп. расходы при поступлении товаров | C35: Обл. НДС Бетон С20/25 W6 F75 P4 Надходження товарів і послуг ІБ00-000960 від 08.03.2025 18:00:04 Глобине-2 | D35: Кременчуцький річковий порт ПРАТ Договір 112/Б від 15.10.2024_Глобине-2 Надходження дод. витрат ІБ00-000127 від 08.03.2025 18:00:05 | E35: 205 | F35: 16994.5 | H35: 631 | K35: Д | L35: 289870.27
A36: 08.03.2025 | B36: Переміщення товарів ІБ00-000179 від 08.03.2025 18:10:00 Перемещение ТМЦ | C36: Обл. НДС Бетон С20/25 W6 F75 P4 Надходження товарів і послуг ІБ00-000862 від 06.03.2025 20:05:58 Котельна (Глобине) | D36: Обл. НДС Бетон С20/25 W6 F75 P4 Надходження товарів і послуг ІБ00-000862 від 06.03.2025 20:05:58 Глобине-2 | E36: 205 | H36: 205 | I36: 1851.62 | K36: Д | L36: 288018.65
A37: 08.03.2025 | B37: Переміщення товарів ІБ00-000179 від 08.03.2025 18:10:00 Перемещение ТМЦ | C37: Обл. НДС Бетон С20/25 W6 F75 P4 Надходження товарів і послуг ІБ00-000960 від 08.03.2025 18:00:04 Котельна (Глобине) | D37: Обл. НДС Бетон С20/25 W6 F75 P4 Надходження товарів і послуг ІБ00-000960 від 08.03.2025 18:00:04 Глобине-2 | E37: 205 | H37: 205 | I37: 44295.83 | K37: Д | L37: 243722.82
A38: 08.03.2025 | B38: Переміщення товарів ІБ00-000180 від 08.03.2025 18:10:00 Перемещение ТМЦ | C38: Обл. НДС Бетон С20/25 W6 F75 P4 Надходження товарів і послуг ІБ00-000960 від 08.03.2025 18:00:04 Цех екстракції (Глобине) | D38: Обл. НДС Бетон С20/25 W6 F75 P4 Надходження товарів і послуг ІБ00-000960 від 08.03.2025 18:00:04 Глобине-2 | E38: 205 | H38: 205 | I38: 10029.24 | K38: Д | L38: 233693.58
A39: 10.03.2025 | B39: Надходження товарів і послуг ІБ00-001338 від 10.03.2025 20:00:39 Оприходованы ТМЦ | C39: Обл. НДС Труба п/е 25вт (2 м) Надходження товарів і послуг ІБ00-001338 від 10.03.2025 20:00:39 Глобине-2 | D39: ПРОТЕКС УКРАЇНА Договір 9 від 11.12.2023_Глобине 2 Рахунок на оплату постачальника ІБ00-000965 від 06.03.2025 22:00:42 | E39: 205 | F39: 1750 | H39: 631 | K39: Д | L39: 235443.58
A40: 10.03.2025 | B40: Переміщення товарів ІБ00-000255 від 10.03.2025 20:00:40 Перемещение ТМЦ | C40: Обл. НДС Труба п/е 25вт (2 м) Надходження товарів і послуг ІБ00-001338 від 10.03.2025 20:00:39 Цех екстракції (Глобине) | D40: Обл. НДС Труба п/е 25вт (2 м) Надходження товарів і послуг ІБ00-001338 від 10.03.2025 20:00:39 Глобине-2 | E40: 205 | H40: 205 | I40: 1750 | K40: Д | L40: 233693.58
...

Sheet Котельна
A1: Період | B1: Документ | C1: Аналітика Дт | D1: Аналітика Кт | E1: Дебет | H1: Кредит | K1: Поточне сальдо
E2: Рахунок | H2: Рахунок
A3: 01.03.2025 | B3: Переміщення товарів ІБ00-000153 від 01.03.2025 18:10:00 Перемещение ТМЦ | C3: Обл. НДС Бетон С20/25 W6 F75 P4 доб-10 Надходження товарів і послуг ІБ00-000751 від 01.03.2025 18:00:01 Котельна (Глобине) | D3: Обл. НДС Бетон С20/25 W6 F75 P4 доб-10 Надходження товарів і послуг ІБ00-000751 від 01.03.2025 18:00:01 Глобине-2 | E3: 205 | F3: 7389.33 | H3: 205 | K3: Д | L3: 444674.87
A4: 01.03.2025 | B4: Надходження товарів і послуг ІБ00-001037 від 01.03.2025 18:17:06 Оприходованы ТМЦ | C4: Обл. НДС Труба 80*80*4 ст1-3 пс L=12000 Надходження товарів і послуг ІБ00-001037 від 01.03.2025 18:17:06 Котельна (Глобине) | D4: МЕТАЛ ХОЛДІНГ ТРЕЙД ТОВ Договір 01/467/24 від 06.09.2024_Глобине-2 Рахунок на оплату постачальника ІБ00-000868 від 01.03.2025 18:17:05 | E4: 205 | F4: 12373.97 | H4: 631 | K4: Д | L4: 457048.84
A5: 01.03.2025 | B5: Надходження товарів і послуг ІБ00-001037 від 01.03.2025 18:17:06 Оприходованы ТМЦ | C5: Обл. НДС Кутик 75*75*6мм ст.3ПС МІРА 12 м Надходження товарів і послуг ІБ00-001037 від 01.03.2025 18:17:06 Котельна (Глобине) | D5: МЕТАЛ ХОЛДІНГ ТРЕЙД ТОВ Договір 01/467/24 від 06.09.2024_Глобине-2 Рахунок на оплату постачальника ІБ00-000868 від 01.03.2025 18:17:05 | E5: 205 | F5: 576.02 | H5: 631 | K5: Д | L5: 457624.86
A6: 01.03.2025 | B6: Надходження товарів і послуг ІБ00-001037 від 01.03.2025 18:17:06 Оприходованы ТМЦ | C6: Обл. НДС Швелер 16П (160 12,05 8240 3пс) Надходження товарів і послуг ІБ00-001037 від 01.03.2025 18:17:06 Котельна (Глобине) | D6: МЕТАЛ ХОЛДІНГ ТРЕЙД ТОВ Договір 01/467/24 від 06.09.2024_Глобине-2 Рахунок на оплату постачальника ІБ00-000868 від 01.03.2025 18:17:05 | E6: 205 | F6: 6927.17 | H6: 631 | K6: Д | L6: 464552.03
A7: 01.03.2025 | B7: Надходження товарів і послуг ІБ00-001037 від 01.03.2025 18:17:06 Оприходованы ТМЦ | C7: Обл. НДС Швелер 18П (180 12,05 8240 3пс5) Надходження товарів і послуг ІБ00-001037 від 01.03.2025 18:17:06 Котельна (Глобине) | D7: МЕТАЛ ХОЛДІНГ ТРЕЙД ТОВ Договір 01/467/24 від 06.09.2024_Глобине-2 Рахунок на оплату постачальника ІБ00-000868 від 01.03.2025 18:17:05 | E7: 205 | F7: 18497.9 | H7: 631 | K7: Д | L7: 483049.93
A8: 01.03.2025 | B8: Надходження товарів і послуг ІБ00-001037 від 01.03.2025 18:17:06 Оприходованы ТМЦ | C8: Обл. НДС Балка 20 L=12000 Надходження товарів і послуг ІБ00-001037 від 01.03.2025 18:17:06 Котельна (Глобине) | D8: МЕТАЛ ХОЛДІНГ ТРЕЙД ТОВ Договір 01/467/24 від 06.09.2024_Глобине-2 Рахунок на оплату постачальника ІБ00-000868 від 01.03.2025 18:17:05 | E8: 205 | F8: 4325.23 | H8: 631 | K8: Д | L8: 487375.16
A9: 01.03.2025 | B9: Надходження товарів і послуг ІБ00-001037 від 01.03.2025 18:17:06 Оприходованы ТМЦ | C9: Обл. НДС Лист г/к 4,0*1500*6000 мм; ст.3 сп/пс Надходження товарів і послуг ІБ00-001037 від 01.03.2025 18:17:06 Котельна (Глобине) | D9: МЕТАЛ ХОЛДІНГ ТРЕЙД ТОВ Договір 01/467/24 від 06.09.2024_Глобине-2 Рахунок на оплату постачальника ІБ00-000868 від 01.03.2025 18:17:05 | E9: 205 | F9: 680.46 | H9: 631 | K9: Д | L9: 488055.62
A10: 01.03.2025 | B10: Надходження товарів і послуг ІБ00-001037 від 01.03.2025 18:17:06 Оприходованы ТМЦ | C10: Обл. НДС Лист г/к 10*2000*6000 1-3 сп/пс Надходження товарів і послуг ІБ00-001037 від 01.03.2025 18:17:06 Котельна (Глобине) | D10: МЕТАЛ ХОЛДІНГ ТРЕЙД ТОВ Договір 01/467/24 від 06.09.2024_Глобине-2 Рахунок на оплату постачальника ІБ00-000868 від 01.03.2025 18:17:05 | E10: 205 | F10: 2425 | H10: 631 | K10: Д | L10: 490480.62
A11: 01.03.2025 | B11: Надходження дод. витрат ІБ00-000147 від 01.03.2025 18:17:07 Доп. расходы при поступлении товаров | C11: Обл. НДС Труба 80*80*4 ст1-3 пс L=12000 Надходження товарів і послуг ІБ00-001037 від 01.03.2025 18:17:06 Котельна (Глобине) | D11: МЕТАЛ ХОЛДІНГ ТРЕЙД ТОВ Договір 01/467/24 від 06.09.2024_Глобине-2 Рахунок на оплату постачальника ІБ00-000868 від 01.03.2025 18:17:05 | E11: 205 | F11: 3803.84 | H11: 631 | K11: Д | L11: 494284.46
A12: 01.03.2025 | B12: Надходження дод. витрат ІБ00-000147 від 01.03.2025 18:17:07 Доп. расходы при поступлении товаров | C12: Обл. НДС Кутик 75*75*6мм ст.3ПС МІРА 12 м Надходження товарів і послуг ІБ00-001037 від 01.03.2025 18:17:06 Котельна (Глобине) | D12: МЕТАЛ ХОЛДІНГ ТРЕЙД ТОВ Договір 01/467/24 від 06.09.2024_Глобине-2 Рахунок на оплату постачальника ІБ00-000868 від 01.03.2025 18:17:05 | E12: 205 | F12: 177.07 | H12: 631 | K12: Д | L12: 494461.53
A13: 01.03.2025 | B13: Надходження дод. витрат ІБ00-000147 від 01.03.2025 18:17:07 Доп. расходы при поступлении товаров | C13: Обл. НДС Швелер 16П (160 12,05 8240 3пс) Надходження товарів і послуг ІБ00-001037 від 01.03.2025 18:17:06 Котельна (Глобине) | D13: МЕТАЛ ХОЛДІНГ ТРЕЙД ТОВ Договір 01/467/24 від 06.09.2024_Глобине-2 Рахунок на оплату постачальника ІБ00-000868 від 01.03.2025 18:17:05 | E13: 205 | F13: 2129.46 | H13: 631 | K13: Д | L13: 496590.99
A14: 01.03.2025 | B14: Надходження дод. витрат ІБ00-000147 від 01.03.2025 18:17:07 Доп. расходы при поступлении товаров | C14: Обл. НДС Швелер 18П (180 12,05 8240 3пс5) Надходження товарів і послуг ІБ00-001037 від 01.03.2025 18:17:06 Котельна (Глобине) | D14: МЕТАЛ ХОЛДІНГ ТРЕЙД ТОВ Договір 01/467/24 від 06.09.2024_Глобине-2 Рахунок на оплату постачальника ІБ00-000868 від 01.03.2025 18:17:05 | E14: 205 | F14: 5686.38 | H14: 631 | K14: Д | L14: 502277.37
... A45: 06.03.2025 | B45: Переміщення товарів ІБ00-000167 від 06.03.2025 20:10:00 Перемещение ТМЦ | C45: Обл. НДС Бетон С20/25 W6 F75 P4 Надходження товарів і послуг ІБ00-000862 від 06.03.2025 20:05:58 Котельна (Глобине) | D45: Обл. НДС Бетон С20/25 W6 F75 P4 Надходження товарів і послуг ІБ00-000862 від 06.03.2025 20:05:58 Глобине-2 | E45: 205 | F45: 259227.5 | H45: 205 | K45: Д | L45: 1006263.2
A46: 06.03.2025 | B46: Вимога-накладна ІБ00-000146 від 06.03.2025 20:20:00 Списаны ТМЦ | C46: Обл. НДС Виробничий (Глобине-2) Глобине-2 Прямі материальні виробничі витрати крім зворотніх відходів | D46: Обл. НДС Щебінь 20-40 Надходження товарів і послуг ІБ00-006356 від 19.12.2024 12:14:15 Котельна (Глобине) | E46: 231 | H46: 205 | I46: 34830 | K46: Д | L46: 971433.22
A47: 06.03.2025 | B47: Вимога-накладна ІБ00-000146 від 06.03.2025 20:20:00 Списаны ТМЦ | C47: Обл. НДС Виробничий (Глобине-2) Глобине-2 Прямі материальні виробничі витрати крім зворотніх відходів | D47: Обл. НДС Плівка п/е рукав 1500*100 Надходження товарів і послуг ІБ00-005781 від 19.11.2024 17:51:41 Котельна (Глобине) | E47: 231 | H47: 205 | I47: 1378.08 | K47: Д | L47: 970055.14
A48: 06.03.2025 | B48: Вимога-накладна ІБ00-000146 від 06.03.2025 20:20:00 Списаны ТМЦ | C48: Обл. НДС Виробничий (Глобине-2) Глобине-2 Прямі материальні виробничі витрати крім зворотніх відходів | D48: Обл. НДС Бетон С20/25 W6 F75 P4 Надходження товарів і послуг ІБ00-000368 від 31.01.2025 16:00:16 Котельна (Глобине) | E48: 231 | H48: 205 | I48: 1855.12 | K48: Д | L48: 968200.02
A49: 06.03.2025 | B49: Вимога-накладна ІБ00-000146 від 06.03.2025 20:20:00 Списаны ТМЦ | C49: Обл. НДС Виробничий (Глобине-2) Глобине-2 Прямі материальні виробничі витрати крім зворотніх відходів | D49: Обл. НДС Бетон С20/25 W6 F75 P4 Надходження товарів і послуг ІБ00-000862 від 06.03.2025 20:05:58 Котельна (Глобине) | E49: 231 | H49: 205 | I49: 4592.03 | K49: Д | L49: 963607.99
A50: 06.03.2025 | B50: Вимога-накладна ІБ00-000146 від 06.03.2025 20:20:00 Списаны ТМЦ | C50: Обл. НДС Виробничий (Глобине-2) Глобине-2 Прямі материальні виробничі витрати крім зворотніх відходів | D50: Обл. НДС Бетон С20/25 W6 F75 P4 доб-10 Надходження товарів і послуг ІБ00-000481 від 06.02.2025 18:36:18 Котельна (Глобине) | E50: 231 | H50: 205 | I50: 3710.66 | K50: Д | L50: 959897.33
A51: 06.03.2025 | B51: Вимога-накладна ІБ00-000146 від 06.03.2025 20:20:00 Списаны ТМЦ | C51: Обл. НДС Виробничий (Глобине-2) Глобине-2 Прямі материальні виробничі витрати крім зворотніх відходів | D51: Обл. НДС Бетон С20/25 W6 F75 P4 доб-10 Надходження товарів і послуг ІБ00-000522 від 08.02.2025 10:00:03 Котельна (Глобине) | E51: 231 | H51: 205 | I51: 6491.62 | K51: Д | L51: 953405.71
A52: 06.03.2025 | B52: Вимога-накладна ІБ00-000146 від 06.03.2025 20:20:00 Списаны ТМЦ | C52: Обл. НДС Виробничий (Глобине-2) Глобине-2 Прямі материальні виробничі витрати крім зворотніх відходів | D52: Обл. НДС Бетон С20/25 W6 F75 P4 доб-10 Надходження товарів і послуг ІБ00-000522 від 08.02.2025 10:00:03 Котельна (Глобине) | E52: 231 | H52: 205 | I52: 85737.15 | K52: Д | L52: 867668.56
A53: 06.03.2025 | B53: Вимога-накладна ІБ00-000146 від 06.03.2025 20:20:00 Списаны ТМЦ | C53: Обл. НДС Виробничий (Глобине-2) Глобине-2 Прямі материальні виробничі витрати крім зворотніх відходів | D53: Обл. НДС Бетон С20/25 W6 F75 P4 доб-10 Надходження товарів і послуг ІБ00-000751 від 01.03.2025 18:00:01 Котельна (Глобине) | E53: 231 | H53: 205 | I53: 7389.33 | K53: Д | L53: 860279.23
A54: 06.03.2025 | B54: Вимога-накладна ІБ00-000146 від 06.03.2025 20:20:00 Списаны ТМЦ | C54: Обл. НДС Виробничий (Глобине-2) Глобине-2 Прямі материальні виробничі витрати крім зворотніх відходів | D54: Обл. НДС Бетон С20/25 W6 F75 P4 доб-5 Надходження товарів і послуг ІБ00-000755 від 03.03.2025 18:08:02 Котельна (Глобине) | E54: 231 | H54: 205 | I54: 4189.39 | K54: Д | L54: 856089.84
A55: 06.03.2025 | B55: Вимога-накладна ІБ00-000146 від 06.03.2025 20:20:00 Списаны ТМЦ | C55: Обл. НДС Виробничий (Глобине-2) Глобине-2 Прямі материальні виробничі витрати крім зворотніх відходів | D55: Обл. НДС Пінополістирол екструдований 20х600х1200мм Надходження товарів і послуг ІБ00-006461 від 20.12.2024 18:18:13 Котельна (Глобине) | E55: 231 | H55: 205 | I55: 537.24 | K55: Д | L55: 855552.6
A56: 06.03.2025 | B56: Вимога-накладна ІБ00-000146 від 06.03.2025 20:20:00 Списаны ТМЦ | C56: Обл. НДС Виробничий (Глобине-2) Глобине-2 Прямі материальні виробничі витрати крім зворотніх відходів | D56: Обл. НДС Пінополістирол фасад шаршавий 1200х600х20мм 0,264 куб м Надходження товарів і послуг ІБ00-000464 від 06.02.2025 18:36:11 Котельна (Глобине) | E56: 231 | H56: 205 | I56: 97.5 | K56: Д | L56: 855455.1
A57: 06.03.2025 | B57: Вимога-накладна ІБ00-000150 від 06.03.2025 22:00:00 Списаны ТМЦ | C57: Обл. НДС Виробничий (Глобине-2) Глобине-2 Прямі материальні виробничі витрати крім зворотніх відходів | D57: Обл. НДС Бетон С20/25 W6 F75 P4 Надходження товарів і послуг ІБ00-000862 від 06.03.2025 20:05:58 Котельна (Глобине) | E57: 231 | H57: 205 | I57: 2888.53 | K57: Д | L57: 852566.57
A58: 06.03.2025 | B58: Надходження товарів і послуг ІБ00-000950 від 06.03.2025 22:00:06 Оприходованы ТМЦ | C58: Обл. НДС DIN933 Болт М12х65 5.8 цб пр Надходження товарів і послуг ІБ00-000950 від 06.03.2025 22:00:06 Котельна (Глобине) | D58: Солді і Ко ПАТ Дог № 378542-55/19 від 21.01.2019 р. РАХ_Глобине-2 Рахунок на оплату постачальника ІБ00-000791 від 06.03.2025 22:00:05 | E58: 205 | F58: 308.7 | H58: 631 | K58: Д | L58: 852875.27
A59: 07.03.2025 | B59: Надходження товарів і послуг ІБ00-000861 від 07.03.2025 18:55:25 Оприходованы ТМЦ (Зачет аванса поставщику) | C59: Обл. НДС Мапеграут 450 Тіксо/25 Надходження товарів і послуг ІБ00-000861 від 07.03.2025 18:55:25 Котельна (Глобине) | D59: СЛОН-М ТОВ РАХУНКИ_Глобино-2 Рахунок на оплату постачальника ІБ00-000669 від 04.03.2025 00:00:00 | E59: 205 | F59: 2852.38 | H59: 631 | K59: Д | L59: 855727.65
A60: 07.03.2025 | B60: Надходження дод. витрат ІБ00-000122 від 07.03.2025 18:55:26 Доп. расходы при поступлении товаров (Зачет аванса поставщику) | C60: Обл. НДС Мапеграут 450 Тіксо/25 Надходження товарів і послуг ІБ00-000861 від 07.03.2025 18:55:25 Котельна (Глобине) | D60: СЛОН-М ТОВ РАХУНКИ_Глобино-2 Рахунок на оплату постачальника ІБ00-000669 від 04.03.2025 00:00:00 | E60: 205 | F60: 420 | H60: 631 | K60: Д | L60: 856147.65
A61: 08.03.2025 | B61: Переміщення товарів ІБ00-000179 від 08.03.2025 18:10:00 Перемещение ТМЦ | C61: Обл. НДС Бетон С20/25 W6 F75 P4 Надходження товарів і послуг ІБ00-000862 від 06.03.2025 20:05:58 Котельна (Глобине) | D61: Обл. НДС Бетон С20/25 W6 F75 P4 Надходження товарів і послуг ІБ00-000862 від 06.03.2025 20:05:58 Глобине-2 | E61: 205 | F61: 1851.62 | H61: 205 | K61: Д | L61: 857999.27
A62: 08.03.2025 | B62: Переміщення товарів ІБ00-000179 від 08.03.2025 18:10:00 Перемещение ТМЦ | C62: Обл. НДС Бетон С20/25 W6 F75 P4 Надходження товарів і послуг ІБ00-000960 від 08.03.2025 18:00:04 Котельна (Глобине) | D62: Обл. НДС Бетон С20/25 W6 F75 P4 Надходження товарів і послуг ІБ00-000960 від 08.03.2025 18:00:04 Глобине-2 | E62: 205 | F62: 44295.83 | H62: 205 | K62: Д | L62: 902295.1
