Workbook
Name list: #REF!
Name list: #REF!
Name spec_values: [1]BOQ_Шаблон!$A$6:$A$275
Name МШП_СПИСОК: [2]НОРМИ_МК!$F$5:$R$5

Sheet Бюджет_Проекта
A1: Статья движения денежных средств | B1: ф1 | C1: ф2 | D1: Итого, грн | E1: Комментарии к бюджету объекта | H1: Матеріали | I1: =D101+D98 -> 705624.01
A2: ПОСТУПЛЕНИЯ | B2: =B3+B10 -> 1232000 | C2: =C3+C10 -> 0 | D2: =B2+C2 -> 1232000 | H2: Загальна сс, грн | I2: =D14-I1 -> 320996
A3: Операционная деятельность | B3: =SUM(B4:B9) -> 1232000 | C3: =SUM(C4:C9) -> 0 | D3: =B3+C3 -> 1232000 | H3: Налоговая нагрузка, 3%: | I3: =I4*3% -> 36960
A4: Поступление от Заказчика | B4: 1232000 | D4: =B4+C4 -> 1232000 | H4: КП: | I4: =B4 -> 1232000
A5: Прочие поступления | D5: =B5+C5 -> 0 | H5: Маржа, грн: за шт | I5: =I4-I3-I2-I1 -> 168419.99
A6: Возврат залоговой суммы | D6: =B6+C6 -> 0 | H6: Маржа, %: | I6: =I5/I4 -> 0.13670454
A7: Поступление от возврата денежных средств | D7: =B7+C7 -> 0 | H7: Количество в заказе, шт | I7: 1
A8: Поступление цех | D8: =B8+C8 -> 0 | H8: Итого маржа по заказу, грн | I8: =I7*I5 -> 168419.99 | K8: 157130.11
A9: Поступление за технику | D9: =B9+C9 -> 0
A10: Финансовая деятельность | B10: =SUM(B11:B13) -> 0 | C10: =SUM(C11:C13) -> 0 | D10: =B10+C10 -> 0
A11: Получение финансовой помощи | D11: =B11+C11 -> 0
A12: Поступление от Фин агента | C12: =B133 -> 0 | D12: =B12+C12 -> 0
A13: Кредитная линия | D13: =B13+C13 -> 0
A14: СПИСАНИЕ | B14: =B15+B128+B141 -> 832000.01 | C14: =C15+C128+C141 -> 194620 | D14: =B14+C14 -> 1026620
A15: Операционная деятельность | B15: =B16+B70+B93+B66 -> 802807.01 | C15: =C16+C70+C93+C66 -> 194620 | D15: =B15+C15 -> 997427.01
A16: Административные затраты | B16: =B17+B24+B29+B33+B41+B45+B49+B52+B58+B61+B21 -> 15000 | C16: =C17+C24+C29+C33+C41+C45+C49+C52+C58+C61+C21 -> 0 | D16: =B16+C16 -> 15000
A17: Аренда офиса | B17: =SUM(B18:B20) -> 0 | C17: =SUM(C18:C20) -> 0 | D17: =B17+C17 -> 0
A18: Аренда офиса | B18: =SUMIF('Проект СС'!$B:$B,$A18,'Проект СС'!$O:$O) -> 0 | D18: =B18+C18 -> 0
A19: Коммунальные платежи (офис) | B19: =SUMIF('Проект СС'!$B:$B,$A19,'Проект СС'!$O:$O) -> 0 | D19: =B19+C19 -> 0
A20: Охрана офиса и пожарная сигнализация | B20: =SUMIF('Проект СС'!$B:$B,$A20,'Проект СС'!$O:$O) -> 0 | D20: =B20+C20 -> 0
A21: Аренда квартиры | B21: =SUM(B22:B23) -> 0 | C21: =SUM(C22:C23) -> 0 | D21: =B21+C21 -> 0
A22: Аренда квартиры | B22: =SUMIF('Проект СС'!$B:$B,$A22,'Проект СС'!$O:$O) -> 0 | D22: =B22+C22 -> 0
A23: Коммунальные платежи | B23: =SUMIF('Проект СС'!$B:$B,$A23,'Проект СС'!$O:$O) -> 0 | D23: =B23+C23 -> 0
A24: Затраты на персонал | B24: =SUM(B25:B28) -> 0 | C24: =SUM(C25:C28) -> 0 | D24: =B24+C24 -> 0
A25: Затраты на обучение управленческого персонала | B25: =SUMIF('Проект СС'!$B:$B,$A25,'Проект СС'!$O:$O) -> 0 | D25: =B25+C25 -> 0
A26: Затраты по корпоративной культуре | B26: =SUMIF('Проект СС'!$B:$B,$A26,'Проект СС'!$O:$O) -> 0 | D26: =B26+C26 -> 0
A27: Материальная помощь | B27: =SUMIF('Проект СС'!$B:$B,$A27,'Проект СС'!$O:$O) -> 0 | D27: =B27+C27 -> 0
A28: Периодика | B28: =SUMIF('Проект СС'!$B:$B,$A28,'Проект СС'!$O:$O) -> 0 | D28: =B28+C28 -> 0
A29: Затраты на командировку | B29: =SUM(B30:B32) -> 5000 | C29: =SUM(C30:C32) -> 0 | D29: =B29+C29 -> 5000
A30: Проезд | B30: =SUMIF('Проект СС'!$B:$B,$A30,'Проект СС'!$O:$O) -> 0
A31: Проживание | B31: =SUMIF('Проект СС'!$B:$B,$A31,'Проект СС'!$O:$O) -> 5000 | D31: =B31+C31 -> 5000
A32: Суточные | B32: =SUMIF('Проект СС'!$B:$B,$A32,'Проект СС'!$O:$O) -> 0 | D32: =B32+C32 -> 0
A33: ЗП управленческого персонала с начислениями | B33: =SUM(B34:B40) -> 0 | C33: =SUM(C34:C40) -> 0 | D33: =B33+C33 -> 0
A34: Зарплата PM | C34: =SUMIF('Проект СС'!$B:$B,$A34,'Проект СС'!$O:$O) -> 0 | D34: =B34+C34 -> 0 | E34: 2 мес + 5 мес
A35: Удержание с зарплаты РМ | B35: =SUMIF('Проект СС'!$B:$B,$A35,'Проект СС'!$O:$O) -> 0 | D35: =B35+C35 -> 0
A36: Начисления на зарплату PM | B36: =SUMIF('Проект СС'!$B:$B,$A36,'Проект СС'!$O:$O) -> 0 | D36: =B36+C36 -> 0
A37: Зарплата управленческого персонала | B37: =SUMIF('Проект СС'!$B:$B,$A37,'Проект СС'!$O:$O) -> 0 | D37: =B37+C37 -> 0
A38: Удержание с админ зарплату | B38: =SUMIF('Проект СС'!$B:$B,$A38,'Проект СС'!$O:$O) -> 0 | D38: =B38+C38 -> 0
A39: Начисления на админ зарплату | B39: =SUMIF('Проект СС'!$B:$B,$A39,'Проект СС'!$O:$O) -> 0 | D39: =B39+C39 -> 0
A40: Премия админ персоналу | B40: =SUMIF('Проект СС'!$B:$B,$A40,'Проект СС'!$O:$O) -> 0 | D40: =B40+C40 -> 0
...

Sheet Анализ
A1: IRC 15 m2 | D1: Курс | E1: 43.5 | F1: Площадь | G1: 15
A3: Сумма по полю Всього, грн. з ПДВ | B3: Названия столбцов
A4: Названия строк | B4: Матеріал | C4: Робота | D4: Общий итог | E4: Материал $ | F4: Общий итог $ | G4: На 1 м2 $
A5: Дополнительная Комплектация | B5: 155087 | C5: 0 | D5: 155087 | E5: =B5/$E$1 -> 3565.2184 | F5: =D5/$E$1 -> 3565.2184 | G5: =F5/$G$1 -> 237.68123
A6: Каркас | B6: 151946.44 | C6: 0 | D6: 151946.44 | E6: =B6/$E$1 -> 3493.0215 | F6: =D6/$E$1 -> 3493.0215 | G6: =F6/$G$1 -> 232.8681
A7: Монтаж будинку | B7: 0 | C7: 0 | D7: 0 | E7: =B7/$E$1 -> 0 | F7: =D7/$E$1 -> 0 | G7: =F7/$G$1 -> 0
A8: Окна/двери | B8: 102799 | C8: 0 | D8: 102799 | E8: =B8/$E$1 -> 2363.1954 | F8: =D8/$E$1 -> 2363.1954 | G8: =F8/$G$1 -> 157.54636
A9: Отделка | B9: 163888.82 | C9: 0 | D9: 163888.82 | E9: =B9/$E$1 -> 3767.5591 | F9: =D9/$E$1 -> 3767.5591 | G9: =F9/$G$1 -> 251.17061
A10: Сантехника | B10: 39783.4 | C10: 0 | D10: 39783.4 | E10: =B10/$E$1 -> 914.56092 | F10: =D10/$E$1 -> 914.56092 | G10: =F10/$G$1 -> 60.970728
A11: Фасад | B11: 53172 | C11: 0 | D11: 53172 | E11: =B11/$E$1 -> 1222.3448 | F11: =D11/$E$1 -> 1222.3448 | G11: =F11/$G$1 -> 81.489655
A12: Электрика/Подогрев | B12: 38947.35 | C12: 0 | D12: 38947.35 | E12: =B12/$E$1 -> 895.34138 | F12: =D12/$E$1 -> 895.34138 | G12: =F12/$G$1 -> 59.689425
A13: Общий итог | B13: 705624.01 | C13: 0 | D13: 705624.01 | E13: =SUM(E5:E12) -> 16221.241 | F13: =SUM(F5:F12) -> 16221.241

Sheet Проект СС
A1: № | B1: Стаття в ДДС | C1: Робота/матеріал/додаткові | D1: Виробництво/Будівництво | E1: Тип робіт | F1: № з/п | G1: Найменування робіт/витрат/матеріалів | H1: Найменування робіт/витрат/матеріалів узагальнена | I1: Од. вим. | J1: Кіль- кість | K1: Вартість робіт за од.виміру, грн. з ПДВ | L1: Вартість матеріалів за од.виміру, грн. з ПДВ | M1: Вартість робіт за повний обсяг, грн. з ПДВ | N1: Вартість матеріалів за повний обсяг, грн. з ПДВ | O1: Всього, грн. з ПДВ
A2: І | F2: І | G2: Каркас | J2: =L3+L12 -> 0
A3: 1.1 | F3: 1.1 | G3: РОБОТА | L3: =SUM(L5:L11) -> 0
A4: 1.1.1 | B4: Зарплата производственного персонала | C4: Робота | D4: Виробництво/Будівництво | E4: Каркас | F4: 1.1.1 | G4: Приймання матеріалу | I4: чол/год | K4: 200 | M4: =J4*K4 -> 0 | N4: =J4*L4 -> 0 | O4: =N4+M4 -> 0
A5: 1.1.2 | B5: Зарплата производственного персонала | C5: Робота | D5: Виробництво/Будівництво | E5: Каркас | F5: 1.1.2 | G5: Обробка матеріалу (дерево) | I5: чол/год | J5: =96/7 -> 13.714286 | K5: 200 | M5: =J5*K5 -> 2742.8571 | N5: =J5*L5 -> 0 | O5: =N5+M5 -> 2742.8571
A6: 1.1.3 | B6: Зарплата производственного персонала | C6: Робота | D6: Виробництво/Будівництво | E6: Каркас | F6: 1.1.3 | G6: Нарізання деталей зігдно креслень | I6: чол/год | J6: =96/7 -> 13.714286 | K6: 200 | M6: =J6*K6 -> 2742.8571 | N6: =J6*L6 -> 0 | O6: =N6+M6 -> 2742.8571
A7: 1.1.4 | B7: Зарплата производственного персонала | C7: Робота | D7: Виробництво/Будівництво | E7: Каркас | F7: 1.1.4 | G7: Збирання деталей | I7: чол/год | J7: =96/7 -> 13.714286 | K7: 200 | M7: =J7*K7 -> 2742.8571 | N7: =J7*L7 -> 0 | O7: =N7+M7 -> 2742.8571
A8: 1.1.5 | B8: Зарплата производственного персонала | C8: Робота | D8: Виробництво/Будівництво | E8: Каркас | F8: 1.1.5 | G8: зварювання (дерево зєдання) | I8: чол/год | J8: =96/7 -> 13.714286 | K8: 200 | M8: =J8*K8 -> 2742.8571 | N8: =J8*L8 -> 0 | O8: =N8+M8 -> 2742.8571
A9: 1.1.6 | B9: Зарплата производственного персонала | C9: Робота | D9: Виробництво/Будівництво | E9: Каркас | F9: 1.1.6 | G9: Влаштування підшиви модуля | I9: чол/год | J9: =96/7 -> 13.714286 | K9: 200 | M9: =J9*K9 -> 2742.8571 | N9: =J9*L9 -> 0 | O9: =N9+M9 -> 2742.8571
A10: 1.1.7 | B10: Зарплата производственного персонала | C10: Робота | D10: Виробництво/Будівництво | E10: Каркас | F10: 1.1.7 | G10: Грунтування металокаркасу | I10: чол/год | J10: =96/7 -> 13.714286 | K10: 200 | M10: =J10*K10 -> 2742.8571 | N10: =J10*L10 -> 0 | O10: =N10+M10 -> 2742.8571
A11: 1.1.8 | B11: Зарплата производственного персонала | C11: Робота | D11: Виробництво/Будівництво | E11: Каркас | F11: 1.1.8 | G11: Фарубування металокаркасу | I11: чол/год | J11: =96/7 -> 13.714286 | K11: 200 | M11: =J11*K11 -> 2742.8571 | N11: =J11*L11 -> 0 | O11: =N11+M11 -> 2742.8571
A12: 1.2 | F12: 1.2 | G12: МАТЕРІАЛИ
A13: 1.2.1 | B13: Строительные материалы | C13: Матеріал | D13: Виробництво/Будівництво | E13: Каркас | F13: 1.2.1 | G13: Труба металева Ст3 100*100*3 | H13: Профільна труба | I13: м.п | J13: 50.2 | L13: 473 | M13: =J13*K13 -> 0 | N13: =J13*L13 -> 23744.6 | O13: =M13+N13 -> 23744.6
A14: 1.2.2 | B14: Строительные материалы | C14: Матеріал | D14: Виробництво/Будівництво | E14: Каркас | F14: 1.2.2 | G14: Труба металева Ст3 50*50*2 | H14: Профільна труба | I14: м.п. | J14: 175.2 | L14: 157 | M14: =J14*K14 -> 0 | N14: =J14*L14 -> 27506.4 | O14: =M14+N14 -> 27506.4
A15: 1.2.3 | B15: Строительные материалы | C15: Матеріал | D15: Виробництво/Будівництво | E15: Каркас | F15: 1.2.3 | G15: Труба металева Ст3 дв 40 *3,5 | H15: Профільна труба | I15: м.п | J15: 1.2 | L15: 151 | M15: =J15*K15 -> 0 | N15: =J15*L15 -> 181.2 | O15: =M15+N15 -> 181.2
A16: 1.2.4 | B16: Строительные материалы | C16: Матеріал | D16: Виробництво/Будівництво | E16: Каркас | F16: 1.2.4 | G16: Труба металева Ст3 дв 89 *3,5 | H16: Профільна труба | I16: м.п. | J16: 1 | L16: 339 | M16: =J16*K16 -> 0 | N16: =J16*L16 -> 339 | O16: =M16+N16 -> 339
A17: 1.2.5 | B17: Строительные материалы | C17: Матеріал | D17: Виробництво/Будівництво | E17: Каркас | F17: 1.2.5 | G17: Лист 4мм | H17: Лист ГК | I17: м.кв. | J17: 0.68 | L17: 1207 | M17: =J17*K17 -> 0 | N17: =J17*L17 -> 820.76 | O17: =M17+N17 -> 820.76
A18: 1.2.6 | B18: Строительные материалы | C18: Матеріал | D18: Виробництво/Будівництво | E18: Каркас | F18: 1.2.6 | G18: Лист 8мм | H18: Лист ГК | I18: м.кв. | J18: 1.215 | L18: 2487 | M18: =J18*K18 -> 0 | N18: =J18*L18 -> 3021.705 | O18: =M18+N18 -> 3021.705
A19: 1.2.7 | B19: Строительные материалы | C19: Матеріал | D19: Виробництво/Будівництво | E19: Каркас | F19: 1.2.7 | G19: Лист 14мм | H19: Лист ГК | I19: м.кв. | J19: 0.12 | L19: 4976 | M19: =J19*K19 -> 0 | N19: =J19*L19 -> 597.12 | O19: =M19+N19 -> 597.12
A20: 1.2.8 | B20: Строительные материалы | C20: Матеріал | D20: Виробництво/Будівництво | E20: Каркас | F20: 1.2.8 | G20: Гайка М48 | H20: Гайка | I20: шт | J20: 6 | L20: 1740 | M20: =J20*K20 -> 0 | N20: =J20*L20 -> 10440 | O20: =M20+N20 -> 10440
A21: 1.2.9 | B21: Строительные материалы | C21: Матеріал | D21: Виробництво/Будівництво | E21: Каркас | F21: 1.2.9 | G21: Шпилька М48 довжина 1000 мм | H21: Шпилька | I21: шт | J21: 3 | L21: 3600 | M21: =J21*K21 -> 0 | N21: =J21*L21 -> 10800 | O21: =M21+N21 -> 10800
A22: 1.2.10 | B22: Строительные материалы | C22: Матеріал | D22: Виробництво/Будівництво | E22: Каркас | F22: 1.2.10 | G22: Гайка М24 | H22: Гайка | I22: шт | J22: 14 | L22: 154 | M22: =J22*K22 -> 0 | N22: =J22*L22 -> 2156 | O22: =M22+N22 -> 2156
A23: 1.2.11 | B23: Строительные материалы | C23: Матеріал | D23: Виробництво/Будівництво | E23: Каркас | F23: 1.2.11 | G23: Болт М24х200 | H23: Болт | I23: шт | J23: 4 | L23: 168 | M23: =J23*K23 -> 0 | N23: =J23*L23 -> 672 | O23: =M23+N23 -> 672
A24: 1.2.12 | B24: Строительные материалы | C24: Матеріал | D24: Виробництво/Будівництво | E24: Каркас | F24: 1.2.12 | G24: Труба 40*40*3 | H24: Профільна труба | I24: м.п. | J24: 72 | L24: 165 | M24: =J24*K24 -> 0 | N24: =J24*L24 -> 11880 | O24: =M24+N24 -> 11880
... A51: 1.2.39 | B51: Строительные материалы | C51: Матеріал | D51: Виробництво/Будівництво | E51: Каркас | F51: 1.2.39 | G51: Гвинт з прес-шайбою 4,2*19 | H51: Гвинт | I51: шт | J51: 227 | L51: 0.93 | M51: =J51*K51 -> 0 | N51: =J51*L51 -> 211.11 | O51: =M51+N51 -> 211.11
A52: 1.2.40 | B52: Строительные материалы | C52: Матеріал | D52: Виробництво/Будівництво | E52: Каркас | F52: 1.2.40 | G52: Гвинт з прес-шайбою 4,2*16 | H52: Гвинт | I52: шт | J52: 60 | L52: 0.32 | M52: =J52*K52 -> 0 | N52: =J52*L52 -> 19.2 | O52: =M52+N52 -> 19.2 | P52: =SUM(N13:N52) -> 151946.44 | Q52: +
A53: ІІ | F53: ІІ | G53: Отделка | M53: =J53*K53 -> 0 | N53: =J53*L53 -> 0 | O53: =N53+M53 -> 0
A54: 2.1 | F54: 2.1 | G54: РОБОТА | M54: =J54*K54 -> 0 | N54: =J54*L54 -> 0 | O54: =N54+M54 -> 0
A55: 2.1.1 | B55: Зарплата производственного персонала | C55: Робота | D55: Виробництво/Будівництво | E55: Отделка | F55: 2.1.1 | G55: Утеплення та гідроізоляція підлоги | I55: чол/год | J55: =3*8 -> 24 | K55: 200 | M55: =J55*K55 -> 4800 | N55: =J55*L55 -> 0 | O55: =N55+M55 -> 4800
A56: 2.1.2 | B56: Зарплата производственного персонала | C56: Робота | D56: Виробництво/Будівництво | E56: Отделка | F56: 2.1.2 | G56: Монтаж брусу по каркасу | I56: чол/год | J56: =3*8 -> 24 | K56: 200 | M56: =J56*K56 -> 4800 | N56: =J56*L56 -> 0 | O56: =N56+M56 -> 4800
A57: 2.1.3 | B57: Зарплата производственного персонала | C57: Робота | D57: Виробництво/Будівництво | E57: Отделка | F57: 2.1.3 | G57: Пароізоляційна мембрана; | I57: чол/год | J57: =3*8*1 -> 24 | K57: 200 | M57: =J57*K57 -> 4800 | N57: =J57*L57 -> 0 | O57: =N57+M57 -> 4800
A58: 2.1.4 | B58: Зарплата производственного персонала | C58: Робота | D58: Виробництво/Будівництво | E58: Отделка | F58: 2.1.4 | G58: Укладання Настил підлоги | I58: чол/год | J58: =3*8*1 -> 24 | K58: 200 | M58: =J58*K58 -> 4800 | N58: =J58*L58 -> 0 | O58: =N58+M58 -> 4800
A59: 2.1.5 | B59: Зарплата производственного персонала | C59: Робота | D59: Виробництво/Будівництво | E59: Отделка | F59: 2.1.5 | G59: Гідроізоляційна та пароізоляція стін та стелі | I59: чол/год | J59: =3*8*1 -> 24 | K59: 200 | M59: =J59*K59 -> 4800 | N59: =J59*L59 -> 0 | O59: =N59+M59 -> 4800
A60: 2.1.6 | B60: Зарплата производственного персонала | C60: Робота | D60: Виробництво/Будівництво | E60: Отделка | F60: 2.1.6 | G60: Утеплення стеля та стіни | I60: чол/год | J60: =3*8*1 -> 24 | K60: 200 | M60: =J60*K60 -> 4800 | N60: =J60*L60 -> 0 | O60: =N60+M60 -> 4800
A61: 2.1.7 | B61: Зарплата производственного персонала | C61: Робота | D61: Виробництво/Будівництво | E61: Отделка | F61: 2.1.7 | G61: Монтаж фінішного оздоблення | I61: чол/год | J61: =3*8*2+12 -> 60 | K61: 200 | M61: =J61*K61 -> 12000 | N61: =J61*L61 -> 0 | O61: =N61+M61 -> 12000
A62: 2.2 | E62: Отделка | F62: 2.2 | G62: МАТЕРІАЛИ | M62: =J62*K62 -> 0 | N62: =J62*L62 -> 0 | O62: =N62+M62 -> 0
A63: 2.2.1 | B63: Строительные материалы | C63: Матеріал | D63: Виробництво/Будівництво | E63: Отделка | F63: 2.2.1 | G63: Вітробарєр | H63: Вітробарєр | I63: м2 | J63: 42 | L63: 29 | M63: =J63*K63 -> 0 | N63: =J63*L63 -> 1218 | O63: =M63+N63 -> 1218
A64: 2.2.2 | B64: Строительные материалы | C64: Матеріал | D64: Виробництво/Будівництво | E64: Отделка | F64: 2.2.2 | G64: Паро-гідро бар'єр | H64: Паробар'єр | I64: м2 | J64: 120 | L64: 13 | M64: =J64*K64 -> 0 | N64: =J64*L64 -> 1560 | O64: =M64+N64 -> 1560
A65: 2.2.3 | B65: Строительные материалы | C65: Матеріал | D65: Виробництво/Будівництво | E65: Отделка | F65: 2.2.3 | G65: Пінопласт товщина 50 мм | H65: Пінопласт | I65: м2 | J65: 44 | L65: 88 | M65: =J65*K65 -> 0 | N65: =J65*L65 -> 3872 | O65: =M65+N65 -> 3872
A66: 2.2.4 | B66: Строительные материалы | C66: Матеріал | D66: Виробництво/Будівництво | E66: Отделка | F66: 2.2.4 | G66: Мінеральна вата (100 мм) | H66: Мінеральна вата | I66: м2 | J66: 55 | L66: 176 | M66: =J66*K66 -> 0 | N66: =J66*L66 -> 9680 | O66: =M66+N66 -> 9680
...

Sheet 30 м2
A1: № | B1: Стаття в ДДС | C1: Робота/матеріал/додаткові | D1: Виробництво/Будівництво | E1: Тип робіт | F1: № з/п | G1: Найменування робіт/витрат/матеріалів | I1: Од. вим. | J1: Кіль- кість | K1: Вартість робіт за од.виміру, грн. з ПДВ | L1: Вартість матеріалів за од.виміру, грн. з ПДВ | M1: Вартість робіт за повний обсяг, грн. з ПДВ | N1: Вартість матеріалів за повний обсяг, грн. з ПДВ | O1: Всього, грн. з ПДВ
A2: І | F2: І | G2: Каркас | J2: =L3+L12 -> 0
A3: 1.1 | F3: 1.1 | G3: РОБОТА | L3: =SUM(L5:L11) -> 0
A4: 1.1.1 | B4: Зарплата производственного персонала | C4: Робота | D4: Виробництво/Будівництво | E4: Каркас | F4: 1.1.1 | G4: Приймання матеріалу | I4: чол/год | K4: 200 | M4: =J4*K4 -> 0 | N4: =J4*L4 -> 0 | O4: =N4+M4 -> 0
A5: 1.1.2 | B5: Зарплата производственного персонала | C5: Робота | D5: Виробництво/Будівництво | E5: Каркас | F5: 1.1.2 | G5: Обробка матеріалу (дерево) | I5: чол/год | K5: 200 | M5: =J5*K5 -> 0 | N5: =J5*L5 -> 0 | O5: =N5+M5 -> 0
A6: 1.1.3 | B6: Зарплата производственного персонала | C6: Робота | D6: Виробництво/Будівництво | E6: Каркас | F6: 1.1.3 | G6: Нарізання деталей зігдно креслень | I6: чол/год | K6: 200 | M6: =J6*K6 -> 0 | N6: =J6*L6 -> 0 | O6: =N6+M6 -> 0
A7: 1.1.4 | B7: Зарплата производственного персонала | C7: Робота | D7: Виробництво/Будівництво | E7: Каркас | F7: 1.1.4 | G7: Збирання деталей | I7: чол/год | K7: 200 | M7: =J7*K7 -> 0 | N7: =J7*L7 -> 0 | O7: =N7+M7 -> 0
A8: 1.1.5 | B8: Зарплата производственного персонала | C8: Робота | D8: Виробництво/Будівництво | E8: Каркас | F8: 1.1.5 | G8: зварювання (дерево зєдання) | I8: чол/год | K8: 200 | M8: =J8*K8 -> 0 | N8: =J8*L8 -> 0 | O8: =N8+M8 -> 0
A9: 1.1.6 | B9: Зарплата производственного персонала | C9: Робота | D9: Виробництво/Будівництво | E9: Каркас | F9: 1.1.6 | G9: Влаштування підшиви модуля | I9: чол/год | K9: 200 | M9: =J9*K9 -> 0 | N9: =J9*L9 -> 0 | O9: =N9+M9 -> 0
A10: 1.1.7 | B10: Зарплата производственного персонала | C10: Робота | D10: Виробництво/Будівництво | E10: Каркас | F10: 1.1.7 | G10: Грунтування металокаркасу | I10: чол/год | K10: 200 | M10: =J10*K10 -> 0 | N10: =J10*L10 -> 0 | O10: =N10+M10 -> 0
A11: 1.1.8 | B11: Зарплата производственного персонала | C11: Робота | D11: Виробництво/Будівництво | E11: Каркас | F11: 1.1.8 | G11: Фарубування металокаркасу | I11: чол/год | K11: 200 | M11: =J11*K11 -> 0 | N11: =J11*L11 -> 0 | O11: =N11+M11 -> 0
A12: 1.2 | F12: 1.2 | G12: МАТЕРІАЛИ
A13: 1.2.1 | B13: Строительные материалы | C13: Матеріал | D13: Виробництво/Будівництво | E13: Каркас | F13: 1.2.1 | G13: Труба металева Ст3 100*100*3 | H13: Профільна труба | I13: м.п | J13: 80.4 | L13: 473 | M13: =J13*K13 -> 0 | N13: =J13*L13 -> 38029.2 | O13: =N13+M13 -> 38029.2
A14: 1.2.2 | B14: Строительные материалы | C14: Матеріал | D14: Виробництво/Будівництво | E14: Каркас | F14: 1.2.2 | G14: Труба металева Ст3 50*50*2 | H14: Профільна труба | I14: м.п. | J14: 240 | L14: 157 | M14: =J14*K14 -> 0 | N14: =J14*L14 -> 37680 | O14: =N14+M14 -> 37680
A15: 1.2.3 | B15: Строительные материалы | C15: Матеріал | D15: Виробництво/Будівництво | E15: Каркас | F15: 1.2.3 | G15: Труба металева Ст3 дв 40 *3,5 | H15: Профільна труба | I15: м.п | J15: 2.5 | L15: 151 | M15: =J15*K15 -> 0 | N15: =J15*L15 -> 377.5 | O15: =N15+M15 -> 377.5
A16: 1.2.4 | B16: Строительные материалы | C16: Матеріал | D16: Виробництво/Будівництво | E16: Каркас | F16: 1.2.4 | G16: Труба металева Ст3 дв 89 *3,5 | H16: Профільна труба | I16: м.п. | J16: 2 | L16: 339 | M16: =J16*K16 -> 0 | N16: =J16*L16 -> 678 | O16: =N16+M16 -> 678
A17: 1.2.5 | B17: Строительные материалы | C17: Матеріал | D17: Виробництво/Будівництво | E17: Каркас | F17: 1.2.5 | G17: Лист 4мм | H17: лист ГК | I17: м.кв. | J17: 1.02 | L17: 1207 | M17: =J17*K17 -> 0 | N17: =J17*L17 -> 1231.14 | O17: =N17+M17 -> 1231.14
A18: 1.2.6 | B18: Строительные материалы | C18: Матеріал | D18: Виробництво/Будівництво | E18: Каркас | F18: 1.2.6 | G18: Лист 8мм | H18: лист ГК | I18: м.кв. | J18: 1.215 | L18: 2487 | M18: =J18*K18 -> 0 | N18: =J18*L18 -> 3021.705 | O18: =N18+M18 -> 3021.705
A19: 1.2.7 | B19: Строительные материалы | C19: Матеріал | D19: Виробництво/Будівництво | E19: Каркас | F19: 1.2.7 | G19: Лист 14мм | H19: лист ГК | I19: м.кв. | J19: 0.24 | L19: 4976 | M19: =J19*K19 -> 0 | N19: =J19*L19 -> 1194.24 | O19: =N19+M19 -> 1194.24
A20: 1.2.8 | B20: Строительные материалы | C20: Матеріал | D20: Виробництво/Будівництво | E20: Каркас | F20: 1.2.8 | G20: Гайка М48 | H20: Гайка | I20: шт | J20: 11 | L20: 350 | M20: =J20*K20 -> 0 | N20: =J20*L20 -> 3850 | O20: =N20+M20 -> 3850
A21: 1.2.9 | B21: Строительные материалы | C21: Матеріал | D21: Виробництво/Будівництво | E21: Каркас | F21: 1.2.9 | G21: Шпилька М48 довжина 1000 мм | H21: Шпилька | I21: шт | J21: 5 | L21: 3600 | M21: =J21*K21 -> 0 | N21: =J21*L21 -> 18000 | O21: =N21+M21 -> 18000
A22: 1.2.10 | B22: Строительные материалы | C22: Матеріал | D22: Виробництво/Будівництво | E22: Каркас | F22: 1.2.10 | G22: Гайка М24 | H22: Гайка | I22: шт | J22: 28 | L22: 154 | M22: =J22*K22 -> 0 | N22: =J22*L22 -> 4312 | O22: =N22+M22 -> 4312
A23: 1.2.11 | B23: Строительные материалы | C23: Матеріал | D23: Виробництво/Будівництво | E23: Каркас | F23: 1.2.11 | G23: Болт М24х200 | H23: Болт | I23: шт | J23: 9 | L23: 168 | M23: =J23*K23 -> 0 | N23: =J23*L23 -> 1512 | O23: =N23+M23 -> 1512
A24: 1.2.12 | B24: Строительные материалы | C24: Матеріал | D24: Виробництво/Будівництво | E24: Каркас | F24: 1.2.12 | G24: Труба 40*40*3 | H24: Профільна труба | I24: м.п. | J24: 141 | L24: 165 | M24: =J24*K24 -> 0 | N24: =J24*L24 -> 23265 | O24: =N24+M24 -> 23265
... A52: 1.2.40 | B52: Строительные материалы | C52: Матеріал | D52: Виробництво/Будівництво | E52: Каркас | F52: 1.2.40 | G52: Гвинт з прес-шайбою 4,2*16 | H52: Гвинт | I52: шт | J52: 200 | L52: 0.32 | M52: =J52*K52 -> 0 | N52: =J52*L52 -> 64 | O52: =N52+M52 -> 64
A53: 1.2.41 | B53: Строительные материалы | C53: Матеріал | D53: Виробництво/Будівництво | E53: Каркас | F53: 1.2.41 | G53: Шуруп з пером 5,5*90 | H53: Саморіз | I53: шт | J53: 275 | L53: 1.03 | M53: =J53*K53 -> 0 | N53: =J53*L53 -> 283.25 | O53: =N53+M53 -> 283.25 | P53: =SUM(O13:O53) -> 236595.13 | Q53: +
A54: ІІ | F54: ІІ | G54: Отделка | M54: =J54*K54 -> 0 | N54: =J54*L54 -> 0 | O54: =N54+M54 -> 0
A55: 2.1 | F55: 2.1 | G55: РОБОТА | M55: =J55*K55 -> 0 | N55: =J55*L55 -> 0 | O55: =N55+M55 -> 0
A56: 2.1.1 | B56: Зарплата производственного персонала | C56: Робота | D56: Виробництво/Будівництво | E56: Отделка | F56: 2.1.1 | G56: Утеплення та гідроізоляція підлоги | I56: чол/год | K56: 200 | M56: =J56*K56 -> 0 | N56: =J56*L56 -> 0 | O56: =N56+M56 -> 0
A57: 2.1.2 | B57: Зарплата производственного персонала | C57: Робота | D57: Виробництво/Будівництво | E57: Отделка | F57: 2.1.2 | G57: Монтаж брусу по каркасу | I57: чол/год | K57: 200 | M57: =J57*K57 -> 0 | N57: =J57*L57 -> 0 | O57: =N57+M57 -> 0
A58: 2.1.3 | B58: Зарплата производственного персонала | C58: Робота | D58: Виробництво/Будівництво | E58: Отделка | F58: 2.1.3 | G58: Пароізоляційна мембрана; | I58: чол/год | K58: 200 | M58: =J58*K58 -> 0 | N58: =J58*L58 -> 0 | O58: =N58+M58 -> 0
A59: 2.1.4 | B59: Зарплата производственного персонала | C59: Робота | D59: Виробництво/Будівництво | E59: Отделка | F59: 2.1.4 | G59: Укладання Настил підлоги | I59: чол/год | K59: 200 | M59: =J59*K59 -> 0 | N59: =J59*L59 -> 0 | O59: =N59+M59 -> 0
A60: 2.1.5 | B60: Зарплата производственного персонала | C60: Робота | D60: Виробництво/Будівництво | E60: Отделка | F60: 2.1.5 | G60: Гідроізоляційна та пароізоляція стін та стелі | I60: чол/год | K60: 200 | M60: =J60*K60 -> 0 | N60: =J60*L60 -> 0 | O60: =N60+M60 -> 0
A61: 2.1.6 | B61: Зарплата производственного персонала | C61: Робота | D61: Виробництво/Будівництво | E61: Отделка | F61: 2.1.6 | G61: Утеплення стеля та стіни | I61: чол/год | K61: 200 | M61: =J61*K61 -> 0 | N61: =J61*L61 -> 0 | O61: =N61+M61 -> 0
A62: 2.1.7 | B62: Зарплата производственного персонала | C62: Робота | D62: Виробництво/Будівництво | E62: Отделка | F62: 2.1.7 | G62: Монтаж фінішного оздоблення | I62: чол/год | K62: 200 | M62: =J62*K62 -> 0 | N62: =J62*L62 -> 0 | O62: =N62+M62 -> 0
A63: 2.2 | E63: Отделка | F63: 2.2 | G63: МАТЕРІАЛИ | M63: =J63*K63 -> 0 | N63: =J63*L63 -> 0 | O63: =N63+M63 -> 0
A64: 2.2.1 | B64: Строительные материалы | C64: Матеріал | D64: Виробництво/Будівництво | E64: Отделка | F64: 2.2.1 | G64: Вітробарєр | H64: Мембрана | I64: м2 | J64: 82 | L64: 29 | M64: =J64*K64 -> 0 | N64: =J64*L64 -> 2378 | O64: =N64+M64 -> 2378
A65: 2.2.2 | B65: Строительные материалы | C65: Матеріал | D65: Виробництво/Будівництво | E65: Отделка | F65: 2.2.2 | G65: Паро-гідро бар'єр | H65: Мембрана | I65: м2 | J65: 210 | L65: 13 | M65: =J65*K65 -> 0 | N65: =J65*L65 -> 2730 | O65: =N65+M65 -> 2730
A66: 2.2.3 | B66: Строительные материалы | C66: Матеріал | D66: Виробництво/Будівництво | E66: Отделка | F66: 2.2.3 | G66: Пінопласт товщина 50 мм | H66: Пінопласт | I66: м2 | J66: 88 | L66: 112 | M66: =J66*K66 -> 0 | N66: =J66*L66 -> 9856 | O66: =N66+M66 -> 9856
A67: 2.2.4 | B67: Строительные материалы | C67: Матеріал | D67: Виробництво/Будівництво | E67: Отделка | F67: 2.2.4 | G67: Мінеральна вата (100 мм) | H67: мінеральна вата | I67: м2 | J67: 100 | L67: 180 | M67: =J67*K67 -> 0 | N67: =J67*L67 -> 18000 | O67: =N67+M67 -> 18000
...

Sheet IRC 30 m2
G2: =VLOOKUP(#REF!,[3]СВОД!$B$4:$D$4,3,0) -> #REF!
A3: Найменування матеріалів | C3: Од. вим. | D3: Кількість | E3: Вартість матеріалів за од., грн. з ПДВ | F3: Разом вартість матеріалів, грн. з ПДВ | G3: Вартість 1 м.кв. грн
A4: 7 | C4: 8 | D4: 9 | E4: 10 | F4: 11
A5: Каркас
A6: Труба металева Ст3 100*100*3 | B6: Профільна труба | C6: м.п | D6: =100.4-20 -> 80.4 | E6: 473 | F6: =E6*D6 -> 38029.2
A7: Труба металева Ст3 50*50*2 | B7: Профільна труба | C7: м.п. | D7: =290-50 -> 240 | E7: 157 | F7: =E7*D7 -> 37680
A8: Труба металева Ст3 дв 40 *3,5 | B8: Профільна труба | C8: м.п | D8: 2.5 | E8: 151 | F8: =E8*D8 -> 377.5
A9: Труба металева Ст3 дв 89 *3,5 | B9: Профільна труба | C9: м.п. | D9: 2 | E9: 339 | F9: =E9*D9 -> 678
A10: Лист 4мм | B10: лист ГК | C10: м.кв. | D10: 1.02 | E10: 1207 | F10: =E10*D10 -> 1231.14
A11: Лист 8мм | B11: лист ГК | C11: м.кв. | D11: 1.215 | E11: 2487 | F11: =E11*D11 -> 3021.705
A12: Лист 14мм | B12: лист ГК | C12: м.кв. | D12: 0.24 | E12: 4976 | F12: =E12*D12 -> 1194.24
A13: Гайка М48 | B13: Гайка | C13: шт | D13: 11 | E13: 350 | F13: =E13*D13 -> 3850
A14: Шпилька М48 довжина 1000 мм | B14: Шпилька | C14: шт | D14: 5 | E14: 3600 | F14: =E14*D14 -> 18000
A15: Гайка М24 | B15: Гайка | C15: шт | D15: 28 | E15: 154 | F15: =E15*D15 -> 4312
A16: Болт М24х200 | B16: Болт | C16: шт | D16: 9 | E16: 168 | F16: =E16*D16 -> 1512
A17: Труба 40*40*3 | B17: Профільна труба | C17: м.п. | D17: 141 | E17: 165 | F17: =E17*D17 -> 23265
A18: кутик 32*32 *3 | B18: Кутики сталеві | C18: м.п. | D18: 10 | E18: 62 | F18: =E18*D18 -> 620
A19: пвл 406 1,25*2,5 | B19: МШП | C19: лист | D19: 2 | E19: 1799.27 | F19: =E19*D19 -> 3598.54
... A46: Шуруп з пером 5,5*90 | B46: Саморіз | C46: шт | D46: 275 | E46: 1.03 | F46: =E46*D46 -> 283.25
A47: Загальна сума | F47: =SUM(F6:F46) -> 236595.13
A48: Отделка
A49: Вітробарєр | B49: Мембрана | C49: м2 | D49: 82 | E49: 29 | F49: =E49*D49 -> 2378
A50: Паро-гідро бар'єр | B50: Мембрана | C50: м2 | D50: 210 | E50: 13 | F50: =E50*D50 -> 2730
A51: Пінопласт товщина 50 мм | B51: Пінопласт | C51: м2 | D51: 88 | E51: 112 | F51: =E51*D51 -> 9856
A52: Мінеральна вата (100 мм) | B52: мінеральна вата | C52: м2 | D52: 100 | E52: 180 | F52: =E52*D52 -> 18000
A53: Мінеральна вата (50 мм) | B53: мінеральна вата | C53: м2 | D53: 341 | E53: 90 | F53: =E53*D53 -> 30690
A54: ЦСП панель 20 мм | B54: Плита ЦСП | C54: шт | D54: 9 | E54: 7700 | F54: =E54*D54 -> 69300
A55: Лінолеум комерційний на підлогу | B55: Лінолеум | C55: м2 | D55: 36 | E55: 515 | F55: =E55*D55 -> 18540
A56: Лінолеум на стіни | B56: Лінолеум | C56: м2 | D56: 160 | E56: 429 | F56: =E56*D56 -> 68640
A57: Клей для лінолеума | B57: Клей для лінолеума | C57: кг | D57: 35 | E57: 540 | F57: =E57*D57 -> 18900
A58: Плінтус 100 | B58: Плінтус | C58: м.п | D58: 75 | E58: 132.58 | F58: =E58*D58 -> 9943.5
A59: ПВХ вагонка 8мм біла | B59: ПВХ вагонка | C59: м2 | D59: 36 | E59: 229 | F59: =E59*D59 -> 8244
A60: Меблевий кутик | B60: Кутики пластикові | C60: м.п | D60: 92 | E60: 139.26 | F60: =E60*D60 -> 12811.92
... A69: Піна клей | B69: Піна клей | C69: шт | D69: 6 | E69: 293 | F69: =E69*D69 -> 1758
A70: Загальна сума | F70: =SUM(F49:F69) -> 325398.42
A71: Фасад
A72: Порфлист ПК 8 | B72: Профнастил | C72: м2 | D72: 33 | E72: 286 | F72: =E72*D72 -> 9438
A73: Порфлист ПК 20 Покрівля | B73: Профнастил | C73: м2 | D73: 43.2 | E73: 289 | F73: =E73*D73 -> 12484.8
A74: Порфлист ПК 10 Стіни | B74: Профнастил | C74: м2 | D74: 100 | E74: 281 | F74: =E74*D74 -> 28100
A75: Гладкий лист білий | B75: Гладкий лист метал | C75: м2 | D75: 44 | E75: 277 | F75: =E75*D75 -> 12188
...

Sheet IRC 15 m2
G2: =VLOOKUP(#REF!,[3]СВОД!$B$4:$D$4,3,0) -> #REF!
A3: Найменування матеріалів | B3: Уніфікації | C3: Од. вим. | D3: Кількість | E3: Вартість матеріалів за од., грн. з ПДВ | F3: Разом вартість матеріалів, грн. з ПДВ | G3: Вартість 1 м.кв. грн
A4: 7 | C4: 8 | D4: 9 | E4: 10 | F4: 11
A5: Каркас
A6: Труба металева Ст3 100*100*3 | B6: Профільна труба | C6: м.п | D6: 50.2 | E6: 473 | F6: =E6*D6 -> 23744.6
A7: Труба металева Ст3 50*50*2 | B7: Профільна труба | C7: м.п. | D7: 175.2 | E7: 157 | F7: =E7*D7 -> 27506.4
A8: Труба металева Ст3 дв 40 *3,5 | B8: Профільна труба | C8: м.п | D8: 1.2 | E8: 151 | F8: =E8*D8 -> 181.2
A9: Труба металева Ст3 дв 89 *3,5 | B9: Профільна труба | C9: м.п. | D9: 1 | E9: 339 | F9: =E9*D9 -> 339
A10: Лист 4мм | B10: Лист ГК | C10: м.кв. | D10: 0.68 | E10: 1207 | F10: =E10*D10 -> 820.76
A11: Лист 8мм | B11: Лист ГК | C11: м.кв. | D11: 1.215 | E11: 2487 | F11: =E11*D11 -> 3021.705
A12: Лист 14мм | B12: Лист ГК | C12: м.кв. | D12: 0.12 | E12: 4976 | F12: =E12*D12 -> 597.12
A13: Гайка М48 | B13: Гайка | C13: шт | D13: 6 | E13: 1740 | F13: =E13*D13 -> 10440
A14: Шпилька М48 довжина 1000 мм | B14: Шпилька | C14: шт | D14: 3 | E14: 3600 | F14: =E14*D14 -> 10800
A15: Гайка М24 | B15: Гайка | C15: шт | D15: 14 | E15: 154 | F15: =E15*D15 -> 2156
A16: Болт М24х200 | B16: Болт | C16: шт | D16: 4 | E16: 168 | F16: =E16*D16 -> 672
A17: Труба 40*40*3 | B17: Профільна труба | C17: м.п. | D17: 72 | E17: 165 | F17: =E17*D17 -> 11880
... A46: Шуруп з пером 5,5*90 | B46: Саморіз | C46: шт | D46: 135 | E46: 1.03 | F46: =E46*D46 -> 139.05
A47: Загальна сума | F47: =SUM(F6:F46) -> 152085.49
A48: Отделка
A49: Вітробарєр | B49: Вітробарєр | C49: м2 | D49: 42 | E49: 29 | F49: =E49*D49 -> 1218
A50: Паро-гідро бар'єр | B50: Паробар'єр | C50: м2 | D50: 120 | E50: 13 | F50: =E50*D50 -> 1560
A51: Пінопласт товщина 50 мм | B51: Пінопласт | C51: м2 | D51: 44 | E51: 88 | F51: =E51*D51 -> 3872
A52: Мінеральна вата (100 мм) | B52: Мінеральна вата | C52: м2 | D52: 55 | E52: 176 | F52: =E52*D52 -> 9680
A53: Мінеральна вата (50 мм) | B53: Мінеральна вата | C53: м2 | D53: 171 | E53: 77 | F53: =E53*D53 -> 13167
A54: ЦСП панель 20 мм | B54: Плита ЦСП | C54: шт | D54: 5 | E54: 7700 | F54: =E54*D54 -> 38500
A55: Лінолеум комерційний на підлогу | B55: Лінолеум | C55: м2 | D55: 18 | E55: 515 | F55: =E55*D55 -> 9270
A56: Лінолеум на стіни | B56: Лінолеум | C56: м2 | D56: 80.1 | E56: 429 | F56: =E56*D56 -> 34362.9
A57: Клей для лінолеума | B57: Клей для лінолеума | C57: кг | D57: 26 | E57: 321.37 | F57: =E57*D57 -> 8355.62
A58: Плінтус | B58: Плінтус | C58: м.п | D58: 35 | E58: 132.58 | F58: =E58*D58 -> 4640.3
A59: ПВХ вагонка 8мм біла | B59: ПВХ вагонка | C59: м2 | D59: 18 | E59: 229 | F59: =E59*D59 -> 4122
A60: Меблевий кутик | B60: Кутик меблевий | C60: м.п | D60: 84 | E60: 75 | F60: =E60*D60 -> 6300
... A69: Піна клей | B69: Піна клей | C69: шт | D69: 4 | E69: 293 | F69: =E69*D69 -> 1172
A70: Загальна сума | F70: =SUM(F49:F69) -> 163888.82
A71: Фасад
A72: Порфлист ПК 8 | B72: Профнастил | C72: м2 | D72: 16.5 | E72: 286 | F72: =E72*D72 -> 4719
A73: Порфлист ПК 20 Покрівля | B73: Профнастил | C73: м2 | D73: 21 | E73: 289 | F73: =E73*D73 -> 6069
A74: Порфлист ПК 10 Стіни | B74: Профнастил | C74: м2 | D74: 105 | E74: 281 | F74: =E74*D74 -> 29505
A75: Гладкий лист білий | B75: Гладкий лист метал | C75: м2 | D75: 23 | E75: 277 | F75: =E75*D75 -> 6371
A76: Ринва | B76: Ринва | C76: шт | D76: 3 | E76: 403 | F76: =E76*D76 -> 1209
A77: труба | B77: Труба водостічна | C77: шт | D77: 2 | E77: 442 | F77: =E77*D77 -> 884
...

Sheet Склади Стіл
A1: Склад | E1: Количество | F1: Сумма | G1: Количество для списания
A2: Рахунок | B2: Номенклатура код | C2: Номенклатура | D2: Единица | H2: Узагальнена назва | I2: ТИП
A3: СТІЛ _Червоний хрест | E3: 148.392 | F3: 306596.47
A4: 0221 | B4: 00-00016761 | C4: Водонагрівач 80л | D4: шт | E4: 2 | F4: 25520 | H4: Бойлер електричний | I4: Сантехніка
A5: 0221 | B5: 00-00017550 | C5: Двері вхідні 2050х860 металеві Л | D5: шт | E5: 2 | F5: 14866.6 | H5: Вхідні двері металеві | I5: вікна та двері
A6: 0221 | B6: 00-00017549 | C6: Двері вхідні 2050х860 металеві П | D6: шт | E6: 4 | F6: 29733.4 | H6: Вхідні двері металеві | I6: вікна та двері
A7: 0221 | B7: 00-00005567 | C7: Диспенсер туалетного папіру | D7: шт | E7: 2 | F7: 1308 | H7: Диспенсер для туалетного паперу | I7: Дополнительная Комплектация
A8: 0221 | B8: 00000006816 | C8: Дозатор для мила | D8: шт | E8: 2 | F8: 1374 | H8: Диспенсер рідкого мила | I8: Дополнительная Комплектация
A9: 0221 | B9: 00-00005396 | C9: Душова система | D9: шт | E9: 2 | F9: 8653.33 | H9: Змішувач для душу | I9: Сантехніка
A10: 0221 | B10: 00-00017539 | C10: Емаль ЕП-140 сіра, кг | D10: кг | E10: 50 | F10: 7291.5 | H10: фарба | I10: Каркас та конструкції
A11: 0221 | B11: 00000006819 | C11: Йоршик | D11: шт | E11: 2 | F11: 445 | H11: Йоршик | I11: Дополнительная Комплектация
A12: 0221 | B12: 00-00011895 | C12: Кріплення для телевізора | D12: шт | E12: 4 | F12: 4623.33 | H12: Кріплення для телевізора | I12: Дополнительная Комплектация
A13: 0221 | B13: 00-00017537 | C13: Кронштейн для мікрохвильвої печі | D13: шт | E13: 4 | F13: 2776.67 | H13: Кріплення для мікрохвильової печі | I13: Дополнительная Комплектация
A14: 0221 | B14: 00-00017255 | C14: Кутник 200х200х14 L=6 ст 1-3 сп/пс 5 | D14: т | E14: 2.02 | F14: 84587.5 | H14: Кутик | I14: Каркас та конструкції
A15: 0221 | B15: 00000012186 | C15: Кутник 63х63х5 L=6000 | D15: т | E15: 0.055 | F15: 1588.25 | H15: Кутик | I15: Каркас та конструкції
... A27: 0221 | B27: 00-00015078 | C27: Швелер 12 UPEAA | D27: т | E27: 0.265 | F27: 8338.53 | H27: Швелер | I27: Каркас та конструкції
A28: СТІЛ Виробничий склад | E28: 269.917 | F28: 54236.46
A29: 203 | B29: 00-00000320 | C29: Бензин А-95 | D29: л | E29: 14.2 | F29: 780.72
A30: 201 | B30: 00-00003742 | C30: Гіпсокартон KNAUF 12,5 мм х 1,2 х 2,5 м | D30: шт | E30: 1 | F30: 416 | H30: ГКЛ | I30: Отделка
A31: 201 | B31: 00-00006387 | C31: Добавка для фарби 1 л | D31: шт | E31: 2 | F31: 138 | H31: фарба | I31: Отделка
A32: 201 | B32: 00000010866 | C32: Емаль алкідна ПФ-115 М чорна 0,9 л | D32: шт | E32: 1 | F32: 118 | H32: фарба | I32: Каркас та конструкції
A33: 201 | B33: 00000020666 | C33: Емаль алкідна ПФ-115 червона 2,8 кг | D33: шт | E33: 1 | F33: 435 | H33: фарба | I33: Каркас та конструкції
A34: 201 | B34: 00000000102 | C34: З'єднувач PP-R D=20 mm. х1\2 Н сірий | D34: шт | E34: 3 | F34: 144.36 | H34: З'єднувач PP-R | I34: Сантехніка
A35: 201 | B35: 00000003426 | C35: Замок навісний | D35: шт | E35: 2 | F35: 386 | H35: мшп | I35: МШП
A36: 201 | B36: 00000002631 | C36: Кабель КГ 1х16 | D36: км | E36: 0.02 | F36: 1855.92 | H36: мшп | I36: МШП
A37: 201 | B37: 00-00010543 | C37: Кабель КГ 1х50 | D37: км | E37: 0.012 | F37: 3406.03 | H37: мшп | I37: МШП
A38: 221 | B38: 00-00012204 | C38: Колесо до візка *160 | D38: шт | E38: 4 | F38: 2024 | H38: мшп | I38: МШП
A39: 221 | B39: 00000007159 | C39: Круг алмазний відрізний 1A1RSS/C3-W 350х3,2/2,2*25,4 R160 Meteor Н15 | D39: шт | E39: 5 | F39: 808.35 | H39: мшп | I39: МШП
A40: 221 | B40: 00000017499 | C40: Круг відрізний по металу 125х1.6х22.2 мм прямий по металу | D40: шт | E40: 21 | F40: 384.3 | H40: Обрізні диски | I40: МШП
A41: 221 | B41: 00000017499 | C41: Круг відрізний по металу 125х1.6х22.2 мм прямий по металу | D41: шт | E41: 4 | F41: 730.4 | H41: Обрізні диски | I41: МШП
... A45: 201 | B45: 00-00009039 | C45: Накінечник DT-010 | D45: шт | E45: 8 | F45: 192 | H45: мшп | I45: МШП
A46: 221 | B46: 00000002101 | C46: Окуляри захисні | D46: шт | F46: 73.04 | H46: мшп | I46: МШП
A47: 221 | B47: 00-00015312 | C47: Олива для двохкратних двигунів | D47: шт | E47: 1 | F47: 159.2 | H47: мшп | I47: МШП
A48: 201 | B48: 00000020498 | C48: ПВС 3х2,5 дріт | D48: км | E48: 0.08 | F48: 3722.88 | H48: кабель | I48: Электрика/Подогрев
A49: 201 | B49: 00-00010574 | C49: Пісок (20кг) | D49: шт | E49: 20 | F49: 580 | H49: мшп | I49: МШП
A50: 201 | B50: 00-00010574 | C50: Пісок (20кг) | D50: шт | E50: 50 | F50: 1450 | H50: мшп | I50: МШП
A51: 201 | B51: 00-00010574 | C51: Пісок (20кг) | D51: шт | E51: 25 | F51: 725 | H51: мшп | I51: МШП
A52: 201 | B52: 00-00010574 | C52: Пісок (20кг) | D52: шт | E52: 18 | F52: 522 | H52: мшп | I52: МШП
A53: 221 | B53: 00000008993 | C53: Пістолет для підкачки коліс вантаж.авто | D53: шт | E53: 1 | F53: 275.8 | H53: мшп | I53: МШП
A54: 221 | B54: 00000020793 | C54: Прожектор світлодіодний LED 100 W FL12 чорний | D54: шт | E54: 10 | F54: 6513.1 | H54: Світильник | I54: Электрика/Подогрев
...

Sheet Матеріали по СС
A1: №№ | B1: Назва згідно СС | C1: Узагальнена назва | D1: Од | E1: Тип
A2: 1 | B2: П’ЄДЕСТАЛ DECO 3922900000 | C2: П’ЄДЕСТАЛ | D2: шт | E2: Сантехніка
A3: 2 | B3: Болт кріплення для бойлера, М10х100мм ( 2шт) | C3: Болт кріплення М10х100мм | D3: шт | E3: Сантехніка
A4: 3 | B4: Гнучний шланг, 1 / 2" ВВ, довжина 30 см | C4: Гнучний шланг, 1 / 2" ВВ | D4: шт | E4: Сантехніка
A5: 4 | B5: Держак ринви | C5: Держак ринви | D5: шт | E5: фасад
A6: 5 | B6: Держак труби металевий | C6: Держак труби металевий | D6: шт | E6: фасад
A7: 6 | B7: Заглушка D=50 | C7: Заглушка | D7: шт | E7: Сантехніка
A8: 7 | B8: Залізо бетонна кришка з отвором Д1500 мм | C8: Залізо бетонна кришка Д 1500 мм | D8: шт | E8: Сантехніка
A9: 8 | B9: Залізо бетонне дно Д1500 мм | C9: Залізо бетонне дно Д 1500 мм | D9: шт | E9: Сантехніка
A10: 9 | B10: Залізо бетонне кільце Д1500 мм | C10: Залізо бетонне кільце Д 1500 мм | D10: шт | E10: Сантехніка
A11: 10 | B11: З'єднувач PP-R D=20 mm. х1\2 З | C11: З'єднувач PP-R D=20 mm. х1\2 З | D11: шт | E11: Сантехніка
A12: 11 | B12: З'єднувач ринви | C12: З'єднувач ринви | D12: шт | E12: фасад
A13: 12 | B13: Змішувач NICO, для умивальника, хром. | C13: Змішувач | D13: шт | E13: Сантехніка
... A315: 314 | B315: Злив правий | C315: Злив правий | D315: шт | E315: фасад
A316: 315 | B316: Інформаційний банер зовнішній - 2130х500мм | C316: Інформаційний банер | E316: Дополнительная Комплектация
A317: 316 | B317: Карниз кутовий 90*90 | C317: Карниз кутовий | D317: шт | E317: фасад
A318: 317 | B318: Керамічна плитка | C318: Керамічна плитка | D318: м² | E318: Отделка
A319: 318 | B319: Клей для лінолеума | C319: Клей для лінолеума | D319: кг | E319: Отделка
A320: 319 | B320: Клей для лінолеума | C320: Клей для лінолеума | D320: кг | E320: Отделка
A321: 320 | B321: Клей для ПВХ мембрани | C321: Клей для ПВХ мембрани | D321: кг | E321: Отделка
A322: 321 | B322: Клей монтажнй білий | C322: Клей монтажнй білий | D322: шт | E322: Отделка
A323: 322 | B323: Кляймер для фальш-бруса | C323: Кляймер для фальш-бруса | D323: шт | E323: Отделка
A324: 323 | B324: кріплення ринви | C324: кріплення | D324: шт | E324: фасад
A325: 324 | B325: кріплення труби | C325: кріплення | D325: шт | E325: фасад
A326: 325 | B326: Кут внутрішній | C326: Кут внутрішній | D326: шт | E326: фасад
A327: 326 | B327: Кут зовнішній | C327: Кут зовнішній | D327: шт | E327: фасад
A328: 327 | B328: Кутик 25х25х3 мм | C328: Кутики сталеві | D328: м.п | E328: Каркас та конструкції
... A334: 333 | B334: Кутики білі 50*50 мм 2,7м | C334: Кутик | D334: шт | E334: Отделка
A335: 334 | B335: Кутики, з'єднувачі, глушки | C335: з'єднувачі | E335: Отделка
A336: 335 | B336: Кутова планка внутрішня дерев'яна 15*15 (3м) | C336: Кутик | D336: м | E336: Отделка
A337: 337 | B337: Лак Паркетний | C337: Лак | D337: шт | E337: Отделка
A338: 338 | B338: Лак поліуретановий білий ТН 4701-902 | C338: Лак | D338: л | E338: Отделка
A339: 339 | B339: Ламінована ДСП плита 16мм (колір - білий); | C339: Плита ЛДСП | D339: м2 | E339: Отделка
A340: 340 | B340: ЛДСП 16 мм Swiss Krono U119 PE | C340: Плита ЛДСП | D340: м² | E340: Отделка
A341: 341 | B341: Лист 14мм | C341: лист ГК | D341: м.кв. | E341: Каркас та конструкції
A342: 342 | B342: лист 3 мм | C342: лист ГК | D342: м.кв. | E342: Каркас та конструкції
A343: 343 | B343: Лист 4 мм | C343: лист ГК | D343: тон | E343: Каркас та конструкції
A344: 344 | B344: Лист 4мм | C344: лист ГК | D344: м.кв. | E344: Каркас та конструкції
A345: 345 | B345: Лист 5 мм | C345: лист ГК | D345: м.кв. | E345: Каркас та конструкції
A346: 346 | B346: Лист 6мм | C346: лист ГК | D346: т | E346: Каркас та конструкції
...
