Workbook
Name Excel_BuiltIn_Print_Area_4: "#REF!"
Name Excel_BuiltIn_Print_Area_4_1: "#REF!"
Name Excel_BuiltIn_Print_Area_7: "#REF!"
Name Excel_BuiltIn_Print_Area_7_1: "#REF!"

Sheet расчет 2020
A2: 1. Расчет комиссии ФА: | C2: =AVERAGE(E4:E15) -> 0.1203793
C3: Всего | D3: в т.ч. комиссия | E3: удельный вес комиссии
B4: 1 | C4: =21734908.08+3039907.5 -> 24774816 | D4: 3039907.5 | E4: =D4/C4 -> 0.12270152
B5: 2 | C5: 2085216.7 | D5: 250168.02 | E5: =D5/C5 -> 0.11997219
B6: 3 | C6: 1619210.3 | D6: 187157.29 | E6: =D6/C6 -> 0.11558554
B7: 4 | C7: 6381759.2 | D7: 713762.83 | E7: =D7/C7 -> 0.11184421
B8: 5 | C8: 4404553.6 | D8: 504620.64 | E8: =D8/C8 -> 0.11456794
B9: 6 | C9: 5156496.2 | D9: 640953.8 | E9: =D9/C9 -> 0.12430026
B10: 7 | C10: 10920915 | D10: 1332106.5 | E10: =D10/C10 -> 0.12197756
B11: 8 | C11: 1984735.1 | D11: 252504.11 | E11: =D11/C11 -> 0.12722308
B12: 9 | C12: 3501909.8 | D12: 427337.8 | E12: =D12/C12 -> 0.12202993
B13: 10 | C13: 8418994.3 | D13: 1036294.3 | E13: =D13/C13 -> 0.12309003
B14: 11 | C14: 4529395.4 | D14: 544927.64 | E14: =D14/C14 -> 0.12030914
B15: 12 | C15: 3867500 | D15: 467775 | E15: =D15/C15 -> 0.12095023
A17: 2. | B17: Чистая прибыль: | C17: =#REF! -> #REF!
B18: Дивиденды выплачены | C18: =2051500+250000+246471 -> 2547971
B19: Покупка ОС | C19: =SUM(C21:C25) -> 23342228
B20: в т.ч.:
B21: офис | C21: =ОС!E41+88654.88+28990+12399.97+9971+18496.99 -> 262876.84
B22: техника | C22: =ОС!E39+806079.43+11600.04 -> 20594884
B23: производственные ОС | C23: =1348943.82+134648.07+ОС!E40+66223.6+41478.04+153811.68 -> 2167456.5
B24: ПК, ПО | C24: =242313.65+36673+600+37424 -> 317010.65
B26: фин.помощь,поплн.капит. | C26: =1840475+2243327+4623157-2186000 -> 6520959
C27: =C17-C18-C19+C26 -> #REF!
B29: не проведен:
B30: Пологи
B33: Приднепровский
C36: =SUM(C30:C35) -> 0
B38: резервный фонд (ф1 и Ф2 кроме ячейки согласно фиксов) | C38: =1300000+200000 -> 1500000
C40: =C27+C36-C38 -> #REF!
B41: тягач в январе | C41: -500000
C42: =C40+C41 -> #REF!

Sheet ОС
A8: Платежное поручение исходящее 9463 от 28.01.2020 0:00:00 | B8: РДК 250 | D8: -246 540,00 | E8: -246540 | F8: техника
A9: Платежное поручение исходящее 9502 от 31.01.2020 0:00:00 | B9: Гусиничные экскаватор | D9: -750 000,00 | E9: -750000 | F9: техника
A10: Расходный кассовый ордер N00017577 от 04.02.2020 12:00:04 | B10: покупка экскаватора JCB 220 34 400 $ | C10: -852 432,00 | E10: -852432 | F10: техника
A11: Расходный кассовый ордер N00016963 от 05.02.2020 15:05:30 | B11: Покупка гусенничного экскаватора (33 300 $) | C11: -833 215,00 | E11: -833215 | F11: техника
A12: Платежное поручение исходящее 9657 от 14.02.2020 0:00:00 | D12: -221 175,00 | E12: -221175 | F12: техника
A13: Платежное поручение исходящее 9816 от 18.02.2020 0:00:00 | B13: доплата за экскаватор 220 | D13: -108 395,00 | E13: -108395 | F13: техника
A14: Платежное поручение исходящее 000000513 от 31.03.2020 0:00:00 | D14: -562 600,00 | E14: -562600 | F14: техника
A15: Расходный кассовый ордер N00018123 от 31.03.2020 17:57:36 | B15: покупка экскаватора JCB 3Cх 16 650$ | C15: -466 200,00 | E15: -466200 | F15: техника
A16: Расходный кассовый ордер N00018408 от 17.04.2020 15:28:32 | B16: доплата за экскаватор 9000 $ 8350 - по курсу 28 грн - 233 800 + 300 по курсу 27,3 - 8 190 грн 350 по курсу 27,35 - 9572,5 | C16: -251 562,50 | E16: -251562.5 | F16: техника
A17: Платежное поручение исходящее 000001247 от 30.04.2020 11:19:10 | B17: покупка автокрана | D17: -2 062 500,00 | E17: -2062500 | F17: техника
A18: Расходный кассовый ордер N00018609 от 30.04.2020 11:23:57 | B18: Автокран 70 100$ курс 27 грн | C18: -1 892 700,00 | E18: -1892700 | F18: техника
A19: Платежное поручение исходящее 000001416 от 07.05.2020 12:50:04 | B19: Тахеометр -1 шт, штатив дер. с клипсами -1 шт , минипризма -1 шт, стикир для отбивки а-4 -1 шт | D19: -104 364,00 | E19: -104364 | F19: офис
A20: Платежное поручение исходящее 000001870 от 26.05.2020 0:00:00 | D20: -134 425,00 | E20: -134425 | F20: техника
A21: Платежное поручение исходящее 000002737 от 25.06.2020 0:00:00 | B21: Покупка нового автокрана | D21: -272 442,00 | E21: -272442 | F21: техника
A22: Платежное поручение исходящее 000002951 от 03.07.2020 0:00:00 | B22: самосвал | D22: -137 500,00 | E22: -137500 | F22: техника
A23: Расходный кассовый ордер N00019738 от 03.07.2020 17:29:02 | B23: покупка самосвала 25000$*27,05 | C23: -676 250,00 | E23: -676250 | F23: техника
A24: Расходный кассовый ордер N00019737 от 03.07.2020 17:29:43 | B24: покупка автокрана 54800$*27,05 | C24: -1 482 340,00 | E24: -1482340 | F24: техника
A25: Платежное поручение исходящее 000003272 от 14.07.2020 0:00:00 | B25: налоги за покупку камаза | D25: -2 205,88 | E25: -2205.88 | F25: техника
A26: Платежное поручение исходящее 000003274 от 14.07.2020 0:00:00 | B26: за покупку камаза | D26: -7 352,94 | E26: -7352.94 | F26: техника
A27: Платежное поручение исходящее 000003506 от 24.07.2020 10:52:58 | B27: автонавантажувач | D27: -1 210 170,00 | E27: -1210170 | F27: техника
A28: Платежное поручение исходящее 000004799 от 08.09.2020 13:24:04 | B28: Аванс телескоп 2 000 $ *27.77 | D28: -55 540,00 | E28: -55540 | F28: техника
A29: Платежное поручение исходящее 000005108 от 15.09.2020 15:52:23 | B29: Комплекс електродугової металізації КЕМ-1 (мод. 03-01) - 1 шт. | D29: -220 026,00 | E29: -220026 | F29: производственные ОС
A30: Платежное поручение исходящее 000005107 от 15.09.2020 15:52:31 | B30: Компресор А-1808 стаціонарний електричний гвинтовий - 1 шт; Система дистанційного керування - 1 шт; Повітряний рукав для дихання 9мм х 15мм, 40м - 1 шт; AirFlex-32 Повітряний рукав ID=32мм, бухта 40м - 0,125 шт; Фітинг Ду.32 DKR (1,1/4``-11) - 2 шт; Хомут для рукава 1.1/4" з захисними затискачами - 2 шт; Ресивер РВ 500.600-37 - 1 шт; Фильтр ФСВ -О-140 - 1 шт. | D30: -188 332,02 | E30: -188332.02 | F30: производственные ОС
A31: Платежное поручение исходящее 000005470 от 29.09.2020 11:30:56 | B31: кабеля для станка метализации и компрессора нового | D31: -13 993,25 | E31: -13993.25 | F31: производственные ОС
A32: Платежное поручение исходящее 000005610 от 30.09.2020 11:29:08 | B32: доплата телескоп 4 ( 46 100$ * 28.35) | D32: -1 306 935,00 | E32: -1306935 | F32: техника
A33: Платежное поручение исходящее 000005839 от 09.10.2020 9:37:38 | B33: Аванс XCMG 55 73 000 евро *33,36 + 0,65 % РКО | D33: -2 451 109,32 | E33: -2451109.3 | F33: техника
A34: Платежное поручение исходящее 000005905 от 09.10.2020 13:00:39 | B34: АВАНС 2000 дол. | D34: -56 520,00 | E34: -56520 | F34: техника
A35: Платежное поручение исходящее 000006053 от 15.10.2020 14:40:09 | B35: XCMG 55 = 69 500 евро *33,36+0,65 % РКО | D35: -2 333 590,38 | E35: -2333590.4 | F35: техника
A36: Платежное поручение исходящее 000006054 от 15.10.2020 14:45:16 | B36: Полная оплата 49 500 *28, 35 | D36: -1 403 505,00 | E36: -1403505 | F36: техника
E37: =SUM(E8:E36) -> -20303920
E39: =SUMIF($F$8:$F$36,F39,$E$8:$E$36)*-1 -> 19777205 | F39: техника
E40: =SUMIF($F$8:$F$36,F40,$E$8:$E$36)*-1 -> 422351.27 | F40: производственные ОС
E41: =SUMIF($F$8:$F$36,F41,$E$8:$E$36)*-1 -> 104364 | F41: офис
E42: =SUMIF($F$8:$F$36,F42,$E$8:$E$36)*-1 -> 0 | F42: Автомобіль Renauit Kangoo

Sheet PL_Сватово очередь 2
A2: PL Сватово очередь 2 | G2: Июнь 2020 | L2: Июль 2020 | Q2: Август 2020 | V2: Сентябрь 2020 | AA2: Октябрь 2020 | AF2: Ноябрь 2020 | AK2: Декабрь 2020 | AP2: Накопительный PL | AU2: Остаток PL январь 2020
A3: План итого
B4: Статья | C4: Сумма по Ф1, грн | D4: Сумма по Ф2, грн | E4: Сумма итого, грн | F4: % суммы затрат в общем объеме | G4: Сумма по Ф1, грн | H4: Сумма по Ф2, грн | I4: Сумма итого, грн | J4: % суммы затрат в общем объеме | K4: Комментарий | L4: Сумма по Ф1, грн | M4: Сумма по Ф2, грн | N4: Сумма итого, грн | O4: % суммы затрат в общем объеме | P4: Комментарий | Q4: Сумма по Ф1, грн | R4: Сумма по Ф2, грн | S4: Сумма итого, грн | T4: % суммы затрат в общем объеме | U4: Комментарий | V4: Сумма по Ф1, грн | W4: Сумма по Ф2, грн | X4: Сумма итого, грн | Y4: % суммы затрат в общем объеме | Z4: Комментарий | AA4: Сумма по Ф1, грн | AB4: Сумма по Ф2, грн | AC4: Сумма итого, грн | AD4: % суммы затрат в общем объеме | AE4: Комментарий | AF4: Сумма по Ф1, грн | AG4: Сумма по Ф2, грн | AH4: Сумма итого, грн | AI4: % суммы затрат в общем объеме | AJ4: Комментарий | AK4: Сумма по Ф1, грн | AL4: Сумма по Ф2, грн | AM4: Сумма итого, грн | AN4: % суммы затрат в общем объеме | AO4: Комментарий | AP4: Сумма по Ф1, грн | AQ4: Сумма по Ф2, грн | AR4: Сумма итого, грн | AS4: % суммы затрат в общем объеме | AT4: Комментарии | AU4: Сумма по Ф1, грн | AV4: Сумма по Ф2, грн | AW4: Сумма итого, грн | AX4: % суммы затрат в общем объеме | AY4: Комментарии
B5: Операционный доход | C5: =C6 -> 4590956 | D5: =D6 -> 0 | E5: =E6 -> 4590956 | G5: =G6 -> 0 | H5: =H6 -> 0 | I5: =I6 -> 0 | L5: =L6 -> 0 | M5: =M6 -> 0 | N5: =N6 -> 0 | Q5: =Q6 -> 0 | R5: =R6 -> 0 | S5: =S6 -> 0 | V5: =V6 -> 3025190.4 | W5: =W6 -> 0 | X5: =X6 -> 3025190.4 | AA5: =AA6 -> 1468296.4 | AB5: =AB6 -> 0 | AC5: =AC6 -> 1468296.4 | AF5: =AF6 -> 506097.41 | AG5: =AG6 -> 0 | AH5: =AH6 -> 506097.41 | AK5: =AK6 -> 0 | AL5: =AL6 -> 0 | AM5: =AM6 -> 0 | AP5: =AP6 -> 4999584.2 | AQ5: =AQ6 -> 0 | AR5: =AR6 -> 4999584.2 | AU5: =AU6 -> -408628.15 | AV5: =AV6 -> 0 | AW5: =AW6 -> -408628.15
A6: ='PL_Сватово очередь 2'!I6 -> 0 | B6: Выручка от продаж (товаров, работ, услуг) | C6: 4590956 | E6: =C6+D6 -> 4590956 | I6: =G6+H6 -> 0 | N6: =L6+M6 -> 0 | S6: =Q6+R6 -> 0 | V6: =524483.22+2500707.14 -> 3025190.4 | X6: =V6+W6 -> 3025190.4 | Z6: 2 Акта ( проведены бух учет в октябре) | AA6: =721198.33+254990+211690.21+280417.84 -> 1468296.4 | AC6: =AA6+AB6 -> 1468296.4 | AF6: =419194.7+86902.71 -> 506097.41 | AH6: =AF6+AG6 -> 506097.41 | AM6: =AK6+AL6 -> 0 | AP6: =G6+L6+Q6+V6+AA6+AF6+AK6 -> 4999584.2 | AQ6: =H6+M6+R6+W6+AB6+AG6+AL6 -> 0 | AR6: =AP6+AQ6 -> 4999584.2 | AU6: =C6-AP6 -> -408628.15 | AV6: =D6-AQ6 -> 0 | AW6: =AU6+AV6 -> -408628.15
B7: Доход от прочей операционной деятельности | E7: =C7+D7 -> 0 | I7: =G7+H7 -> 0 | N7: =L7+M7 -> 0 | S7: =Q7+R7 -> 0 | X7: =V7+W7 -> 0 | AC7: =AA7+AB7 -> 0 | AH7: =AF7+AG7 -> 0 | AM7: =AK7+AL7 -> 0 | AP7: =G7+L7+Q7+V7+AA7+AF7+AK7 -> 0 | AQ7: =H7+M7+R7+W7+AB7+AG7+AL7 -> 0 | AR7: =AP7+AQ7 -> 0 | AU7: =C7-AP7 -> 0 | AV7: =D7-AQ7 -> 0 | AW7: =AU7+AV7 -> 0
B8: Себестоимость проданой продукции (переменные производственные затраты) | C8: =SUM(C9:C31) -> 2057027 | D8: =SUM(D9:D31) -> 856715 | E8: =SUM(E9:E31) -> 2913742 | F8: =E8/$E$87 -> 0.91196428 | G8: =SUM(G9:G31) -> 44655 | H8: =SUM(H9:H31) -> 30403 | I8: =SUM(I9:I31) -> 75058 | J8: =I8/$I$87 -> 0.9450119 | L8: =SUM(L9:L31) -> 956216.47 | M8: =SUM(M9:M31) -> 43331.796 | N8: =SUM(N9:N31) -> 999548.27 | O8: =N8/$N$87 -> 0.98991612 | Q8: =SUM(Q9:Q31) -> 218190.11 | R8: =SUM(R9:R31) -> 30888 | S8: =SUM(S9:S31) -> 249078.11 | T8: =S8/$S$87 -> 0.9499065 | V8: =SUM(V9:V31) -> 1081138 | W8: =SUM(W9:W31) -> 458642 | X8: =SUM(X9:X31) -> 1539780 | Y8: =X8/$X$87 -> 0.95830793 | AA8: =SUM(AA9:AA31) -> 381045.94 | AB8: =SUM(AB9:AB31) -> 260754.52 | AC8: =SUM(AC9:AC31) -> 641800.46 | AD8: =AC8/$AC$87 -> 0.94336814 | AF8: =SUM(AF9:AF31) -> 38804.423 | AG8: =SUM(AG9:AG31) -> 180831.36 | AH8: =SUM(AH9:AH31) -> 219635.78 | AI8: =AH8/$AH$87 -> 0.8969512 | AK8: =SUM(AK9:AK31) -> 2054.406 | AL8: =SUM(AL9:AL31) -> 80000 | AM8: =SUM(AM9:AM31) -> 82054.406 | AN8: =AM8/$AM$87 -> 0.86833214 | AP8: =SUM(AP9:AP31) -> 2722104.4 | AQ8: =SUM(AQ9:AQ31) -> 1084850.7 | AR8: =SUM(AR9:AR31) -> 3806955.1 | AS8: =AR8/$AR$87 -> 0.95733641 | AU8: =SUM(AU9:AU31) -> -665077.39 | AV8: =SUM(AV9:AV31) -> -228135.68 | AW8: =SUM(AW9:AW31) -> -893213.06 | AX8: =AW8/$AW$87 -> 1.1257942
B9: ЗП производственного персонала | C9: 109480 | E9: =C9+D9 -> 109480 | F9: =E9/$E$87 -> 0.034265851 | G9: =4*3421.25 -> 13685 | I9: =G9+H9*1 -> 13685 | K9: 0,5 мес Сватовские | L9: 30791.25 | N9: =L9+M9*1 -> 30791.25 | O9: =N9/$N$87 -> 0.03049453 | Q9: =4*6842.5 -> 27370 | S9: =Q9+R9*1 -> 27370 | T9: =S9/$S$87 -> 0.10438067 | U9: бр Сватовские | V9: 27370 | X9: =V9+W9*1 -> 27370 | Y9: =X9/$X$87 -> 0.017034179 | Z9: 4 чел бр.Сватовские | AA9: =6842.5*4 -> 27370 | AC9: =AA9+AB9*1 -> 27370 | AD9: =AC9/$AC$87 -> 0.040230551 | AE9: бр.Сватовские | AF9: 6516.68 | AH9: =AF9+AG9*1 -> 6516.68 | AI9: =AH9/$AH$87 -> 0.026612895 | AM9: =AK9+AL9*1 -> 0 | AN9: =AM9/$AM$87 -> 0 | AP9: =G9+L9+Q9+V9+AA9+AF9+AK9 -> 133102.93 | AQ9: =H9+M9+R9+W9+AB9+AG9+AL9 -> 0 | AR9: =AP9+AQ9*1 -> 133102.93 | AS9: =AR9/$AR$87 -> 0.033471443 | AU9: =C9-AP9 -> -23622.93 | AV9: =D9-AQ9 -> 0 | AW9: =AU9+AV9*1 -> -23622.93 | AX9: =AW9/$AW$87 -> 0.029774035
B10: Удержание с зарплаты производственного персонала | C10: 26520 | E10: =C10+D10 -> 26520 | F10: =E10/$E$87 -> 0.0083004236 | G10: =4*8500*19.5% -> 6630 | I10: =G10+H10*1 -> 6630 | L10: 7458.75 | N10: =L10+M10*1 -> 7458.75 | O10: =N10/$N$87 -> 0.0073868737 | Q10: =8050*19.5%*4 -> 6279 | S10: =Q10+R10*1 -> 6279 | T10: =S10/$S$87 -> 0.023946155 | V10: 6630 | X10: =V10+W10*1 -> 6630 | Y10: =X10/$X$87 -> 0.0041262917 | AA10: =1658*4 -> 6632 | AC10: =AA10+AB10*1 -> 6632 | AD10: =AC10/$AC$87 -> 0.0097482285 | AF10: =AF9/0.805*0.195 -> 1578.5747 | AH10: =AF10+AG10*1 -> 1578.5747 | AI10: =AH10/$AH$87 -> 0.0064466018 | AM10: =AK10+AL10*1 -> 0 | AN10: =AM10/$AM$87 -> 0 | AP10: =G10+L10+Q10+V10+AA10+AF10+AK10 -> 35208.325 | AQ10: =H10+M10+R10+W10+AB10+AG10+AL10 -> 0 | AR10: =AP10+AQ10*1 -> 35208.325 | AS10: =AR10/$AR$87 -> 0.0088538505 | AU10: =C10-AP10 -> -8688.3247 | AV10: =D10-AQ10 -> 0 | AW10: =AU10+AV10*1 -> -8688.3247 | AX10: =AW10/$AW$87 -> 0.010950652
B11: Начисления на зарплату производственного персонала | C11: 29920 | E11: =C11+D11 -> 29920 | F11: =E11/$E$87 -> 0.0093645804 | G11: =4*8500*22% -> 7480 | I11: =G11+H11*1 -> 7480 | L11: 8415 | N11: =L11+M11*1 -> 8415 | O11: =N11/$N$87 -> 0.0083339088 | Q11: =8050*22%*4 -> 7084 | S11: =Q11+R11*1 -> 7084 | T11: =S11/$S$87 -> 0.027016174 | V11: 7480 | X11: =V11+W11*1 -> 7480 | Y11: =X11/$X$87 -> 0.0046553035 | AA11: =1870*2 -> 3740 | AC11: =AA11+AB11*1 -> 3740 | AD11: =AC11/$AC$87 -> 0.0054973424 | AF11: =AF9/0.805*0.22 -> 1780.956 | AH11: =AF11+AG11*1 -> 1780.956 | AI11: =AH11/$AH$87 -> 0.0072730893 | AJ11: бр.Сватовские, 1 половина ноября | AM11: =AK11+AL11*1 -> 0 | AN11: =AM11/$AM$87 -> 0 | AP11: =G11+L11+Q11+V11+AA11+AF11+AK11 -> 35979.956 | AQ11: =H11+M11+R11+W11+AB11+AG11+AL11 -> 0 | AR11: =AP11+AQ11*1 -> 35979.956 | AS11: =AR11/$AR$87 -> 0.0090478929 | AU11: =C11-AP11 -> -6059.956 | AV11: =D11-AQ11 -> 0 | AW11: =AU11+AV11*1 -> -6059.956 | AX11: =AW11/$AW$87 -> 0.0076378902
B12: Зарплата ИТР | C12: 28980 | D12: 91020 | E12: =C12+D12 -> 120000 | F12: =E12/$E$87 -> 0.037558478 | G12: 9660 | H12: 20340 | I12: =G12+H12*1 -> 30000 | J12: =I12/$I$87 -> 0.37771266 | K12: Терещенко | L12: 9660 | M12: 20340 | N12: =L12+M12*1 -> 30000 | O12: =N12/$N$87 -> 0.029710905 | P12: Терещенко А июль | Q12: 9660 | R12: 17340 | S12: =Q12+R12*1 -> 27000 | T12: =S12/$S$87 -> 0.10296961 | U12: Терещенко А за минусом штрафа 3 000 грн | V12: 9660 | W12: 19340 | X12: =V12+W12*1 -> 29000 | Y12: =X12/$X$87 -> 0.018048636 | Z12: Терещенко сентябрь за минусом штрафа 1 000 грн | AA12: 4830 | AB12: =20340/2 -> 10170 | AC12: =AA12+AB12*1 -> 15000 | AD12: =AC12/$AC$87 -> 0.022048165 | AE12: Терещенко | AH12: =AF12+AG12*1 -> 0 | AI12: =AH12/$AH$87 -> 0 | AM12: =AK12+AL12*1 -> 0 | AN12: =AM12/$AM$87 -> 0 | AP12: =G12+L12+Q12+V12+AA12+AF12+AK12 -> 43470 | AQ12: =H12+M12+R12+W12+AB12+AG12+AL12 -> 87530 | AR12: =AP12+AQ12*1 -> 131000 | AS12: =AR12/$AR$87 -> 0.032942619 | AU12: =C12-AP12 -> -14490 | AV12: =D12-AQ12 -> 3490 | AW12: =AU12+AV12*1 -> -11000 | AX12: =AW12/$AW$87 -> 0.013864258
B13: Удержание с зарплаты ИТР | C13: 9360 | E13: =C13+D13 -> 9360 | F13: =E13/$E$87 -> 0.0029295613 | G13: =12000*19.5% -> 2340 | I13: =G13+H13*1 -> 2340 | J13: =I13/$I$87 -> 0.029461588 | L13: 2340 | N13: =L13+M13*1 -> 2340 | O13: =N13/$N$87 -> 0.0023174506 | Q13: 2340 | S13: =Q13+R13*1 -> 2340 | T13: =S13/$S$87 -> 0.0089240327 | V13: 2340 | X13: =V13+W13*1 -> 2340 | Y13: =X13/$X$87 -> 0.0014563382 | AA13: 1170 | AC13: =AA13+AB13*1 -> 1170 | AD13: =AC13/$AC$87 -> 0.0017197568 | AH13: =AF13+AG13*1 -> 0 | AI13: =AH13/$AH$87 -> 0 | AM13: =AK13+AL13*1 -> 0 | AN13: =AM13/$AM$87 -> 0 | AP13: =G13+L13+Q13+V13+AA13+AF13+AK13 -> 10530 | AQ13: =H13+M13+R13+W13+AB13+AG13+AL13 -> 0 | AR13: =AP13+AQ13*1 -> 10530 | AS13: =AR13/$AR$87 -> 0.002647983 | AU13: =C13-AP13 -> -1170 | AV13: =D13-AQ13 -> 0 | AW13: =AU13+AV13*1 -> -1170 | AX13: =AW13/$AW$87 -> 0.0014746529
B14: Начисления на зарплату ИТР | C14: 10560 | E14: =C14+D14 -> 10560 | F14: =E14/$E$87 -> 0.003305146 | G14: =12000*22% -> 2640 | I14: =G14+H14*1 -> 2640 | J14: =I14/$I$87 -> 0.033238714 | L14: 2640 | N14: =L14+M14*1 -> 2640 | O14: =N14/$N$87 -> 0.0026145596 | Q14: 2640 | S14: =Q14+R14*1 -> 2640 | T14: =S14/$S$87 -> 0.010068139 | V14: 2640 | X14: =V14+W14*1 -> 2640 | Y14: =X14/$X$87 -> 0.0016430483 | AA14: 1320 | AC14: =AA14+AB14*1 -> 1320 | AD14: =AC14/$AC$87 -> 0.0019402385 | AH14: =AF14+AG14*1 -> 0 | AI14: =AH14/$AH$87 -> 0 | AM14: =AK14+AL14*1 -> 0 | AN14: =AM14/$AM$87 -> 0 | AP14: =G14+L14+Q14+V14+AA14+AF14+AK14 -> 11880 | AQ14: =H14+M14+R14+W14+AB14+AG14+AL14 -> 0 | AR14: =AP14+AQ14*1 -> 11880 | AS14: =AR14/$AR$87 -> 0.002987468 | AU14: =C14-AP14 -> -1320 | AV14: =D14-AQ14 -> 0 | AW14: =AU14+AV14*1 -> -1320 | AX14: =AW14/$AW$87 -> 0.0016637109
B15: ЗП подсобников | E15: =C15+D15 -> 0 | F15: =E15/$E$87 -> 0 | I15: =G15+H15*1 -> 0 | N15: =L15+M15*1 -> 0 | O15: =N15/$N$87 -> 0 | S15: =Q15+R15*1 -> 0 | T15: =S15/$S$87 -> 0 | X15: =V15+W15*1 -> 0 | Y15: =X15/$X$87 -> 0 | AC15: =AA15+AB15*1 -> 0 | AD15: =AC15/$AC$87 -> 0 | AG15: 1500 | AH15: =AF15+AG15*1 -> 1500 | AI15: =AH15/$AH$87 -> 0.0061257177 | AJ15: ЗП подсобников | AM15: =AK15+AL15*1 -> 0 | AN15: =AM15/$AM$87 -> 0 | AP15: =G15+L15+Q15+V15+AA15+AF15+AK15 -> 0 | AQ15: =H15+M15+R15+W15+AB15+AG15+AL15 -> 1500 | AR15: =AP15+AQ15*1 -> 1500 | AS15: =AR15/$AR$87 -> 0.00037720556 | AU15: =C15-AP15 -> 0 | AV15: =D15-AQ15 -> -1500 | AW15: =AU15+AV15*1 -> -1500 | AX15: =AW15/$AW$87 -> 0.0018905806
B16: Оплата за выполненные работы | D16: 623695 | E16: =C16+D16 -> 623695 | F16: =E16/$E$87 -> 0.19520862 | I16: =G16+H16*1 -> 0 | N16: =L16+M16*1 -> 0 | O16: =N16/$N$87 -> 0 | S16: =Q16+R16*1 -> 0 | T16: =S16/$S$87 -> 0 | W16: =9340+56250+36695+178352 -> 280637 | X16: =V16+W16*1 -> 280637 | Y16: =X16/$X$87 -> 0.17465914 | Z16: Сборная - 56 250 грн Харьковские - 9 340 грн Жук - 36 695 грн Сватовские - 178 352 грн | AB16: =47520+34695+28253.64+86385.5+15945+33625 -> 246424.14 | AC16: =AA16+AB16*1 -> 246424.14 | AD16: =AC16/$AC$87 -> 0.36221333 | AE16: 47520 - Чешко 34695 - Жук 164209,14 - Сватовские | AG16: =2992+15600+13739.36 -> 32331.36 | AH16: =AF16+AG16*1 -> 32331.36 | AI16: =AH16/$AH$87 -> 0.13203519 | AJ16: 2992 - Сватовские 15600 - Хрьковские 13739,36 - бр.Михальского | AM16: =AK16+AL16*1 -> 0 | AN16: =AM16/$AM$87 -> 0 | AP16: =G16+L16+Q16+V16+AA16+AF16+AK16 -> 0 | AQ16: =H16+M16+R16+W16+AB16+AG16+AL16 -> 559392.5 | AR16: =AP16+AQ16*1 -> 559392.5 | AS16: =AR16/$AR$87 -> 0.14067064 | AU16: =C16-AP16 -> 0 | AV16: =D16-AQ16 -> 64302.5 | AW16: =AU16+AV16*1 -> 64302.5 | AX16: =AW16/$AW$87 -> -0.081046039
B17: Премия производственного персонала | D17: 30000 | E17: =C17+D17 -> 30000 | F17: =E17/$E$87 -> 0.0093896194 | I17: =G17+H17*1 -> 0 | M17: 300 | N17: =L17+M17*1 -> 300 | O17: =N17/$N$87 -> 0.00029710905 | P17: Первый бетон бр.Жука 4 чел *75грн | S17: =Q17+R17*1 -> 0 | T17: =S17/$S$87 -> 0 | X17: =V17+W17*1 -> 0 | Y17: =X17/$X$87 -> 0 | AC17: =AA17+AB17*1 -> 0 | AD17: =AC17/$AC$87 -> 0 | AH17: =AF17+AG17*1 -> 0 | AI17: =AH17/$AH$87 -> 0 | AL17: =30000+50000 -> 80000 | AM17: =AK17+AL17*1 -> 80000 | AN17: =AM17/$AM$87 -> 0.8465916 | AP17: =G17+L17+Q17+V17+AA17+AF17+AK17 -> 0 | AQ17: =H17+M17+R17+W17+AB17+AG17+AL17 -> 80300 | AR17: =AP17+AQ17*1 -> 80300 | AS17: =AR17/$AR$87 -> 0.020193071 | AU17: =C17-AP17 -> 0 | AV17: =D17-AQ17 -> -50300 | AW17: =AU17+AV17*1 -> -50300 | AX17: =AW17/$AW$87 -> 0.063397469
B18: Услуги сторонних организаций | C18: 741860 | E18: =C18+D18 -> 741860 | F18: =E18/$E$87 -> 0.23219277 | I18: =G18+H18*1 -> 0 | L18: =48.79*14000 -> 683060 | M18: 3880 | N18: =L18+M18*1 -> 686940 | O18: =N18/$N$87 -> 0.6803203 | P18: Изготовление добора "цинк" для бункеров приема и кровли цеха грануляции - 3 400 грн+ изготовление доп стропов, услуги электрика Цех металлоконструкций - Цех грануляции лузги - 48,79*14000= 683 060грн | R18: 200 | S18: =Q18+R18*1 -> 200 | T18: =S18/$S$87 -> 0.00076273784 | U18: работа токаря -200,00 | W18: 150000 | X18: =V18+W18*1 -> 150000 | Y18: =X18/$X$87 -> 0.093355016 | Z18: выдал Воронцов А.В - аванс Вектор -150 000,00 | AC18: =AA18+AB18*1 -> 0 | AD18: =AC18/$AC$87 -> 0 | AG18: 147000 | AH18: =AF18+AG18*1 -> 147000 | AI18: =AH18/$AH$87 -> 0.60032034 | AJ18: ТОВ Вектор перевод Европочтой -147 000,00 | AM18: =AK18+AL18*1 -> 0 | AN18: =AM18/$AM$87 -> 0 | AP18: =G18+L18+Q18+V18+AA18+AF18+AK18 -> 683060 | AQ18: =H18+M18+R18+W18+AB18+AG18+AL18 -> 301080 | AR18: =AP18+AQ18*1 -> 984140 | AS18: =AR18/$AR$87 -> 0.24748205 | AU18: =C18-AP18 -> 58800 | AV18: =D18-AQ18 -> -301080 | AW18: =AU18+AV18*1 -> -242280 | AX18: =AW18/$AW$87 -> 0.30536658
B19: Аренда строительного оборудования | E19: =C19+D19 -> 0 | F19: =E19/$E$87 -> 0 | I19: =G19+H19*1 -> 0 | M19: 600 | N19: =L19+M19*1 -> 600 | O19: =N19/$N$87 -> 0.0005942181 | P19: аренда трамбовки | S19: =Q19+R19*1 -> 0 | T19: =S19/$S$87 -> 0 | X19: =V19+W19*1 -> 0 | Y19: =X19/$X$87 -> 0 | AC19: =AA19+AB19*1 -> 0 | AD19: =AC19/$AC$87 -> 0 | AH19: =AF19+AG19*1 -> 0 | AI19: =AH19/$AH$87 -> 0 | AM19: =AK19+AL19*1 -> 0 | AN19: =AM19/$AM$87 -> 0 | AP19: =G19+L19+Q19+V19+AA19+AF19+AK19 -> 0 | AQ19: =H19+M19+R19+W19+AB19+AG19+AL19 -> 600 | AR19: =AP19+AQ19*1 -> 600 | AS19: =AR19/$AR$87 -> 0.00015088222 | AU19: =C19-AP19 -> 0 | AV19: =D19-AQ19 -> -600 | AW19: =AU19+AV19*1 -> -600 | AX19: =AW19/$AW$87 -> 0.00075623224
B20: Аренда опалубки | E20: =C20+D20 -> 0 | F20: =E20/$E$87 -> 0 | I20: =G20+H20*1 -> 0 | N20: =L20+M20*1 -> 0 | O20: =N20/$N$87 -> 0 | S20: =Q20+R20*1 -> 0 | T20: =S20/$S$87 -> 0 | X20: =V20+W20*1 -> 0 | Y20: =X20/$X$87 -> 0 | AC20: =AA20+AB20*1 -> 0 | AD20: =AC20/$AC$87 -> 0 | AH20: =AF20+AG20*1 -> 0 | AI20: =AH20/$AH$87 -> 0 | AM20: =AK20+AL20*1 -> 0 | AN20: =AM20/$AM$87 -> 0 | AP20: =G20+L20+Q20+V20+AA20+AF20+AK20 -> 0 | AQ20: =H20+M20+R20+W20+AB20+AG20+AL20 -> 0 | AR20: =AP20+AQ20*1 -> 0 | AS20: =AR20/$AR$87 -> 0 | AU20: =C20-AP20 -> 0 | AV20: =D20-AQ20 -> 0 | AW20: =AU20+AV20*1 -> 0 | AX20: =AW20/$AW$87 -> 0
B21: Арена техники | C21: 269500 | E21: =C21+D21 -> 269500 | F21: =E21/$E$87 -> 0.084350081 | I21: =G21+H21*1 -> 0 | L21: =(285*459.49)+(4181.06*1.2)+(818*27.42) -> 158401.48 | M21: 1500 | N21: =L21+M21*1 -> 159901.48 | O21: =N21/$N$87 -> 0.15836059 | P21: Автокран ХСМG - (285*459,49)= 130 954,65 Автокран закрыто актами - 5 017,27 грн Перебазировка Автокран ХСМG = 818км*27,42 грн = 22 429,56 грн | Q21: =(339*459.49) -> 155767.11 | S21: =Q21+R21*1 -> 155767.11 | T21: =S21/$S$87 -> 0.59404735 | U21: Автокран XCMG - 155 767 ,11 | X21: =V21+W21*1 -> 0 | Y21: =X21/$X$87 -> 0 | AC21: =AA21+AB21*1 -> 0 | AD21: =AC21/$AC$87 -> 0 | AH21: =AF21+AG21*1 -> 0 | AI21: =AH21/$AH$87 -> 0 | AM21: =AK21+AL21*1 -> 0 | AN21: =AM21/$AM$87 -> 0 | AP21: =G21+L21+Q21+V21+AA21+AF21+AK21 -> 314168.59 | AQ21: =H21+M21+R21+W21+AB21+AG21+AL21 -> 1500 | AR21: =AP21+AQ21*1 -> 315668.59 | AS21: =AR21/$AR$87 -> 0.079381298 | AU21: =C21-AP21 -> -44668.592 | AV21: =D21-AQ21 -> -1500 | AW21: =AU21+AV21*1 -> -46168.592 | AX21: =AW21/$AW$87 -> 0.058190296
B22: Логистические затраты | C22: 58900 | E22: =C22+D22 -> 58900 | F22: =E22/$E$87 -> 0.018434953 | I22: =G22+H22*1 -> 0 | L22: =36166.66*1.2 -> 43399.992 | M22: 100 | N22: =L22+M22*1 -> 43499.992 | O22: =N22/$N$87 -> 0.043080804 | P22: ДХ Транс Украина - 43 399,99 грн | R22: 200 | S22: =Q22+R22*1 -> 200 | T22: =S22/$S$87 -> 0.00076273784 | U22: доставка мшп | X22: =V22+W22*1 -> 0 | Y22: =X22/$X$87 -> 0 | AA22: 14800 | AC22: =AA22+AB22*1 -> 14800 | AD22: =AC22/$AC$87 -> 0.021754189 | AE22: 14 800,00 - БЕЛЕС ТРАНС"ПП | AF22: =11500 -> 11500 | AH22: =AF22+AG22*1 -> 11500 | AI22: =AH22/$AH$87 -> 0.046963836 | AJ22: 11 500,00 - БЕЛЕС ТРАНС"ПП | AM22: =AK22+AL22*1 -> 0 | AN22: =AM22/$AM$87 -> 0 | AP22: =G22+L22+Q22+V22+AA22+AF22+AK22 -> 69699.992 | AQ22: =H22+M22+R22+W22+AB22+AG22+AL22 -> 300 | AR22: =AP22+AQ22*1 -> 69999.992 | AS22: =AR22/$AR$87 -> 0.017602924 | AU22: =C22-AP22 -> -10799.992 | AV22: =D22-AQ22 -> -300 | AW22: =AU22+AV22*1 -> -11099.992 | AX22: =AW22/$AW$87 -> 0.013990286
B23: МШП | C23: 57900 | E23: =C23+D23 -> 57900 | F23: =E23/$E$87 -> 0.018121965 | H23: 1524 | I23: =G23+H23*1 -> 1524 | M23: 3966 | N23: =L23+M23*1 -> 3966 | O23: =N23/$N$87 -> 0.0039277816 | R23: 1520 | S23: =Q23+R23*1 -> 1520 | T23: =S23/$S$87 -> 0.0057968076 | V23: =14274.39*1.2 -> 17129.268 | W23: 960 | X23: =V23+W23*1 -> 18089.268 | Y23: =X23/$X$87 -> 0.011258159 | Z23: согласно списания | AA23: =3959.69*1.2 -> 4751.628 | AB23: 1040 | AC23: =AA23+AB23*1 -> 5791.628 | AD23: =AC23/$AC$87 -> 0.0085129845 | AE23: ф2 - мшп + доставка Терещенко | AH23: =AF23+AG23*1 -> 0 | AI23: =AH23/$AH$87 -> 0 | AK23: =1198.98*1.2+615.63 -> 2054.406 | AM23: =AK23+AL23*1 -> 2054.406 | AN23: =AM23/$AM$87 -> 0.021740536 | AP23: =G23+L23+Q23+V23+AA23+AF23+AK23 -> 23935.302 | AQ23: =H23+M23+R23+W23+AB23+AG23+AL23 -> 9010 | AR23: =AP23+AQ23*1 -> 32945.302 | AS23: =AR23/$AR$87 -> 0.0082847673 | AU23: =C23-AP23 -> 33964.698 | AV23: =D23-AQ23 -> -9010 | AW23: =AU23+AV23*1 -> 24954.698 | AX23: =AW23/$AW$87 -> -0.031452578
B24: Строительные материалы | C24: 609407 | D24: 32000 | E24: =C24+D24 -> 641407 | F24: =E24/$E$87 -> 0.20075225 | H24: 400 | I24: =G24+H24*1 -> 400 | N24: =L24+M24*1 -> 0 | O24: =N24/$N$87 -> 0 | S24: =Q24+R24*1 -> 0 | T24: =S24/$S$87 -> 0 | V24: =(684058.3+243453.41-99070.06)*1.2 -> 994129.98 | X24: =V24+W24*1 -> 994129.98 | Y24: =X24/$X$87 -> 0.61871347 | Z24: в т ч металл для изготовления м/к цеха = 411 865,41 грн с НДС за минусом склада обмена 118 884,07 грн | AA24: =(90507.85+165264.62+5412.79)*1.2 -> 313422.31 | AC24: =AA24+AB24*1 -> 313422.31 | AD24: =AC24/$AC$87 -> 0.46069245 | AF24: =14523.51*1.2 -> 17428.212 | AH24: =AF24+AG24*1 -> 17428.212 | AI24: =AH24/$AH$87 -> 0.071173538 | AM24: =AK24+AL24*1 -> 0 | AN24: =AM24/$AM$87 -> 0 | AP24: =G24+L24+Q24+V24+AA24+AF24+AK24 -> 1324980.5 | AQ24: =H24+M24+R24+W24+AB24+AG24+AL24 -> 400 | AR24: =AP24+AQ24*1 -> 1325380.5 | AS24: =AR24/$AR$87 -> 0.33329393 | AU24: =C24-AP24 -> -715573.5 | AV24: =D24-AQ24 -> 31600 | AW24: =AU24+AV24*1 -> -683973.5 | AX24: =AW24/$AW$87 -> 0.86207135
B25: Ремонты | C25: 8000 | E25: =C25+D25 -> 8000 | F25: =E25/$E$87 -> 0.0025038985 | I25: =G25+H25*1 -> 0 | N25: =L25+M25*1 -> 0 | O25: =N25/$N$87 -> 0 | R25: 650 | S25: =Q25+R25*1 -> 650 | T25: =S25/$S$87 -> 0.002478898 | U25: ремонт лебедки -650,00 | V25: =4359.16*1.2 -> 5230.992 | W25: 400 | X25: =V25+W25*1 -> 5630.992 | Y25: =X25/$X$87 -> 0.0035045423 | Z25: Виктория Макс - ремонт инструмента ф2 -Ремонт отбойника -400,00 | AC25: =AA25+AB25*1 -> 0 | AD25: =AC25/$AC$87 -> 0 | AH25: =AF25+AG25*1 -> 0 | AI25: =AH25/$AH$87 -> 0 | AM25: =AK25+AL25*1 -> 0 | AN25: =AM25/$AM$87 -> 0 | AP25: =G25+L25+Q25+V25+AA25+AF25+AK25 -> 5230.992 | AQ25: =H25+M25+R25+W25+AB25+AG25+AL25 -> 1050 | AR25: =AP25+AQ25*1 -> 6280.992 | AS25: =AR25/$AR$87 -> 0.0015794834 | AU25: =C25-AP25 -> 2769.008 | AV25: =D25-AQ25 -> -1050 | AW25: =AU25+AV25*1 -> 1719.008 | AX25: =AW25/$AW$87 -> -0.0021666154
B26: Прочие производственные затраты | C26: 45040 | E26: =C26+D26 -> 45040 | F26: =E26/$E$87 -> 0.014096949 | I26: =G26+H26*1 -> 0 | M26: =950+(4.83*1.2) -> 955.796 | N26: =L26+M26*1 -> 955.796 | O26: =N26/$N$87 -> 0.00094658547 | P26: резиновые сапоги 4 пары=950 грн | R26: 120 | S26: =Q26+R26*1 -> 120 | T26: =S26/$S$87 -> 0.0004576427 | U26: лекарства для рабочего -120,00 | V26: =64.83*1.2 -> 77.796 | W26: 305 | X26: =V26+W26*1 -> 382.796 | Y26: =X26/$X$87 -> 0.00023823951 | Z26: карандаш строительный, прочие Бытовые покупки ( одеяло для Терещенко А) -305,00 | AB26: 500 | AC26: =AA26+AB26*1 -> 500 | AD26: =AC26/$AC$87 -> 0.00073493882 | AE26: заправка баллона газом | AH26: =AF26+AG26*1 -> 0 | AI26: =AH26/$AH$87 -> 0 | AM26: =AK26+AL26*1 -> 0 | AN26: =AM26/$AM$87 -> 0 | AP26: =G26+L26+Q26+V26+AA26+AF26+AK26 -> 77.796 | AQ26: =H26+M26+R26+W26+AB26+AG26+AL26 -> 1880.796 | AR26: =AP26+AQ26*1 -> 1958.592 | AS26: =AR26/$AR$87 -> 0.00049252786 | AU26: =C26-AP26 -> 44962.204 | AV26: =D26-AQ26 -> -1880.796 | AW26: =AU26+AV26*1 -> 43081.408 | AX26: =AW26/$AW$87 -> -0.054299249
B27: Командировочные производственного персонала | C27: 51600 | E27: =C27+D27 -> 51600 | F27: =E27/$E$87 -> 0.016150145 | G27: 2220 | I27: =G27+H27*1 -> 2220 | J27: =I27/$I$87 -> 0.027950737 | K27: 1820- Терещенко 400 -Гончаренко | L27: 10050 | M27: 2800 | N27: =L27+M27*1 -> 12850 | O27: =N27/$N$87 -> 0.012726171 | P27: бр Жуки, Сватовские, Терещенко | Q27: 7050 | R27: 200 | S27: =Q27+R27*1 -> 7250 | T27: =S27/$S$87 -> 0.027649247 | U27: Терещенко - 3 250 грн Бр Жук, Гончаренко | V27: =8710-260 -> 8450 | W27: 3000 | X27: =V27+W27*1 -> 11450 | Y27: =X27/$X$87 -> 0.0071260996 | Z27: ф1 - ИТР - 4 550 Гончаренко - 3 500 + 400грн Голубев ф2 - бр.Чешко 2 чел = 3000 | AA27: 3010 | AC27: =AA27+AB27*1 -> 3010 | AD27: =AC27/$AC$87 -> 0.0044243317 | AE27: Терещенко - 910грн Гончаренко - 2 100 | AH27: =AF27+AG27*1 -> 0 | AI27: =AH27/$AH$87 -> 0 | AM27: =AK27+AL27*1 -> 0 | AN27: =AM27/$AM$87 -> 0 | AP27: =G27+L27+Q27+V27+AA27+AF27+AK27 -> 30780 | AQ27: =H27+M27+R27+W27+AB27+AG27+AL27 -> 6000 | AR27: =AP27+AQ27*1 -> 36780 | AS27: =AR27/$AR$87 -> 0.0092490803 | AU27: =C27-AP27 -> 20820 | AV27: =D27-AQ27 -> -6000 | AW27: =AU27+AV27*1 -> 14820 | AX27: =AW27/$AW$87 -> -0.018678936
B28: Аренда квартиры с коммунальными платежами | D28: 16000 | E28: =C28+D28 -> 16000 | F28: =E28/$E$87 -> 0.005007797 | H28: =3500+ 1000 -> 4500 | I28: =G28+H28*1 -> 4500 | K28: Аренда квартиры | M28: =3500+500 -> 4000 | N28: =L28+M28*1 -> 4000 | O28: =N28/$N$87 -> 0.003961454 | P28: Терещенко | R28: =3500+800 -> 4300 | S28: =Q28+R28*1 -> 4300 | T28: =S28/$S$87 -> 0.016398864 | U28: аренда квартиры 3500 Терещенко + к/у 800 грн за август | W28: 3500 | X28: =V28+W28*1 -> 3500 | Y28: =X28/$X$87 -> 0.0021782837 | Z28: без к/у, квартира в счет посл месяца | AB28: 550 | AC28: =AA28+AB28*1 -> 550 | AD28: =AC28/$AC$87 -> 0.0008084327 | AE28: К/у Терещенко за октябрь -550,00 | AH28: =AF28+AG28*1 -> 0 | AI28: =AH28/$AH$87 -> 0 | AM28: =AK28+AL28*1 -> 0 | AN28: =AM28/$AM$87 -> 0 | AP28: =G28+L28+Q28+V28+AA28+AF28+AK28 -> 0 | AQ28: =H28+M28+R28+W28+AB28+AG28+AL28 -> 16850 | AR28: =AP28+AQ28*1 -> 16850 | AS28: =AR28/$AR$87 -> 0.0042372758 | AU28: =C28-AP28 -> 0 | AV28: =D28-AQ28 -> -850 | AW28: =AU28+AV28*1 -> -850 | AX28: =AW28/$AW$87 -> 0.001071329
B29: Транспортные затраты производственного персонала | D29: 14000 | E29: =C29+D29 -> 14000 | F29: =E29/$E$87 -> 0.0043818224 | H29: =969+770 -> 1739 | I29: =G29+H29*1 -> 1739 | J29: =I29/$I$87 -> 0.021894744 | K29: Терещенко на обьект Нежин-Киев-Сватово+ такси | M29: =800+2900 -> 3700 | N29: =L29+M29*1 -> 3700 | O29: =N29/$N$87 -> 0.0036643449 | P29: 2700 - приезд бриг жука 4 чел (563 гр. Поезд киев-сватово+ проезд нежин - киев бла-блакар, доставка людей с инструментом на объект на такси 2*50 5 чел) Такси -800 грн | R29: 6358 | S29: =Q29+R29*1 -> 6358 | T29: =S29/$S$87 -> 0.024247436 | U29: Уезд с обьекта 4чел бр.Жука -1 200,00 Приезд бр.на проф лист 3 чел (топливо) -750,00 приезд монтажников силоса 5 чел -2 100,00 Проезд Голубева И согласно билетам -957,50 Приезд на обьект Воликова -350,00 Приезд на обьект Чешко Сиряченко ( заправка топливо) -1 000,00 | W29: 500 | X29: =V29+W29*1 -> 500 | Y29: =X29/$X$87 -> 0.00031118339 | Z29: Чешко,Сиряченко уезд с обьекта (газ на машину) -500,00 | AB29: 2070.38 | AC29: =AA29+AB29*1 -> 2070.38 | AD29: =AC29/$AC$87 -> 0.0030432053 | AE29: Проезд Голубева по подотчету Киев-Сватово -810,38 Проезд Терещенко по городу ( магазины, рынок) -260,00 Проезд Терещенко Сватово-Киев- Кривой Рог -1 000,00 | AH29: =AF29+AG29*1 -> 0 | AI29: =AH29/$AH$87 -> 0 | AM29: =AK29+AL29*1 -> 0 | AN29: =AM29/$AM$87 -> 0 | AP29: =G29+L29+Q29+V29+AA29+AF29+AK29 -> 0 | AQ29: =H29+M29+R29+W29+AB29+AG29+AL29 -> 14367.38 | AR29: =AP29+AQ29*1 -> 14367.38 | AS29: =AR29/$AR$87 -> 0.0036129704 | AU29: =C29-AP29 -> 0 | AV29: =D29-AQ29 -> -367.38 | AW29: =AU29+AV29*1 -> -367.38 | AX29: =AW29/$AW$87 -> 0.000463041
B30: Разрешительная документация | E30: =C30+D30 -> 0 | F30: =E30/$E$87 -> 0 | I30: =G30+H30*1 -> 0 | N30: =L30+M30*1 -> 0 | O30: =N30/$N$87 -> 0 | S30: =Q30+R30*1 -> 0 | T30: =S30/$S$87 -> 0 | X30: =V30+W30*1 -> 0 | Y30: =X30/$X$87 -> 0 | AC30: =AA30+AB30*1 -> 0 | AD30: =AC30/$AC$87 -> 0 | AH30: =AF30+AG30*1 -> 0 | AI30: =AH30/$AH$87 -> 0 | AM30: =AK30+AL30*1 -> 0 | AN30: =AM30/$AM$87 -> 0 | AP30: =G30+L30+Q30+V30+AA30+AF30+AK30 -> 0 | AQ30: =H30+M30+R30+W30+AB30+AG30+AL30 -> 0 | AR30: =AP30+AQ30*1 -> 0 | AS30: =AR30/$AR$87 -> 0 | AU30: =C30-AP30 -> 0 | AV30: =D30-AQ30 -> 0 | AW30: =AU30+AV30*1 -> 0 | AX30: =AW30/$AW$87 -> 0
B31: Представительские затраты | D31: 50000 | E31: =C31+D31 -> 50000 | F31: =E31/$E$87 -> 0.015649366 | H31: 1900 | I31: =G31+H31*1 -> 1900 | K31: 600грн - налаживание отношений сэкскаваторщиками 600грн. - взятка трактаристу за неделю 700грн. - первый бетон бр.Сватовские (традиция) | M31: 1190 | N31: =L31+M31*1 -> 1190 | O31: =N31/$N$87 -> 0.0011785326 | P31: гостинец сватовским(рабочим) 390грн., налаживание отнош.с руководящими сотрудниками завода. | S31: =Q31+R31*1 -> 0 | T31: =S31/$S$87 -> 0 | X31: =V31+W31*1 -> 0 | Y31: =X31/$X$87 -> 0 | AC31: =AA31+AB31*1 -> 0 | AD31: =AC31/$AC$87 -> 0 | AH31: =AF31+AG31*1 -> 0 | AI31: =AH31/$AH$87 -> 0 | AM31: =AK31+AL31*1 -> 0 | AN31: =AM31/$AM$87 -> 0 | AP31: =G31+L31+Q31+V31+AA31+AF31+AK31 -> 0 | AQ31: =H31+M31+R31+W31+AB31+AG31+AL31 -> 3090 | AR31: =AP31+AQ31*1 -> 3090 | AS31: =AR31/$AR$87 -> 0.00077704345 | AU31: =C31-AP31 -> 0 | AV31: =D31-AQ31 -> 46910 | AW31: =AU31+AV31*1 -> 46910 | AX31: =AW31/$AW$87 -> -0.059124757
O32: =N32/$N$87 -> 0 | T32: =S32/$S$87 -> 0 | Y32: =X32/$X$87 -> 0 | AN32: =AM32/$AM$87 -> 0 | AP32: =G32 -> 0 | AQ32: =H32 -> 0
B33: Дополнительные расходы | C33: =C34 -> 0 | D33: =D34 -> 0 | E33: =E34 -> 0 | F33: =E33/$E$87 -> 0 | G33: =G34 -> 0 | H33: =H34 -> 0 | I33: =I34 -> 0 | L33: =L34 -> 0 | M33: =M34 -> 0 | N33: =N34 -> 0 | O33: =N33/$N$87 -> 0 | Q33: =Q34 -> 0 | R33: =R34 -> 0 | S33: =S34 -> 0 | T33: =S33/$S$87 -> 0 | V33: =V34 -> 0 | W33: =W34 -> 0 | X33: =X34 -> 0 | Y33: =X33/$X$87 -> 0 | AA33: =AA34 -> 0 | AB33: =AB34 -> 0 | AC33: =AC34 -> 0 | AD33: =AC33/$AC$87 -> 0 | AF33: =AF34 -> 0 | AG33: =AG34 -> 0 | AH33: =AH34 -> 0 | AI33: =AH33/$AC$87 -> 0 | AK33: =AK34 -> 0 | AL33: =AL34 -> 0 | AM33: =AM34 -> 0 | AN33: =AM33/$AM$87 -> 0 | AP33: =G33+L33+Q33+V33+AA33+AF33+AK33 -> 0 | AQ33: =H33+M33+R33+W33+AB33+AG33+AL33 -> 0 | AR33: =AR34 -> 0 | AU33: =AU34 -> 0 | AV33: =AV34 -> 0 | AW33: =AW34 -> 0
B34: Расход от ивест. Деятельности (ОС) | E34: =C34+D34 -> 0 | F34: =E34/$E$87 -> 0 | I34: =G34+H34*1 -> 0 | N34: =L34+M34*1 -> 0 | O34: =N34/$N$87 -> 0 | S34: =Q34+R34*1 -> 0 | T34: =S34/$S$87 -> 0 | X34: =V34+W34*1 -> 0 | Y34: =X34/$X$87 -> 0 | AC34: =AA34+AB34*1 -> 0 | AD34: =AC34/$AC$87 -> 0 | AH34: =AF34+AG34*1 -> 0 | AI34: =AH34/$AC$87 -> 0 | AM34: =AK34+AL34*1 -> 0 | AN34: =AM34/$AM$87 -> 0 | AP34: =G34+L34+Q34+V34+AA34+AF34+AK34 -> 0 | AQ34: =H34+M34+R34+W34+AB34+AG34+AL34 -> 0 | AR34: =AP34+AQ34*1 -> 0 | AS34: =AR34/$AR$87 -> 0 | AU34: =C34-AP34 -> 0 | AV34: =D34-AQ34 -> 0 | AW34: =AU34+AV34*1 -> 0 | AX34: =AW34/$E$87 -> 0
O35: =N35/$N$87 -> 0 | T35: =S35/$N$87 -> 0 | Y35: =X35/$N$87 -> 0 | AD35: =AC35/$N$87 -> 0 | AI35: =AH35/$N$87 -> 0 | AN35: =AM35/$AM$87 -> 0 | AP35: =G35 -> 0 | AQ35: =H35 -> 0
B36: Маржинальный доход, грн | C36: =(C5)-(C8) -> 2533929 | D36: =(D5)-(D8) -> -856715 | E36: =(E5)-(E8) -> 1677214 | G36: =(G5)-(G8) -> -44655 | H36: =(H5)-(H8) -> -30403 | I36: =(I5)-(I8) -> -75058 | L36: =(L5)-(L8) -> -956216.47 | M36: =(M5)-(M8) -> -43331.796 | N36: =(N5)-(N8) -> -999548.27 | Q36: =(Q5)-(Q8) -> -218190.11 | R36: =(R5)-(R8) -> -30888 | S36: =(S5)-(S8) -> -249078.11 | V36: =(V5)-(V8) -> 1944052.3 | W36: =(W5)-(W8) -> -458642 | X36: =(X5)-(X8) -> 1485410.3 | AA36: =(AA5)-(AA8) -> 1087250.4 | AB36: =(AB5)-(AB8) -> -260754.52 | AC36: =(AC5)-(AC8) -> 826495.92 | AF36: =(AF5)-(AF8) -> 467292.99 | AG36: =(AG5)-(AG8) -> -180831.36 | AH36: =(AH5)-(AH8) -> 286461.63 | AK36: =(AK5)-(AK8) -> -2054.406 | AL36: =(AL5)-(AL8) -> -80000 | AM36: =(AM5)-(AM8) -> -82054.406 | AN36: =AM36/$AM$87 -> -0.86833214 | AP36: =(AP5)-(AP8) -> 2277479.8 | AQ36: =(AQ5)-(AQ8) -> -1084850.7 | AR36: =(AR5)-(AR8) -> 1192629.1 | AU36: =(AU5)-(AU8) -> 256449.24 | AV36: =(AV5)-(AV8) -> 228135.68 | AW36: =(AW5)-(AW8) -> 484584.91
B37: Маржинальный доход, % | C37: =C36/(C5) -> 0.55193929 | D37: =D36/(D5) -> #DIV/0! | E37: =E36/(E5) -> 0.36533001 | G37: =G36/(G5) -> #DIV/0! | H37: =H36/(H5) -> #DIV/0! | I37: =I36/(I5) -> #DIV/0! | L37: =L36/(L5) -> #DIV/0! | M37: =M36/(M5) -> #DIV/0! | N37: =N36/(N5) -> #DIV/0! | Q37: =Q36/(Q5) -> #DIV/0! | R37: =R36/(R5) -> #DIV/0! | S37: =S36/(S5) -> #DIV/0! | T37: =S37/$S$87 -> #DIV/0! | V37: =V36/(V5) -> 0.64262149 | W37: =W36/(W5) -> #DIV/0! | X37: =X36/(X5) -> 0.49101384 | Y37: =X37/$S$87 -> 1.8725742e-06 | AA37: =AA36/(AA5) -> 0.74048432 | AB37: =AB36/(AB5) -> #DIV/0! | AC37: =AC36/(AC5) -> 0.56289448 | AD37: =AC37/$S$87 -> 2.1467046e-06 | AF37: =AF36/(AF5) -> 0.92332618 | AG37: =AG36/(AG5) -> #DIV/0! | AH37: =AH36/(AH5) -> 0.56602073 | AI37: =AH37/$AH$87 -> 2.3115222e-06 | AK37: =AK36/(AK5) -> #DIV/0! | AL37: =AL36/(AL5) -> #DIV/0! | AM37: =AM36/(AM5) -> #DIV/0! | AN37: =AM37/$AM$87 -> #DIV/0! | AP37: =AP36/(AP5) -> 0.45553384 | AQ37: =AQ36/(AQ5) -> #DIV/0! | AR37: =AR36/(AR5) -> 0.23854566 | AU37: =AU36/(AU5) -> -0.62758583 | AV37: =AV36/(AV5) -> #DIV/0! | AW37: =AW36/(AW5) -> -1.1858824
T38: =S38/$S$87 -> 0 | Y38: =X38/$S$87 -> 0 | AD38: =AC38/$S$87 -> 0 | AI38: =AH38/$S$87 -> 0 | AN38: =AM38/$AM$87 -> 0
B39: Общепроизводственные затраты | C39: =SUM(C40:C46) -> 4000 | D39: =SUM(D40:D46) -> 5600 | E39: =SUM(E40:E46) -> 9600 | F39: =E39/$E$87 -> 0.0030046782 | G39: =SUM(G40:G46) -> 0 | H39: =SUM(H40:H46) -> 100 | I39: =SUM(I40:I46) -> 100 | J39: =I39/$I$87 -> 0.0012590422 | L39: =SUM(L40:L46) -> 0 | M39: =SUM(M40:M46) -> 50 | N39: =SUM(N40:N46) -> 50 | O39: =N39/$I$87 -> 0.00062952111 | Q39: =SUM(Q40:Q46) -> 1817.5 | R39: =SUM(R40:R46) -> 0 | S39: =SUM(S40:S46) -> 1817.5 | T39: =S39/$S$87 -> 0.0069313801 | V39: =SUM(V40:V46) -> 2504.5 | W39: =SUM(W40:W46) -> 0 | X39: =SUM(X40:X46) -> 2504.5 | Y39: =X39/$X$87 -> 0.0015587176 | AA39: =SUM(AA40:AA46) -> 0 | AB39: =SUM(AB40:AB46) -> 0 | AC39: =SUM(AC40:AC46) -> 0 | AD39: =AC39/$AC$87 -> 0 | AF39: =SUM(AF40:AF46) -> 0 | AG39: =SUM(AG40:AG46) -> 0 | AH39: =SUM(AH40:AH46) -> 0 | AI39: =AH39/$AC$87 -> 0 | AK39: =SUM(AK40:AK46) -> 0 | AL39: =SUM(AL40:AL46) -> 0 | AM39: =SUM(AM40:AM46) -> 0 | AN39: =AM39/$AM$87 -> 0 | AP39: =SUM(AP40:AP46) -> 4322 | AQ39: =SUM(AQ40:AQ46) -> 150 | AR39: =SUM(AR40:AR46) -> 4472 | AS39: =AR39/$AR$87 -> 0.0011245755 | AU39: =SUM(AU40:AU46) -> -322 | AV39: =SUM(AV40:AV46) -> 5450 | AW39: =SUM(AW40:AW46) -> 5128
B40: Благоустройство офиса | E40: =C40+D40 -> 0 | F40: =E40/$E$87 -> 0 | I40: =G40+H40*1 -> 0 | N40: =L40+M40*1 -> 0 | O40: =N40/$N$87 -> 0 | S40: =Q40+R40*1 -> 0 | T40: =S40/$S$87 -> 0 | X40: =V40+W40*1 -> 0 | Y40: =X40/$X$87 -> 0 | AC40: =AA40+AB40*1 -> 0 | AD40: =AC40/$AC$87 -> 0 | AH40: =AF40+AG40*1 -> 0 | AI40: =AH40/$AC$87 -> 0 | AM40: =AK40+AL40*1 -> 0 | AN40: =AM40/$AM$87 -> 0 | AP40: =G40+L40+Q40+V40 -> 0 | AQ40: =H40+M40+R40+W40 -> 0 | AR40: =AP40+AQ40*1 -> 0 | AS40: =AR40/$AR$87 -> 0 | AU40: =C40-AP40 -> 0 | AV40: =D40-AQ40 -> 0 | AW40: =AU40+AV40*1 -> 0 | AX40: =AW40/$E$87 -> 0
B41: Хозтовары и материалы | D41: 1200 | E41: =C41+D41 -> 1200 | F41: =E41/$E$87 -> 0.00037558478 | I41: =G41+H41*1 -> 0 | N41: =L41+M41*1 -> 0 | O41: =N41/$N$87 -> 0 | S41: =Q41+R41*1 -> 0 | T41: =S41/$S$87 -> 0 | X41: =V41+W41*1 -> 0 | Y41: =X41/$X$87 -> 0 | AC41: =AA41+AB41*1 -> 0 | AD41: =AC41/$AC$87 -> 0 | AH41: =AF41+AG41*1 -> 0 | AI41: =AH41/$AC$87 -> 0 | AM41: =AK41+AL41*1 -> 0 | AN41: =AM41/$AM$87 -> 0 | AP41: =G41+L41+Q41+V41 -> 0 | AQ41: =H41+M41+R41+W41 -> 0 | AR41: =AP41+AQ41*1 -> 0 | AS41: =AR41/$AR$87 -> 0 | AU41: =C41-AP41 -> 0 | AV41: =D41-AQ41 -> 1200 | AW41: =AU41+AV41*1 -> 1200 | AX41: =AW41/$E$87 -> 0.00037558478
...

Sheet расчет 2022
C1: СТРОИТЕЛЬСТВО | G1: ЛОГИСТИКА | K1: ПРОИЗВОДСТВО
A2: 1. Расчет комиссии ФА: | C2: =SUM(D4:D23)/SUM(C4:C23) -> 0.12232717 | G2: =SUM(H4:H23)/SUM(G4:G23) -> 0.11141855 | K2: =SUM(L4:L23)/SUM(K4:K23) -> 0.058979856
C3: Всего | D3: в т.ч. комиссия | E3: удельный вес комиссии | G3: Всего | H3: в т.ч. комиссия | I3: удельный вес комиссии | K3: Всего | L3: в т.ч. комиссия | M3: удельный вес комиссии
B4: 1 | C4: 2408426 | D4: 313095.38 | E4: =D4/C4 -> 0.13 | I4: =H4/G4 -> #DIV/0! | M4: =L4/K4 -> #DIV/0!
B5: 2 | C5: 3090864 | D5: 401812.32 | E5: =D5/C5 -> 0.13 | I5: =H5/G5 -> #DIV/0! | M5: =L5/K5 -> #DIV/0!
B6: 3 | C6: 0 | D6: 0 | E6: 0.13 | I6: 0.13 | M6: 0.13
B7: Август | C7: 5652236.7 | D7: 621432.22 | E7: =D7/C7 -> 0.10994448 | G7: 63036 | H7: 8825 | I7: =H7/G7 -> 0.13999937 | K7: =699476 -> 699476 | L7: 47451.54 | M7: =L7/K7 -> 0.067838696
B8: Сентябрь | C8: 10747681 | D8: 1359669.4 | E8: =D8/C8 -> 0.12650816 | G8: 100378.2 | H8: 14052.95 | I8: =H8/G8 -> 0.14000002 | K8: 1340996 | L8: 46250 | M8: =L8/K8 -> 0.03448929
B9: Октябрь | E9: =D9/C9 -> #DIV/0! | G9: 618288.79 | H9: 25433.85 | I9: =H9/G9 -> 0.041135874 | K9: 4151566 | L9: 195298.3 | M9: =L9/K9 -> 0.04704208
B10: Ноябрь | E10: =D10/C10 -> #DIV/0! | G10: 150445 | H10: 16548.95 | I10: =H10/G10 -> 0.11 | K10: 1312900 | L10: 59465 | M10: =L10/K10 -> 0.045292863
B11: Декабрь | C11: 3979360 | D11: 457626.4 | E11: =D11/C11 -> 0.115 | G11: 1267898 | H11: 147703.57 | I11: =H11/G11 -> 0.11649483 | K11: 4368550 | L11: 204187.5 | M11: =L11/K11 -> 0.046740337
B12: Январь 2023 | E12: =D12/C12 -> #DIV/0! | I12: =H12/G12 -> #DIV/0! | K12: 200000 | L12: 6000 | M12: =L12/K12 -> 0.03
B13: Февраль 2023 | C13: 2285664.8 | D13: 262851.45 | E13: =D13/C13 -> 0.115 | G13: 696620.59 | H13: 80111.37 | I13: =H13/G13 -> 0.115 | K13: 200000 | L13: 6000 | M13: =L13/K13 -> 0.03
B14: Март 2023 | C14: 4006508.2 | D14: 475748.45 | E14: =D14/C14 -> 0.11874391 | G14: =655733.71+139000 -> 794733.71 | H14: 75409.377 | I14: =H14/G14 -> 0.094886345 | K14: 4229000 | L14: 126870 | M14: =L14/K14 -> 0.03
B15: апрель 2023 | C15: 2850000 | D15: 342000 | E15: =D15/C15 -> 0.12 | G15: 429137.72 | H15: 49350.838 | I15: =H15/G15 -> 0.115 | K15: 1405340 | L15: 70267 | M15: =L15/K15 -> 0.05
B16: май 2023 | C16: 1889615.7 | D16: 223397.73 | E16: =D16/C16 -> 0.11822389 | I16: =H16/G16 -> #DIV/0! | K16: 2131701.4 | L16: 109432.72 | M16: =L16/K16 -> 0.051335858
B17: июнь 2023 | C17: 5146581 | D17: 637523 | E17: =D17/C17 -> 0.12387311 | G17: 401936 | H17: 52252 | I17: =H17/G17 -> 0.1300008 | K17: 1726170 | L17: 94939 | M17: =L17/K17 -> 0.054999797
B18: июль 2023 | C18: 1091840 | D18: 119011 | E18: =D18/C18 -> 0.1090004 | G18: 483950 | H18: 53235 | I18: =H18/G18 -> 0.11000103 | K18: 3202451 | L18: 167623 | M18: =L18/K18 -> 0.052342097
B19: август 2023 | C19: 9462589.4 | D19: 1103619.3 | E19: =D19/C19 -> 0.11662973 | G19: 299954 | H19: 32994.94 | I19: =H19/G19 -> 0.11 | K19: 1499970.2 | L19: 172496.57 | M19: =L19/K19 -> 0.115
B20: сентябрь 2023 | C20: 7762830 | D20: 918259 | E20: =D20/C20 -> 0.11828921 | G20: 543482 | H20: 70452 | I20: =H20/G20 -> 0.12963079 | K20: 1318783 | L20: 157961 | M20: =L20/K20 -> 0.11977786
B21: октябрь 2023 | C21: 4285951 | D21: 496273.3 | E21: =D21/C21 -> 0.11579071 | G21: 449304.76 | H21: 52029.49 | I21: =H21/G21 -> 0.1158 | K21: =1006651.19 -> 1006651.2 | L21: 116570.2 | M21: =L21/K21 -> 0.11579999
B22: Ноябрь 2023 | C22: 5646078 | D22: 718987 | E22: =D22/C22 -> 0.12734273 | G22: 123912 | H22: 17348 | I22: =H22/G22 -> 0.14000258 | M22: 0.1273
B23: Декабрь 2023 | C23: 9191143 | D23: 1273382 | E23: =D23/C23 -> 0.13854447 | G23: 628409 | H23: 89919 | I23: =H23/G23 -> 0.14308993 | K23: 1468605 | L23: 204046 | M23: =L23/K23 -> 0.13893865
B24: Январь 2024 | C24: 3135856 | D24: 394168 | E24: =D24/C24 -> 0.1256971 | G24: 120000 | H24: 16200 | I24: =H24/G24 -> 0.135 | K24: 1312728 | L24: 183782 | M24: =L24/K24 -> 0.14000006
B25: Февраль 2024 | C25: 4891736 | D25: 629847 | E25: =D25/C25 -> 0.12875736 | G25: 0 | H25: 0 | I25: =I24 -> 0.135 | K25: 442477 | L25: 57522 | M25: =L25/K25 -> 0.12999998
B26: Март 2024 | C26: 5338093 | D26: 672676.22 | E26: =D26/C26 -> 0.12601433 | G26: 120000 | H26: 15600 | I26: =H26/G26 -> 0.13 | K26: 319855 | L26: 41581 | M26: =L26/K26 -> 0.12999953
B29: Переходящяя Чистая прибыль за минусом CAPEX и Фин деятельности на 31.12.2021г. | C29: 15831480
B31: Прибыль по отчету | C31: 17670
C32: PnL | D32: инвестиции | E32: дивиденды | F32: Свободные ДС | G32: Резервный фонд | H32: ДС к распределению
B33: PnL по направлениям | C33: =C41 -> #REF! | D33: =SUM(D34:D38) -> 58733285 | E33: =SUM(E34:E38) -> 17798641 | F33: =SUM(F34:F38) -> #REF! | G33: =SUM(G34:G37) -> 7750000 | H33: =SUM(H34:H37) -> #REF!
B34: СТРОИТЕЛЬСТВО | C34: =53608622.52+721597+#REF!+#REF! -> #REF! | D34: =C43 -> 44652349 | E34: =C61 -> 12993064 | F34: =C34-D34-E34+(C37/3*2) -> #REF! | G34: =3000000+1000000/3*2+1500000+1000000/3*2 -> 5833333.3 | H34: =F34-G34 -> #REF!
B35: ЛОГИСТИКА+спецтехника | C35: =1563454.33+Техника!BH86+PL_Логистика!BH86+Техника!BM86+PL_Логистика!BM86 -> 1327792 | D35: =C52 -> 2537197 | E35: =C62 -> 0 | F35: =C35-D35-E35 -> -1209405 | H35: =F35-G35 -> -1209405
B36: ПРОИЗВОДСТВО | C36: =24034035.74+#REF!+#REF! -> #REF! | D36: =C55 -> 11543739 | E36: =C63 -> 4805576.9 | F36: =C36-D36-E36+(C37/3) -> #REF! | G36: =750000+1000000/3+500000+1000000/3 -> 1916666.7 | H36: =F36-G36 -> #REF!
B37: ЦО распределить Строительстов 2/ Производство 1 | C37: =-4674263.27+#REF!+#REF! -> #REF!
C38: =C33-C34-C35-C36-C37 -> #REF!
B39: добавить вливания инвестора по направлениям
B41: операционная прибыль по компании 2022 - 2024г. | C41: =75253446.36+#REF! -> #REF! | D41: 44562 | E41: 44593 | F41: 44621 | G41: 44652 | H41: 44682 | I41: 44713 | J41: 44743 | K41: 44774 | L41: 44805 | M41: 44835 | N41: 44866 | O41: 44896 | P41: янв.23 | Q41: фев.23 | R41: март 23 | S41: апр.23 | T41: май 23 | U41: июн.23 | V41: июл.23 | W41: авг.23 | X41: сент.23 | Y41: окт.23 | Z41: 45231 | AA41: 45261 | AB41: 45292 | AC41: 45323
B42: Покупка ОС (CAPEX) или инвестиции | C42: =C43+C52+C55 -> 58733285 | D42: =D43+D52+D55 -> 2050243.6 | E42: =E43+E52+E55 -> 4709675 | F42: =F43+F52+F55 -> 0 | G42: =G43+G52+G55 -> 0 | H42: =H43+H52+H55 -> 0 | I42: =I43+I52+I55 -> 8236445.2 | J42: =J43+J52+J55 -> 5137258 | ... AC42: =AC43+AC52+AC55 -> 1338520
B43: СТРОИТЕЛЬСТВО | C43: =SUM(D43:AC43) -> 44652349 | D43: =SUM(D44:D51) -> 2050243.6 | E43: =SUM(E44:E51) -> 4709675 | F43: =SUM(F44:F51) -> 0 | G43: =SUM(G44:G51) -> 0 | H43: =SUM(H44:H51) -> 0 | I43: =SUM(I44:I51) -> 8236445.2 | J43: =SUM(J44:J51) -> 5137258 | K43: =SUM(K44:K51) -> 9675 | ... AC43: =SUM(AC44:AC51) -> 1338020
B44: офис | C44: =SUM(D44:AC44) -> 10624 | E44: =10624 -> 10624
...

Sheet PL_Козин
A2: PL Козин | G2: 2019 | L2: Январь 2020 | Q2: Февраль 2020 | V2: Март 2020 | AA2: Накопительный PL январь-март 2020 | AF2: Остаток PL январь 2020
A3: План итого
B4: Статья | C4: Сумма по Ф1, грн | D4: Сумма по Ф2, грн | E4: Сумма итого, грн | F4: % суммы затрат в общем объеме | G4: Сумма по Ф1, грн | H4: Сумма по Ф2, грн | I4: Сумма итого, грн | J4: % суммы затрат в общем объеме | K4: Комментарий | L4: Сумма по Ф1, грн | M4: Сумма по Ф2, грн | N4: Сумма итого, грн | O4: % суммы затрат в общем объеме | P4: Комментарий | Q4: Сумма по Ф1, грн | R4: Сумма по Ф2, грн | S4: Сумма итого, грн | T4: % суммы затрат в общем объеме | U4: Комментарий | V4: Сумма по Ф1, грн | W4: Сумма по Ф2, грн | X4: Сумма итого, грн | Y4: % суммы затрат в общем объеме | Z4: Комментарий | AA4: Сумма по Ф1, грн | AB4: Сумма по Ф2, грн | AC4: Сумма итого, грн | AD4: % суммы затрат в общем объеме | AE4: Комментарии | AF4: Сумма по Ф1, грн | AG4: Сумма по Ф2, грн | AH4: Сумма итого, грн | AI4: % суммы затрат в общем объеме | AJ4: Комментарии
B5: Операционный доход | C5: =C6 -> 0 | D5: =D6 -> 4969127 | E5: =E6 -> 4969127 | G5: =G6 -> 0 | H5: =H6 -> 0 | I5: =I6 -> 0 | L5: =L6 -> 0 | M5: =M6 -> 1911138 | N5: =N6 -> 1911138 | Q5: =Q6 -> 0 | R5: =R6 -> 0 | S5: =S6 -> 0 | V5: =V6 -> 0 | W5: =W6 -> 2770509.3 | X5: =X6 -> 2770509.3 | AA5: =AA6 -> 0 | AB5: =AB6 -> 4681647.3 | AC5: =AC6 -> 4681647.3 | AF5: =AF6 -> 0 | AG5: =AG6 -> 287479.69 | AH5: =AH6 -> 287479.69
B6: Выручка от продаж (товаров, работ, услуг) | D6: 4969127 | E6: =C6+D6 -> 4969127 | I6: =G6+H6 -> 0 | M6: =1911138 -> 1911138 | N6: =L6+M6 -> 1911138 | P6: акт 1 | S6: =Q6+R6 -> 0 | W6: =3342509.28-572000 -> 2770509.3 | X6: =V6+W6 -> 2770509.3 | Z6: за минусом 572 000 грн не оплатили | AA6: =L6+Q6+V6+G6 -> 0 | AB6: =M6+R6+W6+H6 -> 4681647.3 | AC6: =AA6+AB6 -> 4681647.3 | AF6: =C6-AA6 -> 0 | AG6: =D6-AB6 -> 287479.69 | AH6: =AF6+AG6 -> 287479.69
B7: Доход от прочей операционной деятельности | E7: =C7+D7 -> 0 | I7: =G7+H7 -> 0 | N7: =L7+M7 -> 0 | S7: =Q7+R7 -> 0 | X7: =V7+W7 -> 0 | AC7: =AA7+AB7 -> 0 | AF7: =C7-AA7 -> 0 | AG7: =D7-AB7 -> 0 | AH7: =AF7+AG7 -> 0
B8: Себестоимость проданой продукции (переменные производственные затраты) | C8: =SUM(C9:C31) -> 975438 | D8: =SUM(D9:D31) -> 2243523 | E8: =SUM(E9:E31) -> 3218961 | F8: =E8/$E$87 -> 0.957426 | G8: =SUM(G9:G31) -> 0 | H8: =SUM(H9:H31) -> 480 | I8: =SUM(I9:I31) -> 480 | J8: =I8/$N$87 -> 0.0011248467 | L8: =SUM(L9:L31) -> 172736.6 | M8: =SUM(M9:M31) -> 163985.65 | N8: =SUM(N9:N31) -> 336722.25 | O8: =N8/$N$87 -> 0.7890852 | Q8: =SUM(Q9:Q31) -> 132386.06 | R8: =SUM(R9:R31) -> 33025 | S8: =SUM(S9:S31) -> 165411.06 | T8: =S8/$S$87 -> 0.71402739 | V8: =SUM(V9:V31) -> 209487.07 | W8: =SUM(W9:W31) -> 296819.5 | X8: =SUM(X9:X31) -> 506306.57 | Y8: =X8/$X$87 -> 0.82906417 | AA8: =SUM(AA9:AA31) -> 514609.72 | AB8: =SUM(AB9:AB31) -> 494310.15 | AC8: =SUM(AC9:AC31) -> 1008919.9 | AD8: =AC8/$AC$87 -> 0.79240227 | AF8: =SUM(AF9:AF31) -> 460828.28 | AG8: =SUM(AG9:AG31) -> 1749212.9 | AH8: =SUM(AH9:AH31) -> 2210041.1 | AI8: =AH8/$AH$87 -> 0.91677175
B9: ЗП производственного персонала | C9: 51842 | E9: =C9+D9 -> 51842 | F9: =E9/$E$87 -> 0.015419534 | I9: =G9+H9*1 -> 0 | J9: =I9/$N$87 -> 0 | L9: =5*3944.5 -> 19722.5 | N9: =L9+M9*1 -> 19722.5 | O9: =N9/$N$87 -> 0.046218309 | Q9: =5*6842.5 -> 34212.5 | S9: =Q9+R9*1 -> 34212.5 | T9: =S9/$S$87 -> 0.14768457 | U9: 5 чел бр Пономаренки | V9: =7*6842.5 -> 47897.5 | X9: =V9+W9*1 -> 47897.5 | Y9: =X9/$X$87 -> 0.078430942 | Z9: зп бр.Пономаренко 5чел - 34 212,5 зп бр.Перкатогот 2 чел - 13 685 | AA9: =L9+Q9+V9+G9 -> 101832.5 | AB9: =M9+R9+W9+H9 -> 0 | AC9: =AA9+AB9*1 -> 101832.5 | AD9: =AC9/$AC$87 -> 0.079978902 | AF9: =C9-AA9 -> -49990.5 | AG9: =D9-AB9 -> 0 | AH9: =AF9+AG9*1 -> -49990.5 | AI9: =AH9/$AH$87 -> -0.020737116
B10: Удержание с зарплаты производственного персонала | C10: 14168 | E10: =C10+D10 -> 14168 | F10: =E10/$E$87 -> 0.0042140341 | I10: =G10+H10*1 -> 0 | J10: =I10/$N$87 -> 0 | L10: =955.5*5 -> 4777.5 | N10: =L10+M10*1 -> 4777.5 | O10: =N10/$N$87 -> 0.01119574 | Q10: =1657.5*5 -> 8287.5 | S10: =Q10+R10*1 -> 8287.5 | T10: =S10/$S$87 -> 0.035774524 | V10: =(8500*19.5%)*7 -> 11602.5 | X10: =V10+W10*1 -> 11602.5 | Y10: =X10/$X$87 -> 0.0189988 | AA10: =L10+Q10+V10+G10 -> 24667.5 | AB10: =M10+R10+W10+H10 -> 0 | AC10: =AA10+AB10*1 -> 24667.5 | AD10: =AC10/$AC$87 -> 0.019373771 | AF10: =C10-AA10 -> -10499.5 | AG10: =D10-AB10 -> 0 | AH10: =AF10+AG10*1 -> -10499.5 | AI10: =AH10/$AH$87 -> -0.0043554144
B11: Начисления на зарплату производственного персонала | C11: 12558 | E11: =C11+D11 -> 12558 | F11: =E11/$E$87 -> 0.0037351666 | I11: =G11+H11*1 -> 0 | J11: =I11/$N$87 -> 0 | L11: =1078*5 -> 5390 | N11: =L11+M11*1 -> 5390 | O11: =N11/$N$87 -> 0.012631091 | Q11: =1870*5 -> 9350 | S11: =Q11+R11*1 -> 9350 | T11: =S11/$S$87 -> 0.040361002 | V11: =(8500*22%)*7 -> 13090 | X11: =V11+W11*1 -> 13090 | Y11: =X11/$X$87 -> 0.021434543 | AA11: =L11+Q11+V11+G11 -> 27830 | AB11: =M11+R11+W11+H11 -> 0 | AC11: =AA11+AB11*1 -> 27830 | AD11: =AC11/$AC$87 -> 0.021857588 | AF11: =C11-AA11 -> -15272 | AG11: =D11-AB11 -> 0 | AH11: =AF11+AG11*1 -> -15272 | AI11: =AH11/$AH$87 -> -0.0063351482
B12: Зарплата ИТР | E12: =C12+D12 -> 0 | F12: =E12/$E$87 -> 0 | I12: =G12+H12*1 -> 0 | J12: =I12/$N$87 -> 0 | N12: =L12+M12*1 -> 0 | O12: =N12/$N$87 -> 0 | S12: =Q12+R12*1 -> 0 | T12: =S12/$S$87 -> 0 | X12: =V12+W12*1 -> 0 | Y12: =X12/$X$87 -> 0 | AA12: =L12+Q12+V12+G12 -> 0 | AB12: =M12+R12+W12+H12 -> 0 | AC12: =AA12+AB12*1 -> 0 | AD12: =AC12/$AC$87 -> 0 | AF12: =C12-AA12 -> 0 | AG12: =D12-AB12 -> 0 | AH12: =AF12+AG12*1 -> 0 | AI12: =AH12/$AH$87 -> 0
B13: Удержание с зарплаты ИТР | E13: =C13+D13 -> 0 | F13: =E13/$E$87 -> 0 | I13: =G13+H13*1 -> 0 | J13: =I13/$N$87 -> 0 | N13: =L13+M13*1 -> 0 | O13: =N13/$N$87 -> 0 | S13: =Q13+R13*1 -> 0 | T13: =S13/$S$87 -> 0 | X13: =V13+W13*1 -> 0 | Y13: =X13/$X$87 -> 0 | AA13: =L13+Q13+V13+G13 -> 0 | AB13: =M13+R13+W13+H13 -> 0 | AC13: =AA13+AB13*1 -> 0 | AD13: =AC13/$AC$87 -> 0 | AF13: =C13-AA13 -> 0 | AG13: =D13-AB13 -> 0 | AH13: =AF13+AG13*1 -> 0 | AI13: =AH13/$AH$87 -> 0
B14: Начисления на зарплату ИТР | E14: =C14+D14 -> 0 | F14: =E14/$E$87 -> 0 | I14: =G14+H14*1 -> 0 | J14: =I14/$N$87 -> 0 | N14: =L14+M14*1 -> 0 | O14: =N14/$N$87 -> 0 | S14: =Q14+R14*1 -> 0 | T14: =S14/$S$87 -> 0 | X14: =V14+W14*1 -> 0 | Y14: =X14/$X$87 -> 0 | AA14: =L14+Q14+V14+G14 -> 0 | AB14: =M14+R14+W14+H14 -> 0 | AC14: =AA14+AB14*1 -> 0 | AD14: =AC14/$AC$87 -> 0 | AF14: =C14-AA14 -> 0 | AG14: =D14-AB14 -> 0 | AH14: =AF14+AG14*1 -> 0 | AI14: =AH14/$AH$87 -> 0
B15: ЗП подсобников | E15: =C15+D15 -> 0 | F15: =E15/$E$87 -> 0 | I15: =G15+H15*1 -> 0 | J15: =I15/$N$87 -> 0 | N15: =L15+M15*1 -> 0 | O15: =N15/$N$87 -> 0 | S15: =Q15+R15*1 -> 0 | T15: =S15/$S$87 -> 0 | X15: =V15+W15*1 -> 0 | Y15: =X15/$X$87 -> 0 | AA15: =L15+Q15+V15+G15 -> 0 | AB15: =M15+R15+W15+H15 -> 0 | AC15: =AA15+AB15*1 -> 0 | AD15: =AC15/$AC$87 -> 0 | AF15: =C15-AA15 -> 0 | AG15: =D15-AB15 -> 0 | AH15: =AF15+AG15*1 -> 0 | AI15: =AH15/$AH$87 -> 0
B16: Оплата за выполненные работы | D16: 1708693 | E16: =C16+D16 -> 1708693 | F16: =E16/$E$87 -> 0.5082221 | I16: =G16+H16*1 -> 0 | J16: =I16/$N$87 -> 0 | M16: =135000-L9 -> 115277.5 | N16: =L16+M16*1 -> 115277.5 | O16: =N16/$N$87 -> 0.27014482 | P16: за январь | S16: =Q16+R16*1 -> 0 | T16: =S16/$S$87 -> 0 | W16: 250552.5 | X16: =V16+W16*1 -> 250552.5 | Y16: =X16/$X$87 -> 0.41027337 | Z16: Перкатый Пономаренки | AA16: =L16+Q16+V16+G16 -> 0 | AB16: =M16+R16+W16+H16 -> 365830 | AC16: =AA16+AB16*1 -> 365830 | AD16: =AC16/$AC$87 -> 0.28732165 | AF16: =C16-AA16 -> 0 | AG16: =D16-AB16 -> 1342863 | AH16: =AF16+AG16*1 -> 1342863 | AI16: =AH16/$AH$87 -> 0.55704794
B17: Премия производственного персонала | E17: =C17+D17 -> 0 | F17: =E17/$E$87 -> 0 | I17: =G17+H17*1 -> 0 | J17: =I17/$N$87 -> 0 | N17: =L17+M17*1 -> 0 | O17: =N17/$N$87 -> 0 | S17: =Q17+R17*1 -> 0 | T17: =S17/$S$87 -> 0 | X17: =V17+W17*1 -> 0 | Y17: =X17/$X$87 -> 0 | AA17: =L17+Q17+V17+G17 -> 0 | AB17: =M17+R17+W17+H17 -> 0 | AC17: =AA17+AB17*1 -> 0 | AD17: =AC17/$AC$87 -> 0 | AF17: =C17-AA17 -> 0 | AG17: =D17-AB17 -> 0 | AH17: =AF17+AG17*1 -> 0 | AI17: =AH17/$AH$87 -> 0
B18: Услуги сторонних организаций | C18: 30000 | D18: 18830 | E18: =C18+D18 -> 48830 | F18: =E18/$E$87 -> 0.014523665 | I18: =G18+H18*1 -> 0 | J18: =I18/$N$87 -> 0 | L18: 15000 | M18: 18830 | N18: =L18+M18*1 -> 33830 | O18: =N18/$N$87 -> 0.079278256 | P18: Монтаж РДК -15 000 грн КМД - 18 830 грн | R18: 7455 | S18: =Q18+R18*1 -> 7455 | T18: =S18/$S$87 -> 0.032180884 | U18: КМД | V18: 21000 | X18: =V18+W18*1 -> 21000 | Y18: =X18/$X$87 -> 0.034386968 | Z18: Демонтаж РДК | AA18: =L18+Q18+V18+G18 -> 36000 | AB18: =M18+R18+W18+H18 -> 26285 | AC18: =AA18+AB18*1 -> 62285 | AD18: =AC18/$AC$87 -> 0.048918429 | AF18: =C18-AA18 -> -6000 | AG18: =D18-AB18 -> -7455 | AH18: =AF18+AG18*1 -> -13455 | AI18: =AH18/$AH$87 -> -0.0055814183
B19: Аренда строительного оборудования | E19: =C19+D19 -> 0 | F19: =E19/$E$87 -> 0 | I19: =G19+H19*1 -> 0 | J19: =I19/$N$87 -> 0 | N19: =L19+M19*1 -> 0 | O19: =N19/$N$87 -> 0 | S19: =Q19+R19*1 -> 0 | T19: =S19/$S$87 -> 0 | X19: =V19+W19*1 -> 0 | Y19: =X19/$X$87 -> 0 | AA19: =L19+Q19+V19+G19 -> 0 | AB19: =M19+R19+W19+H19 -> 0 | AC19: =AA19+AB19*1 -> 0 | AD19: =AC19/$AC$87 -> 0 | AF19: =C19-AA19 -> 0 | AG19: =D19-AB19 -> 0 | AH19: =AF19+AG19*1 -> 0 | AI19: =AH19/$AH$87 -> 0
B20: Аренда опалубки | E20: =C20+D20 -> 0 | F20: =E20/$E$87 -> 0 | I20: =G20+H20*1 -> 0 | J20: =I20/$N$87 -> 0 | N20: =L20+M20*1 -> 0 | O20: =N20/$N$87 -> 0 | S20: =Q20+R20*1 -> 0 | T20: =S20/$S$87 -> 0 | X20: =V20+W20*1 -> 0 | Y20: =X20/$X$87 -> 0 | AA20: =L20+Q20+V20+G20 -> 0 | AB20: =M20+R20+W20+H20 -> 0 | AC20: =AA20+AB20*1 -> 0 | AD20: =AC20/$AC$87 -> 0 | AF20: =C20-AA20 -> 0 | AG20: =D20-AB20 -> 0 | AH20: =AF20+AG20*1 -> 0 | AI20: =AH20/$AH$87 -> 0
B21: Арена техники | C21: 140000 | E21: =C21+D21 -> 140000 | F21: =E21/$E$87 -> 0.041640654 | I21: =G21+H21*1 -> 0 | J21: =I21/$N$87 -> 0 | L21: 48080.76 | N21: =L21+M21*1 -> 48080.76 | O21: =N21/$N$87 -> 0.11267392 | P21: РДК 250 (наш) = 105*264,18 грн= 27 739 грн+77 ч 8848 | Q21: 70536.06 | S21: =Q21+R21*1 -> 70536.06 | T21: =S21/$S$87 -> 0.30448193 | U21: РДК 158 ч*264,18+109 ч для 8848 | V21: 35664 | X21: =V21+W21*1 -> 35664 | Y21: =X21/$X$87 -> 0.058398896 | Z21: РДК 250 135ч =35 664 в т ч 8848-22ч | AA21: =L21+Q21+V21+G21 -> 154280.82 | AB21: =M21+R21+W21+H21 -> 0 | AC21: =AA21+AB21*1 -> 154280.82 | AD21: =AC21/$AC$87 -> 0.12117164 | AF21: =C21-AA21 -> -14280.82 | AG21: =D21-AB21 -> 0 | AH21: =AF21+AG21*1 -> -14280.82 | AI21: =AH21/$AH$87 -> -0.0059239858
B22: Логистические затраты | C22: 145600 | E22: =C22+D22 -> 145600 | F22: =E22/$E$87 -> 0.04330628 | I22: =G22+H22*1 -> 0 | J22: =I22/$N$87 -> 0 | L22: =(20833.35*1.2)+15000 -> 40000.02 | N22: =L22+M22*1 -> 40000.02 | O22: =N22/$N$87 -> 0.093737269 | P22: доставка металлоконструкций Альфабизнесгрупп 3 ходки + 15 000 грн перебазировка СБМУ | Q22: 10000 | S22: =Q22+R22*1 -> 10000 | T22: =S22/$S$87 -> 0.043166847 | U22: Доставка м/к Альфа-бизнес груп | V22: =8000*1.2 -> 9600 | X22: =V22+W22*1 -> 9600 | Y22: =X22/$X$87 -> 0.015719757 | Z22: Альфа бизнес групп | AA22: =L22+Q22+V22+G22 -> 59600.02 | AB22: =M22+R22+W22+H22 -> 0 | AC22: =AA22+AB22*1 -> 59600.02 | AD22: =AC22/$AC$87 -> 0.046809655 | AF22: =C22-AA22 -> 85999.98 | AG22: =D22-AB22 -> 0 | AH22: =AF22+AG22*1 -> 85999.98 | AI22: =AH22/$AH$87 -> 0.035674609
B23: МШП | C23: 302006 | E23: =C23+D23 -> 302006 | F23: =E23/$E$87 -> 0.089826623 | I23: =G23+H23*1 -> 0 | J23: =I23/$N$87 -> 0 | L23: =4769.8*1.2 -> 5723.76 | M23: 354.45 | N23: =L23+M23*1 -> 6078.21 | O23: =N23/$N$87 -> 0.014243863 | P23: списанные МШП | R23: 300 | S23: =Q23+R23*1 -> 300 | T23: =S23/$S$87 -> 0.0012950054 | V23: 11862.624 | W23: 163 | X23: =V23+W23*1 -> 12025.624 | Y23: =X23/$X$87 -> 0.019691654 | Z23: за минусом спецодежды механизатора -2 442,99 | AA23: =L23+Q23+V23+G23 -> 17586.384 | AB23: =M23+R23+W23+H23 -> 817.45 | AC23: =AA23+AB23*1 -> 18403.834 | AD23: =AC23/$AC$87 -> 0.014454309 | AF23: =C23-AA23 -> 284419.62 | AG23: =D23-AB23 -> -817.45 | AH23: =AF23+AG23*1 -> 283602.17 | AI23: =AH23/$AH$87 -> 0.11764417
