Workbook

Sheet АПК
A1: Період | B1: Документ | C1: Аналітика Дт | D1: Аналітика Кт | E1: Дебет | H1: Кредит | K1: Поточне сальдо
E2: Рахунок | H2: Рахунок
A3: 01.04.2025 | B3: Переміщення товарів ІБ00-000377 від 01.04.2025 11:00:00 Перемещение ТМЦ | C3: Обл. НДС Емульсія бітумна Igoflex-101 каністра 32л Надходження товарів і послуг ІБ00-000606 від 21.02.2024 23:54:14 АПК (Глобине) | D3: Обл. НДС Емульсія бітумна Igoflex-101 каністра 32л Надходження товарів і послуг ІБ00-000606 від 21.02.2024 23:54:14 Глобине-2 | E3: 205 | F3: 2507.38 | H3: 205 | K3: Д | L3: 1981064.7
A4: 01.04.2025 | B4: Переміщення товарів ІБ00-000377 від 01.04.2025 11:00:00 Перемещение ТМЦ | C4: Обл. НДС Емульсія бітумна Igoflex-101 каністра 32л Надходження товарів і послуг ІБ00-001108 від 22.03.2024 17:34:05 АПК (Глобине) | D4: Обл. НДС Емульсія бітумна Igoflex-101 каністра 32л Надходження товарів і послуг ІБ00-001108 від 22.03.2024 17:34:05 Глобине-2 | E4: 205 | F4: 93456 | H4: 205 | K4: Д | L4: 2074520.7
A5: 01.04.2025 | B5: Переміщення товарів ІБ00-000360 від 01.04.2025 23:11:15 Перемещение ТМЦ | C5: Обл. НДС Емульсія бітумна Р-10 EN каністра 20л Надходження товарів і послуг ІБ00-002088 від 19.12.2023 18:21:48 АПК (Глобине) | D5: Обл. НДС Емульсія бітумна Р-10 EN каністра 20л Надходження товарів і послуг ІБ00-002088 від 19.12.2023 18:21:48 Глобине-2 | E5: 205 | F5: 19202.93 | H5: 205 | K5: Д | L5: 2093723.6
A6: 01.04.2025 | B6: Переміщення товарів ІБ00-000363 від 01.04.2025 23:11:17 Перемещение ТМЦ | C6: Обл. НДС Бетон С 8/10 Р4 Надходження товарів і послуг ІБ00-001194 від 21.03.2025 19:26:05 Пункт фасування та зберігання в бігбегах (Глобине) | D6: Обл. НДС Бетон С 8/10 Р4 Надходження товарів і послуг ІБ00-001194 від 21.03.2025 19:26:05 АПК (Глобине) | E6: 205 | H6: 205 | I6: 6414.41 | K6: Д | L6: 2087309.2
A7: 03.04.2025 | B7: Вимога-накладна ІБ00-000256 від 03.04.2025 17:41:31 Списаны ТМЦ | C7: Обл. НДС Виробничий (Глобине-2) Глобине-2 Прямі материальні виробничі витрати крім зворотніх відходів | D7: Обл. НДС Прокат сталевий круглий (кл. А240С) ф8мм, ст.3пс, міра 6м Надходження товарів і послуг ІБ00-000851 від 03.03.2025 18:09:07 АПК (Глобине) | E7: 231 | H7: 205 | I7: 2666.67 | K7: Д | L7: 2084642.5
A8: 03.04.2025 | B8: Вимога-накладна ІБ00-000256 від 03.04.2025 17:41:31 Списаны ТМЦ | C8: Обл. НДС Виробничий (Глобине-2) Глобине-2 Прямі материальні виробничі витрати крім зворотніх відходів | D8: Обл. НДС Прокат сталевий круглий (кл. А240С) ф12мм, ст.3пс, міра 6м Надходження товарів і послуг ІБ00-000851 від 03.03.2025 18:09:07 АПК (Глобине) | E8: 231 | H8: 205 | I8: 69200 | K8: Д | L8: 2015442.5
A9: 03.04.2025 | B9: Вимога-накладна ІБ00-000256 від 03.04.2025 17:41:31 Списаны ТМЦ | C9: Обл. НДС Виробничий (Глобине-2) Глобине-2 Прямі материальні виробничі витрати крім зворотніх відходів | D9: Обл. НДС Прокат арматурний №12 мм А500С 6м Надходження товарів і послуг ІБ00-000851 від 03.03.2025 18:09:07 АПК (Глобине) | E9: 231 | H9: 205 | I9: 108420 | K9: Д | L9: 1907022.5
A10: 03.04.2025 | B10: Вимога-накладна ІБ00-000256 від 03.04.2025 17:41:31 Списаны ТМЦ | C10: Обл. НДС Виробничий (Глобине-2) Глобине-2 Прямі материальні виробничі витрати крім зворотніх відходів | D10: Обл. НДС Прокат арматурний №14 мм А500С, 12 м Надходження товарів і послуг ІБ00-000851 від 03.03.2025 18:09:07 АПК (Глобине) | E10: 231 | H10: 205 | I10: 292500 | K10: Д | L10: 1614522.5
A11: 03.04.2025 | B11: Вимога-накладна ІБ00-000256 від 03.04.2025 17:41:31 Списаны ТМЦ | C11: Обл. НДС Виробничий (Глобине-2) Глобине-2 Прямі материальні виробничі витрати крім зворотніх відходів | D11: Обл. НДС Прокат арматурний №14 мм А500С, 12 м Надходження товарів і послуг ІБ00-000820 від 04.03.2025 17:40:13 АПК (Глобине) | E11: 231 | H11: 205 | I11: 77220 | K11: Д | L11: 1537302.5
A12: 03.04.2025 | B12: Вимога-накладна ІБ00-000256 від 03.04.2025 17:41:31 Списаны ТМЦ | C12: Обл. НДС Виробничий (Глобине-2) Глобине-2 Прямі материальні виробничі витрати крім зворотніх відходів | D12: Обл. НДС Прокат арматурний №18 мм А500С Надходження товарів і послуг ІБ00-000819 від 04.03.2025 17:40:12 АПК (Глобине) | E12: 231 | H12: 205 | I12: 538278 | K12: Д | L12: 999024.54
A13: 03.04.2025 | B13: Вимога-накладна ІБ00-000256 від 03.04.2025 17:41:31 Списаны ТМЦ | C13: Обл. НДС Виробничий (Глобине-2) Глобине-2 Прямі материальні виробничі витрати крім зворотніх відходів | D13: Обл. НДС Прокат арматурний №18 мм А500С Надходження товарів і послуг ІБ00-000820 від 04.03.2025 17:40:13 АПК (Глобине) | E13: 231 | H13: 205 | I13: 415480 | K13: Д | L13: 583544.54
A14: 03.04.2025 | B14: Вимога-накладна ІБ00-000256 від 03.04.2025 17:41:31 Списаны ТМЦ | C14: Обл. НДС Виробничий (Глобине-2) Глобине-2 Прямі материальні виробничі витрати крім зворотніх відходів | D14: Обл. НДС Прокат арматурний №25 мм А500С 12м Надходження товарів і послуг ІБ00-000851 від 03.03.2025 18:09:07 АПК (Глобине) | E14: 231 | H14: 205 | I14: 10686 | K14: Д | L14: 572858.54
A15: 03.04.2025 | B15: Вимога-накладна ІБ00-000256 від 03.04.2025 17:41:31 Списаны ТМЦ | C15: Обл. НДС Виробничий (Глобине-2) Глобине-2 Прямі материальні виробничі витрати крім зворотніх відходів | D15: Обл. НДС Дріт 1,2 мм термооброблений Надходження товарів і послуг ІБ00-000851 від 03.03.2025 18:09:07 АПК (Глобине) | E15: 231 | H15: 205 | I15: 19415.5 | K15: Д | L15: 553443.04
A16: 03.04.2025 | B16: Вимога-накладна ІБ00-000256 від 03.04.2025 17:41:31 Списаны ТМЦ | C16: Обл. НДС Виробничий (Глобине-2) Глобине-2 Прямі материальні виробничі витрати крім зворотніх відходів | D16: Обл. НДС Щебінь 70-120 Надходження товарів і послуг ІБ00-001071 від 05.03.2025 18:40:09 АПК (Глобине) | E16: 231 | H16: 205 | I16: 146841.75 | K16: Д | L16: 406601.29
A17: 03.04.2025 | B17: Вимога-накладна ІБ00-000256 від 03.04.2025 17:41:31 Списаны ТМЦ | C17: Обл. НДС Виробничий (Глобине-2) Глобине-2 Прямі материальні виробничі витрати крім зворотніх відходів | D17: Обл. НДС Щебінь 40-70 Надходження товарів і послуг ІБ00-001478 від 13.03.2025 11:00:00 АПК (Глобине) | E17: 231 | H17: 205 | I17: 33967.3 | K17: Д | L17: 372633.99
... A19: 03.04.2025 | B19: Вимога-накладна ІБ00-000256 від 03.04.2025 17:41:31 Списаны ТМЦ | C19: Обл. НДС Виробничий (Глобине-2) Глобине-2 Прямі материальні виробничі витрати крім зворотніх відходів | D19: Обл. НДС Щебінь 40-70 Надходження товарів і послуг ІБ00-001482 від 18.03.2025 11:00:00 АПК (Глобине) | E19: 231 | H19: 205 | I19: 40817.2 | K19: Д | L19: 306155.96
A20: 04.04.2025 | B20: Надходження товарів і послуг ІБ00-001456 від 04.04.2025 11:00:00 Оприходованы ТМЦ | C20: Обл. НДС Пенетрон Адмікс 18кг/мішок Надходження товарів і послуг ІБ00-001456 від 04.04.2025 11:00:00 АПК (Глобине) | D20: АГРОНАС ТОВ Договір 12/04/2024 від 12.04.2024_Глобине 2 Рахунок на оплату постачальника ІБ00-001146 від 04.04.2025 23:24:22 | E20: 205 | F20: 128700 | H20: 631 | K20: Д | L20: 434855.96
A21: 07.04.2025 | B21: Надходження товарів і послуг ІБ00-001530 від 07.04.2025 20:00:36 Оприходованы ТМЦ (Зачет аванса поставщику) | C21: Обл. НДС Бетон С 20/25 F75 W6 Р4 Надходження товарів і послуг ІБ00-001530 від 07.04.2025 20:00:36 АПК (Глобине) | D21: Кременчуцький річковий порт ПРАТ Договір 112/Б від 15.10.2024_Глобине-2 Списання з банківського рахунку 00000024808 від 04.04.2025 17:02:03 | E21: 205 | F21: 210298.52 | H21: 631 | K21: Д | L21: 645154.48
A22: 07.04.2025 | B22: Надходження товарів і послуг ІБ00-001530 від 07.04.2025 20:00:36 Оприходованы ТМЦ (Зачет аванса поставщику) | C22: Обл. НДС Бетон С 20/25 F75 W6 Р4 Надходження товарів і послуг ІБ00-001530 від 07.04.2025 20:00:36 АПК (Глобине) | D22: Кременчуцький річковий порт ПРАТ Договір 112/Б від 15.10.2024_Глобине-2 Списання з банківського рахунку 00000024261 від 25.03.2025 17:00:54 | E22: 205 | F22: 335741.48 | H22: 631 | K22: Д | L22: 980895.96
A23: 07.04.2025 | B23: Надходження дод. витрат ІБ00-000235 від 07.04.2025 20:00:37 Доп. расходы при поступлении товаров | C23: Обл. НДС Бетон С 20/25 F75 W6 Р4 Надходження товарів і послуг ІБ00-001530 від 07.04.2025 20:00:36 АПК (Глобине) | D23: Кременчуцький річковий порт ПРАТ Договір 112/Б від 15.10.2024_Глобине-2 Надходження дод. витрат ІБ00-000235 від 07.04.2025 20:00:37 | E23: 205 | F23: 131750.42 | H23: 631 | K23: Д | L23: 1112646.4
A24: 07.04.2025 | B24: Надходження дод. витрат ІБ00-000235 від 07.04.2025 20:00:37 Доп. расходы при поступлении товаров (Зачет аванса поставщику) | C24: Обл. НДС Бетон С 20/25 F75 W6 Р4 Надходження товарів і послуг ІБ00-001530 від 07.04.2025 20:00:36 АПК (Глобине) | D24: Кременчуцький річковий порт ПРАТ Договір 112/Б від 15.10.2024_Глобине-2 Списання з банківського рахунку 00000024808 від 04.04.2025 17:02:03 | E24: 205 | F24: 28437.08 | H24: 631 | K24: Д | L24: 1141083.5
A25: 09.04.2025 | B25: Переміщення товарів ІБ00-000324 від 09.04.2025 11:05:00 Перемещение ТМЦ | C25: Обл. НДС Піна монтажна 750 мл Надходження товарів і послуг ІБ00-001613 від 09.04.2025 11:00:00 АПК (Глобине) | D25: Обл. НДС Піна монтажна 750 мл Надходження товарів і послуг ІБ00-001613 від 09.04.2025 11:00:00 Глобине-2 | E25: 205 | F25: 5400 | H25: 205 | K25: Д | L25: 1146483.5
A26: 11.04.2025 | B26: Надходження товарів і послуг ІБ00-001648 від 11.04.2025 11:00:00 Оприходованы ТМЦ | C26: Обл. НДС Кутник 125х125 мм 8,0 мм, S355JR. 12м Надходження товарів і послуг ІБ00-001648 від 11.04.2025 11:00:00 АПК (Глобине) | D26: АВ МЕТАЛ ГРУП ТОВ Дог 2420/Р от 05.10.2023від 05.10.2023_Глобино-2 Рахунок на оплату постачальника ІБ00-001268 від 11.04.2025 15:03:51 | E26: 205 | F26: 42462.91 | H26: 631 | K26: Д | L26: 1188946.4
A27: 26.04.2025 | B27: Надходження товарів і послуг ІБ00-001882 від 26.04.2025 11:00:00 Оприходованы ТМЦ | C27: Обл. НДС Бетон С20/25 W6 F75 P4 Надходження товарів і послуг ІБ00-001882 від 26.04.2025 11:00:00 АПК (Глобине) | D27: Кременчуцький річковий порт ПРАТ Договір 112/Б від 15.10.2024_Глобине-2 Надходження товарів і послуг ІБ00-001882 від 26.04.2025 11:00:00 | E27: 205 | F27: 82782.52 | H27: 631 | K27: Д | L27: 1271728.9
A28: 26.04.2025 | B28: Надходження товарів і послуг ІБ00-001882 від 26.04.2025 11:00:00 Оприходованы ТМЦ (Зачет аванса поставщику) | C28: Обл. НДС Бетон С20/25 W6 F75 P4 Надходження товарів і послуг ІБ00-001882 від 26.04.2025 11:00:00 АПК (Глобине) | D28: Кременчуцький річковий порт ПРАТ Договір 112/Б від 15.10.2024_Глобине-2 Списання з банківського рахунку 00000025169 від 10.04.2025 09:09:56 | E28: 205 | F28: 57377.48 | H28: 631 | K28: Д | L28: 1329106.4
A29: 26.04.2025 | B29: Надходження дод. витрат ІБ00-000288 від 26.04.2025 11:05:00 Доп. расходы при поступлении товаров | C29: Обл. НДС Бетон С20/25 W6 F75 P4 Надходження товарів і послуг ІБ00-001882 від 26.04.2025 11:00:00 АПК (Глобине) | D29: Кременчуцький річковий порт ПРАТ Договір 112/Б від 15.10.2024_Глобине-2 Надходження дод. витрат ІБ00-000288 від 26.04.2025 11:05:00 | E29: 205 | F29: 38875 | H29: 631 | K29: Д | L29: 1367981.4
A30: 29.04.2025 | B30: Списання товарів ІБ00-000201 від 29.04.2025 00:00:00 Списаны ТМЦ | C30: Обл. НДС Виробничий (Глобине-2) Глобине-2 Прямі материальні виробничі витрати крім зворотніх відходів | D30: Обл. НДС Піна монтажна 750 мл Надходження товарів і послуг ІБ00-001198 від 21.03.2025 19:26:08 АПК (Глобине) | E30: 231 | H30: 205 | I30: 810 | K30: Д | L30: 1367171.4
A31: 29.04.2025 | B31: Списання товарів ІБ00-000201 від 29.04.2025 00:00:00 Списаны ТМЦ | C31: Обл. НДС Виробничий (Глобине-2) Глобине-2 Прямі материальні виробничі витрати крім зворотніх відходів | D31: Обл. НДС Шуруп г/к по дереву 3,5*55 мм Надходження товарів і послуг ІБ00-000711 від 18.02.2025 20:00:44 АПК (Глобине) | E31: 231 | H31: 205 | I31: 99.05 | K31: Д | L31: 1367072.3
A32: 29.04.2025 | B32: Списання товарів ІБ00-000201 від 29.04.2025 00:00:00 Списаны ТМЦ | C32: Обл. НДС Виробничий (Глобине-2) Глобине-2 Прямі материальні виробничі витрати крім зворотніх відходів | D32: Обл. НДС Шуруп г/к по дереву 4,2*76 мм Надходження товарів і послуг ІБ00-000711 від 18.02.2025 20:00:44 АПК (Глобине) | E32: 231 | H32: 205 | I32: 182.5 | K32: Д | L32: 1366889.8
A33: 29.04.2025 | B33: Вимога-накладна ІБ00-000277 від 29.04.2025 14:08:17 Списаны ТМЦ | C33: Обл. НДС Виробничий (Глобине-2) Глобине-2 Прямі материальні виробничі витрати крім зворотніх відходів | D33: Обл. НДС Бетон С 8/10 Р4 Надходження товарів і послуг ІБ00-001194 від 21.03.2025 19:26:05 АПК (Глобине) | E33: 231 | H33: 205 | I33: 100393.59 | K33: Д | L33: 1266496.2
A34: 29.04.2025 | B34: Вимога-накладна ІБ00-000277 від 29.04.2025 14:08:17 Списаны ТМЦ | C34: Обл. НДС Виробничий (Глобине-2) Глобине-2 Прямі материальні виробничі витрати крім зворотніх відходів | D34: Обл. НДС Бетон С 8/10 Р4 Надходження товарів і послуг ІБ00-001449 від 22.03.2025 12:00:01 АПК (Глобине) | E34: 231 | H34: 205 | I34: 6240.16 | K34: Д | L34: 1260256.1
A35: 29.04.2025 | B35: Вимога-накладна ІБ00-000277 від 29.04.2025 14:08:17 Списаны ТМЦ | C35: Обл. НДС Виробничий (Глобине-2) Глобине-2 Прямі материальні виробничі витрати крім зворотніх відходів | D35: Обл. НДС Бетон С 8/10 Р4 Надходження товарів і послуг ІБ00-001449 від 22.03.2025 12:00:01 АПК (Глобине) | E35: 231 | H35: 205 | I35: 34167.88 | K35: Д | L35: 1226088.2
A36: 29.04.2025 | B36: Вимога-накладна ІБ00-000277 від 29.04.2025 14:08:17 Списаны ТМЦ | C36: Обл. НДС Виробничий (Глобине-2) Глобине-2 Прямі материальні виробничі витрати крім зворотніх відходів | D36: Обл. НДС Бетон С 20/25 F75 W6 Р4 Надходження товарів і послуг ІБ00-001530 від 07.04.2025 20:00:36 АПК (Глобине) | E36: 231 | H36: 205 | I36: 706227.5 | K36: Д | L36: 519860.69
A37: 29.04.2025 | B37: Вимога-накладна ІБ00-000277 від 29.04.2025 14:08:17 Списаны ТМЦ | C37: Обл. НДС Виробничий (Глобине-2) Глобине-2 Прямі материальні виробничі витрати крім зворотніх відходів | D37: Обл. НДС Плівка п/е рукав 1500*200 мкм Надходження товарів і послуг ІБ00-001528 від 26.03.2025 11:00:00 АПК (Глобине) | E37: 231 | H37: 205 | I37: 4900.14 | K37: Д | L37: 514960.55
A38: 29.04.2025 | B38: Вимога-накладна ІБ00-000277 від 29.04.2025 14:08:17 Списаны ТМЦ | C38: Обл. НДС Виробничий (Глобине-2) Глобине-2 Прямі материальні виробничі витрати крім зворотніх відходів | D38: Обл. НДС Труба КАН внутр 50/1000 1,8мм Надходження товарів і послуг ІБ00-001377 від 28.03.2025 20:00:14 АПК (Глобине) | E38: 231 | H38: 205 | I38: 444 | K38: Д | L38: 514516.55
A39: 29.04.2025 | B39: Вимога-накладна ІБ00-000277 від 29.04.2025 14:08:17 Списаны ТМЦ | C39: Обл. НДС Виробничий (Глобине-2) Глобине-2 Прямі материальні виробничі витрати крім зворотніх відходів | D39: Обл. НДС Труба КАН тришар 110/2000 2,7мм Надходження товарів і послуг ІБ00-001377 від 28.03.2025 20:00:14 АПК (Глобине) | E39: 231 | H39: 205 | I39: 1470 | K39: Д | L39: 513046.55
A40: 29.04.2025 | B40: Вимога-накладна ІБ00-000277 від 29.04.2025 14:08:17 Списаны ТМЦ | C40: Обл. НДС Виробничий (Глобине-2) Глобине-2 Прямі материальні виробничі витрати крім зворотніх відходів | D40: Обл. НДС Коліно каналіз. 50/90 Надходження товарів і послуг ІБ00-001377 від 28.03.2025 20:00:14 АПК (Глобине) | E40: 231 | H40: 205 | I40: 52 | K40: Д | L40: 512994.55
A41: 29.04.2025 | B41: Вимога-накладна ІБ00-000277 від 29.04.2025 14:08:17 Списаны ТМЦ | C41: Обл. НДС Виробничий (Глобине-2) Глобине-2 Прямі материальні виробничі витрати крім зворотніх відходів | D41: Обл. НДС Коліно 110/90° внутр КАН Надходження товарів і послуг ІБ00-001377 від 28.03.2025 20:00:14 АПК (Глобине) | E41: 231 | H41: 205 | I41: 166 | K41: Д | L41: 512828.55
...

Sheet Генплан благоустрій
A1: Період | B1: Документ | C1: Аналітика Дт | D1: Аналітика Кт | E1: Дебет | H1: Кредит | K1: Поточне сальдо
E2: Рахунок | H2: Рахунок
A3: 30.04.2025 | B3: Переміщення товарів ІБ00-000399 від 30.04.2025 10:00:00 Перемещение ТМЦ | C3: Обл. НДС Щебінь 20-40 Надходження товарів і послуг ІБ00-001480 від 19.03.2025 11:00:00 Генплан благоустрій (Глобине) | D3: Обл. НДС Щебінь 20-40 Надходження товарів і послуг ІБ00-001480 від 19.03.2025 11:00:00 Резервуар для зберігання розчинника(Глобине) | E3: 205 | F3: 46829.29 | H3: 205 | K3: Д | L3: 46829.29
A4: 30.04.2025 | B4: Переміщення товарів ІБ00-000399 від 30.04.2025 10:00:00 Перемещение ТМЦ | C4: Обл. НДС Щебінь 20-40 Надходження товарів і послуг ІБ00-001479 від 24.03.2025 11:00:00 Генплан благоустрій (Глобине) | D4: Обл. НДС Щебінь 20-40 Надходження товарів і послуг ІБ00-001479 від 24.03.2025 11:00:00 Резервуар для зберігання розчинника(Глобине) | E4: 205 | F4: 434.74 | H4: 205 | K4: Д | L4: 47264.03
A5: 30.04.2025 | B5: Вимога-накладна ІБ00-000328 від 30.04.2025 10:00:00 Списаны ТМЦ | C5: Обл. НДС Виробничий (Глобине-2) Глобине-2 Прямі материальні виробничі витрати крім зворотніх відходів | D5: Обл. НДС Щебінь 20-40 Надходження товарів і послуг ІБ00-001480 від 19.03.2025 11:00:00 Генплан благоустрій (Глобине) | E5: 231 | H5: 205 | I5: 46829.29 | K5: Д | L5: 434.74
A6: 30.04.2025 | B6: Вимога-накладна ІБ00-000328 від 30.04.2025 10:00:00 Списаны ТМЦ | C6: Обл. НДС Виробничий (Глобине-2) Глобине-2 Прямі материальні виробничі витрати крім зворотніх відходів | D6: Обл. НДС Щебінь 20-40 Надходження товарів і послуг ІБ00-001479 від 24.03.2025 11:00:00 Генплан благоустрій (Глобине) | E6: 231 | H6: 205 | I6: 434.74
A7: Обороти за період та сальдо на кінець | E7: 47264.03 | H7: 47264.03 | L7: 0
J9: =SUBTOTAL(9,I5:J6) -> 47264.03

Sheet Генплан митний склад
A1: Період | B1: Документ | C1: Аналітика Дт | D1: Аналітика Кт | E1: Дебет | H1: Кредит | K1: Поточне сальдо
E2: Рахунок | H2: Рахунок
A3: 01.04.2025 | B3: Надходження товарів і послуг ІБ00-001661 від 01.04.2025 11:00:00 Оприходованы ТМЦ | C3: Обл. НДС Дріт в'язальний 1,6 мм 100м Надходження товарів і послуг ІБ00-001661 від 01.04.2025 11:00:00 Генплан митний склад (Глобине) | D3: Солді і Ко ПАТ Дог № 378542-55/19 від 21.01.2019 р. РАХ_Глобине-2 Рахунок на оплату постачальника ІБ00-001179 від 28.03.2025 20:00:28 | E3: 205 | F3: 400 | H3: 631 | K3: Д | L3: 119748.1
A4: 01.04.2025 | B4: Переміщення товарів ІБ00-000331 від 01.04.2025 11:10:00 Перемещение ТМЦ | C4: Обл. НДС Труба профільна 80*80*4 L=12 м Надходження товарів і послуг ІБ00-001657 від 01.04.2025 11:00:00 Генплан митний склад (Глобине) | D4: Обл. НДС Труба профільна 80*80*4 L=12 м Надходження товарів і послуг ІБ00-001657 від 01.04.2025 11:00:00 Глобине-2 | E4: 205 | F4: 5148.68 | H4: 205 | K4: Д | L4: 124896.78
A5: 01.04.2025 | B5: Переміщення товарів ІБ00-000331 від 01.04.2025 11:10:00 Перемещение ТМЦ | C5: Обл. НДС Труба профільна 40*40*3,0 L=6000 мм ст1-3 сп/пс Надходження товарів і послуг ІБ00-001657 від 01.04.2025 11:00:00 Генплан митний склад (Глобине) | D5: Обл. НДС Труба профільна 40*40*3,0 L=6000 мм ст1-3 сп/пс Надходження товарів і послуг ІБ00-001657 від 01.04.2025 11:00:00 Глобине-2 | E5: 205 | F5: 5792.26 | H5: 205 | K5: Д | L5: 130689.04
A6: 01.04.2025 | B6: Переміщення товарів ІБ00-000331 від 01.04.2025 11:10:00 Перемещение ТМЦ | C6: Обл. НДС Дріт 3,0мм з/я т/о Надходження товарів і послуг ІБ00-001657 від 01.04.2025 11:00:00 Генплан митний склад (Глобине) | D6: Обл. НДС Дріт 3,0мм з/я т/о Надходження товарів і послуг ІБ00-001657 від 01.04.2025 11:00:00 Глобине-2 | E6: 205 | F6: 343.23 | H6: 205 | K6: Д | L6: 131032.27
A7: 01.04.2025 | B7: Переміщення товарів ІБ00-000331 від 01.04.2025 11:10:00 Перемещение ТМЦ | C7: Обл. НДС Труба ДУ 32*2,8 ст.1-3пс; 6 м Надходження товарів і послуг ІБ00-001657 від 01.04.2025 11:00:00 Генплан митний склад (Глобине) | D7: Обл. НДС Труба ДУ 32*2,8 ст.1-3пс; 6 м Надходження товарів і послуг ІБ00-001657 від 01.04.2025 11:00:00 Глобине-2 | E7: 205 | F7: 14567.68 | H7: 205 | K7: Д | L7: 145599.95
A8: 01.04.2025 | B8: Переміщення товарів ІБ00-000331 від 01.04.2025 11:10:00 Перемещение ТМЦ | C8: Обл. НДС Кутник 45х45х4,0 Надходження товарів і послуг ІБ00-001657 від 01.04.2025 11:00:00 Генплан митний склад (Глобине) | D8: Обл. НДС Кутник 45х45х4,0 Надходження товарів і послуг ІБ00-001657 від 01.04.2025 11:00:00 Глобине-2 | E8: 205 | F8: 2865.61 | H8: 205 | K8: Д | L8: 148465.56
A9: 01.04.2025 | B9: Переміщення товарів ІБ00-000331 від 01.04.2025 11:10:00 Перемещение ТМЦ | C9: Обл. НДС Труба 100х100х4 (12,05- 8940:2019 08кп/1-3пс) Надходження товарів і послуг ІБ00-001657 від 01.04.2025 11:00:00 Генплан митний склад (Глобине) | D9: Обл. НДС Труба 100х100х4 (12,05- 8940:2019 08кп/1-3пс) Надходження товарів і послуг ІБ00-001657 від 01.04.2025 11:00:00 Глобине-2 | E9: 205 | F9: 4370.3 | H9: 205 | K9: Д | L9: 152835.86
A10: 02.04.2025 | B10: Списання товарів ІБ00-000168 від 02.04.2025 15:47:34 Списаны ТМЦ | C10: Обл. НДС Виробничий (Глобине-2) Глобине-2 Прямі материальні виробничі витрати крім зворотніх відходів | D10: Обл. НДС Хомут нейлон. 4,8х350мм ІЕК Надходження товарів і послуг ІБ00-001198 від 21.03.2025 19:26:08 Генплан митний склад (Глобине) | E10: 231 | H10: 205 | I10: 358.6 | K10: Д | L10: 152477.26
A11: 03.04.2025 | B11: Списання товарів ІБ00-000199 від 03.04.2025 17:41:39 Списаны ТМЦ | C11: Обл. НДС Виробничий (Глобине-2) Глобине-2 Прямі материальні виробничі витрати крім зворотніх відходів | D11: Обл. НДС Провід ПВС 3*2,5 бухта 100м Надходження товарів і послуг ІБ00-001045 від 12.03.2025 18:45:21 Генплан митний склад (Глобине) | E11: 231 | H11: 205 | I11: 446.15 | K11: Д | L11: 152031.11
A12: 07.04.2025 | B12: Надходження товарів і послуг ІБ00-001660 від 07.04.2025 11:00:00 Оприходованы ТМЦ | C12: Обл. НДС Прожектор LED200W 6000К 16000Lm Надходження товарів і послуг ІБ00-001660 від 07.04.2025 11:00:00 Генплан митний склад (Глобине) | D12: Моноліт - Центр" ТОВ Рахунки_Глобине-2 Рахунок на оплату постачальника ІБ00-001341 від 14.03.2025 18:14:57 | E12: 205 | F12: 1602.75 | H12: 631 | K12: Д | L12: 153633.86
A13: 09.04.2025 | B13: Переміщення товарів ІБ00-000322 від 09.04.2025 11:10:00 Перемещение ТМЦ | C13: Обл. НДС Бетон С20/25 W6 F75 P4 доб-5 Надходження товарів і послуг ІБ00-001591 від 09.04.2025 11:00:00 Генплан митний склад (Глобине) | D13: Обл. НДС Бетон С20/25 W6 F75 P4 доб-5 Надходження товарів і послуг ІБ00-001591 від 09.04.2025 11:00:00 Глобине-2 | E13: 205 | F13: 3941.11 | H13: 205 | K13: Д | L13: 157574.97
A14: 11.04.2025 | B14: Надходження товарів і послуг ІБ00-001809 від 11.04.2025 11:00:00 Оприходованы ТМЦ (Зачет аванса поставщику) | C14: Обл. НДС Дріт колючо-ріжуч спіраль діам кільця=500мм/3скоби 10м Надходження товарів і послуг ІБ00-001809 від 11.04.2025 11:00:00 Генплан митний склад (Глобине) | D14: Сітка Захід Україна ТОВ Договір 19/09/24 від 19.09.2024_Глобине 2 Рахунок на оплату постачальника ІБ00-001035 від 27.03.2025 18:14:42 | E14: 205 | F14: 5250 | H14: 631 | K14: Д | L14: 162824.97
A15: 11.04.2025 | B15: Надходження товарів і послуг ІБ00-001604 від 11.04.2025 20:51:44 Оприходованы ТМЦ | C15: Обл. НДС Щебінь 40-70 Надходження товарів і послуг ІБ00-001604 від 11.04.2025 20:51:44 Генплан митний склад (Глобине) | D15: Енергія Логістик ТОВ №28/10-2024 ВІД 28/10/24_Глобине-2 Рахунок на оплату постачальника ІБ00-001315 від 11.04.2025 20:51:43 | E15: 205 | F15: 13345.5 | H15: 631 | K15: Д | L15: 176170.47
A16: 11.04.2025 | B16: Надходження дод. витрат ІБ00-000246 від 11.04.2025 20:51:45 Доп. расходы при поступлении товаров | C16: Обл. НДС Щебінь 40-70 Надходження товарів і послуг ІБ00-001604 від 11.04.2025 20:51:44 Генплан митний склад (Глобине) | D16: Енергія Логістик ТОВ №28/10-2024 ВІД 28/10/24_Глобине-2 Рахунок на оплату постачальника ІБ00-001315 від 11.04.2025 20:51:43 | E16: 205 | F16: 13671 | H16: 631 | K16: Д | L16: 189841.47
A17: 12.04.2025 | B17: Надходження товарів і послуг ІБ00-001628 від 12.04.2025 12:00:03 Оприходованы ТМЦ | C17: Обл. НДС Щебенево-піщана суміш фр 0-70 мм Надходження товарів і послуг ІБ00-001628 від 12.04.2025 12:00:03 Генплан митний склад (Глобине) | D17: Венкрас Авто ПП Договір 05/09/2024 від 05.09.2024_Глобине-2 Рахунок на оплату постачальника ІБ00-001331 від 12.04.2025 12:00:02 | E17: 205 | F17: 10017 | H17: 631 | K17: Д | L17: 199858.47
A18: 12.04.2025 | B18: Надходження дод. витрат ІБ00-000265 від 12.04.2025 12:05:00 Доп. расходы при поступлении товаров | C18: Обл. НДС Щебенево-піщана суміш фр 0-70 мм Надходження товарів і послуг ІБ00-001628 від 12.04.2025 12:00:03 Генплан митний склад (Глобине) | D18: Венкрас Авто ПП Договір 05/09/2024 від 05.09.2024_Глобине-2 Рахунок на оплату постачальника ІБ00-001331 від 12.04.2025 12:00:02 | E18: 205 | F18: 10573.5 | H18: 631 | K18: Д | L18: 210431.97
A19: 15.04.2025 | B19: Переміщення товарів ІБ00-000334 від 15.04.2025 11:10:00 Перемещение ТМЦ | C19: Обл. НДС Пісок з відсіву дроблення щебеню фр. 0-5мм. Надходження товарів і послуг ІБ00-001681 від 15.04.2025 11:00:00 Генплан митний склад (Глобине) | D19: Обл. НДС Пісок з відсіву дроблення щебеню фр. 0-5мм. Надходження товарів і послуг ІБ00-001681 від 15.04.2025 11:00:00 Глобине-2 | E19: 205 | F19: 18870 | H19: 205 | K19: Д | L19: 229301.97
A20: 18.04.2025 | B20: Переміщення товарів ІБ00-000345 від 18.04.2025 11:10:00 Перемещение ТМЦ | C20: Обл. НДС Пісок з відсіву дроблення щебеню фр. 0-5мм. Надходження товарів і послуг ІБ00-001749 від 18.04.2025 11:00:00 Генплан митний склад (Глобине) | D20: Обл. НДС Пісок з відсіву дроблення щебеню фр. 0-5мм. Надходження товарів і послуг ІБ00-001749 від 18.04.2025 11:00:00 Глобине-2 | E20: 205 | F20: 9105 | H20: 205 | K20: Д | L20: 238406.97
A21: 30.04.2025 | B21: Переміщення товарів ІБ00-000402 від 30.04.2025 10:00:00 Перемещение ТМЦ | C21: Обл. НДС Бетон С 20/25 F75 W6 Р4 Надходження товарів і послуг ІБ00-001450 від 20.03.2025 12:16:00 Цех екстракції (Глобине) | D21: Обл. НДС Бетон С 20/25 F75 W6 Р4 Надходження товарів і послуг ІБ00-001450 від 20.03.2025 12:16:00 Генплан митний склад (Глобине) | E21: 205 | H21: 205 | I21: 5035.45 | K21: Д | L21: 233371.52
A22: 30.04.2025 | B22: Переміщення товарів ІБ00-000402 від 30.04.2025 10:00:00 Перемещение ТМЦ | C22: Обл. НДС Бетон С20/25 W6 F75 P4 доб-5 Надходження товарів і послуг ІБ00-001591 від 09.04.2025 11:00:00 Цех екстракції (Глобине) | D22: Обл. НДС Бетон С20/25 W6 F75 P4 доб-5 Надходження товарів і послуг ІБ00-001591 від 09.04.2025 11:00:00 Генплан митний склад (Глобине) | E22: 205 | H22: 205 | I22: 3941.11 | K22: Д | L22: 229430.41
A23: 30.04.2025 | B23: Переміщення товарів ІБ00-000405 від 30.04.2025 10:00:00 Перемещение ТМЦ | C23: Обл. НДС Щебінь 40-70 Надходження товарів і послуг ІБ00-001604 від 11.04.2025 20:51:44 Генплан підпірна стінка (Глобине) | D23: Обл. НДС Щебінь 40-70 Надходження товарів і послуг ІБ00-001604 від 11.04.2025 20:51:44 Генплан митний склад (Глобине) | E23: 205 | H23: 205 | I23: 17537.21 | K23: Д | L23: 211893.2
A24: Обороти за період та сальдо на кінець | E24: 119863.62 | H24: 27318.52 | K24: Д | L24: 211893.2
J26: =SUBTOTAL(9,I10:J11) -> 804.75

Sheet Генплан підпірна стінка
A1: Період | B1: Документ | C1: Аналітика Дт | D1: Аналітика Кт | E1: Дебет | H1: Кредит | K1: Поточне сальдо
E2: Рахунок | H2: Рахунок
A3: 01.04.2025 | B3: Надходження товарів і послуг ІБ00-002038 від 01.04.2025 11:00:00 Оприходованы ТМЦ (Зачет аванса поставщику) | C3: Обл. НДС Цемент ПЦ ІІ/А-Ш 500 25кг 1пал/64шт Надходження товарів і послуг ІБ00-002038 від 01.04.2025 11:00:00 Генплан підпірна стінка (Глобине) | D3: Лозовий Микола Миколайович ФОП РАХУНКИ_Глобино-2 Рахунок на оплату постачальника ІБ00-000941 від 17.03.2025 18:00:03 | E3: 205 | F3: 17820 | H3: 631 | K3: Д | L3: 179410.54
A4: 01.04.2025 | B4: Надходження товарів і послуг ІБ00-002042 від 01.04.2025 11:00:00 Оприходованы ТМЦ (Зачет аванса поставщику) | C4: Обл. НДС Цемент ПЦ ІІ/А-Ш 500 25кг 1пал/64шт Надходження товарів і послуг ІБ00-002042 від 01.04.2025 11:00:00 Генплан підпірна стінка (Глобине) | D4: Лозовий Микола Миколайович ФОП РАХУНКИ_Глобино-2 Рахунок на оплату постачальника ІБ00-000940 від 17.03.2025 18:00:02 | E4: 205 | F4: 1980 | H4: 631 | K4: Д | L4: 181390.54
A5: 01.04.2025 | B5: Переміщення товарів ІБ00-000349 від 01.04.2025 11:05:00 Перемещение ТМЦ | C5: Обл. НДС дошка 0,15*0,25 4 м Надходження товарів і послуг ІБ00-001790 від 01.04.2025 11:00:00 Генплан підпірна стінка (Глобине) | D5: Обл. НДС дошка 0,15*0,25 4 м Надходження товарів і послуг ІБ00-001790 від 01.04.2025 11:00:00 Глобине-2 | E5: 205 | F5: 3167.5 | H5: 205 | K5: Д | L5: 184558.04
A6: 01.04.2025 | B6: Переміщення товарів ІБ00-000303 від 01.04.2025 18:03:57 Перемещение ТМЦ | C6: Обл. НДС Щебінь 20-40 Надходження товарів і послуг ІБ00-001482 від 18.03.2025 11:00:00 Цех екстракції (Глобине) | D6: Обл. НДС Щебінь 20-40 Надходження товарів і послуг ІБ00-001482 від 18.03.2025 11:00:00 Генплан підпірна стінка (Глобине) | E6: 205 | H6: 205 | I6: 27724.19 | K6: Д | L6: 156833.85
A7: 14.04.2025 | B7: Переміщення товарів ІБ00-000337 від 14.04.2025 11:15:00 Перемещение ТМЦ | C7: Обл. НДС Щебенево-піщана суміш фр 0-70 мм Надходження товарів і послуг ІБ00-001691 від 14.04.2025 11:04:21 Генплан підпірна стінка (Глобине) | D7: Обл. НДС Щебенево-піщана суміш фр 0-70 мм Надходження товарів і послуг ІБ00-001691 від 14.04.2025 11:04:21 Глобине-2 | E7: 205 | F7: 62647.17 | H7: 205 | K7: Д | L7: 219481.02
A8: 21.04.2025 | B8: Надходження товарів і послуг ІБ00-001748 від 21.04.2025 11:00:00 Оприходованы ТМЦ | C8: Обл. НДС Пісок з відсіву дроблення щебеню фр. 0-5мм. Надходження товарів і послуг ІБ00-001748 від 21.04.2025 11:00:00 Генплан підпірна стінка (Глобине) | D8: Енергія Логістик ТОВ №28/10-2024 ВІД 28/10/24_Глобине-2 Рахунок на оплату постачальника ІБ00-001404 від 21.04.2025 11:00:01 | E8: 205 | F8: 3327 | H8: 631 | K8: Д | L8: 222808.02
A9: 23.04.2025 | B9: Переміщення товарів ІБ00-000358 від 23.04.2025 11:10:00 Перемещение ТМЦ | C9: Обл. НДС Пісок з відсіву дроблення щебеню фр. 0-5мм. Надходження товарів і послуг ІБ00-001810 від 23.04.2025 11:00:00 Генплан підпірна стінка (Глобине) | D9: Обл. НДС Пісок з відсіву дроблення щебеню фр. 0-5мм. Надходження товарів і послуг ІБ00-001810 від 23.04.2025 11:00:00 Глобине-2 | E9: 205 | F9: 19797.33 | H9: 205 | K9: Д | L9: 242605.35
A10: 30.04.2025 | B10: Переміщення товарів ІБ00-000405 від 30.04.2025 10:00:00 Перемещение ТМЦ | C10: Обл. НДС Щебінь 40-70 Надходження товарів і послуг ІБ00-001604 від 11.04.2025 20:51:44 Генплан підпірна стінка (Глобине) | D10: Обл. НДС Щебінь 40-70 Надходження товарів і послуг ІБ00-001604 від 11.04.2025 20:51:44 Генплан митний склад (Глобине) | E10: 205 | F10: 17537.21 | H10: 205 | K10: Д | L10: 260142.56
A11: 30.04.2025 | B11: Переміщення товарів ІБ00-000406 від 30.04.2025 10:00:00 Перемещение ТМЦ | C11: Обл. НДС Бетон С20/25 W6 F75 P4 Надходження товарів і послуг ІБ00-001089 від 13.03.2025 18:55:01 СПК (Глобине) | D11: Обл. НДС Бетон С20/25 W6 F75 P4 Надходження товарів і послуг ІБ00-001089 від 13.03.2025 18:55:01 Генплан підпірна стінка (Глобине) | E11: 205 | H11: 205 | I11: 37254.24 | K11: Д | L11: 222888.32
A12: 30.04.2025 | B12: Переміщення товарів ІБ00-000407 від 30.04.2025 10:00:00 Перемещение ТМЦ | C12: Обл. НДС Бетон С20/25 W6 F75 P4 Надходження товарів і послуг ІБ00-001089 від 13.03.2025 18:55:01 Котельна (Глобине) | D12: Обл. НДС Бетон С20/25 W6 F75 P4 Надходження товарів і послуг ІБ00-001089 від 13.03.2025 18:55:01 Генплан підпірна стінка (Глобине) | E12: 205 | H12: 205 | I12: 3184.12 | K12: Д | L12: 219704.2
A13: 30.04.2025 | B13: Переміщення товарів ІБ00-000410 від 30.04.2025 10:00:00 Перемещение ТМЦ | C13: Обл. НДС Бетон С20/25 W6 F75 P4 Надходження товарів і послуг ІБ00-001089 від 13.03.2025 18:55:01 Котельна (Глобине) | D13: Обл. НДС Бетон С20/25 W6 F75 P4 Надходження товарів і послуг ІБ00-001089 від 13.03.2025 18:55:01 Генплан підпірна стінка (Глобине) | E13: 205 | H13: 205 | I13: 61533.18 | K13: Д | L13: 158171.02
A14: 30.04.2025 | B14: Переміщення товарів ІБ00-000420 від 30.04.2025 10:00:00 Перемещение ТМЦ | C14: Обл. НДС Бетон С20/25 W6 F75 P4 Надходження товарів і послуг ІБ00-001089 від 13.03.2025 18:55:01 Пункт фасування та зберігання в бігбегах (Глобине) | D14: Обл. НДС Бетон С20/25 W6 F75 P4 Надходження товарів і послуг ІБ00-001089 від 13.03.2025 18:55:01 Генплан підпірна стінка (Глобине) | E14: 205 | H14: 205 | I14: 23403.31 | K14: Д | L14: 134767.71
A15: 30.04.2025 | B15: Переміщення товарів ІБ00-000423 від 30.04.2025 10:00:00 Перемещение ТМЦ | C15: Обл. НДС Фібра поліпропілен 12мм Надходження товарів і послуг ІБ00-001072 від 01.03.2025 18:17:15 Транспортна галерея (Глобине) | D15: Обл. НДС Фібра поліпропілен 12мм Надходження товарів і послуг ІБ00-001072 від 01.03.2025 18:17:15 Генплан підпірна стінка (Глобине) | E15: 205 | H15: 205 | I15: 8491.5 | K15: Д | L15: 126276.21
A16: 30.04.2025 | B16: Вимога-накладна ІБ00-000337 від 30.04.2025 11:00:00 Списаны ТМЦ | C16: Обл. НДС Виробничий (Глобине-2) Глобине-2 Прямі материальні виробничі витрати крім зворотніх відходів | D16: Обл. НДС Щебінь 40-70 Надходження товарів і послуг ІБ00-001604 від 11.04.2025 20:51:44 Генплан підпірна стінка (Глобине) | E16: 231 | H16: 205 | I16: 17537.21 | K16: Д | L16: 108739
A17: 30.04.2025 | B17: Переміщення товарів ІБ00-000382 від 30.04.2025 11:10:00 Перемещение ТМЦ | C17: Обл. НДС Бетон С 30/35 W4 F75 Р4 Надходження товарів і послуг ІБ00-001961 від 30.04.2025 11:00:00 Генплан підпірна стінка (Глобине) | D17: Обл. НДС Бетон С 30/35 W4 F75 Р4 Надходження товарів і послуг ІБ00-001961 від 30.04.2025 11:00:00 Глобине-2 | E17: 205 | F17: 11827.73 | H17: 205 | K17: Д | L17: 120566.73
A18: Обороти за період та сальдо на кінець | E18: 138103.94 | H18: 179127.75 | K18: Д | L18: 120566.73
J20: =SUBTOTAL(9,I16) -> 17537.21

Sheet Глобине-2
A1: Період | B1: Документ | C1: Аналітика Дт | D1: Аналітика Кт | E1: Дебет | H1: Кредит | K1: Поточне сальдо
E2: Рахунок | H2: Рахунок
A3: 01.04.2025 | B3: Переміщення товарів ІБ00-000377 від 01.04.2025 11:00:00 Перемещение ТМЦ | C3: Обл. НДС Емульсія бітумна Igoflex-101 каністра 32л Надходження товарів і послуг ІБ00-000606 від 21.02.2024 23:54:14 АПК (Глобине) | D3: Обл. НДС Емульсія бітумна Igoflex-101 каністра 32л Надходження товарів і послуг ІБ00-000606 від 21.02.2024 23:54:14 Глобине-2 | E3: 205 | H3: 205 | I3: 2507.38 | K3: Д | L3: 385036.45
A4: 01.04.2025 | B4: Переміщення товарів ІБ00-000377 від 01.04.2025 11:00:00 Перемещение ТМЦ | C4: Обл. НДС Емульсія бітумна Igoflex-101 каністра 32л Надходження товарів і послуг ІБ00-001108 від 22.03.2024 17:34:05 АПК (Глобине) | D4: Обл. НДС Емульсія бітумна Igoflex-101 каністра 32л Надходження товарів і послуг ІБ00-001108 від 22.03.2024 17:34:05 Глобине-2 | E4: 205 | H4: 205 | I4: 93456 | K4: Д | L4: 291580.45
A5: 01.04.2025 | B5: Надходження товарів і послуг ІБ00-001657 від 01.04.2025 11:00:00 Оприходованы ТМЦ (Зачет аванса поставщику) | C5: Обл. НДС Круг 10 (6,05- 3760 3пс/А240с) Надходження товарів і послуг ІБ00-001657 від 01.04.2025 11:00:00 Глобине-2 | D5: МЕТАЛ ХОЛДІНГ ТРЕЙД ТОВ Договір 01/467/24 від 06.09.2024_Глобине-2 Рахунок на оплату постачальника ІБ00-000855 від 13.03.2025 18:54:43 | E5: 205 | F5: 14828.4 | H5: 631 | K5: Д | L5: 306408.85
A6: 01.04.2025 | B6: Надходження товарів і послуг ІБ00-001657 від 01.04.2025 11:00:00 Оприходованы ТМЦ (Зачет аванса поставщику) | C6: Обл. НДС Арматура 12 міра (12-3760 А500С/А400С) Надходження товарів і послуг ІБ00-001657 від 01.04.2025 11:00:00 Глобине-2 | D6: МЕТАЛ ХОЛДІНГ ТРЕЙД ТОВ Договір 01/467/24 від 06.09.2024_Глобине-2 Рахунок на оплату постачальника ІБ00-000855 від 13.03.2025 18:54:43 | E6: 205 | F6: 22400 | H6: 631 | K6: Д | L6: 328808.85
A7: 01.04.2025 | B7: Надходження товарів і послуг ІБ00-001657 від 01.04.2025 11:00:00 Оприходованы ТМЦ (Зачет аванса поставщику) | C7: Обл. НДС Арматура 14 міра (12-3760 А500С/А400С) Надходження товарів і послуг ІБ00-001657 від 01.04.2025 11:00:00 Глобине-2 | D7: МЕТАЛ ХОЛДІНГ ТРЕЙД ТОВ Договір 01/467/24 від 06.09.2024_Глобине-2 Рахунок на оплату постачальника ІБ00-000855 від 13.03.2025 18:54:43 | E7: 205 | F7: 41466.67 | H7: 631 | K7: Д | L7: 370275.52
A8: 01.04.2025 | B8: Надходження товарів і послуг ІБ00-001657 від 01.04.2025 11:00:00 Оприходованы ТМЦ (Зачет аванса поставщику) | C8: Обл. НДС Труба г/к 377х9 (11,8- 8732 20) Надходження товарів і послуг ІБ00-001657 від 01.04.2025 11:00:00 Глобине-2 | D8: МЕТАЛ ХОЛДІНГ ТРЕЙД ТОВ Договір 01/467/24 від 06.09.2024_Глобине-2 Рахунок на оплату постачальника ІБ00-000855 від 13.03.2025 18:54:43 | E8: 205 | F8: 17560.4 | H8: 631 | K8: Д | L8: 387835.92
A9: 01.04.2025 | B9: Надходження товарів і послуг ІБ00-001657 від 01.04.2025 11:00:00 Оприходованы ТМЦ (Зачет аванса поставщику) | C9: Обл. НДС Дріт 1,2 мм термооброблений Надходження товарів і послуг ІБ00-001657 від 01.04.2025 11:00:00 Глобине-2 | D9: МЕТАЛ ХОЛДІНГ ТРЕЙД ТОВ Договір 01/467/24 від 06.09.2024_Глобине-2 Рахунок на оплату постачальника ІБ00-000855 від 13.03.2025 18:54:43 | E9: 205 | F9: 996.24 | H9: 631 | K9: Д | L9: 388832.16
A10: 01.04.2025 | B10: Надходження товарів і послуг ІБ00-001657 від 01.04.2025 11:00:00 Оприходованы ТМЦ (Зачет аванса поставщику) | C10: Обл. НДС Труба профільна 80*80*4 L=12 м Надходження товарів і послуг ІБ00-001657 від 01.04.2025 11:00:00 Глобине-2 | D10: МЕТАЛ ХОЛДІНГ ТРЕЙД ТОВ Договір 01/467/24 від 06.09.2024_Глобине-2 Рахунок на оплату постачальника ІБ00-000855 від 13.03.2025 18:54:43 | E10: 205 | F10: 4898.56 | H10: 631 | K10: Д | L10: 393730.72
A11: 01.04.2025 | B11: Надходження товарів і послуг ІБ00-001657 від 01.04.2025 11:00:00 Оприходованы ТМЦ (Зачет аванса поставщику) | C11: Обл. НДС Труба профільна 40*40*3,0 L=6000 мм ст1-3 сп/пс Надходження товарів і послуг ІБ00-001657 від 01.04.2025 11:00:00 Глобине-2 | D11: МЕТАЛ ХОЛДІНГ ТРЕЙД ТОВ Договір 01/467/24 від 06.09.2024_Глобине-2 Рахунок на оплату постачальника ІБ00-000855 від 13.03.2025 18:54:43 | E11: 205 | F11: 5510.88 | H11: 631 | K11: Д | L11: 399241.6
A12: 01.04.2025 | B12: Надходження товарів і послуг ІБ00-001657 від 01.04.2025 11:00:00 Оприходованы ТМЦ (Зачет аванса поставщику) | C12: Обл. НДС Дріт 3,0мм з/я т/о Надходження товарів і послуг ІБ00-001657 від 01.04.2025 11:00:00 Глобине-2 | D12: МЕТАЛ ХОЛДІНГ ТРЕЙД ТОВ Договір 01/467/24 від 06.09.2024_Глобине-2 Рахунок на оплату постачальника ІБ00-000855 від 13.03.2025 18:54:43 | E12: 205 | F12: 326.56 | H12: 631 | K12: Д | L12: 399568.16
A13: 01.04.2025 | B13: Надходження товарів і послуг ІБ00-001657 від 01.04.2025 11:00:00 Оприходованы ТМЦ (Зачет аванса поставщику) | C13: Обл. НДС Балка 30 (12,05 8239 3пс5) Надходження товарів і послуг ІБ00-001657 від 01.04.2025 11:00:00 Глобине-2 | D13: МЕТАЛ ХОЛДІНГ ТРЕЙД ТОВ Договір 01/467/24 від 06.09.2024_Глобине-2 Рахунок на оплату постачальника ІБ00-000855 від 13.03.2025 18:54:43 | E13: 205 | F13: 109156.32 | H13: 631 | K13: Д | L13: 508724.48
A14: 01.04.2025 | B14: Надходження товарів і послуг ІБ00-001657 від 01.04.2025 11:00:00 Оприходованы ТМЦ | C14: Обл. НДС Труба профільна 100*100*4 L=12000 мм ст1-3 сп/пс Надходження товарів і послуг ІБ00-001657 від 01.04.2025 11:00:00 Глобине-2 | D14: МЕТАЛ ХОЛДІНГ ТРЕЙД ТОВ Договір 01/467/24 від 06.09.2024_Глобине-2 Рахунок на оплату постачальника ІБ00-000855 від 13.03.2025 18:54:43 | E14: 205 | F14: 4093.58 | H14: 631 | K14: Д | L14: 512818.06
A15: 01.04.2025 | B15: Надходження товарів і послуг ІБ00-001657 від 01.04.2025 11:00:00 Оприходованы ТМЦ | C15: Обл. НДС Труба ДУ 32*2,8 ст.1-3пс; 6 м Надходження товарів і послуг ІБ00-001657 від 01.04.2025 11:00:00 Глобине-2 | D15: МЕТАЛ ХОЛДІНГ ТРЕЙД ТОВ Договір 01/467/24 від 06.09.2024_Глобине-2 Рахунок на оплату постачальника ІБ00-000855 від 13.03.2025 18:54:43 | E15: 205 | F15: 13860 | H15: 631 | K15: Д | L15: 526678.06
A16: 01.04.2025 | B16: Надходження товарів і послуг ІБ00-001657 від 01.04.2025 11:00:00 Оприходованы ТМЦ | C16: Обл. НДС Кутник 45х45х4,0 Надходження товарів і послуг ІБ00-001657 від 01.04.2025 11:00:00 Глобине-2 | D16: МЕТАЛ ХОЛДІНГ ТРЕЙД ТОВ Договір 01/467/24 від 06.09.2024_Глобине-2 Рахунок на оплату постачальника ІБ00-000855 від 13.03.2025 18:54:43 | E16: 205 | F16: 2726.4 | H16: 631 | K16: Д | L16: 529404.46
... A21: 01.04.2025 | B21: Надходження товарів і послуг ІБ00-001790 від 01.04.2025 11:00:00 Оприходованы ТМЦ (Зачет аванса поставщику) | C21: Обл. НДС Плита OSB 18 мм Надходження товарів і послуг ІБ00-001790 від 01.04.2025 11:00:00 Глобине-2 | D21: Мошинець Ю.П. ФОП Рахунки_Глобине-2 Рахунок на оплату постачальника ІБ00-000841 від 01.03.2025 18:16:41 | E21: 205 | F21: 17800 | H21: 631 | K21: Д | L21: 577485.03
A22: 01.04.2025 | B22: Переміщення товарів ІБ00-000348 від 01.04.2025 11:05:00 Перемещение ТМЦ | C22: Обл. НДС дошка 0,15*0,25 4 м Надходження товарів і послуг ІБ00-001790 від 01.04.2025 11:00:00 Цех екстракції (Глобине) | D22: Обл. НДС дошка 0,15*0,25 4 м Надходження товарів і послуг ІБ00-001790 від 01.04.2025 11:00:00 Глобине-2 | E22: 205 | H22: 205 | I22: 3801 | K22: Д | L22: 573684.03
A23: 01.04.2025 | B23: Переміщення товарів ІБ00-000348 від 01.04.2025 11:05:00 Перемещение ТМЦ | C23: Обл. НДС Плита OSB 18 мм Надходження товарів і послуг ІБ00-001790 від 01.04.2025 11:00:00 Цех екстракції (Глобине) | D23: Обл. НДС Плита OSB 18 мм Надходження товарів і послуг ІБ00-001790 від 01.04.2025 11:00:00 Глобине-2 | E23: 205 | H23: 205 | I23: 17800 | K23: Д | L23: 555884.03
A24: 01.04.2025 | B24: Переміщення товарів ІБ00-000349 від 01.04.2025 11:05:00 Перемещение ТМЦ | C24: Обл. НДС дошка 0,15*0,25 4 м Надходження товарів і послуг ІБ00-001790 від 01.04.2025 11:00:00 Генплан підпірна стінка (Глобине) | D24: Обл. НДС дошка 0,15*0,25 4 м Надходження товарів і послуг ІБ00-001790 від 01.04.2025 11:00:00 Глобине-2 | E24: 205 | H24: 205 | I24: 3167.5 | K24: Д | L24: 552716.53
A25: 01.04.2025 | B25: Надходження дод. витрат ІБ00-000253 від 01.04.2025 11:05:00 Доп. расходы при поступлении товаров | C25: Обл. НДС Круг 10 (6,05- 3760 3пс/А240с) Надходження товарів і послуг ІБ00-001657 від 01.04.2025 11:00:00 Глобине-2 | D25: МЕТАЛ ХОЛДІНГ ТРЕЙД ТОВ Договір 01/467/24 від 06.09.2024_Глобине-2 Рахунок на оплату постачальника ІБ00-000855 від 13.03.2025 18:54:43 | E25: 205 | F25: 757.12 | H25: 631 | K25: Д | L25: 553473.65
A26: 01.04.2025 | B26: Надходження дод. витрат ІБ00-000253 від 01.04.2025 11:05:00 Доп. расходы при поступлении товаров | C26: Обл. НДС Арматура 12 міра (12-3760 А500С/А400С) Надходження товарів і послуг ІБ00-001657 від 01.04.2025 11:00:00 Глобине-2 | D26: МЕТАЛ ХОЛДІНГ ТРЕЙД ТОВ Договір 01/467/24 від 06.09.2024_Глобине-2 Рахунок на оплату постачальника ІБ00-000855 від 13.03.2025 18:54:43 | E26: 205 | F26: 1143.72 | H26: 631 | K26: Д | L26: 554617.37
A27: 01.04.2025 | B27: Надходження дод. витрат ІБ00-000253 від 01.04.2025 11:05:00 Доп. расходы при поступлении товаров | C27: Обл. НДС Арматура 14 міра (12-3760 А500С/А400С) Надходження товарів і послуг ІБ00-001657 від 01.04.2025 11:00:00 Глобине-2 | D27: МЕТАЛ ХОЛДІНГ ТРЕЙД ТОВ Договір 01/467/24 від 06.09.2024_Глобине-2 Рахунок на оплату постачальника ІБ00-000855 від 13.03.2025 18:54:43 | E27: 205 | F27: 2117.24 | H27: 631 | K27: Д | L27: 556734.61
A28: 01.04.2025 | B28: Надходження дод. витрат ІБ00-000253 від 01.04.2025 11:05:00 Доп. расходы при поступлении товаров | C28: Обл. НДС Труба г/к 377х9 (11,8- 8732 20) Надходження товарів і послуг ІБ00-001657 від 01.04.2025 11:00:00 Глобине-2 | D28: МЕТАЛ ХОЛДІНГ ТРЕЙД ТОВ Договір 01/467/24 від 06.09.2024_Глобине-2 Рахунок на оплату постачальника ІБ00-000855 від 13.03.2025 18:54:43 | E28: 205 | F28: 896.62 | H28: 631 | K28: Д | L28: 557631.23
A29: 01.04.2025 | B29: Надходження дод. витрат ІБ00-000253 від 01.04.2025 11:05:00 Доп. расходы при поступлении товаров | C29: Обл. НДС Дріт 1,2 мм термооброблений Надходження товарів і послуг ІБ00-001657 від 01.04.2025 11:00:00 Глобине-2 | D29: МЕТАЛ ХОЛДІНГ ТРЕЙД ТОВ Договір 01/467/24 від 06.09.2024_Глобине-2 Рахунок на оплату постачальника ІБ00-000855 від 13.03.2025 18:54:43 | E29: 205 | F29: 50.87 | H29: 631 | K29: Д | L29: 557682.1
A30: 01.04.2025 | B30: Надходження дод. витрат ІБ00-000253 від 01.04.2025 11:05:00 Доп. расходы при поступлении товаров | C30: Обл. НДС Труба профільна 80*80*4 L=12 м Надходження товарів і послуг ІБ00-001657 від 01.04.2025 11:00:00 Глобине-2 | D30: МЕТАЛ ХОЛДІНГ ТРЕЙД ТОВ Договір 01/467/24 від 06.09.2024_Глобине-2 Рахунок на оплату постачальника ІБ00-000855 від 13.03.2025 18:54:43 | E30: 205 | F30: 250.12 | H30: 631 | K30: Д | L30: 557932.22
A31: 01.04.2025 | B31: Надходження дод. витрат ІБ00-000253 від 01.04.2025 11:05:00 Доп. расходы при поступлении товаров | C31: Обл. НДС Труба профільна 40*40*3,0 L=6000 мм ст1-3 сп/пс Надходження товарів і послуг ІБ00-001657 від 01.04.2025 11:00:00 Глобине-2 | D31: МЕТАЛ ХОЛДІНГ ТРЕЙД ТОВ Договір 01/467/24 від 06.09.2024_Глобине-2 Рахунок на оплату постачальника ІБ00-000855 від 13.03.2025 18:54:43 | E31: 205 | F31: 281.38 | H31: 631 | K31: Д | L31: 558213.6
A32: 01.04.2025 | B32: Надходження дод. витрат ІБ00-000253 від 01.04.2025 11:05:00 Доп. расходы при поступлении товаров | C32: Обл. НДС Дріт 3,0мм з/я т/о Надходження товарів і послуг ІБ00-001657 від 01.04.2025 11:00:00 Глобине-2 | D32: МЕТАЛ ХОЛДІНГ ТРЕЙД ТОВ Договір 01/467/24 від 06.09.2024_Глобине-2 Рахунок на оплату постачальника ІБ00-000855 від 13.03.2025 18:54:43 | E32: 205 | F32: 16.67 | H32: 631 | K32: Д | L32: 558230.27
A33: 01.04.2025 | B33: Надходження дод. витрат ІБ00-000253 від 01.04.2025 11:05:00 Доп. расходы при поступлении товаров | C33: Обл. НДС Балка 30 (12,05 8239 3пс5) Надходження товарів і послуг ІБ00-001657 від 01.04.2025 11:00:00 Глобине-2 | D33: МЕТАЛ ХОЛДІНГ ТРЕЙД ТОВ Договір 01/467/24 від 06.09.2024_Глобине-2 Рахунок на оплату постачальника ІБ00-000855 від 13.03.2025 18:54:43 | E33: 205 | F33: 5573.41 | H33: 631 | K33: Д | L33: 563803.68
A34: 01.04.2025 | B34: Надходження дод. витрат ІБ00-000253 від 01.04.2025 11:05:00 Доп. расходы при поступлении товаров | C34: Обл. НДС Труба профільна 100*100*4 L=12000 мм ст1-3 сп/пс Надходження товарів і послуг ІБ00-001657 від 01.04.2025 11:00:00 Глобине-2 | D34: МЕТАЛ ХОЛДІНГ ТРЕЙД ТОВ Договір 01/467/24 від 06.09.2024_Глобине-2 Рахунок на оплату постачальника ІБ00-000855 від 13.03.2025 18:54:43 | E34: 205 | F34: 209.01 | H34: 631 | K34: Д | L34: 564012.69
A35: 01.04.2025 | B35: Надходження дод. витрат ІБ00-000253 від 01.04.2025 11:05:00 Доп. расходы при поступлении товаров | C35: Обл. НДС Труба ДУ 32*2,8 ст.1-3пс; 6 м Надходження товарів і послуг ІБ00-001657 від 01.04.2025 11:00:00 Глобине-2 | D35: МЕТАЛ ХОЛДІНГ ТРЕЙД ТОВ Договір 01/467/24 від 06.09.2024_Глобине-2 Рахунок на оплату постачальника ІБ00-000855 від 13.03.2025 18:54:43 | E35: 205 | F35: 707.68 | H35: 631 | K35: Д | L35: 564720.37
A36: 01.04.2025 | B36: Надходження дод. витрат ІБ00-000253 від 01.04.2025 11:05:00 Доп. расходы при поступлении товаров | C36: Обл. НДС Кутник 45х45х4,0 Надходження товарів і послуг ІБ00-001657 від 01.04.2025 11:00:00 Глобине-2 | D36: МЕТАЛ ХОЛДІНГ ТРЕЙД ТОВ Договір 01/467/24 від 06.09.2024_Глобине-2 Рахунок на оплату постачальника ІБ00-000855 від 13.03.2025 18:54:43 | E36: 205 | F36: 139.21 | H36: 631 | K36: Д | L36: 564859.58
... A39: 01.04.2025 | B39: Надходження дод. витрат ІБ00-000253 від 01.04.2025 11:05:00 Доп. расходы при поступлении товаров | C39: Обл. НДС Кутик 75*75*6мм ст.3ПС МІРА 12 м Надходження товарів і послуг ІБ00-001657 від 01.04.2025 11:00:00 Глобине-2 | D39: МЕТАЛ ХОЛДІНГ ТРЕЙД ТОВ Договір 01/467/24 від 06.09.2024_Глобине-2 Рахунок на оплату постачальника ІБ00-000855 від 13.03.2025 18:54:43 | E39: 205 | F39: 20.51 | H39: 631 | K39: Д | L39: 566049.86
A40: 01.04.2025 | B40: Переміщення товарів ІБ00-000329 від 01.04.2025 11:10:00 Перемещение ТМЦ | C40: Обл. НДС Круг 10 (6,05- 3760 3пс/А240с) Надходження товарів і послуг ІБ00-001657 від 01.04.2025 11:00:00 Транспортна галерея (Глобине) | D40: Обл. НДС Круг 10 (6,05- 3760 3пс/А240с) Надходження товарів і послуг ІБ00-001657 від 01.04.2025 11:00:00 Глобине-2 | E40: 205 | H40: 205 | I40: 15585.52 | K40: Д | L40: 550464.34
A41: 01.04.2025 | B41: Переміщення товарів ІБ00-000329 від 01.04.2025 11:10:00 Перемещение ТМЦ | C41: Обл. НДС Арматура 12 міра (12-3760 А500С/А400С) Надходження товарів і послуг ІБ00-001657 від 01.04.2025 11:00:00 Транспортна галерея (Глобине) | D41: Обл. НДС Арматура 12 міра (12-3760 А500С/А400С) Надходження товарів і послуг ІБ00-001657 від 01.04.2025 11:00:00 Глобине-2 | E41: 205 | H41: 205 | I41: 23543.72 | K41: Д | L41: 526920.62
A42: 01.04.2025 | B42: Переміщення товарів ІБ00-000329 від 01.04.2025 11:10:00 Перемещение ТМЦ | C42: Обл. НДС Арматура 14 міра (12-3760 А500С/А400С) Надходження товарів і послуг ІБ00-001657 від 01.04.2025 11:00:00 Транспортна галерея (Глобине) | D42: Обл. НДС Арматура 14 міра (12-3760 А500С/А400С) Надходження товарів і послуг ІБ00-001657 від 01.04.2025 11:00:00 Глобине-2 | E42: 205 | H42: 205 | I42: 43583.91 | K42: Д | L42: 483336.71
A43: 01.04.2025 | B43: Переміщення товарів ІБ00-000329 від 01.04.2025 11:10:00 Перемещение ТМЦ | C43: Обл. НДС Дріт 1,2 мм термооброблений Надходження товарів і послуг ІБ00-001657 від 01.04.2025 11:00:00 Транспортна галерея (Глобине) | D43: Обл. НДС Дріт 1,2 мм термооброблений Надходження товарів і послуг ІБ00-001657 від 01.04.2025 11:00:00 Глобине-2 | E43: 205 | H43: 205 | I43: 1047.11 | K43: Д | L43: 482289.6
A44: 01.04.2025 | B44: Переміщення товарів ІБ00-000330 від 01.04.2025 11:10:00 Перемещение ТМЦ | C44: Обл. НДС Труба г/к 377х9 (11,8- 8732 20) Надходження товарів і послуг ІБ00-001657 від 01.04.2025 11:00:00 Резервуар для зберігання розчинника(Глобине) | D44: Обл. НДС Труба г/к 377х9 (11,8- 8732 20) Надходження товарів і послуг ІБ00-001657 від 01.04.2025 11:00:00 Глобине-2 | E44: 205 | H44: 205 | I44: 18457.02 | K44: Д | L44: 463832.58
A45: 01.04.2025 | B45: Переміщення товарів ІБ00-000331 від 01.04.2025 11:10:00 Перемещение ТМЦ | C45: Обл. НДС Труба профільна 80*80*4 L=12 м Надходження товарів і послуг ІБ00-001657 від 01.04.2025 11:00:00 Генплан митний склад (Глобине) | D45: Обл. НДС Труба профільна 80*80*4 L=12 м Надходження товарів і послуг ІБ00-001657 від 01.04.2025 11:00:00 Глобине-2 | E45: 205 | H45: 205 | I45: 5148.68 | K45: Д | L45: 458683.9
A46: 01.04.2025 | B46: Переміщення товарів ІБ00-000331 від 01.04.2025 11:10:00 Перемещение ТМЦ | C46: Обл. НДС Труба профільна 40*40*3,0 L=6000 мм ст1-3 сп/пс Надходження товарів і послуг ІБ00-001657 від 01.04.2025 11:00:00 Генплан митний склад (Глобине) | D46: Обл. НДС Труба профільна 40*40*3,0 L=6000 мм ст1-3 сп/пс Надходження товарів і послуг ІБ00-001657 від 01.04.2025 11:00:00 Глобине-2 | E46: 205 | H46: 205 | I46: 5792.26 | K46: Д | L46: 452891.64
...

Sheet Котельна
A1: Період | B1: Документ | C1: Аналітика Дт | D1: Аналітика Кт | E1: Дебет | H1: Кредит | K1: Поточне сальдо
E2: Рахунок | H2: Рахунок
A3: 01.04.2025 | B3: Надходження товарів і послуг ІБ00-001789 від 01.04.2025 11:00:00 Оприходованы ТМЦ (Зачет аванса поставщику) | C3: Обл. НДС дошка 0,15*0,25 4 м Надходження товарів і послуг ІБ00-001789 від 01.04.2025 11:00:00 Котельна (Глобине) | D3: Мошинець Ю.П. ФОП Рахунки_Глобине-2 Рахунок на оплату постачальника ІБ00-000782 від 24.01.2025 22:10:42 | E3: 205 | F3: 4882.5 | H3: 631 | K3: Д | L3: 2277339.7
A4: 01.04.2025 | B4: Переміщення товарів ІБ00-000333 від 01.04.2025 11:10:00 Перемещение ТМЦ | C4: Обл. НДС Труба профільна 80*80*4 L=12 ст 1-3 сп/пс Надходження товарів і послуг ІБ00-001657 від 01.04.2025 11:00:00 Котельна (Глобине) | D4: Обл. НДС Труба профільна 80*80*4 L=12 ст 1-3 сп/пс Надходження товарів і послуг ІБ00-001657 від 01.04.2025 11:00:00 Глобине-2 | E4: 205 | F4: 19709.77 | H4: 205 | K4: Д | L4: 2297049.5
A5: 01.04.2025 | B5: Переміщення товарів ІБ00-000333 від 01.04.2025 11:10:00 Перемещение ТМЦ | C5: Обл. НДС Кутик 75*75*6мм ст.3ПС МІРА 12 м Надходження товарів і послуг ІБ00-001657 від 01.04.2025 11:00:00 Котельна (Глобине) | D5: Обл. НДС Кутик 75*75*6мм ст.3ПС МІРА 12 м Надходження товарів і послуг ІБ00-001657 від 01.04.2025 11:00:00 Глобине-2 | E5: 205 | F5: 422.28 | H5: 205 | K5: Д | L5: 2297471.8
A6: 01.04.2025 | B6: Надходження товарів і послуг ІБ00-001594 від 01.04.2025 23:10:21 Оприходованы ТМЦ (Зачет аванса поставщику) | C6: Обл. НДС Газоблок 300*200*600 D500 Надходження товарів і послуг ІБ00-001594 від 01.04.2025 23:10:21 Котельна (Глобине) | D6: СТАНДАРТ БУД ГРУП РАХУНКИ_Глобино-2 Рахунок на оплату постачальника ІБ00-000931 від 19.03.2025 23:12:36 | E6: 205 | F6: 123750 | H6: 631 | K6: Д | L6: 2421221.8
A7: 01.04.2025 | B7: Надходження товарів і послуг ІБ00-001596 від 01.04.2025 23:10:22 Оприходованы ТМЦ | C7: Обл. НДС Газоблок 300*200*600 D500 Надходження товарів і послуг ІБ00-001596 від 01.04.2025 23:10:22 Котельна (Глобине) | D7: СТАНДАРТ БУД ГРУП РАХУНКИ_Глобино-2 Рахунок на оплату постачальника ІБ00-000895 від 17.03.2025 17:20:10 | E7: 205 | F7: 4950 | H7: 631 | K7: Д | L7: 2426171.8
A8: 01.04.2025 | B8: Надходження товарів і послуг ІБ00-001596 від 01.04.2025 23:10:22 Оприходованы ТМЦ (Зачет аванса поставщику) | C8: Обл. НДС Газоблок 300*200*600 D500 Надходження товарів і послуг ІБ00-001596 від 01.04.2025 23:10:22 Котельна (Глобине) | D8: СТАНДАРТ БУД ГРУП РАХУНКИ_Глобино-2 Рахунок на оплату постачальника ІБ00-000895 від 17.03.2025 17:20:10 | E8: 205 | F8: 118800 | H8: 631 | K8: Д | L8: 2544971.8
A9: 01.04.2025 | B9: Надходження товарів і послуг ІБ00-001597 від 01.04.2025 23:10:23 Оприходованы ТМЦ (Зачет аванса поставщику) | C9: Обл. НДС Клей для газобетону МР2 (25 кг) Надходження товарів і послуг ІБ00-001597 від 01.04.2025 23:10:23 Котельна (Глобине) | D9: СТАНДАРТ БУД ГРУП РАХУНКИ_Глобино-2 Рахунок на оплату постачальника ІБ00-000931 від 19.03.2025 23:12:36 | E9: 205 | F9: 10158.34 | H9: 631 | K9: Д | L9: 2555130.1
A10: 01.04.2025 | B10: Надходження товарів і послуг ІБ00-001597 від 01.04.2025 23:10:23 Оприходованы ТМЦ (Зачет аванса поставщику) | C10: Обл. НДС Газоблок 300*200*600 D500 Надходження товарів і послуг ІБ00-001597 від 01.04.2025 23:10:23 Котельна (Глобине) | D10: СТАНДАРТ БУД ГРУП РАХУНКИ_Глобино-2 Рахунок на оплату постачальника ІБ00-000931 від 19.03.2025 23:12:36 | E10: 205 | F10: 106875 | H10: 631 | K10: Д | L10: 2662005.1
A11: 02.04.2025 | B11: Надходження товарів і послуг ІБ00-001389 від 02.04.2025 18:08:50 Оприходованы ТМЦ | C11: Обл. НДС Газоблок 300*200*600 D500 Надходження товарів і послуг ІБ00-001389 від 02.04.2025 18:08:50 Котельна (Глобине) | D11: СТАНДАРТ БУД ГРУП РАХУНКИ_Глобино-2 Рахунок на оплату постачальника ІБ00-001096 від 31.03.2025 23:59:59 | E11: 205 | F11: 22500 | H11: 631 | K11: Д | L11: 2684505.1
A12: 02.04.2025 | B12: Надходження товарів і послуг ІБ00-001397 від 02.04.2025 18:08:54 Оприходованы ТМЦ | C12: Обл. НДС Газоблок 300*200*600 D500 Надходження товарів і послуг ІБ00-001397 від 02.04.2025 18:08:54 Котельна (Глобине) | D12: СТАНДАРТ БУД ГРУП РАХУНКИ_Глобино-2 Рахунок на оплату постачальника ІБ00-000931 від 19.03.2025 23:12:36 | E12: 205 | F12: 61838 | H12: 631 | K12: Д | L12: 2746343.1
A13: 02.04.2025 | B13: Надходження товарів і послуг ІБ00-001397 від 02.04.2025 18:08:54 Оприходованы ТМЦ (Зачет аванса поставщику) | C13: Обл. НДС Газоблок 300*200*600 D500 Надходження товарів і послуг ІБ00-001397 від 02.04.2025 18:08:54 Котельна (Глобине) | D13: СТАНДАРТ БУД ГРУП РАХУНКИ_Глобино-2 Рахунок на оплату постачальника ІБ00-000931 від 19.03.2025 23:12:36 | E13: 205 | F13: 39412 | H13: 631 | K13: Д | L13: 2785755.1
A14: 03.04.2025 | B14: Вимога-накладна ІБ00-000255 від 03.04.2025 17:41:25 Списаны ТМЦ | C14: Обл. НДС Виробничий (Глобине-2) Глобине-2 Прямі материальні виробничі витрати крім зворотніх відходів | D14: Обл. НДС Клей для газобетону ХСМ МР2 (25 кг) Надходження товарів і послуг ІБ00-000860 від 04.03.2025 10:00:00 Котельна (Глобине) | E14: 231 | H14: 205 | I14: 2300 | K14: Д | L14: 2783455.1
A15: 03.04.2025 | B15: Вимога-накладна ІБ00-000255 від 03.04.2025 17:41:25 Списаны ТМЦ | C15: Обл. НДС Виробничий (Глобине-2) Глобине-2 Прямі материальні виробничі витрати крім зворотніх відходів | D15: Обл. НДС Газоблок 300*200*600 D500 Надходження товарів і послуг ІБ00-000860 від 04.03.2025 10:00:00 Котельна (Глобине) | E15: 231 | H15: 205 | I15: 86375 | K15: Д | L15: 2697080.1
A16: 03.04.2025 | B16: Вимога-накладна ІБ00-000255 від 03.04.2025 17:41:25 Списаны ТМЦ | C16: Обл. НДС Виробничий (Глобине-2) Глобине-2 Прямі материальні виробничі витрати крім зворотніх відходів | D16: Обл. НДС Прокат арматурний № 8 мм А500С 12м Надходження товарів і послуг ІБ00-000546 від 14.02.2025 10:00:00 Котельна (Глобине) | E16: 231 | H16: 205 | I16: 35550 | K16: Д | L16: 2661530.1
A17: 03.04.2025 | B17: Вимога-накладна ІБ00-000260 від 03.04.2025 17:41:45 Списаны ТМЦ | C17: Обл. НДС Виробничий (Глобине-2) Глобине-2 Прямі материальні виробничі витрати крім зворотніх відходів | D17: Обл. НДС Клей для газобетону ХСМ МР2 (25 кг) Надходження товарів і послуг ІБ00-000860 від 04.03.2025 10:00:00 Котельна (Глобине) | E17: 231 | H17: 205 | I17: 2760 | K17: Д | L17: 2658770.1
A18: 03.04.2025 | B18: Вимога-накладна ІБ00-000260 від 03.04.2025 17:41:45 Списаны ТМЦ | C18: Обл. НДС Виробничий (Глобине-2) Глобине-2 Прямі материальні виробничі витрати крім зворотніх відходів | D18: Обл. НДС Газоблок 300*200*600 D500 Надходження товарів і послуг ІБ00-000860 від 04.03.2025 10:00:00 Котельна (Глобине) | E18: 231 | H18: 205 | I18: 17275 | K18: Д | L18: 2641495.1
A19: 03.04.2025 | B19: Вимога-накладна ІБ00-000260 від 03.04.2025 17:41:45 Списаны ТМЦ | C19: Обл. НДС Виробничий (Глобине-2) Глобине-2 Прямі материальні виробничі витрати крім зворотніх відходів | D19: Обл. НДС Газоблок 300*200*600 D500 Надходження товарів і послуг ІБ00-001594 від 01.04.2025 23:10:21 Котельна (Глобине) | E19: 231 | H19: 205 | I19: 93750 | K19: Д | L19: 2547745.1
A20: 07.04.2025 | B20: Надходження товарів і послуг ІБ00-001525 від 07.04.2025 20:00:35 Оприходованы ТМЦ (Зачет аванса поставщику) | C20: Обл. НДС Решітковий настил KOZ 34*38/30*2/оц/1068*1130 Надходження товарів і послуг ІБ00-001525 від 07.04.2025 20:00:35 Котельна (Глобине) | D20: Червоноградський завод металоконструкцій Договір поставки № 44 від 11.06.2020 р._Глобино-2 Рахунок на оплату постачальника ІБ00-000980 від 12.03.2025 18:45:42 | E20: 205 | F20: 4150 | H20: 631 | K20: Д | L20: 2551895.1
A21: 07.04.2025 | B21: Надходження товарів і послуг ІБ00-001525 від 07.04.2025 20:00:35 Оприходованы ТМЦ (Зачет аванса поставщику) | C21: Обл. НДС Сходинки SOZ/34*38/30*2/оц/800*205 Надходження товарів і послуг ІБ00-001525 від 07.04.2025 20:00:35 Котельна (Глобине) | D21: Червоноградський завод металоконструкцій Договір поставки № 44 від 11.06.2020 р._Глобино-2 Рахунок на оплату постачальника ІБ00-000980 від 12.03.2025 18:45:42 | E21: 205 | F21: 1977.2 | H21: 631 | K21: Д | L21: 2553872.3
A22: 07.04.2025 | B22: Надходження товарів і послуг ІБ00-001525 від 07.04.2025 20:00:35 Оприходованы ТМЦ (Зачет аванса поставщику) | C22: Обл. НДС Кріплення гакове до швелера 16 Надходження товарів і послуг ІБ00-001525 від 07.04.2025 20:00:35 Котельна (Глобине) | D22: Червоноградський завод металоконструкцій Договір поставки № 44 від 11.06.2020 р._Глобино-2 Рахунок на оплату постачальника ІБ00-000980 від 12.03.2025 18:45:42 | E22: 205 | F22: 477.6 | H22: 631 | K22: Д | L22: 2554349.9
A23: 07.04.2025 | B23: Надходження товарів і послуг ІБ00-001525 від 07.04.2025 20:00:35 Оприходованы ТМЦ (Зачет аванса поставщику) | C23: Обл. НДС Кріплення для сходинок Надходження товарів і послуг ІБ00-001525 від 07.04.2025 20:00:35 Котельна (Глобине) | D23: Червоноградський завод металоконструкцій Договір поставки № 44 від 11.06.2020 р._Глобино-2 Рахунок на оплату постачальника ІБ00-000980 від 12.03.2025 18:45:42 | E23: 205 | F23: 235.2 | H23: 631 | K23: Д | L23: 2554585.1
A24: 12.04.2025 | B24: Надходження товарів і послуг ІБ00-001654 від 12.04.2025 12:00:04 Оприходованы ТМЦ (Зачет аванса поставщику) | C24: Обл. НДС Клей для газобетону МР2 (25 кг) Надходження товарів і послуг ІБ00-001654 від 12.04.2025 12:00:04 Котельна (Глобине) | D24: СТАНДАРТ БУД ГРУП РАХУНКИ_Глобино-2 Рахунок на оплату постачальника ІБ00-001294 від 10.04.2025 00:00:00 | E24: 205 | F24: 9126.68 | H24: 631 | K24: Д | L24: 2563711.8
A25: 16.04.2025 | B25: Надходження товарів і послуг ІБ00-001716 від 16.04.2025 11:00:00 Оприходованы ТМЦ | C25: Обл. НДС Розчинник УС Нефрас 0,94 л/ 0,75 кг Надходження товарів і послуг ІБ00-001716 від 16.04.2025 11:00:00 Котельна (Глобине) | D25: Лук'ян Михайло Федорович ФОП 22/08-24-1 от 22.08.2024 (РАХУНКИ)_Глобине-2 Рахунок на оплату постачальника ІБ00-001398 від 15.04.2025 18:30:58 | E25: 205 | F25: 281 | H25: 631 | K25: Д | L25: 2563992.8
