Workbook

Sheet Свод
B2: АПК (Глобине) | C2: ='АПК (Глобине)'!J33*1.2 -> 29397.78
B3: Генплан митний склад (Глобине) | C3: ='Генплан митний склад'!H4*1.2 -> 936
B4: Глобине-2 | C4: ='Глобине-2'!J175*1.2 -> 108930.1
B5: Котельна (Глобине) | C5: ='Котельна (Глобине)'!J33*1.2 -> 16948.956
B6: Насосна Градирня (Глобине) | C6: ='Насосна Градирня'!J18*1.2 -> 5066.16
B7: Підготовчі роботи та тимчасові споруди (Глобине) | C7: ='Підготовчі роботи'!J14*1.2 -> 5357.04
B8: Пожежений резервуар (Глобине) | C8: ='Пожежений резервуар'!J15*1.2 -> 9787.44
B9: Пункт фасування та зберігання в бігбегах (Глобине) | C9: ='Пункт фасування'!J22*1.2 -> 9197.064
B10: Резервуар для зберігання розчинника(Глобине) | C10: ='зберігання розчинника'!J13*1.2 -> 7070.04
B11: СПК (Глобине) | C11: ='СПК (Глобине)'!J52*1.2 -> 3034.128
B12: Цех екстракції (Глобине) | C12: ='Цех екстракції'!J36*1.2 -> 28695.78
C13: =SUM(C2:C12) -> 224420.48

Sheet АПК (Глобине)
A1: Період | B1: Документ | C1: Аналітика Дт | D1: Аналітика Кт | E1: Дебет | H1: Кредит | K1: Поточне сальдо
E2: Рахунок | H2: Рахунок
A3: 18.04.2025 | B3: Переміщення товарів ІБ00-000343 від 18.04.2025 11:05:00 Перемещение ТМЦ | C3: Обл. НДС Круг відрізний 230*2.5*22 увігнутий Надходження товарів і послуг ІБ00-001740 від 18.04.2025 11:00:00 АПК (Глобине) | D3: Обл. НДС Круг відрізний 230*2.5*22 увігнутий Надходження товарів і послуг ІБ00-001740 від 18.04.2025 11:00:00 Глобине-2 | E3: 221 | F3: 1410 | H3: 221 | K3: Д | L3: 31808.05
A4: 29.04.2025 | B4: Передача малоцінних активів в експлуатацію ІБ00-000171 від 29.04.2025 14:26:22 Списание стоимости малоценных активов | C4: Обл. НДС Виробничий (Глобине-2) Глобине-2 Амортизація ОЗ загальновиробничого призначення | D4: Обл. НДС Валик 48*180 мм Надходження товарів і послуг ІБ00-001198 від 21.03.2025 19:26:08 АПК (Глобине) | E4: 231 | H4: 221 | I4: 61.7 | K4: Д | L4: 31746.35
A5: 29.04.2025 | B5: Передача малоцінних активів в експлуатацію ІБ00-000171 від 29.04.2025 14:26:22 Списание стоимости малоценных активов | C5: Обл. НДС Виробничий (Глобине-2) Глобине-2 Амортизація ОЗ загальновиробничого призначення | D5: Обл. НДС Взуття чоловіче SEVEN SAFETY S1FUR" р.42 Надходження товарів і послуг ІБ00-001048 від 10.03.2025 20:00:27 АПК (Глобине) | E5: 231 | H5: 221 | I5: 813 | K5: Д | L5: 30933.35
A6: 29.04.2025 | B6: Передача малоцінних активів в експлуатацію ІБ00-000171 від 29.04.2025 14:26:22 Списание стоимости малоценных активов | C6: Обл. НДС Виробничий (Глобине-2) Глобине-2 Амортизація ОЗ загальновиробничого призначення | D6: Обл. НДС Взуття чоловіче SEVEN SAFETY S1FUR" р.43 Надходження товарів і послуг ІБ00-001048 від 10.03.2025 20:00:27 АПК (Глобине) | E6: 231 | H6: 221 | I6: 813 | K6: Д | L6: 30120.35
A7: 29.04.2025 | B7: Передача малоцінних активів в експлуатацію ІБ00-000171 від 29.04.2025 14:26:22 Списание стоимости малоценных активов | C7: Обл. НДС Виробничий (Глобине-2) Глобине-2 Амортизація ОЗ загальновиробничого призначення | D7: Обл. НДС Вилка пряма з з/к,ІР44 Надходження товарів і послуг ІБ00-000748 від 25.02.2025 18:19:56 АПК (Глобине) | E7: 231 | H7: 221 | I7: 537.5 | K7: Д | L7: 29582.85
A8: 29.04.2025 | B8: Передача малоцінних активів в експлуатацію ІБ00-000171 від 29.04.2025 14:26:22 Списание стоимости малоценных активов | C8: Обл. НДС Виробничий (Глобине-2) Глобине-2 Амортизація ОЗ загальновиробничого призначення | D8: Обл. НДС Електроди "Моноліт РЦ" 3 мм 2,5кг Надходження товарів і послуг ІБ00-001431 від 31.03.2025 11:59:59 АПК (Глобине) | E8: 231 | H8: 221 | I8: 2524 | K8: Д | L8: 27058.85
A9: 29.04.2025 | B9: Передача малоцінних активів в експлуатацію ІБ00-000171 від 29.04.2025 14:26:22 Списание стоимости малоценных активов | C9: Обл. НДС Виробничий (Глобине-2) Глобине-2 Амортизація ОЗ загальновиробничого призначення | D9: Обл. НДС Електроди "Моноліт РЦ" 4 мм уп. 5,0 кг Надходження товарів і послуг ІБ00-001431 від 31.03.2025 11:59:59 АПК (Глобине) | E9: 231 | H9: 221 | I9: 3042.25 | K9: Д | L9: 24016.6
A10: 29.04.2025 | B10: Передача малоцінних активів в експлуатацію ІБ00-000171 від 29.04.2025 14:26:22 Списание стоимости малоценных активов | C10: Обл. НДС Виробничий (Глобине-2) Глобине-2 Амортизація ОЗ загальновиробничого призначення | D10: Обл. НДС Електроди д. 4 мм "Моноліт РЦ" (5 кг) (Україна) Надходження товарів і послуг ІБ00-001198 від 21.03.2025 19:26:08 АПК (Глобине) | E10: 231 | H10: 221 | I10: 1825.35 | K10: Д | L10: 22191.25
A11: 29.04.2025 | B11: Передача малоцінних активів в експлуатацію ІБ00-000171 від 29.04.2025 14:26:22 Списание стоимости малоценных активов | C11: Обл. НДС Виробничий (Глобине-2) Глобине-2 Амортизація ОЗ загальновиробничого призначення | D11: Обл. НДС Жилет світловідбиваючий помаранч. Надходження товарів і послуг ІБ00-001049 від 10.03.2025 20:00:28 АПК (Глобине) | E11: 231 | H11: 221 | I11: 2669.28 | K11: Д | L11: 19521.97
A12: 29.04.2025 | B12: Передача малоцінних активів в експлуатацію ІБ00-000171 від 29.04.2025 14:26:22 Списание стоимости малоценных активов | C12: Обл. НДС Виробничий (Глобине-2) Глобине-2 Амортизація ОЗ загальновиробничого призначення | D12: Обл. НДС Касета-розетка 3гн., з/к з кришками ОМЕГА ІР44 16А Надходження товарів і послуг ІБ00-000748 від 25.02.2025 18:19:56 АПК (Глобине) | E12: 231 | H12: 221 | I12: 2232 | K12: Д | L12: 17289.97
A13: 29.04.2025 | B13: Передача малоцінних активів в експлуатацію ІБ00-000171 від 29.04.2025 14:26:22 Списание стоимости малоценных активов | C13: Обл. НДС Виробничий (Глобине-2) Глобине-2 Амортизація ОЗ загальновиробничого призначення | D13: Обл. НДС Перчатки зварюв.червоні(краги) Надходження товарів і послуг ІБ00-000976 від 07.03.2025 19:00:34 АПК (Глобине) | E13: 231 | H13: 221 | I13: 758.4 | K13: Д | L13: 16531.57
A14: 29.04.2025 | B14: Передача малоцінних активів в експлуатацію ІБ00-000171 від 29.04.2025 14:26:22 Списание стоимости малоценных активов | C14: Обл. НДС Виробничий (Глобине-2) Глобине-2 Амортизація ОЗ загальновиробничого призначення | D14: Обл. НДС Рукавиці трикотажні з ПВХ Надходження товарів і послуг ІБ00-001431 від 31.03.2025 11:59:59 АПК (Глобине) | E14: 231 | H14: 221 | I14: 294 | K14: Д | L14: 16237.57
A15: 29.04.2025 | B15: Передача малоцінних активів в експлуатацію ІБ00-000171 від 29.04.2025 14:26:22 Списание стоимости малоценных активов | C15: Обл. НДС Виробничий (Глобине-2) Глобине-2 Амортизація ОЗ загальновиробничого призначення | D15: Обл. НДС Рукавички скло/камінь черв з рифл гум надол р.10 Надходження товарів і послуг ІБ00-001431 від 31.03.2025 11:59:59 АПК (Глобине) | E15: 231 | H15: 221 | I15: 151 | K15: Д | L15: 16086.57
... A23: 29.04.2025 | B23: Передача малоцінних активів в експлуатацію ІБ00-000171 від 29.04.2025 14:26:22 Списание стоимости малоценных активов | C23: Обл. НДС Виробничий (Глобине-2) Глобине-2 Амортизація ОЗ загальновиробничого призначення | D23: Обл. НДС Ножиці д/труб 0-42мм Надходження товарів і послуг ІБ00-001386 від 28.03.2025 20:00:18 АПК (Глобине) | E23: 231 | H23: 221 | I23: 210 | K23: Д | L23: 14695.02
A24: 30.04.2025 | B24: Переміщення товарів ІБ00-000380 від 30.04.2025 11:05:00 Перемещение ТМЦ | C24: Обл. НДС Дюбель-цвях 4,5х40 Надходження товарів і послуг ІБ00-001908 від 30.04.2025 11:00:00 АПК (Глобине) | D24: Обл. НДС Дюбель-цвях 4,5х40 Надходження товарів і послуг ІБ00-001908 від 30.04.2025 11:00:00 Глобине-2 | E24: 221 | F24: 543.1 | H24: 221 | K24: Д | L24: 15238.12
A25: 30.04.2025 | B25: Передача малоцінних активів в експлуатацію ІБ00-000213 від 30.04.2025 20:00:00 Списание стоимости малоценных активов | C25: Обл. НДС Виробничий (Глобине-2) Глобине-2 Амортизація ОЗ загальновиробничого призначення | D25: Обл. НДС Дюбель-цвях 4,5х40 Надходження товарів і послуг ІБ00-001908 від 30.04.2025 11:00:00 АПК (Глобине) | E25: 231 | H25: 221 | I25: 543.1 | K25: Д | L25: 14695.02
A26: 30.04.2025 | B26: Передача малоцінних активів в експлуатацію ІБ00-000213 від 30.04.2025 20:00:00 Списание стоимости малоценных активов | C26: Обл. НДС Виробничий (Глобине-2) Глобине-2 Амортизація ОЗ загальновиробничого призначення | D26: Обл. НДС Електроди "Моноліт РЦ" 4 мм уп. 5,0 кг Надходження товарів і послуг ІБ00-001431 від 31.03.2025 11:59:59 АПК (Глобине) | E26: 231 | H26: 221 | I26: 3042.25 | K26: Д | L26: 11652.77
A27: 30.04.2025 | B27: Передача малоцінних активів в експлуатацію ІБ00-000213 від 30.04.2025 20:00:00 Списание стоимости малоценных активов | C27: Обл. НДС Виробничий (Глобине-2) Глобине-2 Амортизація ОЗ загальновиробничого призначення | D27: Обл. НДС Круг відрізний по металу 125*1,6*22,2 Надходження товарів і послуг ІБ00-001198 від 21.03.2025 19:26:08 АПК (Глобине) | E27: 231 | H27: 221 | I27: 145.25 | K27: Д | L27: 11507.52
A28: 30.04.2025 | B28: Передача малоцінних активів в експлуатацію ІБ00-000213 від 30.04.2025 20:00:00 Списание стоимости малоценных активов | C28: Обл. НДС Виробничий (Глобине-2) Глобине-2 Амортизація ОЗ загальновиробничого призначення | D28: Обл. НДС Круг відрізний 230*2,5*22 Надходження товарів і послуг ІБ00-001198 від 21.03.2025 19:26:08 АПК (Глобине) | E28: 231 | H28: 221 | I28: 1061 | K28: Д | L28: 10446.52
A29: 30.04.2025 | B29: Передача малоцінних активів в експлуатацію ІБ00-000197 від 30.04.2025 23:59:27 Списание стоимости малоценных активов | C29: Обл. НДС Виробничий (Глобине-2) Глобине-2 Амортизація ОЗ загальновиробничого призначення | D29: Обл. НДС Краги зварювальника Надходження товарів і послуг ІБ00-001198 від 21.03.2025 19:26:08 АПК (Глобине) | E29: 231 | H29: 221 | I29: 257.9 | K29: Д | L29: 10188.62
A30: 30.04.2025 | B30: Передача малоцінних активів в експлуатацію ІБ00-000197 від 30.04.2025 23:59:27 Списание стоимости малоценных активов | C30: Обл. НДС Виробничий (Глобине-2) Глобине-2 Амортизація ОЗ загальновиробничого призначення | D30: Обл. НДС Жилет світловідбиваючий помаранч. Надходження товарів і послуг ІБ00-001049 від 10.03.2025 20:00:28 АПК (Глобине) | E30: 231 | H30: 221 | I30: 2335.62 | K30: Д | L30: 7853
A31: Обороти за період та сальдо на кінець | E31: 1953.1 | H31: 24498.15 | K31: Д | L31: 7853
J33: =SUBTOTAL(9,I4:J30) -> 24498.15

Sheet Генплан митний склад
A1: Період | B1: Документ | C1: Аналітика Дт | D1: Аналітика Кт | E1: Дебет | H1: Кредит | K1: Поточне сальдо
E2: Рахунок | H2: Рахунок
A3: 03.04.2025 | B3: Передача малоцінних активів в експлуатацію ІБ00-000149 від 03.04.2025 17:41:40 Списание стоимости малоценных активов | C3: Обл. НДС Виробничий (Глобине-2) Глобине-2 Амортизація ОЗ загальновиробничого призначення | D3: Обл. НДС Замок навісний Надходження товарів і послуг ІБ00-001368 від 28.03.2025 20:00:05 Генплан митний склад (Глобине) | E3: 231 | H3: 221 | I3: 780
A4: Обороти за період та сальдо на кінець | E4: 0 | H4: 780 | L4: 0

Sheet Глобине-2
A1: Період | B1: Документ | C1: Аналітика Дт | D1: Аналітика Кт | E1: Дебет | H1: Кредит | K1: Поточне сальдо
E2: Рахунок | H2: Рахунок
A3: 03.04.2025 | B3: Передача малоцінних активів в експлуатацію ІБ00-000150 від 03.04.2025 17:41:42 Списание стоимости малоценных активов | C3: Обл. НДС Виробничий (Глобине-2) Глобине-2 Амортизація ОЗ загальновиробничого призначення | D3: Обл. НДС Шланг напірн Д=50мм бухта 20м Надходження товарів і послуг ІБ00-000542 від 16.02.2024 10:08:26 Глобине-2 | E3: 231 | H3: 221 | I3: 797.15 | K3: Д | L3: 66366.45
A4: 03.04.2025 | B4: Передача малоцінних активів в експлуатацію ІБ00-000150 від 03.04.2025 17:41:42 Списание стоимости малоценных активов | C4: Обл. НДС Виробничий (Глобине-2) Глобине-2 Амортизація ОЗ загальновиробничого призначення | D4: Обл. НДС Провід ПВС 3*1,5 бухта 100м Надходження товарів і послуг ІБ00-004399 від 19.09.2024 18:10:36 Глобине-2 | E4: 231 | H4: 221 | I4: 2312.3 | K4: Д | L4: 64054.15
A5: 03.04.2025 | B5: Передача малоцінних активів в експлуатацію ІБ00-000150 від 03.04.2025 17:41:42 Списание стоимости малоценных активов | C5: Обл. НДС Виробничий (Глобине-2) Глобине-2 Амортизація ОЗ загальновиробничого призначення | D5: Обл. НДС Костюм "Віват" р.104-108/170-176 Надходження товарів і послуг ІБ00-005042 від 02.10.2024 10:00:00 Глобине-2 | E5: 231 | H5: 221 | I5: 1477.5 | K5: Д | L5: 62576.65
A6: 03.04.2025 | B6: Передача малоцінних активів в експлуатацію ІБ00-000155 від 03.04.2025 17:41:54 Списание стоимости малоценных активов | C6: Обл. НДС Виробничий (Глобине-2) Глобине-2 Амортизація ОЗ загальновиробничого призначення | D6: Обл. НДС Кабель КГ 3*25+1*10 Надходження товарів і послуг ІБ00-005782 від 05.11.2024 20:00:07 Глобине-2 | E6: 231 | H6: 221 | I6: 25507.2 | K6: Д | L6: 37069.45
A7: 09.04.2025 | B7: Надходження товарів і послуг ІБ00-001613 від 09.04.2025 11:00:00 Оприходованы ТМЦ | C7: Обл. НДС Рівень 2000мм Spirit магнітний Надходження товарів і послуг ІБ00-001613 від 09.04.2025 11:00:00 Глобине-2 | D7: Лук'ян Михайло Федорович ФОП 22/08-24-1 от 22.08.2024 (РАХУНКИ)_Глобине-2 Рахунок на оплату постачальника ІБ00-001318 від 09.04.2025 23:59:59 | E7: 221 | F7: 3143.1 | H7: 631 | K7: Д | L7: 40212.55
A8: 09.04.2025 | B8: Надходження товарів і послуг ІБ00-001613 від 09.04.2025 11:00:00 Оприходованы ТМЦ | C8: Обл. НДС Шнур каменяра 1,3 мм*100 м Надходження товарів і послуг ІБ00-001613 від 09.04.2025 11:00:00 Глобине-2 | D8: Лук'ян Михайло Федорович ФОП 22/08-24-1 от 22.08.2024 (РАХУНКИ)_Глобине-2 Рахунок на оплату постачальника ІБ00-001318 від 09.04.2025 23:59:59 | E8: 221 | F8: 1683 | H8: 631 | K8: Д | L8: 41895.55
A9: 09.04.2025 | B9: Надходження товарів і послуг ІБ00-001613 від 09.04.2025 11:00:00 Оприходованы ТМЦ | C9: Обл. НДС Бита Рh2 51мм Надходження товарів і послуг ІБ00-001613 від 09.04.2025 11:00:00 Глобине-2 | D9: Лук'ян Михайло Федорович ФОП 22/08-24-1 от 22.08.2024 (РАХУНКИ)_Глобине-2 Рахунок на оплату постачальника ІБ00-001318 від 09.04.2025 23:59:59 | E9: 221 | F9: 190.5 | H9: 631 | K9: Д | L9: 42086.05
A10: 09.04.2025 | B10: Надходження товарів і послуг ІБ00-001613 від 09.04.2025 11:00:00 Оприходованы ТМЦ | C10: Обл. НДС Подовжувач і магнітний для біт М8*65 д/6гр.гл Надходження товарів і послуг ІБ00-001613 від 09.04.2025 11:00:00 Глобине-2 | D10: Лук'ян Михайло Федорович ФОП 22/08-24-1 от 22.08.2024 (РАХУНКИ)_Глобине-2 Рахунок на оплату постачальника ІБ00-001318 від 09.04.2025 23:59:59 | E10: 221 | F10: 204.25 | H10: 631 | K10: Д | L10: 42290.3
A11: 09.04.2025 | B11: Надходження товарів і послуг ІБ00-001613 від 09.04.2025 11:00:00 Оприходованы ТМЦ | C11: Обл. НДС Рулетка 10 м*25 мм Надходження товарів і послуг ІБ00-001613 від 09.04.2025 11:00:00 Глобине-2 | D11: Лук'ян Михайло Федорович ФОП 22/08-24-1 от 22.08.2024 (РАХУНКИ)_Глобине-2 Рахунок на оплату постачальника ІБ00-001318 від 09.04.2025 23:59:59 | E11: 221 | F11: 990.75 | H11: 631 | K11: Д | L11: 43281.05
A12: 09.04.2025 | B12: Надходження товарів і послуг ІБ00-001613 від 09.04.2025 11:00:00 Оприходованы ТМЦ | C12: Обл. НДС Свердло 13,0мм HSS TiN Надходження товарів і послуг ІБ00-001613 від 09.04.2025 11:00:00 Глобине-2 | D12: Лук'ян Михайло Федорович ФОП 22/08-24-1 от 22.08.2024 (РАХУНКИ)_Глобине-2 Рахунок на оплату постачальника ІБ00-001318 від 09.04.2025 23:59:59 | E12: 221 | F12: 687.6 | H12: 631 | K12: Д | L12: 43968.65
A13: 09.04.2025 | B13: Надходження товарів і послуг ІБ00-001613 від 09.04.2025 11:00:00 Оприходованы ТМЦ | C13: Обл. НДС Наколінники гумові Надходження товарів і послуг ІБ00-001613 від 09.04.2025 11:00:00 Глобине-2 | D13: Лук'ян Михайло Федорович ФОП 22/08-24-1 от 22.08.2024 (РАХУНКИ)_Глобине-2 Рахунок на оплату постачальника ІБ00-001318 від 09.04.2025 23:59:59 | E13: 221 | F13: 1263.4 | H13: 631 | K13: Д | L13: 45232.05
A14: 09.04.2025 | B14: Переміщення товарів ІБ00-000323 від 09.04.2025 11:05:00 Перемещение ТМЦ | C14: Обл. НДС Рівень 2000мм Spirit магнітний Надходження товарів і послуг ІБ00-001613 від 09.04.2025 11:00:00 Котельна (Глобине) | D14: Обл. НДС Рівень 2000мм Spirit магнітний Надходження товарів і послуг ІБ00-001613 від 09.04.2025 11:00:00 Глобине-2 | E14: 221 | H14: 221 | I14: 3143.1 | K14: Д | L14: 42088.95
A15: 09.04.2025 | B15: Переміщення товарів ІБ00-000323 від 09.04.2025 11:05:00 Перемещение ТМЦ | C15: Обл. НДС Шнур каменяра 1,3 мм*100 м Надходження товарів і послуг ІБ00-001613 від 09.04.2025 11:00:00 Котельна (Глобине) | D15: Обл. НДС Шнур каменяра 1,3 мм*100 м Надходження товарів і послуг ІБ00-001613 від 09.04.2025 11:00:00 Глобине-2 | E15: 221 | H15: 221 | I15: 1683 | K15: Д | L15: 40405.95
A16: 09.04.2025 | B16: Переміщення товарів ІБ00-000323 від 09.04.2025 11:05:00 Перемещение ТМЦ | C16: Обл. НДС Бита Рh2 51мм Надходження товарів і послуг ІБ00-001613 від 09.04.2025 11:00:00 Котельна (Глобине) | D16: Обл. НДС Бита Рh2 51мм Надходження товарів і послуг ІБ00-001613 від 09.04.2025 11:00:00 Глобине-2 | E16: 221 | H16: 221 | I16: 190.5 | K16: Д | L16: 40215.45
A17: 09.04.2025 | B17: Переміщення товарів ІБ00-000323 від 09.04.2025 11:05:00 Перемещение ТМЦ | C17: Обл. НДС Подовжувач і магнітний для біт М8*65 д/6гр.гл Надходження товарів і послуг ІБ00-001613 від 09.04.2025 11:00:00 Котельна (Глобине) | D17: Обл. НДС Подовжувач і магнітний для біт М8*65 д/6гр.гл Надходження товарів і послуг ІБ00-001613 від 09.04.2025 11:00:00 Глобине-2 | E17: 221 | H17: 221 | I17: 204.25 | K17: Д | L17: 40011.2
A18: 09.04.2025 | B18: Переміщення товарів ІБ00-000323 від 09.04.2025 11:05:00 Перемещение ТМЦ | C18: Обл. НДС Рулетка 10 м*25 мм Надходження товарів і послуг ІБ00-001613 від 09.04.2025 11:00:00 Котельна (Глобине) | D18: Обл. НДС Рулетка 10 м*25 мм Надходження товарів і послуг ІБ00-001613 від 09.04.2025 11:00:00 Глобине-2 | E18: 221 | H18: 221 | I18: 990.75 | K18: Д | L18: 39020.45
A19: 09.04.2025 | B19: Переміщення товарів ІБ00-000325 від 09.04.2025 11:05:00 Перемещение ТМЦ | C19: Обл. НДС Свердло 13,0мм HSS TiN Надходження товарів і послуг ІБ00-001613 від 09.04.2025 11:00:00 Цех екстракції (Глобине) | D19: Обл. НДС Свердло 13,0мм HSS TiN Надходження товарів і послуг ІБ00-001613 від 09.04.2025 11:00:00 Глобине-2 | E19: 221 | H19: 221 | I19: 687.6 | K19: Д | L19: 38332.85
A20: 09.04.2025 | B20: Переміщення товарів ІБ00-000325 від 09.04.2025 11:05:00 Перемещение ТМЦ | C20: Обл. НДС Наколінники гумові Надходження товарів і послуг ІБ00-001613 від 09.04.2025 11:00:00 Цех екстракції (Глобине) | D20: Обл. НДС Наколінники гумові Надходження товарів і послуг ІБ00-001613 від 09.04.2025 11:00:00 Глобине-2 | E20: 221 | H20: 221 | I20: 1263.4 | K20: Д | L20: 37069.45
A21: 10.04.2025 | B21: Переміщення товарів ІБ00-000313 від 10.04.2025 15:00:00 Перемещение ТМЦ | C21: Обл. НДС Автоматичний вимикач 1р В 16А 6кА Надходження товарів і послуг ІБ00-004458 від 23.09.2024 18:22:19 Глобине-2 | D21: Обл. НДС Автоматичний вимикач 1р В 16А 6кА Надходження товарів і послуг ІБ00-004458 від 23.09.2024 18:22:19 Молоко Вітчизни | E21: 221 | F21: 682.27 | H21: 221 | K21: Д | L21: 37751.72
A22: 10.04.2025 | B22: Переміщення товарів ІБ00-000313 від 10.04.2025 15:00:00 Перемещение ТМЦ | C22: Обл. НДС Автоматичний вимикач 1р С 25А 6кА Надходження товарів і послуг ІБ00-004458 від 23.09.2024 18:22:19 Глобине-2 | D22: Обл. НДС Автоматичний вимикач 1р С 25А 6кА Надходження товарів і послуг ІБ00-004458 від 23.09.2024 18:22:19 Молоко Вітчизни | E22: 221 | F22: 660.56 | H22: 221 | K22: Д | L22: 38412.28
A23: 10.04.2025 | B23: Переміщення товарів ІБ00-000313 від 10.04.2025 15:00:00 Перемещение ТМЦ | C23: Обл. НДС Автоматичний вимикач 1р С 40А 6кА Надходження товарів і послуг ІБ00-004458 від 23.09.2024 18:22:19 Глобине-2 | D23: Обл. НДС Автоматичний вимикач 1р С 40А 6кА Надходження товарів і послуг ІБ00-004458 від 23.09.2024 18:22:19 Молоко Вітчизни | E23: 221 | F23: 156.4 | H23: 221 | K23: Д | L23: 38568.68
A24: 10.04.2025 | B24: Переміщення товарів ІБ00-000313 від 10.04.2025 15:00:00 Перемещение ТМЦ | C24: Обл. НДС Бур 12*250*310 Надходження товарів і послуг ІБ00-004231 від 12.09.2024 18:41:34 Глобине-2 | D24: Обл. НДС Бур 12*250*310 Надходження товарів і послуг ІБ00-004231 від 12.09.2024 18:41:34 Молоко Вітчизни | E24: 221 | F24: 726.45 | H24: 221 | K24: Д | L24: 39295.13
A25: 10.04.2025 | B25: Переміщення товарів ІБ00-000313 від 10.04.2025 15:00:00 Перемещение ТМЦ | C25: Обл. НДС Бур 16*250*310мм SDS Plus Надходження товарів і послуг ІБ00-000579 від 16.02.2024 18:08:40 Глобине-2 | D25: Обл. НДС Бур 16*250*310мм SDS Plus Надходження товарів і послуг ІБ00-000579 від 16.02.2024 18:08:40 Молоко Вітчизни | E25: 221 | F25: 342.9 | H25: 221 | K25: Д | L25: 39638.03
A26: 10.04.2025 | B26: Переміщення товарів ІБ00-000313 від 10.04.2025 15:00:00 Перемещение ТМЦ | C26: Обл. НДС Відбивач плівковий А4 білий Надходження товарів і послуг ІБ00-005586 від 15.10.2024 22:00:12 Глобине-2 | D26: Обл. НДС Відбивач плівковий А4 білий Надходження товарів і послуг ІБ00-005586 від 15.10.2024 22:00:12 Молоко Вітчизни | E26: 221 | F26: 800 | H26: 221 | K26: Д | L26: 40438.03
A27: 10.04.2025 | B27: Переміщення товарів ІБ00-000313 від 10.04.2025 15:00:00 Перемещение ТМЦ | C27: Обл. НДС Відро будівельне 15 л Надходження товарів і послуг ІБ00-004231 від 12.09.2024 18:41:34 Глобине-2 | D27: Обл. НДС Відро будівельне 15 л Надходження товарів і послуг ІБ00-004231 від 12.09.2024 18:41:34 Молоко Вітчизни | E27: 221 | F27: 310.65 | H27: 221 | K27: Д | L27: 40748.68
A28: 10.04.2025 | B28: Переміщення товарів ІБ00-000313 від 10.04.2025 15:00:00 Перемещение ТМЦ | C28: Обл. НДС Відро будівельне 20 л Надходження товарів і послуг ІБ00-001026 від 05.03.2024 18:27:30 Глобине-2 | D28: Обл. НДС Відро будівельне 20 л Надходження товарів і послуг ІБ00-001026 від 05.03.2024 18:27:30 Молоко Вітчизни | E28: 221 | F28: 385.05 | H28: 221 | K28: Д | L28: 41133.73
A29: 10.04.2025 | B29: Переміщення товарів ІБ00-000313 від 10.04.2025 15:00:00 Перемещение ТМЦ | C29: Обл. НДС Вставка зі штуч.хутра в чол.чоботи р.41-42 Надходження товарів і послуг ІБ00-004231 від 12.09.2024 18:41:34 Глобине-2 | D29: Обл. НДС Вставка зі штуч.хутра в чол.чоботи р.41-42 Надходження товарів і послуг ІБ00-004231 від 12.09.2024 18:41:34 Молоко Вітчизни | E29: 221 | F29: 185 | H29: 221 | K29: Д | L29: 41318.73
A30: 10.04.2025 | B30: Переміщення товарів ІБ00-000313 від 10.04.2025 15:00:00 Перемещение ТМЦ | C30: Обл. НДС Вставка зі штуч.хутра в чол.чоботи р.45-46 Надходження товарів і послуг ІБ00-004231 від 12.09.2024 18:41:34 Глобине-2 | D30: Обл. НДС Вставка зі штуч.хутра в чол.чоботи р.45-46 Надходження товарів і послуг ІБ00-004231 від 12.09.2024 18:41:34 Молоко Вітчизни | E30: 221 | F30: 185 | H30: 221 | K30: Д | L30: 41503.73
A31: 10.04.2025 | B31: Переміщення товарів ІБ00-000313 від 10.04.2025 15:00:00 Перемещение ТМЦ | C31: Обл. НДС Держак д/лопати 1,2 м Надходження товарів і послуг ІБ00-004231 від 12.09.2024 18:41:34 Глобине-2 | D31: Обл. НДС Держак д/лопати 1,2 м Надходження товарів і послуг ІБ00-004231 від 12.09.2024 18:41:34 Молоко Вітчизни | E31: 221 | F31: 324 | H31: 221 | K31: Д | L31: 41827.73
A32: 10.04.2025 | B32: Переміщення товарів ІБ00-000313 від 10.04.2025 15:00:00 Перемещение ТМЦ | C32: Обл. НДС Диск пильний 190*30 24 зуб. Надходження товарів і послуг ІБ00-004231 від 12.09.2024 18:41:34 Глобине-2 | D32: Обл. НДС Диск пильний 190*30 24 зуб. Надходження товарів і послуг ІБ00-004231 від 12.09.2024 18:41:34 Молоко Вітчизни | E32: 221 | F32: 545.7 | H32: 221 | K32: Д | L32: 42373.43
... A62: 18.04.2025 | B62: Надходження товарів і послуг ІБ00-001740 від 18.04.2025 11:00:00 Оприходованы ТМЦ | C62: Обл. НДС Змазка компресорна 1л ISO100 Надходження товарів і послуг ІБ00-001740 від 18.04.2025 11:00:00 Глобине-2 | D62: Лук'ян Михайло Федорович ФОП 22/08-24-1 от 22.08.2024 (РАХУНКИ)_Глобине-2 Рахунок на оплату постачальника ІБ00-001400 від 18.04.2025 18:10:00 | E62: 221 | F62: 328.5 | H62: 631 | K62: Д | L62: 103806.23
A63: 18.04.2025 | B63: Переміщення товарів ІБ00-000340 від 18.04.2025 11:05:00 Перемещение ТМЦ | C63: Обл. НДС Вилка пряма з з/к,ІР44 Надходження товарів і послуг ІБ00-001740 від 18.04.2025 11:00:00 СПК (Глобине) | D63: Обл. НДС Вилка пряма з з/к,ІР44 Надходження товарів і послуг ІБ00-001740 від 18.04.2025 11:00:00 Глобине-2 | E63: 221 | H63: 221 | I63: 53.75 | K63: Д | L63: 103752.48
A64: 18.04.2025 | B64: Переміщення товарів ІБ00-000340 від 18.04.2025 11:05:00 Перемещение ТМЦ | C64: Обл. НДС Касета-розетка 3гн, з/к з кришками Омега ІР44 16А Надходження товарів і послуг ІБ00-001740 від 18.04.2025 11:00:00 СПК (Глобине) | D64: Обл. НДС Касета-розетка 3гн, з/к з кришками Омега ІР44 16А Надходження товарів і послуг ІБ00-001740 від 18.04.2025 11:00:00 Глобине-2 | E64: 221 | H64: 221 | I64: 223.2 | K64: Д | L64: 103529.28
A65: 18.04.2025 | B65: Переміщення товарів ІБ00-000340 від 18.04.2025 11:05:00 Перемещение ТМЦ | C65: Обл. НДС Провід ПВС 3*2,5 бухта 100м Надходження товарів і послуг ІБ00-001740 від 18.04.2025 11:00:00 СПК (Глобине) | D65: Обл. НДС Провід ПВС 3*2,5 бухта 100м Надходження товарів і послуг ІБ00-001740 від 18.04.2025 11:00:00 Глобине-2 | E65: 221 | H65: 221 | I65: 4461.45 | K65: Д | L65: 99067.83
A66: 18.04.2025 | B66: Переміщення товарів ІБ00-000340 від 18.04.2025 11:05:00 Перемещение ТМЦ | C66: Обл. НДС Електроди "Моноліт РЦ" 3 мм 2,5кг Надходження товарів і послуг ІБ00-001740 від 18.04.2025 11:00:00 СПК (Глобине) | D66: Обл. НДС Електроди "Моноліт РЦ" 3 мм 2,5кг Надходження товарів і послуг ІБ00-001740 від 18.04.2025 11:00:00 Глобине-2 | E66: 221 | H66: 221 | I66: 2524 | K66: Д | L66: 96543.83
A67: 18.04.2025 | B67: Переміщення товарів ІБ00-000340 від 18.04.2025 11:05:00 Перемещение ТМЦ | C67: Обл. НДС Електроди "Моноліт РЦ" 4 мм уп. 5,0 кг Надходження товарів і послуг ІБ00-001740 від 18.04.2025 11:00:00 СПК (Глобине) | D67: Обл. НДС Електроди "Моноліт РЦ" 4 мм уп. 5,0 кг Надходження товарів і послуг ІБ00-001740 від 18.04.2025 11:00:00 Глобине-2 | E67: 221 | H67: 221 | I67: 12169 | K67: Д | L67: 84374.83
A68: 18.04.2025 | B68: Переміщення товарів ІБ00-000340 від 18.04.2025 11:05:00 Перемещение ТМЦ | C68: Обл. НДС Маска зварювальника Надходження товарів і послуг ІБ00-001740 від 18.04.2025 11:00:00 СПК (Глобине) | D68: Обл. НДС Маска зварювальника Надходження товарів і послуг ІБ00-001740 від 18.04.2025 11:00:00 Глобине-2 | E68: 221 | H68: 221 | I68: 1916.7 | K68: Д | L68: 82458.13
A69: 18.04.2025 | B69: Переміщення товарів ІБ00-000340 від 18.04.2025 11:05:00 Перемещение ТМЦ | C69: Обл. НДС Рулетка 10 м*25 мм Надходження товарів і послуг ІБ00-001740 від 18.04.2025 11:00:00 СПК (Глобине) | D69: Обл. НДС Рулетка 10 м*25 мм Надходження товарів і послуг ІБ00-001740 від 18.04.2025 11:00:00 Глобине-2 | E69: 221 | H69: 221 | I69: 198.15 | K69: Д | L69: 82259.98
...

Sheet Котельна (Глобине)
A1: Період | B1: Документ | C1: Аналітика Дт | D1: Аналітика Кт | E1: Дебет | H1: Кредит | K1: Поточне сальдо
E2: Рахунок | H2: Рахунок
A3: 01.04.2025 | B3: Надходження товарів і послуг ІБ00-001609 від 01.04.2025 23:10:30 Оприходованы ТМЦ | C3: Обл. НДС Костюм "Віват" р.104-108/170-176 Надходження товарів і послуг ІБ00-001609 від 01.04.2025 23:10:30 Котельна (Глобине) | D3: БРАВО-СП ТОВ РАХУНКИ_Глобине-2 Рахунок на оплату постачальника ІБ00-001317 від 31.03.2025 10:00:00 | E3: 221 | F3: 3045 | H3: 631 | K3: Д | L3: 17957.2
A4: 03.04.2025 | B4: Передача малоцінних активів в експлуатацію ІБ00-000146 від 03.04.2025 17:41:29 Списание стоимости малоценных активов | C4: Обл. НДС Виробничий (Глобине-2) Глобине-2 Амортизація ОЗ загальновиробничого призначення | D4: Обл. НДС Круг алмазний по бетону Turbo 230 Надходження товарів і послуг ІБ00-001198 від 21.03.2025 19:26:08 Котельна (Глобине) | E4: 231 | H4: 221 | I4: 1065.9 | K4: Д | L4: 16891.3
A5: 03.04.2025 | B5: Передача малоцінних активів в експлуатацію ІБ00-000146 від 03.04.2025 17:41:29 Списание стоимости малоценных активов | C5: Обл. НДС Виробничий (Глобине-2) Глобине-2 Амортизація ОЗ загальновиробничого призначення | D5: Обл. НДС Маска "малярська пелюстка" Надходження товарів і послуг ІБ00-001046 від 12.03.2025 18:45:25 Котельна (Глобине) | E5: 231 | H5: 221 | I5: 222.5 | K5: Д | L5: 16668.8
A6: 03.04.2025 | B6: Передача малоцінних активів в експлуатацію ІБ00-000146 від 03.04.2025 17:41:29 Списание стоимости малоценных активов | C6: Обл. НДС Виробничий (Глобине-2) Глобине-2 Амортизація ОЗ загальновиробничого призначення | D6: Обл. НДС Стрейч-плівка 23 мікрон 200м (190м), брутто 2,3 кг Надходження товарів і послуг ІБ00-001198 від 21.03.2025 19:26:08 Котельна (Глобине) | E6: 231 | H6: 221 | I6: 193.35 | K6: Д | L6: 16475.45
A7: 03.04.2025 | B7: Передача малоцінних активів в експлуатацію ІБ00-000146 від 03.04.2025 17:41:29 Списание стоимости малоценных активов | C7: Обл. НДС Виробничий (Глобине-2) Глобине-2 Амортизація ОЗ загальновиробничого призначення | D7: Обл. НДС Шпатель 80 мм Надходження товарів і послуг ІБ00-001198 від 21.03.2025 19:26:08 Котельна (Глобине) | E7: 231 | H7: 221 | I7: 100 | K7: Д | L7: 16375.45
A8: 03.04.2025 | B8: Передача малоцінних активів в експлуатацію ІБ00-000146 від 03.04.2025 17:41:29 Списание стоимости малоценных активов | C8: Обл. НДС Виробничий (Глобине-2) Глобине-2 Амортизація ОЗ загальновиробничого призначення | D8: Обл. НДС Шпатель 150 Надходження товарів і послуг ІБ00-001198 від 21.03.2025 19:26:08 Котельна (Глобине) | E8: 231 | H8: 221 | I8: 93.6 | K8: Д | L8: 16281.85
A9: 03.04.2025 | B9: Передача малоцінних активів в експлуатацію ІБ00-000146 від 03.04.2025 17:41:29 Списание стоимости малоценных активов | C9: Обл. НДС Виробничий (Глобине-2) Глобине-2 Амортизація ОЗ загальновиробничого призначення | D9: Обл. НДС Рукавички трикотажні чорні ТМ Vulkan LUX, р.10 Надходження товарів і послуг ІБ00-001198 від 21.03.2025 19:26:08 Котельна (Глобине) | E9: 231 | H9: 221 | I9: 294 | K9: Д | L9: 15987.85
A10: 03.04.2025 | B10: Передача малоцінних активів в експлуатацію ІБ00-000146 від 03.04.2025 17:41:29 Списание стоимости малоценных активов | C10: Обл. НДС Виробничий (Глобине-2) Глобине-2 Амортизація ОЗ загальновиробничого призначення | D10: Обл. НДС Круг відрізний 230*2,5*22 Надходження товарів і послуг ІБ00-001198 від 21.03.2025 19:26:08 Котельна (Глобине) | E10: 231 | H10: 221 | I10: 530.5 | K10: Д | L10: 15457.35
A11: 03.04.2025 | B11: Передача малоцінних активів в експлуатацію ІБ00-000152 від 03.04.2025 17:41:46 Списание стоимости малоценных активов | C11: Обл. НДС Виробничий (Глобине-2) Глобине-2 Амортизація ОЗ загальновиробничого призначення | D11: Обл. НДС Скотч 300 м Надходження товарів і послуг ІБ00-001198 від 21.03.2025 19:26:08 Котельна (Глобине) | E11: 231 | H11: 221 | I11: 64.2 | K11: Д | L11: 15393.15
A12: 03.04.2025 | B12: Передача малоцінних активів в експлуатацію ІБ00-000152 від 03.04.2025 17:41:46 Списание стоимости малоценных активов | C12: Обл. НДС Виробничий (Глобине-2) Глобине-2 Амортизація ОЗ загальновиробничого призначення | D12: Обл. НДС Круг відрізний 230*2,5*22 Надходження товарів і послуг ІБ00-001198 від 21.03.2025 19:26:08 Котельна (Глобине) | E12: 231 | H12: 221 | I12: 530.5 | K12: Д | L12: 14862.65
A13: 03.04.2025 | B13: Передача малоцінних активів в експлуатацію ІБ00-000152 від 03.04.2025 17:41:46 Списание стоимости малоценных активов | C13: Обл. НДС Виробничий (Глобине-2) Глобине-2 Амортизація ОЗ загальновиробничого призначення | D13: Обл. НДС Рукавиці трикотажні з ПВХ Надходження товарів і послуг ІБ00-001431 від 31.03.2025 11:59:59 Котельна (Глобине) | E13: 231 | H13: 221 | I13: 294 | K13: Д | L13: 14568.65
A14: 03.04.2025 | B14: Передача малоцінних активів в експлуатацію ІБ00-000152 від 03.04.2025 17:41:46 Списание стоимости малоценных активов | C14: Обл. НДС Виробничий (Глобине-2) Глобине-2 Амортизація ОЗ загальновиробничого призначення | D14: Обл. НДС Рукавички скло/камінь черв з рифл гум надол р.10 Надходження товарів і послуг ІБ00-001431 від 31.03.2025 11:59:59 Котельна (Глобине) | E14: 231 | H14: 221 | I14: 151 | K14: Д | L14: 14417.65
A15: 09.04.2025 | B15: Переміщення товарів ІБ00-000323 від 09.04.2025 11:05:00 Перемещение ТМЦ | C15: Обл. НДС Рівень 2000мм Spirit магнітний Надходження товарів і послуг ІБ00-001613 від 09.04.2025 11:00:00 Котельна (Глобине) | D15: Обл. НДС Рівень 2000мм Spirit магнітний Надходження товарів і послуг ІБ00-001613 від 09.04.2025 11:00:00 Глобине-2 | E15: 221 | F15: 3143.1 | H15: 221 | K15: Д | L15: 17560.75
A16: 09.04.2025 | B16: Переміщення товарів ІБ00-000323 від 09.04.2025 11:05:00 Перемещение ТМЦ | C16: Обл. НДС Шнур каменяра 1,3 мм*100 м Надходження товарів і послуг ІБ00-001613 від 09.04.2025 11:00:00 Котельна (Глобине) | D16: Обл. НДС Шнур каменяра 1,3 мм*100 м Надходження товарів і послуг ІБ00-001613 від 09.04.2025 11:00:00 Глобине-2 | E16: 221 | F16: 1683 | H16: 221 | K16: Д | L16: 19243.75
A17: 09.04.2025 | B17: Переміщення товарів ІБ00-000323 від 09.04.2025 11:05:00 Перемещение ТМЦ | C17: Обл. НДС Бита Рh2 51мм Надходження товарів і послуг ІБ00-001613 від 09.04.2025 11:00:00 Котельна (Глобине) | D17: Обл. НДС Бита Рh2 51мм Надходження товарів і послуг ІБ00-001613 від 09.04.2025 11:00:00 Глобине-2 | E17: 221 | F17: 190.5 | H17: 221 | K17: Д | L17: 19434.25
A18: 09.04.2025 | B18: Переміщення товарів ІБ00-000323 від 09.04.2025 11:05:00 Перемещение ТМЦ | C18: Обл. НДС Подовжувач і магнітний для біт М8*65 д/6гр.гл Надходження товарів і послуг ІБ00-001613 від 09.04.2025 11:00:00 Котельна (Глобине) | D18: Обл. НДС Подовжувач і магнітний для біт М8*65 д/6гр.гл Надходження товарів і послуг ІБ00-001613 від 09.04.2025 11:00:00 Глобине-2 | E18: 221 | F18: 204.25 | H18: 221 | K18: Д | L18: 19638.5
A19: 09.04.2025 | B19: Переміщення товарів ІБ00-000323 від 09.04.2025 11:05:00 Перемещение ТМЦ | C19: Обл. НДС Рулетка 10 м*25 мм Надходження товарів і послуг ІБ00-001613 від 09.04.2025 11:00:00 Котельна (Глобине) | D19: Обл. НДС Рулетка 10 м*25 мм Надходження товарів і послуг ІБ00-001613 від 09.04.2025 11:00:00 Глобине-2 | E19: 221 | F19: 990.75 | H19: 221 | K19: Д | L19: 20629.25
A20: 29.04.2025 | B20: Передача малоцінних активів в експлуатацію ІБ00-000179 від 29.04.2025 16:19:37 Списание стоимости малоценных активов | C20: Обл. НДС Виробничий (Глобине-2) Глобине-2 Амортизація ОЗ загальновиробничого призначення | D20: Обл. НДС Распіратор FFP2 з клапаном Надходження товарів і послуг ІБ00-001431 від 31.03.2025 11:59:59 Котельна (Глобине) | E20: 231 | H20: 221 | I20: 167 | K20: Д | L20: 20462.25
A21: 29.04.2025 | B21: Передача малоцінних активів в експлуатацію ІБ00-000179 від 29.04.2025 16:19:37 Списание стоимости малоценных активов | C21: Обл. НДС Виробничий (Глобине-2) Глобине-2 Амортизація ОЗ загальновиробничого призначення | D21: Обл. НДС Рулетка 10 м*25 мм Надходження товарів і послуг ІБ00-001613 від 09.04.2025 11:00:00 Котельна (Глобине) | E21: 231 | H21: 221 | I21: 396.3 | K21: Д | L21: 20065.95
A22: 29.04.2025 | B22: Передача малоцінних активів в експлуатацію ІБ00-000179 від 29.04.2025 16:19:37 Списание стоимости малоценных активов | C22: Обл. НДС Виробничий (Глобине-2) Глобине-2 Амортизація ОЗ загальновиробничого призначення | D22: Обл. НДС Шнур каменяра 1,3 мм*100 м Надходження товарів і послуг ІБ00-001613 від 09.04.2025 11:00:00 Котельна (Глобине) | E22: 231 | H22: 221 | I22: 504.9 | K22: Д | L22: 19561.05
A23: 30.04.2025 | B23: Передача малоцінних активів в експлуатацію ІБ00-000204 від 30.04.2025 10:00:00 Списание стоимости малоценных активов | C23: Обл. НДС Виробничий (Глобине-2) Глобине-2 Амортизація ОЗ загальновиробничого призначення | D23: Обл. НДС Бита Рh2 51мм Надходження товарів і послуг ІБ00-001613 від 09.04.2025 11:00:00 Котельна (Глобине) | E23: 231 | H23: 221 | I23: 190.5 | K23: Д | L23: 19370.55
A24: 30.04.2025 | B24: Передача малоцінних активів в експлуатацію ІБ00-000204 від 30.04.2025 10:00:00 Списание стоимости малоценных активов | C24: Обл. НДС Виробничий (Глобине-2) Глобине-2 Амортизація ОЗ загальновиробничого призначення | D24: Обл. НДС Головка удлинен 3/4" 30мм Надходження товарів і послуг ІБ00-001375 від 28.03.2025 20:00:12 Котельна (Глобине) | E24: 231 | H24: 221 | I24: 804.05 | K24: Д | L24: 18566.5
A25: 30.04.2025 | B25: Передача малоцінних активів в експлуатацію ІБ00-000204 від 30.04.2025 10:00:00 Списание стоимости малоценных активов | C25: Обл. НДС Виробничий (Глобине-2) Глобине-2 Амортизація ОЗ загальновиробничого призначення | D25: Обл. НДС Рівень 2000мм Spirit магнітний Надходження товарів і послуг ІБ00-001613 від 09.04.2025 11:00:00 Котельна (Глобине) | E25: 231 | H25: 221 | I25: 1571.55 | K25: Д | L25: 16994.95
A26: 30.04.2025 | B26: Передача малоцінних активів в експлуатацію ІБ00-000204 від 30.04.2025 10:00:00 Списание стоимости малоценных активов | C26: Обл. НДС Виробничий (Глобине-2) Глобине-2 Амортизація ОЗ загальновиробничого призначення | D26: Обл. НДС Рулетка 10 м*25 мм Надходження товарів і послуг ІБ00-001613 від 09.04.2025 11:00:00 Котельна (Глобине) | E26: 231 | H26: 221 | I26: 594.45 | K26: Д | L26: 16400.5
A27: 30.04.2025 | B27: Передача малоцінних активів в експлуатацію ІБ00-000205 від 30.04.2025 10:00:00 Списание стоимости малоценных активов | C27: Обл. НДС Виробничий (Глобине-2) Глобине-2 Амортизація ОЗ загальновиробничого призначення | D27: Обл. НДС Патрон монтаж. 6,8*11 мм червоні Надходження товарів і послуг ІБ00-000506 від 04.02.2025 17:50:27 Котельна (Глобине) | E27: 231 | H27: 221 | I27: 3591.68 | K27: Д | L27: 12808.82
A28: 30.04.2025 | B28: Передача малоцінних активів в експлуатацію ІБ00-000207 від 30.04.2025 10:00:00 Списание стоимости малоценных активов | C28: Обл. НДС Виробничий (Глобине-2) Глобине-2 Амортизація ОЗ загальновиробничого призначення | D28: Обл. НДС Подовжувач і магнітний для біт М8*65 д/6гр.гл Надходження товарів і послуг ІБ00-001613 від 09.04.2025 11:00:00 Котельна (Глобине) | E28: 231 | H28: 221 | I28: 204.25 | K28: Д | L28: 12604.57
A29: 30.04.2025 | B29: Передача малоцінних активів в експлуатацію ІБ00-000207 від 30.04.2025 10:00:00 Списание стоимости малоценных активов | C29: Обл. НДС Виробничий (Глобине-2) Глобине-2 Амортизація ОЗ загальновиробничого призначення | D29: Обл. НДС Рівень 2000мм Spirit магнітний Надходження товарів і послуг ІБ00-001613 від 09.04.2025 11:00:00 Котельна (Глобине) | E29: 231 | H29: 221 | I29: 1571.55 | K29: Д | L29: 11033.02
A30: 30.04.2025 | B30: Передача малоцінних активів в експлуатацію ІБ00-000208 від 30.04.2025 23:59:48 Списание стоимости малоценных активов | C30: Обл. НДС Виробничий (Глобине-2) Глобине-2 Амортизація ОЗ загальновиробничого призначення | D30: Обл. НДС Черевики з метноском р 43 Надходження товарів і послуг ІБ00-001202 від 14.03.2025 17:51:05 Котельна (Глобине) | E30: 231 | H30: 221 | I30: 988.35 | K30: Д | L30: 10044.67
A31: Обороти за період та сальдо на кінець | E31: 9256.6 | H31: 14124.13 | K31: Д | L31: 10044.67
J33: =SUBTOTAL(9,I4:J30) -> 14124.13

Sheet Насосна Градирня
A1: Період | B1: Документ | C1: Аналітика Дт | D1: Аналітика Кт | E1: Дебет | H1: Кредит | K1: Поточне сальдо
E2: Рахунок | H2: Рахунок
A3: 01.04.2025 | B3: Надходження товарів і послуг ІБ00-001610 від 01.04.2025 23:10:31 Оприходованы ТМЦ | C3: Обл. НДС Костюм "Віват" р.104-108/170-176 Надходження товарів і послуг ІБ00-001610 від 01.04.2025 23:10:31 Насосна Градирня (Глобине) | D3: БРАВО-СП ТОВ РАХУНКИ_Глобине-2 Рахунок на оплату постачальника ІБ00-001317 від 31.03.2025 10:00:00 | E3: 221 | F3: 3045 | H3: 631 | K3: Д | L3: 3963.8
A4: 04.04.2025 | B4: Надходження товарів і послуг ІБ00-001433 від 04.04.2025 11:24:02 Оприходованы ТМЦ | C4: Обл. НДС Валик малярний Надходження товарів і послуг ІБ00-001433 від 04.04.2025 11:24:02 Насосна Градирня (Глобине) | D4: АЛЬЦЕСТ ПАТ Рахунки_Глобине-2 Рахунок на оплату постачальника ІБ00-001134 від 03.04.2025 10:00:00 | E4: 221 | F4: 110.25 | H4: 631 | K4: Д | L4: 4074.05
A5: 04.04.2025 | B5: Надходження товарів і послуг ІБ00-001433 від 04.04.2025 11:24:02 Оприходованы ТМЦ | C5: Обл. НДС Ручка для валика 6х100 Надходження товарів і послуг ІБ00-001433 від 04.04.2025 11:24:02 Насосна Градирня (Глобине) | D5: АЛЬЦЕСТ ПАТ Рахунки_Глобине-2 Рахунок на оплату постачальника ІБ00-001134 від 03.04.2025 10:00:00 | E5: 221 | F5: 75.75 | H5: 631 | K5: Д | L5: 4149.8
A6: 04.04.2025 | B6: Надходження товарів і послуг ІБ00-001433 від 04.04.2025 11:24:02 Оприходованы ТМЦ | C6: Обл. НДС Пензель флейцевий Надходження товарів і послуг ІБ00-001433 від 04.04.2025 11:24:02 Насосна Градирня (Глобине) | D6: АЛЬЦЕСТ ПАТ Рахунки_Глобине-2 Рахунок на оплату постачальника ІБ00-001134 від 03.04.2025 10:00:00 | E6: 221 | F6: 72 | H6: 631 | K6: Д | L6: 4221.8
A7: 30.04.2025 | B7: Передача малоцінних активів в експлуатацію ІБ00-000196 від 30.04.2025 23:59:24 Списание стоимости малоценных активов | C7: Обл. НДС Виробничий (Глобине-2) Глобине-2 Амортизація ОЗ загальновиробничого призначення | D7: Обл. НДС Костюм "Віват" р.104-108/170-176 Надходження товарів і послуг ІБ00-001610 від 01.04.2025 23:10:31 Насосна Градирня (Глобине) | E7: 231 | H7: 221 | I7: 3045 | K7: Д | L7: 1176.8
A8: 30.04.2025 | B8: Передача малоцінних активів в експлуатацію ІБ00-000198 від 30.04.2025 23:59:30 Списание стоимости малоценных активов | C8: Обл. НДС Виробничий (Глобине-2) Глобине-2 Амортизація ОЗ загальновиробничого призначення | D8: Обл. НДС Рукавиці трикотажні з ПВХ Надходження товарів і послуг ІБ00-001431 від 31.03.2025 11:59:59 Насосна Градирня (Глобине) | E8: 231 | H8: 221 | I8: 294 | K8: Д | L8: 882.8
A9: 30.04.2025 | B9: Передача малоцінних активів в експлуатацію ІБ00-000198 від 30.04.2025 23:59:30 Списание стоимости малоценных активов | C9: Обл. НДС Виробничий (Глобине-2) Глобине-2 Амортизація ОЗ загальновиробничого призначення | D9: Обл. НДС Рукавички скло/камінь черв з рифл гум надол р.10 Надходження товарів і послуг ІБ00-001431 від 31.03.2025 11:59:59 Насосна Градирня (Глобине) | E9: 231 | H9: 221 | I9: 151 | K9: Д | L9: 731.8
A10: 30.04.2025 | B10: Передача малоцінних активів в експлуатацію ІБ00-000198 від 30.04.2025 23:59:30 Списание стоимости малоценных активов | C10: Обл. НДС Виробничий (Глобине-2) Глобине-2 Амортизація ОЗ загальновиробничого призначення | D10: Обл. НДС Ручка для валика 6х100 Надходження товарів і послуг ІБ00-001433 від 04.04.2025 11:24:02 Насосна Градирня (Глобине) | E10: 231 | H10: 221 | I10: 75.75 | K10: Д | L10: 656.05
A11: 30.04.2025 | B11: Передача малоцінних активів в експлуатацію ІБ00-000198 від 30.04.2025 23:59:30 Списание стоимости малоценных активов | C11: Обл. НДС Виробничий (Глобине-2) Глобине-2 Амортизація ОЗ загальновиробничого призначення | D11: Обл. НДС Валик малярний Надходження товарів і послуг ІБ00-001433 від 04.04.2025 11:24:02 Насосна Градирня (Глобине) | E11: 231 | H11: 221 | I11: 110.25 | K11: Д | L11: 545.8
A12: 30.04.2025 | B12: Передача малоцінних активів в експлуатацію ІБ00-000199 від 30.04.2025 23:59:35 Списание стоимости малоценных активов | C12: Обл. НДС Виробничий (Глобине-2) Глобине-2 Амортизація ОЗ загальновиробничого призначення | D12: Обл. НДС Пензель 50мм Надходження товарів і послуг ІБ00-001431 від 31.03.2025 11:59:59 Насосна Градирня (Глобине) | E12: 231 | H12: 221 | I12: 136.8 | K12: Д | L12: 409
A13: 30.04.2025 | B13: Передача малоцінних активів в експлуатацію ІБ00-000199 від 30.04.2025 23:59:35 Списание стоимости малоценных активов | C13: Обл. НДС Виробничий (Глобине-2) Глобине-2 Амортизація ОЗ загальновиробничого призначення | D13: Обл. НДС Пензель плаский Євро 80мм пластик.ручка Надходження товарів і послуг ІБ00-001198 від 21.03.2025 19:26:08 Насосна Градирня (Глобине) | E13: 231 | H13: 221 | I13: 170 | K13: Д | L13: 239
A14: 30.04.2025 | B14: Передача малоцінних активів в експлуатацію ІБ00-000199 від 30.04.2025 23:59:35 Списание стоимости малоценных активов | C14: Обл. НДС Виробничий (Глобине-2) Глобине-2 Амортизація ОЗ загальновиробничого призначення | D14: Обл. НДС Пензель флейцевий Надходження товарів і послуг ІБ00-001433 від 04.04.2025 11:24:02 Насосна Градирня (Глобине) | E14: 231 | H14: 221 | I14: 72 | K14: Д | L14: 167
A15: 30.04.2025 | B15: Передача малоцінних активів в експлуатацію ІБ00-000199 від 30.04.2025 23:59:35 Списание стоимости малоценных активов | C15: Обл. НДС Виробничий (Глобине-2) Глобине-2 Амортизація ОЗ загальновиробничого призначення | D15: Обл. НДС Распіратор FFP2 з клапаном Надходження товарів і послуг ІБ00-001431 від 31.03.2025 11:59:59 Насосна Градирня (Глобине) | E15: 231 | H15: 221 | I15: 167
A16: Обороти за період та сальдо на кінець | E16: 3303 | H16: 4221.8 | L16: 0
J18: =SUBTOTAL(9,I7:J15) -> 4221.8

Sheet Підготовчі роботи
A1: Період | B1: Документ | C1: Аналітика Дт | D1: Аналітика Кт | E1: Дебет | H1: Кредит | K1: Поточне сальдо
E2: Рахунок | H2: Рахунок
A3: 01.04.2025 | B3: Надходження товарів і послуг ІБ00-001800 від 01.04.2025 11:00:00 Оприходованы ТМЦ (Зачет аванса поставщику) | C3: Обл. НДС Замок навісний Надходження товарів і послуг ІБ00-001800 від 01.04.2025 11:00:00 Підготовчі роботи та тимчасові споруди (Глобине) | D3: Дудкін О.В. ФОП РАХУНКИ_Глобине-2 Рахунок на оплату постачальника ІБ00-004787 від 01.11.2024 20:00:52 | E3: 221 | F3: 260 | H3: 631 | K3: Д | L3: 4264.2
A4: 01.04.2025 | B4: Надходження товарів і послуг ІБ00-001800 від 01.04.2025 11:00:00 Оприходованы ТМЦ (Зачет аванса поставщику) | C4: Обл. НДС Замок навісний Надходження товарів і послуг ІБ00-001800 від 01.04.2025 11:00:00 Підготовчі роботи та тимчасові споруди (Глобине) | D4: Дудкін О.В. ФОП РАХУНКИ_Глобине-2 Рахунок на оплату постачальника ІБ00-004787 від 01.11.2024 20:00:52 | E4: 221 | F4: 200 | H4: 631 | K4: Д | L4: 4464.2
A5: 30.04.2025 | B5: Передача малоцінних активів в експлуатацію ІБ00-000210 від 30.04.2025 10:59:54 Списание стоимости малоценных активов | C5: Обл. НДС Виробничий (Глобине-2) Глобине-2 Амортизація ОЗ загальновиробничого призначення | D5: Обл. НДС Cвітильник стельовий світлодіодний ENERLIGHT 40Вт 4000К Надходження товарів і послуг ІБ00-005751 від 01.11.2024 19:58:27 Підготовчі роботи та тимчасові споруди (Глобине) | E5: 231 | H5: 221 | I5: 445.6 | K5: Д | L5: 4018.6
A6: 30.04.2025 | B6: Передача малоцінних активів в експлуатацію ІБ00-000210 від 30.04.2025 10:59:54 Списание стоимости малоценных активов | C6: Обл. НДС Виробничий (Глобине-2) Глобине-2 Амортизація ОЗ загальновиробничого призначення | D6: Обл. НДС Вилка пряма з з/к,ІР44 Надходження товарів і послуг ІБ00-001198 від 21.03.2025 19:26:08 Підготовчі роботи та тимчасові споруди (Глобине) | E6: 231 | H6: 221 | I6: 430 | K6: Д | L6: 3588.6
A7: 30.04.2025 | B7: Передача малоцінних активів в експлуатацію ІБ00-000210 від 30.04.2025 10:59:54 Списание стоимости малоценных активов | C7: Обл. НДС Виробничий (Глобине-2) Глобине-2 Амортизація ОЗ загальновиробничого призначення | D7: Обл. НДС Замок навісний Надходження товарів і послуг ІБ00-001800 від 01.04.2025 11:00:00 Підготовчі роботи та тимчасові споруди (Глобине) | E7: 231 | H7: 221 | I7: 460 | K7: Д | L7: 3128.6
A8: 30.04.2025 | B8: Передача малоцінних активів в експлуатацію ІБ00-000210 від 30.04.2025 10:59:54 Списание стоимости малоценных активов | C8: Обл. НДС Виробничий (Глобине-2) Глобине-2 Амортизація ОЗ загальновиробничого призначення | D8: Обл. НДС Ізоляційна стрічка 0,18*0,19мм, 20 м Надходження товарів і послуг ІБ00-001198 від 21.03.2025 19:26:08 Підготовчі роботи та тимчасові споруди (Глобине) | E8: 231 | H8: 221 | I8: 201.9 | K8: Д | L8: 2926.7
A9: 30.04.2025 | B9: Передача малоцінних активів в експлуатацію ІБ00-000210 від 30.04.2025 10:59:54 Списание стоимости малоценных активов | C9: Обл. НДС Виробничий (Глобине-2) Глобине-2 Амортизація ОЗ загальновиробничого призначення | D9: Обл. НДС Касета-розетка 3гн, з/к з кришками Омега ІР44 16А Надходження товарів і послуг ІБ00-001198 від 21.03.2025 19:26:08 Підготовчі роботи та тимчасові споруди (Глобине) | E9: 231 | H9: 221 | I9: 2232 | K9: Д | L9: 694.7
A10: 30.04.2025 | B10: Передача малоцінних активів в експлуатацію ІБ00-000210 від 30.04.2025 10:59:54 Списание стоимости малоценных активов | C10: Обл. НДС Виробничий (Глобине-2) Глобине-2 Амортизація ОЗ загальновиробничого призначення | D10: Обл. НДС Світильник лінійний світлодіод ІР65 36W 6500K (1.2m) SLIM Надходження товарів і послуг ІБ00-005751 від 01.11.2024 19:58:27 Підготовчі роботи та тимчасові споруди (Глобине) | E10: 231 | H10: 221 | I10: 694.7
A11: Обороти за період та сальдо на кінець | E11: 460 | H11: 4464.2 | L11: 0
J14: =SUBTOTAL(9,I5:J10) -> 4464.2

Sheet Пожежений резервуар
A1: Період | B1: Документ | C1: Аналітика Дт | D1: Аналітика Кт | E1: Дебет | H1: Кредит | K1: Поточне сальдо
E2: Рахунок | H2: Рахунок
A3: 18.04.2025 | B3: Переміщення товарів ІБ00-000342 від 18.04.2025 11:05:00 Перемещение ТМЦ | C3: Обл. НДС Вилка пряма з з/к,ІР44 Надходження товарів і послуг ІБ00-001740 від 18.04.2025 11:00:00 Пожежений резервуар (Глобине) | D3: Обл. НДС Вилка пряма з з/к,ІР44 Надходження товарів і послуг ІБ00-001740 від 18.04.2025 11:00:00 Глобине-2 | E3: 221 | F3: 268.75 | H3: 221 | K3: Д | L3: 1168.75
A4: 18.04.2025 | B4: Переміщення товарів ІБ00-000342 від 18.04.2025 11:05:00 Перемещение ТМЦ | C4: Обл. НДС Касета-розетка 3гн, з/к з кришками Омега ІР44 16А Надходження товарів і послуг ІБ00-001740 від 18.04.2025 11:00:00 Пожежений резервуар (Глобине) | D4: Обл. НДС Касета-розетка 3гн, з/к з кришками Омега ІР44 16А Надходження товарів і послуг ІБ00-001740 від 18.04.2025 11:00:00 Глобине-2 | E4: 221 | F4: 1116 | H4: 221 | K4: Д | L4: 2284.75
A5: 18.04.2025 | B5: Переміщення товарів ІБ00-000342 від 18.04.2025 11:05:00 Перемещение ТМЦ | C5: Обл. НДС Провід ПВС 3*2,5 бухта 100м Надходження товарів і послуг ІБ00-001740 від 18.04.2025 11:00:00 Пожежений резервуар (Глобине) | D5: Обл. НДС Провід ПВС 3*2,5 бухта 100м Надходження товарів і послуг ІБ00-001740 від 18.04.2025 11:00:00 Глобине-2 | E5: 221 | F5: 4461.45 | H5: 221 | K5: Д | L5: 6746.2
A6: 18.04.2025 | B6: Переміщення товарів ІБ00-000342 від 18.04.2025 11:05:00 Перемещение ТМЦ | C6: Обл. НДС Круг відрізний 230*2.5*22 увігнутий Надходження товарів і послуг ІБ00-001740 від 18.04.2025 11:00:00 Пожежений резервуар (Глобине) | D6: Обл. НДС Круг відрізний 230*2.5*22 увігнутий Надходження товарів і послуг ІБ00-001740 від 18.04.2025 11:00:00 Глобине-2 | E6: 221 | F6: 1410 | H6: 221 | K6: Д | L6: 8156.2
A7: 30.04.2025 | B7: Передача малоцінних активів в експлуатацію ІБ00-000203 від 30.04.2025 10:00:00 Списание стоимости малоценных активов | C7: Обл. НДС Виробничий (Глобине-2) Глобине-2 Амортизація ОЗ загальновиробничого призначення | D7: Обл. НДС Вилка пряма з з/к,ІР44 Надходження товарів і послуг ІБ00-001740 від 18.04.2025 11:00:00 Пожежений резервуар (Глобине) | E7: 231 | H7: 221 | I7: 268.75 | K7: Д | L7: 7887.45
A8: 30.04.2025 | B8: Передача малоцінних активів в експлуатацію ІБ00-000203 від 30.04.2025 10:00:00 Списание стоимости малоценных активов | C8: Обл. НДС Виробничий (Глобине-2) Глобине-2 Амортизація ОЗ загальновиробничого призначення | D8: Обл. НДС Електрод плазменний до Р80 Надходження товарів і послуг ІБ00-001295 від 28.03.2025 18:00:01 Пожежений резервуар (Глобине) | E8: 231 | H8: 221 | I8: 470 | K8: Д | L8: 7417.45
A9: 30.04.2025 | B9: Передача малоцінних активів в експлуатацію ІБ00-000203 від 30.04.2025 10:00:00 Списание стоимости малоценных активов | C9: Обл. НДС Виробничий (Глобине-2) Глобине-2 Амортизація ОЗ загальновиробничого призначення | D9: Обл. НДС Касета-розетка 3гн, з/к з кришками Омега ІР44 16А Надходження товарів і послуг ІБ00-001740 від 18.04.2025 11:00:00 Пожежений резервуар (Глобине) | E9: 231 | H9: 221 | I9: 1116 | K9: Д | L9: 6301.45
A10: 30.04.2025 | B10: Передача малоцінних активів в експлуатацію ІБ00-000203 від 30.04.2025 10:00:00 Списание стоимости малоценных активов | C10: Обл. НДС Виробничий (Глобине-2) Глобине-2 Амортизація ОЗ загальновиробничого призначення | D10: Обл. НДС Круг відрізний 230*2.5*22 увігнутий Надходження товарів і послуг ІБ00-001740 від 18.04.2025 11:00:00 Пожежений резервуар (Глобине) | E10: 231 | H10: 221 | I10: 1410 | K10: Д | L10: 4891.45
A11: 30.04.2025 | B11: Передача малоцінних активів в експлуатацію ІБ00-000203 від 30.04.2025 10:00:00 Списание стоимости малоценных активов | C11: Обл. НДС Виробничий (Глобине-2) Глобине-2 Амортизація ОЗ загальновиробничого призначення | D11: Обл. НДС Сопло до плазмотрону Р-80-1,7 Надходження товарів і послуг ІБ00-001295 від 28.03.2025 18:00:01 Пожежений резервуар (Глобине) | E11: 231 | H11: 221 | I11: 430 | K11: Д | L11: 4461.45
A12: 30.04.2025 | B12: Передача малоцінних активів в експлуатацію ІБ00-000203 від 30.04.2025 10:00:00 Списание стоимости малоценных активов | C12: Обл. НДС Виробничий (Глобине-2) Глобине-2 Амортизація ОЗ загальновиробничого призначення | D12: Обл. НДС Провід ПВС 3*2,5 бухта 100м Надходження товарів і послуг ІБ00-001740 від 18.04.2025 11:00:00 Пожежений резервуар (Глобине) | E12: 231 | H12: 221 | I12: 4461.45
A13: Обороти за період та сальдо на кінець | E13: 7256.2 | H13: 8156.2 | L13: 0
J15: =SUBTOTAL(9,I7:J12) -> 8156.2

Sheet Пункт фасування
A1: Період | B1: Документ | C1: Аналітика Дт | D1: Аналітика Кт | E1: Дебет | H1: Кредит | K1: Поточне сальдо
E2: Рахунок | H2: Рахунок
A3: 03.04.2025 | B3: Передача малоцінних активів в експлуатацію ІБ00-000151 від 03.04.2025 16:36:23 Списание стоимости малоценных активов | C3: Обл. НДС Виробничий (Глобине-2) Глобине-2 Амортизація ОЗ загальновиробничого призначення | D3: Обл. НДС Електроди "Моноліт РЦ" 4 мм уп. 5,0 кг Надходження товарів і послуг ІБ00-000711 від 18.02.2025 20:00:44 Пункт фасування та зберігання в бігбегах (Глобине) | E3: 231 | H3: 221 | I3: 1216.9 | K3: Д | L3: 54112.25
A4: 03.04.2025 | B4: Передача малоцінних активів в експлуатацію ІБ00-000151 від 03.04.2025 16:36:23 Списание стоимости малоценных активов | C4: Обл. НДС Виробничий (Глобине-2) Глобине-2 Амортизація ОЗ загальновиробничого призначення | D4: Обл. НДС Краги зварювальника Надходження товарів і послуг ІБ00-001198 від 21.03.2025 19:26:08 Пункт фасування та зберігання в бігбегах (Глобине) | E4: 231 | H4: 221 | I4: 257.9 | K4: Д | L4: 53854.35
A5: 03.04.2025 | B5: Передача малоцінних активів в експлуатацію ІБ00-000151 від 03.04.2025 16:36:23 Списание стоимости малоценных активов | C5: Обл. НДС Виробничий (Глобине-2) Глобине-2 Амортизація ОЗ загальновиробничого призначення | D5: Обл. НДС Круг відрізний 230*2,5*22 Надходження товарів і послуг ІБ00-001198 від 21.03.2025 19:26:08 Пункт фасування та зберігання в бігбегах (Глобине) | E5: 231 | H5: 221 | I5: 636.6 | K5: Д | L5: 53217.75
A6: 03.04.2025 | B6: Передача малоцінних активів в експлуатацію ІБ00-000151 від 03.04.2025 16:36:23 Списание стоимости малоценных активов | C6: Обл. НДС Виробничий (Глобине-2) Глобине-2 Амортизація ОЗ загальновиробничого призначення | D6: Обл. НДС Круг відрізний по металу 125*1,6*22,2 Надходження товарів і послуг ІБ00-001198 від 21.03.2025 19:26:08 Пункт фасування та зберігання в бігбегах (Глобине) | E6: 231 | H6: 221 | I6: 145.25 | K6: Д | L6: 53072.5
A7: 03.04.2025 | B7: Передача малоцінних активів в експлуатацію ІБ00-000151 від 03.04.2025 16:36:23 Списание стоимости малоценных активов | C7: Обл. НДС Виробничий (Глобине-2) Глобине-2 Амортизація ОЗ загальновиробничого призначення | D7: Обл. НДС Рукавички трикотажні чорні ТМ Vulkan LUX, р.10 Надходження товарів і послуг ІБ00-001198 від 21.03.2025 19:26:08 Пункт фасування та зберігання в бігбегах (Глобине) | E7: 231 | H7: 221 | I7: 294 | K7: Д | L7: 52778.5
A8: 03.04.2025 | B8: Передача малоцінних активів в експлуатацію ІБ00-000151 від 03.04.2025 16:36:23 Списание стоимости малоценных активов | C8: Обл. НДС Виробничий (Глобине-2) Глобине-2 Амортизація ОЗ загальновиробничого призначення | D8: Обл. НДС Рулетка 5 м*19 мм Надходження товарів і послуг ІБ00-001198 від 21.03.2025 19:26:08 Пункт фасування та зберігання в бігбегах (Глобине) | E8: 231 | H8: 221 | I8: 95.85 | K8: Д | L8: 52682.65
A9: 03.04.2025 | B9: Передача малоцінних активів в експлуатацію ІБ00-000151 від 03.04.2025 16:36:23 Списание стоимости малоценных активов | C9: Обл. НДС Виробничий (Глобине-2) Глобине-2 Амортизація ОЗ загальновиробничого призначення | D9: Обл. НДС Щітка чашкова 65мм для УШМ, М14 гофров дріт Надходження товарів і послуг ІБ00-001198 від 21.03.2025 19:26:08 Пункт фасування та зберігання в бігбегах (Глобине) | E9: 231 | H9: 221 | I9: 625 | K9: Д | L9: 52057.65
A10: 09.04.2025 | B10: Надходження товарів і послуг ІБ00-001713 від 09.04.2025 12:59:59 Оприходованы ТМЦ | C10: Обл. НДС Жилет сигнальний Надходження товарів і послуг ІБ00-001713 від 09.04.2025 12:59:59 Пункт фасування та зберігання в бігбегах (Глобине) | D10: БРАВО-СП ТОВ РАХУНКИ_Глобине-2 Рахунок на оплату постачальника ІБ00-001397 від 08.04.2025 23:12:01 | E10: 221 | F10: 3336.6 | H10: 631 | K10: Д | L10: 55394.25
A11: 10.04.2025 | B11: Надходження товарів і послуг ІБ00-001714 від 10.04.2025 11:00:00 Оприходованы ТМЦ | C11: Обл. НДС Костюм зварювальника брезент. ОП з посиленнями р.104-108/170-176 Надходження товарів і послуг ІБ00-001714 від 10.04.2025 11:00:00 Пункт фасування та зберігання в бігбегах (Глобине) | D11: БРАВО-СП ТОВ РАХУНКИ_Глобине-2 Рахунок на оплату постачальника ІБ00-001397 від 08.04.2025 23:12:01 | E11: 221 | F11: 2582.5 | H11: 631 | K11: Д | L11: 57976.75
A12: 29.04.2025 | B12: Передача малоцінних активів в експлуатацію ІБ00-000178 від 29.04.2025 16:06:39 Списание стоимости малоценных активов | C12: Обл. НДС Виробничий (Глобине-2) Глобине-2 Амортизація ОЗ загальновиробничого призначення | D12: Обл. НДС Круг відрізний 230*2,5*22 Надходження товарів і послуг ІБ00-001198 від 21.03.2025 19:26:08 Пункт фасування та зберігання в бігбегах (Глобине) | E12: 231 | H12: 221 | I12: 424.4 | K12: Д | L12: 57552.35
A13: 29.04.2025 | B13: Передача малоцінних активів в експлуатацію ІБ00-000178 від 29.04.2025 16:06:39 Списание стоимости малоценных активов | C13: Обл. НДС Виробничий (Глобине-2) Глобине-2 Амортизація ОЗ загальновиробничого призначення | D13: Обл. НДС Рукавиці трикотажні з ПВХ Надходження товарів і послуг ІБ00-001431 від 31.03.2025 11:59:59 Пункт фасування та зберігання в бігбегах (Глобине) | E13: 231 | H13: 221 | I13: 294 | K13: Д | L13: 57258.35
A14: 29.04.2025 | B14: Передача малоцінних активів в експлуатацію ІБ00-000178 від 29.04.2025 16:06:39 Списание стоимости малоценных активов | C14: Обл. НДС Виробничий (Глобине-2) Глобине-2 Амортизація ОЗ загальновиробничого призначення | D14: Обл. НДС Рукавички скло/камінь черв з рифл гум надол р.10 Надходження товарів і послуг ІБ00-001431 від 31.03.2025 11:59:59 Пункт фасування та зберігання в бігбегах (Глобине) | E14: 231 | H14: 221 | I14: 151 | K14: Д | L14: 57107.35
A15: 29.04.2025 | B15: Передача малоцінних активів в експлуатацію ІБ00-000178 від 29.04.2025 16:06:39 Списание стоимости малоценных активов | C15: Обл. НДС Виробничий (Глобине-2) Глобине-2 Амортизація ОЗ загальновиробничого призначення | D15: Обл. НДС Ручка для валика Надходження товарів і послуг ІБ00-001198 від 21.03.2025 19:26:08 Пункт фасування та зберігання в бігбегах (Глобине) | E15: 231 | H15: 221 | I15: 136.5 | K15: Д | L15: 56970.85
A16: 29.04.2025 | B16: Передача малоцінних активів в експлуатацію ІБ00-000178 від 29.04.2025 16:06:39 Списание стоимости малоценных активов | C16: Обл. НДС Виробничий (Глобине-2) Глобине-2 Амортизація ОЗ загальновиробничого призначення | D16: Обл. НДС Валик 48*180 мм Надходження товарів і послуг ІБ00-001198 від 21.03.2025 19:26:08 Пункт фасування та зберігання в бігбегах (Глобине) | E16: 231 | H16: 221 | I16: 61.7 | K16: Д | L16: 56909.15
A17: 30.04.2025 | B17: Передача малоцінних активів в експлуатацію ІБ00-000201 від 30.04.2025 10:00:00 Списание стоимости малоценных активов | C17: Обл. НДС Виробничий (Глобине-2) Глобине-2 Амортизація ОЗ загальновиробничого призначення | D17: Обл. НДС Електроди "Моноліт РЦ" ф3 мм уп/2,5кг Надходження товарів і послуг ІБ00-000976 від 07.03.2025 19:00:34 Пункт фасування та зберігання в бігбегах (Глобине) | E17: 231 | H17: 221 | I17: 2276 | K17: Д | L17: 54633.15
A18: 30.04.2025 | B18: Передача малоцінних активів в експлуатацію ІБ00-000201 від 30.04.2025 10:00:00 Списание стоимости малоценных активов | C18: Обл. НДС Виробничий (Глобине-2) Глобине-2 Амортизація ОЗ загальновиробничого призначення | D18: Обл. НДС Скотч 48 ммх100 м.п. Надходження товарів і послуг ІБ00-000748 від 25.02.2025 18:19:56 Пункт фасування та зберігання в бігбегах (Глобине) | E18: 231 | H18: 221 | I18: 75.6 | K18: Д | L18: 54557.55
