Workbook
Name spec_values: [1]BOQ_Шаблон!$A$6:$A$275

Sheet Бюджет_Проекта
A1: Статья движения денежных средств | B1: ф1 | C1: ф2 | D1: Итого, грн | E1: Комментарии к бюджету объекта | H1: Матеріали | I1: =D101+D98 -> 3213611.4
A2: ПОСТУПЛЕНИЯ | B2: =B3+B10 -> 3838766 | C2: =C3+C10 -> 0 | D2: =B2+C2 -> 3838766 | H2: Загальна сс, грн | I2: =D14-I1 -> 1333865.5
A3: Операционная деятельность | B3: =SUM(B4:B9) -> 3838766 | C3: =SUM(C4:C9) -> 0 | D3: =B3+C3 -> 3838766 | H3: Налоговая нагрузка, 3%: | I3: =I4*3% -> 115162.98
A4: Поступление от Заказчика | B4: 3838766 | D4: =B4+C4 -> 3838766 | H4: КП: | I4: =B4 -> 3838766
A5: Прочие поступления | D5: =B5+C5 -> 0 | H5: Маржа, грн: за шт | I5: =I4-I3-I2-I1 -> -823873.9
A6: Возврат залоговой суммы | D6: =B6+C6 -> 0 | H6: Маржа, %: | I6: =I5/I4 -> -0.21461946
A7: Поступление от возврата денежных средств | D7: =B7+C7 -> 0 | H7: Количество в заказе, шт | I7: 1
A8: Поступление цех | D8: =B8+C8 -> 0 | H8: Итого маржа по заказу, грн | I8: =I7*I5 -> -823873.9
A9: Поступление за технику | D9: =B9+C9 -> 0
A10: Финансовая деятельность | B10: =SUM(B11:B13) -> 0 | C10: =SUM(C11:C13) -> 0 | D10: =B10+C10 -> 0
A11: Получение финансовой помощи | D11: =B11+C11 -> 0
A12: Поступление от Фин агента | C12: =B133 -> 0 | D12: =B12+C12 -> 0
A13: Кредитная линия | D13: =B13+C13 -> 0
A14: СПИСАНИЕ | B14: =B15+B128+B141 -> 3704526.9 | C14: =C15+C128+C141 -> 842950 | D14: =B14+C14 -> 4547476.9
A15: Операционная деятельность | B15: =B16+B70+B93+B66 -> 3578084.4 | C15: =C16+C70+C93+C66 -> 842950 | D15: =B15+C15 -> 4421034.4
A16: Административные затраты | B16: =B17+B24+B29+B33+B41+B45+B49+B52+B58+B61+B21 -> 59000 | C16: =C17+C24+C29+C33+C41+C45+C49+C52+C58+C61+C21 -> 0 | D16: =B16+C16 -> 59000
A17: Аренда офиса | B17: =SUM(B18:B20) -> 0 | C17: =SUM(C18:C20) -> 0 | D17: =B17+C17 -> 0
A18: Аренда офиса | B18: =SUMIF('Проект СС'!$B:$B,$A18,'Проект СС'!$O:$O) -> 0 | D18: =B18+C18 -> 0
A19: Коммунальные платежи (офис) | B19: =SUMIF('Проект СС'!$B:$B,$A19,'Проект СС'!$O:$O) -> 0 | D19: =B19+C19 -> 0
A20: Охрана офиса и пожарная сигнализация | B20: =SUMIF('Проект СС'!$B:$B,$A20,'Проект СС'!$O:$O) -> 0 | D20: =B20+C20 -> 0
A21: Аренда квартиры | B21: =SUM(B22:B23) -> 0 | C21: =SUM(C22:C23) -> 0 | D21: =B21+C21 -> 0
A22: Аренда квартиры | B22: =SUMIF('Проект СС'!$B:$B,$A22,'Проект СС'!$O:$O) -> 0 | D22: =B22+C22 -> 0
A23: Коммунальные платежи | B23: =SUMIF('Проект СС'!$B:$B,$A23,'Проект СС'!$O:$O) -> 0 | D23: =B23+C23 -> 0
A24: Затраты на персонал | B24: =SUM(B25:B28) -> 0 | C24: =SUM(C25:C28) -> 0 | D24: =B24+C24 -> 0
A25: Затраты на обучение управленческого персонала | B25: =SUMIF('Проект СС'!$B:$B,$A25,'Проект СС'!$O:$O) -> 0 | D25: =B25+C25 -> 0
A26: Затраты по корпоративной культуре | B26: =SUMIF('Проект СС'!$B:$B,$A26,'Проект СС'!$O:$O) -> 0 | D26: =B26+C26 -> 0
A27: Материальная помощь | B27: =SUMIF('Проект СС'!$B:$B,$A27,'Проект СС'!$O:$O) -> 0 | D27: =B27+C27 -> 0
A28: Периодика | B28: =SUMIF('Проект СС'!$B:$B,$A28,'Проект СС'!$O:$O) -> 0 | D28: =B28+C28 -> 0
A29: Затраты на командировку | B29: =SUM(B30:B32) -> 48000 | C29: =SUM(C30:C32) -> 0 | D29: =B29+C29 -> 48000
A30: Проезд | B30: =SUMIF('Проект СС'!$B:$B,$A30,'Проект СС'!$O:$O) -> 0
A31: Проживание | B31: =SUMIF('Проект СС'!$B:$B,$A31,'Проект СС'!$O:$O) -> 48000 | D31: =B31+C31 -> 48000
A32: Суточные | B32: =SUMIF('Проект СС'!$B:$B,$A32,'Проект СС'!$O:$O) -> 0 | D32: =B32+C32 -> 0
A33: ЗП управленческого персонала с начислениями | B33: =SUM(B34:B40) -> 0 | C33: =SUM(C34:C40) -> 0 | D33: =B33+C33 -> 0
A34: Зарплата PM | C34: =SUMIF('Проект СС'!$B:$B,$A34,'Проект СС'!$O:$O) -> 0 | D34: =B34+C34 -> 0 | E34: 2 мес + 5 мес
A35: Удержание с зарплаты РМ | B35: =SUMIF('Проект СС'!$B:$B,$A35,'Проект СС'!$O:$O) -> 0 | D35: =B35+C35 -> 0
A36: Начисления на зарплату PM | B36: =SUMIF('Проект СС'!$B:$B,$A36,'Проект СС'!$O:$O) -> 0 | D36: =B36+C36 -> 0
A37: Зарплата управленческого персонала | B37: =SUMIF('Проект СС'!$B:$B,$A37,'Проект СС'!$O:$O) -> 0 | D37: =B37+C37 -> 0
A38: Удержание с админ зарплату | B38: =SUMIF('Проект СС'!$B:$B,$A38,'Проект СС'!$O:$O) -> 0 | D38: =B38+C38 -> 0
A39: Начисления на админ зарплату | B39: =SUMIF('Проект СС'!$B:$B,$A39,'Проект СС'!$O:$O) -> 0 | D39: =B39+C39 -> 0
A40: Премия админ персоналу | B40: =SUMIF('Проект СС'!$B:$B,$A40,'Проект СС'!$O:$O) -> 0 | D40: =B40+C40 -> 0
...

Sheet Анализ
A1: МД EMS мала | D1: Курс | E1: 43.5 | F1: Площадь | G1: =10*12 -> 120
A3: Сумма по полю Всього, грн. з ПДВ | B3: Названия столбцов
A4: Названия строк | B4: Матеріал | C4: Робота | D4: Общий итог | E4: Материал $ | F4: Общий итог $ | G4: На 1 м2 $
A5: Дополнительная Комплектация | B5: 323204 | C5: 0 | D5: 323204 | E5: =B5/$E$1 -> 7429.977 | F5: =D5/$E$1 -> 7429.977 | G5: =F5/$G$1 -> 61.916475
A6: Каркас | B6: 402079.36 | C6: 0 | D6: 402079.36 | E6: =B6/$E$1 -> 9243.2037 | F6: =D6/$E$1 -> 9243.2037 | G6: =F6/$G$1 -> 77.026697
A7: Монтаж будинку | C7: 0 | D7: 0 | E7: =B7/$E$1 -> 0 | F7: =D7/$E$1 -> 0 | G7: =F7/$G$1 -> 0
A8: Окна/двери | B8: 144953.03 | C8: 0 | D8: 144953.03 | E8: =B8/$E$1 -> 3332.2536 | F8: =D8/$E$1 -> 3332.2536 | G8: =F8/$G$1 -> 27.76878
A9: Отделка | B9: 665033.4 | C9: 0 | D9: 665033.4 | E9: =B9/$E$1 -> 15288.124 | F9: =D9/$E$1 -> 15288.124 | G9: =F9/$G$1 -> 127.40103
A10: Сантехника | B10: 97874 | C10: 0 | D10: 97874 | E10: =B10/$E$1 -> 2249.977 | F10: =D10/$E$1 -> 2249.977 | G10: =F10/$G$1 -> 18.749808
A11: Фасад | B11: 107743.56 | C11: 0 | D11: 107743.56 | E11: =B11/$E$1 -> 2476.8634 | F11: =D11/$E$1 -> 2476.8634 | G11: =F11/$G$1 -> 20.640529
A12: Электрика/Подогрев | B12: 136627.04 | C12: 0 | D12: 136627.04 | E12: =B12/$E$1 -> 3140.8515 | F12: =D12/$E$1 -> 3140.8515 | G12: =F12/$G$1 -> 26.173762
A13: Общий итог | B13: 1877514.4 | C13: 0 | D13: 1877514.4 | E13: =SUM(E5:E12) -> 43161.25 | F13: =SUM(F5:F12) -> 43161.25

Sheet Проект СС
A1: № | B1: Стаття в ДДС | C1: Робота/матеріал/додаткові | D1: Виробництво/Будівництво | E1: Тип робіт | F1: № з/п | G1: Найменування робіт/витрат/матеріалів | H1: Найменування робіт/витрат/матеріалів узагальнена | I1: Од. вим. | J1: Кіль- кість | K1: Вартість робіт за од.виміру, грн. з ПДВ | L1: Вартість матеріалів за од.виміру, грн. з ПДВ | M1: Вартість робіт за повний обсяг, грн. з ПДВ | N1: Вартість матеріалів за повний обсяг, грн. з ПДВ | O1: Всього, грн. з ПДВ
A2: І | F2: І | G2: Каркас | J2: =L3+L12 -> 0
A3: 1.1 | F3: 1.1 | G3: РОБОТА | L3: =SUM(L5:L11) -> 0
A4: 1.1.1 | B4: Зарплата производственного персонала | C4: Робота | D4: Виробництво/Будівництво | E4: Каркас | F4: 1.1.1 | G4: Приймання матеріалу | I4: чол/год | J4: =480/8 -> 60 | K4: 200 | M4: =J4*K4 -> 12000 | N4: =J4*L4 -> 0 | O4: =N4+M4 -> 12000
A5: 1.1.2 | B5: Зарплата производственного персонала | C5: Робота | D5: Виробництво/Будівництво | E5: Каркас | F5: 1.1.2 | G5: Обробка матеріалу (дерево) | I5: чол/год | J5: =480/8 -> 60 | K5: 200 | M5: =J5*K5 -> 12000 | N5: =J5*L5 -> 0 | O5: =N5+M5 -> 12000
A6: 1.1.3 | B6: Зарплата производственного персонала | C6: Робота | D6: Виробництво/Будівництво | E6: Каркас | F6: 1.1.3 | G6: Нарізання деталей зігдно креслень | I6: чол/год | J6: =480/8 -> 60 | K6: 200 | M6: =J6*K6 -> 12000 | N6: =J6*L6 -> 0 | O6: =N6+M6 -> 12000
A7: 1.1.4 | B7: Зарплата производственного персонала | C7: Робота | D7: Виробництво/Будівництво | E7: Каркас | F7: 1.1.4 | G7: Збирання деталей | I7: чол/год | J7: =480/8 -> 60 | K7: 200 | M7: =J7*K7 -> 12000 | N7: =J7*L7 -> 0 | O7: =N7+M7 -> 12000
A8: 1.1.5 | B8: Зарплата производственного персонала | C8: Робота | D8: Виробництво/Будівництво | E8: Каркас | F8: 1.1.5 | G8: зварювання (дерево зєдання) | I8: чол/год | J8: =480/8 -> 60 | K8: 200 | M8: =J8*K8 -> 12000 | N8: =J8*L8 -> 0 | O8: =N8+M8 -> 12000
A9: 1.1.6 | B9: Зарплата производственного персонала | C9: Робота | D9: Виробництво/Будівництво | E9: Каркас | F9: 1.1.6 | G9: Влаштування підшиви модуля | I9: чол/год | J9: =480/8 -> 60 | K9: 200 | M9: =J9*K9 -> 12000 | N9: =J9*L9 -> 0 | O9: =N9+M9 -> 12000
A10: 1.1.7 | B10: Зарплата производственного персонала | C10: Робота | D10: Виробництво/Будівництво | E10: Каркас | F10: 1.1.7 | G10: Грунтування металокаркасу | I10: чол/год | J10: =480/8 -> 60 | K10: 200 | M10: =J10*K10 -> 12000 | N10: =J10*L10 -> 0 | O10: =N10+M10 -> 12000
A11: 1.1.8 | B11: Зарплата производственного персонала | C11: Робота | D11: Виробництво/Будівництво | E11: Каркас | F11: 1.1.8 | G11: Фарубування металокаркасу | I11: чол/год | J11: =480/8 -> 60 | K11: 200 | M11: =J11*K11 -> 12000 | N11: =J11*L11 -> 0 | O11: =N11+M11 -> 12000
A12: 1.2 | F12: 1.2 | G12: МАТЕРІАЛИ
A13: 1.2.1 | B13: Строительные материалы | C13: Матеріал | D13: Виробництво/Будівництво | E13: Каркас | F13: 1.2.1 | G13: Труба металева Ст3 100*100*3 | H13: Профільна труба | I13: м.п | J13: 359 | L13: 441 | M13: =J13*K13 -> 0 | N13: =J13*L13 -> 158319 | O13: =N13+M13 -> 158319
A14: 1.2.2 | B14: Строительные материалы | C14: Матеріал | D14: Виробництво/Будівництво | E14: Каркас | F14: 1.2.2 | G14: Труба металева Ст3 50*50*2 | H14: Профільна труба | I14: м.п. | J14: 684 | L14: 156 | M14: =J14*K14 -> 0 | N14: =J14*L14 -> 106704 | O14: =N14+M14 -> 106704
A15: 1.2.3 | B15: Строительные материалы | C15: Матеріал | D15: Виробництво/Будівництво | E15: Каркас | F15: 1.2.3 | G15: Труба металева Ст3 50*25*2 | H15: Профільна труба | I15: м.п | J15: 384 | L15: 98 | M15: =J15*K15 -> 0 | N15: =J15*L15 -> 37632 | O15: =N15+M15 -> 37632
A16: 1.2.4 | B16: Строительные материалы | C16: Матеріал | D16: Виробництво/Будівництво | E16: Каркас | F16: 1.2.4 | G16: Лист 4мм | H16: лист ГК | I16: м2 | J16: 4.5 | L16: 1698 | M16: =J16*K16 -> 0 | N16: =J16*L16 -> 7641 | O16: =N16+M16 -> 7641
A17: 1.2.5 | B17: Строительные материалы | C17: Матеріал | D17: Виробництво/Будівництво | E17: Каркас | F17: 1.2.5 | G17: Лист 8мм | H17: лист ГК | I17: м2 | J17: 4.5 | L17: 3356 | M17: =J17*K17 -> 0 | N17: =J17*L17 -> 15102 | O17: =N17+M17 -> 15102
A18: 1.2.6 | B18: Строительные материалы | C18: Матеріал | D18: Виробництво/Будівництво | E18: Каркас | F18: 1.2.6 | G18: Лист 14мм | H18: лист ГК | I18: м.кв. | J18: 0.16 | L18: 6811 | M18: =J18*K18 -> 0 | N18: =J18*L18 -> 1089.76 | O18: =N18+M18 -> 1089.76
A19: 1.2.7 | B19: Строительные материалы | C19: Матеріал | D19: Виробництво/Будівництво | E19: Каркас | F19: 1.2.7 | G19: Шпилька М48 | H19: Шпилька | I19: м.п. | J19: 18 | L19: 1984 | M19: =J19*K19 -> 0 | N19: =J19*L19 -> 35712 | O19: =N19+M19 -> 35712
A20: 1.2.8 | B20: Строительные материалы | C20: Матеріал | D20: Виробництво/Будівництво | E20: Каркас | F20: 1.2.8 | G20: Гайка м 48 | H20: Гайка | I20: шт | J20: 36 | L20: 274 | M20: =J20*K20 -> 0 | N20: =J20*L20 -> 9864 | O20: =N20+M20 -> 9864
A21: 1.2.9 | B21: Строительные материалы | C21: Матеріал | D21: Виробництво/Будівництво | E21: Каркас | F21: 1.2.9 | G21: Болт м24*200 | H21: Болт | I21: шт | J21: 32 | L21: 145 | M21: =J21*K21 -> 0 | N21: =J21*L21 -> 4640 | O21: =N21+M21 -> 4640
A22: 1.2.10 | B22: Строительные материалы | C22: Матеріал | D22: Виробництво/Будівництво | E22: Каркас | F22: 1.2.10 | G22: Гайка м 24 | H22: Гайка | I22: шт | J22: 32 | L22: 154 | M22: =J22*K22 -> 0 | N22: =J22*L22 -> 4928 | O22: =N22+M22 -> 4928
A23: 1.2.11 | B23: Строительные материалы | C23: Матеріал | D23: Виробництво/Будівництво | E23: Каркас | F23: 1.2.11 | G23: Болт М16*90 | H23: Болт | I23: шт | J23: 52 | L23: 98 | M23: =J23*K23 -> 0 | N23: =J23*L23 -> 5096 | O23: =N23+M23 -> 5096
A24: 1.2.12 | B24: Строительные материалы | C24: Матеріал | D24: Виробництво/Будівництво | E24: Каркас | F24: 1.2.12 | G24: Гайка м 16 | H24: Гайка | I24: шт | J24: 52 | L24: 4.92 | M24: =J24*K24 -> 0 | N24: =J24*L24 -> 255.84 | O24: =N24+M24 -> 255.84
... A34: 1.2.22 | B34: МШП | C34: Матеріал | D34: Виробництво/Будівництво | E34: Каркас | F34: 1.2.22 | G34: Гайки м12 | H34: Гайка | I34: шт | J34: 38 | L34: 13.27 | M34: =J34*K34 -> 0 | N34: =J34*L34 -> 504.26 | O34: =N34+M34 -> 504.26
B35: Строительные материалы | C35: Матеріал | D35: Виробництво/Будівництво | E35: Каркас | F35: 1.2.23 | G35: шайба м12 | H35: Шайба | I35: шт | J35: 38 | L35: 9.215 | M35: =J35*K35 -> 0 | N35: =J35*L35 -> 350.17 | O35: =N35+M35 -> 350.17
B36: Строительные материалы | C36: Матеріал | D36: Виробництво/Будівництво | E36: Каркас | F36: 1.2.24 | G36: гровер м12 | H36: Гровер | I36: шт | J36: 40 | L36: 8.36 | M36: =J36*K36 -> 0 | N36: =J36*L36 -> 334.4 | O36: =N36+M36 -> 334.4
B37: Строительные материалы | C37: Матеріал | D37: Виробництво/Будівництво | E37: Каркас | F37: 1.2.25 | G37: Завіса 16мм | H37: Завіса | I37: шт | J37: 8 | L37: 136 | M37: =J37*K37 -> 0 | N37: =J37*L37 -> 1088 | O37: =N37+M37 -> 1088
B38: Строительные материалы | C38: Матеріал | D38: Виробництво/Будівництво | E38: Каркас | F38: 1.2.26 | G38: Завіса 20мм | H38: Завіса | I38: шт | J38: 4 | L38: 154 | M38: =J38*K38 -> 0 | N38: =J38*L38 -> 616 | O38: =N38+M38 -> 616
B39: Строительные материалы | C39: Матеріал | D39: Виробництво/Будівництво | E39: Каркас | F39: 1.2.27 | G39: Лист 5 мм | H39: лист ГК | I39: м.кв. | J39: 0.5 | L39: 1959.6 | M39: =J39*K39 -> 0 | N39: =J39*L39 -> 979.8 | O39: =N39+M39 -> 979.8
B40: Строительные материалы | C40: Матеріал | D40: Виробництво/Будівництво | E40: Каркас | F40: 1.2.28 | G40: Фарба 3 в 1 сіра | H40: Фарба | I40: кг | J40: 5 | L40: 216 | M40: =J40*K40 -> 0 | N40: =J40*L40 -> 1080 | O40: =N40+M40 -> 1080
B41: Строительные материалы | C41: Матеріал | D41: Виробництво/Будівництво | E41: Каркас | F41: 1.2.29 | G41: Розчинник | H41: Розчинник | I41: л | J41: 1 | L41: 96 | M41: =J41*K41 -> 0 | N41: =J41*L41 -> 96 | O41: =N41+M41 -> 96
B42: Строительные материалы | C42: Матеріал | D42: Виробництво/Будівництво | E42: Каркас | F42: 1.2.30 | G42: Труба 40*40*3 | H42: Профільна труба | I42: м.п | J42: 27.2 | L42: 132 | M42: =J42*K42 -> 0 | N42: =J42*L42 -> 3590.4 | O42: =N42+M42 -> 3590.4
B43: Строительные материалы | C43: Матеріал | D43: Виробництво/Будівництво | E43: Каркас | F43: 1.2.31 | G43: Труба 20*40*3 | H43: Профільна труба | I43: м.п. | J43: 53 | L43: 97 | M43: =J43*K43 -> 0 | N43: =J43*L43 -> 5141 | O43: =N43+M43 -> 5141
B44: Строительные материалы | C44: Матеріал | D44: Виробництво/Будівництво | E44: Каркас | F44: 1.2.32 | G44: Лист 4мм | H44: лист ГК | I44: т | J44: 0.013 | L44: 1698 | M44: =J44*K44 -> 0 | N44: =J44*L44 -> 22.074 | O44: =N44+M44 -> 22.074
B45: Строительные материалы | C45: Матеріал | D45: Виробництво/Будівництво | E45: Каркас | F45: 1.2.33 | G45: Лист 6мм | H45: лист ГК | I45: т | J45: 0.031 | L45: 2077 | M45: =J45*K45 -> 0 | N45: =J45*L45 -> 64.387 | O45: =N45+M45 -> 64.387
B46: Строительные материалы | C46: Матеріал | D46: Виробництво/Будівництво | E46: Каркас | F46: 1.2.34 | G46: Завіси 16 мм круглі | H46: Завіса | I46: шт | J46: 4 | L46: 136 | M46: =J46*K46 -> 0 | N46: =J46*L46 -> 544 | O46: =N46+M46 -> 544
B47: Строительные материалы | C47: Матеріал | D47: Виробництво/Будівництво | E47: Каркас | F47: 1.2.35 | G47: Фарба 3 в 1 | H47: Фарба | I47: кг | J47: 2.5 | L47: 216 | M47: =J47*K47 -> 0 | N47: =J47*L47 -> 540 | O47: =N47+M47 -> 540
B48: Строительные материалы | C48: Матеріал | D48: Виробництво/Будівництво | E48: Каркас | F48: 1.2.36 | G48: Розчинник | H48: #N/A | I48: л | J48: 1 | L48: 96 | M48: =J48*K48 -> 0 | N48: =J48*L48 -> 96 | O48: =N48+M48 -> 96
B49: Строительные материалы | C49: Матеріал | D49: Виробництво/Будівництво | E49: Каркас | F49: 1.2.37 | G49: Пінопласт 100мм | H49: Пінопласт | I49: м.кв. | J49: 9.6 | L49: 220 | M49: =J49*K49 -> 0 | N49: =J49*L49 -> 2112 | O49: =N49+M49 -> 2112
...

Sheet анализ виготовлення
A1: Найменування робіт | D1: Статус | E1: Факт виконання | F1: аналіз годин до закінчення, плановий
A2: Приймання матеріалу | B2: чол/год | C2: =480/8 -> 60 | D2: виконується | F2: 25
A3: Обробка матеріалу (дерево) | B3: чол/год | C3: =480/8 -> 60 | F3: 60
A4: Нарізання деталей зігдно креслень | B4: чол/год | C4: =480/8 -> 60 | D4: 1
A5: Збирання деталей | B5: чол/год | C5: =480/8 -> 60 | D5: 0.5 | F5: =30 -> 30
A6: зварювання (дерево зєдання) | B6: чол/год | C6: =480/8 -> 60 | D6: 0.5 | F6: =30 -> 30
A7: Влаштування підшиви модуля | B7: чол/год | C7: =480/8 -> 60 | D7: 0.5 | F7: =30 -> 30
A8: Грунтування металокаркасу | B8: чол/год | C8: =480/8 -> 60 | F8: =C8 -> 60
A9: Фарубування металокаркасу | B9: чол/год | C9: =480/8 -> 60 | F9: =C9 -> 60
A10: Утеплення та гідроізоляція підлоги | B10: чол/год | C10: =1080/7 -> 154.28571 | F10: =C10 -> 154.28571
A11: Монтаж брусу по каркасу | B11: чол/год | C11: =1080/7 -> 154.28571 | F11: =C11 -> 154.28571
A12: Пароізоляційна мембрана; | B12: чол/год | C12: =1080/7 -> 154.28571 | F12: =C12 -> 154.28571
A13: Укладання Настил підлоги | B13: чол/год | C13: =1080/7 -> 154.28571 | F13: =C13 -> 154.28571
A14: Гідроізоляційна та пароізоляція стін та стелі | B14: чол/год | C14: =1080/7 -> 154.28571 | F14: =C14 -> 154.28571
A15: Утеплення стеля та стіни | B15: чол/год | C15: =1080/7 -> 154.28571 | F15: =C15 -> 154.28571
A16: Монтаж фінішного оздоблення | B16: чол/год | C16: =1080/7 -> 154.28571 | F16: =C16 -> 154.28571
A17: монтаж обрешітки по каркасу | B17: чол/год | C17: =3*8*1*8 -> 192 | F17: =C17 -> 192
A18: Гідроізоляційна плівка | B18: чол/год | C18: =3*8*0.5*8 -> 96 | F18: =C18 -> 96
A19: монтаж фасаду та покрівлі | B19: чол/год | C19: =3*8*2*8 -> 384 | F19: =C19 -> 384
A20: монтаж вікон | B20: чол/год | C20: =3*8*4 -> 96 | F20: =C20 -> 96
A21: монтаж вхідних дверей | B21: чол/год | C21: =2*8*1 -> 16 | F21: =C21 -> 16
A22: монтаж мдф дверей | B22: чол/год | C22: 0 | F22: =C22 -> 0
A23: монтаж металопластикових дврей | B23: чол/год | C23: =3*8*4 -> 96 | F23: =C23 -> 96
A24: монтаж трубопроводів | B24: чол/год | C24: =100/4 -> 25 | F24: =C24 -> 25
A25: монтаж каналізаційних труб | B25: чол/год | C25: =100/4 -> 25 | F25: =C25 -> 25
A26: монтаж сантехнічних приборів | B26: чол/год | C26: =100/4 -> 25 | F26: =C26 -> 25
A27: підключення та перевірка сантехнічного обладнання | B27: чол/год | C27: =100/4 -> 25 | F27: =C27 -> 25
A28: табель | E28: 155 | F28: =C28 -> 0
A29: Загальна кількість, год | C29: =SUM(C2:C27) -> 2540 | E29: =SUM(E2:E28) -> 155 | F29: =SUM(F2:F28) -> 2355
