Workbook

Sheet СВОД_ГЛОБИНО
B2: Глобине-2 | C2: ='Глобине-2'!J158 -> 70837.596
B3: Котельна (Глобине) | C3: =Котельна!J92 -> 638686.48
B4: Насосна Градирня (Глобине) | C4: ='Насосна Градирня '!J28 -> 78034.44
B5: Пункт фасування та зберігання в бігбегах (Глобине) | C5: 0
B6: Резервуар для зберігання розчинника(Глобине) | C6: ='Резервуар для зберігання'!J37 -> 356643.52
B7: Резервуарний парк соєвої меляси (Глобине) | C7: ='Резервуарний парк'!J69 -> 952397.94
B8: СПК (Глобине) | C8: ='СПК (Глобине)'!J125 -> 728107.56
B9: Цех екстракції (Глобине) | C9: ='Цех екстракції (Глобине)'!J251 -> 4934146
B10: Цех_Глобино | C10: ='СПК (Глобине)'!J125 -> 728107.56
C11: =SUM(C2:C10) -> 8486961.1

Sheet Глобине-2
A1: Період | B1: Документ | C1: Аналітика Дт | D1: Аналітика Кт | E1: Дебет | H1: Кредит | K1: Поточне сальдо
E2: Рахунок | H2: Рахунок
A3: 01.02.2025 | B3: Надходження товарів і послуг ІБ00-000353 від 01.02.2025 18:00:04 Оприходованы ТМЦ (Зачет аванса поставщику) | C3: Обл. НДС Бетон С20/25 W6 F75 P4 Надходження товарів і послуг ІБ00-000353 від 01.02.2025 18:00:04 Глобине-2 | D3: Кременчуцький річковий порт ПРАТ Договір 112/Б від 15.10.2024_Глобине-2 Списання з банківського рахунку 00000001239 від 31.01.2025 16:20:57 | E3: 205 | F3: 127440 | H3: 631 | K3: Д | L3: 271058.51
A4: 01.02.2025 | B4: Надходження дод. витрат ІБ00-000059 від 01.02.2025 18:05:00 Доп. расходы при поступлении товаров (Зачет аванса поставщику) | C4: Обл. НДС Бетон С20/25 W6 F75 P4 Надходження товарів і послуг ІБ00-000353 від 01.02.2025 18:00:04 Глобине-2 | D4: Кременчуцький річковий порт ПРАТ Договір 112/Б від 15.10.2024_Глобине-2 Списання з банківського рахунку 00000001239 від 31.01.2025 16:20:57 | E4: 205 | F4: 30127.5 | H4: 631 | K4: Д | L4: 301186.01
A5: 01.02.2025 | B5: Переміщення товарів ІБ00-000055 від 01.02.2025 18:10:00 Перемещение ТМЦ | C5: Обл. НДС Бетон С20/25 W6 F75 P4 Надходження товарів і послуг ІБ00-000353 від 01.02.2025 18:00:04 Котельна (Глобине) | D5: Обл. НДС Бетон С20/25 W6 F75 P4 Надходження товарів і послуг ІБ00-000353 від 01.02.2025 18:00:04 Глобине-2 | E5: 205 | H5: 205 | I5: 62370.47 | K5: Д | L5: 238815.54
A6: 01.02.2025 | B6: Переміщення товарів ІБ00-000056 від 01.02.2025 18:10:00 Перемещение ТМЦ | C6: Обл. НДС Бетон С20/25 W6 F75 P4 Надходження товарів і послуг ІБ00-000353 від 01.02.2025 18:00:04 Цех екстракції (Глобине) | D6: Обл. НДС Бетон С20/25 W6 F75 P4 Надходження товарів і послуг ІБ00-000353 від 01.02.2025 18:00:04 Глобине-2 | E6: 205 | H6: 205 | I6: 95197.03 | K6: Д | L6: 143618.51
A7: 01.02.2025 | B7: Переміщення товарів ІБ00-000087 від 01.02.2025 18:10:09 Перемещение ТМЦ | C7: Обл. НДС Піна монтажна 860 мл Надходження товарів і послуг ІБ00-006233 від 14.12.2024 17:00:01 Глобине-2 | D7: Обл. НДС Піна монтажна 860 мл Надходження товарів і послуг ІБ00-006233 від 14.12.2024 17:00:01 СПК (Глобине) | E7: 205 | F7: 950 | H7: 205 | K7: Д | L7: 144568.51
A8: 01.02.2025 | B8: Переміщення товарів ІБ00-000089 від 01.02.2025 18:10:11 Перемещение ТМЦ | C8: Обл. НДС Шпонка гідроізоляційна ВР 200 20м п Надходження товарів і послуг ІБ00-002091 від 21.12.2023 18:14:00 Резервуарний парк соєвої меляси (Глобине) | D8: Обл. НДС Шпонка гідроізоляційна ВР 200 20м п Надходження товарів і послуг ІБ00-002091 від 21.12.2023 18:14:00 Глобине-2 | E8: 205 | H8: 205 | I8: 839.5 | K8: Д | L8: 143729.01
A9: 01.02.2025 | B9: Переміщення товарів ІБ00-000094 від 01.02.2025 18:10:16 Перемещение ТМЦ | C9: Обл. НДС Анкер хімічний 585 мл EРОХ Надходження товарів і послуг ІБ00-000723 від 29.02.2024 23:00:01 Цех екстракції (Глобине) | D9: Обл. НДС Анкер хімічний 585 мл EРОХ Надходження товарів і послуг ІБ00-000723 від 29.02.2024 23:00:01 Глобине-2 | E9: 205 | H9: 205 | I9: 2342.8 | K9: Д | L9: 141386.21
A10: 04.02.2025 | B10: Надходження товарів і послуг ІБ00-000525 від 04.02.2025 18:00:08 Оприходованы ТМЦ | C10: Обл. НДС Труба п/е 25- (2 м) Надходження товарів і послуг ІБ00-000525 від 04.02.2025 18:00:08 Глобине-2 | D10: ПРОТЕКС УКРАЇНА Договір 9 від 11.12.2023_Глобіно2 Рахунок на оплату постачальника ІБ00-000458 від 03.02.2025 18:10:32 | E10: 205 | F10: 2390 | H10: 631 | K10: Д | L10: 143776.21
A11: 04.02.2025 | B11: Надходження товарів і послуг ІБ00-000525 від 04.02.2025 18:00:08 Оприходованы ТМЦ | C11: Обл. НДС Фіксатор конус Надходження товарів і послуг ІБ00-000525 від 04.02.2025 18:00:08 Глобине-2 | D11: ПРОТЕКС УКРАЇНА Договір 9 від 11.12.2023_Глобіно2 Рахунок на оплату постачальника ІБ00-000458 від 03.02.2025 18:10:32 | E11: 205 | F11: 900 | H11: 631 | K11: Д | L11: 144676.21
A12: 04.02.2025 | B12: Надходження товарів і послуг ІБ00-000525 від 04.02.2025 18:00:08 Оприходованы ТМЦ | C12: Обл. НДС Фіксатор зірочка 25 Надходження товарів і послуг ІБ00-000525 від 04.02.2025 18:00:08 Глобине-2 | D12: ПРОТЕКС УКРАЇНА Договір 9 від 11.12.2023_Глобіно2 Рахунок на оплату постачальника ІБ00-000458 від 03.02.2025 18:10:32 | E12: 205 | F12: 766.7 | H12: 631 | K12: Д | L12: 145442.91
A13: 04.02.2025 | B13: Надходження товарів і послуг ІБ00-000525 від 04.02.2025 18:00:08 Оприходованы ТМЦ | C13: Обл. НДС Фіксатор Стілець 50/8-24 Надходження товарів і послуг ІБ00-000525 від 04.02.2025 18:00:08 Глобине-2 | D13: ПРОТЕКС УКРАЇНА Договір 9 від 11.12.2023_Глобіно2 Рахунок на оплату постачальника ІБ00-000458 від 03.02.2025 18:10:32 | E13: 205 | F13: 3900 | H13: 631 | K13: Д | L13: 149342.91
A14: 05.02.2025 | B14: Надходження товарів і послуг ІБ00-000454 від 05.02.2025 18:00:12 Оприходованы ТМЦ (Зачет аванса поставщику) | C14: Обл. НДС Бетон С 8/10 Р4 доб-10 Надходження товарів і послуг ІБ00-000454 від 05.02.2025 18:00:12 Глобине-2 | D14: Кременчуцький річковий порт ПРАТ Договір 112/Б від 15.10.2024_Глобине-2 Списання з банківського рахунку 00000001239 від 31.01.2025 16:20:57 | E14: 205 | F14: 29625 | H14: 631 | K14: Д | L14: 178967.91
A15: 05.02.2025 | B15: Надходження товарів і послуг ІБ00-000454 від 05.02.2025 18:00:12 Оприходованы ТМЦ (Зачет аванса поставщику) | C15: Обл. НДС Бетон С20/25 W6 F75 P4 доб-10 Надходження товарів і послуг ІБ00-000454 від 05.02.2025 18:00:12 Глобине-2 | D15: Кременчуцький річковий порт ПРАТ Договір 112/Б від 15.10.2024_Глобине-2 Списання з банківського рахунку 00000001239 від 31.01.2025 16:20:57 | E15: 205 | F15: 68977.5 | H15: 631 | K15: Д | L15: 247945.41
A16: 05.02.2025 | B16: Надходження дод. витрат ІБ00-000069 від 05.02.2025 18:00:13 Доп. расходы при поступлении товаров (Зачет аванса поставщику) | C16: Обл. НДС Бетон С 8/10 Р4 доб-10 Надходження товарів і послуг ІБ00-000454 від 05.02.2025 18:00:12 Глобине-2 | D16: Кременчуцький річковий порт ПРАТ Договір 112/Б від 15.10.2024_Глобине-2 Списання з банківського рахунку 00000001239 від 31.01.2025 16:20:57 | E16: 205 | F16: 11862.09 | H16: 631 | K16: Д | L16: 259807.5
A17: 05.02.2025 | B17: Надходження дод. витрат ІБ00-000069 від 05.02.2025 18:00:13 Доп. расходы при поступлении товаров (Зачет аванса поставщику) | C17: Обл. НДС Бетон С20/25 W6 F75 P4 доб-10 Надходження товарів і послуг ІБ00-000454 від 05.02.2025 18:00:12 Глобине-2 | D17: Кременчуцький річковий порт ПРАТ Договір 112/Б від 15.10.2024_Глобине-2 Списання з банківського рахунку 00000001239 від 31.01.2025 16:20:57 | E17: 205 | F17: 27619.16 | H17: 631 | K17: Д | L17: 287426.66
A18: 05.02.2025 | B18: Вимога-накладна ІБ00-000065 від 05.02.2025 18:00:14 Списаны ТМЦ | C18: Обл. НДС Виробничий (Глобине-2) Глобине-2 Прямі материальні виробничі витрати крім зворотніх відходів | D18: Обл. НДС Шпонка гідроізоляційна ВР 200 20м п Надходження товарів і послуг ІБ00-002091 від 21.12.2023 18:14:00 Глобине-2 | E18: 231 | H18: 205 | I18: 1022 | K18: Д | L18: 286404.66
A19: 05.02.2025 | B19: Вимога-накладна ІБ00-000065 від 05.02.2025 18:00:14 Списаны ТМЦ | C19: Обл. НДС Виробничий (Глобине-2) Глобине-2 Прямі материальні виробничі витрати крім зворотніх відходів | D19: Обл. НДС Бетон С20/25 W6 F75 P4 доб-10 Надходження товарів і послуг ІБ00-000454 від 05.02.2025 18:00:12 Глобине-2 | E19: 231 | H19: 205 | I19: 53010.73 | K19: Д | L19: 233393.93
A20: 05.02.2025 | B20: Списання товарів ІБ00-000057 від 05.02.2025 18:00:15 Списаны ТМЦ | C20: Обл. НДС Виробничий (Глобине-2) Глобине-2 Прямі материальні виробничі витрати крім зворотніх відходів | D20: Обл. НДС Труба п/е 25- (2 м) Надходження товарів і послуг ІБ00-005516 від 05.11.2024 17:28:14 Глобине-2 | E20: 231 | H20: 205 | I20: 251.25 | K20: Д | L20: 233142.68
A21: 05.02.2025 | B21: Списання товарів ІБ00-000058 від 05.02.2025 18:00:19 Списаны ТМЦ | C21: Обл. НДС Виробничий (Глобине-2) Глобине-2 Прямі материальні виробничі витрати крім зворотніх відходів | D21: Обл. НДС Піна монтажна 860 мл Надходження товарів і послуг ІБ00-006233 від 14.12.2024 17:00:01 Глобине-2 | E21: 231 | H21: 205 | I21: 950 | K21: Д | L21: 232192.68
A22: 05.02.2025 | B22: Списання товарів ІБ00-000058 від 05.02.2025 18:00:19 Списаны ТМЦ | C22: Обл. НДС Виробничий (Глобине-2) Глобине-2 Прямі материальні виробничі витрати крім зворотніх відходів | D22: Обл. НДС Труба п/е 25- (2 м) Надходження товарів і послуг ІБ00-005516 від 05.11.2024 17:28:14 Глобине-2 | E22: 231 | H22: 205 | I22: 502.5 | K22: Д | L22: 231690.18
A23: 05.02.2025 | B23: Переміщення товарів ІБ00-000090 від 05.02.2025 18:10:00 Перемещение ТМЦ | C23: Обл. НДС Бетон С20/25 W6 F75 P4 доб-10 Надходження товарів і послуг ІБ00-000454 від 05.02.2025 18:00:12 СПК (Глобине) | D23: Обл. НДС Бетон С20/25 W6 F75 P4 доб-10 Надходження товарів і послуг ІБ00-000454 від 05.02.2025 18:00:12 Глобине-2 | E23: 205 | H23: 205 | I23: 39775.1 | K23: Д | L23: 191915.08
A24: 06.02.2025 | B24: Надходження товарів і послуг ІБ00-000478 від 06.02.2025 15:36:15 Оприходованы ТМЦ (Зачет аванса поставщику) | C24: Обл. НДС Коліно 110/90 ПЕТ терморезист SDR11 Надходження товарів і послуг ІБ00-000478 від 06.02.2025 15:36:15 Глобине-2 | D24: Лук'янець Максим Миколайович ФОП РАХУНКИ_Глобине 2 Рахунок на оплату постачальника ІБ00-000305 від 23.01.2025 18:20:30 | E24: 205 | F24: 3928 | H24: 631 | K24: Д | L24: 195843.08
A25: 06.02.2025 | B25: Надходження товарів і послуг ІБ00-000478 від 06.02.2025 15:36:15 Оприходованы ТМЦ (Зачет аванса поставщику) | C25: Обл. НДС Коліно 125/90 ПЕТ терморезист SDR11 Надходження товарів і послуг ІБ00-000478 від 06.02.2025 15:36:15 Глобине-2 | D25: Лук'янець Максим Миколайович ФОП РАХУНКИ_Глобине 2 Рахунок на оплату постачальника ІБ00-000305 від 23.01.2025 18:20:30 | E25: 205 | F25: 2740 | H25: 631 | K25: Д | L25: 198583.08
A26: 06.02.2025 | B26: Надходження товарів і послуг ІБ00-000478 від 06.02.2025 15:36:15 Оприходованы ТМЦ | C26: Обл. НДС Труба ПЕТ125*11,4 16атм чорна SDR11 Надходження товарів і послуг ІБ00-000478 від 06.02.2025 15:36:15 Глобине-2 | D26: Лук'янець Максим Миколайович ФОП РАХУНКИ_Глобине 2 Рахунок на оплату постачальника ІБ00-000305 від 23.01.2025 18:20:30 | E26: 205 | F26: 518.5 | H26: 631 | K26: Д | L26: 199101.58
A27: 06.02.2025 | B27: Надходження товарів і послуг ІБ00-000478 від 06.02.2025 15:36:15 Оприходованы ТМЦ (Зачет аванса поставщику) | C27: Обл. НДС Труба ПЕТ125*11,4 16атм чорна SDR11 Надходження товарів і послуг ІБ00-000478 від 06.02.2025 15:36:15 Глобине-2 | D27: Лук'янець Максим Миколайович ФОП РАХУНКИ_Глобине 2 Рахунок на оплату постачальника ІБ00-000305 від 23.01.2025 18:20:30 | E27: 205 | F27: 5106.5 | H27: 631 | K27: Д | L27: 204208.08
A28: 06.02.2025 | B28: Надходження товарів і послуг ІБ00-000478 від 06.02.2025 15:36:15 Оприходованы ТМЦ | C28: Обл. НДС Труба ПЕТ110*10 16атм чорна SDR11 Надходження товарів і послуг ІБ00-000478 від 06.02.2025 15:36:15 Глобине-2 | D28: Лук'янець Максим Миколайович ФОП РАХУНКИ_Глобине 2 Рахунок на оплату постачальника ІБ00-000305 від 23.01.2025 18:20:30 | E28: 205 | F28: 6656 | H28: 631 | K28: Д | L28: 210864.08
A29: 06.02.2025 | B29: Надходження дод. витрат ІБ00-000084 від 06.02.2025 16:00:00 Доп. расходы при поступлении товаров | C29: Обл. НДС Коліно 110/90 ПЕТ терморезист SDR11 Надходження товарів і послуг ІБ00-000478 від 06.02.2025 15:36:15 Глобине-2 | D29: Лук'янець Максим Миколайович ФОП РАХУНКИ_Глобине 2 Рахунок на оплату постачальника ІБ00-000305 від 23.01.2025 18:20:30 | E29: 205 | F29: 953.55 | H29: 631 | K29: Д | L29: 211817.63
A30: 06.02.2025 | B30: Надходження дод. витрат ІБ00-000084 від 06.02.2025 16:00:00 Доп. расходы при поступлении товаров | C30: Обл. НДС Коліно 125/90 ПЕТ терморезист SDR11 Надходження товарів і послуг ІБ00-000478 від 06.02.2025 15:36:15 Глобине-2 | D30: Лук'янець Максим Миколайович ФОП РАХУНКИ_Глобине 2 Рахунок на оплату постачальника ІБ00-000305 від 23.01.2025 18:20:30 | E30: 205 | F30: 665.15 | H30: 631 | K30: Д | L30: 212482.78
A31: 06.02.2025 | B31: Надходження дод. витрат ІБ00-000084 від 06.02.2025 16:00:00 Доп. расходы при поступлении товаров | C31: Обл. НДС Труба ПЕТ125*11,4 16атм чорна SDR11 Надходження товарів і послуг ІБ00-000478 від 06.02.2025 15:36:15 Глобине-2 | D31: Лук'янець Максим Миколайович ФОП РАХУНКИ_Глобине 2 Рахунок на оплату постачальника ІБ00-000305 від 23.01.2025 18:20:30 | E31: 205 | F31: 1365.51 | H31: 631 | K31: Д | L31: 213848.29
A32: 06.02.2025 | B32: Надходження дод. витрат ІБ00-000084 від 06.02.2025 16:00:00 Доп. расходы при поступлении товаров | C32: Обл. НДС Труба ПЕТ110*10 16атм чорна SDR11 Надходження товарів і послуг ІБ00-000478 від 06.02.2025 15:36:15 Глобине-2 | D32: Лук'янець Максим Миколайович ФОП РАХУНКИ_Глобине 2 Рахунок на оплату постачальника ІБ00-000305 від 23.01.2025 18:20:30 | E32: 205 | F32: 1615.79 | H32: 631 | K32: Д | L32: 215464.08
A33: 06.02.2025 | B33: Надходження товарів і послуг ІБ00-000464 від 06.02.2025 18:36:11 Оприходованы ТМЦ (Зачет аванса поставщику) | C33: Обл. НДС Пінополістирол фасад шаршавий 1200х600х20мм 0,264 куб м Надходження товарів і послуг ІБ00-000464 від 06.02.2025 18:36:11 Глобине-2 | D33: Лозовий Микола Миколайович ФОП РАХУНКИ_Глобино-2 Рахунок на оплату постачальника ІБ00-000266 від 30.01.2025 00:00:00 | E33: 205 | F33: 6370 | H33: 631 | K33: Д | L33: 221834.08
A34: 06.02.2025 | B34: Переміщення товарів ІБ00-000066 від 06.02.2025 18:36:12 Перемещение ТМЦ | C34: Обл. НДС Пінополістирол фасад шаршавий 1200х600х20мм 0,264 куб м Надходження товарів і послуг ІБ00-000464 від 06.02.2025 18:36:11 Котельна (Глобине) | D34: Обл. НДС Пінополістирол фасад шаршавий 1200х600х20мм 0,264 куб м Надходження товарів і послуг ІБ00-000464 від 06.02.2025 18:36:11 Глобине-2 | E34: 205 | H34: 205 | I34: 4550 | K34: Д | L34: 217284.08
A35: 06.02.2025 | B35: Переміщення товарів ІБ00-000067 від 06.02.2025 18:36:13 Перемещение ТМЦ | C35: Обл. НДС Пінополістирол фасад шаршавий 1200х600х20мм 0,264 куб м Надходження товарів і послуг ІБ00-000464 від 06.02.2025 18:36:11 Цех екстракції (Глобине) | D35: Обл. НДС Пінополістирол фасад шаршавий 1200х600х20мм 0,264 куб м Надходження товарів і послуг ІБ00-000464 від 06.02.2025 18:36:11 Глобине-2 | E35: 205 | H35: 205 | I35: 1820 | K35: Д | L35: 215464.08
A36: 06.02.2025 | B36: Надходження товарів і послуг ІБ00-000475 від 06.02.2025 18:36:14 Оприходованы ТМЦ (Зачет аванса поставщику) | C36: Обл. НДС Плінтус дуб леон 60 мм 2,5м №356 Надходження товарів і послуг ІБ00-000475 від 06.02.2025 18:36:14 Глобине-2 | D36: Лозовий Микола Миколайович ФОП РАХУНКИ_Глобино-2 Рахунок на оплату постачальника ІБ00-000267 від 30.01.2025 18:00:05 | E36: 205 | F36: 1120 | H36: 631 | K36: Д | L36: 216584.08
A37: 06.02.2025 | B37: Надходження товарів і послуг ІБ00-000475 від 06.02.2025 18:36:14 Оприходованы ТМЦ (Зачет аванса поставщику) | C37: Обл. НДС Кут внутр дуб леон 60 мм 2,5м №356 Надходження товарів і послуг ІБ00-000475 від 06.02.2025 18:36:14 Глобине-2 | D37: Лозовий Микола Миколайович ФОП РАХУНКИ_Глобино-2 Рахунок на оплату постачальника ІБ00-000267 від 30.01.2025 18:00:05 | E37: 205 | F37: 64 | H37: 631 | K37: Д | L37: 216648.08
A38: 06.02.2025 | B38: Надходження товарів і послуг ІБ00-000475 від 06.02.2025 18:36:14 Оприходованы ТМЦ (Зачет аванса поставщику) | C38: Обл. НДС З"єднання дуб леон 60 мм 2,5м №356 Надходження товарів і послуг ІБ00-000475 від 06.02.2025 18:36:14 Глобине-2 | D38: Лозовий Микола Миколайович ФОП РАХУНКИ_Глобино-2 Рахунок на оплату постачальника ІБ00-000267 від 30.01.2025 18:00:05 | E38: 205 | F38: 160 | H38: 631 | K38: Д | L38: 216808.08
A39: 06.02.2025 | B39: Надходження товарів і послуг ІБ00-000475 від 06.02.2025 18:36:14 Оприходованы ТМЦ (Зачет аванса поставщику) | C39: Обл. НДС Заглушка ліва дуб леон 60 мм 2,5м №356 Надходження товарів і послуг ІБ00-000475 від 06.02.2025 18:36:14 Глобине-2 | D39: Лозовий Микола Миколайович ФОП РАХУНКИ_Глобино-2 Рахунок на оплату постачальника ІБ00-000267 від 30.01.2025 18:00:05 | E39: 205 | F39: 16 | H39: 631 | K39: Д | L39: 216824.08
A40: 06.02.2025 | B40: Надходження товарів і послуг ІБ00-000475 від 06.02.2025 18:36:14 Оприходованы ТМЦ (Зачет аванса поставщику) | C40: Обл. НДС Заглушка права дуб леон 60 мм 2,5м №356 Надходження товарів і послуг ІБ00-000475 від 06.02.2025 18:36:14 Глобине-2 | D40: Лозовий Микола Миколайович ФОП РАХУНКИ_Глобино-2 Рахунок на оплату постачальника ІБ00-000267 від 30.01.2025 18:00:05 | E40: 205 | F40: 16 | H40: 631 | K40: Д | L40: 216840.08
...

Sheet Котельна
A1: Період | B1: Документ | C1: Аналітика Дт | D1: Аналітика Кт | E1: Дебет | H1: Кредит | K1: Поточне сальдо
E2: Рахунок | H2: Рахунок
A3: 01.02.2025 | B3: Переміщення товарів ІБ00-000055 від 01.02.2025 18:10:00 Перемещение ТМЦ | C3: Обл. НДС Бетон С20/25 W6 F75 P4 Надходження товарів і послуг ІБ00-000353 від 01.02.2025 18:00:04 Котельна (Глобине) | D3: Обл. НДС Бетон С20/25 W6 F75 P4 Надходження товарів і послуг ІБ00-000353 від 01.02.2025 18:00:04 Глобине-2 | E3: 205 | F3: 62370.47 | H3: 205 | K3: Д | L3: 591721
A4: 01.02.2025 | B4: Переміщення товарів ІБ00-000092 від 01.02.2025 18:10:14 Перемещение ТМЦ | C4: Обл. НДС Щебінь 20-40 Надходження товарів і послуг ІБ00-006224 від 12.12.2024 18:00:32 Котельна (Глобине) | D4: Обл. НДС Щебінь 20-40 Надходження товарів і послуг ІБ00-006224 від 12.12.2024 18:00:32 Цех екстракції (Глобине) | E4: 205 | F4: 26455.21 | H4: 205 | K4: Д | L4: 618176.21
A5: 01.02.2025 | B5: Переміщення товарів ІБ00-000093 від 01.02.2025 18:10:15 Перемещение ТМЦ | C5: Обл. НДС Пінополістирол екструдований 20х600х1200мм Надходження товарів і послуг ІБ00-006461 від 20.12.2024 18:18:13 Котельна (Глобине) | D5: Обл. НДС Пінополістирол екструдований 20х600х1200мм Надходження товарів і послуг ІБ00-006461 від 20.12.2024 18:18:13 СПК (Глобине) | E5: 205 | F5: 1269.83 | H5: 205 | K5: Д | L5: 619446.04
A6: 01.02.2025 | B6: Переміщення товарів ІБ00-000095 від 01.02.2025 18:10:17 Перемещение ТМЦ | C6: Обл. НДС Бетон С20/25 W6 F75 P4 доб-5 Надходження товарів і послуг ІБ00-000087 від 15.01.2025 18:05:18 Котельна (Глобине) | D6: Обл. НДС Бетон С20/25 W6 F75 P4 доб-5 Надходження товарів і послуг ІБ00-000087 від 15.01.2025 18:05:18 Насосна Градирня (Глобине) | E6: 205 | F6: 11554 | H6: 205 | K6: Д | L6: 631000.04
A7: 01.02.2025 | B7: Переміщення товарів ІБ00-000095 від 01.02.2025 18:10:17 Перемещение ТМЦ | C7: Обл. НДС Бетон С20/25 W6 F75 P4 доб-5 Надходження товарів і послуг ІБ00-000148 від 17.01.2025 17:59:51 Котельна (Глобине) | D7: Обл. НДС Бетон С20/25 W6 F75 P4 доб-5 Надходження товарів і послуг ІБ00-000148 від 17.01.2025 17:59:51 Насосна Градирня (Глобине) | E7: 205 | F7: 2504.18 | H7: 205 | K7: Д | L7: 633504.22
A8: 01.02.2025 | B8: Переміщення товарів ІБ00-000127 від 01.02.2025 18:10:52 Перемещение ТМЦ | C8: Обл. НДС Щебінь 40-70 Надходження товарів і послуг ІБ00-005821 від 05.11.2024 20:00:09 Насосна Градирня (Глобине) | D8: Обл. НДС Щебінь 40-70 Надходження товарів і послуг ІБ00-005821 від 05.11.2024 20:00:09 Котельна (Глобине) | E8: 205 | H8: 205 | I8: 20275.5 | K8: Д | L8: 613228.72
A9: 01.02.2025 | B9: Переміщення товарів ІБ00-000127 від 01.02.2025 18:10:52 Перемещение ТМЦ | C9: Обл. НДС Щебінь 40-70 Надходження товарів і послуг ІБ00-005854 від 11.11.2024 18:00:22 Насосна Градирня (Глобине) | D9: Обл. НДС Щебінь 40-70 Надходження товарів і послуг ІБ00-005854 від 11.11.2024 18:00:22 Котельна (Глобине) | E9: 205 | H9: 205 | I9: 11501 | K9: Д | L9: 601727.72
A10: 01.02.2025 | B10: Переміщення товарів ІБ00-000139 від 01.02.2025 18:11:37 Перемещение ТМЦ | C10: Обл. НДС Кутник 75*75 мм 12 м Надходження товарів і послуг ІБ00-006410 від 23.12.2024 17:16:14 Цех екстракції (Глобине) | D10: Обл. НДС Кутник 75*75 мм 12 м Надходження товарів і послуг ІБ00-006410 від 23.12.2024 17:16:14 Котельна (Глобине) | E10: 205 | H10: 205 | I10: 1043.42 | K10: Д | L10: 600684.3
A11: 03.02.2025 | B11: Надходження товарів і послуг ІБ00-000418 від 03.02.2025 18:10:14 Оприходованы ТМЦ | C11: Обл. НДС Арматура №18 А-400С/500С 12 м Надходження товарів і послуг ІБ00-000418 від 03.02.2025 18:10:14 Котельна (Глобине) | D11: МЕТАЛ ХОЛДІНГ ТРЕЙД ТОВ Договір 01/467/24 від 06.09.2024_Глобине-2 Рахунок на оплату постачальника ІБ00-000364 від 31.01.2025 23:20:20 | E11: 205 | F11: 15266.77 | H11: 631 | K11: Д | L11: 615951.07
A12: 03.02.2025 | B12: Надходження дод. витрат ІБ00-000068 від 03.02.2025 18:10:15 Доп. расходы при поступлении товаров | C12: Обл. НДС Арматура №18 А-400С/500С 12 м Надходження товарів і послуг ІБ00-000418 від 03.02.2025 18:10:14 Котельна (Глобине) | D12: МЕТАЛ ХОЛДІНГ ТРЕЙД ТОВ Договір 01/467/24 від 06.09.2024_Глобине-2 Рахунок на оплату постачальника ІБ00-000364 від 31.01.2025 23:20:20 | E12: 205 | F12: 7710 | H12: 631 | K12: Д | L12: 623661.07
A13: 03.02.2025 | B13: Надходження товарів і послуг ІБ00-000503 від 03.02.2025 18:10:29 Оприходованы ТМЦ (Зачет аванса поставщику) | C13: Обл. НДС Гвинт 3,5*9,5 самосв цб нпкр Надходження товарів і послуг ІБ00-000503 від 03.02.2025 18:10:29 Котельна (Глобине) | D13: Солді і Ко ПАТ Дог № 378542-55/19 від 21.01.2019 р. РАХ_Глобине-2 Рахунок на оплату постачальника ІБ00-000303 від 23.01.2025 18:20:29 | E13: 205 | F13: 234.33 | H13: 631 | K13: Д | L13: 623895.4
A14: 05.02.2025 | B14: Списання товарів ІБ00-000060 від 05.02.2025 00:00:00 Списаны ТМЦ | C14: Обл. НДС Виробничий (Глобине-2) Глобине-2 Прямі материальні виробничі витрати крім зворотніх відходів | D14: Обл. НДС Шуруп г/к по дереву 4,2*76 мм Надходження товарів і послуг ІБ00-000089 від 01.01.2025 18:00:23 Котельна (Глобине) | E14: 231 | H14: 205 | I14: 91.25 | K14: Д | L14: 623804.15
A15: 05.02.2025 | B15: Списання товарів ІБ00-000060 від 05.02.2025 00:00:00 Списаны ТМЦ | C15: Обл. НДС Виробничий (Глобине-2) Глобине-2 Прямі материальні виробничі витрати крім зворотніх відходів | D15: Обл. НДС Шуруп г/к по дереву 4,2*76 мм Надходження товарів і послуг ІБ00-000111 від 14.01.2025 18:05:23 Котельна (Глобине) | E15: 231 | H15: 205 | I15: 182.5 | K15: Д | L15: 623621.65
A16: 05.02.2025 | B16: Вимога-накладна ІБ00-000068 від 05.02.2025 18:15:26 Списаны ТМЦ | C16: Обл. НДС Виробничий (Глобине-2) Глобине-2 Прямі материальні виробничі витрати крім зворотніх відходів | D16: Обл. НДС Арматура №12 А240С L=6000 мм Надходження товарів і послуг ІБ00-004646 від 02.10.2024 17:19:54 Котельна (Глобине) | E16: 231 | H16: 205 | I16: 2238.33 | K16: Д | L16: 621383.32
A17: 05.02.2025 | B17: Вимога-накладна ІБ00-000069 від 05.02.2025 18:15:29 Списаны ТМЦ | C17: Обл. НДС Виробничий (Глобине-2) Глобине-2 Прямі материальні виробничі витрати крім зворотніх відходів | D17: Обл. НДС Плівка п/е рукав 1500*100 Надходження товарів і послуг ІБ00-005781 від 19.11.2024 17:51:41 Котельна (Глобине) | E17: 231 | H17: 205 | I17: 1351.75 | K17: Д | L17: 620031.57
A18: 05.02.2025 | B18: Вимога-накладна ІБ00-000069 від 05.02.2025 18:15:29 Списаны ТМЦ | C18: Обл. НДС Виробничий (Глобине-2) Глобине-2 Прямі материальні виробничі витрати крім зворотніх відходів | D18: Обл. НДС Бетон С20/25 W6 F75 P4 Надходження товарів і послуг ІБ00-000353 від 01.02.2025 18:00:04 Котельна (Глобине) | E18: 231 | H18: 205 | I18: 62370.47 | K18: Д | L18: 557661.1
A19: 05.02.2025 | B19: Вимога-накладна ІБ00-000069 від 05.02.2025 18:15:29 Списаны ТМЦ | C19: Обл. НДС Виробничий (Глобине-2) Глобине-2 Прямі материальні виробничі витрати крім зворотніх відходів | D19: Обл. НДС Бетон С20/25 W6 F75 P4 доб-5 Надходження товарів і послуг ІБ00-000087 від 15.01.2025 18:05:18 Котельна (Глобине) | E19: 231 | H19: 205 | I19: 4197.95 | K19: Д | L19: 553463.15
A20: 05.02.2025 | B20: Вимога-накладна ІБ00-000069 від 05.02.2025 18:15:29 Списаны ТМЦ | C20: Обл. НДС Виробничий (Глобине-2) Глобине-2 Прямі материальні виробничі витрати крім зворотніх відходів | D20: Обл. НДС Бетон С20/25 W6 F75 P4 доб-5 Надходження товарів і послуг ІБ00-000087 від 15.01.2025 18:05:18 Котельна (Глобине) | E20: 231 | H20: 205 | I20: 7356.05 | K20: Д | L20: 546107.1
A21: 05.02.2025 | B21: Вимога-накладна ІБ00-000069 від 05.02.2025 18:15:29 Списаны ТМЦ | C21: Обл. НДС Виробничий (Глобине-2) Глобине-2 Прямі материальні виробничі витрати крім зворотніх відходів | D21: Обл. НДС Бетон С20/25 W6 F75 P4 доб-5 Надходження товарів і послуг ІБ00-000148 від 17.01.2025 17:59:51 Котельна (Глобине) | E21: 231 | H21: 205 | I21: 2504.18 | K21: Д | L21: 543602.92
A22: 05.02.2025 | B22: Вимога-накладна ІБ00-000069 від 05.02.2025 18:15:29 Списаны ТМЦ | C22: Обл. НДС Виробничий (Глобине-2) Глобине-2 Прямі материальні виробничі витрати крім зворотніх відходів | D22: Обл. НДС Кутник 40*40*4,0 мм 6 м Надходження товарів і послуг ІБ00-006410 від 23.12.2024 17:16:14 Котельна (Глобине) | E22: 231 | H22: 205 | I22: 5382.3 | K22: Д | L22: 538220.62
A23: 05.02.2025 | B23: Вимога-накладна ІБ00-000069 від 05.02.2025 18:15:29 Списаны ТМЦ | C23: Обл. НДС Виробничий (Глобине-2) Глобине-2 Прямі материальні виробничі витрати крім зворотніх відходів | D23: Обл. НДС Щебінь 20-40 Надходження товарів і послуг ІБ00-006224 від 12.12.2024 18:00:32 Котельна (Глобине) | E23: 231 | H23: 205 | I23: 26455.21 | K23: Д | L23: 511765.41
A24: 05.02.2025 | B24: Вимога-накладна ІБ00-000069 від 05.02.2025 18:15:29 Списаны ТМЦ | C24: Обл. НДС Виробничий (Глобине-2) Глобине-2 Прямі материальні виробничі витрати крім зворотніх відходів | D24: Обл. НДС Щебінь 20-40 Надходження товарів і послуг ІБ00-006545 від 26.12.2024 12:00:00 Котельна (Глобине) | E24: 231 | H24: 205 | I24: 2071.92 | K24: Д | L24: 509693.49
A25: 05.02.2025 | B25: Вимога-накладна ІБ00-000069 від 05.02.2025 18:15:29 Списаны ТМЦ | C25: Обл. НДС Виробничий (Глобине-2) Глобине-2 Прямі материальні виробничі витрати крім зворотніх відходів | D25: Обл. НДС Щебінь 20-40 Надходження товарів і послуг ІБ00-006545 від 26.12.2024 12:00:00 Котельна (Глобине) | E25: 231 | H25: 205 | I25: 12149.74 | K25: Д | L25: 497543.75
A26: 05.02.2025 | B26: Вимога-накладна ІБ00-000069 від 05.02.2025 18:15:29 Списаны ТМЦ | C26: Обл. НДС Виробничий (Глобине-2) Глобине-2 Прямі материальні виробничі витрати крім зворотніх відходів | D26: Обл. НДС Пінополістирол екструдований 20х600х1200мм Надходження товарів і послуг ІБ00-006461 від 20.12.2024 18:18:13 Котельна (Глобине) | E26: 231 | H26: 205 | I26: 732.59 | K26: Д | L26: 496811.16
A27: 06.02.2025 | B27: Надходження товарів і послуг ІБ00-000457 від 06.02.2025 15:36:10 Оприходованы ТМЦ | C27: Обл. НДС Труба ПЕТ110*10 16атм чорна SDR11 Надходження товарів і послуг ІБ00-000457 від 06.02.2025 15:36:10 Котельна (Глобине) | D27: Лук'янець Максим Миколайович ФОП РАХУНКИ_Глобине 2 Рахунок на оплату постачальника ІБ00-000304 від 30.01.2025 18:03:04 | E27: 205 | F27: 652.5 | H27: 631 | K27: Д | L27: 497463.66
A28: 06.02.2025 | B28: Надходження товарів і послуг ІБ00-000457 від 06.02.2025 15:36:10 Оприходованы ТМЦ (Зачет аванса поставщику) | C28: Обл. НДС Труба ПЕТ110*10 16атм чорна SDR11 Надходження товарів і послуг ІБ00-000457 від 06.02.2025 15:36:10 Котельна (Глобине) | D28: Лук'янець Максим Миколайович ФОП РАХУНКИ_Глобине 2 Рахунок на оплату постачальника ІБ00-000304 від 30.01.2025 18:03:04 | E28: 205 | F28: 3507.5 | H28: 631 | K28: Д | L28: 500971.16
A29: 06.02.2025 | B29: Надходження товарів і послуг ІБ00-000457 від 06.02.2025 15:36:10 Оприходованы ТМЦ | C29: Обл. НДС Коліно 110/90 ПЕТ терморезист SDR11 Надходження товарів і послуг ІБ00-000457 від 06.02.2025 15:36:10 Котельна (Глобине) | D29: Лук'янець Максим Миколайович ФОП РАХУНКИ_Глобине 2 Рахунок на оплату постачальника ІБ00-000304 від 30.01.2025 18:03:04 | E29: 205 | F29: 1655 | H29: 631 | K29: Д | L29: 502626.16
A30: 06.02.2025 | B30: Надходження дод. витрат ІБ00-000085 від 06.02.2025 16:00:00 Доп. расходы при поступлении товаров | C30: Обл. НДС Труба ПЕТ110*10 16атм чорна SDR11 Надходження товарів і послуг ІБ00-000457 від 06.02.2025 15:36:10 Котельна (Глобине) | D30: Лук'янець Максим Миколайович ФОП РАХУНКИ_Глобине 2 Рахунок на оплату постачальника ІБ00-000304 від 30.01.2025 18:03:04 | E30: 205 | F30: 858.47 | H30: 631 | K30: Д | L30: 503484.63
A31: 06.02.2025 | B31: Надходження дод. витрат ІБ00-000085 від 06.02.2025 16:00:00 Доп. расходы при поступлении товаров | C31: Обл. НДС Коліно 110/90 ПЕТ терморезист SDR11 Надходження товарів і послуг ІБ00-000457 від 06.02.2025 15:36:10 Котельна (Глобине) | D31: Лук'янець Максим Миколайович ФОП РАХУНКИ_Глобине 2 Рахунок на оплату постачальника ІБ00-000304 від 30.01.2025 18:03:04 | E31: 205 | F31: 341.53 | H31: 631 | K31: Д | L31: 503826.16
A32: 06.02.2025 | B32: Переміщення товарів ІБ00-000066 від 06.02.2025 18:36:12 Перемещение ТМЦ | C32: Обл. НДС Пінополістирол фасад шаршавий 1200х600х20мм 0,264 куб м Надходження товарів і послуг ІБ00-000464 від 06.02.2025 18:36:11 Котельна (Глобине) | D32: Обл. НДС Пінополістирол фасад шаршавий 1200х600х20мм 0,264 куб м Надходження товарів і послуг ІБ00-000464 від 06.02.2025 18:36:11 Глобине-2 | E32: 205 | F32: 4550 | H32: 205 | K32: Д | L32: 508376.16
A33: 06.02.2025 | B33: Переміщення товарів ІБ00-000069 від 06.02.2025 18:36:17 Перемещение ТМЦ | C33: Обл. НДС Коліно 125/90 ПЕТ терморезист SDR11 Надходження товарів і послуг ІБ00-000478 від 06.02.2025 15:36:15 Котельна (Глобине) | D33: Обл. НДС Коліно 125/90 ПЕТ терморезист SDR11 Надходження товарів і послуг ІБ00-000478 від 06.02.2025 15:36:15 Глобине-2 | E33: 205 | F33: 3405.15 | H33: 205 | K33: Д | L33: 511781.31
A34: 06.02.2025 | B34: Переміщення товарів ІБ00-000069 від 06.02.2025 18:36:17 Перемещение ТМЦ | C34: Обл. НДС Труба ПЕТ125*11,4 16атм чорна SDR11 Надходження товарів і послуг ІБ00-000478 від 06.02.2025 15:36:15 Котельна (Глобине) | D34: Обл. НДС Труба ПЕТ125*11,4 16атм чорна SDR11 Надходження товарів і послуг ІБ00-000478 від 06.02.2025 15:36:15 Глобине-2 | E34: 205 | F34: 6990.51 | H34: 205 | K34: Д | L34: 518771.82
A35: 06.02.2025 | B35: Переміщення товарів ІБ00-000159 від 06.02.2025 18:36:52 Перемещение ТМЦ | C35: Обл. НДС Клей-піна монтажна , 860 мл Надходження товарів і послуг ІБ00-000776 від 06.02.2025 18:36:51 Котельна (Глобине) | D35: Обл. НДС Клей-піна монтажна , 860 мл Надходження товарів і послуг ІБ00-000776 від 06.02.2025 18:36:51 Глобине-2 | E35: 205 | F35: 1251.43 | H35: 205 | K35: Д | L35: 520023.25
A36: 07.02.2025 | B36: Надходження товарів і послуг ІБ00-000504 від 07.02.2025 18:30:23 Оприходованы ТМЦ (Зачет аванса поставщику) | C36: Обл. НДС Стрижень М 12 8.8 1м цб DIN 975 Надходження товарів і послуг ІБ00-000504 від 07.02.2025 18:30:23 Котельна (Глобине) | D36: Солді і Ко ПАТ Дог № 378542-55/19 від 21.01.2019 р. РАХ_Глобине-2 Рахунок на оплату постачальника ІБ00-000360 від 31.01.2025 23:20:15 | E36: 205 | F36: 54.07 | H36: 631 | K36: Д | L36: 520077.32
A37: 07.02.2025 | B37: Надходження товарів і послуг ІБ00-000504 від 07.02.2025 18:30:23 Оприходованы ТМЦ (Зачет аванса поставщику) | C37: Обл. НДС Стрижень М 16 8.8 1м цб DIN 975 Надходження товарів і послуг ІБ00-000504 від 07.02.2025 18:30:23 Котельна (Глобине) | D37: Солді і Ко ПАТ Дог № 378542-55/19 від 21.01.2019 р. РАХ_Глобине-2 Рахунок на оплату постачальника ІБ00-000360 від 31.01.2025 23:20:15 | E37: 205 | F37: 302.83 | H37: 631 | K37: Д | L37: 520380.15
A38: 08.02.2025 | B38: Переміщення товарів ІБ00-000097 від 08.02.2025 10:20:00 Перемещение ТМЦ | C38: Обл. НДС Бетон С20/25 W6 F75 P4 доб-10 Надходження товарів і послуг ІБ00-000481 від 06.02.2025 18:36:18 Котельна (Глобине) | D38: Обл. НДС Бетон С20/25 W6 F75 P4 доб-10 Надходження товарів і послуг ІБ00-000481 від 06.02.2025 18:36:18 Глобине-2 | E38: 205 | F38: 3710.66 | H38: 205 | K38: Д | L38: 524090.81
... A40: 14.02.2025 | B40: Переміщення товарів ІБ00-000116 від 14.02.2025 10:10:00 Перемещение ТМЦ | C40: Обл. НДС Прокат арматурний № 8 мм А500С 12м Надходження товарів і послуг ІБ00-000546 від 14.02.2025 10:00:00 Котельна (Глобине) | D40: Обл. НДС Прокат арматурний № 8 мм А500С 12м Надходження товарів і послуг ІБ00-000546 від 14.02.2025 10:00:00 Глобине-2 | E40: 205 | F40: 35550 | H40: 205 | K40: Д | L40: 651869.58
A41: 20.02.2025 | B41: Списання товарів ІБ00-000076 від 20.02.2025 00:00:00 Списаны ТМЦ | C41: Обл. НДС Виробничий (Глобине-2) Глобине-2 Прямі материальні виробничі витрати крім зворотніх відходів | D41: Обл. НДС Гвинт 3,5*9,5 самосв цб нпкр Надходження товарів і послуг ІБ00-000503 від 03.02.2025 18:10:29 Котельна (Глобине) | E41: 231 | H41: 205 | I41: 234.33 | K41: Д | L41: 651635.25
...

Sheet Насосна Градирня 
A1: Період | B1: Документ | C1: Аналітика Дт | D1: Аналітика Кт | E1: Дебет | H1: Кредит | K1: Поточне сальдо
E2: Рахунок | H2: Рахунок
A3: 01.02.2025 | B3: Переміщення товарів ІБ00-000095 від 01.02.2025 18:10:17 Перемещение ТМЦ | C3: Обл. НДС Бетон С20/25 W6 F75 P4 доб-5 Надходження товарів і послуг ІБ00-000087 від 15.01.2025 18:05:18 Котельна (Глобине) | D3: Обл. НДС Бетон С20/25 W6 F75 P4 доб-5 Надходження товарів і послуг ІБ00-000087 від 15.01.2025 18:05:18 Насосна Градирня (Глобине) | E3: 205 | H3: 205 | I3: 11554 | K3: Д | L3: 49789.71
A4: 01.02.2025 | B4: Переміщення товарів ІБ00-000095 від 01.02.2025 18:10:17 Перемещение ТМЦ | C4: Обл. НДС Бетон С20/25 W6 F75 P4 доб-5 Надходження товарів і послуг ІБ00-000148 від 17.01.2025 17:59:51 Котельна (Глобине) | D4: Обл. НДС Бетон С20/25 W6 F75 P4 доб-5 Надходження товарів і послуг ІБ00-000148 від 17.01.2025 17:59:51 Насосна Градирня (Глобине) | E4: 205 | H4: 205 | I4: 2504.18 | K4: Д | L4: 47285.53
A5: 01.02.2025 | B5: Переміщення товарів ІБ00-000127 від 01.02.2025 18:10:52 Перемещение ТМЦ | C5: Обл. НДС Щебінь 40-70 Надходження товарів і послуг ІБ00-005821 від 05.11.2024 20:00:09 Насосна Градирня (Глобине) | D5: Обл. НДС Щебінь 40-70 Надходження товарів і послуг ІБ00-005821 від 05.11.2024 20:00:09 Котельна (Глобине) | E5: 205 | F5: 20275.5 | H5: 205 | K5: Д | L5: 67561.03
A6: 01.02.2025 | B6: Переміщення товарів ІБ00-000127 від 01.02.2025 18:10:52 Перемещение ТМЦ | C6: Обл. НДС Щебінь 40-70 Надходження товарів і послуг ІБ00-005854 від 11.11.2024 18:00:22 Насосна Градирня (Глобине) | D6: Обл. НДС Щебінь 40-70 Надходження товарів і послуг ІБ00-005854 від 11.11.2024 18:00:22 Котельна (Глобине) | E6: 205 | F6: 11501 | H6: 205 | K6: Д | L6: 79062.03
A7: 12.02.2025 | B7: Надходження товарів і послуг ІБ00-000538 від 12.02.2025 18:02:48 Оприходованы ТМЦ | C7: Обл. НДС Анкер М 10*100/35 цб/цж одноконусний Надходження товарів і послуг ІБ00-000538 від 12.02.2025 18:02:48 Насосна Градирня (Глобине) | D7: Солді і Ко ПАТ Дог № 378542-55/19 від 21.01.2019 р. РАХ_Глобине-2 Рахунок на оплату постачальника ІБ00-000471 від 12.02.2025 18:02:47 | E7: 205 | F7: 568.89 | H7: 631 | K7: Д | L7: 79630.92
A8: 20.02.2025 | B8: Списання товарів ІБ00-000080 від 20.02.2025 00:00:00 Списаны ТМЦ | C8: Обл. НДС Виробничий (Глобине-2) Глобине-2 Прямі материальні виробничі витрати крім зворотніх відходів | D8: Обл. НДС Шуруп г/к по дереву 3,5*55 мм Надходження товарів і послуг ІБ00-000089 від 01.01.2025 18:00:23 Насосна Градирня (Глобине) | E8: 231 | H8: 205 | I8: 97.55 | K8: Д | L8: 79533.37
A9: 20.02.2025 | B9: Списання товарів ІБ00-000080 від 20.02.2025 00:00:00 Списаны ТМЦ | C9: Обл. НДС Виробничий (Глобине-2) Глобине-2 Прямі материальні виробничі витрати крім зворотніх відходів | D9: Обл. НДС Шуруп г/к по дереву 4,2*76 мм Надходження товарів і послуг ІБ00-000089 від 01.01.2025 18:00:23 Насосна Градирня (Глобине) | E9: 231 | H9: 205 | I9: 91.25 | K9: Д | L9: 79442.12
A10: 20.02.2025 | B10: Списання товарів ІБ00-000080 від 20.02.2025 00:00:00 Списаны ТМЦ | C10: Обл. НДС Виробничий (Глобине-2) Глобине-2 Прямі материальні виробничі витрати крім зворотніх відходів | D10: Обл. НДС Дюбель з уд.ш 6*80 Надходження товарів і послуг ІБ00-000109 від 14.01.2025 18:05:21 Насосна Градирня (Глобине) | E10: 231 | H10: 205 | I10: 77 | K10: Д | L10: 79365.12
A11: 20.02.2025 | B11: Списання товарів ІБ00-000080 від 20.02.2025 00:00:00 Списаны ТМЦ | C11: Обл. НДС Виробничий (Глобине-2) Глобине-2 Прямі материальні виробничі витрати крім зворотніх відходів | D11: Обл. НДС Дюбель-цвях 3,7*50 DN50 Надходження товарів і послуг ІБ00-000089 від 01.01.2025 18:00:23 Насосна Градирня (Глобине) | E11: 231 | H11: 205 | I11: 144.8 | K11: Д | L11: 79220.32
A12: 20.02.2025 | B12: Списання товарів ІБ00-000080 від 20.02.2025 00:00:00 Списаны ТМЦ | C12: Обл. НДС Виробничий (Глобине-2) Глобине-2 Прямі материальні виробничі витрати крім зворотніх відходів | D12: Обл. НДС Анкер М 10*100/35 цб/цж одноконусний Надходження товарів і послуг ІБ00-000538 від 12.02.2025 18:02:48 Насосна Градирня (Глобине) | E12: 231 | H12: 205 | I12: 568.89 | K12: Д | L12: 78651.43
A13: 20.02.2025 | B13: Вимога-накладна ІБ00-000115 від 20.02.2025 00:00:00 Списаны ТМЦ | C13: Обл. НДС Виробничий (Глобине-2) Глобине-2 Прямі материальні виробничі витрати крім зворотніх відходів | D13: Обл. НДС Болт М16*45 DIN 933 Надходження товарів і послуг ІБ00-000206 від 22.01.2025 19:00:01 Насосна Градирня (Глобине) | E13: 231 | H13: 205 | I13: 607.24 | K13: Д | L13: 78044.19
A14: 20.02.2025 | B14: Вимога-накладна ІБ00-000115 від 20.02.2025 00:00:00 Списаны ТМЦ | C14: Обл. НДС Виробничий (Глобине-2) Глобине-2 Прямі материальні виробничі витрати крім зворотніх відходів | D14: Обл. НДС Болт М16*50 DIN 933 оц. 5,8 Надходження товарів і послуг ІБ00-000206 від 22.01.2025 19:00:01 Насосна Градирня (Глобине) | E14: 231 | H14: 205 | I14: 362.58 | K14: Д | L14: 77681.61
A15: 20.02.2025 | B15: Вимога-накладна ІБ00-000115 від 20.02.2025 00:00:00 Списаны ТМЦ | C15: Обл. НДС Виробничий (Глобине-2) Глобине-2 Прямі материальні виробничі витрати крім зворотніх відходів | D15: Обл. НДС Болт М16*65 DIN 933 цб Надходження товарів і послуг ІБ00-000206 від 22.01.2025 19:00:01 Насосна Градирня (Глобине) | E15: 231 | H15: 205 | I15: 298.62 | K15: Д | L15: 77382.99
A16: 20.02.2025 | B16: Вимога-накладна ІБ00-000115 від 20.02.2025 00:00:00 Списаны ТМЦ | C16: Обл. НДС Виробничий (Глобине-2) Глобине-2 Прямі материальні виробничі витрати крім зворотніх відходів | D16: Обл. НДС Болт М16*90 DIN 933 з шест.голівкою цб Надходження товарів і послуг ІБ00-000206 від 22.01.2025 19:00:01 Насосна Градирня (Глобине) | E16: 231 | H16: 205 | I16: 209.6 | K16: Д | L16: 77173.39
A17: 20.02.2025 | B17: Вимога-накладна ІБ00-000115 від 20.02.2025 00:00:00 Списаны ТМЦ | C17: Обл. НДС Виробничий (Глобине-2) Глобине-2 Прямі материальні виробничі витрати крім зворотніх відходів | D17: Обл. НДС Гайка М16 DIN 934 Надходження товарів і послуг ІБ00-000206 від 22.01.2025 19:00:01 Насосна Градирня (Глобине) | E17: 231 | H17: 205 | I17: 552.9 | K17: Д | L17: 76620.49
A18: 20.02.2025 | B18: Вимога-накладна ІБ00-000115 від 20.02.2025 00:00:00 Списаны ТМЦ | C18: Обл. НДС Виробничий (Глобине-2) Глобине-2 Прямі материальні виробничі витрати крім зворотніх відходів | D18: Обл. НДС Шайба 16 DIN125 Надходження товарів і послуг ІБ00-000206 від 22.01.2025 19:00:01 Насосна Градирня (Глобине) | E18: 231 | H18: 205 | I18: 254.54 | K18: Д | L18: 76365.95
A19: 20.02.2025 | B19: Вимога-накладна ІБ00-000083 від 20.02.2025 10:00:00 Списаны ТМЦ | C19: Обл. НДС Виробничий (Глобине-2) Глобине-2 Прямі материальні виробничі витрати крім зворотніх відходів | D19: Обл. НДС Бетон С20/25 W6 F75 P4 доб-5 Надходження товарів і послуг ІБ00-000148 від 17.01.2025 17:59:51 Насосна Градирня (Глобине) | E19: 231 | H19: 205 | I19: 5517.68 | K19: Д | L19: 70848.27
... A25: 20.02.2025 | B25: Вимога-накладна ІБ00-000088 від 20.02.2025 18:11:04 Списаны ТМЦ | C25: Обл. НДС Виробничий (Глобине-2) Глобине-2 Прямі материальні виробничі витрати крім зворотніх відходів | D25: Обл. НДС Арматура №16 А500С L=12000 мм Надходження товарів і послуг ІБ00-004378 від 21.09.2024 23:45:38 Насосна Градирня (Глобине) | E25: 231 | H25: 205 | I25: 2457.33 | K25: Д | L25: 14602.22
A26: Обороти за період та сальдо на кінець | E26: 32345.39 | H26: 79086.88 | K26: Д | L26: 14602.22
J28: =SUBTOTAL(9,I8:J25)*1.2 -> 78034.44

Sheet Пункт фасування
A1: Період | B1: Документ | C1: Аналітика Дт | D1: Аналітика Кт | E1: Дебет | H1: Кредит | K1: Поточне сальдо
E2: Рахунок | H2: Рахунок
A3: 13.02.2025 | B3: Переміщення товарів ІБ00-000106 від 13.02.2025 18:20:00 Перемещение ТМЦ | C3: Обл. НДС Провід ПВС 4*2,5 Expert Power Надходження товарів і послуг ІБ00-000543 від 13.02.2025 18:15:01 Пункт фасування та зберігання в бігбегах (Глобине) | D3: Обл. НДС Провід ПВС 4*2,5 Expert Power Надходження товарів і послуг ІБ00-000543 від 13.02.2025 18:15:01 Глобине-2 | E3: 205 | F3: 7387.5 | H3: 205 | K3: Д | L3: 7387.5
A4: 14.02.2025 | B4: Переміщення товарів ІБ00-000113 від 14.02.2025 10:10:00 Перемещение ТМЦ | C4: Обл. НДС Прокат сталевий круглий (кл. А240С) ф10мм, ст.3пс, міра 6м Надходження товарів і послуг ІБ00-000546 від 14.02.2025 10:00:00 Пункт фасування та зберігання в бігбегах (Глобине) | D4: Обл. НДС Прокат сталевий круглий (кл. А240С) ф10мм, ст.3пс, міра 6м Надходження товарів і послуг ІБ00-000546 від 14.02.2025 10:00:00 Глобине-2 | E4: 205 | F4: 19240 | H4: 205 | K4: Д | L4: 26627.5
A5: 14.02.2025 | B5: Переміщення товарів ІБ00-000113 від 14.02.2025 10:10:00 Перемещение ТМЦ | C5: Обл. НДС Прокат сталевий круглий (кл. А240С) ф12мм, ст.3пс, міра 6м Надходження товарів і послуг ІБ00-000546 від 14.02.2025 10:00:00 Пункт фасування та зберігання в бігбегах (Глобине) | D5: Обл. НДС Прокат сталевий круглий (кл. А240С) ф12мм, ст.3пс, міра 6м Надходження товарів і послуг ІБ00-000546 від 14.02.2025 10:00:00 Глобине-2 | E5: 205 | F5: 7800 | H5: 205 | K5: Д | L5: 34427.5
A6: 14.02.2025 | B6: Переміщення товарів ІБ00-000113 від 14.02.2025 10:10:00 Перемещение ТМЦ | C6: Обл. НДС Прокат арматурний №12 мм А500С 12м Надходження товарів і послуг ІБ00-000546 від 14.02.2025 10:00:00 Пункт фасування та зберігання в бігбегах (Глобине) | D6: Обл. НДС Прокат арматурний №12 мм А500С 12м Надходження товарів і послуг ІБ00-000546 від 14.02.2025 10:00:00 Глобине-2 | E6: 205 | F6: 150866.67 | H6: 205 | K6: Д | L6: 185294.17
A7: 14.02.2025 | B7: Переміщення товарів ІБ00-000113 від 14.02.2025 10:10:00 Перемещение ТМЦ | C7: Обл. НДС Прокат арматурний №14 мм А500С, 12 м Надходження товарів і послуг ІБ00-000546 від 14.02.2025 10:00:00 Пункт фасування та зберігання в бігбегах (Глобине) | D7: Обл. НДС Прокат арматурний №14 мм А500С, 12 м Надходження товарів і послуг ІБ00-000546 від 14.02.2025 10:00:00 Глобине-2 | E7: 205 | F7: 52958.33 | H7: 205 | K7: Д | L7: 238252.5
A8: 14.02.2025 | B8: Переміщення товарів ІБ00-000113 від 14.02.2025 10:10:00 Перемещение ТМЦ | C8: Обл. НДС Дріт 1,2 мм термооброблений Надходження товарів і послуг ІБ00-000546 від 14.02.2025 10:00:00 Пункт фасування та зберігання в бігбегах (Глобине) | D8: Обл. НДС Дріт 1,2 мм термооброблений Надходження товарів і послуг ІБ00-000546 від 14.02.2025 10:00:00 Глобине-2 | E8: 205 | F8: 2284.92 | H8: 205 | K8: Д | L8: 240537.42
A9: 25.02.2025 | B9: Переміщення товарів ІБ00-000147 від 25.02.2025 18:20:01 Перемещение ТМЦ | C9: Обл. НДС Цвяхи 100*4,0 10кг Надходження товарів і послуг ІБ00-000748 від 25.02.2025 18:19:56 Пункт фасування та зберігання в бігбегах (Глобине) | D9: Обл. НДС Цвяхи 100*4,0 10кг Надходження товарів і послуг ІБ00-000748 від 25.02.2025 18:19:56 Глобине-2 | E9: 205 | F9: 150.45 | H9: 205 | K9: Д | L9: 240687.87
A10: 25.02.2025 | B10: Переміщення товарів ІБ00-000147 від 25.02.2025 18:20:01 Перемещение ТМЦ | C10: Обл. НДС Шуруп г/к по дереву 3,5*55 мм Надходження товарів і послуг ІБ00-000711 від 18.02.2025 20:00:44 Пункт фасування та зберігання в бігбегах (Глобине) | D10: Обл. НДС Шуруп г/к по дереву 3,5*55 мм Надходження товарів і послуг ІБ00-000711 від 18.02.2025 20:00:44 Глобине-2 | E10: 205 | F10: 198.1 | H10: 205 | K10: Д | L10: 240885.97
A11: 28.02.2025 | B11: Переміщення товарів ІБ00-000177 від 28.02.2025 10:00:00 Перемещение ТМЦ | C11: Обл. НДС Прокат арматурний №12 мм А500С 12м Надходження товарів і послуг ІБ00-000546 від 14.02.2025 10:00:00 Котельна (Глобине) | D11: Обл. НДС Прокат арматурний №12 мм А500С 12м Надходження товарів і послуг ІБ00-000546 від 14.02.2025 10:00:00 Пункт фасування та зберігання в бігбегах (Глобине) | E11: 205 | H11: 205 | I11: 95945 | K11: Д | L11: 144940.97
A12: Обороти за період та сальдо на кінець | E12: 240885.97 | H12: 95945 | K12: Д | L12: 144940.97

Sheet Резервуар для зберігання
A1: Період | B1: Документ | C1: Аналітика Дт | D1: Аналітика Кт | E1: Дебет | H1: Кредит | K1: Поточне сальдо
E2: Рахунок | H2: Рахунок
A3: 01.02.2025 | B3: Переміщення товарів ІБ00-000130 від 01.02.2025 00:00:00 Перемещение ТМЦ | C3: Обл. НДС Щебінь 20-40 Надходження товарів і послуг ІБ00-006196 від 10.12.2024 18:00:19 Резервуар для зберігання розчинника(Глобине) | D3: Обл. НДС Щебінь 20-40 Надходження товарів і послуг ІБ00-006196 від 10.12.2024 18:00:19 Цех екстракції (Глобине) | E3: 205 | F3: 4510.67 | H3: 205 | K3: Д | L3: 4510.67
A4: 01.02.2025 | B4: Переміщення товарів ІБ00-000130 від 01.02.2025 00:00:00 Перемещение ТМЦ | C4: Обл. НДС Щебінь 20-40 Надходження товарів і послуг ІБ00-006201 від 11.12.2024 18:00:22 Резервуар для зберігання розчинника(Глобине) | D4: Обл. НДС Щебінь 20-40 Надходження товарів і послуг ІБ00-006201 від 11.12.2024 18:00:22 Цех екстракції (Глобине) | E4: 205 | F4: 95477.16 | H4: 205 | K4: Д | L4: 99987.83
A5: 01.02.2025 | B5: Переміщення товарів ІБ00-000130 від 01.02.2025 00:00:00 Перемещение ТМЦ | C5: Обл. НДС Щебінь 20-40 Надходження товарів і послуг ІБ00-006224 від 12.12.2024 18:00:32 Резервуар для зберігання розчинника(Глобине) | D5: Обл. НДС Щебінь 20-40 Надходження товарів і послуг ІБ00-006224 від 12.12.2024 18:00:32 Цех екстракції (Глобине) | E5: 205 | F5: 9476.97 | H5: 205 | K5: Д | L5: 109464.8
A6: 01.02.2025 | B6: Переміщення товарів ІБ00-000121 від 01.02.2025 18:10:37 Перемещение ТМЦ | C6: Обл. НДС Щебінь 20-40 Надходження товарів і послуг ІБ00-006224 від 12.12.2024 18:00:32 Резервуар для зберігання розчинника(Глобине) | D6: Обл. НДС Щебінь 20-40 Надходження товарів і послуг ІБ00-006224 від 12.12.2024 18:00:32 Цех екстракції (Глобине) | E6: 205 | F6: 10108.82 | H6: 205 | K6: Д | L6: 119573.62
A7: 01.02.2025 | B7: Переміщення товарів ІБ00-000121 від 01.02.2025 18:10:37 Перемещение ТМЦ | C7: Обл. НДС Щебінь 20-40 Надходження товарів і послуг ІБ00-006317 від 18.12.2024 18:00:25 Резервуар для зберігання розчинника(Глобине) | D7: Обл. НДС Щебінь 20-40 Надходження товарів і послуг ІБ00-006317 від 18.12.2024 18:00:25 Цех екстракції (Глобине) | E7: 205 | F7: 7356 | H7: 205 | K7: Д | L7: 126929.62
A8: 01.02.2025 | B8: Переміщення товарів ІБ00-000140 від 01.02.2025 18:11:38 Перемещение ТМЦ | C8: Обл. НДС Пісок з відсіву дроблення щебеню фр. 0-5мм. Надходження товарів і послуг ІБ00-006313 від 17.12.2024 18:00:22 Резервуар для зберігання розчинника(Глобине) | D8: Обл. НДС Пісок з відсіву дроблення щебеню фр. 0-5мм. Надходження товарів і послуг ІБ00-006313 від 17.12.2024 18:00:22 СПК (Глобине) | E8: 205 | F8: 17510 | H8: 205 | K8: Д | L8: 144439.62
A9: 06.02.2025 | B9: Переміщення товарів ІБ00-000071 від 06.02.2025 18:36:21 Перемещение ТМЦ | C9: Обл. НДС Бетон С20/25 W6 F75 P4 доб-10 Надходження товарів і послуг ІБ00-000481 від 06.02.2025 18:36:18 Резервуар для зберігання розчинника(Глобине) | D9: Обл. НДС Бетон С20/25 W6 F75 P4 доб-10 Надходження товарів і послуг ІБ00-000481 від 06.02.2025 18:36:18 Глобине-2 | E9: 205 | F9: 55327.94 | H9: 205 | K9: Д | L9: 199767.56
A10: 06.02.2025 | B10: Надходження товарів і послуг ІБ00-000488 від 06.02.2025 18:36:23 Оприходованы ТМЦ | C10: Обл. НДС Пісок з відсіву дроблення щебеню фр. 0-5мм. Надходження товарів і послуг ІБ00-000488 від 06.02.2025 18:36:23 Резервуар для зберігання розчинника(Глобине) | D10: Енергія Логістик ТОВ №28/10-2024 ВІД 28/10/24_Глобине-2 Рахунок на оплату постачальника ІБ00-000418 від 06.02.2025 18:36:22 | E10: 205 | F10: 8172 | H10: 631 | K10: Д | L10: 207939.56
A11: 06.02.2025 | B11: Надходження дод. витрат ІБ00-000071 від 06.02.2025 18:36:24 Доп. расходы при поступлении товаров | C11: Обл. НДС Пісок з відсіву дроблення щебеню фр. 0-5мм. Надходження товарів і послуг ІБ00-000488 від 06.02.2025 18:36:23 Резервуар для зберігання розчинника(Глобине) | D11: Енергія Логістик ТОВ №28/10-2024 ВІД 28/10/24_Глобине-2 Рахунок на оплату постачальника ІБ00-000418 від 06.02.2025 18:36:22 | E11: 205 | F11: 19068 | H11: 631 | K11: Д | L11: 227007.56
A12: 06.02.2025 | B12: Переміщення товарів ІБ00-000161 від 06.02.2025 18:36:54 Перемещение ТМЦ | C12: Обл. НДС Пінополістирол фасад шаршавий 1200х600х20мм 0,264 куб м Надходження товарів і послуг ІБ00-000776 від 06.02.2025 18:36:51 Резервуар для зберігання розчинника(Глобине) | D12: Обл. НДС Пінополістирол фасад шаршавий 1200х600х20мм 0,264 куб м Надходження товарів і послуг ІБ00-000776 від 06.02.2025 18:36:51 Глобине-2 | E12: 205 | F12: 224.35 | H12: 205 | K12: Д | L12: 227231.91
A13: 06.02.2025 | B13: Переміщення товарів ІБ00-000161 від 06.02.2025 18:36:54 Перемещение ТМЦ | C13: Обл. НДС Пінополістирол фасад шаршавий 1200х600х20мм 0,264 куб м Надходження товарів і послуг ІБ00-000776 від 06.02.2025 18:36:51 Резервуар для зберігання розчинника(Глобине) | D13: Обл. НДС Пінополістирол фасад шаршавий 1200х600х20мм 0,264 куб м Надходження товарів і послуг ІБ00-000776 від 06.02.2025 18:36:51 Глобине-2 | E13: 205 | F13: 10170.65 | H13: 205 | K13: Д | L13: 237402.56
A14: 07.02.2025 | B14: Переміщення товарів ІБ00-000076 від 07.02.2025 18:30:15 Перемещение ТМЦ | C14: Обл. НДС Щебінь 20-40 Надходження товарів і послуг ІБ00-000491 від 07.02.2025 18:30:12 Резервуар для зберігання розчинника(Глобине) | D14: Обл. НДС Щебінь 20-40 Надходження товарів і послуг ІБ00-000491 від 07.02.2025 18:30:12 Глобине-2 | E14: 205 | F14: 112353.33 | H14: 205 | K14: Д | L14: 349755.89
A15: 12.02.2025 | B15: Вимога-накладна ІБ00-000073 від 12.02.2025 18:02:55 Списаны ТМЦ | C15: Обл. НДС Виробничий (Глобине-2) Глобине-2 Прямі материальні виробничі витрати крім зворотніх відходів | D15: Обл. НДС Щебінь 20-40 Надходження товарів і послуг ІБ00-006201 від 11.12.2024 18:00:22 Резервуар для зберігання розчинника(Глобине) | E15: 231 | H15: 205 | I15: 17314.26 | K15: Д | L15: 332441.63
A16: 12.02.2025 | B16: Вимога-накладна ІБ00-000073 від 12.02.2025 18:02:55 Списаны ТМЦ | C16: Обл. НДС Виробничий (Глобине-2) Глобине-2 Прямі материальні виробничі витрати крім зворотніх відходів | D16: Обл. НДС Щебінь 20-40 Надходження товарів і послуг ІБ00-000491 від 07.02.2025 18:30:12 Резервуар для зберігання розчинника(Глобине) | E16: 231 | H16: 205 | I16: 96923.33 | K16: Д | L16: 235518.3
A17: 12.02.2025 | B17: Вимога-накладна ІБ00-000073 від 12.02.2025 18:02:55 Списаны ТМЦ | C17: Обл. НДС Виробничий (Глобине-2) Глобине-2 Прямі материальні виробничі витрати крім зворотніх відходів | D17: Обл. НДС Щебінь 20-40 Надходження товарів і послуг ІБ00-000491 від 07.02.2025 18:30:12 Резервуар для зберігання розчинника(Глобине) | E17: 231 | H17: 205 | I17: 15430 | K17: Д | L17: 220088.3
A18: 13.02.2025 | B18: Переміщення товарів ІБ00-000103 від 13.02.2025 18:15:00 Перемещение ТМЦ | C18: Обл. НДС Бетон С 8/10 Р4 доб-15 Надходження товарів і послуг ІБ00-000541 від 13.02.2025 18:05:07 Резервуар для зберігання розчинника(Глобине) | D18: Обл. НДС Бетон С 8/10 Р4 доб-15 Надходження товарів і послуг ІБ00-000541 від 13.02.2025 18:05:07 Глобине-2 | E18: 205 | F18: 13169.98 | H18: 205 | K18: Д | L18: 233258.28
A19: 13.02.2025 | B19: Надходження товарів і послуг ІБ00-000659 від 13.02.2025 18:20:14 Оприходованы ТМЦ | C19: Обл. НДС Шпонка гідроізоляційна ВД 240 Надходження товарів і послуг ІБ00-000659 від 13.02.2025 18:20:14 Резервуар для зберігання розчинника(Глобине) | D19: ПРОТЕКС УКРАЇНА Договір 9 від 11.12.2023_Глобіно2 Рахунок на оплату постачальника ІБ00-000555 від 11.02.2025 21:16:59 | E19: 205 | F19: 5375 | H19: 631 | K19: Д | L19: 238633.28
A20: 14.02.2025 | B20: Надходження товарів і послуг ІБ00-000655 від 14.02.2025 00:00:00 Оприходованы ТМЦ (Зачет аванса поставщику) | C20: Обл. НДС Труба Дн 273 стал. 8,0мм Надходження товарів і послуг ІБ00-000655 від 14.02.2025 00:00:00 Резервуар для зберігання розчинника(Глобине) | D20: Паритет"ТОВ ТД Договір 06-09/1 від 06.09.2024_Глобино-2 Рахунок на оплату постачальника ІБ00-000456 від 11.02.2025 18:10:02 | E20: 205 | F20: 7145.53 | H20: 631 | K20: Д | L20: 245778.81
A21: 14.02.2025 | B21: Надходження товарів і послуг ІБ00-000655 від 14.02.2025 00:00:00 Оприходованы ТМЦ (Зачет аванса поставщику) | C21: Обл. НДС Труба 426х7 стальна Надходження товарів і послуг ІБ00-000655 від 14.02.2025 00:00:00 Резервуар для зберігання розчинника(Глобине) | D21: Паритет"ТОВ ТД Договір 06-09/1 від 06.09.2024_Глобино-2 Рахунок на оплату постачальника ІБ00-000456 від 11.02.2025 18:10:02 | E21: 205 | F21: 837.82 | H21: 631 | K21: Д | L21: 246616.63
A22: 14.02.2025 | B22: Переміщення товарів ІБ00-000115 від 14.02.2025 10:10:00 Перемещение ТМЦ | C22: Обл. НДС Кутик 50х50х5мм ст 3пс МІРА Надходження товарів і послуг ІБ00-000546 від 14.02.2025 10:00:00 Резервуар для зберігання розчинника(Глобине) | D22: Обл. НДС Кутик 50х50х5мм ст 3пс МІРА Надходження товарів і послуг ІБ00-000546 від 14.02.2025 10:00:00 Глобине-2 | E22: 205 | F22: 3510 | H22: 205 | K22: Д | L22: 250126.63
A23: 14.02.2025 | B23: Переміщення товарів ІБ00-000115 від 14.02.2025 10:10:00 Перемещение ТМЦ | C23: Обл. НДС Прокат арматурний №16 мм А500С Надходження товарів і послуг ІБ00-000546 від 14.02.2025 10:00:00 Резервуар для зберігання розчинника(Глобине) | D23: Обл. НДС Прокат арматурний №16 мм А500С Надходження товарів і послуг ІБ00-000546 від 14.02.2025 10:00:00 Глобине-2 | E23: 205 | F23: 31258.33 | H23: 205 | K23: Д | L23: 281384.96
A24: 17.02.2025 | B24: Надходження товарів і послуг ІБ00-000649 від 17.02.2025 23:45:08 Оприходованы ТМЦ (Зачет аванса поставщику) | C24: Обл. НДС Пенебар SW-55 тип А 5м/рул Надходження товарів і послуг ІБ00-000649 від 17.02.2025 23:45:08 Резервуар для зберігання розчинника(Глобине) | D24: ПЕНЕТРОН УКРАЇНА ТОВ РАХУНКИ_Глобино-2 Рахунок на оплату постачальника ІБ00-000457 від 10.02.2025 17:47:30 | E24: 205 | F24: 1187.5 | H24: 631 | K24: Д | L24: 282572.46
A25: 17.02.2025 | B25: Надходження товарів і послуг ІБ00-000649 від 17.02.2025 23:45:08 Оприходованы ТМЦ (Зачет аванса поставщику) | C25: Обл. НДС Пенекрит 5кг/відро Надходження товарів і послуг ІБ00-000649 від 17.02.2025 23:45:08 Резервуар для зберігання розчинника(Глобине) | D25: ПЕНЕТРОН УКРАЇНА ТОВ РАХУНКИ_Глобино-2 Рахунок на оплату постачальника ІБ00-000457 від 10.02.2025 17:47:30 | E25: 205 | F25: 1145.83 | H25: 631 | K25: Д | L25: 283718.29
A26: 20.02.2025 | B26: Вимога-накладна ІБ00-000118 від 20.02.2025 00:00:00 Списаны ТМЦ | C26: Обл. НДС Виробничий (Глобине-2) Глобине-2 Прямі материальні виробничі витрати крім зворотніх відходів | D26: Обл. НДС Щебінь 20-40 Надходження товарів і послуг ІБ00-006196 від 10.12.2024 18:00:19 Резервуар для зберігання розчинника(Глобине) | E26: 231 | H26: 205 | I26: 4510.67 | K26: Д | L26: 279207.62
A27: 20.02.2025 | B27: Вимога-накладна ІБ00-000118 від 20.02.2025 00:00:00 Списаны ТМЦ | C27: Обл. НДС Виробничий (Глобине-2) Глобине-2 Прямі материальні виробничі витрати крім зворотніх відходів | D27: Обл. НДС Щебінь 20-40 Надходження товарів і послуг ІБ00-006201 від 11.12.2024 18:00:22 Резервуар для зберігання розчинника(Глобине) | E27: 231 | H27: 205 | I27: 78162.9 | K27: Д | L27: 201044.72
A28: 20.02.2025 | B28: Вимога-накладна ІБ00-000118 від 20.02.2025 00:00:00 Списаны ТМЦ | C28: Обл. НДС Виробничий (Глобине-2) Глобине-2 Прямі материальні виробничі витрати крім зворотніх відходів | D28: Обл. НДС Щебінь 20-40 Надходження товарів і послуг ІБ00-006224 від 12.12.2024 18:00:32 Резервуар для зберігання розчинника(Глобине) | E28: 231 | H28: 205 | I28: 583.44 | K28: Д | L28: 200461.28
A29: 20.02.2025 | B29: Вимога-накладна ІБ00-000118 від 20.02.2025 00:00:00 Списаны ТМЦ | C29: Обл. НДС Виробничий (Глобине-2) Глобине-2 Прямі материальні виробничі витрати крім зворотніх відходів | D29: Обл. НДС Щебінь 20-40 Надходження товарів і послуг ІБ00-006224 від 12.12.2024 18:00:32 Резервуар для зберігання розчинника(Глобине) | E29: 231 | H29: 205 | I29: 19002.35 | K29: Д | L29: 181458.93
A30: 20.02.2025 | B30: Вимога-накладна ІБ00-000118 від 20.02.2025 00:00:00 Списаны ТМЦ | C30: Обл. НДС Виробничий (Глобине-2) Глобине-2 Прямі материальні виробничі витрати крім зворотніх відходів | D30: Обл. НДС Щебінь 20-40 Надходження товарів і послуг ІБ00-006317 від 18.12.2024 18:00:25 Резервуар для зберігання розчинника(Глобине) | E30: 231 | H30: 205 | I30: 7356 | K30: Д | L30: 174102.93
A31: 20.02.2025 | B31: Вимога-накладна ІБ00-000118 від 20.02.2025 00:00:00 Списаны ТМЦ | C31: Обл. НДС Виробничий (Глобине-2) Глобине-2 Прямі материальні виробничі витрати крім зворотніх відходів | D31: Обл. НДС Бетон С 8/10 Р4 доб-15 Надходження товарів і послуг ІБ00-000541 від 13.02.2025 18:05:07 Резервуар для зберігання розчинника(Глобине) | E31: 231 | H31: 205 | I31: 13169.98 | K31: Д | L31: 160932.95
A32: 20.02.2025 | B32: Вимога-накладна ІБ00-000118 від 20.02.2025 00:00:00 Списаны ТМЦ | C32: Обл. НДС Виробничий (Глобине-2) Глобине-2 Прямі материальні виробничі витрати крім зворотніх відходів | D32: Обл. НДС Пісок з відсіву дроблення щебеню фр. 0-5мм. Надходження товарів і послуг ІБ00-006313 від 17.12.2024 18:00:22 Резервуар для зберігання розчинника(Глобине) | E32: 231 | H32: 205 | I32: 17510 | K32: Д | L32: 143422.95
A33: 20.02.2025 | B33: Вимога-накладна ІБ00-000118 від 20.02.2025 00:00:00 Списаны ТМЦ | C33: Обл. НДС Виробничий (Глобине-2) Глобине-2 Прямі материальні виробничі витрати крім зворотніх відходів | D33: Обл. НДС Пісок з відсіву дроблення щебеню фр. 0-5мм. Надходження товарів і послуг ІБ00-000488 від 06.02.2025 18:36:23 Резервуар для зберігання розчинника(Глобине) | E33: 231 | H33: 205 | I33: 9730 | K33: Д | L33: 133692.95
A34: 20.02.2025 | B34: Вимога-накладна ІБ00-000118 від 20.02.2025 00:00:00 Списаны ТМЦ | C34: Обл. НДС Виробничий (Глобине-2) Глобине-2 Прямі материальні виробничі витрати крім зворотніх відходів | D34: Обл. НДС Пісок з відсіву дроблення щебеню фр. 0-5мм. Надходження товарів і послуг ІБ00-000488 від 06.02.2025 18:36:23 Резервуар для зберігання розчинника(Глобине) | E34: 231 | H34: 205 | I34: 17510 | K34: Д | L34: 116182.95
A35: Обороти за період та сальдо на кінець | E35: 413385.88 | H35: 297202.93 | K35: Д | L35: 116182.95
J37: =SUBTOTAL(9,I15:J34)*1.2 -> 356643.52

Sheet Резервуарний парк
A1: Період | B1: Документ | C1: Аналітика Дт | D1: Аналітика Кт | E1: Дебет | H1: Кредит | K1: Поточне сальдо
E2: Рахунок | H2: Рахунок
A3: 01.02.2025 | B3: Надходження товарів і послуг ІБ00-000352 від 01.02.2025 18:00:02 Оприходованы ТМЦ | C3: Обл. НДС Пісок з відсіву дроблення щебеню фр. 0-5мм. Надходження товарів і послуг ІБ00-000352 від 01.02.2025 18:00:02 Резервуарний парк соєвої меляси (Глобине) | D3: Енергія Логістик ТОВ №28/10-2024 ВІД 28/10/24_Глобине-2 Рахунок на оплату постачальника ІБ00-000313 від 01.02.2025 18:00:01 | E3: 205 | F3: 8151 | H3: 631 | K3: Д | L3: 190754.53
A4: 01.02.2025 | B4: Надходження дод. витрат ІБ00-000058 від 01.02.2025 18:00:03 Доп. расходы при поступлении товаров | C4: Обл. НДС Пісок з відсіву дроблення щебеню фр. 0-5мм. Надходження товарів і послуг ІБ00-000352 від 01.02.2025 18:00:02 Резервуарний парк соєвої меляси (Глобине) | D4: Енергія Логістик ТОВ №28/10-2024 ВІД 28/10/24_Глобине-2 Рахунок на оплату постачальника ІБ00-000313 від 01.02.2025 18:00:01 | E4: 205 | F4: 19019 | H4: 631 | K4: Д | L4: 209773.53
A5: 01.02.2025 | B5: Переміщення товарів ІБ00-000088 від 01.02.2025 18:10:10 Перемещение ТМЦ | C5: Обл. НДС Бетон С20/25 W6 F75 P4 Надходження товарів і послуг ІБ00-000026 від 08.01.2025 18:00:01 Резервуарний парк соєвої меляси (Глобине) | D5: Обл. НДС Бетон С20/25 W6 F75 P4 Надходження товарів і послуг ІБ00-000026 від 08.01.2025 18:00:01 СПК (Глобине) | E5: 205 | F5: 6307.8 | H5: 205 | K5: Д | L5: 216081.33
