Workbook

Sheet ноябрь
A5: Замовник: ТОВ "СІА"
A6: Генпідрядник: ТОВ "ДИПРОІНБУД"
A7: Найменування будови та її адреса - Будівництво житлово-громадської забудови з об’єктами соціальної та інженерно-транспортної інфраструктури по вул. Євгена Сверстюка, 4 (колишня вул. Марини Раскової) у Дніпровському районі м. Києва.
A8: Найменування об'єкта - Житловий будинок № 3, секції 5 та 6.
A9: Договір: №14/08/2017-ГПР-III/ГЛ від 14.08.2017 р.
A11: РЕЄСТР АКТІВ ВИКОНАНИХ РОБІТ ПО ОБ'ЄКТУ | J11: 1.03 | V11: 100
A13: № п/п | B13: Вид робіт (витрат) | C13: Найменування робіт | D13: ДЦ | E13: Сума ДЦ | F13: Управлінський облік | H13: Всего управлінський облік | J13: Діпроинбуд | M13: Підрядник | Q13: Перевірка | V13: г/п
F14: листопад 2017()
A15: 1 | B15: 2 | C15: 3 | D15: 4 | F15: 4 | G15: 5 | I15: 7
J16: всього | K16: робота | L16: мат-ли | M16: всього | N16: робота | O16: мат-ли | P16: найменув. | Q16: робота | R16: мат-ли | S16: зараб. 3% | T16: перевірка
A17: 1 | B17: Розробка котловану | C17: грунт | D17: 12102-1 | E17: 657140 | F17: 12102-1/1 | G17: =301810.6 -> 301810.6 | H17: =F17 -> 12102-1/1 | I17: 301810.6 | J17: =(K17+L17)*$J$11 -> 251508.83 | K17: =244183.33 -> 244183.33 | L17: 0 | M17: =N17+O17 -> 336378.6 | N17: =280315.5*1.2 -> 336378.6 | P17: Индустрія | Q17: =K17-N17 -> -92195.27 | R17: =L17-O17 -> 0 | S17: =J17-M17*1.03 -> -94961.128 | T17: =M17*1.03 -> 346469.96 | U17: =J17-M17 -> -84869.77 | V17: =Q17/$V$11*W17 -> -2765.8581 | W17: 3
A18: 2 | B18: Палі основні | C18: палі | D18: 12103-1 | E18: =7254070.69 -> 7254070.7 | F18: 12103-1/1 | G18: =3195761.59 -> 3195761.6 | H18: =F18 -> 12103-1/1 | I18: =G18 -> 3195761.6 | J18: =L18*$J$11+K18 -> 3195761.6 | K18: =743034.22*1.2 -> 891641.06 | L18: =1864175.18*1.2 -> 2237010.2 | M18: =N18+O18 -> 3128651.3 | N18: =743034.22*1.2 -> 891641.06 | O18: =1864175.18*1.2 -> 2237010.2 | P18: Фундамент | Q18: =K19-N18 -> -876120.53 | R18: =L19-O18 -> -2187140.3 | S18: =J18-M18*1.03 -> -26749.232 | T18: =M18*1.03 -> 3222510.8 | U18: =J18-M18 -> 67110.306 | V18: =Q18/$V$11*W18 -> -13141.808 | W18: 1.5
A19: 3 | B19: Палі під баштовий кран | C19: палі кран | D19: 12104-1 | F19: 12104-1/1 | G19: =66886.52 -> 66886.52 | H19: =F19 -> 12104-1/1 | I19: =G19 -> 66886.52 | J19: =L19*$J$11+K19 -> 66886.521 | K19: =12933.78*1.2 -> 15520.536 | L19: =41558.24*1.2 -> 49869.888 | M19: =N19+O19 -> 0 | Q19: =#REF!-N19 -> #REF! | R19: =#REF!-O19 -> #REF! | S19: =J19-M19*1.03 -> 66886.521 | T19: =M19*1.03 -> 0 | U19: =J19-M19 -> 66886.521 | V19: =Q19/$V$11*W19 -> #REF!
A20: 4 | B20: Зняття електроенергії | C20: г/п доп | F20: г/п доп | G20: =-27521.64*1.2 -> -33025.968
B21: ВСЬОГО: | G21: =SUM(G17:G20) -> 3531432.7
B23: Виконав: __________________Кириченко Р.Л. 097-434-82-92
B27: Погоджено __________________________

Sheet Реєстр ДЦ
A1: ДОВІДКА по об'єктам ТОВ "ІНДАСТРІАЛБУД"
A3: № з/п | B3: Об'єкт | C3: Замовник | D3: Найменування робіт (витрат) | E3: №, дата Договору | F3: ДЦ до Договру, грн. з ПДВ | I3: Статус | J3: Собівартість, грн. з ПДВ | M3: Примітки
F4: Разом | G4: Матеріали | H4: Робота | J4: Разом | K4: Матеріали | L4: Робота
A5: 1 | B5: 2 | C5: 3 | D5: 4 | E5: 5 | F5: 6 | G5: 7 | H5: 8 | I5: 9 | J5: 10 | K5: 11 | L5: 12 | M5: 10
A6: 4 | B6: «Нове будівництво олієпресового цеху по переробці насіння соняшника потужністю 1200т/добу з допоміжними будівлями та спорудами внутрішньогосподарського комплексу по виробництву кормів" м.Ладижин, Вінницької області» | C6: ПрАТ "МХП" | D6: Будівництво каркасу оліє-пресового цеху №2 з трансформаторною підстанцією, м.Ладижин, Вінницька область | E6: №389-10 від 19.02.2021 | F6: =9670800 -> 9670800 | G6: =980219.27 -> 980219.27 | H6: =F6-G6 -> 8690580.7 | I6: Погоджено замовником
D7: Додаткові роботи по монтажу/демонтажу з/б балок каркасу, згідно дефектного акту №1 | E7: Д/У№1 до дог. №389-10 від 19.02.2021 | F7: 131336.26 | G7: 41465.11 | H7: =F7-G7 -> 89871.15 | I7: Погоджено замовником | J7: =102739.6 -> 102739.6 | K7: =16812.5 -> 16812.5 | L7: =J7-K7 -> 85927.1 | M7: 0.2783
D8: Влаштування фундаментів допоміжних споруд оліє-пресового цеху по переробці насіння соняшника 1200т/добу | E8: №396-10 від 31.03.2021 | F8: =4080000 -> 4080000 | G8: =2262472.26 -> 2262472.3 | H8: =F8-G8 -> 1817527.7 | I8: Погоджено замовником
D9: Мурування ТП | F9: =1100452.22 -> 1100452.2 | G9: =F9-H9 -> 410866.37 | H9: =689585.85 -> 689585.85 | I9: Внутр. погодження
F10: =SUM(F6:F9) -> 14982588 | G10: =SUM(G6:G9) -> 3695023 | H10: =SUM(H6:H9) -> 11287565
F11: =F10+#REF!+#REF!+#REF! -> #REF! | G11: =G10+#REF!+#REF!+#REF! -> #REF! | H11: =H10+#REF!+#REF!+#REF! -> #REF!

Sheet Реєстр АВР
B1: ДОВІДКА по об'єктам ТОВ "ІНДАСТРІАЛБУД" | D1: 44336
A2: № з/п | B2: Найменування об'єкту | C2: Замовник | D2: № Договору | E2: Загальна вартість Договору з урах.ДУ | H2: Сума АВР | N2: Залишок по Договору
E3: Разом | F3: Матеріали | G3: Робота | H3: № | I3: Разом | J3: Матеріали | K3: Робота | L3: Дата | M3: Статус | N3: Разом | O3: Матеріали | P3: Робота
A4: 4 | B4: «Нове будівництво олієпресового цеху по переробці насіння соняшника потужністю 1200т/добу з допоміжними будівлями та спорудами внутрішньогосподарського комплексу по виробництву кормів" м.Ладижин, Вінницької області» | C4: ПрАТ "МХП" | D4: №389-10 від 19.02.2021 | E4: ='Реєстр ДЦ'!F6 -> 9670800 | F4: ='Реєстр ДЦ'!G6 -> 980219.27 | G4: ='Реєстр ДЦ'!H6 -> 8690580.7 | H4: 1 | I4: =288379.22 -> 288379.22 | J4: =7494.3*1.2 -> 8993.16 | K4: =I4-J4 -> 279386.06 | L4: 44314 | M4: Підписаний | N4: =E4-I8 -> 7863750.8 | O4: =F4-J8 -> 950795.63 | P4: =G4-K8 -> 6912955.1
H5: 2 | I5: =193609.49 -> 193609.49 | J5: 0 | K5: =I5 -> 193609.49 | L5: 44314 | M5: Підписаний
H6: 3 | I6: 266283.61 | J6: =7768.48*1.2 -> 9322.176 | K6: =I6-J6 -> 256961.43 | L6: травень 2021 | M6: Підписаний
H7: 4 | I7: 1058776.9 | J7: =9256.92*1.2 -> 11108.304 | K7: =I7-J7 -> 1047668.6 | L7: травень 2022 | M7: Підписаний
I8: =SUM(I4:I7) -> 1807049.2 | J8: =SUM(J4:J7) -> 29423.64 | K8: =SUM(K4:K7) -> 1777625.6
D9: Д/У№1 до дог.№389-10 від 19.02.2021 | E9: ='Реєстр ДЦ'!F7 -> 131336.26 | F9: ='Реєстр ДЦ'!G7 -> 41465.11 | G9: ='Реєстр ДЦ'!H7 -> 89871.15 | I9: 5042.8 | J9: 0 | K9: =I9-J9 -> 5042.8 | M9: На розгляді у замовника | N9: =E9-I11 -> 126293.46 | O9: =F9-J11 -> 41465.11 | P9: =G9-K11 -> 84828.35
I11: =SUM(I9:I10) -> 5042.8 | J11: =SUM(J9:J10) -> 0 | K11: =SUM(K9:K10) -> 5042.8
D12: №396-10 від 31.03.2021 | E12: ='Реєстр ДЦ'!F8 -> 4080000 | F12: =1885393.55*1.2 -> 2262472.3 | G12: =E12-F12 -> 1817527.7 | N12: =E12-I14 -> 4080000 | O12: =F12-J14 -> 2262472.3 | P12: =G12-K14 -> 1817527.7
I14: =SUM(I12:I13) -> 0 | J14: =SUM(J12:J13) -> 0 | K14: =SUM(K12:K13) -> 0
D15: Нет номера договора | E15: ='Реєстр ДЦ'!F9 -> 1100452.2 | F15: =410866.37 -> 410866.37 | G15: =E15-F15 -> 689585.85 | N15: =E15-I16 -> 1100452.2 | O15: =F15-J16 -> 410866.37 | P15: =G15-K16 -> 689585.85
I16: =SUM(I15) -> 0 | J16: =SUM(J15) -> 0 | K16: =SUM(K15) -> 0
I17: =I8+I11+I14+I16 -> 1812092.1 | J17: =J8+J11+J14+J16 -> 29423.64 | K17: =K8+K11+K14+K16 -> 1782668.4
E18: =SUM(E4:E16) -> 14982588 | F18: =SUM(F4:F16) -> 3695023 | G18: =SUM(G4:G16) -> 11287565 | I18: =#REF!+#REF!+#REF!+I17 -> #REF! | J18: =#REF!+#REF!+#REF!+J17 -> #REF! | K18: =#REF!+#REF!+#REF!+K17 -> #REF! | N18: =SUM(N4:N16) -> 13170496 | O18: =SUM(O4:O16) -> 3665599.4 | P18: =SUM(P4:P16) -> 9504897.1

Sheet Реєстр ДЦ 
A1: Реєстр ДЦ по об'єкту "Комплекс будівельно-монтажних та пусконалагоджувальних робіт з монтажу та підключення турбогенераторної установки для виробництва електричної енергії на базі парової турбіни "
D3: Договір №З-12
A4: № ДЦ | B4: Найменування договірної ціни | C4: Договір | D4: Роботи з ПДВ, грн | E4: Матеріали з ПДВ, грн | F4: Всього по ДЦ з ПДВ, грн | G4: Статус | H4: Дата | I4: Коментарі
A6: 1 | B6: Влаштування фундамента під турбіну та кран-балку | C6: № З-12 | F6: 12434.74 | G6: підписано. Оригінал договору в офісі
A7: =A6+1 -> 2 | B7: Влаштування металоконструкцій площадок, огорож та сходів в машинному залі | F7: 775924.93
A8: =A7+1 -> 3 | B8: Поставка та монтаж кран-балки вантажопідйомністю-10т | F8: 1435680
A9: =A8+1 -> 4 | B9: Монтаж системи масляного охолодження турбіни | F9: 117868.46
A10: =A9+1 -> 5 | B10: Монтаж і обв'язування турбіни та генератора | F10: 4049560.8
A11: =A10+1 -> 6 | B11: Влаштування додаткової вентиляції операторської | F11: 121951.34
A12: =A11+1 -> 7 | B12: Монтаж та обв'язування конденсатора | F12: 585897.12
A13: =A12+1 -> 8 | B13: Влаштування промислової підлоги | F13: 512538.17
A14: =A13+1 -> 9 | B14: Влаштування паропроводу. | F14: 5299207
A15: =A14+1 -> 10 | B15: Влаштування дренажів. | F15: 408096.48
A16: =A15+1 -> 11 | B16: Влаштування конденсаторопровода | F16: 702045.67
A17: =A16+1 -> 12 | B17: Оздоблювальні роботи | F17: 744021.82
A18: =A17+1 -> 13 | B18: Влаштування благоустрою території | F18: 2383935.7
... A24: =A23+1 -> 19 | B24: Пусконалагоджувальні роботи | F24: 4885307.5
A25: =A24+1 -> 20 | B25: Випробування кабельних трас
A26: =A25+1 -> 21 | B26: Випробування трубопроводів | F26: 255500
A27: =A26+1 -> 22 | B27: Перебазування дільниці | F27: 220000
B28: Піскоструменеве очищення металоконструкцій | D28: 457389.45 | E28: 26059.841 | F28: 481468.45 | G28: согласовано (ОК в почте от Резниченко) | H28: 45468 | I28: после пересчета ДЦ, в новую редакцию будут включены данные работы. Объемы фактические подписаны Резниченко, закрыто в АВР №3
B29: Обслуговування (ревізія) Турбіни | C29: № З-34 | D29: =F29 -> 377607.41 | F29: 377607.41 | G29: подписан. Оригинал в офисе
B30: Дефектовка ГПП | D30: 114260 | E30: =F30-D30 -> 138118.65 | F30: 252378.65 | G30: согласовано (ОК в почте от Резниченко) | H30: 45503 | I30: после пересчета ДЦ, в новую редакцию будут включены данные работы. Объемы фактические подписаны Резниченко, закрыто в АВР №4
B31: Технічне забезпечення шефмонтажних та пусконалагоджувальних робіт. Інжинірингові послуги (супровід та узгодження дозвільної документації в Запоріжжяобленерго) | D31: =F31 -> 3726000 | F31: =3428000+298000 -> 3726000 | G31: Оригинал на подписи у Закерничного (ДЦ будет подписано директором после уточнения даты начала ПНР)
B32: Доп. Работы (согласно подписанных дефектных актов) | D32: =F32-E32 -> 2026266.6 | E32: =554309.57*1.2 -> 665171.48 | F32: 2691438.1 | G32: согласовано (ОК в почте от Резниченко) | H32: 45573
B36: ВСЬОГО: | D36: =SUM(D6:D35) -> 6701523.5 | E36: =SUM(E6:E35) -> 829349.97 | F36: =SUM(F6:F35) -> 58504295

Sheet РеєстрАВР
A1: Реєстр актів виконаних робіт по об'єкту "___________________________________________________"
A3: № ДЦ | B3: Найменування договірної ціни | C3: Всього по ДЦ з ПДВ, грн | D3: АКТИ | J3: Коментарі
D4: № акта | E4: Всього, грн з ПДВ | F4: Матеріали з ПДВ, грн | G4: Роботи з ПДВ, грн | H4: Статус | I4: Дата | K4: Сумма по АВР
B5: Машинний зал | F5: 0
B6: Влаштування фундамента під турбіну та кран-балку | D6: №3/1 | E6: 12324.5 | F6: 5635.752 | G6: =E6-F6 -> 6688.748 | J6: закрыто 100% | K6: =E6 -> 12324.5
B7: Влаштування металоконструкцій площадок, огорож та сходів в машинному залі | D7: №2/1 | E7: 270698.92 | F7: 9303.396 | G7: =E7-F7 -> 261395.52 | J7: закрыто 100% | K7: =E7+E8 -> 1149199.3
D8: №3/2 | E8: 878500.36 | F8: 297661.7 | G8: =E8-F8 -> 580838.66
D9: №7/1 | E9: 633942.2 | F9: 356081.39 | G9: =E9-F9 -> 277860.81
D10: №12/1 | E10: 451253.94 | F10: =1612.4*1.2 -> 1934.88 | G10: =E10-F10 -> 449319.06 | H10: оригинал в офисе
B11: Поставка та монтаж кран-балки вантажопідйомністю-10т | D11: №2/2 | E11: 1410108 | F11: 1203914.9 | G11: =E11-F11 -> 206193.15 | J11: закрыто 100% | K11: =E11 -> 1410108
B12: Монтаж системи масляного охолодження турбіни | D12: №2/3 | E12: 24870.04 | F12: 10154.412 | G12: =E12-F12 -> 14715.628 | J12: закрыто по факту | K12: =E12+E13 -> 84548.68
D13: №3/3 | E13: 59678.64 | F13: =9434.59*1.2 -> 11321.508 | G13: =E13-F13 -> 48357.132
B14: Монтаж і обв'язування турбіни та генератора | D14: №2/4 | E14: 3500757.4 | F14: 204032.86 | G14: =E14-F14 -> 3296724.5 | J14: закрыто 100%
D15: №5/1 | E15: 529231.08 | G15: =E15-F15 -> 529231.08
D16: №10/1 | E16: 164217.67 | G16: =E16-F16 -> 164217.67
B17: Влаштування додаткової вентиляції операторської | D17: №2/5 | E17: 124618.82 | F17: 120493.22 | G17: =E17-F17 -> 4125.596 | J17: закрыто 100% | K17: =E17+E18 -> 159521.14
D18: №3/4 | E18: 34902.32 | F18: =1167.21*1.2 -> 1400.652 | G18: =E18-F18 -> 33501.668
B19: Монтаж та обв'язування конденсатора | D19: №8/1 | E19: 398311.36 | F19: 9771.576 | G19: =E19-F19 -> 388539.78 | J19: закрыто 100%
D20: №9/1 | E20: 325074.25 | F20: 37459.8 | G20: =E20-F20 -> 287614.45
B21: Влаштування промислової підлоги | D21: №5/2 | E21: 342716.66 | F21: =173751.78*1.2 -> 208502.14 | G21: =E21-F21 -> 134214.52 | J21: закрыто 100%
D22: №6/1 | E22: 153264.7 | F22: =103692.08*1.2 -> 124430.5 | G22: =E22-F22 -> 28834.204
B23: Влаштування паропроводу. | D23: №3/5 | E23: 718425.36 | F23: =217956.39*1.2 -> 261547.67 | G23: =E23-F23 -> 456877.69
D24: №5/3 | E24: 1241599 | F24: =687539.28*1.2 -> 825047.14 | G24: =E24-F24 -> 416551.82
D25: №6/2 | E25: 29198.56 | G25: =E25-F25 -> 29198.56
D26: №8/2 | E26: 94069.87 | F26: 74841.924 | G26: =E26-F26 -> 19227.946
D27: №9/2 | E27: 1846546.4 | F27: 1397310 | G27: =E27-F27 -> 449236.36
D28: №10/2 | E28: 655585.96 | F28: =342784.28*1.2 -> 411341.14 | G28: =E28-F28 -> 244244.82
D29: №11/1 | E29: 106612.76 | F29: 85840.79 | G29: =E29-F29 -> 20771.97
D30: №12/2 | E30: 303289.33 | F30: =54549.55*1.2 -> 65459.46 | G30: =E30-F30 -> 237829.87 | H30: оригинал в офисе
B31: Влаштування дренажів. | D31: №3/6 | E31: 383834.03 | F31: =53776.66*1.2 -> 64531.992 | G31: =E31-F31 -> 319302.04 | J31: закрыто 100% | K31: =E31 -> 383834.03
D32: №8/3 | E32: 534342.44 | F32: 143822.12 | G32: =E32-F32 -> 390520.32
D33: №12/3 | E33: 4845.04 | F33: =2431.92*1.2 -> 2918.304 | G33: =E33-F33 -> 1926.736 | H33: оригинал в офисе
B34: Влаштування конденсаторопровода | D34: №3/7 | E34: 611563.93 | F34: =142784.19*1.2 -> 171341.03 | G34: =E34-F34 -> 440222.9 | J34: закрыто 100%
D35: №5/4 | E35: 258127.72 | F35: =20576.74*1.2 -> 24692.088 | G35: =E35-F35 -> 233435.63
D36: №7/2 | E36: 37302.28 | F36: =25381.31*1.2 -> 30457.572 | G36: =E36-F36 -> 6844.708
B37: Оздоблювальні роботи | D37: №3/8 | E37: 86531.94 | F37: =52775*1.2 -> 63330 | G37: =E37-F37 -> 23201.94 | J37: закрыто 100%
D38: №8/4 | E38: 368527.66 | F38: 249730.07 | G38: =E38-F38 -> 118797.59
D39: №10/3 | E39: 77060.93 | F39: =33242.18*1.2 -> 39890.616 | G39: =E39-F39 -> 37170.314
D40: №12/4 | E40: 231879.02 | F40: =64512.12*1.2 -> 77414.544 | G40: =E40-F40 -> 154464.48 | H40: оригинал в офисе
B41: Влаштування благоустрою території | D41: №1 | E41: 783940.68 | F41: 407415 | G41: =E41-F41 -> 376525.68 | J41: закрыто 100%
...

Sheet Реєстр ДЦ  (2)
A1: Реєстр ДЦ по об'єкту "_______________________________ "
I2: *********Вимоги
A3: № ДЦ | B3: Найменування договірної ціни | C3: Роботи з ПДВ, грн | D3: Матеріали з ПДВ, грн | E3: Всього по ДЦ з ПДВ, грн | F3: Статус | G3: Дата | H3: Коментарі | I3: Для заповнення колонки статус | J3: Для заповнення колонки коментарі
I4: Варіанти статусу | J4: Побажання до коментарів (основне)
A5: №1 | B5: Влаштування фундамента під турбіну та кран-балку | I5: ДЦ у відділі ВТВ | J5: заповнюємо колонку коли отримали інформацію і планова дата ССДЦ, або ДЦ ДУ планується і вказуємо що маємо отримати інформацію
A6: №2 | B6: Влаштування металоконструкцій площадок, огорож та сходів в машинному залі | I6: На внутрішньому погодженні | J6: заповнюємо колонку зауваження до ССДЦ якщо є і на кому затримка в погодженні
A7: №3 | B7: Поставка та монтаж кран-балки вантажопідйомністю-10т | I7: Подано на Замовника | J7: заповнюємо колонку коли замовник обіцяє погодити, зауваження якщо є
A8: №4 | B8: Монтаж системи масляного охолодження турбіни | I8: Погоджено Замовником | J8: заповнюємо колонку коментарі з датою коли буде оригінал
A9: №1 | B9: Монтаж і обв'язування турбіни та генератора | I9: ДЦ у відділі ВТВ | J9: заповнюємо колонку коли отримали інформацію і планова дата ССДЦ, або ДЦ ДУ планується і вказуємо що маємо отримати інформацію
A10: №2 | B10: Влаштування додаткової вентиляції операторської | I10: На внутрішньому погодженні | J10: заповнюємо колонку зауваження до ССДЦ якщо є і на кому затримка в погодженні
A11: №3 | B11: Монтаж та обв'язування конденсатора | I11: Подано на Замовника | J11: заповнюємо колонку коли замовник обіцяє погодити, зауваження якщо є
A12: №1 | B12: Влаштування промислової підлоги | I12: ДЦ у відділі ВТВ | J12: заповнюємо колонку коли отримали інформацію і планова дата ССДЦ, або ДЦ ДУ планується і вказуємо що маємо отримати інформацію
A13: №2 | B13: Влаштування паропроводу. | I13: На внутрішньому погодженні | J13: заповнюємо колонку зауваження до ССДЦ якщо є і на кому затримка в погодженні
A14: №3 | B14: Влаштування дренажів. | I14: Подано на Замовника | J14: заповнюємо колонку коли замовник обіцяє погодити, зауваження якщо є
A15: №4 | B15: Влаштування конденсаторопровода | I15: Погоджено Замовником | J15: заповнюємо колонку коментарі з датою коли буде оригінал
A16: №1 | B16: Оздоблювальні роботи | I16: ДЦ у відділі ВТВ | J16: заповнюємо колонку коли отримали інформацію і планова дата ССДЦ, або ДЦ ДУ планується і вказуємо що маємо отримати інформацію
... A26: №1 | B26: Перебазування дільниці | I26: ДЦ у відділі ВТВ | J26: заповнюємо колонку коли отримали інформацію і планова дата ССДЦ, або ДЦ ДУ планується і вказуємо що маємо отримати інформацію
A27: №2 | I27: На внутрішньому погодженні | J27: заповнюємо колонку зауваження до ССДЦ якщо є і на кому затримка в погодженні
A28: №3 | I28: Подано на Замовника | J28: заповнюємо колонку коли замовник обіцяє погодити, зауваження якщо є
A29: №4 | I29: Погоджено Замовником | J29: заповнюємо колонку коментарі з датою коли буде оригінал
A30: №1 | I30: ДЦ у відділі ВТВ | J30: заповнюємо колонку коли отримали інформацію і планова дата ССДЦ, або ДЦ ДУ планується і вказуємо що маємо отримати інформацію
A31: №2 | I31: На внутрішньому погодженні | J31: заповнюємо колонку зауваження до ССДЦ якщо є і на кому затримка в погодженні
A32: №3 | I32: Подано на Замовника | J32: заповнюємо колонку коли замовник обіцяє погодити, зауваження якщо є
A33: №4 | I33: Погоджено Замовником | J33: заповнюємо колонку коментарі з датою коли буде оригінал
A34: №5 | I34: Оригінал в офісі | J34: не заповнюємо колонку коментарі
B35: ВСЬОГО: | C35: =SUM(C5:C34) -> 0 | D35: =SUM(D5:D34) -> 0 | E35: =SUM(E5:E34) -> 0

Sheet 10 акт переносится
A2: Реєстр актів виконаних робіт по об'єкту "Ладижин -2"
A4: Акт №1 | B4: Вид робіт (витрат) | C4: Договірна ціна | E4: Зміст актів виконаних робіт | F4: Управлінський облік 2021 р. | Y4: Всього управлінський облік | AB4: ТОВ "ІНДАСТРІАЛБУД"
F5: квітень 2021 р. | H5: травень 2021 р. | J5: червень 2021 р. | L5: липень 2021 р. | N5: серпень 2021 р. | P5: вересень 2021 р. | R5: жовтень 2021 р.
C6: № ДЦ | D6: Сумма ДЦ | F6: № акта | G6: сума, грн з ПДВ | H6: № акта | I6: сума, грн з ПДВ | J6: № акта | K6: сума, грн з ПДВ | L6: № акта | M6: сума, грн з ПДВ | N6: № акта | O6: сума, грн з ПДВ | P6: № акта | Q6: сума, грн з ПДВ | R6: № акта | S6: сума, грн з ПДВ | T6: № акта | U6: сума, грн з ПДВ | V6: № акта | W6: сума, грн з ПДВ | Y6: № акта | Z6: сума, грн з ПДВ | AA6: загальна сума | AB6: всього | AC6: робота | AD6: мат-ли
A7: 1 | B7: 2 | C7: 3 | D7: 4 | E7: 5 | F7: 8 | G7: 9 | Y7: 10 | Z7: 11 | AA7: 12 | AB7: 19 | AC7: 20 | AD7: 21
A8: 1 | B8: Будівництво каркасу оліє-пресового цеху №2 з трансформаторною підстанцією, м.Ладижин, Вінницька область | C8: №1 | D8: 9670800 | E8: земля та фундаменти 7.1-7.9, 12.1-12.3 | F8: №1 | G8: =288379.22 -> 288379.22 | Y8: 1 | Z8: 288379.22 | AA8: =SUM(AB8:AB22) -> 8579031.9 | AB8: 288379.22 | AC8: 279386.06 | AD8: 8993.16
E9: земля 10.6, 10.12 | F9: №2 | G9: 193609.49 | Y9: 2 | Z9: 193609.49 | AB9: 193609.49 | AC9: 193609.49 | AD9: 0
E10: земля, фундаменти 7.1-7.9, 12.1-12.3 | H10: №3 | I10: 266283.61 | Y10: 3 | Z10: 266283.61 | AB10: 266283.61 | AC10: 256961.43 | AD10: 9322.176
E11: земля 8.1-8.4 | H11: №4 | I11: 1054954.1 | Y11: 4 | Z11: 1054954.1 | AB11: =Z11 -> 1054954.1 | AC11: 1043855.2 | AD11: 11098.87
E12: земля, фундаменти 16.2 | J12: №5 | K12: 70786.21 | Y12: 5 | Z12: 70786.21 | AB12: 70786.21 | AC12: 68044.39 | AD12: 2741.82
J13: №6 | K13: 862817.57 | Y13: 6 | Z13: 862817.57 | AB13: 862817.57 | AC13: 805192.25 | AD13: 57625.32
J14: №7 | K14: 291462.71 | Y14: 7 | Z14: 291462.71 | AB14: 291462.71 | AC14: 280166.43 | AD14: 11296.28
J15: №8 | K15: 449187.01 | Y15: 8 | Z15: =K15 -> 449187.01 | AB15: =Z15 -> 449187.01 | AC15: 439722.83 | AD15: 9464.18
J16: №9 | K16: 603287.62 | Y16: 9 | Z16: 603287.62 | AB16: 603287.62 | AC16: 595984.13 | AD16: 7303.49
E17: земля, фунд.7.1-7.9, 8.1-8.4, з/б 16.2 | L17: №10 | M17: 941673.71 | Y17: 10 | Z17: =M17 -> 941673.71 | AB17: =Z17 -> 941673.71 | AC17: =AB17-AD17 -> 921997.47 | AD17: 19676.244
E18: земля, щеб., арм.7.1-7.9, 8.1-8.4, з/б 16.2 | L18: №11 | M18: =Z18 -> 293363.47 | Y18: 11 | Z18: 293363.47 | AB18: =Z18 -> 293363.47 | AC18: 290271.42 | AD18: 3092.05
E19: бет.подг., фунд, гідроіз.7.1-7-9,8.1-8.4,16.2 | L19: №12 | M19: 372983.72 | Y19: 12 | Z19: =M19 -> 372983.72 | AB19: =Z19 -> 372983.72 | AC19: 368468.62 | AD19: 4515.1
E20: земля, фунд.7.1-7.9, 8.1-8.4, м/к 16.2 | N20: №13 | O20: 354144.6 | Y20: №13 | Z20: 354144.6 | AB20: 354144.6 | AC20: =Z20-AD20 -> 349857.55 | AD20: 4287.05
E21: перевез, засипка, ущільн 7.1-7.9, 12.1-12.3 | N21: №14 | O21: 177987.94 | Y21: №14 | Z21: =O21 -> 177987.94 | AB21: 177987.94 | AC21: =AB21-AD21 -> 160077.57 | AD21: 17910.37
E22: фундаменти зерносушарки | P22: №15 | Q22: 2358110.9 | Y22: №15 | Z22: =Q22 -> 2358110.9 | AB22: =Z22 -> 2358110.9 | AC22: 1910403.6 | AD22: 447707.33
Y23: всего | Z23: =SUM(Z8:Z22) -> 8579031.9 | AB23: =SUM(AB8:AB22) -> 8579031.9 | AC23: =SUM(AC8:AC22) -> 7963998.4 | AD23: =SUM(AD8:AD22) -> 615033.44
A25: 2 | B25: ДУ 2 від 19.02.2021 Влаштування шпильок під балки покриття ОПЦ №2 | C25: ДУ 2 | D25: 281803.98 | P25: №1 | Q25: 281803.98 | Y25: №1 | Z25: 281803.98 | AA25: =SUM(AB25:AB26) -> 281803.98 | AB25: =AC25+AD25 -> 281803.98 | AC25: =Z25-AD25 -> 251804.03 | AD25: 29999.95
A27: 3 | B27: Додаткові роботи по монтажу/демонтажу з/б балок каркасу, згідно дефектного акту №1 | D27: 131336.26 | H27: №1 | I27: 110363.99 | Y27: 1 | Z27: =I27 -> 110363.99 | AA27: =AB27 -> 110363.99 | AB27: =I27 -> 110363.99 | AC27: =AB27-AD27 -> 85118.37 | AD27: 25245.62
A30: =A8+1 -> 2 | B30: Влаштування фундаментів допоміжних споруд оліє-пресового цеху по переробці насіння соняшника 1200т/добу №396-10 від 23.03.2021 ДУ 1 | C30: №2 | D30: =#REF! -> #REF! | E30: земля, фундаменти ПРм1 9.5-9.6 | H30: №1 | I30: 111154.22 | Y30: №1 | Z30: 111154.22 | AA30: =SUM(AB30:AB44) -> 2293462.3 | AB30: 111154.22 | AC30: =AB30-AD30 -> 44105.48 | AD30: =55873.95*1.2 -> 67048.74
E31: земля, фундаменти ПРм1 9.7-9.8 | J31: №2 | K31: 99020.51 | Y31: №2 | Z31: =K31 -> 99020.51 | AB31: =K31 -> 99020.51 | AC31: 53748.15 | AD31: 45272.36
J32: №3 | K32: 345752.57 | Y32: №3 | Z32: 345752.57 | AB32: 345752.57 | AC32: 231533.51 | AD32: 114219.06
J33: №4 | K33: 103230.59 | V33: =D30-Z45 -> #REF! | Y33: №4 | Z33: 103230.59 | AB33: 103230.59 | AC33: 30347.27 | AD33: 72883.32
J34: №5 | K34: 58541.36 | Y34: №5 | Z34: 58541.36 | AB34: 58541.36 | AC34: 33049.98 | AD34: 25491.38
L35: №6 | M35: 20510.87 | Y35: №6 | Z35: 20510.87 | AB35: 20510.87 | AC35: =Z35-AD35 -> 19006.322 | AD35: 1504.548
L36: №7 | M36: =Z36 -> 112396.12 | Y36: №7 | Z36: 112396.12 | AB36: =Z36 -> 112396.12 | AC36: 57471.424 | AD36: 54924.696
L37: №8 | M37: 36533.03 | Y37: №8 | Z37: =M37 -> 36533.03 | AB37: =Z37 -> 36533.03 | AC37: 32587.68 | AD37: 3945.35
L38: №9 | M38: 282807.74 | Y38: №9 | Z38: =M38 -> 282807.74 | AB38: =Z38 -> 282807.74 | AC38: =AB38-AD38 -> 157013.31 | AD38: 125794.43
R39: №10 | S39: 236670.38 | W39: ВО 27 | X39: =Z39+Z43+Z44 -> 596567.15 | Y39: №10 | Z39: 236670.38 | AB39: 236670.38 | AC39: =AB39-AD39 -> 135826.63 | AD39: 100843.75
R40: №11 | S40: 78675.94 | W40: ВО 24 | X40: =X39+'Реєстр ДЦ '!#REF!+'Реєстр ДЦ '!#REF!+'Реєстр ДЦ '!#REF!+'Реєстр ДЦ '!#REF! -> #REF! | Y40: №11 | Z40: 78675.94 | AB40: 78675.94 | AC40: =AB40-AD40 -> 32607.32 | AD40: 46068.62
R41: №12 | S41: 83218.66 | W41: ВО 23 | Y41: №12 | Z41: 75489.29 | AB41: =Z41 -> 75489.29 | AC41: =AB41-AD41 -> 31514.7 | AD41: 43974.59
R42: №13 | S42: =Z42 -> 372782.87 | W42: ВО 25 | Y42: №13 | Z42: 372782.87 | AB42: =Z42 -> 372782.87 | AC42: =AB42-AD42 -> 152785.19 | AD42: 219997.68
R43: №14 | S43: 328788.29 | W43: ВО 26 | Y43: №14 | Z43: 356228.86 | AB43: =Z43 -> 356228.86 | AC43: =AB43-AD43 -> 201417.04 | AD43: 154811.82
R44: №15 | S44: 12657.74 | W44: ВО 22 | Y44: №15 | Z44: 3667.91 | AB44: =Z44 -> 3667.91 | AC44: =AB44-AD44 -> 2114.51 | AD44: 1553.4
Y45: всего | Z45: =SUM(Z30:Z44) -> 2293462.3 | AB45: =SUM(AB30:AB44) -> 2293462.3 | AC45: =SUM(AC30:AC40) -> 827297.08 | AD45: =AB45-AC45 -> 1466165.2
A47: 3 | B47: Виготовлення і монтаж металоконструкцій ТХ | C47: №3 | D47: 1540968 | N47: №1 | O47: 248026.63 | Y47: №1 | Z47: 248026.63 | AA47: =SUM(AB47:AB51) -> 672881.95 | AB47: 248026.63 | AC47: =Z47-AD47 -> 242763.11 | AD47: 5263.52
...

Sheet материал Ладижин
A2: АВР "Ладижин -2"
D3: МАТЕРІАЛИ
A4: п/п | B4: ДОГОВІР | C4: № акта | D4: БЕЗ ПДВ | E4: З ПДВ
A5: 1 | B5: Будівництво каркасу оліє-пресового цеху №2 з трансформаторною підстанцією, м.Ладижин, Вінницька область №389-10 від 19.02.2021 | C5: №1 | D5: 7494.3 | E5: =D5*1.2 -> 8993.16
C6: №2 | D6: 23.05 | E6: =D6*1.2 -> 27.66
C7: №3 | D7: 7768.48 | E7: =D7*1.2 -> 9322.176
C8: №4 | D8: 9249.06 | E8: =D8*1.2 -> 11098.872
C9: №5 | D9: 2284.84 | E9: =D9*1.2 -> 2741.808
C10: №6 | D10: 48021.11 | E10: =D10*1.2 -> 57625.332
C11: №7 | D11: 9413.57 | E11: =D11*1.2 -> 11296.284
C12: №8 | D12: 7886.82 | E12: =D12*1.2 -> 9464.184
C13: №9 | D13: 6086.26 | E13: =D13*1.2 -> 7303.512
C14: №10 | D14: 16396.86 | E14: =D14*1.2 -> 19676.232
C15: №11 | D15: 2576.71 | E15: =D15*1.2 -> 3092.052
C16: №12 | D16: 3762.57 | E16: =D16*1.2 -> 4515.084
C17: №13 | D17: 3572.55 | E17: =D17*1.2 -> 4287.06
... C19: №15 | D19: 373089.66 | E19: =D19*1.2 -> 447707.59
C20: всего | E20: =SUM(E5:E19) -> 615061.38
A21: 2 | B21: ДУ 2 від 19.02.2021 Влаштування шпильок під балки покриття ОПЦ №2 №389-10 від 19.02.2021 ДУ 2 від 19.02.2021 | C21: №1 | D21: 24999.96 | E21: =D21*1.2 -> 29999.952
A22: 3 | B22: Додаткові роботи по монтажу/демонтажу з/б балок каркасу, згідно дефектного акту №1 Д/У№1 до дог. №389-10 від 19.02.2021 | C22: №1 | D22: 21038.02 | E22: =D22*1.2 -> 25245.624
A23: =A5+1 -> 2 | B23: Влаштування фундаментів допоміжних споруд оліє-пресового цеху по переробці насіння соняшника 1200т/добу №396-10 від 23.03.2021 ДУ 1 | C23: №1 | D23: 55874.91 | E23: =D23*1.2 -> 67049.892
C24: №2 | D24: 37726.97 | E24: =D24*1.2 -> 45272.364
C25: №3 | D25: 95182.55 | E25: =D25*1.2 -> 114219.06
C26: №4 | D26: 60736.1 | E26: =D26*1.2 -> 72883.32
C27: №5 | D27: 21242.81 | E27: =D27*1.2 -> 25491.372
C28: №6 | D28: 1253.78 | E28: =D28*1.2 -> 1504.536
C29: №7 | D29: 45770.58 | E29: =D29*1.2 -> 54924.696
C30: №8 | D30: 3287.79 | E30: =D30*1.2 -> 3945.348
C31: №9 | D31: 104828.68 | E31: =D31*1.2 -> 125794.42
C32: №10 | D32: 38390.54 | E32: =D32*1.2 -> 46068.648
C33: №11 | D33: 33164.52 | E33: =D33*1.2 -> 39797.424
C34: №12 | D34: 171056.73 | E34: =D34*1.2 -> 205268.08
C35: №13 | D35: 59510.96 | E35: =D35*1.2 -> 71413.152
... C41: №19 | D41: 766.9 | E41: =D41*1.2 -> 920.28
C42: всего | E42: =SUM(E23:E41) -> 1193453.6
A43: 3 | B43: Виготовлення і монтаж металоконструкцій ТХ №406-10 від 02.06.2021 | C43: №1 | D43: 4386.25 | E43: =D43*1.2 -> 5263.5
C44: №2 | D44: 4018.36 | E44: =D44*1.2 -> 4822.032
C45: №3 | D45: 3494.95 | E45: =D45*1.2 -> 4193.94
C46: №4 | D46: 3400.86 | E46: =D46*1.2 -> 4081.032
C47: всего | E47: =SUM(E43:E46) -> 18360.504
...

Sheet Пожарка подрядчик
A1: РЕЄСТР ДОГОВІРНИХ ЦІН
A3: № п/п | B3: Вид робіт (витрат) | C3: ознака робіт | D3: Номер ДЦ | E3: Сумма | F3: Статус
A4: 1 | B4: Монтаж системи газ.пожежогасіння машинного приміщення ЛТПП секц.5 | C4: пожарка | D4: №1 | E4: 107970.18 | F4: погоджено
A5: =A4+1 -> 2 | B5: Монтаж системи контролю загазованості секц.5 | C5: пожарка | D5: №2 | E5: 38378.59 | F5: погоджено
A6: =A5+1 -> 3 | B6: Монтаж автоматичної системи оповіщення людей про пожежу секц.5 | C6: пожарка | D6: №3 | E6: 82852.78 | F6: погоджено
A7: =A6+1 -> 4 | B7: Монтаж системи автоматичної пожежної сигналізації секц.5 | C7: пожарка | D7: №4 | E7: 979787.02 | F7: погоджено
A8: =A7+1 -> 5 | B8: Монтаж системи автоматизації протидимного захисту секц.5 | C8: пожарка | D8: №5 | E8: 565478.29 | F8: погоджено
A9: =A8+1 -> 6 | B9: Монтаж системи димовидалення (технологічна частина) секц.5 | C9: пожарка | D9: №6 | E9: 573308.27 | F9: погоджено
A10: =A9+1 -> 7 | B10: Монтаж системи димовидалення (технологічна частина) секц.5 (дод.роботи) | C10: пожарка | D10: №7 | E10: 88842.36 | F10: погоджено
A11: =A10+1 -> 8 | B11: Монтаж системи автоматизації протидимного захисту секц.6 | C11: пожарка | D11: №12 | E11: 589296.65 | F11: погоджено
A12: =A11+1 -> 9 | B12: Монтаж автоматичної системи оповіщення людей про пожежу секц.6 | C12: пожарка | D12: №10 | E12: 100485.89 | F12: погоджено
A13: =A12+1 -> 10 | B13: Монтаж системи газ.пожежогасіння машинного приміщення ЛТПП секц.6 | C13: пожарка | D13: №8 | E13: 107970.18 | F13: погоджено
A14: =A13+1 -> 11 | B14: Монтаж системи контролю загазованості секц.6 | C14: пожарка | D14: №9 | E14: 55788.36 | F14: погоджено
A15: =A14+1 -> 12 | B15: Монтаж системи автоматичної пожежної сигналізації секц.6 | C15: пожарка | D15: №11 | E15: 1129114.1 | F15: погоджено
A16: =A15+1 -> 13 | B16: Монтаж системи димовидалення (технологічна частина) секц.6 | C16: пожарка | D16: №13 | E16: 542099.16 | F16: погоджено
A17: =A16+1 -> 14 | B17: Монтаж системи димовидалення (технологічна частина) секц.6 (дод.роботи) | C17: пожарка | D17: №14 | E17: 91400.04 | F17: погоджено
B18: ВСЬОГО | E18: =SUBTOTAL(109,E4:E17) -> 5052771.8

Sheet Лист1
