Workbook

Sheet Свод
B2: АПК (Глобине) | C2: =АПК!J60*1.2 -> 1110875.9
B3: Генплан благоустрій (Глобине) | C3: ='Генплан благоустрій'!J49*1.2 -> 162842.05
B4: Генплан дорога СПК (Глобине) | C4: ='Генплан дорога СПК'!J34 -> 0
B5: Генплан митний склад (Глобине) | C5: ='Генплан митний склад'!J17*1.2 -> 8953.836
B6: Генплан підпірна стінка (Глобине) | C6: ='Генплан підпірна стінка'!J11 -> 0
B7: Глобине-2 | C7: ='Глобине-2'!J169*1.2 -> 60007.524
B8: Котельна (Глобине) | C8: =Котельна!J32*1.2 -> 655.5
B9: Насосна Градирня (Глобине) | C9: ='Насосна Градирня'!J12 -> 0
B10: Пожежений резервуар (Глобине) | C10: ='Пож. резервуар'!J67*1.2 -> 764275.34
B11: Пункт фасування та зберігання в бігбегах (Глобине) | C11: =БигБеги!J36*1.2 -> 194434.32
B12: Резервуар для зберігання розчинника(Глобине) | C12: ='Резервуар розчин'!J50*1.2 -> 478068.59
B13: Резервуарний парк соєвої меляси (Глобине) | C13: ='Резервуарний соев мел'!J46*1.21 -> 205384.54
B14: СПК (Глобине) | C14: =СПК!J301*1.2 -> 4722773.1
B15: Транспортна галерея (Глобине) | C15: ='Транспортна галерея'!J67*1.2 -> 181126.67
B16: Цех екстракції (Глобине) | C16: ='Цех екстракції 205'!J712*1.2 -> 3559335
A18: 205.1 | B18: Цех екстракції (Глобине) | C18: ='Цех екстракції 205.1'!J14*1.2 -> 161433.84
B20: ВСЕГО | C20: =SUM(C2:C18) -> 11610166

Sheet АПК
A1: Період | B1: Документ | C1: Аналітика Дт | D1: Аналітика Кт | E1: Дебет | H1: Кредит | K1: Поточне сальдо
E2: Рахунок | H2: Рахунок
A3: 01.05.2025 | B3: Надходження товарів і послуг ІБ00-002184 від 01.05.2025 11:00:00 Оприходованы ТМЦ | C3: Обл. НДС Шнур бентонітовий ГІДРОСТОП 15*25 Надходження товарів і послуг ІБ00-002184 від 01.05.2025 11:00:00 АПК (Глобине) | D3: ПРОТЕКС УКРАЇНА Договір 9 від 11.12.2023_Глобине 2 Рахунок на оплату постачальника ІБ00-001780 від 01.05.2025 23:31:24 | E3: 205 | F3: 18285 | H3: 631 | K3: Д | L3: 357925.54
A4: 01.05.2025 | B4: Надходження товарів і послуг ІБ00-002184 від 01.05.2025 11:00:00 Оприходованы ТМЦ | C4: Обл. НДС Профіль кріпильний 25*15мм Надходження товарів і послуг ІБ00-002184 від 01.05.2025 11:00:00 АПК (Глобине) | D4: ПРОТЕКС УКРАЇНА Договір 9 від 11.12.2023_Глобине 2 Рахунок на оплату постачальника ІБ00-001780 від 01.05.2025 23:31:24 | E4: 205 | F4: 3727.5 | H4: 631 | K4: Д | L4: 361653.04
A5: 01.05.2025 | B5: Переміщення товарів ІБ00-000437 від 01.05.2025 11:10:00 Перемещение ТМЦ | C5: Обл. НДС Труба Дн 89*3 Надходження товарів і послуг ІБ00-002202 від 01.05.2025 11:00:00 АПК (Глобине) | D5: Обл. НДС Труба Дн 89*3 Надходження товарів і послуг ІБ00-002202 від 01.05.2025 11:00:00 Глобине-2 | E5: 205 | F5: 308.44 | H5: 205 | K5: Д | L5: 361961.48
A6: 01.05.2025 | B6: Переміщення товарів ІБ00-000437 від 01.05.2025 11:10:00 Перемещение ТМЦ | C6: Обл. НДС Труба Дн 108*5,0мм Надходження товарів і послуг ІБ00-002202 від 01.05.2025 11:00:00 АПК (Глобине) | D6: Обл. НДС Труба Дн 108*5,0мм Надходження товарів і послуг ІБ00-002202 від 01.05.2025 11:00:00 Глобине-2 | E6: 205 | F6: 287.87 | H6: 205 | K6: Д | L6: 362249.35
A7: 01.05.2025 | B7: Переміщення товарів ІБ00-000437 від 01.05.2025 11:10:00 Перемещение ТМЦ | C7: Обл. НДС Труба 127*5.0мм Надходження товарів і послуг ІБ00-002202 від 01.05.2025 11:00:00 АПК (Глобине) | D7: Обл. НДС Труба 127*5.0мм Надходження товарів і послуг ІБ00-002202 від 01.05.2025 11:00:00 Глобине-2 | E7: 205 | F7: 688.85 | H7: 205 | K7: Д | L7: 362938.2
A8: 01.05.2025 | B8: Переміщення товарів ІБ00-000437 від 01.05.2025 11:10:00 Перемещение ТМЦ | C8: Обл. НДС Труба 159*5.0мм Надходження товарів і послуг ІБ00-002202 від 01.05.2025 11:00:00 АПК (Глобине) | D8: Обл. НДС Труба 159*5.0мм Надходження товарів і послуг ІБ00-002202 від 01.05.2025 11:00:00 Глобине-2 | E8: 205 | F8: 1967.85 | H8: 205 | K8: Д | L8: 364906.05
A9: 01.05.2025 | B9: Переміщення товарів ІБ00-000437 від 01.05.2025 11:10:00 Перемещение ТМЦ | C9: Обл. НДС Труба 219*6 Надходження товарів і послуг ІБ00-002202 від 01.05.2025 11:00:00 АПК (Глобине) | D9: Обл. НДС Труба 219*6 Надходження товарів і послуг ІБ00-002202 від 01.05.2025 11:00:00 Глобине-2 | E9: 205 | F9: 1176.19 | H9: 205 | K9: Д | L9: 366082.24
A10: 01.05.2025 | B10: Переміщення товарів ІБ00-000437 від 01.05.2025 11:10:00 Перемещение ТМЦ | C10: Обл. НДС Труба 377*10,0 Надходження товарів і послуг ІБ00-002202 від 01.05.2025 11:00:00 АПК (Глобине) | D10: Обл. НДС Труба 377*10,0 Надходження товарів і послуг ІБ00-002202 від 01.05.2025 11:00:00 Глобине-2 | E10: 205 | F10: 2801.67 | H10: 205 | K10: Д | L10: 368883.91
A11: 01.05.2025 | B11: Переміщення товарів ІБ00-000437 від 01.05.2025 11:10:00 Перемещение ТМЦ | C11: Обл. НДС Труба 426*10,0мм Надходження товарів і послуг ІБ00-002202 від 01.05.2025 11:00:00 АПК (Глобине) | D11: Обл. НДС Труба 426*10,0мм Надходження товарів і послуг ІБ00-002202 від 01.05.2025 11:00:00 Глобине-2 | E11: 205 | F11: 10641.21 | H11: 205 | K11: Д | L11: 379525.12
A12: 01.05.2025 | B12: Переміщення товарів ІБ00-000430 від 01.05.2025 22:00:50 Перемещение ТМЦ | C12: Обл. НДС Прокат арматурний №12 мм А500С 12м Надходження товарів і послуг ІБ00-000546 від 14.02.2025 10:00:00 АПК (Глобине) | D12: Обл. НДС Прокат арматурний №12 мм А500С 12м Надходження товарів і послуг ІБ00-000546 від 14.02.2025 10:00:00 Пожежений резервуар (Глобине) | E12: 205 | F12: 8990 | H12: 205 | K12: Д | L12: 388515.12
A13: 01.05.2025 | B13: Вимога-накладна ІБ00-000362 від 01.05.2025 22:00:51 Списаны ТМЦ | C13: Обл. НДС Виробничий (Глобине-2) Глобине-2 Прямі материальні виробничі витрати крім зворотніх відходів | D13: Обл. НДС Прокат арматурний №12 мм А500С 12м Надходження товарів і послуг ІБ00-000546 від 14.02.2025 10:00:00 АПК (Глобине) | E13: 231 | H13: 205 | I13: 8990 | K13: Д | L13: 379525.12
A14: 03.05.2025 | B14: Переміщення товарів ІБ00-000395 від 03.05.2025 11:10:00 Перемещение ТМЦ | C14: Обл. НДС Бетон С20/25 W6 F75 P4 Надходження товарів і послуг ІБ00-002008 від 03.05.2025 11:00:00 АПК (Глобине) | D14: Обл. НДС Бетон С20/25 W6 F75 P4 Надходження товарів і послуг ІБ00-002008 від 03.05.2025 11:00:00 Глобине-2 | E14: 205 | F14: 163102.31 | H14: 205 | K14: Д | L14: 542627.43
A15: 08.05.2025 | B15: Переміщення товарів ІБ00-000448 від 08.05.2025 11:10:00 Перемещение ТМЦ | C15: Обл. НДС Пенекрит 25кг/відро Надходження товарів і послуг ІБ00-002340 від 08.05.2025 11:00:00 АПК (Глобине) | D15: Обл. НДС Пенекрит 25кг/відро Надходження товарів і послуг ІБ00-002340 від 08.05.2025 11:00:00 Глобине-2 | E15: 205 | F15: 4687.5 | H15: 205 | K15: Д | L15: 547314.93
A16: 10.05.2025 | B16: Переміщення товарів ІБ00-000428 від 10.05.2025 11:10:00 Перемещение ТМЦ | C16: Обл. НДС Бетон С20/25 W6 F75 P4 Надходження товарів і послуг ІБ00-002159 від 10.05.2025 11:00:00 АПК (Глобине) | D16: Обл. НДС Бетон С20/25 W6 F75 P4 Надходження товарів і послуг ІБ00-002159 від 10.05.2025 11:00:00 Глобине-2 | E16: 205 | F16: 192194.21 | H16: 205 | K16: Д | L16: 739509.14
A17: 14.05.2025 | B17: Надходження товарів і послуг ІБ00-002335 від 14.05.2025 11:00:00 Оприходованы ТМЦ | C17: Обл. НДС Фанера ламінована 1250*2500*21 мм кв м Надходження товарів і послуг ІБ00-002335 від 14.05.2025 11:00:00 АПК (Глобине) | D17: Пері Україна ТОВ Дог СО-24-0001187 від 01.03.2024 Глобине-2 Надходження товарів і послуг ІБ00-002335 від 14.05.2025 11:00:00 | E17: 205 | F17: 119332.5 | H17: 631 | K17: Д | L17: 858841.64
A18: 20.05.2025 | B18: Надходження товарів і послуг ІБ00-002353 від 20.05.2025 11:00:00 Оприходованы ТМЦ | C18: Обл. НДС Труба КАН внутр 110/2000 2,7мм Надходження товарів і послуг ІБ00-002353 від 20.05.2025 11:00:00 АПК (Глобине) | D18: Лук'янець Аліна Василівна ФОП РАХУНКИ_Глобине 2 Рахунок на оплату постачальника ІБ00-001967 від 19.05.2025 17:48:01 | E18: 205 | F18: 1449 | H18: 631 | K18: Д | L18: 860290.64
A19: 20.05.2025 | B19: Надходження товарів і послуг ІБ00-002353 від 20.05.2025 11:00:00 Оприходованы ТМЦ | C19: Обл. НДС Труба КАН внутр 110/1500 2,7мм Надходження товарів і послуг ІБ00-002353 від 20.05.2025 11:00:00 АПК (Глобине) | D19: Лук'янець Аліна Василівна ФОП РАХУНКИ_Глобине 2 Рахунок на оплату постачальника ІБ00-001967 від 19.05.2025 17:48:01 | E19: 205 | F19: 817 | H19: 631 | K19: Д | L19: 861107.64
A20: 20.05.2025 | B20: Надходження товарів і послуг ІБ00-002353 від 20.05.2025 11:00:00 Оприходованы ТМЦ | C20: Обл. НДС Труба КАН 110/500 внутр 2,7мм Надходження товарів і послуг ІБ00-002353 від 20.05.2025 11:00:00 АПК (Глобине) | D20: Лук'янець Аліна Василівна ФОП РАХУНКИ_Глобине 2 Рахунок на оплату постачальника ІБ00-001967 від 19.05.2025 17:48:01 | E20: 205 | F20: 1027.5 | H20: 631 | K20: Д | L20: 862135.14
A21: 20.05.2025 | B21: Надходження товарів і послуг ІБ00-002353 від 20.05.2025 11:00:00 Оприходованы ТМЦ | C21: Обл. НДС Труба 50/3000 внутр Надходження товарів і послуг ІБ00-002353 від 20.05.2025 11:00:00 АПК (Глобине) | D21: Лук'янець Аліна Василівна ФОП РАХУНКИ_Глобине 2 Рахунок на оплату постачальника ІБ00-001967 від 19.05.2025 17:48:01 | E21: 205 | F21: 687 | H21: 631 | K21: Д | L21: 862822.14
A22: 20.05.2025 | B22: Надходження товарів і послуг ІБ00-002353 від 20.05.2025 11:00:00 Оприходованы ТМЦ | C22: Обл. НДС Труба КАН 50/500 1,8мм внутріш Надходження товарів і послуг ІБ00-002353 від 20.05.2025 11:00:00 АПК (Глобине) | D22: Лук'янець Аліна Василівна ФОП РАХУНКИ_Глобине 2 Рахунок на оплату постачальника ІБ00-001967 від 19.05.2025 17:48:01 | E22: 205 | F22: 212 | H22: 631 | K22: Д | L22: 863034.14
A23: 20.05.2025 | B23: Надходження товарів і послуг ІБ00-002353 від 20.05.2025 11:00:00 Оприходованы ТМЦ | C23: Обл. НДС Коліно 110/90° внутр КАН Надходження товарів і послуг ІБ00-002353 від 20.05.2025 11:00:00 АПК (Глобине) | D23: Лук'янець Аліна Василівна ФОП РАХУНКИ_Глобине 2 Рахунок на оплату постачальника ІБ00-001967 від 19.05.2025 17:48:01 | E23: 205 | F23: 134 | H23: 631 | K23: Д | L23: 863168.14
A24: 20.05.2025 | B24: Надходження товарів і послуг ІБ00-002353 від 20.05.2025 11:00:00 Оприходованы ТМЦ | C24: Обл. НДС Коліно КАН. 50/90° внутріш Надходження товарів і послуг ІБ00-002353 від 20.05.2025 11:00:00 АПК (Глобине) | D24: Лук'янець Аліна Василівна ФОП РАХУНКИ_Глобине 2 Рахунок на оплату постачальника ІБ00-001967 від 19.05.2025 17:48:01 | E24: 205 | F24: 145 | H24: 631 | K24: Д | L24: 863313.14
A25: 20.05.2025 | B25: Надходження товарів і послуг ІБ00-002353 від 20.05.2025 11:00:00 Оприходованы ТМЦ | C25: Обл. НДС Трійник 110/110/90° Надходження товарів і послуг ІБ00-002353 від 20.05.2025 11:00:00 АПК (Глобине) | D25: Лук'янець Аліна Василівна ФОП РАХУНКИ_Глобине 2 Рахунок на оплату постачальника ІБ00-001967 від 19.05.2025 17:48:01 | E25: 205 | F25: 754 | H25: 631 | K25: Д | L25: 864067.14
... A28: 20.05.2025 | B28: Переміщення товарів ІБ00-000468 від 20.05.2025 21:00:01 Перемещение ТМЦ | C28: Обл. НДС Шпонка гідроізоляційна ВР 200 20м п Надходження товарів і послуг ІБ00-000524 від 01.02.2025 18:10:19 АПК (Глобине) | D28: Обл. НДС Шпонка гідроізоляційна ВР 200 20м п Надходження товарів і послуг ІБ00-000524 від 01.02.2025 18:10:19 Резервуарний парк соєвої меляси (Глобине) | E28: 205 | F28: 3178.5 | H28: 205 | K28: Д | L28: 871458.14
A29: 22.05.2025 | B29: Вимога-накладна ІБ00-000372 від 22.05.2025 13:18:42 Списаны ТМЦ | C29: Обл. НДС Виробничий (Глобине-2) Глобине-2 Прямі материальні виробничі витрати крім зворотніх відходів | D29: Обл. НДС Бетон С20/25 W6 F75 P4 Надходження товарів і послуг ІБ00-001882 від 26.04.2025 11:00:00 АПК (Глобине) | E29: 231 | H29: 205 | I29: 895.17 | K29: Д | L29: 870562.97
A30: 22.05.2025 | B30: Вимога-накладна ІБ00-000372 від 22.05.2025 13:18:42 Списаны ТМЦ | C30: Обл. НДС Виробничий (Глобине-2) Глобине-2 Прямі материальні виробничі витрати крім зворотніх відходів | D30: Обл. НДС Бетон С20/25 W6 F75 P4 Надходження товарів і послуг ІБ00-002008 від 03.05.2025 11:00:00 АПК (Глобине) | E30: 231 | H30: 205 | I30: 151940.61 | K30: Д | L30: 718622.36
A31: 22.05.2025 | B31: Вимога-накладна ІБ00-000372 від 22.05.2025 13:18:42 Списаны ТМЦ | C31: Обл. НДС Виробничий (Глобине-2) Глобине-2 Прямі материальні виробничі витрати крім зворотніх відходів | D31: Обл. НДС Щебінь 70-120 Надходження товарів і послуг ІБ00-001071 від 05.03.2025 18:40:09 АПК (Глобине) | E31: 231 | H31: 205 | I31: 10478.25 | K31: Д | L31: 708144.11
A32: 26.05.2025 | B32: Надходження товарів і послуг ІБ00-002451 від 26.05.2025 11:00:00 Оприходованы ТМЦ | C32: Обл. НДС Бетон С20/25 W6 F75 P4 Надходження товарів і послуг ІБ00-002451 від 26.05.2025 11:00:00 АПК (Глобине) | D32: Кременчуцький річковий порт ПРАТ Договір 112/Б від 15.10.2024_Глобине-2 Надходження товарів і послуг ІБ00-002451 від 26.05.2025 11:00:00 | E32: 205 | F32: 293460 | H32: 631 | K32: Д | L32: 1001604.1
A33: 26.05.2025 | B33: Надходження дод. витрат ІБ00-000341 від 26.05.2025 11:05:00 Доп. расходы при поступлении товаров | C33: Обл. НДС Бетон С20/25 W6 F75 P4 Надходження товарів і послуг ІБ00-002451 від 26.05.2025 11:00:00 АПК (Глобине) | D33: Кременчуцький річковий порт ПРАТ Договір 112/Б від 15.10.2024_Глобине-2 Надходження дод. витрат ІБ00-000341 від 26.05.2025 11:05:00 | E33: 205 | F33: 85120 | H33: 631 | K33: Д | L33: 1086724.1
A34: 28.05.2025 | B34: Переміщення товарів ІБ00-000508 від 28.05.2025 11:10:00 Перемещение ТМЦ | C34: Обл. НДС Пісок з відсіву дроблення щебеню фр. 0-5мм. Надходження товарів і послуг ІБ00-002712 від 28.05.2025 11:00:00 АПК (Глобине) | D34: Обл. НДС Пісок з відсіву дроблення щебеню фр. 0-5мм. Надходження товарів і послуг ІБ00-002712 від 28.05.2025 11:00:00 Глобине-2 | E34: 205 | F34: 2053.33 | H34: 205 | K34: Д | L34: 1088777.4
A35: 29.05.2025 | B35: Переміщення товарів ІБ00-000490 від 29.05.2025 08:00:00 Перемещение ТМЦ | C35: Обл. НДС Емульсія бітумна Р-10 EN каністра 20л Надходження товарів і послуг ІБ00-002088 від 19.12.2023 18:21:48 АПК (Глобине) | D35: Обл. НДС Емульсія бітумна Р-10 EN каністра 20л Надходження товарів і послуг ІБ00-002088 від 19.12.2023 18:21:48 Глобине-2 | E35: 205 | F35: 4977 | H35: 205 | K35: Д | L35: 1093754.4
A36: 29.05.2025 | B36: Переміщення товарів ІБ00-000494 від 29.05.2025 08:00:00 Перемещение ТМЦ | C36: Обл. НДС Емульсія бітумна Igoflex-101 каністра 32л Надходження товарів і послуг ІБ00-000606 від 21.02.2024 23:54:14 Транспортна галерея (Глобине) | D36: Обл. НДС Емульсія бітумна Igoflex-101 каністра 32л Надходження товарів і послуг ІБ00-000606 від 21.02.2024 23:54:14 АПК (Глобине) | E36: 205 | H36: 205 | I36: 2507.38 | K36: Д | L36: 1091247.1
A37: 29.05.2025 | B37: Переміщення товарів ІБ00-000494 від 29.05.2025 08:00:00 Перемещение ТМЦ | C37: Обл. НДС Емульсія бітумна Igoflex-101 каністра 32л Надходження товарів і послуг ІБ00-001108 від 22.03.2024 17:34:05 Транспортна галерея (Глобине) | D37: Обл. НДС Емульсія бітумна Igoflex-101 каністра 32л Надходження товарів і послуг ІБ00-001108 від 22.03.2024 17:34:05 АПК (Глобине) | E37: 205 | H37: 205 | I37: 811.37 | K37: Д | L37: 1090435.7
A38: 29.05.2025 | B38: Вимога-накладна ІБ00-000391 від 29.05.2025 12:24:48 Списаны ТМЦ | C38: Обл. НДС Виробничий (Глобине-2) Глобине-2 Прямі материальні виробничі витрати крім зворотніх відходів | D38: Обл. НДС Бетон С20/25 W6 F75 P4 Надходження товарів і послуг ІБ00-002008 від 03.05.2025 11:00:00 АПК (Глобине) | E38: 231 | H38: 205 | I38: 11161.7 | K38: Д | L38: 1079274
A39: 29.05.2025 | B39: Вимога-накладна ІБ00-000391 від 29.05.2025 12:24:48 Списаны ТМЦ | C39: Обл. НДС Виробничий (Глобине-2) Глобине-2 Прямі материальні виробничі витрати крім зворотніх відходів | D39: Обл. НДС Бетон С20/25 W6 F75 P4 Надходження товарів і послуг ІБ00-002159 від 10.05.2025 11:00:00 АПК (Глобине) | E39: 231 | H39: 205 | I39: 192194.21 | K39: Д | L39: 887079.78
A40: 29.05.2025 | B40: Вимога-накладна ІБ00-000391 від 29.05.2025 12:24:48 Списаны ТМЦ | C40: Обл. НДС Виробничий (Глобине-2) Глобине-2 Прямі материальні виробничі витрати крім зворотніх відходів | D40: Обл. НДС Пенетрон Адмікс 18кг/мішок/відро Надходження товарів і послуг ІБ00-001895 від 30.04.2025 11:00:00 АПК (Глобине) | E40: 231 | H40: 205 | I40: 20965.5 | K40: Д | L40: 866114.28
A41: 29.05.2025 | B41: Вимога-накладна ІБ00-000391 від 29.05.2025 12:24:48 Списаны ТМЦ | C41: Обл. НДС Виробничий (Глобине-2) Глобине-2 Прямі материальні виробничі витрати крім зворотніх відходів | D41: Обл. НДС Шпонка гідроізоляційна ВР 200 20м п Надходження товарів і послуг ІБ00-000524 від 01.02.2025 18:10:19 АПК (Глобине) | E41: 231 | H41: 205 | I41: 3178.5 | K41: Д | L41: 862935.78
A42: 29.05.2025 | B42: Вимога-накладна ІБ00-000391 від 29.05.2025 12:24:48 Списаны ТМЦ | C42: Обл. НДС Виробничий (Глобине-2) Глобине-2 Прямі материальні виробничі витрати крім зворотніх відходів | D42: Обл. НДС Шнур бентонітовий ГІДРОСТОП 15*25 Надходження товарів і послуг ІБ00-002184 від 01.05.2025 11:00:00 АПК (Глобине) | E42: 231 | H42: 205 | I42: 11105.09 | K42: Д | L42: 851830.69
...

Sheet Генплан благоустрій
A1: Період | B1: Документ | C1: Аналітика Дт | D1: Аналітика Кт | E1: Дебет | H1: Кредит | K1: Поточне сальдо
E2: Рахунок | H2: Рахунок
A3: 03.05.2025 | B3: Надходження товарів і послуг ІБ00-001965 від 03.05.2025 11:00:00 Оприходованы ТМЦ | C3: Обл. НДС Пісок з відсіву дроблення щебеню фр. 0-5мм. Надходження товарів і послуг ІБ00-001965 від 03.05.2025 11:00:00 Генплан благоустрій (Глобине) | D3: Енергія Логістик ТОВ №28/10-2024 ВІД 28/10/24_Глобине-2 Рахунок на оплату постачальника ІБ00-001612 від 03.05.2025 11:00:01 | E3: 205 | F3: 7443.33 | H3: 631 | K3: Д | L3: 7443.33
A4: 20.05.2025 | B4: Переміщення товарів ІБ00-000480 від 20.05.2025 15:00:33 Перемещение ТМЦ | C4: Обл. НДС Замок навісний Надходження товарів і послуг ІБ00-002303 від 17.05.2025 11:00:00 Генплан благоустрій (Глобине) | D4: Обл. НДС Замок навісний Надходження товарів і послуг ІБ00-002303 від 17.05.2025 11:00:00 Глобине-2 | E4: 205 | F4: 418.2 | H4: 221 | K4: Д | L4: 7861.53
A5: 20.05.2025 | B5: Переміщення товарів ІБ00-000480 від 20.05.2025 15:00:33 Перемещение ТМЦ | C5: Обл. НДС Дріт оцинк. т/о 1,4 мм Авансовий звіт ІБ00-000116 від 19.05.2025 15:48:32 Генплан благоустрій (Глобине) | D5: Обл. НДС Дріт оцинк. т/о 1,4 мм Авансовий звіт ІБ00-000116 від 19.05.2025 15:48:32 Глобине-2 | E5: 205 | F5: 273.9 | H5: 205 | K5: Д | L5: 8135.43
A6: 20.05.2025 | B6: Переміщення товарів ІБ00-000480 від 20.05.2025 15:00:33 Перемещение ТМЦ | C6: Обл. НДС Дріт оцинкований 3,0 мм Авансовий звіт ІБ00-000116 від 19.05.2025 15:48:32 Генплан благоустрій (Глобине) | D6: Обл. НДС Дріт оцинкований 3,0 мм Авансовий звіт ІБ00-000116 від 19.05.2025 15:48:32 Глобине-2 | E6: 205 | F6: 153.98 | H6: 205 | K6: Д | L6: 8289.41
A7: 20.05.2025 | B7: Переміщення товарів ІБ00-000482 від 20.05.2025 15:09:52 Перемещение ТМЦ | C7: Обл. НДС Труба ДУ 32*2,8 ст.1-3пс; 6 м Надходження товарів і послуг ІБ00-001657 від 01.04.2025 11:00:00 Генплан благоустрій (Глобине) | D7: Обл. НДС Труба ДУ 32*2,8 ст.1-3пс; 6 м Надходження товарів і послуг ІБ00-001657 від 01.04.2025 11:00:00 Генплан митний склад (Глобине) | E7: 205 | F7: 993.25 | H7: 205 | K7: Д | L7: 9282.66
A8: 20.05.2025 | B8: Переміщення товарів ІБ00-000482 від 20.05.2025 15:09:52 Перемещение ТМЦ | C8: Обл. НДС Дріт колючо-ріжуч спіраль діам кільця=500мм/3скоби 10м Надходження товарів і послуг ІБ00-001809 від 11.04.2025 11:00:00 Генплан благоустрій (Глобине) | D8: Обл. НДС Дріт колючо-ріжуч спіраль діам кільця=500мм/3скоби 10м Надходження товарів і послуг ІБ00-001809 від 11.04.2025 11:00:00 Генплан митний склад (Глобине) | E8: 205 | F8: 5250 | H8: 205 | K8: Д | L8: 14532.66
A9: 20.05.2025 | B9: Переміщення товарів ІБ00-000482 від 20.05.2025 15:09:52 Перемещение ТМЦ | C9: Обл. НДС Щебенево-піщана суміш фр 0-70 мм Надходження товарів і послуг ІБ00-001628 від 12.04.2025 12:00:03 Генплан благоустрій (Глобине) | D9: Обл. НДС Щебенево-піщана суміш фр 0-70 мм Надходження товарів і послуг ІБ00-001628 від 12.04.2025 12:00:03 Генплан митний склад (Глобине) | E9: 205 | F9: 20590.5 | H9: 205 | K9: Д | L9: 35123.16
A10: 20.05.2025 | B10: Переміщення товарів ІБ00-000482 від 20.05.2025 15:09:52 Перемещение ТМЦ | C10: Обл. НДС Щебінь 40-70 Надходження товарів і послуг ІБ00-001604 від 11.04.2025 20:51:44 Генплан благоустрій (Глобине) | D10: Обл. НДС Щебінь 40-70 Надходження товарів і послуг ІБ00-001604 від 11.04.2025 20:51:44 Генплан митний склад (Глобине) | E10: 205 | F10: 9479.29 | H10: 205 | K10: Д | L10: 44602.45
A11: 20.05.2025 | B11: Переміщення товарів ІБ00-000481 від 20.05.2025 21:00:02 Перемещение ТМЦ | C11: Обл. НДС Бетон С20/25 W6 F75 P4 Надходження товарів і послуг ІБ00-002051 від 06.05.2025 11:00:00 Генплан благоустрій (Глобине) | D11: Обл. НДС Бетон С20/25 W6 F75 P4 Надходження товарів і послуг ІБ00-002051 від 06.05.2025 11:00:00 Резервуар для зберігання розчинника(Глобине) | E11: 205 | F11: 3994.07 | H11: 205 | K11: Д | L11: 48596.52
A12: 20.05.2025 | B12: Переміщення товарів ІБ00-000483 від 20.05.2025 21:00:03 Перемещение ТМЦ | C12: Обл. НДС Щебінь 20-40 Надходження товарів і послуг ІБ00-001692 від 14.04.2025 11:00:00 Генплан благоустрій (Глобине) | D12: Обл. НДС Щебінь 20-40 Надходження товарів і послуг ІБ00-001692 від 14.04.2025 11:00:00 СПК (Глобине) | E12: 205 | F12: 4423.21 | H12: 205 | K12: Д | L12: 53019.73
A13: 22.05.2025 | B13: Переміщення товарів ІБ00-000457 від 22.05.2025 16:33:25 Перемещение ТМЦ | C13: Обл. НДС Щебінь 20-40 Надходження товарів і послуг ІБ00-002154 від 10.05.2025 11:00:00 Генплан благоустрій (Глобине) | D13: Обл. НДС Щебінь 20-40 Надходження товарів і послуг ІБ00-002154 від 10.05.2025 11:00:00 СПК (Глобине) | E13: 205 | F13: 14277.25 | H13: 205 | K13: Д | L13: 67296.98
A14: 22.05.2025 | B14: Переміщення товарів ІБ00-000457 від 22.05.2025 16:33:25 Перемещение ТМЦ | C14: Обл. НДС Щебінь 20-40 Надходження товарів і послуг ІБ00-002157 від 13.05.2025 11:00:00 Генплан благоустрій (Глобине) | D14: Обл. НДС Щебінь 20-40 Надходження товарів і послуг ІБ00-002157 від 13.05.2025 11:00:00 СПК (Глобине) | E14: 205 | F14: 11925.5 | H14: 205 | K14: Д | L14: 79222.48
A15: 22.05.2025 | B15: Вимога-накладна ІБ00-000377 від 22.05.2025 16:33:58 Списаны ТМЦ | C15: Обл. НДС Виробничий (Глобине-2) Глобине-2 Прямі материальні виробничі витрати крім зворотніх відходів | D15: Обл. НДС Щебінь 20-40 Надходження товарів і послуг ІБ00-001692 від 14.04.2025 11:00:00 Генплан благоустрій (Глобине) | E15: 231 | H15: 205 | I15: 4423.21 | K15: Д | L15: 74799.27
A16: 22.05.2025 | B16: Вимога-накладна ІБ00-000377 від 22.05.2025 16:33:58 Списаны ТМЦ | C16: Обл. НДС Виробничий (Глобине-2) Глобине-2 Прямі материальні виробничі витрати крім зворотніх відходів | D16: Обл. НДС Щебінь 20-40 Надходження товарів і послуг ІБ00-002154 від 10.05.2025 11:00:00 Генплан благоустрій (Глобине) | E16: 231 | H16: 205 | I16: 14277.25 | K16: Д | L16: 60522.02
A17: 22.05.2025 | B17: Вимога-накладна ІБ00-000377 від 22.05.2025 16:33:58 Списаны ТМЦ | C17: Обл. НДС Виробничий (Глобине-2) Глобине-2 Прямі материальні виробничі витрати крім зворотніх відходів | D17: Обл. НДС Щебінь 20-40 Надходження товарів і послуг ІБ00-002157 від 13.05.2025 11:00:00 Генплан благоустрій (Глобине) | E17: 231 | H17: 205 | I17: 9474.08 | K17: Д | L17: 51047.94
A18: 29.05.2025 | B18: Переміщення товарів ІБ00-000495 від 29.05.2025 08:00:00 Перемещение ТМЦ | C18: Обл. НДС Пісок з відсіву дроблення щебеню фр. 0-5мм. Надходження товарів і послуг ІБ00-001527 від 09.04.2025 11:00:00 Генплан благоустрій (Глобине) | D18: Обл. НДС Пісок з відсіву дроблення щебеню фр. 0-5мм. Надходження товарів і послуг ІБ00-001527 від 09.04.2025 11:00:00 Генплан дорога СПК (Глобине) | E18: 205 | F18: 9300 | H18: 205 | K18: Д | L18: 60347.94
A19: 29.05.2025 | B19: Переміщення товарів ІБ00-000495 від 29.05.2025 08:00:00 Перемещение ТМЦ | C19: Обл. НДС Пісок з відсіву дроблення щебеню фр. 0-5мм. Надходження товарів і послуг ІБ00-001881 від 29.04.2025 11:00:00 Генплан благоустрій (Глобине) | D19: Обл. НДС Пісок з відсіву дроблення щебеню фр. 0-5мм. Надходження товарів і послуг ІБ00-001881 від 29.04.2025 11:00:00 Генплан дорога СПК (Глобине) | E19: 205 | F19: 12794.67 | H19: 205 | K19: Д | L19: 73142.61
A20: 29.05.2025 | B20: Переміщення товарів ІБ00-000495 від 29.05.2025 08:00:00 Перемещение ТМЦ | C20: Обл. НДС Пісок з відсіву дроблення щебеню фр. 0-5мм. Надходження товарів і послуг ІБ00-002158 від 05.05.2025 11:00:00 Генплан благоустрій (Глобине) | D20: Обл. НДС Пісок з відсіву дроблення щебеню фр. 0-5мм. Надходження товарів і послуг ІБ00-002158 від 05.05.2025 11:00:00 Генплан дорога СПК (Глобине) | E20: 205 | F20: 571.08 | H20: 205 | K20: Д | L20: 73713.69
A21: 29.05.2025 | B21: Переміщення товарів ІБ00-000495 від 29.05.2025 08:00:00 Перемещение ТМЦ | C21: Обл. НДС Геотекстиль термоскріплений F-50 300г/м.кв (шир. 5 м) Надходження товарів і послуг ІБ00-000821 від 03.03.2025 18:09:02 Генплан благоустрій (Глобине) | D21: Обл. НДС Геотекстиль термоскріплений F-50 300г/м.кв (шир. 5 м) Надходження товарів і послуг ІБ00-000821 від 03.03.2025 18:09:02 Генплан дорога СПК (Глобине) | E21: 205 | F21: 8631.93 | H21: 205 | K21: Д | L21: 82345.62
A22: 29.05.2025 | B22: Переміщення товарів ІБ00-000522 від 29.05.2025 08:00:00 Перемещение ТМЦ | C22: Обл. НДС Пісок з відсіву дроблення щебеню фр. 0-5мм. Надходження товарів і послуг ІБ00-002158 від 05.05.2025 11:00:00 Генплан благоустрій (Глобине) | D22: Обл. НДС Пісок з відсіву дроблення щебеню фр. 0-5мм. Надходження товарів і послуг ІБ00-002158 від 05.05.2025 11:00:00 Генплан дорога СПК (Глобине) | E22: 205 | F22: 6982.25 | H22: 205 | K22: Д | L22: 89327.87
A23: 29.05.2025 | B23: Переміщення товарів ІБ00-000522 від 29.05.2025 08:00:00 Перемещение ТМЦ | C23: Обл. НДС Пісок з відсіву дроблення щебеню фр. 0-5мм. Надходження товарів і послуг ІБ00-002047 від 06.05.2025 11:00:00 Генплан благоустрій (Глобине) | D23: Обл. НДС Пісок з відсіву дроблення щебеню фр. 0-5мм. Надходження товарів і послуг ІБ00-002047 від 06.05.2025 11:00:00 Генплан дорога СПК (Глобине) | E23: 205 | F23: 4147.91 | H23: 205 | K23: Д | L23: 93475.78
A24: 29.05.2025 | B24: Переміщення товарів ІБ00-000522 від 29.05.2025 08:00:00 Перемещение ТМЦ | C24: Обл. НДС Щебнево-пісчана суміш фр.0-70 мм Надходження товарів і послуг ІБ00-002632 від 23.05.2025 11:00:00 Генплан благоустрій (Глобине) | D24: Обл. НДС Щебнево-пісчана суміш фр.0-70 мм Надходження товарів і послуг ІБ00-002632 від 23.05.2025 11:00:00 Генплан дорога СПК (Глобине) | E24: 205 | F24: 5709.33 | H24: 205 | K24: Д | L24: 99185.11
A25: 29.05.2025 | B25: Переміщення товарів ІБ00-000522 від 29.05.2025 08:00:00 Перемещение ТМЦ | C25: Обл. НДС Геотекстиль термоскріплений F-50 300г/м.кв (шир. 5 м) Надходження товарів і послуг ІБ00-000821 від 03.03.2025 18:09:02 Генплан благоустрій (Глобине) | D25: Обл. НДС Геотекстиль термоскріплений F-50 300г/м.кв (шир. 5 м) Надходження товарів і послуг ІБ00-000821 від 03.03.2025 18:09:02 Генплан дорога СПК (Глобине) | E25: 205 | F25: 12828.22 | H25: 205 | K25: Д | L25: 112013.33
A26: 29.05.2025 | B26: Вимога-накладна ІБ00-000397 від 29.05.2025 14:52:08 Списаны ТМЦ | C26: Обл. НДС Виробничий (Глобине-2) Глобине-2 Прямі материальні виробничі витрати крім зворотніх відходів | D26: Обл. НДС Замок навісний Надходження товарів і послуг ІБ00-002303 від 17.05.2025 11:00:00 Генплан благоустрій (Глобине) | E26: 231 | H26: 205 | I26: 418.2 | K26: Д | L26: 111595.13
A27: 29.05.2025 | B27: Вимога-накладна ІБ00-000397 від 29.05.2025 14:52:08 Списаны ТМЦ | C27: Обл. НДС Виробничий (Глобине-2) Глобине-2 Прямі материальні виробничі витрати крім зворотніх відходів | D27: Обл. НДС Дріт оцинк. т/о 1,4 мм Авансовий звіт ІБ00-000116 від 19.05.2025 15:48:32 Генплан благоустрій (Глобине) | E27: 231 | H27: 205 | I27: 273.9 | K27: Д | L27: 111321.23
A28: 29.05.2025 | B28: Вимога-накладна ІБ00-000397 від 29.05.2025 14:52:08 Списаны ТМЦ | C28: Обл. НДС Виробничий (Глобине-2) Глобине-2 Прямі материальні виробничі витрати крім зворотніх відходів | D28: Обл. НДС Дріт оцинкований 3,0 мм Авансовий звіт ІБ00-000116 від 19.05.2025 15:48:32 Генплан благоустрій (Глобине) | E28: 231 | H28: 205 | I28: 153.98 | K28: Д | L28: 111167.25
A29: 29.05.2025 | B29: Вимога-накладна ІБ00-000397 від 29.05.2025 14:52:08 Списаны ТМЦ | C29: Обл. НДС Виробничий (Глобине-2) Глобине-2 Прямі материальні виробничі витрати крім зворотніх відходів | D29: Обл. НДС Бетон С20/25 W6 F75 P4 Надходження товарів і послуг ІБ00-002051 від 06.05.2025 11:00:00 Генплан благоустрій (Глобине) | E29: 231 | H29: 205 | I29: 3994.07 | K29: Д | L29: 107173.18
A30: 29.05.2025 | B30: Вимога-накладна ІБ00-000397 від 29.05.2025 14:52:08 Списаны ТМЦ | C30: Обл. НДС Виробничий (Глобине-2) Глобине-2 Прямі материальні виробничі витрати крім зворотніх відходів | D30: Обл. НДС Пісок з відсіву дроблення щебеню фр. 0-5мм. Надходження товарів і послуг ІБ00-001965 від 03.05.2025 11:00:00 Генплан благоустрій (Глобине) | E30: 231 | H30: 205 | I30: 1032.17 | K30: Д | L30: 106141.01
A31: 29.05.2025 | B31: Вимога-накладна ІБ00-000397 від 29.05.2025 14:52:08 Списаны ТМЦ | C31: Обл. НДС Виробничий (Глобине-2) Глобине-2 Прямі материальні виробничі витрати крім зворотніх відходів | D31: Обл. НДС Труба ДУ 32*2,8 ст.1-3пс; 6 м Надходження товарів і послуг ІБ00-001657 від 01.04.2025 11:00:00 Генплан благоустрій (Глобине) | E31: 231 | H31: 205 | I31: 993.25 | K31: Д | L31: 105147.76
A32: 29.05.2025 | B32: Вимога-накладна ІБ00-000397 від 29.05.2025 14:52:08 Списаны ТМЦ | C32: Обл. НДС Виробничий (Глобине-2) Глобине-2 Прямі материальні виробничі витрати крім зворотніх відходів | D32: Обл. НДС Дріт колючо-ріжуч спіраль діам кільця=500мм/3скоби 10м Надходження товарів і послуг ІБ00-001809 від 11.04.2025 11:00:00 Генплан благоустрій (Глобине) | E32: 231 | H32: 205 | I32: 5250 | K32: Д | L32: 99897.76
A33: 29.05.2025 | B33: Вимога-накладна ІБ00-000397 від 29.05.2025 14:52:08 Списаны ТМЦ | C33: Обл. НДС Виробничий (Глобине-2) Глобине-2 Прямі материальні виробничі витрати крім зворотніх відходів | D33: Обл. НДС Щебінь 20-40 Надходження товарів і послуг ІБ00-002157 від 13.05.2025 11:00:00 Генплан благоустрій (Глобине) | E33: 231 | H33: 205 | I33: 2451.42 | K33: Д | L33: 97446.34
A34: 29.05.2025 | B34: Вимога-накладна ІБ00-000397 від 29.05.2025 14:52:08 Списаны ТМЦ | C34: Обл. НДС Виробничий (Глобине-2) Глобине-2 Прямі материальні виробничі витрати крім зворотніх відходів | D34: Обл. НДС Пісок з відсіву дроблення щебеню фр. 0-5мм. Надходження товарів і послуг ІБ00-001965 від 03.05.2025 11:00:00 Генплан благоустрій (Глобине) | E34: 231 | H34: 205 | I34: 1925 | K34: Д | L34: 95521.34
A35: 29.05.2025 | B35: Вимога-накладна ІБ00-000397 від 29.05.2025 14:52:08 Списаны ТМЦ | C35: Обл. НДС Виробничий (Глобине-2) Глобине-2 Прямі материальні виробничі витрати крім зворотніх відходів | D35: Обл. НДС Щебенево-піщана суміш фр 0-70 мм Надходження товарів і послуг ІБ00-001628 від 12.04.2025 12:00:03 Генплан благоустрій (Глобине) | E35: 231 | H35: 205 | I35: 20590.5 | K35: Д | L35: 74930.84
A36: 29.05.2025 | B36: Вимога-накладна ІБ00-000397 від 29.05.2025 14:52:08 Списаны ТМЦ | C36: Обл. НДС Виробничий (Глобине-2) Глобине-2 Прямі материальні виробничі витрати крім зворотніх відходів | D36: Обл. НДС Щебінь 40-70 Надходження товарів і послуг ІБ00-001604 від 11.04.2025 20:51:44 Генплан благоустрій (Глобине) | E36: 231 | H36: 205 | I36: 9479.29 | K36: Д | L36: 65451.55
A37: 29.05.2025 | B37: Вимога-накладна ІБ00-000410 від 29.05.2025 21:00:00 Списаны ТМЦ | C37: Обл. НДС Виробничий (Глобине-2) Глобине-2 Прямі материальні виробничі витрати крім зворотніх відходів | D37: Обл. НДС Пісок з відсіву дроблення щебеню фр. 0-5мм. Надходження товарів і послуг ІБ00-001527 від 09.04.2025 11:00:00 Генплан благоустрій (Глобине) | E37: 231 | H37: 205 | I37: 9300 | K37: Д | L37: 56151.55
... A45: 29.05.2025 | B45: Переміщення товарів ІБ00-000517 від 29.05.2025 21:10:00 Перемещение ТМЦ | C45: Обл. НДС Пісок з відсіву дроблення щебеню фр. 0-5мм. Надходження товарів і послуг ІБ00-002158 від 05.05.2025 11:00:00 Транспортна галерея (Глобине) | D45: Обл. НДС Пісок з відсіву дроблення щебеню фр. 0-5мм. Надходження товарів і послуг ІБ00-002158 від 05.05.2025 11:00:00 Генплан благоустрій (Глобине) | E45: 205 | H45: 205 | I45: 338.25 | K45: Д | L45: 4147.91
A46: 29.05.2025 | B46: Переміщення товарів ІБ00-000517 від 29.05.2025 21:10:00 Перемещение ТМЦ | C46: Обл. НДС Пісок з відсіву дроблення щебеню фр. 0-5мм. Надходження товарів і послуг ІБ00-002047 від 06.05.2025 11:00:00 Транспортна галерея (Глобине) | D46: Обл. НДС Пісок з відсіву дроблення щебеню фр. 0-5мм. Надходження товарів і послуг ІБ00-002047 від 06.05.2025 11:00:00 Генплан благоустрій (Глобине) | E46: 205 | H46: 205 | I46: 4147.91
A47: Обороти за період та сальдо на кінець | E47: 140187.87 | H47: 140187.87 | L47: 0
...

Sheet Генплан дорога СПК
A1: Період | B1: Документ | C1: Аналітика Дт | D1: Аналітика Кт | E1: Дебет | H1: Кредит | K1: Поточне сальдо
E2: Рахунок | H2: Рахунок
A3: 05.05.2025 | B3: Надходження товарів і послуг ІБ00-002158 від 05.05.2025 11:00:00 Оприходованы ТМЦ | C3: Обл. НДС Пісок з відсіву дроблення щебеню фр. 0-5мм. Надходження товарів і послуг ІБ00-002158 від 05.05.2025 11:00:00 Генплан дорога СПК (Глобине) | D3: Енергія Логістик ТОВ №28/10-2024 ВІД 28/10/24_Глобине-2 Рахунок на оплату постачальника ІБ00-001777 від 05.05.2025 18:06:39 | E3: 205 | F3: 7553.33 | H3: 631 | K3: Д | L3: 169863
A4: 06.05.2025 | B4: Надходження товарів і послуг ІБ00-002047 від 06.05.2025 11:00:00 Оприходованы ТМЦ | C4: Обл. НДС Пісок з відсіву дроблення щебеню фр. 0-5мм. Надходження товарів і послуг ІБ00-002047 від 06.05.2025 11:00:00 Генплан дорога СПК (Глобине) | D4: Енергія Логістик ТОВ №28/10-2024 ВІД 28/10/24_Глобине-2 Рахунок на оплату постачальника ІБ00-001653 від 06.05.2025 18:17:22 | E4: 205 | F4: 7657.83 | H4: 631 | K4: Д | L4: 177520.83
A5: 07.05.2025 | B5: Надходження товарів і послуг ІБ00-002046 від 07.05.2025 11:00:00 Оприходованы ТМЦ | C5: Обл. НДС Пісок з відсіву дроблення щебеню фр. 0-5мм. Надходження товарів і послуг ІБ00-002046 від 07.05.2025 11:00:00 Генплан дорога СПК (Глобине) | D5: Енергія Логістик ТОВ №28/10-2024 ВІД 28/10/24_Глобине-2 Рахунок на оплату постачальника ІБ00-001645 від 07.05.2025 18:53:52 | E5: 205 | F5: 7494.67 | H5: 631 | K5: Д | L5: 185015.5
A6: 08.05.2025 | B6: Надходження товарів і послуг ІБ00-002155 від 08.05.2025 11:00:00 Оприходованы ТМЦ | C6: Обл. НДС Пісок з відсіву дроблення щебеню фр. 0-5мм. Надходження товарів і послуг ІБ00-002155 від 08.05.2025 11:00:00 Генплан дорога СПК (Глобине) | D6: Енергія Логістик ТОВ №28/10-2024 ВІД 28/10/24_Глобине-2 Рахунок на оплату постачальника ІБ00-001762 від 08.05.2025 20:00:03 | E6: 205 | F6: 5655.83 | H6: 631 | K6: Д | L6: 190671.33
A7: 09.05.2025 | B7: Надходження товарів і послуг ІБ00-002156 від 09.05.2025 11:00:00 Оприходованы ТМЦ | C7: Обл. НДС Пісок з відсіву дроблення щебеню фр. 0-5мм. Надходження товарів і послуг ІБ00-002156 від 09.05.2025 11:00:00 Генплан дорога СПК (Глобине) | D7: Енергія Логістик ТОВ №28/10-2024 ВІД 28/10/24_Глобине-2 Рахунок на оплату постачальника ІБ00-001764 від 09.05.2025 20:00:08 | E7: 205 | F7: 7507.5 | H7: 631 | K7: Д | L7: 198178.83
A8: 14.05.2025 | B8: Переміщення товарів ІБ00-000440 від 14.05.2025 11:10:00 Перемещение ТМЦ | C8: Обл. НДС Пісок з відсіву дроблення щебеню фр. 0-5мм. Надходження товарів і послуг ІБ00-002222 від 14.05.2025 11:00:00 Генплан дорога СПК (Глобине) | D8: Обл. НДС Пісок з відсіву дроблення щебеню фр. 0-5мм. Надходження товарів і послуг ІБ00-002222 від 14.05.2025 11:00:00 Глобине-2 | E8: 205 | F8: 1871.83 | H8: 205 | K8: Д | L8: 200050.66
A9: 19.05.2025 | B9: Надходження товарів і послуг ІБ00-002305 від 19.05.2025 11:00:00 Оприходованы ТМЦ | C9: Обл. НДС Пісок з відсіву дроблення щебеню фр. 0-5мм. Надходження товарів і послуг ІБ00-002305 від 19.05.2025 11:00:00 Генплан дорога СПК (Глобине) | D9: Енергія Логістик ТОВ №28/10-2024 ВІД 28/10/24_Глобине-2 Рахунок на оплату постачальника ІБ00-001905 від 19.05.2025 17:47:33 | E9: 205 | F9: 7555.17 | H9: 631 | K9: Д | L9: 207605.83
A10: 21.05.2025 | B10: Надходження товарів і послуг ІБ00-002508 від 21.05.2025 11:00:00 Оприходованы ТМЦ | C10: Обл. НДС Пісок з відсіву дроблення щебеню фр. 0-5мм. Надходження товарів і послуг ІБ00-002508 від 21.05.2025 11:00:00 Генплан дорога СПК (Глобине) | D10: Енергія Логістик ТОВ №28/10-2024 ВІД 28/10/24_Глобине-2 Рахунок на оплату постачальника ІБ00-002169 від 21.05.2025 23:00:10 | E10: 205 | F10: 7991.5 | H10: 631 | K10: Д | L10: 215597.33
A11: 22.05.2025 | B11: Надходження товарів і послуг ІБ00-002716 від 22.05.2025 11:00:00 Оприходованы ТМЦ | C11: Обл. НДС Пісок з відсіву дроблення щебеню фр. 0-5мм. Надходження товарів і послуг ІБ00-002716 від 22.05.2025 11:00:00 Генплан дорога СПК (Глобине) | D11: Енергія Логістик ТОВ №28/10-2024 ВІД 28/10/24_Глобине-2 Рахунок на оплату постачальника ІБ00-002247 від 22.05.2025 18:57:13 | E11: 205 | F11: 1904.83 | H11: 631 | K11: Д | L11: 217502.16
A12: 22.05.2025 | B12: Надходження товарів і послуг ІБ00-002716 від 22.05.2025 11:00:00 Оприходованы ТМЦ | C12: Обл. НДС Щебенево-піщана суміш фр 0-70 мм Надходження товарів і послуг ІБ00-002716 від 22.05.2025 11:00:00 Генплан дорога СПК (Глобине) | D12: Енергія Логістик ТОВ №28/10-2024 ВІД 28/10/24_Глобине-2 Рахунок на оплату постачальника ІБ00-002247 від 22.05.2025 18:57:13 | E12: 205 | F12: 5738.67 | H12: 631 | K12: Д | L12: 223240.83
A13: 23.05.2025 | B13: Надходження товарів і послуг ІБ00-002632 від 23.05.2025 11:00:00 Оприходованы ТМЦ | C13: Обл. НДС Щебнево-пісчана суміш фр.0-70 мм Надходження товарів і послуг ІБ00-002632 від 23.05.2025 11:00:00 Генплан дорога СПК (Глобине) | D13: Енергія Логістик ТОВ №28/10-2024 ВІД 28/10/24_Глобине-2 Рахунок на оплату постачальника ІБ00-002209 від 23.05.2025 17:41:13 | E13: 205 | F13: 5709.33 | H13: 631 | K13: Д | L13: 228950.16
A14: 24.05.2025 | B14: Надходження товарів і послуг ІБ00-002633 від 24.05.2025 11:00:00 Оприходованы ТМЦ | C14: Обл. НДС Щебнево-пісчана суміш фр.0-70 мм Надходження товарів і послуг ІБ00-002633 від 24.05.2025 11:00:00 Генплан дорога СПК (Глобине) | D14: Енергія Логістик ТОВ №28/10-2024 ВІД 28/10/24_Глобине-2 Рахунок на оплату постачальника ІБ00-002210 від 24.05.2025 12:00:07 | E14: 205 | F14: 11621.33 | H14: 631 | K14: Д | L14: 240571.49
... A16: 28.05.2025 | B16: Переміщення товарів ІБ00-000507 від 28.05.2025 11:10:00 Перемещение ТМЦ | C16: Обл. НДС Пісок з відсіву дроблення щебеню фр. 0-5мм. Надходження товарів і послуг ІБ00-002712 від 28.05.2025 11:00:00 Генплан дорога СПК (Глобине) | D16: Обл. НДС Пісок з відсіву дроблення щебеню фр. 0-5мм. Надходження товарів і послуг ІБ00-002712 від 28.05.2025 11:00:00 Глобине-2 | E16: 205 | F16: 5985.84 | H16: 205 | K16: Д | L16: 252498.66
A17: 29.05.2025 | B17: Переміщення товарів ІБ00-000495 від 29.05.2025 08:00:00 Перемещение ТМЦ | C17: Обл. НДС Пісок з відсіву дроблення щебеню фр. 0-5мм. Надходження товарів і послуг ІБ00-001527 від 09.04.2025 11:00:00 Генплан благоустрій (Глобине) | D17: Обл. НДС Пісок з відсіву дроблення щебеню фр. 0-5мм. Надходження товарів і послуг ІБ00-001527 від 09.04.2025 11:00:00 Генплан дорога СПК (Глобине) | E17: 205 | H17: 205 | I17: 9300 | K17: Д | L17: 243198.66
A18: 29.05.2025 | B18: Переміщення товарів ІБ00-000495 від 29.05.2025 08:00:00 Перемещение ТМЦ | C18: Обл. НДС Пісок з відсіву дроблення щебеню фр. 0-5мм. Надходження товарів і послуг ІБ00-001881 від 29.04.2025 11:00:00 Генплан благоустрій (Глобине) | D18: Обл. НДС Пісок з відсіву дроблення щебеню фр. 0-5мм. Надходження товарів і послуг ІБ00-001881 від 29.04.2025 11:00:00 Генплан дорога СПК (Глобине) | E18: 205 | H18: 205 | I18: 12794.67 | K18: Д | L18: 230403.99
A19: 29.05.2025 | B19: Переміщення товарів ІБ00-000495 від 29.05.2025 08:00:00 Перемещение ТМЦ | C19: Обл. НДС Пісок з відсіву дроблення щебеню фр. 0-5мм. Надходження товарів і послуг ІБ00-002158 від 05.05.2025 11:00:00 Генплан благоустрій (Глобине) | D19: Обл. НДС Пісок з відсіву дроблення щебеню фр. 0-5мм. Надходження товарів і послуг ІБ00-002158 від 05.05.2025 11:00:00 Генплан дорога СПК (Глобине) | E19: 205 | H19: 205 | I19: 571.08 | K19: Д | L19: 229832.91
A20: 29.05.2025 | B20: Переміщення товарів ІБ00-000495 від 29.05.2025 08:00:00 Перемещение ТМЦ | C20: Обл. НДС Геотекстиль термоскріплений F-50 300г/м.кв (шир. 5 м) Надходження товарів і послуг ІБ00-000821 від 03.03.2025 18:09:02 Генплан благоустрій (Глобине) | D20: Обл. НДС Геотекстиль термоскріплений F-50 300г/м.кв (шир. 5 м) Надходження товарів і послуг ІБ00-000821 від 03.03.2025 18:09:02 Генплан дорога СПК (Глобине) | E20: 205 | H20: 205 | I20: 8631.93 | K20: Д | L20: 221200.98
A21: 29.05.2025 | B21: Переміщення товарів ІБ00-000522 від 29.05.2025 08:00:00 Перемещение ТМЦ | C21: Обл. НДС Пісок з відсіву дроблення щебеню фр. 0-5мм. Надходження товарів і послуг ІБ00-002158 від 05.05.2025 11:00:00 Генплан благоустрій (Глобине) | D21: Обл. НДС Пісок з відсіву дроблення щебеню фр. 0-5мм. Надходження товарів і послуг ІБ00-002158 від 05.05.2025 11:00:00 Генплан дорога СПК (Глобине) | E21: 205 | H21: 205 | I21: 6982.25 | K21: Д | L21: 214218.73
A22: 29.05.2025 | B22: Переміщення товарів ІБ00-000522 від 29.05.2025 08:00:00 Перемещение ТМЦ | C22: Обл. НДС Пісок з відсіву дроблення щебеню фр. 0-5мм. Надходження товарів і послуг ІБ00-002047 від 06.05.2025 11:00:00 Генплан благоустрій (Глобине) | D22: Обл. НДС Пісок з відсіву дроблення щебеню фр. 0-5мм. Надходження товарів і послуг ІБ00-002047 від 06.05.2025 11:00:00 Генплан дорога СПК (Глобине) | E22: 205 | H22: 205 | I22: 4147.91 | K22: Д | L22: 210070.82
A23: 29.05.2025 | B23: Переміщення товарів ІБ00-000522 від 29.05.2025 08:00:00 Перемещение ТМЦ | C23: Обл. НДС Щебнево-пісчана суміш фр.0-70 мм Надходження товарів і послуг ІБ00-002632 від 23.05.2025 11:00:00 Генплан благоустрій (Глобине) | D23: Обл. НДС Щебнево-пісчана суміш фр.0-70 мм Надходження товарів і послуг ІБ00-002632 від 23.05.2025 11:00:00 Генплан дорога СПК (Глобине) | E23: 205 | H23: 205 | I23: 5709.33 | K23: Д | L23: 204361.49
A24: 29.05.2025 | B24: Переміщення товарів ІБ00-000522 від 29.05.2025 08:00:00 Перемещение ТМЦ | C24: Обл. НДС Геотекстиль термоскріплений F-50 300г/м.кв (шир. 5 м) Надходження товарів і послуг ІБ00-000821 від 03.03.2025 18:09:02 Генплан благоустрій (Глобине) | D24: Обл. НДС Геотекстиль термоскріплений F-50 300г/м.кв (шир. 5 м) Надходження товарів і послуг ІБ00-000821 від 03.03.2025 18:09:02 Генплан дорога СПК (Глобине) | E24: 205 | H24: 205 | I24: 12828.22 | K24: Д | L24: 191533.27
A25: 29.05.2025 | B25: Надходження товарів і послуг ІБ00-002713 від 29.05.2025 11:00:00 Оприходованы ТМЦ | C25: Обл. НДС Пісок з відсіву дроблення щебеню фр. 0-5мм. Надходження товарів і послуг ІБ00-002713 від 29.05.2025 11:00:00 Генплан дорога СПК (Глобине) | D25: Енергія Логістик ТОВ №28/10-2024 ВІД 28/10/24_Глобине-2 Рахунок на оплату постачальника ІБ00-002244 від 29.05.2025 21:10:02 | E25: 205 | F25: 7921.83 | H25: 631 | K25: Д | L25: 199455.1
A26: 29.05.2025 | B26: Переміщення товарів ІБ00-000518 від 29.05.2025 21:10:00 Перемещение ТМЦ | C26: Обл. НДС Пісок з відсіву дроблення щебеню фр. 0-5мм. Надходження товарів і послуг ІБ00-002047 від 06.05.2025 11:00:00 Транспортна галерея (Глобине) | D26: Обл. НДС Пісок з відсіву дроблення щебеню фр. 0-5мм. Надходження товарів і послуг ІБ00-002047 від 06.05.2025 11:00:00 Генплан дорога СПК (Глобине) | E26: 205 | H26: 205 | I26: 3509.92 | K26: Д | L26: 195945.18
A27: 29.05.2025 | B27: Переміщення товарів ІБ00-000518 від 29.05.2025 21:10:00 Перемещение ТМЦ | C27: Обл. НДС Пісок з відсіву дроблення щебеню фр. 0-5мм. Надходження товарів і послуг ІБ00-002046 від 07.05.2025 11:00:00 Транспортна галерея (Глобине) | D27: Обл. НДС Пісок з відсіву дроблення щебеню фр. 0-5мм. Надходження товарів і послуг ІБ00-002046 від 07.05.2025 11:00:00 Генплан дорога СПК (Глобине) | E27: 205 | H27: 205 | I27: 7494.67 | K27: Д | L27: 188450.51
A28: 29.05.2025 | B28: Переміщення товарів ІБ00-000518 від 29.05.2025 21:10:00 Перемещение ТМЦ | C28: Обл. НДС Пісок з відсіву дроблення щебеню фр. 0-5мм. Надходження товарів і послуг ІБ00-002155 від 08.05.2025 11:00:00 Транспортна галерея (Глобине) | D28: Обл. НДС Пісок з відсіву дроблення щебеню фр. 0-5мм. Надходження товарів і послуг ІБ00-002155 від 08.05.2025 11:00:00 Генплан дорога СПК (Глобине) | E28: 205 | H28: 205 | I28: 5655.83 | K28: Д | L28: 182794.68
A29: 29.05.2025 | B29: Переміщення товарів ІБ00-000518 від 29.05.2025 21:10:00 Перемещение ТМЦ | C29: Обл. НДС Пісок з відсіву дроблення щебеню фр. 0-5мм. Надходження товарів і послуг ІБ00-002156 від 09.05.2025 11:00:00 Транспортна галерея (Глобине) | D29: Обл. НДС Пісок з відсіву дроблення щебеню фр. 0-5мм. Надходження товарів і послуг ІБ00-002156 від 09.05.2025 11:00:00 Генплан дорога СПК (Глобине) | E29: 205 | H29: 205 | I29: 778.25 | K29: Д | L29: 182016.43
A30: 30.05.2025 | B30: Надходження товарів і послуг ІБ00-002715 від 30.05.2025 11:00:00 Оприходованы ТМЦ | C30: Обл. НДС Пісок з відсіву дроблення щебеню фр. 0-5мм. Надходження товарів і послуг ІБ00-002715 від 30.05.2025 11:00:00 Генплан дорога СПК (Глобине) | D30: Енергія Логістик ТОВ №28/10-2024 ВІД 28/10/24_Глобине-2 Рахунок на оплату постачальника ІБ00-002246 від 30.05.2025 19:00:07 | E30: 205 | F30: 7905.33 | H30: 631 | K30: Д | L30: 189921.76
A31: 31.05.2025 | B31: Надходження товарів і послуг ІБ00-002714 від 31.05.2025 11:00:00 Оприходованы ТМЦ | C31: Обл. НДС Пісок з відсіву дроблення щебеню фр. 0-5мм. Надходження товарів і послуг ІБ00-002714 від 31.05.2025 11:00:00 Генплан дорога СПК (Глобине) | D31: Енергія Логістик ТОВ №28/10-2024 ВІД 28/10/24_Глобине-2 Рахунок на оплату постачальника ІБ00-002245 від 31.05.2025 23:59:11 | E31: 205 | F31: 7932.83 | H31: 631 | K31: Д | L31: 197854.59
A32: Обороти за період та сальдо на кінець | E32: 113948.98 | H32: 78404.06 | K32: Д | L32: 197854.59

Sheet Генплан митний склад
A1: Період | B1: Документ | C1: Аналітика Дт | D1: Аналітика Кт | E1: Дебет | H1: Кредит | K1: Поточне сальдо
E2: Рахунок | H2: Рахунок
A3: 01.05.2025 | B3: Переміщення товарів ІБ00-000471 від 01.05.2025 12:40:09 Перемещение ТМЦ | C3: Обл. НДС Пісок з відсіву дроблення щебеню фр. 0-5мм. Надходження товарів і послуг ІБ00-001681 від 15.04.2025 11:00:00 Резервуарний парк соєвої меляси (Глобине) | D3: Обл. НДС Пісок з відсіву дроблення щебеню фр. 0-5мм. Надходження товарів і послуг ІБ00-001681 від 15.04.2025 11:00:00 Генплан митний склад (Глобине) | E3: 205 | H3: 205 | I3: 18870 | K3: Д | L3: 193023.2
A4: 01.05.2025 | B4: Переміщення товарів ІБ00-000471 від 01.05.2025 12:40:09 Перемещение ТМЦ | C4: Обл. НДС Пісок з відсіву дроблення щебеню фр. 0-5мм. Надходження товарів і послуг ІБ00-001749 від 18.04.2025 11:00:00 Резервуарний парк соєвої меляси (Глобине) | D4: Обл. НДС Пісок з відсіву дроблення щебеню фр. 0-5мм. Надходження товарів і послуг ІБ00-001749 від 18.04.2025 11:00:00 Генплан митний склад (Глобине) | E4: 205 | H4: 205 | I4: 9105 | K4: Д | L4: 183918.2
A5: 20.05.2025 | B5: Переміщення товарів ІБ00-000452 від 20.05.2025 11:05:00 Перемещение ТМЦ | C5: Обл. НДС Лист г/к 6*1500*6000 мм 3 пс Надходження товарів і послуг ІБ00-002356 від 20.05.2025 11:00:00 Генплан митний склад (Глобине) | D5: Обл. НДС Лист г/к 6*1500*6000 мм 3 пс Надходження товарів і послуг ІБ00-002356 від 20.05.2025 11:00:00 Глобине-2 | E5: 205 | F5: 2022.36 | H5: 205 | K5: Д | L5: 185940.56
A6: 20.05.2025 | B6: Переміщення товарів ІБ00-000452 від 20.05.2025 11:05:00 Перемещение ТМЦ | C6: Обл. НДС Лист г/к 10,0 мм 1500х6000, S235 JR Надходження товарів і послуг ІБ00-002356 від 20.05.2025 11:00:00 Генплан митний склад (Глобине) | D6: Обл. НДС Лист г/к 10,0 мм 1500х6000, S235 JR Надходження товарів і послуг ІБ00-002356 від 20.05.2025 11:00:00 Глобине-2 | E6: 205 | F6: 6898.69 | H6: 205 | K6: Д | L6: 192839.25
A7: 20.05.2025 | B7: Переміщення товарів ІБ00-000452 від 20.05.2025 11:05:00 Перемещение ТМЦ | C7: Обл. НДС Труба профільна 40*40*3,0 L=6000 мм ст1-3 сп/пс Надходження товарів і послуг ІБ00-002356 від 20.05.2025 11:00:00 Генплан митний склад (Глобине) | D7: Обл. НДС Труба профільна 40*40*3,0 L=6000 мм ст1-3 сп/пс Надходження товарів і послуг ІБ00-002356 від 20.05.2025 11:00:00 Глобине-2 | E7: 205 | F7: 1959.48 | H7: 205 | K7: Д | L7: 194798.73
A8: 20.05.2025 | B8: Переміщення товарів ІБ00-000482 від 20.05.2025 15:09:52 Перемещение ТМЦ | C8: Обл. НДС Труба ДУ 32*2,8 ст.1-3пс; 6 м Надходження товарів і послуг ІБ00-001657 від 01.04.2025 11:00:00 Генплан благоустрій (Глобине) | D8: Обл. НДС Труба ДУ 32*2,8 ст.1-3пс; 6 м Надходження товарів і послуг ІБ00-001657 від 01.04.2025 11:00:00 Генплан митний склад (Глобине) | E8: 205 | H8: 205 | I8: 993.25 | K8: Д | L8: 193805.48
A9: 20.05.2025 | B9: Переміщення товарів ІБ00-000482 від 20.05.2025 15:09:52 Перемещение ТМЦ | C9: Обл. НДС Дріт колючо-ріжуч спіраль діам кільця=500мм/3скоби 10м Надходження товарів і послуг ІБ00-001809 від 11.04.2025 11:00:00 Генплан благоустрій (Глобине) | D9: Обл. НДС Дріт колючо-ріжуч спіраль діам кільця=500мм/3скоби 10м Надходження товарів і послуг ІБ00-001809 від 11.04.2025 11:00:00 Генплан митний склад (Глобине) | E9: 205 | H9: 205 | I9: 5250 | K9: Д | L9: 188555.48
A10: 20.05.2025 | B10: Переміщення товарів ІБ00-000482 від 20.05.2025 15:09:52 Перемещение ТМЦ | C10: Обл. НДС Щебенево-піщана суміш фр 0-70 мм Надходження товарів і послуг ІБ00-001628 від 12.04.2025 12:00:03 Генплан благоустрій (Глобине) | D10: Обл. НДС Щебенево-піщана суміш фр 0-70 мм Надходження товарів і послуг ІБ00-001628 від 12.04.2025 12:00:03 Генплан митний склад (Глобине) | E10: 205 | H10: 205 | I10: 20590.5 | K10: Д | L10: 167964.98
A11: 20.05.2025 | B11: Переміщення товарів ІБ00-000482 від 20.05.2025 15:09:52 Перемещение ТМЦ | C11: Обл. НДС Щебінь 40-70 Надходження товарів і послуг ІБ00-001604 від 11.04.2025 20:51:44 Генплан благоустрій (Глобине) | D11: Обл. НДС Щебінь 40-70 Надходження товарів і послуг ІБ00-001604 від 11.04.2025 20:51:44 Генплан митний склад (Глобине) | E11: 205 | H11: 205 | I11: 9479.29 | K11: Д | L11: 158485.69
A12: 29.05.2025 | B12: Переміщення товарів ІБ00-000521 від 29.05.2025 08:00:00 Перемещение ТМЦ | C12: Обл. НДС Дріт в'язальний 1,6 мм 100м Надходження товарів і послуг ІБ00-001661 від 01.04.2025 11:00:00 Пожежений резервуар (Глобине) | D12: Обл. НДС Дріт в'язальний 1,6 мм 100м Надходження товарів і послуг ІБ00-001661 від 01.04.2025 11:00:00 Генплан митний склад (Глобине) | E12: 205 | H12: 205 | I12: 400 | K12: Д | L12: 158085.69
A13: 29.05.2025 | B13: Вимога-накладна ІБ00-000430 від 29.05.2025 21:00:00 Списаны ТМЦ | C13: Обл. НДС Виробничий (Глобине-2) Глобине-2 Прямі материальні виробничі витрати крім зворотніх відходів | D13: Обл. НДС Труба ДУ 32*2,8 ст.1-3пс; 6 м Надходження товарів і послуг ІБ00-001657 від 01.04.2025 11:00:00 Генплан митний склад (Глобине) | E13: 231 | H13: 205 | I13: 7118.3 | K13: Д | L13: 150967.39
A14: 29.05.2025 | B14: Вимога-накладна ІБ00-000430 від 29.05.2025 21:00:00 Списаны ТМЦ | C14: Обл. НДС Виробничий (Глобине-2) Глобине-2 Прямі материальні виробничі витрати крім зворотніх відходів | D14: Обл. НДС Дріт 3,0мм з/я т/о Надходження товарів і послуг ІБ00-001657 від 01.04.2025 11:00:00 Генплан митний склад (Глобине) | E14: 231 | H14: 205 | I14: 343.23 | K14: Д | L14: 150624.16
A15: Обороти за період та сальдо на кінець | E15: 10880.53 | H15: 72149.57 | K15: Д | L15: 150624.16
J17: =SUBTOTAL(9,I13:J14) -> 7461.53

Sheet Генплан підпірна стінка
A1: Період | B1: Документ | C1: Аналітика Дт | D1: Аналітика Кт | E1: Дебет | H1: Кредит | K1: Поточне сальдо
E2: Рахунок | H2: Рахунок
A3: 01.05.2025 | B3: Переміщення товарів ІБ00-000469 від 01.05.2025 12:38:57 Перемещение ТМЦ | C3: Обл. НДС Пісок з відсіву дроблення щебеню фр. 0-5мм. Надходження товарів і послуг ІБ00-001748 від 21.04.2025 11:00:00 Резервуарний парк соєвої меляси (Глобине) | D3: Обл. НДС Пісок з відсіву дроблення щебеню фр. 0-5мм. Надходження товарів і послуг ІБ00-001748 від 21.04.2025 11:00:00 Генплан підпірна стінка (Глобине) | E3: 205 | H3: 205 | I3: 561.75 | K3: Д | L3: 120004.98
A4: 01.05.2025 | B4: Переміщення товарів ІБ00-000474 від 01.05.2025 13:13:33 Перемещение ТМЦ | C4: Обл. НДС Пісок з відсіву дроблення щебеню фр. 0-5мм. Надходження товарів і послуг ІБ00-001748 від 21.04.2025 11:00:00 Резервуар для зберігання розчинника(Глобине) | D4: Обл. НДС Пісок з відсіву дроблення щебеню фр. 0-5мм. Надходження товарів і послуг ІБ00-001748 від 21.04.2025 11:00:00 Генплан підпірна стінка (Глобине) | E4: 205 | H4: 205 | I4: 2765.25 | K4: Д | L4: 117239.73
A5: 01.05.2025 | B5: Переміщення товарів ІБ00-000474 від 01.05.2025 13:13:33 Перемещение ТМЦ | C5: Обл. НДС Пісок з відсіву дроблення щебеню фр. 0-5мм. Надходження товарів і послуг ІБ00-001810 від 23.04.2025 11:00:00 Резервуар для зберігання розчинника(Глобине) | D5: Обл. НДС Пісок з відсіву дроблення щебеню фр. 0-5мм. Надходження товарів і послуг ІБ00-001810 від 23.04.2025 11:00:00 Генплан підпірна стінка (Глобине) | E5: 205 | H5: 205 | I5: 19797.33 | K5: Д | L5: 97442.4
A6: 17.05.2025 | B6: Переміщення товарів ІБ00-000443 від 17.05.2025 11:15:00 Перемещение ТМЦ | C6: Обл. НДС Бетон С20/25 W6 F75 P4 Надходження товарів і послуг ІБ00-002293 від 17.05.2025 11:00:00 Генплан підпірна стінка (Глобине) | D6: Обл. НДС Бетон С20/25 W6 F75 P4 Надходження товарів і послуг ІБ00-002293 від 17.05.2025 11:00:00 Глобине-2 | E6: 205 | F6: 1495.18 | H6: 205 | K6: Д | L6: 98937.58
A7: 22.05.2025 | B7: Переміщення товарів ІБ00-000458 від 22.05.2025 16:49:22 Перемещение ТМЦ | C7: Обл. НДС Цемент ПЦ ІІ/А-Ш 500 25кг 1пал/64шт Надходження товарів і послуг ІБ00-002038 від 01.04.2025 11:00:00 Транспортна галерея (Глобине) | D7: Обл. НДС Цемент ПЦ ІІ/А-Ш 500 25кг 1пал/64шт Надходження товарів і послуг ІБ00-002038 від 01.04.2025 11:00:00 Генплан підпірна стінка (Глобине) | E7: 205 | H7: 205 | I7: 1980 | K7: Д | L7: 96957.58
A8: Обороти за період та сальдо на кінець | E8: 1495.18 | H8: 25104.33 | K8: Д | L8: 96957.58

Sheet Глобине-2
A1: Період | B1: Документ | C1: Аналітика Дт | D1: Аналітика Кт | E1: Дебет | H1: Кредит | K1: Поточне сальдо
E2: Рахунок | H2: Рахунок
A3: 01.05.2025 | B3: Надходження товарів і послуг ІБ00-002050 від 01.05.2025 11:00:00 Оприходованы ТМЦ (Зачет аванса поставщику) | C3: Обл. НДС Бетон С 30/35 W4 F75 Р4 Надходження товарів і послуг ІБ00-002050 від 01.05.2025 11:00:00 Глобине-2 | D3: Кременчуцький річковий порт ПРАТ Договір 112/Б від 15.10.2024_Глобине-2 Списання з банківського рахунку 00000026026 від 28.04.2025 17:40:12 | E3: 205 | F3: 12320 | H3: 631 | K3: Д | L3: 389000.04
A4: 01.05.2025 | B4: Надходження товарів і послуг ІБ00-002050 від 01.05.2025 11:00:00 Оприходованы ТМЦ (Зачет аванса поставщику) | C4: Обл. НДС Бетон С 8/10 Р4 Надходження товарів і послуг ІБ00-002050 від 01.05.2025 11:00:00 Глобине-2 | D4: Кременчуцький річковий порт ПРАТ Договір 112/Б від 15.10.2024_Глобине-2 Списання з банківського рахунку 00000026026 від 28.04.2025 17:40:12 | E4: 205 | F4: 18967.5 | H4: 631 | K4: Д | L4: 407967.54
A5: 01.05.2025 | B5: Надходження товарів і послуг ІБ00-002202 від 01.05.2025 11:00:00 Оприходованы ТМЦ (Зачет аванса поставщику) | C5: Обл. НДС Труба Дн 89*3 Надходження товарів і послуг ІБ00-002202 від 01.05.2025 11:00:00 Глобине-2 | D5: ТСПЛ ТОВ Дог пост № 26/04-21 від 26.04.2021 р._Глобине-2 Рахунок на оплату постачальника ІБ00-001332 від 15.04.2025 18:30:31 | E5: 205 | F5: 308.44 | H5: 631 | K5: Д | L5: 408275.98
A6: 01.05.2025 | B6: Надходження товарів і послуг ІБ00-002202 від 01.05.2025 11:00:00 Оприходованы ТМЦ (Зачет аванса поставщику) | C6: Обл. НДС Труба Дн 108*5,0мм Надходження товарів і послуг ІБ00-002202 від 01.05.2025 11:00:00 Глобине-2 | D6: ТСПЛ ТОВ Дог пост № 26/04-21 від 26.04.2021 р._Глобине-2 Рахунок на оплату постачальника ІБ00-001332 від 15.04.2025 18:30:31 | E6: 205 | F6: 287.87 | H6: 631 | K6: Д | L6: 408563.85
A7: 01.05.2025 | B7: Надходження товарів і послуг ІБ00-002202 від 01.05.2025 11:00:00 Оприходованы ТМЦ (Зачет аванса поставщику) | C7: Обл. НДС Труба 127*5.0мм Надходження товарів і послуг ІБ00-002202 від 01.05.2025 11:00:00 Глобине-2 | D7: ТСПЛ ТОВ Дог пост № 26/04-21 від 26.04.2021 р._Глобине-2 Рахунок на оплату постачальника ІБ00-001332 від 15.04.2025 18:30:31 | E7: 205 | F7: 688.85 | H7: 631 | K7: Д | L7: 409252.7
A8: 01.05.2025 | B8: Надходження товарів і послуг ІБ00-002202 від 01.05.2025 11:00:00 Оприходованы ТМЦ (Зачет аванса поставщику) | C8: Обл. НДС Труба 159*5.0мм Надходження товарів і послуг ІБ00-002202 від 01.05.2025 11:00:00 Глобине-2 | D8: ТСПЛ ТОВ Дог пост № 26/04-21 від 26.04.2021 р._Глобине-2 Рахунок на оплату постачальника ІБ00-001332 від 15.04.2025 18:30:31 | E8: 205 | F8: 1967.85 | H8: 631 | K8: Д | L8: 411220.55
A9: 01.05.2025 | B9: Надходження товарів і послуг ІБ00-002202 від 01.05.2025 11:00:00 Оприходованы ТМЦ (Зачет аванса поставщику) | C9: Обл. НДС Труба 219*6 Надходження товарів і послуг ІБ00-002202 від 01.05.2025 11:00:00 Глобине-2 | D9: ТСПЛ ТОВ Дог пост № 26/04-21 від 26.04.2021 р._Глобине-2 Рахунок на оплату постачальника ІБ00-001332 від 15.04.2025 18:30:31 | E9: 205 | F9: 1176.19 | H9: 631 | K9: Д | L9: 412396.74
A10: 01.05.2025 | B10: Надходження товарів і послуг ІБ00-002202 від 01.05.2025 11:00:00 Оприходованы ТМЦ (Зачет аванса поставщику) | C10: Обл. НДС Труба 377*10,0 Надходження товарів і послуг ІБ00-002202 від 01.05.2025 11:00:00 Глобине-2 | D10: ТСПЛ ТОВ Дог пост № 26/04-21 від 26.04.2021 р._Глобине-2 Рахунок на оплату постачальника ІБ00-001332 від 15.04.2025 18:30:31 | E10: 205 | F10: 2801.67 | H10: 631 | K10: Д | L10: 415198.41
A11: 01.05.2025 | B11: Надходження товарів і послуг ІБ00-002202 від 01.05.2025 11:00:00 Оприходованы ТМЦ (Зачет аванса поставщику) | C11: Обл. НДС Труба 426*10,0мм Надходження товарів і послуг ІБ00-002202 від 01.05.2025 11:00:00 Глобине-2 | D11: ТСПЛ ТОВ Дог пост № 26/04-21 від 26.04.2021 р._Глобине-2 Рахунок на оплату постачальника ІБ00-001332 від 15.04.2025 18:30:31 | E11: 205 | F11: 10641.21 | H11: 631 | K11: Д | L11: 425839.62
A12: 01.05.2025 | B12: Надходження товарів і послуг ІБ00-002202 від 01.05.2025 11:00:00 Оприходованы ТМЦ (Зачет аванса поставщику) | C12: Обл. НДС Труба 325*7,0мм Надходження товарів і послуг ІБ00-002202 від 01.05.2025 11:00:00 Глобине-2 | D12: ТСПЛ ТОВ Дог пост № 26/04-21 від 26.04.2021 р._Глобине-2 Рахунок на оплату постачальника ІБ00-001332 від 15.04.2025 18:30:31 | E12: 205 | F12: 1768.39 | H12: 631 | K12: Д | L12: 427608.01
A13: 01.05.2025 | B13: Надходження товарів і послуг ІБ00-002202 від 01.05.2025 11:00:00 Оприходованы ТМЦ (Зачет аванса поставщику) | C13: Обл. НДС Труба 530*8,0мм Надходження товарів і послуг ІБ00-002202 від 01.05.2025 11:00:00 Глобине-2 | D13: ТСПЛ ТОВ Дог пост № 26/04-21 від 26.04.2021 р._Глобине-2 Рахунок на оплату постачальника ІБ00-001332 від 15.04.2025 18:30:31 | E13: 205 | F13: 4935.05 | H13: 631 | K13: Д | L13: 432543.06
A14: 01.05.2025 | B14: Надходження товарів і послуг ІБ00-002202 від 01.05.2025 11:00:00 Оприходованы ТМЦ (Зачет аванса поставщику) | C14: Обл. НДС Труба 720*8,0мм Надходження товарів і послуг ІБ00-002202 від 01.05.2025 11:00:00 Глобине-2 | D14: ТСПЛ ТОВ Дог пост № 26/04-21 від 26.04.2021 р._Глобине-2 Рахунок на оплату постачальника ІБ00-001332 від 15.04.2025 18:30:31 | E14: 205 | F14: 5110.87 | H14: 631 | K14: Д | L14: 437653.93
... A20: 01.05.2025 | B20: Надходження дод. витрат ІБ00-000299 від 01.05.2025 11:05:00 Доп. расходы при поступлении товаров (Зачет аванса поставщику) | C20: Обл. НДС Бетон С 8/10 Р4 Надходження товарів і послуг ІБ00-002050 від 01.05.2025 11:00:00 Глобине-2 | D20: Кременчуцький річковий порт ПРАТ Договір 112/Б від 15.10.2024_Глобине-2 Списання з банківського рахунку 00000026026 від 28.04.2025 17:40:12 | E20: 205 | F20: 11800.32 | H20: 631 | K20: Д | L20: 480210.87
A21: 01.05.2025 | B21: Переміщення товарів ІБ00-000413 від 01.05.2025 11:10:00 Перемещение ТМЦ | C21: Обл. НДС Бетон С 8/10 Р4 Надходження товарів і послуг ІБ00-002050 від 01.05.2025 11:00:00 Резервуар для зберігання розчинника(Глобине) | D21: Обл. НДС Бетон С 8/10 Р4 Надходження товарів і послуг ІБ00-002050 від 01.05.2025 11:00:00 Глобине-2 | E21: 205 | H21: 205 | I21: 5811.7 | K21: Д | L21: 474399.17
