Workbook

Sheet Лист2
B1: Код (Таб. №) | C1: Наименование | D1: Код по ДРФО | E1: Вид договора | F1: Вид занятости | G1: Подразделение организации | H1: Должность организации | I1: Дата приема
B2: 1 | C2: Оренда авто
B3: д000000007 | C3: Воронцов Олександр Володимирович (оренда авто) | D3: 3244112838 | E3: Договор подряда (выполнение работ, оказание услуг)
B4: д000000023 | C4: Гавриченко Тетяна Василівна (оренда авто) | D4: 2890614789 | E4: Договор подряда (выполнение работ, оказание услуг)
B5: д000000010 | C5: Гриценко Олександр Вікторович (оренда авто) | D5: 2751711415 | E5: Договор подряда (выполнение работ, оказание услуг)
B6: д000000001 | C6: Гриценко Сергій Миколайович (дг.) | D6: 3382914593 | E6: Договор подряда (выполнение работ, оказание услуг)
B7: д000000013 | C7: Гриценко Сергій Миколайович (оренда авто) | D7: 3382914593 | E7: Договор подряда (выполнение работ, оказание услуг)
B8: д000000019 | C8: Гуняга Олег Володимирович (оренда авто) | D8: 2711822114 | E8: Договор подряда (выполнение работ, оказание услуг)
B9: д000000008 | C9: Манжула Максим Анатолійович (оренда авто) | D9: 3281710375 | E9: Договор подряда (выполнение работ, оказание услуг)
B10: д000000014 | C10: Огоновський Дмитро Анатолійович (оренда авто) | D10: 2866215672 | E10: Договор подряда (выполнение работ, оказание услуг)
B11: д000000015 | C11: Потьомко Михайло Володимирович (оренда авто) | D11: 3575508457 | E11: Договор подряда (выполнение работ, оказание услуг)
B12: д000000016 | C12: Сикал Павло Анатолійович (оренда авто) | D12: 3306506991 | E12: Договор подряда (выполнение работ, оказание услуг)
B13: д000000012 | C13: Старіков Сергій Вікторович (оренда авто) | D13: 2899410750 | E13: Договор подряда (выполнение работ, оказание услуг)
B14: д000000020 | C14: Шевченко Євген Анатолійович (оренда авто) | D14: 3194113635 | E14: Договор подряда (выполнение работ, оказание услуг)
B15: д000000009 | C15: Ширшов Олександр Леонідович (оренда авто) | D15: 2234022693 | E15: Договор подряда (выполнение работ, оказание услуг)
B16: 23 | C16: Адаменко Віталій Вікторович | D16: 3153900053 | E16: Трудовой договор | F16: Основное место работы | G16: Виробничий (Цех металоконструкцій) | H16: Монтажник будівельний | I16: 05.10.2022
B17: 4 | C17: Аксенчіков Сергій Олександрович | D17: 3457309598 | E17: Трудовой договор | F17: Основное место работы | G17: Адміністративний відділ | H17: Майстер будівельних та монтажних робіт | I17: 01.07.2022
B18: д000000001 | C18: Аксенчіков Сергій Олександрович (оренда авто) | D18: 3457309598 | E18: Договор подряда (выполнение работ, оказание услуг)
B19: 48 | C19: Александров Артем Анатолійович | D19: 2618119132 | E19: Трудовой договор | F19: Основное место работы | G19: Адміністративний відділ | H19: Діловод | I19: 25.09.2018
B20: 203 | C20: Александров Денис Анатолійович | D20: 2765913876 | E20: Трудовой договор | F20: Основное место работы | G20: Адміністративний відділ | H20: Помічник економіста | I20: 01.02.2021
B21: 156 | C21: Александрова Жанна Валентинівна | D21: 2693717247 | E21: Трудовой договор | F21: Основное место работы | G21: Адміністративний відділ | H21: Прибиральник службових приміщень | I21: 01.07.2020
B22: 2289516770 | C22: Антонович Тетяна Сергіївна | D22: 2894801342 | E22: Трудовой договор | F22: Основное место работы | G22: Адміністративний відділ | H22: Директор фінансовий | I22: 22.12.2022
B23: 16 | C23: Антонович Тетяна Сергіївна (сум.) | D23: 2894801342 | E23: Трудовой договор | F23: Внешнее совместительство | G23: Адміністративний відділ | H23: Директор фінансовий | I23: 26.05.2023
B24: 17 | C24: Аулова Маргарита Володимирівна | D24: 3036417408 | E24: Трудовой договор | F24: Внешнее совместительство | G24: Адміністративний відділ | H24: Головний бухгалтер | I24: 01.04.2024
B25: 2289516882 | C25: Аулова Маргарита Володимирівна (осн.) | D25: 3036417408 | E25: Трудовой договор | F25: Основное место работы | G25: Адміністративний відділ | H25: Головний бухгалтер | I25: 27.03.2024
B26: 2289516833 | C26: Ахмедов Тавакгюль Сардар огли | D26: 2358421934 | E26: Трудовой договор | F26: Основное место работы | G26: Виробничий (Ладижин-3) | H26: Маляр | I26: 08.09.2023
B27: 37 | C27: Бабіленко Микола Олександрович | D27: 2564424513 | E27: Трудовой договор | F27: Основное место работы | G27: Виробничий (Цех металоконструкцій) | H27: Слюсар із складання металевих конструкцій | I27: 01.12.2022
B28: 11 | C28: Багацький Вадим Геннадійович | D28: 3247506159 | E28: Трудовой договор | F28: Основное место работы | G28: Виробничий (Цех металоконструкцій) | H28: Електрозварник ручного зварювання | I28: 05.08.2022
B29: 2289516701 | C29: Безкоровайний Дмитро Миколайович | D29: 3358009052 | E29: Трудовой договор | F29: Основное место работы | G29: Виробничий (Підгірці) | H29: Водій автотранспортних засобів | I29: 04.02.2022
B30: 62 | C30: Білоусов Євген Вікторович | D30: 3421002151 | E30: Трудовой договор | F30: Основное место работы | G30: Виробничий (Старокостянтинів) | H30: Арматурник (будівельні, монтажні й ремонтно-будівельні роботи) | I30: 01.02.2019
B31: д000000006 | C31: Бічковський Максим Петрович | D31: 2922419813 | E31: Договор подряда (выполнение работ, оказание услуг)
B32: 2289516746 | C32: Блоха Євген Валерійович | D32: 2919308010 | E32: Трудовой договор | F32: Основное место работы | G32: Виробничий (Старокостянтинів) | H32: Бетоняр | I32: 27.09.2022
B33: 2289516849 | C33: Богданюк Дмитро Леонтійович | D33: 3036408418 | E33: Трудовой договор | F33: Основное место работы | G33: Адміністративний відділ | H33: Інженер з проєктно-кошторисної роботи | I33: 02.11.2023
B34: 19 | C34: Богун Олена Миколаївна | D34: 3813305164 | E34: Трудовой договор | F34: Основное место работы | G34: Виробничій цех | H34: Лаборант | I34: 02.07.2024
B35: 2289516863 | C35: Божков Валерій Вікторович | D35: 2753702532 | E35: Трудовой договор | F35: Основное место работы | G35: Виробничий (Крушинка) | H35: Водій автотранспортних засобів | I35: 19.12.2023
B36: 46 | C36: Бокоч Галина Михайлівна (осн.) | D36: 3018718189 | E36: Трудовой договор | F36: Основное место работы | G36: Адміністративний відділ | H36: Діловод | I36: 24.11.2023
B37: 157 | C37: Болох Володимир Васильович | D37: 2794610037 | E37: Трудовой договор | F37: Основное место работы | G37: Виробничий (Старокостянтинів) | H37: Машиніст крана автомобільного | I37: 03.08.2020
B38: 71 | C38: Борецька Людмила Сергіївна | D38: 3280710149 | E38: Трудовой договор | F38: Основное место работы | G38: Адміністративний відділ | H38: Економіст | I38: 08.04.2019
B39: 2289516756 | C39: Борисенко Олексій Миколайович | D39: 2957816213 | E39: Трудовой договор | F39: Основное место работы | G39: Виробничий (Крушинка) | H39: Машиніст крана автомобільного | I39: 01.11.2022
B40: 49 | C40: Бреус Віталій Григорович | D40: 3143007035 | E40: Трудовой договор | F40: Основное место работы | G40: Адміністративний відділ | H40: Менеджер (управитель) з постачання | I40: 18.07.2023
...

Sheet Лист1
B2: N | C2: Работник (основное назначение) | D2: Период взаиморасчетов | E2: Счет учета | F2: Сумма | G2: Сумма (окр.) | J2: Админ
B3: 1 | C3: Аксенчіков Сергій Олександрович | D3: 01.07.2024 | E3: 661 | F3: 4326 | H3: =MATCH(I3,#REF!,0) -> #REF! | I3: =TRIM(C3) -> Аксенчіков Сергій Олександрович | J3: 1
B4: 2 | C4: Бабіленко Микола Олександрович | D4: 01.07.2024 | E4: 661 | F4: 3990 | H4: =MATCH(I4,#REF!,0) -> #REF! | I4: =TRIM(C4) -> Бабіленко Микола Олександрович | K4: =INDEX(Лист2!D:D,MATCH(C4,Лист2!C:C,0)) -> 2564424513
B5: 3 | C5: Багацький Вадим Геннадійович | D5: 01.07.2024 | E5: 661 | F5: 3990 | H5: =MATCH(I5,#REF!,0) -> #REF! | I5: =TRIM(C5) -> Багацький Вадим Геннадійович | K5: =INDEX(Лист2!D:D,MATCH(C5,Лист2!C:C,0)) -> 3247506159
B6: 4 | C6: Бреус Віталій Григорович | D6: 01.07.2024 | E6: 661 | F6: 5417.99 | H6: =MATCH(I6,#REF!,0) -> #REF! | I6: =TRIM(C6) -> Бреус Віталій Григорович | J6: 1
B7: 5 | C7: Бутенко Матвій Анатолійович | D7: 01.07.2024 | E7: 661 | F7: 4326 | H7: =MATCH(I7,#REF!,0) -> #REF! | I7: =TRIM(C7) -> Бутенко Матвій Анатолійович | J7: 1
B8: 6 | C8: Васильєв Віталій Юрійович | D8: 01.07.2024 | E8: 661 | F8: 3990 | H8: =MATCH(I8,#REF!,0) -> #REF! | I8: =TRIM(C8) -> Васильєв Віталій Юрійович | K8: =INDEX(Лист2!D:D,MATCH(C8,Лист2!C:C,0)) -> 3746304158
B9: 7 | C9: Власенко В'ячеслав Валентинович | D9: 01.07.2024 | E9: 661 | F9: 3990 | H9: =MATCH(I9,#REF!,0) -> #REF! | I9: =TRIM(C9) -> Власенко В'ячеслав Валентинович | K9: =INDEX(Лист2!D:D,MATCH(C9,Лист2!C:C,0)) -> 2831710277
B10: 8 | C10: Горєлов Микита Євгенович | D10: 01.07.2024 | E10: 661 | F10: 2660 | H10: =MATCH(I10,#REF!,0) -> #REF! | I10: =TRIM(C10) -> Горєлов Микита Євгенович | K10: =INDEX(Лист2!D:D,MATCH(C10,Лист2!C:C,0)) -> 3596200395
B11: 9 | C11: Григор'єв Микола Андрійович | D11: 01.07.2024 | E11: 661 | F11: 1662.5 | H11: =MATCH(I11,#REF!,0) -> #REF! | I11: =TRIM(C11) -> Григор'єв Микола Андрійович | K11: =INDEX(Лист2!D:D,MATCH(C11,Лист2!C:C,0)) -> 3422005391
B12: 10 | C12: Григор'єв Михайло Андрійович | D12: 01.07.2024 | E12: 661 | F12: 3990 | H12: =MATCH(I12,#REF!,0) -> #REF! | I12: =TRIM(C12) -> Григор'єв Михайло Андрійович | K12: =INDEX(Лист2!D:D,MATCH(C12,Лист2!C:C,0)) -> 3720407672
B13: 11 | C13: Григоренко Олександр Миколайович | D13: 01.07.2024 | E13: 661 | F13: 3990 | H13: =MATCH(I13,#REF!,0) -> #REF! | I13: =TRIM(C13) -> Григоренко Олександр Миколайович | K13: =INDEX(Лист2!D:D,MATCH(C13,Лист2!C:C,0)) -> 2436600937
B14: 12 | C14: Гриценко Олександр Вікторович | D14: 01.07.2024 | E14: 661 | F14: 5197.5 | H14: =MATCH(I14,#REF!,0) -> #REF! | I14: =TRIM(C14) -> Гриценко Олександр Вікторович | J14: 1
B15: 13 | C15: Грушко Лариса Вікторівна | D15: 01.07.2024 | E15: 661 | F15: 4427.5 | H15: =MATCH(I15,#REF!,0) -> #REF! | I15: =TRIM(C15) -> Грушко Лариса Вікторівна | J15: 1
B16: 14 | C16: Дехтяр Владислав Олександрович | D16: 01.07.2024 | E16: 661 | F16: 3990 | H16: =MATCH(I16,#REF!,0) -> #REF! | I16: =#REF! -> #REF! | K16: =INDEX(Лист2!D:D,MATCH(C16,Лист2!C:C,0)) -> 3374502899
B17: 15 | C17: Желтяков Ігор Юрійович | D17: 01.07.2024 | E17: 661 | F17: 3990 | H17: =MATCH(I17,#REF!,0) -> #REF! | I17: =TRIM(C17) -> Желтяков Ігор Юрійович | K17: =INDEX(Лист2!D:D,MATCH(C17,Лист2!C:C,0)) -> 2637303953
B18: 16 | C18: Іванов Олексій Вікторович | D18: 01.07.2024 | E18: 661 | F18: 3990 | H18: =MATCH(I18,#REF!,0) -> #REF! | I18: =TRIM(C18) -> Іванов Олексій Вікторович | K18: =INDEX(Лист2!D:D,MATCH(C18,Лист2!C:C,0)) -> 3705902230
B19: 17 | C19: Іскрицький Денис Русланович | D19: 01.07.2024 | E19: 661 | F19: 3990 | H19: =MATCH(I19,#REF!,0) -> #REF! | I19: =TRIM(C19) -> Іскрицький Денис Русланович | K19: =INDEX(Лист2!D:D,MATCH(C19,Лист2!C:C,0)) -> 3779110293
B20: 18 | C20: Кіфор Юрій Михайлович | D20: 01.07.2024 | E20: 661 | F20: 3990.02 | H20: =MATCH(I20,#REF!,0) -> #REF! | I20: =TRIM(C20) -> Кіфор Юрій Михайлович | K20: =INDEX(Лист2!D:D,MATCH(C20,Лист2!C:C,0)) -> 2521518612
B21: 19 | C21: Корнієнко Станіслав Володимирович | D21: 01.07.2024 | E21: 661 | F21: 3428.01 | H21: =MATCH(I21,#REF!,0) -> #REF! | I21: =C21 -> Корнієнко Станіслав Володимирович | K21: =INDEX(Лист2!D:D,MATCH(C21,Лист2!C:C,0)) -> 2579305831
B22: 20 | C22: Масливець Ігор Валерійович | D22: 01.07.2024 | E22: 661 | F22: 3990 | H22: =MATCH(I22,#REF!,0) -> #REF! | I22: =TRIM(C22) -> Масливець Ігор Валерійович | K22: =INDEX(Лист2!D:D,MATCH(C22,Лист2!C:C,0)) -> 2880313812
B23: 21 | C23: Мельниченко Максим Вікторович | D23: 01.07.2024 | E23: 661 | F23: 6650 | H23: =MATCH(I23,#REF!,0) -> #REF! | I23: =TRIM(C23) -> Мельниченко Максим Вікторович | K23: =INDEX(Лист2!D:D,MATCH(C23,Лист2!C:C,0)) -> 3348501613
B24: 22 | C24: Мороз Віталій Миколайович | D24: 01.07.2024 | E24: 661 | F24: 6650 | H24: =MATCH(I24,#REF!,0) -> #REF! | I24: =TRIM(C24) -> Мороз Віталій Миколайович | K24: =INDEX(Лист2!D:D,MATCH(C24,Лист2!C:C,0)) -> 3216804294
B25: 23 | C25: Нестерук Сергій Петрович | D25: 01.07.2024 | E25: 661 | F25: 3990.02 | H25: =MATCH(I25,#REF!,0) -> #REF! | I25: =TRIM(C25) -> Нестерук Сергій Петрович | K25: =INDEX(Лист2!D:D,MATCH(C25,Лист2!C:C,0)) -> 3283102618
B26: 24 | C26: Паламарчук Вячеслав Володимирович | D26: 01.07.2024 | E26: 661 | F26: 3990 | H26: =MATCH(I26,#REF!,0) -> #REF! | I26: =TRIM(C26) -> Паламарчук Вячеслав Володимирович | K26: =INDEX(Лист2!D:D,MATCH(C26,Лист2!C:C,0)) -> 3230316597
B27: 25 | C27: Парнєва Олена Вікторівна | D27: 01.07.2024 | E27: 661 | F27: 840 | H27: =MATCH(I27,#REF!,0) -> #REF! | I27: =TRIM(C27) -> Парнєва Олена Вікторівна | K27: =INDEX(Лист2!D:D,MATCH(C27,Лист2!C:C,0)) -> 2938511042
B28: 26 | C28: Пилипчук Олександр Анатолійович | D28: 01.07.2024 | E28: 661 | F28: 3990 | H28: =MATCH(I28,#REF!,0) -> #REF! | I28: =TRIM(C28) -> Пилипчук Олександр Анатолійович | K28: =INDEX(Лист2!D:D,MATCH(C28,Лист2!C:C,0)) -> 3067218612
B29: 27 | C29: Поліщук Олександр Олександрович | D29: 01.07.2024 | E29: 661 | F29: 3990 | H29: =MATCH(I29,#REF!,0) -> #REF! | I29: =TRIM(C29) -> Поліщук Олександр Олександрович | K29: =INDEX(Лист2!D:D,MATCH(C29,Лист2!C:C,0)) -> 3289716153
B30: 28 | C30: Пономаренко Віталій Вікторович | D30: 01.07.2024 | E30: 661 | F30: 3990 | H30: =MATCH(I30,#REF!,0) -> #REF! | I30: =TRIM(C30) -> Пономаренко Віталій Вікторович | K30: =INDEX(Лист2!D:D,MATCH(C30,Лист2!C:C,0)) -> 3185119514
B31: 29 | C31: Пономаренко Олександр Вікторович | D31: 01.07.2024 | E31: 661 | F31: 5460 | H31: =MATCH(I31,#REF!,0) -> #REF! | I31: =TRIM(C31) -> Пономаренко Олександр Вікторович | K31: =INDEX(Лист2!D:D,MATCH(C31,Лист2!C:C,0)) -> 2944519172
B32: 30 | C32: Пономарьов Микола Вікторович | D32: 01.07.2024 | E32: 661 | F32: 3990 | H32: =MATCH(I32,#REF!,0) -> #REF! | I32: =TRIM(C32) -> Пономарьов Микола Вікторович | K32: =INDEX(Лист2!D:D,MATCH(C32,Лист2!C:C,0)) -> 3008300898
B33: 31 | C33: Понуркін Євген Григорович | D33: 01.07.2024 | E33: 661 | F33: 3990 | H33: =MATCH(I33,#REF!,0) -> #REF! | I33: =TRIM(C33) -> Понуркін Євген Григорович | K33: =INDEX(Лист2!D:D,MATCH(C33,Лист2!C:C,0)) -> 3005702873
... B38: 36 | C38: Скрипник Сергій Павлович | D38: 01.07.2024 | E38: 661 | F38: 5460 | H38: =MATCH(I38,#REF!,0) -> #REF! | I38: =TRIM(C38) -> Скрипник Сергій Павлович | K38: =INDEX(Лист2!D:D,MATCH(C38,Лист2!C:C,0)) -> 3219619831
B39: 37 | C39: Стецюк Тетяна Леонідівна | D39: 01.07.2024 | E39: 661 | F39: 5460 | H39: =MATCH(I39,#REF!,0) -> #REF! | I39: =TRIM(C39) -> Стецюк Тетяна Леонідівна | J39: 1
B40: 38 | C40: Тужиков Валерій Владиславович (осн.) | D40: 01.07.2024 | E40: 661 | F40: 3990 | H40: =MATCH(I40,#REF!,0) -> #REF! | I40: =#REF! -> #REF! | K40: =INDEX(Лист2!D:D,MATCH(C40,Лист2!C:C,0)) -> 3233009756
B41: 39 | C41: Тужиков Юрій Владиславович | D41: 01.07.2024 | E41: 661 | F41: 3324.99 | H41: =MATCH(I41,#REF!,0) -> #REF! | I41: =TRIM(C41) -> Тужиков Юрій Владиславович | K41: =INDEX(Лист2!D:D,MATCH(C41,Лист2!C:C,0)) -> 3153508799
B42: 40 | C42: Федорчук Денис Сергійович | D42: 01.07.2024 | E42: 661 | F42: 1995 | H42: =MATCH(I42,#REF!,0) -> #REF! | I42: =TRIM(C42) -> Федорчук Денис Сергійович | K42: =INDEX(Лист2!D:D,MATCH(C42,Лист2!C:C,0)) -> 3428705315
B43: 41 | C43: Чілібін Микола Євгенович | D43: 01.07.2024 | E43: 661 | F43: 5460 | H43: =MATCH(I43,#REF!,0) -> #REF! | I43: =TRIM(C43) -> Чілібін Микола Євгенович | J43: 1
B44: 42 | C44: Чуб Владислав Володимирович | D44: 01.07.2024 | E44: 661 | F44: 840 | H44: =MATCH(I44,#REF!,0) -> #REF! | I44: =TRIM(C44) -> Чуб Владислав Володимирович | K44: =INDEX(Лист2!D:D,MATCH(C44,Лист2!C:C,0)) -> 2858519154
B45: 43 | C45: Щербак Петро Іванович | D45: 01.07.2024 | E45: 661 | F45: 4620 | H45: =MATCH(I45,#REF!,0) -> #REF! | I45: =C45 -> Щербак Петро Іванович | K45: =INDEX(Лист2!D:D,MATCH(C45,Лист2!C:C,0)) -> 2537500655
...

Sheet Табель цех 01 по 15 липня
A1: N | B1: Сотрудник | C1: Удержание за обеды на объекте | D1: виплати на картку за період 1-15.07.25 | E1: ЗП 1-15.07.25 | F1: Сальдо на -30.06.2025 | G1: до виплати | H1: Сальдо на 15.07.2025 | I1: Відпрацьовано годин | J1: ставка | K1: ЦО | L1: IRS | M1: катеринопіль | N1: мк нежин | O1: МД ВООЗ ЕМС | P1: ООН 2025 | Q1: червоний хрест | R1: укрнафта | S1: кернел | T1: глобино | U1: франківськ | V1: перевірка | W1: ЦО | X1: IRS | Y1: катеринопіль | Z1: мк нежин | AA1: МД ВООЗ ЕМС | AB1: ООН 2025 | AC1: червоний хрест | AD1: укрнафта | AE1: кернел | AF1: глобино | AG1: франківськ | AH1: перевірка
A2: 1 | B2: Скрипник Сергій Павлович | D2: 5045.17 | E2: =I2*J2 -> 25740 | F2: =VLOOKUP(B2,'[1]Табель цех 01 по 15 червня'!$B$2:$H$77,7,FALSE) -> -44.08 | G2: =ROUND(E2-D2,-2) -> 20700 | H2: =F2+E2-D2-G2-C2 -> -49.25 | I2: =Цо!AH2+IRS!AH2+Катеринополь!AH2+'Мк нежин'!AH2+'ЕМС Вооз'!AH2+ООН!AN2+'Червоний хрест'!AH2+Укрнафта!AJ2+Кернел!AO2+'Глобино Мк'!AH2+'МД Франківськ'!AH2 -> 143 | J2: 180 | K2: =VLOOKUP(B2,Цо!$B$2:$AH$74,33,FALSE) -> 0 | L2: =VLOOKUP(B2,IRS!$B$2:$AH$73,33,FALSE) -> 22 | M2: =VLOOKUP(B2,Катеринополь!$B$1:$AH$73,33,FALSE) -> 0 | N2: =VLOOKUP(B2,'Мк нежин'!$B$2:$AH$73,33,FALSE) -> 0 | O2: =VLOOKUP(B2,'ЕМС Вооз'!$B$2:$AH$73,33,FALSE) -> 33 | P2: =VLOOKUP(B2,ООН!$H$2:$AN$73,33,FALSE) -> 88 | Q2: =VLOOKUP(B2,'Червоний хрест'!$B$2:$AH$73,33,FALSE) -> 0 | R2: =VLOOKUP(B2,Укрнафта!$D$2:$AJ$73,33,FALSE) -> 0 | S2: =VLOOKUP(B2,Кернел!$I$2:$AO$73,33,FALSE) -> 0 | T2: =VLOOKUP(B2,'Глобино Мк'!$B$2:$AH$73,33,FALSE) -> 0 | U2: =VLOOKUP(B2,'МД Франківськ'!$B$2:$AH$73,33,FALSE) -> 0 | V2: =SUM(K2:U2) -> 143 | W2: =K2/$I2*$G2 -> 0 | X2: =L2/$I2*$G2 -> 3184.6154 | Y2: =M2/$I2*$G2 -> 0 | Z2: =N2/$I2*$G2 -> 0 | AA2: =O2/$I2*$G2 -> 4776.9231 | AB2: =P2/$I2*$G2 -> 12738.462 | AC2: =Q2/$I2*$G2 -> 0 | AD2: =R2/$I2*$G2 -> 0 | ... AG2: =U2/$I2*$G2 -> 0 | AH2: =SUM(W2:AG2) -> 20700
A3: 2 | B3: Багацький Вадим Геннадійович | D3: 3756.26 | E3: =I3*J3 -> 17400 | F3: =VLOOKUP(B3,'[1]Табель цех 01 по 15 червня'!$B$2:$H$77,7,FALSE) -> 20.25 | G3: =ROUND(E3-D3,-2) -> 13600 | H3: =F3+E3-D3-G3-C3 -> 63.99 | I3: =Цо!AH3+IRS!AH3+Катеринополь!AH3+'Мк нежин'!AH3+'ЕМС Вооз'!AH3+ООН!AN3+'Червоний хрест'!AH3+Укрнафта!AJ3+Кернел!AO3+'Глобино Мк'!AH3+'МД Франківськ'!AH3 -> 116 | J3: 150 | K3: =VLOOKUP(B3,Цо!$B$2:$AH$74,33,FALSE) -> 0 | L3: =VLOOKUP(B3,IRS!$B$2:$AH$73,33,FALSE) -> 11 | M3: =VLOOKUP(B3,Катеринополь!$B$1:$AH$73,33,FALSE) -> 11 | N3: =VLOOKUP(B3,'Мк нежин'!$B$2:$AH$73,33,FALSE) -> 77 | O3: =VLOOKUP(B3,'ЕМС Вооз'!$B$2:$AH$73,33,FALSE) -> 0 | P3: =VLOOKUP(B3,ООН!$H$2:$AN$73,33,FALSE) -> 0 | Q3: =VLOOKUP(B3,'Червоний хрест'!$B$2:$AH$73,33,FALSE) -> 0 | R3: =VLOOKUP(B3,Укрнафта!$D$2:$AJ$73,33,FALSE) -> 0 | S3: =VLOOKUP(B3,Кернел!$I$2:$AO$73,33,FALSE) -> 0 | T3: =VLOOKUP(B3,'Глобино Мк'!$B$2:$AH$73,33,FALSE) -> 0 | U3: =VLOOKUP(B3,'МД Франківськ'!$B$2:$AH$73,33,FALSE) -> 17 | V3: =SUM(K3:U3) -> 116 | W3: =K3/$I3*$G3 -> 0 | X3: =L3/$I3*$G3 -> 1289.6552 | Y3: =M3/$I3*$G3 -> 1289.6552 | Z3: =N3/$I3*$G3 -> 9027.5862 | AA3: =O3/$I3*$G3 -> 0 | AB3: =P3/$I3*$G3 -> 0 | AC3: =Q3/$I3*$G3 -> 0 | AD3: =R3/$I3*$G3 -> 0 | ... AG3: =U3/$I3*$G3 -> 1993.1034 | AH3: =SUM(W3:AG3) -> 13600
A4: 3 | B4: Васильєв Віталій Юрійович | D4: 3756.26 | E4: =I4*J4 -> 49800 | F4: =VLOOKUP(B4,'[1]Табель цех 01 по 15 червня'!$B$2:$H$77,7,FALSE) -> 37.26 | G4: =ROUND(E4-D4,-2) -> 46000 | H4: =F4+E4-D4-G4-C4 -> 81 | I4: =Цо!AH4+IRS!AH4+Катеринополь!AH4+'Мк нежин'!AH4+'ЕМС Вооз'!AH4+ООН!AN4+'Червоний хрест'!AH4+Укрнафта!AJ4+Кернел!AO4+'Глобино Мк'!AH4+'МД Франківськ'!AH4 -> 332 | J4: 150 | K4: =VLOOKUP(B4,Цо!$B$2:$AH$74,33,FALSE) -> 0 | L4: =VLOOKUP(B4,IRS!$B$2:$AH$73,33,FALSE) -> 0 | M4: =VLOOKUP(B4,Катеринополь!$B$1:$AH$73,33,FALSE) -> 0 | N4: =VLOOKUP(B4,'Мк нежин'!$B$2:$AH$73,33,FALSE) -> 11 | O4: =VLOOKUP(B4,'ЕМС Вооз'!$B$2:$AH$73,33,FALSE) -> 9 | P4: =VLOOKUP(B4,ООН!$H$2:$AN$73,33,FALSE) -> 120 | Q4: =VLOOKUP(B4,'Червоний хрест'!$B$2:$AH$73,33,FALSE) -> 192 | R4: =VLOOKUP(B4,Укрнафта!$D$2:$AJ$73,33,FALSE) -> 0 | S4: =VLOOKUP(B4,Кернел!$I$2:$AO$73,33,FALSE) -> 0 | T4: =VLOOKUP(B4,'Глобино Мк'!$B$2:$AH$73,33,FALSE) -> 0 | U4: =VLOOKUP(B4,'МД Франківськ'!$B$2:$AH$73,33,FALSE) -> 0 | V4: =SUM(K4:U4) -> 332 | W4: =K4/$I4*$G4 -> 0 | X4: =L4/$I4*$G4 -> 0 | Y4: =M4/$I4*$G4 -> 0 | Z4: =N4/$I4*$G4 -> 1524.0964 | AA4: =O4/$I4*$G4 -> 1246.988 | AB4: =P4/$I4*$G4 -> 16626.506 | AC4: =Q4/$I4*$G4 -> 26602.41 | AD4: =R4/$I4*$G4 -> 0 | ... AG4: =U4/$I4*$G4 -> 0 | AH4: =SUM(W4:AG4) -> 46000
A5: 4 | B5: Григоренко Олександр Миколайович | D5: 3756.26 | E5: =I5*J5 -> 16500 | F5: =VLOOKUP(B5,'[1]Табель цех 01 по 15 червня'!$B$2:$H$77,7,FALSE) -> -29.75 | G5: =ROUND(E5-D5,-2) -> 12700 | H5: =F5+E5-D5-G5-C5 -> 13.99 | I5: =Цо!AH5+IRS!AH5+Катеринополь!AH5+'Мк нежин'!AH5+'ЕМС Вооз'!AH5+ООН!AN5+'Червоний хрест'!AH5+Укрнафта!AJ5+Кернел!AO5+'Глобино Мк'!AH5+'МД Франківськ'!AH5 -> 110 | J5: 150 | K5: =VLOOKUP(B5,Цо!$B$2:$AH$74,33,FALSE) -> 0 | L5: =VLOOKUP(B5,IRS!$B$2:$AH$73,33,FALSE) -> 0 | M5: =VLOOKUP(B5,Катеринополь!$B$1:$AH$73,33,FALSE) -> 0 | N5: =VLOOKUP(B5,'Мк нежин'!$B$2:$AH$73,33,FALSE) -> 11 | O5: =VLOOKUP(B5,'ЕМС Вооз'!$B$2:$AH$73,33,FALSE) -> 11 | P5: =VLOOKUP(B5,ООН!$H$2:$AN$73,33,FALSE) -> 88 | Q5: =VLOOKUP(B5,'Червоний хрест'!$B$2:$AH$73,33,FALSE) -> 0 | R5: =VLOOKUP(B5,Укрнафта!$D$2:$AJ$73,33,FALSE) -> 0 | S5: =VLOOKUP(B5,Кернел!$I$2:$AO$73,33,FALSE) -> 0 | T5: =VLOOKUP(B5,'Глобино Мк'!$B$2:$AH$73,33,FALSE) -> 0 | U5: =VLOOKUP(B5,'МД Франківськ'!$B$2:$AH$73,33,FALSE) -> 0 | V5: =SUM(K5:U5) -> 110 | W5: =K5/$I5*$G5 -> 0 | X5: =L5/$I5*$G5 -> 0 | Y5: =M5/$I5*$G5 -> 0 | Z5: =N5/$I5*$G5 -> 1270 | AA5: =O5/$I5*$G5 -> 1270 | AB5: =P5/$I5*$G5 -> 10160 | AC5: =Q5/$I5*$G5 -> 0 | AD5: =R5/$I5*$G5 -> 0 | ... AG5: =U5/$I5*$G5 -> 0 | AH5: =SUM(W5:AG5) -> 12700
A6: 5 | B6: Григорьєв Микола | D6: 3756.26 | E6: =I6*J6 -> 21150 | F6: =VLOOKUP(B6,'[1]Табель цех 01 по 15 червня'!$B$2:$H$77,7,FALSE) -> -30.05 | G6: =ROUND(E6-D6,-2) -> 17400 | H6: =F6+E6-D6-G6-C6 -> -36.31 | I6: =Цо!AH6+IRS!AH6+Катеринополь!AH6+'Мк нежин'!AH6+'ЕМС Вооз'!AH6+ООН!AN6+'Червоний хрест'!AH6+Укрнафта!AJ6+Кернел!AO6+'Глобино Мк'!AH6+'МД Франківськ'!AH6 -> 141 | J6: 150 | K6: =VLOOKUP(B6,Цо!$B$2:$AH$74,33,FALSE) -> 0 | L6: =VLOOKUP(B6,IRS!$B$2:$AH$73,33,FALSE) -> 22 | M6: =VLOOKUP(B6,Катеринополь!$B$1:$AH$73,33,FALSE) -> 0 | N6: =VLOOKUP(B6,'Мк нежин'!$B$2:$AH$73,33,FALSE) -> 22 | O6: =VLOOKUP(B6,'ЕМС Вооз'!$B$2:$AH$73,33,FALSE) -> 42 | P6: =VLOOKUP(B6,ООН!$H$2:$AN$73,33,FALSE) -> 55 | Q6: =VLOOKUP(B6,'Червоний хрест'!$B$2:$AH$73,33,FALSE) -> 0 | R6: =VLOOKUP(B6,Укрнафта!$D$2:$AJ$73,33,FALSE) -> 0 | S6: =VLOOKUP(B6,Кернел!$I$2:$AO$73,33,FALSE) -> 0 | T6: =VLOOKUP(B6,'Глобино Мк'!$B$2:$AH$73,33,FALSE) -> 0 | U6: =VLOOKUP(B6,'МД Франківськ'!$B$2:$AH$73,33,FALSE) -> 0 | V6: =SUM(K6:U6) -> 141 | W6: =K6/$I6*$G6 -> 0 | X6: =L6/$I6*$G6 -> 2714.8936 | Y6: =M6/$I6*$G6 -> 0 | Z6: =N6/$I6*$G6 -> 2714.8936 | AA6: =O6/$I6*$G6 -> 5182.9787 | AB6: =P6/$I6*$G6 -> 6787.234 | AC6: =Q6/$I6*$G6 -> 0 | AD6: =R6/$I6*$G6 -> 0 | ... AG6: =U6/$I6*$G6 -> 0 | AH6: =SUM(W6:AG6) -> 17400
A7: 6 | B7: Григор'єв Михайло Андрійович | D7: 3756.26 | E7: =I7*J7 -> 17850 | F7: =VLOOKUP(B7,'[1]Табель цех 01 по 15 червня'!$B$2:$H$77,7,FALSE) -> -33.34 | G7: =ROUND(E7-D7,-2) -> 14100 | H7: =F7+E7-D7-G7-C7 -> -39.6 | I7: =Цо!AH7+IRS!AH7+Катеринополь!AH7+'Мк нежин'!AH7+'ЕМС Вооз'!AH7+ООН!AN7+'Червоний хрест'!AH7+Укрнафта!AJ7+Кернел!AO7+'Глобино Мк'!AH7+'МД Франківськ'!AH7 -> 119 | J7: 150 | K7: =VLOOKUP(B7,Цо!$B$2:$AH$74,33,FALSE) -> 0 | L7: =VLOOKUP(B7,IRS!$B$2:$AH$73,33,FALSE) -> 22 | M7: =VLOOKUP(B7,Катеринополь!$B$1:$AH$73,33,FALSE) -> 0 | N7: =VLOOKUP(B7,'Мк нежин'!$B$2:$AH$73,33,FALSE) -> 11 | O7: =VLOOKUP(B7,'ЕМС Вооз'!$B$2:$AH$73,33,FALSE) -> 42 | P7: =VLOOKUP(B7,ООН!$H$2:$AN$73,33,FALSE) -> 44 | Q7: =VLOOKUP(B7,'Червоний хрест'!$B$2:$AH$73,33,FALSE) -> 0 | R7: =VLOOKUP(B7,Укрнафта!$D$2:$AJ$73,33,FALSE) -> 0 | S7: =VLOOKUP(B7,Кернел!$I$2:$AO$73,33,FALSE) -> 0 | T7: =VLOOKUP(B7,'Глобино Мк'!$B$2:$AH$73,33,FALSE) -> 0 | U7: =VLOOKUP(B7,'МД Франківськ'!$B$2:$AH$73,33,FALSE) -> 0 | V7: =SUM(K7:U7) -> 119 | W7: =K7/$I7*$G7 -> 0 | X7: =L7/$I7*$G7 -> 2606.7227 | Y7: =M7/$I7*$G7 -> 0 | Z7: =N7/$I7*$G7 -> 1303.3613 | AA7: =O7/$I7*$G7 -> 4976.4706 | AB7: =P7/$I7*$G7 -> 5213.4454 | AC7: =Q7/$I7*$G7 -> 0 | AD7: =R7/$I7*$G7 -> 0 | ... AG7: =U7/$I7*$G7 -> 0 | AH7: =SUM(W7:AG7) -> 14100
A8: 7 | B8: Іванов Олексій Вікторович | D8: 3756.26 | E8: =I8*J8 -> 30900 | F8: =VLOOKUP(B8,'[1]Табель цех 01 по 15 червня'!$B$2:$H$77,7,FALSE) -> 13.46 | G8: =ROUND(E8-D8,-2) -> 27100 | H8: =F8+E8-D8-G8-C8 -> 57.2 | I8: =Цо!AH8+IRS!AH8+Катеринополь!AH8+'Мк нежин'!AH8+'ЕМС Вооз'!AH8+ООН!AN8+'Червоний хрест'!AH8+Укрнафта!AJ8+Кернел!AO8+'Глобино Мк'!AH8+'МД Франківськ'!AH8 -> 206 | J8: 150 | K8: =VLOOKUP(B8,Цо!$B$2:$AH$74,33,FALSE) -> 0 | L8: =VLOOKUP(B8,IRS!$B$2:$AH$73,33,FALSE) -> 0 | M8: =VLOOKUP(B8,Катеринополь!$B$1:$AH$73,33,FALSE) -> 77 | N8: =VLOOKUP(B8,'Мк нежин'!$B$2:$AH$73,33,FALSE) -> 9 | O8: =VLOOKUP(B8,'ЕМС Вооз'!$B$2:$AH$73,33,FALSE) -> 0 | P8: =VLOOKUP(B8,ООН!$H$2:$AN$73,33,FALSE) -> 120 | Q8: =VLOOKUP(B8,'Червоний хрест'!$B$2:$AH$73,33,FALSE) -> 0 | R8: =VLOOKUP(B8,Укрнафта!$D$2:$AJ$73,33,FALSE) -> 0 | S8: =VLOOKUP(B8,Кернел!$I$2:$AO$73,33,FALSE) -> 0 | T8: =VLOOKUP(B8,'Глобино Мк'!$B$2:$AH$73,33,FALSE) -> 0 | U8: =VLOOKUP(B8,'МД Франківськ'!$B$2:$AH$73,33,FALSE) -> 0 | V8: =SUM(K8:U8) -> 206 | W8: =K8/$I8*$G8 -> 0 | X8: =L8/$I8*$G8 -> 0 | Y8: =M8/$I8*$G8 -> 10129.612 | Z8: =N8/$I8*$G8 -> 1183.9806 | AA8: =O8/$I8*$G8 -> 0 | AB8: =P8/$I8*$G8 -> 15786.408 | AC8: =Q8/$I8*$G8 -> 0 | AD8: =R8/$I8*$G8 -> 0 | ... AG8: =U8/$I8*$G8 -> 0 | AH8: =SUM(W8:AG8) -> 27100
A9: 8 | B9: Іскрицький Денис Русланович | D9: 3756.26 | E9: =I9*J9 -> 33450 | F9: =VLOOKUP(B9,'[1]Табель цех 01 по 15 червня'!$B$2:$H$77,7,FALSE) -> 0.25 | G9: =ROUND(E9-D9,-2) -> 29700 | H9: =F9+E9-D9-G9-C9 -> -6.01 | I9: =Цо!AH9+IRS!AH9+Катеринополь!AH9+'Мк нежин'!AH9+'ЕМС Вооз'!AH9+ООН!AN9+'Червоний хрест'!AH9+Укрнафта!AJ9+Кернел!AO9+'Глобино Мк'!AH9+'МД Франківськ'!AH9 -> 223 | J9: 150 | K9: =VLOOKUP(B9,Цо!$B$2:$AH$74,33,FALSE) -> 0 | L9: =VLOOKUP(B9,IRS!$B$2:$AH$73,33,FALSE) -> 0 | M9: =VLOOKUP(B9,Катеринополь!$B$1:$AH$73,33,FALSE) -> 0 | N9: =VLOOKUP(B9,'Мк нежин'!$B$2:$AH$73,33,FALSE) -> 11 | O9: =VLOOKUP(B9,'ЕМС Вооз'!$B$2:$AH$73,33,FALSE) -> 9 | P9: =VLOOKUP(B9,ООН!$H$2:$AN$73,33,FALSE) -> 0 | Q9: =VLOOKUP(B9,'Червоний хрест'!$B$2:$AH$73,33,FALSE) -> 192 | R9: =VLOOKUP(B9,Укрнафта!$D$2:$AJ$73,33,FALSE) -> 0 | S9: =VLOOKUP(B9,Кернел!$I$2:$AO$73,33,FALSE) -> 0 | T9: =VLOOKUP(B9,'Глобино Мк'!$B$2:$AH$73,33,FALSE) -> 11 | U9: =VLOOKUP(B9,'МД Франківськ'!$B$2:$AH$73,33,FALSE) -> 0 | V9: =SUM(K9:U9) -> 223 | W9: =K9/$I9*$G9 -> 0 | X9: =L9/$I9*$G9 -> 0 | Y9: =M9/$I9*$G9 -> 0 | Z9: =N9/$I9*$G9 -> 1465.0224 | AA9: =O9/$I9*$G9 -> 1198.6547 | AB9: =P9/$I9*$G9 -> 0 | AC9: =Q9/$I9*$G9 -> 25571.3 | AD9: =R9/$I9*$G9 -> 0 | ... AG9: =U9/$I9*$G9 -> 0 | AH9: =SUM(W9:AG9) -> 29700
A10: 9 | B10: Корнієнко Станіслав Володимирович | D10: 3756.26 | E10: =I10*J10 -> 19050 | F10: =VLOOKUP(B10,'[1]Табель цех 01 по 15 червня'!$B$2:$H$77,7,FALSE) -> 13.04 | G10: =ROUND(E10-D10,-2) -> 15300 | H10: =F10+E10-D10-G10-C10 -> 6.78 | I10: =Цо!AH10+IRS!AH10+Катеринополь!AH10+'Мк нежин'!AH10+'ЕМС Вооз'!AH10+ООН!AN10+'Червоний хрест'!AH10+Укрнафта!AJ10+Кернел!AO10+'Глобино Мк'!AH10+'МД Франківськ'!AH10 -> 127 | J10: 150 | K10: =VLOOKUP(B10,Цо!$B$2:$AH$74,33,FALSE) -> 0 | L10: =VLOOKUP(B10,IRS!$B$2:$AH$73,33,FALSE) -> 11 | M10: =VLOOKUP(B10,Катеринополь!$B$1:$AH$73,33,FALSE) -> 22 | N10: =VLOOKUP(B10,'Мк нежин'!$B$2:$AH$73,33,FALSE) -> 44 | O10: =VLOOKUP(B10,'ЕМС Вооз'!$B$2:$AH$73,33,FALSE) -> 0 | P10: =VLOOKUP(B10,ООН!$H$2:$AN$73,33,FALSE) -> 0 | Q10: =VLOOKUP(B10,'Червоний хрест'!$B$2:$AH$73,33,FALSE) -> 0 | R10: =VLOOKUP(B10,Укрнафта!$D$2:$AJ$73,33,FALSE) -> 0 | S10: =VLOOKUP(B10,Кернел!$I$2:$AO$73,33,FALSE) -> 0 | T10: =VLOOKUP(B10,'Глобино Мк'!$B$2:$AH$73,33,FALSE) -> 50 | U10: =VLOOKUP(B10,'МД Франківськ'!$B$2:$AH$73,33,FALSE) -> 0 | V10: =SUM(K10:U10) -> 127 | W10: =K10/$I10*$G10 -> 0 | X10: =L10/$I10*$G10 -> 1325.1969 | Y10: =M10/$I10*$G10 -> 2650.3937 | Z10: =N10/$I10*$G10 -> 5300.7874 | AA10: =O10/$I10*$G10 -> 0 | AB10: =P10/$I10*$G10 -> 0 | AC10: =Q10/$I10*$G10 -> 0 | AD10: =R10/$I10*$G10 -> 0 | ... AG10: =U10/$I10*$G10 -> 0 | AH10: =SUM(W10:AG10) -> 15300
A11: 10 | B11: Масливець Ігор Валерійович | D11: 3756.26 | E11: =I11*J11 -> 19050 | F11: =VLOOKUP(B11,'[1]Табель цех 01 по 15 червня'!$B$2:$H$77,7,FALSE) -> 19.95 | G11: =ROUND(E11-D11,-2) -> 15300 | H11: =F11+E11-D11-G11-C11 -> 13.69 | I11: =Цо!AH11+IRS!AH11+Катеринополь!AH11+'Мк нежин'!AH11+'ЕМС Вооз'!AH11+ООН!AN11+'Червоний хрест'!AH11+Укрнафта!AJ11+Кернел!AO11+'Глобино Мк'!AH11+'МД Франківськ'!AH11 -> 127 | J11: 150 | K11: =VLOOKUP(B11,Цо!$B$2:$AH$74,33,FALSE) -> 11 | L11: =VLOOKUP(B11,IRS!$B$2:$AH$73,33,FALSE) -> 11 | M11: =VLOOKUP(B11,Катеринополь!$B$1:$AH$73,33,FALSE) -> 0 | N11: =VLOOKUP(B11,'Мк нежин'!$B$2:$AH$73,33,FALSE) -> 22 | O11: =VLOOKUP(B11,'ЕМС Вооз'!$B$2:$AH$73,33,FALSE) -> 17 | P11: =VLOOKUP(B11,ООН!$H$2:$AN$73,33,FALSE) -> 44 | Q11: =VLOOKUP(B11,'Червоний хрест'!$B$2:$AH$73,33,FALSE) -> 0 | R11: =VLOOKUP(B11,Укрнафта!$D$2:$AJ$73,33,FALSE) -> 11 | S11: =VLOOKUP(B11,Кернел!$I$2:$AO$73,33,FALSE) -> 0 | T11: =VLOOKUP(B11,'Глобино Мк'!$B$2:$AH$73,33,FALSE) -> 0 | U11: =VLOOKUP(B11,'МД Франківськ'!$B$2:$AH$73,33,FALSE) -> 11 | V11: =SUM(K11:U11) -> 127 | W11: =K11/$I11*$G11 -> 1325.1969 | X11: =L11/$I11*$G11 -> 1325.1969 | Y11: =M11/$I11*$G11 -> 0 | Z11: =N11/$I11*$G11 -> 2650.3937 | AA11: =O11/$I11*$G11 -> 2048.0315 | AB11: =P11/$I11*$G11 -> 5300.7874 | AC11: =Q11/$I11*$G11 -> 0 | AD11: =R11/$I11*$G11 -> 1325.1969 | ... AG11: =U11/$I11*$G11 -> 1325.1969 | AH11: =SUM(W11:AG11) -> 15300
A12: 11 | B12: Пономаренко Віталій Вікторович | D12: 3756.26 | E12: =I12*J12 -> 20880 | F12: =VLOOKUP(B12,'[1]Табель цех 01 по 15 червня'!$B$2:$H$77,7,FALSE) -> -29.75 | G12: =ROUND(E12-D12,-2) -> 17100 | H12: =F12+E12-D12-G12-C12 -> -6.01 | I12: =Цо!AH12+IRS!AH12+Катеринополь!AH12+'Мк нежин'!AH12+'ЕМС Вооз'!AH12+ООН!AN12+'Червоний хрест'!AH12+Укрнафта!AJ12+Кернел!AO12+'Глобино Мк'!AH12+'МД Франківськ'!AH12 -> 116 | J12: 180 | K12: =VLOOKUP(B12,Цо!$B$2:$AH$74,33,FALSE) -> 0 | L12: =VLOOKUP(B12,IRS!$B$2:$AH$73,33,FALSE) -> 61 | M12: =VLOOKUP(B12,Катеринополь!$B$1:$AH$73,33,FALSE) -> 0 | N12: =VLOOKUP(B12,'Мк нежин'!$B$2:$AH$73,33,FALSE) -> 0 | O12: =VLOOKUP(B12,'ЕМС Вооз'!$B$2:$AH$73,33,FALSE) -> 0 | P12: =VLOOKUP(B12,ООН!$H$2:$AN$73,33,FALSE) -> 0 | Q12: =VLOOKUP(B12,'Червоний хрест'!$B$2:$AH$73,33,FALSE) -> 0 | R12: =VLOOKUP(B12,Укрнафта!$D$2:$AJ$73,33,FALSE) -> 0 | S12: =VLOOKUP(B12,Кернел!$I$2:$AO$73,33,FALSE) -> 0 | T12: =VLOOKUP(B12,'Глобино Мк'!$B$2:$AH$73,33,FALSE) -> 11 | U12: =VLOOKUP(B12,'МД Франківськ'!$B$2:$AH$73,33,FALSE) -> 44 | V12: =SUM(K12:U12) -> 116 | W12: =K12/$I12*$G12 -> 0 | X12: =L12/$I12*$G12 -> 8992.2414 | Y12: =M12/$I12*$G12 -> 0 | Z12: =N12/$I12*$G12 -> 0 | AA12: =O12/$I12*$G12 -> 0 | AB12: =P12/$I12*$G12 -> 0 | AC12: =Q12/$I12*$G12 -> 0 | AD12: =R12/$I12*$G12 -> 0 | ... AG12: =U12/$I12*$G12 -> 6486.2069 | AH12: =SUM(W12:AG12) -> 17100
A13: 12 | B13: Скрипник Олександр Павлович | D13: 3756.26 | E13: =I13*J13 -> 18450 | F13: =VLOOKUP(B13,'[1]Табель цех 01 по 15 червня'!$B$2:$H$77,7,FALSE) -> -40 | G13: =ROUND(E13-D13,-2) -> 14700 | H13: =F13+E13-D13-G13-C13 -> -46.26 | I13: =Цо!AH13+IRS!AH13+Катеринополь!AH13+'Мк нежин'!AH13+'ЕМС Вооз'!AH13+ООН!AN13+'Червоний хрест'!AH13+Укрнафта!AJ13+Кернел!AO13+'Глобино Мк'!AH13+'МД Франківськ'!AH13 -> 123 | J13: 150 | K13: =VLOOKUP(B13,Цо!$B$2:$AH$74,33,FALSE) -> 0 | L13: =VLOOKUP(B13,IRS!$B$2:$AH$73,33,FALSE) -> 11 | M13: =VLOOKUP(B13,Катеринополь!$B$1:$AH$73,33,FALSE) -> 0 | N13: =VLOOKUP(B13,'Мк нежин'!$B$2:$AH$73,33,FALSE) -> 11 | O13: =VLOOKUP(B13,'ЕМС Вооз'!$B$2:$AH$73,33,FALSE) -> 18 | P13: =VLOOKUP(B13,ООН!$H$2:$AN$73,33,FALSE) -> 50 | Q13: =VLOOKUP(B13,'Червоний хрест'!$B$2:$AH$73,33,FALSE) -> 0 | R13: =VLOOKUP(B13,Укрнафта!$D$2:$AJ$73,33,FALSE) -> 33 | S13: =VLOOKUP(B13,Кернел!$I$2:$AO$73,33,FALSE) -> 0 | T13: =VLOOKUP(B13,'Глобино Мк'!$B$2:$AH$73,33,FALSE) -> 0 | U13: =VLOOKUP(B13,'МД Франківськ'!$B$2:$AH$73,33,FALSE) -> 0 | V13: =SUM(K13:U13) -> 123 | W13: =K13/$I13*$G13 -> 0 | X13: =L13/$I13*$G13 -> 1314.6341 | Y13: =M13/$I13*$G13 -> 0 | Z13: =N13/$I13*$G13 -> 1314.6341 | AA13: =O13/$I13*$G13 -> 2151.2195 | AB13: =P13/$I13*$G13 -> 5975.6098 | AC13: =Q13/$I13*$G13 -> 0 | AD13: =R13/$I13*$G13 -> 3943.9024 | ... AG13: =U13/$I13*$G13 -> 0 | AH13: =SUM(W13:AG13) -> 14700
... A24: 23 | B24: Серебренніков Володимир Олександрович | D24: 3756.26 | E24: =I24*J24 -> 13500 | F24: =VLOOKUP(B24,'[1]Табель цех 01 по 15 червня'!$B$2:$H$77,7,FALSE) -> 39.62 | G24: =ROUND(E24-D24,-2) -> 9700 | H24: =F24+E24-D24-G24-C24 -> 83.36 | I24: =Цо!AH24+IRS!AH24+Катеринополь!AH24+'Мк нежин'!AH24+'ЕМС Вооз'!AH24+ООН!AN24+'Червоний хрест'!AH24+Укрнафта!AJ24+Кернел!AO24+'Глобино Мк'!AH24+'МД Франківськ'!AH24 -> 90 | J24: 150 | K24: =VLOOKUP(B24,Цо!$B$2:$AH$74,33,FALSE) -> 0 | L24: =VLOOKUP(B24,IRS!$B$2:$AH$73,33,FALSE) -> 13 | M24: =VLOOKUP(B24,Катеринополь!$B$1:$AH$73,33,FALSE) -> 0 | N24: =VLOOKUP(B24,'Мк нежин'!$B$2:$AH$73,33,FALSE) -> 33 | O24: =VLOOKUP(B24,'ЕМС Вооз'!$B$2:$AH$73,33,FALSE) -> 0 | P24: =VLOOKUP(B24,ООН!$H$2:$AN$73,33,FALSE) -> 33 | Q24: =VLOOKUP(B24,'Червоний хрест'!$B$2:$AH$73,33,FALSE) -> 0 | R24: =VLOOKUP(B24,Укрнафта!$D$2:$AJ$73,33,FALSE) -> 11 | S24: =VLOOKUP(B24,Кернел!$I$2:$AO$73,33,FALSE) -> 0 | T24: =VLOOKUP(B24,'Глобино Мк'!$B$2:$AH$73,33,FALSE) -> 0 | U24: =VLOOKUP(B24,'МД Франківськ'!$B$2:$AH$73,33,FALSE) -> 0 | V24: =SUM(K24:U24) -> 90 | W24: =K24/$I24*$G24 -> 0 | X24: =L24/$I24*$G24 -> 1401.1111 | Y24: =M24/$I24*$G24 -> 0 | Z24: =N24/$I24*$G24 -> 3556.6667 | AA24: =O24/$I24*$G24 -> 0 | AB24: =P24/$I24*$G24 -> 3556.6667 | AC24: =Q24/$I24*$G24 -> 0 | AD24: =R24/$I24*$G24 -> 1185.5556 | ... AG24: =U24/$I24*$G24 -> 0 | AH24: =SUM(W24:AG24) -> 9700
A25: 24 | B25: Чешко Сергій Анатолійович | E25: =I25*J25 -> 7200 | F25: =VLOOKUP(B25,'[1]Табель цех 01 по 15 червня'!$B$2:$H$77,7,FALSE) -> -32 | G25: =ROUND(E25-D25,-2) -> 7200 | H25: =F25+E25-D25-G25-C25 -> -32 | I25: =Цо!AH25+IRS!AH25+Катеринополь!AH25+'Мк нежин'!AH25+'ЕМС Вооз'!AH25+ООН!AN25+'Червоний хрест'!AH25+Укрнафта!AJ25+Кернел!AO25+'Глобино Мк'!AH25+'МД Франківськ'!AH25 -> 48 | J25: 150 | K25: =VLOOKUP(B25,Цо!$B$2:$AH$74,33,FALSE) -> 0 | L25: =VLOOKUP(B25,IRS!$B$2:$AH$73,33,FALSE) -> 0 | M25: =VLOOKUP(B25,Катеринополь!$B$1:$AH$73,33,FALSE) -> 0 | N25: =VLOOKUP(B25,'Мк нежин'!$B$2:$AH$73,33,FALSE) -> 0 | O25: =VLOOKUP(B25,'ЕМС Вооз'!$B$2:$AH$73,33,FALSE) -> 48 | P25: =VLOOKUP(B25,ООН!$H$2:$AN$73,33,FALSE) -> 0 | Q25: =VLOOKUP(B25,'Червоний хрест'!$B$2:$AH$73,33,FALSE) -> 0 | R25: =VLOOKUP(B25,Укрнафта!$D$2:$AJ$73,33,FALSE) -> 0 | S25: =VLOOKUP(B25,Кернел!$I$2:$AO$73,33,FALSE) -> 0 | T25: =VLOOKUP(B25,'Глобино Мк'!$B$2:$AH$73,33,FALSE) -> 0 | U25: =VLOOKUP(B25,'МД Франківськ'!$B$2:$AH$73,33,FALSE) -> 0 | V25: =SUM(K25:U25) -> 48 | W25: =K25/$I25*$G25 -> 0 | X25: =L25/$I25*$G25 -> 0 | Y25: =M25/$I25*$G25 -> 0 | Z25: =N25/$I25*$G25 -> 0 | AA25: =O25/$I25*$G25 -> 7200 | AB25: =P25/$I25*$G25 -> 0 | AC25: =Q25/$I25*$G25 -> 0 | AD25: =R25/$I25*$G25 -> 0 | ... AG25: =U25/$I25*$G25 -> 0 | AH25: =SUM(W25:AG25) -> 7200
A26: 25 | B26: Нерезенко Євгеній Віктоорович | E26: =I26*J26 -> 0 | F26: =VLOOKUP(B26,'[1]Табель цех 01 по 15 червня'!$B$2:$H$77,7,FALSE) -> 0 | G26: =ROUND(E26-D26,-2) -> 0 | H26: =F26+E26-D26-G26-C26 -> 0 | I26: =Цо!AH26+IRS!AH26+Катеринополь!AH26+'Мк нежин'!AH26+'ЕМС Вооз'!AH26+ООН!AN26+'Червоний хрест'!AH26+Укрнафта!AJ26+Кернел!AO26+'Глобино Мк'!AH26+'МД Франківськ'!AH26 -> 0 | J26: 150 | K26: =VLOOKUP(B26,Цо!$B$2:$AH$74,33,FALSE) -> 0 | L26: =VLOOKUP(B26,IRS!$B$2:$AH$73,33,FALSE) -> 0 | M26: =VLOOKUP(B26,Катеринополь!$B$1:$AH$73,33,FALSE) -> 0 | N26: =VLOOKUP(B26,'Мк нежин'!$B$2:$AH$73,33,FALSE) -> 0 | O26: =VLOOKUP(B26,'ЕМС Вооз'!$B$2:$AH$73,33,FALSE) -> 0 | P26: =VLOOKUP(B26,ООН!$H$2:$AN$73,33,FALSE) -> 0 | Q26: =VLOOKUP(B26,'Червоний хрест'!$B$2:$AH$73,33,FALSE) -> 0 | R26: =VLOOKUP(B26,Укрнафта!$D$2:$AJ$73,33,FALSE) -> 0 | S26: =VLOOKUP(B26,Кернел!$I$2:$AO$73,33,FALSE) -> 0 | T26: =VLOOKUP(B26,'Глобино Мк'!$B$2:$AH$73,33,FALSE) -> 0 | U26: =VLOOKUP(B26,'МД Франківськ'!$B$2:$AH$73,33,FALSE) -> 0 | V26: =SUM(K26:U26) -> 0 | AH26: =SUM(W26:AG26) -> 0
A27: 26 | B27: Шавкун Максим Анатолійович | E27: =I27*J27 -> 7200 | F27: 0 | G27: =ROUND(E27-D27,-2) -> 7200 | H27: =F27+E27-D27-G27-C27 -> 0 | I27: =Цо!AH27+IRS!AH27+Катеринополь!AH27+'Мк нежин'!AH27+'ЕМС Вооз'!AH27+ООН!AN27+'Червоний хрест'!AH27+Укрнафта!AJ27+Кернел!AO27+'Глобино Мк'!AH27+'МД Франківськ'!AH27 -> 48 | J27: 150 | K27: =VLOOKUP(B27,Цо!$B$2:$AH$74,33,FALSE) -> 0 | L27: =VLOOKUP(B27,IRS!$B$2:$AH$73,33,FALSE) -> 0 | M27: =VLOOKUP(B27,Катеринополь!$B$1:$AH$73,33,FALSE) -> 0 | N27: =VLOOKUP(B27,'Мк нежин'!$B$2:$AH$73,33,FALSE) -> 0 | O27: =VLOOKUP(B27,'ЕМС Вооз'!$B$2:$AH$73,33,FALSE) -> 48 | P27: =VLOOKUP(B27,ООН!$H$2:$AN$73,33,FALSE) -> 0 | Q27: =VLOOKUP(B27,'Червоний хрест'!$B$2:$AH$73,33,FALSE) -> 0 | R27: =VLOOKUP(B27,Укрнафта!$D$2:$AJ$73,33,FALSE) -> 0 | S27: =VLOOKUP(B27,Кернел!$I$2:$AO$73,33,FALSE) -> 0 | T27: =VLOOKUP(B27,'Глобино Мк'!$B$2:$AH$73,33,FALSE) -> 0 | U27: =VLOOKUP(B27,'МД Франківськ'!$B$2:$AH$73,33,FALSE) -> 0 | V27: =SUM(K27:U27) -> 48 | W27: =K27/$I27*$G27 -> 0 | X27: =L27/$I27*$G27 -> 0 | Y27: =M27/$I27*$G27 -> 0 | Z27: =N27/$I27*$G27 -> 0 | AA27: =O27/$I27*$G27 -> 7200 | AB27: =P27/$I27*$G27 -> 0 | AC27: =Q27/$I27*$G27 -> 0 | AD27: =R27/$I27*$G27 -> 0 | ... AG27: =U27/$I27*$G27 -> 0 | AH27: =SUM(W27:AG27) -> 7200
A28: 27 | B28: Чуйко Олег Олегович | D28: 3756.26 | E28: =I28*J28 -> 20250 | F28: =VLOOKUP(B28,'[1]Табель цех 01 по 15 червня'!$B$2:$H$77,7,FALSE) -> -30 | G28: =ROUND(E28-D28,-2) -> 16500 | H28: =F28+E28-D28-G28-C28 -> -36.26 | I28: =Цо!AH28+IRS!AH28+Катеринополь!AH28+'Мк нежин'!AH28+'ЕМС Вооз'!AH28+ООН!AN28+'Червоний хрест'!AH28+Укрнафта!AJ28+Кернел!AO28+'Глобино Мк'!AH28+'МД Франківськ'!AH28 -> 135 | J28: 150 | K28: =VLOOKUP(B28,Цо!$B$2:$AH$74,33,FALSE) -> 0 | L28: =VLOOKUP(B28,IRS!$B$2:$AH$73,33,FALSE) -> 11 | M28: =VLOOKUP(B28,Катеринополь!$B$1:$AH$73,33,FALSE) -> 0 | N28: =VLOOKUP(B28,'Мк нежин'!$B$2:$AH$73,33,FALSE) -> 11 | O28: =VLOOKUP(B28,'ЕМС Вооз'!$B$2:$AH$73,33,FALSE) -> 30 | P28: =VLOOKUP(B28,ООН!$H$2:$AN$73,33,FALSE) -> 83 | Q28: =VLOOKUP(B28,'Червоний хрест'!$B$2:$AH$73,33,FALSE) -> 0 | R28: =VLOOKUP(B28,Укрнафта!$D$2:$AJ$73,33,FALSE) -> 0 | S28: =VLOOKUP(B28,Кернел!$I$2:$AO$73,33,FALSE) -> 0 | T28: =VLOOKUP(B28,'Глобино Мк'!$B$2:$AH$73,33,FALSE) -> 0 | U28: =VLOOKUP(B28,'МД Франківськ'!$B$2:$AH$73,33,FALSE) -> 0 | V28: =SUM(K28:U28) -> 135 | W28: =K28/$I28*$G28 -> 0 | X28: =L28/$I28*$G28 -> 1344.4444 | Y28: =M28/$I28*$G28 -> 0 | Z28: =N28/$I28*$G28 -> 1344.4444 | AA28: =O28/$I28*$G28 -> 3666.6667 | AB28: =P28/$I28*$G28 -> 10144.444 | AC28: =Q28/$I28*$G28 -> 0 | AD28: =R28/$I28*$G28 -> 0 | ... AG28: =U28/$I28*$G28 -> 0 | AH28: =SUM(W28:AG28) -> 16500
A29: 28 | B29: Салюк Дмитро Андрійович | E29: =I29*J29 -> 13950 | F29: =VLOOKUP(B29,'[1]Табель цех 01 по 15 червня'!$B$2:$H$77,7,FALSE) -> -30 | G29: =ROUND(E29-D29,-2) -> 14000 | H29: =F29+E29-D29-G29-C29 -> -80 | I29: =Цо!AH29+IRS!AH29+Катеринополь!AH29+'Мк нежин'!AH29+'ЕМС Вооз'!AH29+ООН!AN29+'Червоний хрест'!AH29+Укрнафта!AJ29+Кернел!AO29+'Глобино Мк'!AH29+'МД Франківськ'!AH29 -> 93 | J29: 150 | K29: =VLOOKUP(B29,Цо!$B$2:$AH$74,33,FALSE) -> 0 | L29: =VLOOKUP(B29,IRS!$B$2:$AH$73,33,FALSE) -> 11 | M29: =VLOOKUP(B29,Катеринополь!$B$1:$AH$73,33,FALSE) -> 0 | N29: =VLOOKUP(B29,'Мк нежин'!$B$2:$AH$73,33,FALSE) -> 6 | O29: =VLOOKUP(B29,'ЕМС Вооз'!$B$2:$AH$73,33,FALSE) -> 0 | P29: =VLOOKUP(B29,ООН!$H$2:$AN$73,33,FALSE) -> 43 | Q29: =VLOOKUP(B29,'Червоний хрест'!$B$2:$AH$73,33,FALSE) -> 0 | R29: =VLOOKUP(B29,Укрнафта!$D$2:$AJ$73,33,FALSE) -> 33 | S29: =VLOOKUP(B29,Кернел!$I$2:$AO$73,33,FALSE) -> 0 | T29: =VLOOKUP(B29,'Глобино Мк'!$B$2:$AH$73,33,FALSE) -> 0 | U29: =VLOOKUP(B29,'МД Франківськ'!$B$2:$AH$73,33,FALSE) -> 0 | V29: =SUM(K29:U29) -> 93 | W29: =K29/$I29*$G29 -> 0 | X29: =L29/$I29*$G29 -> 1655.914 | Y29: =M29/$I29*$G29 -> 0 | Z29: =N29/$I29*$G29 -> 903.22581 | AA29: =O29/$I29*$G29 -> 0 | AB29: =P29/$I29*$G29 -> 6473.1183 | AC29: =Q29/$I29*$G29 -> 0 | AD29: =R29/$I29*$G29 -> 4967.7419 | ... AG29: =U29/$I29*$G29 -> 0 | AH29: =SUM(W29:AG29) -> 14000
A30: 29 | B30: Маковецький Юрій Миколайович | D30: 1878.13 | E30: =I30*J30 -> 16500 | F30: =VLOOKUP(B30,'[1]Табель цех 01 по 15 червня'!$B$2:$H$77,7,FALSE) -> -8.34 | G30: =ROUND(E30-D30,-2) -> 14600 | H30: =F30+E30-D30-G30-C30 -> 13.53 | I30: =Цо!AH30+IRS!AH30+Катеринополь!AH30+'Мк нежин'!AH30+'ЕМС Вооз'!AH30+ООН!AN30+'Червоний хрест'!AH30+Укрнафта!AJ30+Кернел!AO30+'Глобино Мк'!AH30+'МД Франківськ'!AH30 -> 110 | J30: 150 | K30: =VLOOKUP(B30,Цо!$B$2:$AH$74,33,FALSE) -> 0 | L30: =VLOOKUP(B30,IRS!$B$2:$AH$73,33,FALSE) -> 11 | M30: =VLOOKUP(B30,Катеринополь!$B$1:$AH$73,33,FALSE) -> 55 | N30: =VLOOKUP(B30,'Мк нежин'!$B$2:$AH$73,33,FALSE) -> 11 | O30: =VLOOKUP(B30,'ЕМС Вооз'!$B$2:$AH$73,33,FALSE) -> 0 | P30: =VLOOKUP(B30,ООН!$H$2:$AN$73,33,FALSE) -> 11 | Q30: =VLOOKUP(B30,'Червоний хрест'!$B$2:$AH$73,33,FALSE) -> 0 | R30: =VLOOKUP(B30,Укрнафта!$D$2:$AJ$73,33,FALSE) -> 0 | S30: =VLOOKUP(B30,Кернел!$I$2:$AO$73,33,FALSE) -> 0 | T30: =VLOOKUP(B30,'Глобино Мк'!$B$2:$AH$73,33,FALSE) -> 22 | U30: =VLOOKUP(B30,'МД Франківськ'!$B$2:$AH$73,33,FALSE) -> 0 | V30: =SUM(K30:U30) -> 110 | W30: =K30/$I30*$G30 -> 0 | X30: =L30/$I30*$G30 -> 1460 | Y30: =M30/$I30*$G30 -> 7300 | Z30: =N30/$I30*$G30 -> 1460 | AA30: =O30/$I30*$G30 -> 0 | AB30: =P30/$I30*$G30 -> 1460 | AC30: =Q30/$I30*$G30 -> 0 | AD30: =R30/$I30*$G30 -> 0 | ... AG30: =U30/$I30*$G30 -> 0 | AH30: =SUM(W30:AG30) -> 14600
A31: 30 | B31: Міненко Олександр Андрійович | E31: =I31*J31 -> 7200 | F31: =VLOOKUP(B31,'[1]Табель цех 01 по 15 червня'!$B$2:$H$77,7,FALSE) -> 0 | G31: =ROUND(E31-D31,-2) -> 7200 | H31: =F31+E31-D31-G31-C31 -> 0 | I31: =Цо!AH31+IRS!AH31+Катеринополь!AH31+'Мк нежин'!AH31+'ЕМС Вооз'!AH31+ООН!AN31+'Червоний хрест'!AH31+Укрнафта!AJ31+Кернел!AO31+'Глобино Мк'!AH31+'МД Франківськ'!AH31 -> 48 | J31: 150 | K31: =VLOOKUP(B31,Цо!$B$2:$AH$74,33,FALSE) -> 0 | L31: =VLOOKUP(B31,IRS!$B$2:$AH$73,33,FALSE) -> 0 | M31: =VLOOKUP(B31,Катеринополь!$B$1:$AH$73,33,FALSE) -> 0 | N31: =VLOOKUP(B31,'Мк нежин'!$B$2:$AH$73,33,FALSE) -> 0 | O31: =VLOOKUP(B31,'ЕМС Вооз'!$B$2:$AH$73,33,FALSE) -> 48 | P31: =VLOOKUP(B31,ООН!$H$2:$AN$73,33,FALSE) -> 0 | Q31: =VLOOKUP(B31,'Червоний хрест'!$B$2:$AH$73,33,FALSE) -> 0 | R31: =VLOOKUP(B31,Укрнафта!$D$2:$AJ$73,33,FALSE) -> 0 | S31: =VLOOKUP(B31,Кернел!$I$2:$AO$73,33,FALSE) -> 0 | T31: =VLOOKUP(B31,'Глобино Мк'!$B$2:$AH$73,33,FALSE) -> 0 | U31: =VLOOKUP(B31,'МД Франківськ'!$B$2:$AH$73,33,FALSE) -> 0 | V31: =SUM(K31:U31) -> 48 | W31: =K31/$I31*$G31 -> 0 | X31: =L31/$I31*$G31 -> 0 | Y31: =M31/$I31*$G31 -> 0 | Z31: =N31/$I31*$G31 -> 0 | AA31: =O31/$I31*$G31 -> 7200 | AB31: =P31/$I31*$G31 -> 0 | AC31: =Q31/$I31*$G31 -> 0 | AD31: =R31/$I31*$G31 -> 0 | ... AG31: =U31/$I31*$G31 -> 0 | AH31: =SUM(W31:AG31) -> 7200
A32: 31 | B32: Салій Дмитро Миколайович | E32: =I32*J32 -> 0 | F32: =VLOOKUP(B32,'[1]Табель цех 01 по 15 червня'!$B$2:$H$77,7,FALSE) -> 0 | G32: =ROUND(E32-D32,-2) -> 0 | H32: =F32+E32-D32-G32-C32 -> 0 | I32: =Цо!AH32+IRS!AH32+Катеринополь!AH32+'Мк нежин'!AH32+'ЕМС Вооз'!AH32+ООН!AN32+'Червоний хрест'!AH32+Укрнафта!AJ32+Кернел!AO32+'Глобино Мк'!AH32+'МД Франківськ'!AH32 -> 0 | J32: 150 | K32: =VLOOKUP(B32,Цо!$B$2:$AH$74,33,FALSE) -> 0 | L32: =VLOOKUP(B32,IRS!$B$2:$AH$73,33,FALSE) -> 0 | M32: =VLOOKUP(B32,Катеринополь!$B$1:$AH$73,33,FALSE) -> 0 | N32: =VLOOKUP(B32,'Мк нежин'!$B$2:$AH$73,33,FALSE) -> 0 | O32: =VLOOKUP(B32,'ЕМС Вооз'!$B$2:$AH$73,33,FALSE) -> 0 | P32: =VLOOKUP(B32,ООН!$H$2:$AN$73,33,FALSE) -> 0 | Q32: =VLOOKUP(B32,'Червоний хрест'!$B$2:$AH$73,33,FALSE) -> 0 | R32: =VLOOKUP(B32,Укрнафта!$D$2:$AJ$73,33,FALSE) -> 0 | S32: =VLOOKUP(B32,Кернел!$I$2:$AO$73,33,FALSE) -> 0 | T32: =VLOOKUP(B32,'Глобино Мк'!$B$2:$AH$73,33,FALSE) -> 0 | U32: =VLOOKUP(B32,'МД Франківськ'!$B$2:$AH$73,33,FALSE) -> 0 | V32: =SUM(K32:U32) -> 0 | AH32: =SUM(W32:AG32) -> 0
A33: 32 | B33: Різніченко Олег Олександрович | E33: =I33*J33 -> 12000 | F33: =VLOOKUP(B33,'[1]Табель цех 01 по 15 червня'!$B$2:$H$77,7,FALSE) -> -30 | G33: =ROUND(E33-D33,-2) -> 12000 | H33: =F33+E33-D33-G33-C33 -> -30 | I33: =Цо!AH33+IRS!AH33+Катеринополь!AH33+'Мк нежин'!AH33+'ЕМС Вооз'!AH33+ООН!AN33+'Червоний хрест'!AH33+Укрнафта!AJ33+Кернел!AO33+'Глобино Мк'!AH33+'МД Франківськ'!AH33 -> 80 | J33: 150 | K33: =VLOOKUP(B33,Цо!$B$2:$AH$74,33,FALSE) -> 0 | L33: =VLOOKUP(B33,IRS!$B$2:$AH$73,33,FALSE) -> 9 | M33: =VLOOKUP(B33,Катеринополь!$B$1:$AH$73,33,FALSE) -> 9 | N33: =VLOOKUP(B33,'Мк нежин'!$B$2:$AH$73,33,FALSE) -> 62 | O33: =VLOOKUP(B33,'ЕМС Вооз'!$B$2:$AH$73,33,FALSE) -> 0 | P33: =VLOOKUP(B33,ООН!$H$2:$AN$73,33,FALSE) -> 0 | Q33: =VLOOKUP(B33,'Червоний хрест'!$B$2:$AH$73,33,FALSE) -> 0 | R33: =VLOOKUP(B33,Укрнафта!$D$2:$AJ$73,33,FALSE) -> 0 | S33: =VLOOKUP(B33,Кернел!$I$2:$AO$73,33,FALSE) -> 0 | T33: =VLOOKUP(B33,'Глобино Мк'!$B$2:$AH$73,33,FALSE) -> 0 | U33: =VLOOKUP(B33,'МД Франківськ'!$B$2:$AH$73,33,FALSE) -> 0 | V33: =SUM(K33:U33) -> 80 | W33: =K33/$I33*$G33 -> 0 | X33: =L33/$I33*$G33 -> 1350 | Y33: =M33/$I33*$G33 -> 1350 | Z33: =N33/$I33*$G33 -> 9300 | AA33: =O33/$I33*$G33 -> 0 | AB33: =P33/$I33*$G33 -> 0 | AC33: =Q33/$I33*$G33 -> 0 | AD33: =R33/$I33*$G33 -> 0 | ... AG33: =U33/$I33*$G33 -> 0 | AH33: =SUM(W33:AG33) -> 12000
A34: 33 | B34: Рогозовець Андрій Вікторович | D34: 3756.26 | E34: =I34*J34 -> 21600 | F34: =VLOOKUP(B34,'[1]Табель цех 01 по 15 червня'!$B$2:$H$77,7,FALSE) -> -30 | G34: =ROUND(E34-D34,-2) -> 17800 | H34: =F34+E34-D34-G34-C34 -> 13.74 | I34: =Цо!AH34+IRS!AH34+Катеринополь!AH34+'Мк нежин'!AH34+'ЕМС Вооз'!AH34+ООН!AN34+'Червоний хрест'!AH34+Укрнафта!AJ34+Кернел!AO34+'Глобино Мк'!AH34+'МД Франківськ'!AH34 -> 144 | J34: 150 | K34: =VLOOKUP(B34,Цо!$B$2:$AH$74,33,FALSE) -> 0 | L34: =VLOOKUP(B34,IRS!$B$2:$AH$73,33,FALSE) -> 53 | M34: =VLOOKUP(B34,Катеринополь!$B$1:$AH$73,33,FALSE) -> 0 | N34: =VLOOKUP(B34,'Мк нежин'!$B$2:$AH$73,33,FALSE) -> 11 | O34: =VLOOKUP(B34,'ЕМС Вооз'!$B$2:$AH$73,33,FALSE) -> 7 | P34: =VLOOKUP(B34,ООН!$H$2:$AN$73,33,FALSE) -> 0 | Q34: =VLOOKUP(B34,'Червоний хрест'!$B$2:$AH$73,33,FALSE) -> 0 | R34: =VLOOKUP(B34,Укрнафта!$D$2:$AJ$73,33,FALSE) -> 0 | S34: =VLOOKUP(B34,Кернел!$I$2:$AO$73,33,FALSE) -> 0 | T34: =VLOOKUP(B34,'Глобино Мк'!$B$2:$AH$73,33,FALSE) -> 0 | U34: =VLOOKUP(B34,'МД Франківськ'!$B$2:$AH$73,33,FALSE) -> 73 | V34: =SUM(K34:U34) -> 144 | W34: =K34/$I34*$G34 -> 0 | X34: =L34/$I34*$G34 -> 6551.3889 | Y34: =M34/$I34*$G34 -> 0 | Z34: =N34/$I34*$G34 -> 1359.7222 | AA34: =O34/$I34*$G34 -> 865.27778 | AB34: =P34/$I34*$G34 -> 0 | AC34: =Q34/$I34*$G34 -> 0 | AD34: =R34/$I34*$G34 -> 0 | ... AG34: =U34/$I34*$G34 -> 9023.6111 | AH34: =SUM(W34:AG34) -> 17800
A35: 34 | B35: Старков Кирило Юрійович | E35: =I35*J35 -> 0 | F35: =VLOOKUP(B35,'[1]Табель цех 01 по 15 червня'!$B$2:$H$77,7,FALSE) -> 0 | G35: =ROUND(E35-D35,-2) -> 0 | H35: =F35+E35-D35-G35-C35 -> 0 | I35: =Цо!AH35+IRS!AH35+Катеринополь!AH35+'Мк нежин'!AH35+'ЕМС Вооз'!AH35+ООН!AN35+'Червоний хрест'!AH35+Укрнафта!AJ35+Кернел!AO35+'Глобино Мк'!AH35+'МД Франківськ'!AH35 -> 0 | J35: 150 | K35: =VLOOKUP(B35,Цо!$B$2:$AH$74,33,FALSE) -> 0 | L35: =VLOOKUP(B35,IRS!$B$2:$AH$73,33,FALSE) -> 0 | M35: =VLOOKUP(B35,Катеринополь!$B$1:$AH$73,33,FALSE) -> 0 | N35: =VLOOKUP(B35,'Мк нежин'!$B$2:$AH$73,33,FALSE) -> 0 | O35: =VLOOKUP(B35,'ЕМС Вооз'!$B$2:$AH$73,33,FALSE) -> 0 | P35: =VLOOKUP(B35,ООН!$H$2:$AN$73,33,FALSE) -> 0 | Q35: =VLOOKUP(B35,'Червоний хрест'!$B$2:$AH$73,33,FALSE) -> 0 | R35: =VLOOKUP(B35,Укрнафта!$D$2:$AJ$73,33,FALSE) -> 0 | S35: =VLOOKUP(B35,Кернел!$I$2:$AO$73,33,FALSE) -> 0 | T35: =VLOOKUP(B35,'Глобино Мк'!$B$2:$AH$73,33,FALSE) -> 0 | U35: =VLOOKUP(B35,'МД Франківськ'!$B$2:$AH$73,33,FALSE) -> 0 | V35: =SUM(K35:U35) -> 0 | AH35: =SUM(W35:AG35) -> 0
A36: 35 | B36: Зубахін Сергій Александрович | E36: =I36*J36 -> 3600 | F36: =VLOOKUP(B36,'[1]Табель цех 01 по 15 червня'!$B$2:$H$77,7,FALSE) -> 0 | G36: =ROUND(E36-D36,-2) -> 3600 | H36: =F36+E36-D36-G36-C36 -> 0 | I36: =Цо!AH36+IRS!AH36+Катеринополь!AH36+'Мк нежин'!AH36+'ЕМС Вооз'!AH36+ООН!AN36+'Червоний хрест'!AH36+Укрнафта!AJ36+Кернел!AO36+'Глобино Мк'!AH36+'МД Франківськ'!AH36 -> 24 | J36: 150 | K36: =VLOOKUP(B36,Цо!$B$2:$AH$74,33,FALSE) -> 0 | L36: =VLOOKUP(B36,IRS!$B$2:$AH$73,33,FALSE) -> 0 | M36: =VLOOKUP(B36,Катеринополь!$B$1:$AH$73,33,FALSE) -> 0 | N36: =VLOOKUP(B36,'Мк нежин'!$B$2:$AH$73,33,FALSE) -> 0 | O36: =VLOOKUP(B36,'ЕМС Вооз'!$B$2:$AH$73,33,FALSE) -> 24 | P36: =VLOOKUP(B36,ООН!$H$2:$AN$73,33,FALSE) -> 0 | Q36: =VLOOKUP(B36,'Червоний хрест'!$B$2:$AH$73,33,FALSE) -> 0 | R36: =VLOOKUP(B36,Укрнафта!$D$2:$AJ$73,33,FALSE) -> 0 | S36: =VLOOKUP(B36,Кернел!$I$2:$AO$73,33,FALSE) -> 0 | T36: =VLOOKUP(B36,'Глобино Мк'!$B$2:$AH$73,33,FALSE) -> 0 | U36: =VLOOKUP(B36,'МД Франківськ'!$B$2:$AH$73,33,FALSE) -> 0 | V36: =SUM(K36:U36) -> 24 | W36: =K36/$I36*$G36 -> 0 | X36: =L36/$I36*$G36 -> 0 | Y36: =M36/$I36*$G36 -> 0 | Z36: =N36/$I36*$G36 -> 0 | AA36: =O36/$I36*$G36 -> 3600 | AB36: =P36/$I36*$G36 -> 0 | AC36: =Q36/$I36*$G36 -> 0 | AD36: =R36/$I36*$G36 -> 0 | ... AG36: =U36/$I36*$G36 -> 0 | AH36: =SUM(W36:AG36) -> 3600
A37: 36 | B37: Корнієнко Віталій Олегович | D37: 3756.26 | E37: =I37*J37 -> 54000 | F37: =VLOOKUP(B37,'[1]Табель цех 01 по 15 червня'!$B$2:$H$77,7,FALSE) -> -50 | G37: =ROUND(E37-D37,-2) -> 50200 | H37: =F37+E37-D37-G37-C37 -> -6.26 | I37: =Цо!AH37+IRS!AH37+Катеринополь!AH37+'Мк нежин'!AH37+'ЕМС Вооз'!AH37+ООН!AN37+'Червоний хрест'!AH37+Укрнафта!AJ37+Кернел!AO37+'Глобино Мк'!AH37+'МД Франківськ'!AH37 -> 360 | J37: 150 | K37: =VLOOKUP(B37,Цо!$B$2:$AH$74,33,FALSE) -> 0 | L37: =VLOOKUP(B37,IRS!$B$2:$AH$73,33,FALSE) -> 0 | M37: =VLOOKUP(B37,Катеринополь!$B$1:$AH$73,33,FALSE) -> 0 | N37: =VLOOKUP(B37,'Мк нежин'!$B$2:$AH$73,33,FALSE) -> 0 | O37: =VLOOKUP(B37,'ЕМС Вооз'!$B$2:$AH$73,33,FALSE) -> 360 | P37: =VLOOKUP(B37,ООН!$H$2:$AN$73,33,FALSE) -> 0 | Q37: =VLOOKUP(B37,'Червоний хрест'!$B$2:$AH$73,33,FALSE) -> 0 | R37: =VLOOKUP(B37,Укрнафта!$D$2:$AJ$73,33,FALSE) -> 0 | S37: =VLOOKUP(B37,Кернел!$I$2:$AO$73,33,FALSE) -> 0 | T37: =VLOOKUP(B37,'Глобино Мк'!$B$2:$AH$73,33,FALSE) -> 0 | U37: =VLOOKUP(B37,'МД Франківськ'!$B$2:$AH$73,33,FALSE) -> 0 | V37: =SUM(K37:U37) -> 360 | W37: =K37/$I37*$G37 -> 0 | X37: =L37/$I37*$G37 -> 0 | Y37: =M37/$I37*$G37 -> 0 | Z37: =N37/$I37*$G37 -> 0 | AA37: =O37/$I37*$G37 -> 50200 | AB37: =P37/$I37*$G37 -> 0 | AC37: =Q37/$I37*$G37 -> 0 | AD37: =R37/$I37*$G37 -> 0 | ... AG37: =U37/$I37*$G37 -> 0 | AH37: =SUM(W37:AG37) -> 50200
A38: 37 | B38: Рубленко Євген Миколайович | E38: =I38*J38 -> 17700 | F38: =VLOOKUP(B38,'[1]Табель цех 01 по 15 червня'!$B$2:$H$77,7,FALSE) -> -50 | G38: =ROUND(E38-D38,-2) -> 17700 | H38: =F38+E38-D38-G38-C38 -> -50 | I38: =Цо!AH38+IRS!AH38+Катеринополь!AH38+'Мк нежин'!AH38+'ЕМС Вооз'!AH38+ООН!AN38+'Червоний хрест'!AH38+Укрнафта!AJ38+Кернел!AO38+'Глобино Мк'!AH38+'МД Франківськ'!AH38 -> 118 | J38: 150 | K38: =VLOOKUP(B38,Цо!$B$2:$AH$74,33,FALSE) -> 0 | L38: =VLOOKUP(B38,IRS!$B$2:$AH$73,33,FALSE) -> 33 | M38: =VLOOKUP(B38,Катеринополь!$B$1:$AH$73,33,FALSE) -> 0 | N38: =VLOOKUP(B38,'Мк нежин'!$B$2:$AH$73,33,FALSE) -> 11 | O38: =VLOOKUP(B38,'ЕМС Вооз'!$B$2:$AH$73,33,FALSE) -> 11 | P38: =VLOOKUP(B38,ООН!$H$2:$AN$73,33,FALSE) -> 19 | Q38: =VLOOKUP(B38,'Червоний хрест'!$B$2:$AH$73,33,FALSE) -> 0 | R38: =VLOOKUP(B38,Укрнафта!$D$2:$AJ$73,33,FALSE) -> 44 | S38: =VLOOKUP(B38,Кернел!$I$2:$AO$73,33,FALSE) -> 0 | T38: =VLOOKUP(B38,'Глобино Мк'!$B$2:$AH$73,33,FALSE) -> 0 | U38: =VLOOKUP(B38,'МД Франківськ'!$B$2:$AH$73,33,FALSE) -> 0 | V38: =SUM(K38:U38) -> 118 | W38: =K38/$I38*$G38 -> 0 | X38: =L38/$I38*$G38 -> 4950 | Y38: =M38/$I38*$G38 -> 0 | Z38: =N38/$I38*$G38 -> 1650 | AA38: =O38/$I38*$G38 -> 1650 | AB38: =P38/$I38*$G38 -> 2850 | AC38: =Q38/$I38*$G38 -> 0 | AD38: =R38/$I38*$G38 -> 6600 | ... AG38: =U38/$I38*$G38 -> 0 | AH38: =SUM(W38:AG38) -> 17700
A39: 38 | B39: Форманюк Руслан Леонідович | E39: =I39*J39 -> 19050 | F39: =VLOOKUP(B39,'[1]Табель цех 01 по 15 червня'!$B$2:$H$77,7,FALSE) -> -30 | G39: =ROUND(E39-D39,-2) -> 19100 | H39: =F39+E39-D39-G39-C39 -> -80 | I39: =Цо!AH39+IRS!AH39+Катеринополь!AH39+'Мк нежин'!AH39+'ЕМС Вооз'!AH39+ООН!AN39+'Червоний хрест'!AH39+Укрнафта!AJ39+Кернел!AO39+'Глобино Мк'!AH39+'МД Франківськ'!AH39 -> 127 | J39: 150 | K39: =VLOOKUP(B39,Цо!$B$2:$AH$74,33,FALSE) -> 0 | L39: =VLOOKUP(B39,IRS!$B$2:$AH$73,33,FALSE) -> 39 | M39: =VLOOKUP(B39,Катеринополь!$B$1:$AH$73,33,FALSE) -> 11 | N39: =VLOOKUP(B39,'Мк нежин'!$B$2:$AH$73,33,FALSE) -> 11 | O39: =VLOOKUP(B39,'ЕМС Вооз'!$B$2:$AH$73,33,FALSE) -> 22 | P39: =VLOOKUP(B39,ООН!$H$2:$AN$73,33,FALSE) -> 33 | Q39: =VLOOKUP(B39,'Червоний хрест'!$B$2:$AH$73,33,FALSE) -> 0 | R39: =VLOOKUP(B39,Укрнафта!$D$2:$AJ$73,33,FALSE) -> 0 | S39: =VLOOKUP(B39,Кернел!$I$2:$AO$73,33,FALSE) -> 0 | T39: =VLOOKUP(B39,'Глобино Мк'!$B$2:$AH$73,33,FALSE) -> 11 | U39: =VLOOKUP(B39,'МД Франківськ'!$B$2:$AH$73,33,FALSE) -> 0 | V39: =SUM(K39:U39) -> 127 | W39: =K39/$I39*$G39 -> 0 | X39: =L39/$I39*$G39 -> 5865.3543 | Y39: =M39/$I39*$G39 -> 1654.3307 | Z39: =N39/$I39*$G39 -> 1654.3307 | AA39: =O39/$I39*$G39 -> 3308.6614 | AB39: =P39/$I39*$G39 -> 4962.9921 | AC39: =Q39/$I39*$G39 -> 0 | AD39: =R39/$I39*$G39 -> 0 | ... AG39: =U39/$I39*$G39 -> 0 | AH39: =SUM(W39:AG39) -> 19100
A40: 39 | B40: Щербак Петро Іванович | E40: =I40*J40 -> 49950 | F40: =VLOOKUP(B40,'[1]Табель цех 01 по 15 червня'!$B$2:$H$77,7,FALSE) -> -50 | G40: =ROUND(E40-D40,-2) -> 50000 | H40: =F40+E40-D40-G40-C40 -> -100 | I40: =Цо!AH40+IRS!AH40+Катеринополь!AH40+'Мк нежин'!AH40+'ЕМС Вооз'!AH40+ООН!AN40+'Червоний хрест'!AH40+Укрнафта!AJ40+Кернел!AO40+'Глобино Мк'!AH40+'МД Франківськ'!AH40 -> 333 | J40: 150 | K40: =VLOOKUP(B40,Цо!$B$2:$AH$74,33,FALSE) -> 0 | L40: =VLOOKUP(B40,IRS!$B$2:$AH$73,33,FALSE) -> 0 | M40: =VLOOKUP(B40,Катеринополь!$B$1:$AH$73,33,FALSE) -> 10 | N40: =VLOOKUP(B40,'Мк нежин'!$B$2:$AH$73,33,FALSE) -> 11 | O40: =VLOOKUP(B40,'ЕМС Вооз'!$B$2:$AH$73,33,FALSE) -> 0 | P40: =VLOOKUP(B40,ООН!$H$2:$AN$73,33,FALSE) -> 120 | Q40: =VLOOKUP(B40,'Червоний хрест'!$B$2:$AH$73,33,FALSE) -> 192 | R40: =VLOOKUP(B40,Укрнафта!$D$2:$AJ$73,33,FALSE) -> 0 | S40: =VLOOKUP(B40,Кернел!$I$2:$AO$73,33,FALSE) -> 0 | T40: =VLOOKUP(B40,'Глобино Мк'!$B$2:$AH$73,33,FALSE) -> 0 | U40: =VLOOKUP(B40,'МД Франківськ'!$B$2:$AH$73,33,FALSE) -> 0 | V40: =SUM(K40:U40) -> 333 | W40: =K40/$I40*$G40 -> 0 | X40: =L40/$I40*$G40 -> 0 | Y40: =M40/$I40*$G40 -> 1501.5015 | Z40: =N40/$I40*$G40 -> 1651.6517 | AA40: =O40/$I40*$G40 -> 0 | AB40: =P40/$I40*$G40 -> 18018.018 | AC40: =Q40/$I40*$G40 -> 28828.829 | AD40: =R40/$I40*$G40 -> 0 | ... AG40: =U40/$I40*$G40 -> 0 | AH40: =SUM(W40:AG40) -> 50000
A41: 40 | B41: Онучак Віктор Іванович | D41: 3756.26 | E41: =I41*J41 -> 20100 | F41: =VLOOKUP(B41,'[1]Табель цех 01 по 15 червня'!$B$2:$H$77,7,FALSE) -> 0 | G41: =ROUND(E41-D41,-2) -> 16300 | H41: =F41+E41-D41-G41-C41 -> 43.74 | I41: =Цо!AH41+IRS!AH41+Катеринополь!AH41+'Мк нежин'!AH41+'ЕМС Вооз'!AH41+ООН!AN41+'Червоний хрест'!AH41+Укрнафта!AJ41+Кернел!AO41+'Глобино Мк'!AH41+'МД Франківськ'!AH41 -> 134 | J41: 150 | K41: =VLOOKUP(B41,Цо!$B$2:$AH$74,33,FALSE) -> 0 | L41: =VLOOKUP(B41,IRS!$B$2:$AH$73,33,FALSE) -> 50 | M41: =VLOOKUP(B41,Катеринополь!$B$1:$AH$73,33,FALSE) -> 0 | N41: =VLOOKUP(B41,'Мк нежин'!$B$2:$AH$73,33,FALSE) -> 40 | O41: =VLOOKUP(B41,'ЕМС Вооз'!$B$2:$AH$73,33,FALSE) -> 0 | P41: =VLOOKUP(B41,ООН!$H$2:$AN$73,33,FALSE) -> 11 | Q41: =VLOOKUP(B41,'Червоний хрест'!$B$2:$AH$73,33,FALSE) -> 0 | R41: =VLOOKUP(B41,Укрнафта!$D$2:$AJ$73,33,FALSE) -> 0 | S41: =VLOOKUP(B41,Кернел!$I$2:$AO$73,33,FALSE) -> 0 | T41: =VLOOKUP(B41,'Глобино Мк'!$B$2:$AH$73,33,FALSE) -> 33 | U41: =VLOOKUP(B41,'МД Франківськ'!$B$2:$AH$73,33,FALSE) -> 0 | V41: =SUM(K41:U41) -> 134 | W41: =K41/$I41*$G41 -> 0 | X41: =L41/$I41*$G41 -> 6082.0896 | Y41: =M41/$I41*$G41 -> 0 | Z41: =N41/$I41*$G41 -> 4865.6716 | AA41: =O41/$I41*$G41 -> 0 | AB41: =P41/$I41*$G41 -> 1338.0597 | AC41: =Q41/$I41*$G41 -> 0 | AD41: =R41/$I41*$G41 -> 0 | ... AG41: =U41/$I41*$G41 -> 0 | AH41: =SUM(W41:AG41) -> 16300
A42: 41 | B42: Кривка Руслан Олександрович | D42: 3756.26 | E42: =I42*J42 -> 36000 | F42: =VLOOKUP(B42,'[1]Табель цех 01 по 15 червня'!$B$2:$H$77,7,FALSE) -> 37.25 | G42: =ROUND(E42-D42,-2) -> 32200 | H42: =F42+E42-D42-G42-C42 -> 80.99 | I42: =Цо!AH42+IRS!AH42+Катеринополь!AH42+'Мк нежин'!AH42+'ЕМС Вооз'!AH42+ООН!AN42+'Червоний хрест'!AH42+Укрнафта!AJ42+Кернел!AO42+'Глобино Мк'!AH42+'МД Франківськ'!AH42 -> 240 | J42: 150 | K42: =VLOOKUP(B42,Цо!$B$2:$AH$74,33,FALSE) -> 0 | L42: =VLOOKUP(B42,IRS!$B$2:$AH$73,33,FALSE) -> 0 | M42: =VLOOKUP(B42,Катеринополь!$B$1:$AH$73,33,FALSE) -> 0 | N42: =VLOOKUP(B42,'Мк нежин'!$B$2:$AH$73,33,FALSE) -> 0 | O42: =VLOOKUP(B42,'ЕМС Вооз'!$B$2:$AH$73,33,FALSE) -> 0 | P42: =VLOOKUP(B42,ООН!$H$2:$AN$73,33,FALSE) -> 0 | Q42: =VLOOKUP(B42,'Червоний хрест'!$B$2:$AH$73,33,FALSE) -> 0 | R42: =VLOOKUP(B42,Укрнафта!$D$2:$AJ$73,33,FALSE) -> 0 | S42: =VLOOKUP(B42,Кернел!$I$2:$AO$73,33,FALSE) -> 240 | T42: =VLOOKUP(B42,'Глобино Мк'!$B$2:$AH$73,33,FALSE) -> 0 | U42: =VLOOKUP(B42,'МД Франківськ'!$B$2:$AH$73,33,FALSE) -> 0 | V42: =SUM(K42:U42) -> 240 | W42: =K42/$I42*$G42 -> 0 | X42: =L42/$I42*$G42 -> 0 | Y42: =M42/$I42*$G42 -> 0 | Z42: =N42/$I42*$G42 -> 0 | AA42: =O42/$I42*$G42 -> 0 | AB42: =P42/$I42*$G42 -> 0 | AC42: =Q42/$I42*$G42 -> 0 | AD42: =R42/$I42*$G42 -> 0 | ... AG42: =U42/$I42*$G42 -> 0 | AH42: =SUM(W42:AG42) -> 32200
A43: 42 | B43: Батрак Віктор Володимирович | D43: 3756.26 | E43: =I43*J43 -> 12450 | F43: =VLOOKUP(B43,'[1]Табель цех 01 по 15 червня'!$B$2:$H$77,7,FALSE) -> -38.75 | G43: =ROUND(E43-D43,-2) -> 8700 | H43: =F43+E43-D43-G43-C43 -> -45.01 | I43: =Цо!AH43+IRS!AH43+Катеринополь!AH43+'Мк нежин'!AH43+'ЕМС Вооз'!AH43+ООН!AN43+'Червоний хрест'!AH43+Укрнафта!AJ43+Кернел!AO43+'Глобино Мк'!AH43+'МД Франківськ'!AH43 -> 83 | J43: 150 | K43: =VLOOKUP(B43,Цо!$B$2:$AH$74,33,FALSE) -> 0 | L43: =VLOOKUP(B43,IRS!$B$2:$AH$73,33,FALSE) -> 11 | M43: =VLOOKUP(B43,Катеринополь!$B$1:$AH$73,33,FALSE) -> 0 | N43: =VLOOKUP(B43,'Мк нежин'!$B$2:$AH$73,33,FALSE) -> 11 | O43: =VLOOKUP(B43,'ЕМС Вооз'!$B$2:$AH$73,33,FALSE) -> 20 | P43: =VLOOKUP(B43,ООН!$H$2:$AN$73,33,FALSE) -> 19 | Q43: =VLOOKUP(B43,'Червоний хрест'!$B$2:$AH$73,33,FALSE) -> 0 | R43: =VLOOKUP(B43,Укрнафта!$D$2:$AJ$73,33,FALSE) -> 22 | S43: =VLOOKUP(B43,Кернел!$I$2:$AO$73,33,FALSE) -> 0 | T43: =VLOOKUP(B43,'Глобино Мк'!$B$2:$AH$73,33,FALSE) -> 0 | U43: =VLOOKUP(B43,'МД Франківськ'!$B$2:$AH$73,33,FALSE) -> 0 | V43: =SUM(K43:U43) -> 83 | W43: =K43/$I43*$G43 -> 0 | X43: =L43/$I43*$G43 -> 1153.012 | Y43: =M43/$I43*$G43 -> 0 | Z43: =N43/$I43*$G43 -> 1153.012 | AA43: =O43/$I43*$G43 -> 2096.3855 | AB43: =P43/$I43*$G43 -> 1991.5663 | AC43: =Q43/$I43*$G43 -> 0 | AD43: =R43/$I43*$G43 -> 2306.0241 | ... AG43: =U43/$I43*$G43 -> 0 | AH43: =SUM(W43:AG43) -> 8700
A44: 43 | B44: Бондаренко Іван Олександрович | D44: 3756.26 | E44: =I44*J44 -> 54000 | F44: =VLOOKUP(B44,'[1]Табель цех 01 по 15 червня'!$B$2:$H$77,7,FALSE) -> 14 | G44: =ROUND(E44-D44,-2) -> 50200 | H44: =F44+E44-D44-G44-C44 -> 57.74 | I44: =Цо!AH44+IRS!AH44+Катеринополь!AH44+'Мк нежин'!AH44+'ЕМС Вооз'!AH44+ООН!AN44+'Червоний хрест'!AH44+Укрнафта!AJ44+Кернел!AO44+'Глобино Мк'!AH44+'МД Франківськ'!AH44 -> 360 | J44: 150 | K44: =VLOOKUP(B44,Цо!$B$2:$AH$74,33,FALSE) -> 0 | L44: =VLOOKUP(B44,IRS!$B$2:$AH$73,33,FALSE) -> 0 | M44: =VLOOKUP(B44,Катеринополь!$B$1:$AH$73,33,FALSE) -> 0 | N44: =VLOOKUP(B44,'Мк нежин'!$B$2:$AH$73,33,FALSE) -> 0 | O44: =VLOOKUP(B44,'ЕМС Вооз'!$B$2:$AH$73,33,FALSE) -> 360 | P44: =VLOOKUP(B44,ООН!$H$2:$AN$73,33,FALSE) -> 0 | Q44: =VLOOKUP(B44,'Червоний хрест'!$B$2:$AH$73,33,FALSE) -> 0 | R44: =VLOOKUP(B44,Укрнафта!$D$2:$AJ$73,33,FALSE) -> 0 | S44: =VLOOKUP(B44,Кернел!$I$2:$AO$73,33,FALSE) -> 0 | T44: =VLOOKUP(B44,'Глобино Мк'!$B$2:$AH$73,33,FALSE) -> 0 | U44: =VLOOKUP(B44,'МД Франківськ'!$B$2:$AH$73,33,FALSE) -> 0 | V44: =SUM(K44:U44) -> 360 | W44: =K44/$I44*$G44 -> 0 | X44: =L44/$I44*$G44 -> 0 | Y44: =M44/$I44*$G44 -> 0 | Z44: =N44/$I44*$G44 -> 0 | AA44: =O44/$I44*$G44 -> 50200 | AB44: =P44/$I44*$G44 -> 0 | AC44: =Q44/$I44*$G44 -> 0 | AD44: =R44/$I44*$G44 -> 0 | ... AG44: =U44/$I44*$G44 -> 0 | AH44: =SUM(W44:AG44) -> 50200
