Workbook

Sheet Лист2
B1: Код (Таб. №) | C1: Наименование | D1: Код по ДРФО | E1: Вид договора | F1: Вид занятости | G1: Подразделение организации | H1: Должность организации | I1: Дата приема
B2: 1 | C2: Оренда авто
B3: д000000007 | C3: Воронцов Олександр Володимирович (оренда авто) | D3: 3244112838 | E3: Договор подряда (выполнение работ, оказание услуг)
B4: д000000023 | C4: Гавриченко Тетяна Василівна (оренда авто) | D4: 2890614789 | E4: Договор подряда (выполнение работ, оказание услуг)
B5: д000000010 | C5: Гриценко Олександр Вікторович (оренда авто) | D5: 2751711415 | E5: Договор подряда (выполнение работ, оказание услуг)
B6: д000000001 | C6: Гриценко Сергій Миколайович (дг.) | D6: 3382914593 | E6: Договор подряда (выполнение работ, оказание услуг)
B7: д000000013 | C7: Гриценко Сергій Миколайович (оренда авто) | D7: 3382914593 | E7: Договор подряда (выполнение работ, оказание услуг)
B8: д000000019 | C8: Гуняга Олег Володимирович (оренда авто) | D8: 2711822114 | E8: Договор подряда (выполнение работ, оказание услуг)
B9: д000000008 | C9: Манжула Максим Анатолійович (оренда авто) | D9: 3281710375 | E9: Договор подряда (выполнение работ, оказание услуг)
B10: д000000014 | C10: Огоновський Дмитро Анатолійович (оренда авто) | D10: 2866215672 | E10: Договор подряда (выполнение работ, оказание услуг)
B11: д000000015 | C11: Потьомко Михайло Володимирович (оренда авто) | D11: 3575508457 | E11: Договор подряда (выполнение работ, оказание услуг)
B12: д000000016 | C12: Сикал Павло Анатолійович (оренда авто) | D12: 3306506991 | E12: Договор подряда (выполнение работ, оказание услуг)
B13: д000000012 | C13: Старіков Сергій Вікторович (оренда авто) | D13: 2899410750 | E13: Договор подряда (выполнение работ, оказание услуг)
B14: д000000020 | C14: Шевченко Євген Анатолійович (оренда авто) | D14: 3194113635 | E14: Договор подряда (выполнение работ, оказание услуг)
B15: д000000009 | C15: Ширшов Олександр Леонідович (оренда авто) | D15: 2234022693 | E15: Договор подряда (выполнение работ, оказание услуг)
B16: 23 | C16: Адаменко Віталій Вікторович | D16: 3153900053 | E16: Трудовой договор | F16: Основное место работы | G16: Виробничий (Цех металоконструкцій) | H16: Монтажник будівельний | I16: 05.10.2022
B17: 4 | C17: Аксенчіков Сергій Олександрович | D17: 3457309598 | E17: Трудовой договор | F17: Основное место работы | G17: Адміністративний відділ | H17: Майстер будівельних та монтажних робіт | I17: 01.07.2022
B18: д000000001 | C18: Аксенчіков Сергій Олександрович (оренда авто) | D18: 3457309598 | E18: Договор подряда (выполнение работ, оказание услуг)
B19: 48 | C19: Александров Артем Анатолійович | D19: 2618119132 | E19: Трудовой договор | F19: Основное место работы | G19: Адміністративний відділ | H19: Діловод | I19: 25.09.2018
B20: 203 | C20: Александров Денис Анатолійович | D20: 2765913876 | E20: Трудовой договор | F20: Основное место работы | G20: Адміністративний відділ | H20: Помічник економіста | I20: 01.02.2021
B21: 156 | C21: Александрова Жанна Валентинівна | D21: 2693717247 | E21: Трудовой договор | F21: Основное место работы | G21: Адміністративний відділ | H21: Прибиральник службових приміщень | I21: 01.07.2020
B22: 2289516770 | C22: Антонович Тетяна Сергіївна | D22: 2894801342 | E22: Трудовой договор | F22: Основное место работы | G22: Адміністративний відділ | H22: Директор фінансовий | I22: 22.12.2022
B23: 16 | C23: Антонович Тетяна Сергіївна (сум.) | D23: 2894801342 | E23: Трудовой договор | F23: Внешнее совместительство | G23: Адміністративний відділ | H23: Директор фінансовий | I23: 26.05.2023
B24: 17 | C24: Аулова Маргарита Володимирівна | D24: 3036417408 | E24: Трудовой договор | F24: Внешнее совместительство | G24: Адміністративний відділ | H24: Головний бухгалтер | I24: 01.04.2024
B25: 2289516882 | C25: Аулова Маргарита Володимирівна (осн.) | D25: 3036417408 | E25: Трудовой договор | F25: Основное место работы | G25: Адміністративний відділ | H25: Головний бухгалтер | I25: 27.03.2024
B26: 2289516833 | C26: Ахмедов Тавакгюль Сардар огли | D26: 2358421934 | E26: Трудовой договор | F26: Основное место работы | G26: Виробничий (Ладижин-3) | H26: Маляр | I26: 08.09.2023
B27: 37 | C27: Бабіленко Микола Олександрович | D27: 2564424513 | E27: Трудовой договор | F27: Основное место работы | G27: Виробничий (Цех металоконструкцій) | H27: Слюсар із складання металевих конструкцій | I27: 01.12.2022
B28: 11 | C28: Багацький Вадим Геннадійович | D28: 3247506159 | E28: Трудовой договор | F28: Основное место работы | G28: Виробничий (Цех металоконструкцій) | H28: Електрозварник ручного зварювання | I28: 05.08.2022
B29: 2289516701 | C29: Безкоровайний Дмитро Миколайович | D29: 3358009052 | E29: Трудовой договор | F29: Основное место работы | G29: Виробничий (Підгірці) | H29: Водій автотранспортних засобів | I29: 04.02.2022
B30: 62 | C30: Білоусов Євген Вікторович | D30: 3421002151 | E30: Трудовой договор | F30: Основное место работы | G30: Виробничий (Старокостянтинів) | H30: Арматурник (будівельні, монтажні й ремонтно-будівельні роботи) | I30: 01.02.2019
B31: д000000006 | C31: Бічковський Максим Петрович | D31: 2922419813 | E31: Договор подряда (выполнение работ, оказание услуг)
B32: 2289516746 | C32: Блоха Євген Валерійович | D32: 2919308010 | E32: Трудовой договор | F32: Основное место работы | G32: Виробничий (Старокостянтинів) | H32: Бетоняр | I32: 27.09.2022
B33: 2289516849 | C33: Богданюк Дмитро Леонтійович | D33: 3036408418 | E33: Трудовой договор | F33: Основное место работы | G33: Адміністративний відділ | H33: Інженер з проєктно-кошторисної роботи | I33: 02.11.2023
B34: 19 | C34: Богун Олена Миколаївна | D34: 3813305164 | E34: Трудовой договор | F34: Основное место работы | G34: Виробничій цех | H34: Лаборант | I34: 02.07.2024
B35: 2289516863 | C35: Божков Валерій Вікторович | D35: 2753702532 | E35: Трудовой договор | F35: Основное место работы | G35: Виробничий (Крушинка) | H35: Водій автотранспортних засобів | I35: 19.12.2023
B36: 46 | C36: Бокоч Галина Михайлівна (осн.) | D36: 3018718189 | E36: Трудовой договор | F36: Основное место работы | G36: Адміністративний відділ | H36: Діловод | I36: 24.11.2023
B37: 157 | C37: Болох Володимир Васильович | D37: 2794610037 | E37: Трудовой договор | F37: Основное место работы | G37: Виробничий (Старокостянтинів) | H37: Машиніст крана автомобільного | I37: 03.08.2020
B38: 71 | C38: Борецька Людмила Сергіївна | D38: 3280710149 | E38: Трудовой договор | F38: Основное место работы | G38: Адміністративний відділ | H38: Економіст | I38: 08.04.2019
B39: 2289516756 | C39: Борисенко Олексій Миколайович | D39: 2957816213 | E39: Трудовой договор | F39: Основное место работы | G39: Виробничий (Крушинка) | H39: Машиніст крана автомобільного | I39: 01.11.2022
B40: 49 | C40: Бреус Віталій Григорович | D40: 3143007035 | E40: Трудовой договор | F40: Основное место работы | G40: Адміністративний відділ | H40: Менеджер (управитель) з постачання | I40: 18.07.2023
...

Sheet Лист1
B2: N | C2: Работник (основное назначение) | D2: Период взаиморасчетов | E2: Счет учета | F2: Сумма | G2: Сумма (окр.) | J2: Админ
B3: 1 | C3: Аксенчіков Сергій Олександрович | D3: 01.07.2024 | E3: 661 | F3: 4326 | H3: =MATCH(I3,#REF!,0) -> #REF! | I3: =TRIM(C3) -> Аксенчіков Сергій Олександрович | J3: 1
B4: 2 | C4: Бабіленко Микола Олександрович | D4: 01.07.2024 | E4: 661 | F4: 3990 | H4: =MATCH(I4,#REF!,0) -> #REF! | I4: =TRIM(C4) -> Бабіленко Микола Олександрович | K4: =INDEX(Лист2!D:D,MATCH(C4,Лист2!C:C,0)) -> 2564424513
B5: 3 | C5: Багацький Вадим Геннадійович | D5: 01.07.2024 | E5: 661 | F5: 3990 | H5: =MATCH(I5,#REF!,0) -> #REF! | I5: =TRIM(C5) -> Багацький Вадим Геннадійович | K5: =INDEX(Лист2!D:D,MATCH(C5,Лист2!C:C,0)) -> 3247506159
B6: 4 | C6: Бреус Віталій Григорович | D6: 01.07.2024 | E6: 661 | F6: 5417.99 | H6: =MATCH(I6,#REF!,0) -> #REF! | I6: =TRIM(C6) -> Бреус Віталій Григорович | J6: 1
B7: 5 | C7: Бутенко Матвій Анатолійович | D7: 01.07.2024 | E7: 661 | F7: 4326 | H7: =MATCH(I7,#REF!,0) -> #REF! | I7: =TRIM(C7) -> Бутенко Матвій Анатолійович | J7: 1
B8: 6 | C8: Васильєв Віталій Юрійович | D8: 01.07.2024 | E8: 661 | F8: 3990 | H8: =MATCH(I8,#REF!,0) -> #REF! | I8: =TRIM(C8) -> Васильєв Віталій Юрійович | K8: =INDEX(Лист2!D:D,MATCH(C8,Лист2!C:C,0)) -> 3746304158
B9: 7 | C9: Власенко В'ячеслав Валентинович | D9: 01.07.2024 | E9: 661 | F9: 3990 | H9: =MATCH(I9,#REF!,0) -> #REF! | I9: =TRIM(C9) -> Власенко В'ячеслав Валентинович | K9: =INDEX(Лист2!D:D,MATCH(C9,Лист2!C:C,0)) -> 2831710277
B10: 8 | C10: Горєлов Микита Євгенович | D10: 01.07.2024 | E10: 661 | F10: 2660 | H10: =MATCH(I10,#REF!,0) -> #REF! | I10: =TRIM(C10) -> Горєлов Микита Євгенович | K10: =INDEX(Лист2!D:D,MATCH(C10,Лист2!C:C,0)) -> 3596200395
B11: 9 | C11: Григор'єв Микола Андрійович | D11: 01.07.2024 | E11: 661 | F11: 1662.5 | H11: =MATCH(I11,#REF!,0) -> #REF! | I11: =TRIM(C11) -> Григор'єв Микола Андрійович | K11: =INDEX(Лист2!D:D,MATCH(C11,Лист2!C:C,0)) -> 3422005391
B12: 10 | C12: Григор'єв Михайло Андрійович | D12: 01.07.2024 | E12: 661 | F12: 3990 | H12: =MATCH(I12,#REF!,0) -> #REF! | I12: =TRIM(C12) -> Григор'єв Михайло Андрійович | K12: =INDEX(Лист2!D:D,MATCH(C12,Лист2!C:C,0)) -> 3720407672
B13: 11 | C13: Григоренко Олександр Миколайович | D13: 01.07.2024 | E13: 661 | F13: 3990 | H13: =MATCH(I13,#REF!,0) -> #REF! | I13: =TRIM(C13) -> Григоренко Олександр Миколайович | K13: =INDEX(Лист2!D:D,MATCH(C13,Лист2!C:C,0)) -> 2436600937
B14: 12 | C14: Гриценко Олександр Вікторович | D14: 01.07.2024 | E14: 661 | F14: 5197.5 | H14: =MATCH(I14,#REF!,0) -> #REF! | I14: =TRIM(C14) -> Гриценко Олександр Вікторович | J14: 1
B15: 13 | C15: Грушко Лариса Вікторівна | D15: 01.07.2024 | E15: 661 | F15: 4427.5 | H15: =MATCH(I15,#REF!,0) -> #REF! | I15: =TRIM(C15) -> Грушко Лариса Вікторівна | J15: 1
B16: 14 | C16: Дехтяр Владислав Олександрович | D16: 01.07.2024 | E16: 661 | F16: 3990 | H16: =MATCH(I16,#REF!,0) -> #REF! | I16: =#REF! -> #REF! | K16: =INDEX(Лист2!D:D,MATCH(C16,Лист2!C:C,0)) -> 3374502899
B17: 15 | C17: Желтяков Ігор Юрійович | D17: 01.07.2024 | E17: 661 | F17: 3990 | H17: =MATCH(I17,#REF!,0) -> #REF! | I17: =TRIM(C17) -> Желтяков Ігор Юрійович | K17: =INDEX(Лист2!D:D,MATCH(C17,Лист2!C:C,0)) -> 2637303953
B18: 16 | C18: Іванов Олексій Вікторович | D18: 01.07.2024 | E18: 661 | F18: 3990 | H18: =MATCH(I18,#REF!,0) -> #REF! | I18: =TRIM(C18) -> Іванов Олексій Вікторович | K18: =INDEX(Лист2!D:D,MATCH(C18,Лист2!C:C,0)) -> 3705902230
B19: 17 | C19: Іскрицький Денис Русланович | D19: 01.07.2024 | E19: 661 | F19: 3990 | H19: =MATCH(I19,#REF!,0) -> #REF! | I19: =TRIM(C19) -> Іскрицький Денис Русланович | K19: =INDEX(Лист2!D:D,MATCH(C19,Лист2!C:C,0)) -> 3779110293
B20: 18 | C20: Кіфор Юрій Михайлович | D20: 01.07.2024 | E20: 661 | F20: 3990.02 | H20: =MATCH(I20,#REF!,0) -> #REF! | I20: =TRIM(C20) -> Кіфор Юрій Михайлович | K20: =INDEX(Лист2!D:D,MATCH(C20,Лист2!C:C,0)) -> 2521518612
B21: 19 | C21: Корнієнко Станіслав Володимирович | D21: 01.07.2024 | E21: 661 | F21: 3428.01 | H21: =MATCH(I21,#REF!,0) -> #REF! | I21: =C21 -> Корнієнко Станіслав Володимирович | K21: =INDEX(Лист2!D:D,MATCH(C21,Лист2!C:C,0)) -> 2579305831
B22: 20 | C22: Масливець Ігор Валерійович | D22: 01.07.2024 | E22: 661 | F22: 3990 | H22: =MATCH(I22,#REF!,0) -> #REF! | I22: =TRIM(C22) -> Масливець Ігор Валерійович | K22: =INDEX(Лист2!D:D,MATCH(C22,Лист2!C:C,0)) -> 2880313812
B23: 21 | C23: Мельниченко Максим Вікторович | D23: 01.07.2024 | E23: 661 | F23: 6650 | H23: =MATCH(I23,#REF!,0) -> #REF! | I23: =TRIM(C23) -> Мельниченко Максим Вікторович | K23: =INDEX(Лист2!D:D,MATCH(C23,Лист2!C:C,0)) -> 3348501613
B24: 22 | C24: Мороз Віталій Миколайович | D24: 01.07.2024 | E24: 661 | F24: 6650 | H24: =MATCH(I24,#REF!,0) -> #REF! | I24: =TRIM(C24) -> Мороз Віталій Миколайович | K24: =INDEX(Лист2!D:D,MATCH(C24,Лист2!C:C,0)) -> 3216804294
B25: 23 | C25: Нестерук Сергій Петрович | D25: 01.07.2024 | E25: 661 | F25: 3990.02 | H25: =MATCH(I25,#REF!,0) -> #REF! | I25: =TRIM(C25) -> Нестерук Сергій Петрович | K25: =INDEX(Лист2!D:D,MATCH(C25,Лист2!C:C,0)) -> 3283102618
B26: 24 | C26: Паламарчук Вячеслав Володимирович | D26: 01.07.2024 | E26: 661 | F26: 3990 | H26: =MATCH(I26,#REF!,0) -> #REF! | I26: =TRIM(C26) -> Паламарчук Вячеслав Володимирович | K26: =INDEX(Лист2!D:D,MATCH(C26,Лист2!C:C,0)) -> 3230316597
B27: 25 | C27: Парнєва Олена Вікторівна | D27: 01.07.2024 | E27: 661 | F27: 840 | H27: =MATCH(I27,#REF!,0) -> #REF! | I27: =TRIM(C27) -> Парнєва Олена Вікторівна | K27: =INDEX(Лист2!D:D,MATCH(C27,Лист2!C:C,0)) -> 2938511042
B28: 26 | C28: Пилипчук Олександр Анатолійович | D28: 01.07.2024 | E28: 661 | F28: 3990 | H28: =MATCH(I28,#REF!,0) -> #REF! | I28: =TRIM(C28) -> Пилипчук Олександр Анатолійович | K28: =INDEX(Лист2!D:D,MATCH(C28,Лист2!C:C,0)) -> 3067218612
B29: 27 | C29: Поліщук Олександр Олександрович | D29: 01.07.2024 | E29: 661 | F29: 3990 | H29: =MATCH(I29,#REF!,0) -> #REF! | I29: =TRIM(C29) -> Поліщук Олександр Олександрович | K29: =INDEX(Лист2!D:D,MATCH(C29,Лист2!C:C,0)) -> 3289716153
B30: 28 | C30: Пономаренко Віталій Вікторович | D30: 01.07.2024 | E30: 661 | F30: 3990 | H30: =MATCH(I30,#REF!,0) -> #REF! | I30: =TRIM(C30) -> Пономаренко Віталій Вікторович | K30: =INDEX(Лист2!D:D,MATCH(C30,Лист2!C:C,0)) -> 3185119514
B31: 29 | C31: Пономаренко Олександр Вікторович | D31: 01.07.2024 | E31: 661 | F31: 5460 | H31: =MATCH(I31,#REF!,0) -> #REF! | I31: =TRIM(C31) -> Пономаренко Олександр Вікторович | K31: =INDEX(Лист2!D:D,MATCH(C31,Лист2!C:C,0)) -> 2944519172
B32: 30 | C32: Пономарьов Микола Вікторович | D32: 01.07.2024 | E32: 661 | F32: 3990 | H32: =MATCH(I32,#REF!,0) -> #REF! | I32: =TRIM(C32) -> Пономарьов Микола Вікторович | K32: =INDEX(Лист2!D:D,MATCH(C32,Лист2!C:C,0)) -> 3008300898
B33: 31 | C33: Понуркін Євген Григорович | D33: 01.07.2024 | E33: 661 | F33: 3990 | H33: =MATCH(I33,#REF!,0) -> #REF! | I33: =TRIM(C33) -> Понуркін Євген Григорович | K33: =INDEX(Лист2!D:D,MATCH(C33,Лист2!C:C,0)) -> 3005702873
... B38: 36 | C38: Скрипник Сергій Павлович | D38: 01.07.2024 | E38: 661 | F38: 5460 | H38: =MATCH(I38,#REF!,0) -> #REF! | I38: =TRIM(C38) -> Скрипник Сергій Павлович | K38: =INDEX(Лист2!D:D,MATCH(C38,Лист2!C:C,0)) -> 3219619831
B39: 37 | C39: Стецюк Тетяна Леонідівна | D39: 01.07.2024 | E39: 661 | F39: 5460 | H39: =MATCH(I39,#REF!,0) -> #REF! | I39: =TRIM(C39) -> Стецюк Тетяна Леонідівна | J39: 1
B40: 38 | C40: Тужиков Валерій Владиславович (осн.) | D40: 01.07.2024 | E40: 661 | F40: 3990 | H40: =MATCH(I40,#REF!,0) -> #REF! | I40: =#REF! -> #REF! | K40: =INDEX(Лист2!D:D,MATCH(C40,Лист2!C:C,0)) -> 3233009756
B41: 39 | C41: Тужиков Юрій Владиславович | D41: 01.07.2024 | E41: 661 | F41: 3324.99 | H41: =MATCH(I41,#REF!,0) -> #REF! | I41: =TRIM(C41) -> Тужиков Юрій Владиславович | K41: =INDEX(Лист2!D:D,MATCH(C41,Лист2!C:C,0)) -> 3153508799
B42: 40 | C42: Федорчук Денис Сергійович | D42: 01.07.2024 | E42: 661 | F42: 1995 | H42: =MATCH(I42,#REF!,0) -> #REF! | I42: =TRIM(C42) -> Федорчук Денис Сергійович | K42: =INDEX(Лист2!D:D,MATCH(C42,Лист2!C:C,0)) -> 3428705315
B43: 41 | C43: Чілібін Микола Євгенович | D43: 01.07.2024 | E43: 661 | F43: 5460 | H43: =MATCH(I43,#REF!,0) -> #REF! | I43: =TRIM(C43) -> Чілібін Микола Євгенович | J43: 1
B44: 42 | C44: Чуб Владислав Володимирович | D44: 01.07.2024 | E44: 661 | F44: 840 | H44: =MATCH(I44,#REF!,0) -> #REF! | I44: =TRIM(C44) -> Чуб Владислав Володимирович | K44: =INDEX(Лист2!D:D,MATCH(C44,Лист2!C:C,0)) -> 2858519154
B45: 43 | C45: Щербак Петро Іванович | D45: 01.07.2024 | E45: 661 | F45: 4620 | H45: =MATCH(I45,#REF!,0) -> #REF! | I45: =C45 -> Щербак Петро Іванович | K45: =INDEX(Лист2!D:D,MATCH(C45,Лист2!C:C,0)) -> 2537500655
...

Sheet Табель цех 16 по 30 серпня
A1: N | B1: Сотрудник | C1: Удержание за обеды на объекте | D1: виплати на картку за період 16-31.08.25 | E1: ЗП 16-31.08.25 | F1: Сальдо на -15.08.2025 | G1: до виплати | H1: Сальдо на 31.08.2025 | I1: Відпрацьовано годин | J1: ставка | K1: ИТР | L1: ЦО | M1: IRS | N1: катеринопіль | O1: мк нежин | P1: МД ВООЗ ЕМС | Q1: ООН 2025 | R1: червоний хрест | S1: укрнафта | T1: кернел | U1: глобино | V1: франківськ | W1: перевірка | X1: ИТР | Y1: ЦО | Z1: IRS | AA1: катеринопіль | AB1: мк нежин | AC1: МД ВООЗ ЕМС | AD1: ООН 2025 | AE1: червоний хрест | AF1: укрнафта | AG1: кернел | AH1: глобино | AI1: франківськ | AJ1: перевірка
A2: 1 | B2: Скрипник Сергій Павлович | D2: 37894.81 | E2: =I2*J2 -> 21780 | F2: =SUMIF('[1]Табель цех 1 по 15 серпня'!$B:$B,B2,'[1]Табель цех 1 по 15 серпня'!$H:$H) -> -18.75 | G2: 0 | H2: =F2+E2-D2-G2-C2 -> -16133.56 | I2: =ИТР!S2 -> 121 | J2: 180 | K2: =SUMIF(ИТР!B:B,B2,ИТР!S:S) -> 121 | L2: =SUMIF(Цо!R:R,B2,Цо!AI:AI) -> 0 | M2: =SUMIF(IRS!B:B,B2,IRS!S:S) -> 0 | N2: =SUMIF(Катеринополь!B:B,B2,Катеринополь!S:S) -> 0 | Q2: =SUMIF('ООН 2025'!B:B,B2,'ООН 2025'!S:S) -> 0 | R2: =SUMIF('Червоний хрест'!B:B,B2,'Червоний хрест'!S:S) -> 0 | T2: =SUMIF(Кернел!B:B,B2,Кернел!S:S) -> 0 | U2: =SUMIF('Глобино Мк'!B:B,B2,'Глобино Мк'!S:S) -> 0 | V2: =SUMIF('МД Франківськ'!B:B,B2,'МД Франківськ'!S:S) -> 0 | W2: =SUM(K2:V2)-I2 -> 0 | X2: =IFERROR(K2/$I2*$G2,0) -> 0 | Y2: =IFERROR(L2/$I2*$G2,0) -> 0 | Z2: =IFERROR(M2/$I2*$G2,0) -> 0 | AA2: =IFERROR(N2/$I2*$G2,0) -> 0 | AB2: =IFERROR(O2/$I2*$G2,0) -> 0 | AC2: =IFERROR(P2/$I2*$G2,0) -> 0 | AD2: =IFERROR(Q2/$I2*$G2,0) -> 0 | AE2: =IFERROR(R2/$I2*$G2,0) -> 0 | ... AJ2: =IFERROR(W2/$I2*$G2,0) -> 0 | AK2: =AJ2-G2 -> 0
A3: 2 | B3: Пономаренко Віталій Вікторович | D3: 8286.67 | E3: =I3*J3 -> 25560 | F3: =SUMIF('[1]Табель цех 1 по 15 серпня'!$B:$B,B3,'[1]Табель цех 1 по 15 серпня'!$H:$H) -> -50.85 | G3: =ROUND(E3-C3-D3,-2) -> 17300 | H3: =F3+E3-D3-G3-C3 -> -77.52 | I3: =ИТР!S3 -> 142 | J3: 180 | K3: =SUMIF(ИТР!B:B,B3,ИТР!S:S) -> 142 | L3: =SUMIF(Цо!R:R,B3,Цо!AI:AI) -> 0 | M3: =SUMIF(IRS!B:B,B3,IRS!S:S) -> 0 | N3: =SUMIF(Катеринополь!B:B,B3,Катеринополь!S:S) -> 0 | Q3: =SUMIF('ООН 2025'!B:B,B3,'ООН 2025'!S:S) -> 0 | R3: =SUMIF('Червоний хрест'!B:B,B3,'Червоний хрест'!S:S) -> 0 | T3: =SUMIF(Кернел!B:B,B3,Кернел!S:S) -> 0 | U3: =SUMIF('Глобино Мк'!B:B,B3,'Глобино Мк'!S:S) -> 0 | V3: =SUMIF('МД Франківськ'!B:B,B3,'МД Франківськ'!S:S) -> 0 | W3: =SUM(K3:V3)-I3 -> 0 | X3: =IFERROR(K3/$I3*$G3,0) -> 17300 | Y3: =IFERROR(L3/$I3*$G3,0) -> 0 | Z3: =IFERROR(M3/$I3*$G3,0) -> 0 | AA3: =IFERROR(N3/$I3*$G3,0) -> 0 | AB3: =IFERROR(O3/$I3*$G3,0) -> 0 | AC3: =IFERROR(P3/$I3*$G3,0) -> 0 | AD3: =IFERROR(Q3/$I3*$G3,0) -> 0 | AE3: =IFERROR(R3/$I3*$G3,0) -> 0 | ... AI3: =IFERROR(V3/$I3*$G3,0) -> 0 | AJ3: =SUM(X3:AI3) -> 17300 | AK3: =AJ3-G3 -> 0
A4: 3 | B4: Власенко В'ячеслав Валентинович | D4: 3739.99 | E4: =I4*J4 -> 15480 | F4: =SUMIF('[1]Табель цех 1 по 15 серпня'!$B:$B,B4,'[1]Табель цех 1 по 15 серпня'!$H:$H) -> -55.9 | G4: =ROUND(E4-C4-D4,-2) -> 11700 | H4: =F4+E4-D4-G4-C4 -> -15.89 | I4: =ИТР!S4 -> 86 | J4: 180 | K4: =SUMIF(ИТР!B:B,B4,ИТР!S:S) -> 86 | L4: =SUMIF(Цо!R:R,B4,Цо!AI:AI) -> 0 | M4: =SUMIF(IRS!B:B,B4,IRS!S:S) -> 0 | N4: =SUMIF(Катеринополь!B:B,B4,Катеринополь!S:S) -> 0 | Q4: =SUMIF('ООН 2025'!B:B,B4,'ООН 2025'!S:S) -> 0 | R4: =SUMIF('Червоний хрест'!B:B,B4,'Червоний хрест'!S:S) -> 0 | T4: =SUMIF(Кернел!B:B,B4,Кернел!S:S) -> 0 | U4: =SUMIF('Глобино Мк'!B:B,B4,'Глобино Мк'!S:S) -> 0 | V4: =SUMIF('МД Франківськ'!B:B,B4,'МД Франківськ'!S:S) -> 0 | W4: =SUM(K4:V4)-I4 -> 0 | X4: =IFERROR(K4/$I4*$G4,0) -> 11700 | Y4: =IFERROR(L4/$I4*$G4,0) -> 0 | Z4: =IFERROR(M4/$I4*$G4,0) -> 0 | AA4: =IFERROR(N4/$I4*$G4,0) -> 0 | AB4: =IFERROR(O4/$I4*$G4,0) -> 0 | AC4: =IFERROR(P4/$I4*$G4,0) -> 0 | AD4: =IFERROR(Q4/$I4*$G4,0) -> 0 | AE4: =IFERROR(R4/$I4*$G4,0) -> 0 | ... AI4: =IFERROR(V4/$I4*$G4,0) -> 0 | AJ4: =SUM(X4:AI4) -> 11700 | AK4: =AJ4-G4 -> 0
A5: 1 | B5: Багацький Вадим Геннадійович | D5: 3739.99 | E5: =I5*J5 -> 18300 | F5: =SUMIF('[1]Табель цех 1 по 15 серпня'!$B:$B,B5,'[1]Табель цех 1 по 15 серпня'!$H:$H) -> 102.24 | G5: =ROUND(E5-C5-D5,-2) -> 14600 | H5: =F5+E5-D5-G5-C5 -> 62.25 | I5: =Цо!AI2+IRS!S2+Катеринополь!S2+'Червоний хрест'!S2+'ООН 2025'!S2+Кернел!S2+'Глобино Мк'!S2+'МД Франківськ'!S2 -> 122 | J5: 150 | K5: =SUMIF(ИТР!B:B,B5,ИТР!S:S) -> 0 | L5: =SUMIF(Цо!R:R,B5,Цо!AI:AI) -> 0 | M5: =SUMIF(IRS!B:B,B5,IRS!S:S) -> 0 | N5: =SUMIF(Катеринополь!B:B,B5,Катеринополь!S:S) -> 61 | Q5: =SUMIF('ООН 2025'!B:B,B5,'ООН 2025'!S:S) -> 0 | R5: =SUMIF('Червоний хрест'!B:B,B5,'Червоний хрест'!S:S) -> 0 | T5: =SUMIF(Кернел!B:B,B5,Кернел!S:S) -> 0 | U5: =SUMIF('Глобино Мк'!B:B,B5,'Глобино Мк'!S:S) -> 61 | V5: =SUMIF('МД Франківськ'!B:B,B5,'МД Франківськ'!S:S) -> 0 | W5: =SUM(K5:V5)-I5 -> 0 | X5: =IFERROR(K5/$I5*$G5,0) -> 0 | Y5: =IFERROR(L5/$I5*$G5,0) -> 0 | Z5: =IFERROR(M5/$I5*$G5,0) -> 0 | AA5: =IFERROR(N5/$I5*$G5,0) -> 7300 | AB5: =IFERROR(O5/$I5*$G5,0) -> 0 | AC5: =IFERROR(P5/$I5*$G5,0) -> 0 | AD5: =IFERROR(Q5/$I5*$G5,0) -> 0 | AE5: =IFERROR(R5/$I5*$G5,0) -> 0 | ... AI5: =IFERROR(V5/$I5*$G5,0) -> 0 | AJ5: =SUM(X5:AI5) -> 14600 | AK5: =AJ5-G5 -> 0
A6: 2 | B6: Васильєв Віталій Юрійович | D6: 3739.99 | E6: =I6*J6 -> 18750 | F6: =SUMIF('[1]Табель цех 1 по 15 серпня'!$B:$B,B6,'[1]Табель цех 1 по 15 серпня'!$H:$H) -> 69.25 | G6: =ROUND(E6-C6-D6,-2) -> 15000 | H6: =F6+E6-D6-G6-C6 -> 79.26 | I6: =Цо!AI3+IRS!S3+Катеринополь!S3+'Червоний хрест'!S3+'ООН 2025'!S3+Кернел!S3+'Глобино Мк'!S3+'МД Франківськ'!S3 -> 125 | J6: 150 | K6: =SUMIF(ИТР!B:B,B6,ИТР!S:S) -> 0 | L6: =SUMIF(Цо!R:R,B6,Цо!AI:AI) -> 125 | M6: =SUMIF(IRS!B:B,B6,IRS!S:S) -> 0 | N6: =SUMIF(Катеринополь!B:B,B6,Катеринополь!S:S) -> 0 | Q6: =SUMIF('ООН 2025'!B:B,B6,'ООН 2025'!S:S) -> 0 | R6: =SUMIF('Червоний хрест'!B:B,B6,'Червоний хрест'!S:S) -> 0 | T6: =SUMIF(Кернел!B:B,B6,Кернел!S:S) -> 0 | U6: =SUMIF('Глобино Мк'!B:B,B6,'Глобино Мк'!S:S) -> 0 | V6: =SUMIF('МД Франківськ'!B:B,B6,'МД Франківськ'!S:S) -> 0 | W6: =SUM(K6:V6)-I6 -> 0 | X6: =IFERROR(K6/$I6*$G6,0) -> 0 | Y6: =IFERROR(L6/$I6*$G6,0) -> 15000 | Z6: =IFERROR(M6/$I6*$G6,0) -> 0 | AA6: =IFERROR(N6/$I6*$G6,0) -> 0 | AB6: =IFERROR(O6/$I6*$G6,0) -> 0 | AC6: =IFERROR(P6/$I6*$G6,0) -> 0 | AD6: =IFERROR(Q6/$I6*$G6,0) -> 0 | AE6: =IFERROR(R6/$I6*$G6,0) -> 0 | ... AI6: =IFERROR(V6/$I6*$G6,0) -> 0 | AJ6: =SUM(X6:AI6) -> 15000 | AK6: =AJ6-G6 -> 0
A7: 3 | B7: Григоренко Олександр Миколайович | C7: 9162.5 | D7: 3739.99 | E7: =I7*J7 -> 50400 | F7: =SUMIF('[1]Табель цех 1 по 15 серпня'!$B:$B,B7,'[1]Табель цех 1 по 15 серпня'!$H:$H) -> -30.76 | G7: =ROUND(E7-C7-D7,-2) -> 37500 | H7: =F7+E7-D7-G7-C7 -> -33.25 | I7: =Цо!AI4+IRS!S4+Катеринополь!S4+'Червоний хрест'!S4+'ООН 2025'!S4+Кернел!S4+'Глобино Мк'!S4+'МД Франківськ'!S4 -> 336 | J7: 150 | K7: =SUMIF(ИТР!B:B,B7,ИТР!S:S) -> 0 | L7: =SUMIF(Цо!R:R,B7,Цо!AI:AI) -> 0 | M7: =SUMIF(IRS!B:B,B7,IRS!S:S) -> 0 | N7: =SUMIF(Катеринополь!B:B,B7,Катеринополь!S:S) -> 0 | Q7: =SUMIF('ООН 2025'!B:B,B7,'ООН 2025'!S:S) -> 0 | R7: =SUMIF('Червоний хрест'!B:B,B7,'Червоний хрест'!S:S) -> 0 | T7: =SUMIF(Кернел!B:B,B7,Кернел!S:S) -> 336 | U7: =SUMIF('Глобино Мк'!B:B,B7,'Глобино Мк'!S:S) -> 0 | V7: =SUMIF('МД Франківськ'!B:B,B7,'МД Франківськ'!S:S) -> 0 | W7: =SUM(K7:V7)-I7 -> 0 | X7: =IFERROR(K7/$I7*$G7,0) -> 0 | Y7: =IFERROR(L7/$I7*$G7,0) -> 0 | Z7: =IFERROR(M7/$I7*$G7,0) -> 0 | AA7: =IFERROR(N7/$I7*$G7,0) -> 0 | AB7: =IFERROR(O7/$I7*$G7,0) -> 0 | AC7: =IFERROR(P7/$I7*$G7,0) -> 0 | AD7: =IFERROR(Q7/$I7*$G7,0) -> 0 | AE7: =IFERROR(R7/$I7*$G7,0) -> 0 | ... AI7: =IFERROR(V7/$I7*$G7,0) -> 0 | AJ7: =SUM(X7:AI7) -> 37500 | AK7: =AJ7-G7 -> 0
A8: 4 | B8: Григорьєв Микола Андрійович | D8: 3739.99 | E8: =I8*J8 -> 17400 | F8: =SUMIF('[1]Табель цех 1 по 15 серпня'!$B:$B,B8,'[1]Табель цех 1 по 15 серпня'!$H:$H) -> -11.75 | G8: =ROUND(E8-C8-D8,-2) -> 13700 | H8: =F8+E8-D8-G8-C8 -> -51.74 | I8: =Цо!AI5+IRS!S5+Катеринополь!S5+'Червоний хрест'!S5+'ООН 2025'!S5+Кернел!S5+'Глобино Мк'!S5+'МД Франківськ'!S5 -> 116 | J8: 150 | K8: =SUMIF(ИТР!B:B,B8,ИТР!S:S) -> 0 | L8: =SUMIF(Цо!R:R,B8,Цо!AI:AI) -> 0 | M8: =SUMIF(IRS!B:B,B8,IRS!S:S) -> 0 | N8: =SUMIF(Катеринополь!B:B,B8,Катеринополь!S:S) -> 0 | Q8: =SUMIF('ООН 2025'!B:B,B8,'ООН 2025'!S:S) -> 116 | R8: =SUMIF('Червоний хрест'!B:B,B8,'Червоний хрест'!S:S) -> 0 | T8: =SUMIF(Кернел!B:B,B8,Кернел!S:S) -> 0 | U8: =SUMIF('Глобино Мк'!B:B,B8,'Глобино Мк'!S:S) -> 0 | V8: =SUMIF('МД Франківськ'!B:B,B8,'МД Франківськ'!S:S) -> 0 | W8: =SUM(K8:V8)-I8 -> 0 | X8: =IFERROR(K8/$I8*$G8,0) -> 0 | Y8: =IFERROR(L8/$I8*$G8,0) -> 0 | Z8: =IFERROR(M8/$I8*$G8,0) -> 0 | AA8: =IFERROR(N8/$I8*$G8,0) -> 0 | AB8: =IFERROR(O8/$I8*$G8,0) -> 0 | AC8: =IFERROR(P8/$I8*$G8,0) -> 0 | AD8: =IFERROR(Q8/$I8*$G8,0) -> 13700 | AE8: =IFERROR(R8/$I8*$G8,0) -> 0 | ... AI8: =IFERROR(V8/$I8*$G8,0) -> 0 | AJ8: =SUM(X8:AI8) -> 13700 | AK8: =AJ8-G8 -> 0
A9: 5 | B9: Григор'єв Михайло Андрійович | D9: 1869.98 | E9: =I9*J9 -> 8250 | F9: =SUMIF('[1]Табель цех 1 по 15 серпня'!$B:$B,B9,'[1]Табель цех 1 по 15 серпня'!$H:$H) -> -96.85 | G9: =ROUND(E9-C9-D9,-2) -> 6400 | H9: =F9+E9-D9-G9-C9 -> -116.83 | I9: =Цо!AI6+IRS!S6+Катеринополь!S6+'Червоний хрест'!S6+'ООН 2025'!S6+Кернел!S6+'Глобино Мк'!S6+'МД Франківськ'!S6 -> 55 | J9: 150 | K9: =SUMIF(ИТР!B:B,B9,ИТР!S:S) -> 0 | L9: =SUMIF(Цо!R:R,B9,Цо!AI:AI) -> 0 | M9: =SUMIF(IRS!B:B,B9,IRS!S:S) -> 0 | N9: =SUMIF(Катеринополь!B:B,B9,Катеринополь!S:S) -> 0 | Q9: =SUMIF('ООН 2025'!B:B,B9,'ООН 2025'!S:S) -> 55 | R9: =SUMIF('Червоний хрест'!B:B,B9,'Червоний хрест'!S:S) -> 0 | T9: =SUMIF(Кернел!B:B,B9,Кернел!S:S) -> 0 | U9: =SUMIF('Глобино Мк'!B:B,B9,'Глобино Мк'!S:S) -> 0 | V9: =SUMIF('МД Франківськ'!B:B,B9,'МД Франківськ'!S:S) -> 0 | W9: =SUM(K9:V9)-I9 -> 0 | X9: =IFERROR(K9/$I9*$G9,0) -> 0 | Y9: =IFERROR(L9/$I9*$G9,0) -> 0 | Z9: =IFERROR(M9/$I9*$G9,0) -> 0 | AA9: =IFERROR(N9/$I9*$G9,0) -> 0 | AB9: =IFERROR(O9/$I9*$G9,0) -> 0 | AC9: =IFERROR(P9/$I9*$G9,0) -> 0 | AD9: =IFERROR(Q9/$I9*$G9,0) -> 6400 | AE9: =IFERROR(R9/$I9*$G9,0) -> 0 | ... AI9: =IFERROR(V9/$I9*$G9,0) -> 0 | AJ9: =SUM(X9:AI9) -> 6400 | AK9: =AJ9-G9 -> 0
A10: 6 | B10: Іванов Олексій Вікторович | D10: 3740.01 | E10: =I10*J10 -> 16500 | F10: =SUMIF('[1]Табель цех 1 по 15 серпня'!$B:$B,B10,'[1]Табель цех 1 по 15 серпня'!$H:$H) -> 48.56 | G10: =ROUND(E10-C10-D10,-2) -> 12800 | H10: =F10+E10-D10-G10-C10 -> 8.55 | I10: =Цо!AI7+IRS!S7+Катеринополь!S7+'Червоний хрест'!S7+'ООН 2025'!S7+Кернел!S7+'Глобино Мк'!S7+'МД Франківськ'!S7 -> 110 | J10: 150 | K10: =SUMIF(ИТР!B:B,B10,ИТР!S:S) -> 0 | L10: =SUMIF(Цо!R:R,B10,Цо!AI:AI) -> 0 | M10: =SUMIF(IRS!B:B,B10,IRS!S:S) -> 0 | N10: =SUMIF(Катеринополь!B:B,B10,Катеринополь!S:S) -> 71 | Q10: =SUMIF('ООН 2025'!B:B,B10,'ООН 2025'!S:S) -> 0 | R10: =SUMIF('Червоний хрест'!B:B,B10,'Червоний хрест'!S:S) -> 0 | T10: =SUMIF(Кернел!B:B,B10,Кернел!S:S) -> 0 | U10: =SUMIF('Глобино Мк'!B:B,B10,'Глобино Мк'!S:S) -> 39 | V10: =SUMIF('МД Франківськ'!B:B,B10,'МД Франківськ'!S:S) -> 0 | W10: =SUM(K10:V10)-I10 -> 0 | X10: =IFERROR(K10/$I10*$G10,0) -> 0 | Y10: =IFERROR(L10/$I10*$G10,0) -> 0 | Z10: =IFERROR(M10/$I10*$G10,0) -> 0 | AA10: =IFERROR(N10/$I10*$G10,0) -> 8261.8182 | AB10: =IFERROR(O10/$I10*$G10,0) -> 0 | AC10: =IFERROR(P10/$I10*$G10,0) -> 0 | AD10: =IFERROR(Q10/$I10*$G10,0) -> 0 | AE10: =IFERROR(R10/$I10*$G10,0) -> 0 | ... AI10: =IFERROR(V10/$I10*$G10,0) -> 0 | AJ10: =SUM(X10:AI10) -> 12800 | AK10: =AJ10-G10 -> 0
A11: 7 | B11: Іскрицький Денис Русланович | D11: 1869.98 | E11: =I11*J11 -> 14100 | F11: =SUMIF('[1]Табель цех 1 по 15 серпня'!$B:$B,B11,'[1]Табель цех 1 по 15 серпня'!$H:$H) -> -13.26 | G11: =ROUND(E11-C11-D11,-2) -> 12200 | H11: =F11+E11-D11-G11-C11 -> 16.76 | I11: =Цо!AI8+IRS!S8+Катеринополь!S8+'Червоний хрест'!S8+'ООН 2025'!S8+Кернел!S8+'Глобино Мк'!S8+'МД Франківськ'!S8 -> 94 | J11: 150 | K11: =SUMIF(ИТР!B:B,B11,ИТР!S:S) -> 0 | L11: =SUMIF(Цо!R:R,B11,Цо!AI:AI) -> 0 | M11: =SUMIF(IRS!B:B,B11,IRS!S:S) -> 0 | N11: =SUMIF(Катеринополь!B:B,B11,Катеринополь!S:S) -> 22 | Q11: =SUMIF('ООН 2025'!B:B,B11,'ООН 2025'!S:S) -> 0 | R11: =SUMIF('Червоний хрест'!B:B,B11,'Червоний хрест'!S:S) -> 72 | T11: =SUMIF(Кернел!B:B,B11,Кернел!S:S) -> 0 | U11: =SUMIF('Глобино Мк'!B:B,B11,'Глобино Мк'!S:S) -> 0 | V11: =SUMIF('МД Франківськ'!B:B,B11,'МД Франківськ'!S:S) -> 0 | W11: =SUM(K11:V11)-I11 -> 0 | X11: =IFERROR(K11/$I11*$G11,0) -> 0 | Y11: =IFERROR(L11/$I11*$G11,0) -> 0 | Z11: =IFERROR(M11/$I11*$G11,0) -> 0 | AA11: =IFERROR(N11/$I11*$G11,0) -> 2855.3191 | AB11: =IFERROR(O11/$I11*$G11,0) -> 0 | AC11: =IFERROR(P11/$I11*$G11,0) -> 0 | AD11: =IFERROR(Q11/$I11*$G11,0) -> 0 | AE11: =IFERROR(R11/$I11*$G11,0) -> 9344.6809 | ... AI11: =IFERROR(V11/$I11*$G11,0) -> 0 | AJ11: =SUM(X11:AI11) -> 12200 | AK11: =AJ11-G11 -> 0
A12: 8 | B12: Корнієнко Станіслав Володимирович | C12: 9162.5 | D12: 3739.99 | E12: =I12*J12 -> 54000 | F12: =SUMIF('[1]Табель цех 1 по 15 серпня'!$B:$B,B12,'[1]Табель цех 1 по 15 серпня'!$H:$H) -> -37.97 | G12: =ROUND(E12-C12-D12,-2) -> 41100 | H12: =F12+E12-D12-G12-C12 -> -40.46 | I12: =Цо!AI9+IRS!S9+Катеринополь!S9+'Червоний хрест'!S9+'ООН 2025'!S9+Кернел!S9+'Глобино Мк'!S9+'МД Франківськ'!S9 -> 360 | J12: 150 | K12: =SUMIF(ИТР!B:B,B12,ИТР!S:S) -> 0 | L12: =SUMIF(Цо!R:R,B12,Цо!AI:AI) -> 0 | M12: =SUMIF(IRS!B:B,B12,IRS!S:S) -> 0 | N12: =SUMIF(Катеринополь!B:B,B12,Катеринополь!S:S) -> 0 | Q12: =SUMIF('ООН 2025'!B:B,B12,'ООН 2025'!S:S) -> 0 | R12: =SUMIF('Червоний хрест'!B:B,B12,'Червоний хрест'!S:S) -> 0 | T12: =SUMIF(Кернел!B:B,B12,Кернел!S:S) -> 360 | U12: =SUMIF('Глобино Мк'!B:B,B12,'Глобино Мк'!S:S) -> 0 | V12: =SUMIF('МД Франківськ'!B:B,B12,'МД Франківськ'!S:S) -> 0 | W12: =SUM(K12:V12)-I12 -> 0 | X12: =IFERROR(K12/$I12*$G12,0) -> 0 | Y12: =IFERROR(L12/$I12*$G12,0) -> 0 | Z12: =IFERROR(M12/$I12*$G12,0) -> 0 | AA12: =IFERROR(N12/$I12*$G12,0) -> 0 | AB12: =IFERROR(O12/$I12*$G12,0) -> 0 | AC12: =IFERROR(P12/$I12*$G12,0) -> 0 | AD12: =IFERROR(Q12/$I12*$G12,0) -> 0 | AE12: =IFERROR(R12/$I12*$G12,0) -> 0 | ... AI12: =IFERROR(V12/$I12*$G12,0) -> 0 | AJ12: =SUM(X12:AI12) -> 41100 | AK12: =AJ12-G12 -> 0
A13: 9 | B13: Масливець Ігор Валерійович | D13: 3739.99 | E13: =I13*J13 -> 19200 | F13: =SUMIF('[1]Табель цех 1 по 15 серпня'!$B:$B,B13,'[1]Табель цех 1 по 15 серпня'!$H:$H) -> 51.94 | G13: =ROUND(E13-C13-D13,-2) -> 15500 | H13: =F13+E13-D13-G13-C13 -> 11.95 | I13: =Цо!AI10+IRS!S10+Катеринополь!S10+'Червоний хрест'!S10+'ООН 2025'!S10+Кернел!S10+'Глобино Мк'!S10+'МД Франківськ'!S10 -> 128 | J13: 150 | K13: =SUMIF(ИТР!B:B,B13,ИТР!S:S) -> 0 | L13: =SUMIF(Цо!R:R,B13,Цо!AI:AI) -> 0 | M13: =SUMIF(IRS!B:B,B13,IRS!S:S) -> 0 | N13: =SUMIF(Катеринополь!B:B,B13,Катеринополь!S:S) -> 0 | Q13: =SUMIF('ООН 2025'!B:B,B13,'ООН 2025'!S:S) -> 128 | R13: =SUMIF('Червоний хрест'!B:B,B13,'Червоний хрест'!S:S) -> 0 | T13: =SUMIF(Кернел!B:B,B13,Кернел!S:S) -> 0 | U13: =SUMIF('Глобино Мк'!B:B,B13,'Глобино Мк'!S:S) -> 0 | V13: =SUMIF('МД Франківськ'!B:B,B13,'МД Франківськ'!S:S) -> 0 | W13: =SUM(K13:V13)-I13 -> 0 | X13: =IFERROR(K13/$I13*$G13,0) -> 0 | Y13: =IFERROR(L13/$I13*$G13,0) -> 0 | Z13: =IFERROR(M13/$I13*$G13,0) -> 0 | AA13: =IFERROR(N13/$I13*$G13,0) -> 0 | AB13: =IFERROR(O13/$I13*$G13,0) -> 0 | AC13: =IFERROR(P13/$I13*$G13,0) -> 0 | AD13: =IFERROR(Q13/$I13*$G13,0) -> 15500 | AE13: =IFERROR(R13/$I13*$G13,0) -> 0 | ... AI13: =IFERROR(V13/$I13*$G13,0) -> 0 | AJ13: =SUM(X13:AI13) -> 15500 | AK13: =AJ13-G13 -> 0
A14: 10 | B14: Скрипник Олександр Павлович | D14: 3739.99 | E14: =I14*J14 -> 16500 | F14: =SUMIF('[1]Табель цех 1 по 15 серпня'!$B:$B,B14,'[1]Табель цех 1 по 15 серпня'!$H:$H) -> -8.01 | G14: =ROUND(E14-C14-D14,-2) -> 12800 | H14: =F14+E14-D14-G14-C14 -> -48 | I14: =Цо!AI11+IRS!S11+Катеринополь!S11+'Червоний хрест'!S11+'ООН 2025'!S11+Кернел!S11+'Глобино Мк'!S11+'МД Франківськ'!S11 -> 110 | J14: 150 | K14: =SUMIF(ИТР!B:B,B14,ИТР!S:S) -> 0 | L14: =SUMIF(Цо!R:R,B14,Цо!AI:AI) -> 0 | M14: =SUMIF(IRS!B:B,B14,IRS!S:S) -> 0 | N14: =SUMIF(Катеринополь!B:B,B14,Катеринополь!S:S) -> 0 | Q14: =SUMIF('ООН 2025'!B:B,B14,'ООН 2025'!S:S) -> 110 | R14: =SUMIF('Червоний хрест'!B:B,B14,'Червоний хрест'!S:S) -> 0 | T14: =SUMIF(Кернел!B:B,B14,Кернел!S:S) -> 0 | U14: =SUMIF('Глобино Мк'!B:B,B14,'Глобино Мк'!S:S) -> 0 | V14: =SUMIF('МД Франківськ'!B:B,B14,'МД Франківськ'!S:S) -> 0 | W14: =SUM(K14:V14)-I14 -> 0 | X14: =IFERROR(K14/$I14*$G14,0) -> 0 | Y14: =IFERROR(L14/$I14*$G14,0) -> 0 | Z14: =IFERROR(M14/$I14*$G14,0) -> 0 | AA14: =IFERROR(N14/$I14*$G14,0) -> 0 | AB14: =IFERROR(O14/$I14*$G14,0) -> 0 | AC14: =IFERROR(P14/$I14*$G14,0) -> 0 | AD14: =IFERROR(Q14/$I14*$G14,0) -> 12800 | AE14: =IFERROR(R14/$I14*$G14,0) -> 0 | ... AI14: =IFERROR(V14/$I14*$G14,0) -> 0 | AJ14: =SUM(X14:AI14) -> 12800 | AK14: =AJ14-G14 -> 0
A15: 11 | B15: Паламарчук Вячеслав Володимирович | D15: 3740.01 | E15: =I15*J15 -> 18300 | F15: =SUMIF('[1]Табель цех 1 по 15 серпня'!$B:$B,B15,'[1]Табель цех 1 по 15 серпня'!$H:$H) -> -69.62 | G15: =ROUND(E15-C15-D15,-2) -> 14600 | H15: =F15+E15-D15-G15-C15 -> -109.63 | I15: =Цо!AI12+IRS!S12+Катеринополь!S12+'Червоний хрест'!S12+'ООН 2025'!S12+Кернел!S12+'Глобино Мк'!S12+'МД Франківськ'!S12 -> 122 | J15: 150 | K15: =SUMIF(ИТР!B:B,B15,ИТР!S:S) -> 0 | L15: =SUMIF(Цо!R:R,B15,Цо!AI:AI) -> 0 | M15: =SUMIF(IRS!B:B,B15,IRS!S:S) -> 0 | N15: =SUMIF(Катеринополь!B:B,B15,Катеринополь!S:S) -> 0 | Q15: =SUMIF('ООН 2025'!B:B,B15,'ООН 2025'!S:S) -> 122 | R15: =SUMIF('Червоний хрест'!B:B,B15,'Червоний хрест'!S:S) -> 0 | T15: =SUMIF(Кернел!B:B,B15,Кернел!S:S) -> 0 | U15: =SUMIF('Глобино Мк'!B:B,B15,'Глобино Мк'!S:S) -> 0 | V15: =SUMIF('МД Франківськ'!B:B,B15,'МД Франківськ'!S:S) -> 0 | W15: =SUM(K15:V15)-I15 -> 0 | X15: =IFERROR(K15/$I15*$G15,0) -> 0 | Y15: =IFERROR(L15/$I15*$G15,0) -> 0 | Z15: =IFERROR(M15/$I15*$G15,0) -> 0 | AA15: =IFERROR(N15/$I15*$G15,0) -> 0 | AB15: =IFERROR(O15/$I15*$G15,0) -> 0 | AC15: =IFERROR(P15/$I15*$G15,0) -> 0 | AD15: =IFERROR(Q15/$I15*$G15,0) -> 14600 | AE15: =IFERROR(R15/$I15*$G15,0) -> 0 | ... AI15: =IFERROR(V15/$I15*$G15,0) -> 0 | AJ15: =SUM(X15:AI15) -> 14600 | AK15: =AJ15-G15 -> 0
A16: 12 | B16: Дехтяр Владислав Олександрович | C16: 9162.5 | D16: 3739.99 | E16: =I16*J16 -> 50400 | F16: =SUMIF('[1]Табель цех 1 по 15 серпня'!$B:$B,B16,'[1]Табель цех 1 по 15 серпня'!$H:$H) -> 8.22 | G16: =ROUND(E16-C16-D16,-2) -> 37500 | H16: =F16+E16-D16-G16-C16 -> 5.73 | I16: =Цо!AI13+IRS!S13+Катеринополь!S13+'Червоний хрест'!S13+'ООН 2025'!S13+Кернел!S13+'Глобино Мк'!S13+'МД Франківськ'!S13 -> 336 | J16: 150 | K16: =SUMIF(ИТР!B:B,B16,ИТР!S:S) -> 0 | L16: =SUMIF(Цо!R:R,B16,Цо!AI:AI) -> 0 | M16: =SUMIF(IRS!B:B,B16,IRS!S:S) -> 0 | N16: =SUMIF(Катеринополь!B:B,B16,Катеринополь!S:S) -> 0 | Q16: =SUMIF('ООН 2025'!B:B,B16,'ООН 2025'!S:S) -> 0 | R16: =SUMIF('Червоний хрест'!B:B,B16,'Червоний хрест'!S:S) -> 0 | T16: =SUMIF(Кернел!B:B,B16,Кернел!S:S) -> 336 | U16: =SUMIF('Глобино Мк'!B:B,B16,'Глобино Мк'!S:S) -> 0 | V16: =SUMIF('МД Франківськ'!B:B,B16,'МД Франківськ'!S:S) -> 0 | W16: =SUM(K16:V16)-I16 -> 0 | X16: =IFERROR(K16/$I16*$G16,0) -> 0 | Y16: =IFERROR(L16/$I16*$G16,0) -> 0 | Z16: =IFERROR(M16/$I16*$G16,0) -> 0 | AA16: =IFERROR(N16/$I16*$G16,0) -> 0 | AB16: =IFERROR(O16/$I16*$G16,0) -> 0 | AC16: =IFERROR(P16/$I16*$G16,0) -> 0 | AD16: =IFERROR(Q16/$I16*$G16,0) -> 0 | AE16: =IFERROR(R16/$I16*$G16,0) -> 0 | ... AI16: =IFERROR(V16/$I16*$G16,0) -> 0 | AJ16: =SUM(X16:AI16) -> 37500 | AK16: =AJ16-G16 -> 0
A17: 13 | B17: Тужиков Валерій Владиславович | D17: 3739.99 | E17: =I17*J17 -> 17850 | F17: =SUMIF('[1]Табель цех 1 по 15 серпня'!$B:$B,B17,'[1]Табель цех 1 по 15 серпня'!$H:$H) -> 31.74 | G17: =ROUND(E17-C17-D17,-2) -> 14100 | H17: =F17+E17-D17-G17-C17 -> 41.75 | I17: =Цо!AI14+IRS!S14+Катеринополь!S14+'Червоний хрест'!S14+'ООН 2025'!S14+Кернел!S14+'Глобино Мк'!S14+'МД Франківськ'!S14 -> 119 | J17: 150 | K17: =SUMIF(ИТР!B:B,B17,ИТР!S:S) -> 0 | L17: =SUMIF(Цо!R:R,B17,Цо!AI:AI) -> 0 | M17: =SUMIF(IRS!B:B,B17,IRS!S:S) -> 0 | N17: =SUMIF(Катеринополь!B:B,B17,Катеринополь!S:S) -> 55 | Q17: =SUMIF('ООН 2025'!B:B,B17,'ООН 2025'!S:S) -> 0 | R17: =SUMIF('Червоний хрест'!B:B,B17,'Червоний хрест'!S:S) -> 0 | T17: =SUMIF(Кернел!B:B,B17,Кернел!S:S) -> 0 | U17: =SUMIF('Глобино Мк'!B:B,B17,'Глобино Мк'!S:S) -> 28 | V17: =SUMIF('МД Франківськ'!B:B,B17,'МД Франківськ'!S:S) -> 36 | W17: =SUM(K17:V17)-I17 -> 0 | X17: =IFERROR(K17/$I17*$G17,0) -> 0 | Y17: =IFERROR(L17/$I17*$G17,0) -> 0 | Z17: =IFERROR(M17/$I17*$G17,0) -> 0 | AA17: =IFERROR(N17/$I17*$G17,0) -> 6516.8067 | AB17: =IFERROR(O17/$I17*$G17,0) -> 0 | AC17: =IFERROR(P17/$I17*$G17,0) -> 0 | AD17: =IFERROR(Q17/$I17*$G17,0) -> 0 | AE17: =IFERROR(R17/$I17*$G17,0) -> 0 | ... AI17: =IFERROR(V17/$I17*$G17,0) -> 4265.5462 | AJ17: =SUM(X17:AI17) -> 14100 | AK17: =AJ17-G17 -> 0
A18: 14 | B18: Сівов Євген Миколайович | D18: 3739.99 | E18: =I18*J18 -> 18300 | F18: =SUMIF('[1]Табель цех 1 по 15 серпня'!$B:$B,B18,'[1]Табель цех 1 по 15 серпня'!$H:$H) -> 4.76 | G18: =ROUND(E18-C18-D18,-2) -> 14600 | H18: =F18+E18-D18-G18-C18 -> -35.23 | I18: =Цо!AI15+IRS!S15+Катеринополь!S15+'Червоний хрест'!S15+'ООН 2025'!S15+Кернел!S15+'Глобино Мк'!S15+'МД Франківськ'!S15 -> 122 | J18: 150 | K18: =SUMIF(ИТР!B:B,B18,ИТР!S:S) -> 0 | L18: =SUMIF(Цо!R:R,B18,Цо!AI:AI) -> 0 | M18: =SUMIF(IRS!B:B,B18,IRS!S:S) -> 0 | N18: =SUMIF(Катеринополь!B:B,B18,Катеринополь!S:S) -> 78 | Q18: =SUMIF('ООН 2025'!B:B,B18,'ООН 2025'!S:S) -> 0 | R18: =SUMIF('Червоний хрест'!B:B,B18,'Червоний хрест'!S:S) -> 0 | T18: =SUMIF(Кернел!B:B,B18,Кернел!S:S) -> 0 | U18: =SUMIF('Глобино Мк'!B:B,B18,'Глобино Мк'!S:S) -> 44 | V18: =SUMIF('МД Франківськ'!B:B,B18,'МД Франківськ'!S:S) -> 0 | W18: =SUM(K18:V18)-I18 -> 0 | X18: =IFERROR(K18/$I18*$G18,0) -> 0 | Y18: =IFERROR(L18/$I18*$G18,0) -> 0 | Z18: =IFERROR(M18/$I18*$G18,0) -> 0 | AA18: =IFERROR(N18/$I18*$G18,0) -> 9334.4262 | AB18: =IFERROR(O18/$I18*$G18,0) -> 0 | AC18: =IFERROR(P18/$I18*$G18,0) -> 0 | AD18: =IFERROR(Q18/$I18*$G18,0) -> 0 | AE18: =IFERROR(R18/$I18*$G18,0) -> 0 | ... AI18: =IFERROR(V18/$I18*$G18,0) -> 0 | AJ18: =SUM(X18:AI18) -> 14600 | AK18: =AJ18-G18 -> 0
A19: 15 | B19: Кіфор Юрій Михайлович | D19: 3739.99 | E19: =I19*J19 -> 19200 | F19: =SUMIF('[1]Табель цех 1 по 15 серпня'!$B:$B,B19,'[1]Табель цех 1 по 15 серпня'!$H:$H) -> 1.49 | G19: =ROUND(E19-C19-D19,-2) -> 15500 | H19: =F19+E19-D19-G19-C19 -> -38.5 | I19: =Цо!AI16+IRS!S16+Катеринополь!S16+'Червоний хрест'!S16+'ООН 2025'!S16+Кернел!S16+'Глобино Мк'!S16+'МД Франківськ'!S16 -> 128 | J19: 150 | K19: =SUMIF(ИТР!B:B,B19,ИТР!S:S) -> 0 | L19: =SUMIF(Цо!R:R,B19,Цо!AI:AI) -> 0 | M19: =SUMIF(IRS!B:B,B19,IRS!S:S) -> 0 | N19: =SUMIF(Катеринополь!B:B,B19,Катеринополь!S:S) -> 0 | Q19: =SUMIF('ООН 2025'!B:B,B19,'ООН 2025'!S:S) -> 128 | R19: =SUMIF('Червоний хрест'!B:B,B19,'Червоний хрест'!S:S) -> 0 | T19: =SUMIF(Кернел!B:B,B19,Кернел!S:S) -> 0 | U19: =SUMIF('Глобино Мк'!B:B,B19,'Глобино Мк'!S:S) -> 0 | V19: =SUMIF('МД Франківськ'!B:B,B19,'МД Франківськ'!S:S) -> 0 | W19: =SUM(K19:V19)-I19 -> 0 | X19: =IFERROR(K19/$I19*$G19,0) -> 0 | Y19: =IFERROR(L19/$I19*$G19,0) -> 0 | Z19: =IFERROR(M19/$I19*$G19,0) -> 0 | AA19: =IFERROR(N19/$I19*$G19,0) -> 0 | AB19: =IFERROR(O19/$I19*$G19,0) -> 0 | AC19: =IFERROR(P19/$I19*$G19,0) -> 0 | AD19: =IFERROR(Q19/$I19*$G19,0) -> 15500 | AE19: =IFERROR(R19/$I19*$G19,0) -> 0 | ... AI19: =IFERROR(V19/$I19*$G19,0) -> 0 | AJ19: =SUM(X19:AI19) -> 15500 | AK19: =AJ19-G19 -> 0
A20: 16 | B20: Нестерук Сергій Петрович | E20: =I20*J20 -> 0 | F20: =SUMIF('[1]Табель цех 1 по 15 серпня'!$B:$B,B20,'[1]Табель цех 1 по 15 серпня'!$H:$H) -> 38.04 | G20: =ROUND(E20-C20-D20,-2) -> 0 | H20: =F20+E20-D20-G20-C20 -> 38.04 | I20: =Цо!AI17+IRS!S17+Катеринополь!S17+'Червоний хрест'!S17+'ООН 2025'!S17+Кернел!S17+'Глобино Мк'!S17+'МД Франківськ'!S17 -> 0 | J20: 150 | K20: =SUMIF(ИТР!B:B,B20,ИТР!S:S) -> 0 | L20: =SUMIF(Цо!R:R,B20,Цо!AI:AI) -> 0 | M20: =SUMIF(IRS!B:B,B20,IRS!S:S) -> 0 | N20: =SUMIF(Катеринополь!B:B,B20,Катеринополь!S:S) -> 0 | Q20: =SUMIF('ООН 2025'!B:B,B20,'ООН 2025'!S:S) -> 0 | R20: =SUMIF('Червоний хрест'!B:B,B20,'Червоний хрест'!S:S) -> 0 | T20: =SUMIF(Кернел!B:B,B20,Кернел!S:S) -> 0 | U20: =SUMIF('Глобино Мк'!B:B,B20,'Глобино Мк'!S:S) -> 0 | V20: =SUMIF('МД Франківськ'!B:B,B20,'МД Франківськ'!S:S) -> 0 | W20: =SUM(K20:V20)-I20 -> 0 | X20: =IFERROR(K20/$I20*$G20,0) -> 0 | Y20: =IFERROR(L20/$I20*$G20,0) -> 0 | Z20: =IFERROR(M20/$I20*$G20,0) -> 0 | AA20: =IFERROR(N20/$I20*$G20,0) -> 0 | AB20: =IFERROR(O20/$I20*$G20,0) -> 0 | AC20: =IFERROR(P20/$I20*$G20,0) -> 0 | AD20: =IFERROR(Q20/$I20*$G20,0) -> 0 | AE20: =IFERROR(R20/$I20*$G20,0) -> 0 | ... AI20: =IFERROR(V20/$I20*$G20,0) -> 0 | AJ20: =SUM(X20:AI20) -> 0 | AK20: =AJ20-G20 -> 0
A21: 17 | B21: Петренко Микола Григорович | D21: 9350.01 | E21: =I21*J21 -> 26550 | F21: =SUMIF('[1]Табель цех 1 по 15 серпня'!$B:$B,B21,'[1]Табель цех 1 по 15 серпня'!$H:$H) -> -66.48 | G21: =ROUND(E21-C21-D21,-2) -> 17200 | H21: =F21+E21-D21-G21-C21 -> -66.49 | I21: =Цо!AI18+IRS!S18+Катеринополь!S18+'Червоний хрест'!S18+'ООН 2025'!S18+Кернел!S18+'Глобино Мк'!S18+'МД Франківськ'!S18 -> 177 | J21: 150 | K21: =SUMIF(ИТР!B:B,B21,ИТР!S:S) -> 0 | L21: =SUMIF(Цо!R:R,B21,Цо!AI:AI) -> 0 | M21: =SUMIF(IRS!B:B,B21,IRS!S:S) -> 0 | N21: =SUMIF(Катеринополь!B:B,B21,Катеринополь!S:S) -> 0 | Q21: =SUMIF('ООН 2025'!B:B,B21,'ООН 2025'!S:S) -> 57 | R21: =SUMIF('Червоний хрест'!B:B,B21,'Червоний хрест'!S:S) -> 0 | T21: =SUMIF(Кернел!B:B,B21,Кернел!S:S) -> 0 | U21: =SUMIF('Глобино Мк'!B:B,B21,'Глобино Мк'!S:S) -> 0 | V21: =SUMIF('МД Франківськ'!B:B,B21,'МД Франківськ'!S:S) -> 120 | W21: =SUM(K21:V21)-I21 -> 0 | X21: =IFERROR(K21/$I21*$G21,0) -> 0 | Y21: =IFERROR(L21/$I21*$G21,0) -> 0 | Z21: =IFERROR(M21/$I21*$G21,0) -> 0 | AA21: =IFERROR(N21/$I21*$G21,0) -> 0 | AB21: =IFERROR(O21/$I21*$G21,0) -> 0 | AC21: =IFERROR(P21/$I21*$G21,0) -> 0 | AD21: =IFERROR(Q21/$I21*$G21,0) -> 5538.9831 | AE21: =IFERROR(R21/$I21*$G21,0) -> 0 | ... AI21: =IFERROR(V21/$I21*$G21,0) -> 11661.017 | AJ21: =SUM(X21:AI21) -> 17200 | AK21: =AJ21-G21 -> 0
A22: 18 | B22: Рубленко Микола Іванович | D22: 3739.99 | E22: =I22*J22 -> 16500 | F22: =SUMIF('[1]Табель цех 1 по 15 серпня'!$B:$B,B22,'[1]Табель цех 1 по 15 серпня'!$H:$H) -> -48.51 | G22: =ROUND(E22-C22-D22,-2) -> 12800 | H22: =F22+E22-D22-G22-C22 -> -88.5 | I22: =Цо!AI19+IRS!S19+Катеринополь!S19+'Червоний хрест'!S19+'ООН 2025'!S19+Кернел!S19+'Глобино Мк'!S19+'МД Франківськ'!S19 -> 110 | J22: 150 | K22: =SUMIF(ИТР!B:B,B22,ИТР!S:S) -> 0 | L22: =SUMIF(Цо!R:R,B22,Цо!AI:AI) -> 0 | M22: =SUMIF(IRS!B:B,B22,IRS!S:S) -> 0 | N22: =SUMIF(Катеринополь!B:B,B22,Катеринополь!S:S) -> 0 | Q22: =SUMIF('ООН 2025'!B:B,B22,'ООН 2025'!S:S) -> 110 | R22: =SUMIF('Червоний хрест'!B:B,B22,'Червоний хрест'!S:S) -> 0 | T22: =SUMIF(Кернел!B:B,B22,Кернел!S:S) -> 0 | U22: =SUMIF('Глобино Мк'!B:B,B22,'Глобино Мк'!S:S) -> 0 | V22: =SUMIF('МД Франківськ'!B:B,B22,'МД Франківськ'!S:S) -> 0 | W22: =SUM(K22:V22)-I22 -> 0 | X22: =IFERROR(K22/$I22*$G22,0) -> 0 | Y22: =IFERROR(L22/$I22*$G22,0) -> 0 | Z22: =IFERROR(M22/$I22*$G22,0) -> 0 | AA22: =IFERROR(N22/$I22*$G22,0) -> 0 | AB22: =IFERROR(O22/$I22*$G22,0) -> 0 | AC22: =IFERROR(P22/$I22*$G22,0) -> 0 | AD22: =IFERROR(Q22/$I22*$G22,0) -> 12800 | AE22: =IFERROR(R22/$I22*$G22,0) -> 0 | ... AI22: =IFERROR(V22/$I22*$G22,0) -> 0 | AJ22: =SUM(X22:AI22) -> 12800 | AK22: =AJ22-G22 -> 0
A23: 19 | B23: Серебренніков Володимир Олександрович | E23: =I23*J23 -> 2550 | F23: =SUMIF('[1]Табель цех 1 по 15 серпня'!$B:$B,B23,'[1]Табель цех 1 по 15 серпня'!$H:$H) -> 87.52 | G23: =ROUND(E23-C23-D23,-2) -> 2600 | H23: =F23+E23-D23-G23-C23 -> 37.52 | I23: =Цо!AI20+IRS!S20+Катеринополь!S20+'Червоний хрест'!S20+'ООН 2025'!S20+Кернел!S20+'Глобино Мк'!S20+'МД Франківськ'!S20 -> 17 | J23: 150 | K23: =SUMIF(ИТР!B:B,B23,ИТР!S:S) -> 0 | L23: =SUMIF(Цо!R:R,B23,Цо!AI:AI) -> 0 | M23: =SUMIF(IRS!B:B,B23,IRS!S:S) -> 0 | N23: =SUMIF(Катеринополь!B:B,B23,Катеринополь!S:S) -> 0 | Q23: =SUMIF('ООН 2025'!B:B,B23,'ООН 2025'!S:S) -> 17 | R23: =SUMIF('Червоний хрест'!B:B,B23,'Червоний хрест'!S:S) -> 0 | T23: =SUMIF(Кернел!B:B,B23,Кернел!S:S) -> 0 | U23: =SUMIF('Глобино Мк'!B:B,B23,'Глобино Мк'!S:S) -> 0 | V23: =SUMIF('МД Франківськ'!B:B,B23,'МД Франківськ'!S:S) -> 0 | W23: =SUM(K23:V23)-I23 -> 0 | X23: =IFERROR(K23/$I23*$G23,0) -> 0 | Y23: =IFERROR(L23/$I23*$G23,0) -> 0 | Z23: =IFERROR(M23/$I23*$G23,0) -> 0 | AA23: =IFERROR(N23/$I23*$G23,0) -> 0 | AB23: =IFERROR(O23/$I23*$G23,0) -> 0 | AC23: =IFERROR(P23/$I23*$G23,0) -> 0 | AD23: =IFERROR(Q23/$I23*$G23,0) -> 2600 | AE23: =IFERROR(R23/$I23*$G23,0) -> 0 | ... AI23: =IFERROR(V23/$I23*$G23,0) -> 0 | AJ23: =SUM(X23:AI23) -> 2600 | AK23: =AJ23-G23 -> 0
A24: 20 | B24: Чешко Сергій Анатолійович | D24: 8286.67 | E24: =I24*J24 -> 50400 | F24: =SUMIF('[1]Табель цех 1 по 15 серпня'!$B:$B,B24,'[1]Табель цех 1 по 15 серпня'!$H:$H) -> 39.83 | G24: =ROUND(E24-C24-D24,-2) -> 42100 | H24: =F24+E24-D24-G24-C24 -> 53.16 | I24: =Цо!AI21+IRS!S21+Катеринополь!S21+'Червоний хрест'!S21+'ООН 2025'!S21+Кернел!S21+'Глобино Мк'!S21+'МД Франківськ'!S21 -> 336 | J24: 150 | K24: =SUMIF(ИТР!B:B,B24,ИТР!S:S) -> 0 | L24: =SUMIF(Цо!R:R,B24,Цо!AI:AI) -> 0 | M24: =SUMIF(IRS!B:B,B24,IRS!S:S) -> 336 | N24: =SUMIF(Катеринополь!B:B,B24,Катеринополь!S:S) -> 0 | Q24: =SUMIF('ООН 2025'!B:B,B24,'ООН 2025'!S:S) -> 0 | R24: =SUMIF('Червоний хрест'!B:B,B24,'Червоний хрест'!S:S) -> 0 | T24: =SUMIF(Кернел!B:B,B24,Кернел!S:S) -> 0 | U24: =SUMIF('Глобино Мк'!B:B,B24,'Глобино Мк'!S:S) -> 0 | V24: =SUMIF('МД Франківськ'!B:B,B24,'МД Франківськ'!S:S) -> 0 | W24: =SUM(K24:V24)-I24 -> 0 | X24: =IFERROR(K24/$I24*$G24,0) -> 0 | Y24: =IFERROR(L24/$I24*$G24,0) -> 0 | Z24: =IFERROR(M24/$I24*$G24,0) -> 42100 | AA24: =IFERROR(N24/$I24*$G24,0) -> 0 | AB24: =IFERROR(O24/$I24*$G24,0) -> 0 | AC24: =IFERROR(P24/$I24*$G24,0) -> 0 | AD24: =IFERROR(Q24/$I24*$G24,0) -> 0 | AE24: =IFERROR(R24/$I24*$G24,0) -> 0 | ... AI24: =IFERROR(V24/$I24*$G24,0) -> 0 | AJ24: =SUM(X24:AI24) -> 42100 | AK24: =AJ24-G24 -> 0
A25: 21 | B25: Нерезенко Євгеній Віктоорович | D25: 3739.99 | E25: =I25*J25 -> 50400 | F25: =SUMIF('[1]Табель цех 1 по 15 серпня'!$B:$B,B25,'[1]Табель цех 1 по 15 серпня'!$H:$H) -> -14.01 | G25: =ROUND(E25-C25-D25,-2) -> 46700 | H25: =F25+E25-D25-G25-C25 -> -54 | I25: =Цо!AI22+IRS!S22+Катеринополь!S22+'Червоний хрест'!S22+'ООН 2025'!S22+Кернел!S22+'Глобино Мк'!S22+'МД Франківськ'!S22 -> 336 | J25: 150 | K25: =SUMIF(ИТР!B:B,B25,ИТР!S:S) -> 0 | L25: =SUMIF(Цо!R:R,B25,Цо!AI:AI) -> 0 | M25: =SUMIF(IRS!B:B,B25,IRS!S:S) -> 336 | N25: =SUMIF(Катеринополь!B:B,B25,Катеринополь!S:S) -> 0 | Q25: =SUMIF('ООН 2025'!B:B,B25,'ООН 2025'!S:S) -> 0 | R25: =SUMIF('Червоний хрест'!B:B,B25,'Червоний хрест'!S:S) -> 0 | T25: =SUMIF(Кернел!B:B,B25,Кернел!S:S) -> 0 | U25: =SUMIF('Глобино Мк'!B:B,B25,'Глобино Мк'!S:S) -> 0 | V25: =SUMIF('МД Франківськ'!B:B,B25,'МД Франківськ'!S:S) -> 0 | W25: =SUM(K25:V25)-I25 -> 0 | X25: =IFERROR(K25/$I25*$G25,0) -> 0 | Y25: =IFERROR(L25/$I25*$G25,0) -> 0 | Z25: =IFERROR(M25/$I25*$G25,0) -> 46700 | AA25: =IFERROR(N25/$I25*$G25,0) -> 0 | AB25: =IFERROR(O25/$I25*$G25,0) -> 0 | AC25: =IFERROR(P25/$I25*$G25,0) -> 0 | AD25: =IFERROR(Q25/$I25*$G25,0) -> 0 | AE25: =IFERROR(R25/$I25*$G25,0) -> 0 | ... AI25: =IFERROR(V25/$I25*$G25,0) -> 0 | AJ25: =SUM(X25:AI25) -> 46700 | AK25: =AJ25-G25 -> 0
A26: 22 | B26: Шавкун Максим Анатолійович | D26: 9350.01 | E26: =I26*J26 -> 50400 | F26: =SUMIF('[1]Табель цех 1 по 15 серпня'!$B:$B,B26,'[1]Табель цех 1 по 15 серпня'!$H:$H) -> -99.25 | G26: =ROUND(E26-C26-D26,-2) -> 41000 | H26: =F26+E26-D26-G26-C26 -> -49.26 | I26: =Цо!AI23+IRS!S23+Катеринополь!S23+'Червоний хрест'!S23+'ООН 2025'!S23+Кернел!S23+'Глобино Мк'!S23+'МД Франківськ'!S23 -> 336 | J26: 150 | K26: =SUMIF(ИТР!B:B,B26,ИТР!S:S) -> 0 | L26: =SUMIF(Цо!R:R,B26,Цо!AI:AI) -> 0 | M26: =SUMIF(IRS!B:B,B26,IRS!S:S) -> 336 | N26: =SUMIF(Катеринополь!B:B,B26,Катеринополь!S:S) -> 0 | Q26: =SUMIF('ООН 2025'!B:B,B26,'ООН 2025'!S:S) -> 0 | R26: =SUMIF('Червоний хрест'!B:B,B26,'Червоний хрест'!S:S) -> 0 | T26: =SUMIF(Кернел!B:B,B26,Кернел!S:S) -> 0 | U26: =SUMIF('Глобино Мк'!B:B,B26,'Глобино Мк'!S:S) -> 0 | V26: =SUMIF('МД Франківськ'!B:B,B26,'МД Франківськ'!S:S) -> 0 | W26: =SUM(K26:V26)-I26 -> 0 | X26: =IFERROR(K26/$I26*$G26,0) -> 0 | Y26: =IFERROR(L26/$I26*$G26,0) -> 0 | Z26: =IFERROR(M26/$I26*$G26,0) -> 41000 | AA26: =IFERROR(N26/$I26*$G26,0) -> 0 | AB26: =IFERROR(O26/$I26*$G26,0) -> 0 | AC26: =IFERROR(P26/$I26*$G26,0) -> 0 | AD26: =IFERROR(Q26/$I26*$G26,0) -> 0 | AE26: =IFERROR(R26/$I26*$G26,0) -> 0 | ... AI26: =IFERROR(V26/$I26*$G26,0) -> 0 | AJ26: =SUM(X26:AI26) -> 41000 | AK26: =AJ26-G26 -> 0
A27: 23 | B27: Чуйко Олег Олегович | D27: 3739.99 | E27: =I27*J27 -> 18900 | F27: =SUMIF('[1]Табель цех 1 по 15 серпня'!$B:$B,B27,'[1]Табель цех 1 по 15 серпня'!$H:$H) -> 1.99 | G27: =ROUND(E27-C27-D27,-2) -> 15200 | H27: =F27+E27-D27-G27-C27 -> -38 | I27: =Цо!AI24+IRS!S24+Катеринополь!S24+'Червоний хрест'!S24+'ООН 2025'!S24+Кернел!S24+'Глобино Мк'!S24+'МД Франківськ'!S24 -> 126 | J27: 150 | K27: =SUMIF(ИТР!B:B,B27,ИТР!S:S) -> 0 | L27: =SUMIF(Цо!R:R,B27,Цо!AI:AI) -> 0 | M27: =SUMIF(IRS!B:B,B27,IRS!S:S) -> 0 | N27: =SUMIF(Катеринополь!B:B,B27,Катеринополь!S:S) -> 0 | Q27: =SUMIF('ООН 2025'!B:B,B27,'ООН 2025'!S:S) -> 126 | R27: =SUMIF('Червоний хрест'!B:B,B27,'Червоний хрест'!S:S) -> 0 | T27: =SUMIF(Кернел!B:B,B27,Кернел!S:S) -> 0 | U27: =SUMIF('Глобино Мк'!B:B,B27,'Глобино Мк'!S:S) -> 0 | V27: =SUMIF('МД Франківськ'!B:B,B27,'МД Франківськ'!S:S) -> 0 | W27: =SUM(K27:V27)-I27 -> 0 | X27: =IFERROR(K27/$I27*$G27,0) -> 0 | Y27: =IFERROR(L27/$I27*$G27,0) -> 0 | Z27: =IFERROR(M27/$I27*$G27,0) -> 0 | AA27: =IFERROR(N27/$I27*$G27,0) -> 0 | AB27: =IFERROR(O27/$I27*$G27,0) -> 0 | AC27: =IFERROR(P27/$I27*$G27,0) -> 0 | AD27: =IFERROR(Q27/$I27*$G27,0) -> 15200 | AE27: =IFERROR(R27/$I27*$G27,0) -> 0 | ... AI27: =IFERROR(V27/$I27*$G27,0) -> 0 | AJ27: =SUM(X27:AI27) -> 15200 | AK27: =AJ27-G27 -> 0
A28: 24 | B28: Салюк Дмитро Андрійович | E28: =I28*J28 -> 16350 | F28: =SUMIF('[1]Табель цех 1 по 15 серпня'!$B:$B,B28,'[1]Табель цех 1 по 15 серпня'!$H:$H) -> -130 | G28: =ROUND(E28-C28-D28,-2) -> 16400 | H28: =F28+E28-D28-G28-C28 -> -180 | I28: =Цо!AI25+IRS!S25+Катеринополь!S25+'Червоний хрест'!S25+'ООН 2025'!S25+Кернел!S25+'Глобино Мк'!S25+'МД Франківськ'!S25 -> 109 | J28: 150 | K28: =SUMIF(ИТР!B:B,B28,ИТР!S:S) -> 0 | L28: =SUMIF(Цо!R:R,B28,Цо!AI:AI) -> 0 | M28: =SUMIF(IRS!B:B,B28,IRS!S:S) -> 0 | N28: =SUMIF(Катеринополь!B:B,B28,Катеринополь!S:S) -> 0 | Q28: =SUMIF('ООН 2025'!B:B,B28,'ООН 2025'!S:S) -> 109 | R28: =SUMIF('Червоний хрест'!B:B,B28,'Червоний хрест'!S:S) -> 0 | T28: =SUMIF(Кернел!B:B,B28,Кернел!S:S) -> 0 | U28: =SUMIF('Глобино Мк'!B:B,B28,'Глобино Мк'!S:S) -> 0 | V28: =SUMIF('МД Франківськ'!B:B,B28,'МД Франківськ'!S:S) -> 0 | W28: =SUM(K28:V28)-I28 -> 0 | X28: =IFERROR(K28/$I28*$G28,0) -> 0 | Y28: =IFERROR(L28/$I28*$G28,0) -> 0 | Z28: =IFERROR(M28/$I28*$G28,0) -> 0 | AA28: =IFERROR(N28/$I28*$G28,0) -> 0 | AB28: =IFERROR(O28/$I28*$G28,0) -> 0 | AC28: =IFERROR(P28/$I28*$G28,0) -> 0 | AD28: =IFERROR(Q28/$I28*$G28,0) -> 16400 | AE28: =IFERROR(R28/$I28*$G28,0) -> 0 | ... AI28: =IFERROR(V28/$I28*$G28,0) -> 0 | AJ28: =SUM(X28:AI28) -> 16400 | AK28: =AJ28-G28 -> 0
A29: 25 | B29: Маковецький Юрій Миколайович | D29: 2750 | E29: =I29*J29 -> 19200 | F29: =SUMIF('[1]Табель цех 1 по 15 серпня'!$B:$B,B29,'[1]Табель цех 1 по 15 серпня'!$H:$H) -> 47.32 | G29: =ROUND(E29-C29-D29,-2) -> 16500 | H29: =F29+E29-D29-G29-C29 -> -2.68 | I29: =Цо!AI26+IRS!S26+Катеринополь!S26+'Червоний хрест'!S26+'ООН 2025'!S26+Кернел!S26+'Глобино Мк'!S26+'МД Франківськ'!S26 -> 128 | J29: 150 | K29: =SUMIF(ИТР!B:B,B29,ИТР!S:S) -> 0 | L29: =SUMIF(Цо!R:R,B29,Цо!AI:AI) -> 0 | M29: =SUMIF(IRS!B:B,B29,IRS!S:S) -> 0 | N29: =SUMIF(Катеринополь!B:B,B29,Катеринополь!S:S) -> 72 | Q29: =SUMIF('ООН 2025'!B:B,B29,'ООН 2025'!S:S) -> 0 | R29: =SUMIF('Червоний хрест'!B:B,B29,'Червоний хрест'!S:S) -> 0 | T29: =SUMIF(Кернел!B:B,B29,Кернел!S:S) -> 0 | U29: =SUMIF('Глобино Мк'!B:B,B29,'Глобино Мк'!S:S) -> 56 | V29: =SUMIF('МД Франківськ'!B:B,B29,'МД Франківськ'!S:S) -> 0 | W29: =SUM(K29:V29)-I29 -> 0 | X29: =IFERROR(K29/$I29*$G29,0) -> 0 | Y29: =IFERROR(L29/$I29*$G29,0) -> 0 | Z29: =IFERROR(M29/$I29*$G29,0) -> 0 | AA29: =IFERROR(N29/$I29*$G29,0) -> 9281.25 | AB29: =IFERROR(O29/$I29*$G29,0) -> 0 | AC29: =IFERROR(P29/$I29*$G29,0) -> 0 | AD29: =IFERROR(Q29/$I29*$G29,0) -> 0 | AE29: =IFERROR(R29/$I29*$G29,0) -> 0 | ... AI29: =IFERROR(V29/$I29*$G29,0) -> 0 | AJ29: =SUM(X29:AI29) -> 16500 | AK29: =AJ29-G29 -> 0
A30: 26 | B30: Міненко Олександр Андрійович | E30: =I30*J30 -> 50400 | F30: =SUMIF('[1]Табель цех 1 по 15 серпня'!$B:$B,B30,'[1]Табель цех 1 по 15 серпня'!$H:$H) -> 0 | G30: =ROUND(E30-C30-D30,-2) -> 50400 | H30: =F30+E30-D30-G30-C30 -> 0 | I30: =Цо!AI27+IRS!S27+Катеринополь!S27+'Червоний хрест'!S27+'ООН 2025'!S27+Кернел!S27+'Глобино Мк'!S27+'МД Франківськ'!S27 -> 336 | J30: 150 | K30: =SUMIF(ИТР!B:B,B30,ИТР!S:S) -> 0 | L30: =SUMIF(Цо!R:R,B30,Цо!AI:AI) -> 0 | M30: =SUMIF(IRS!B:B,B30,IRS!S:S) -> 336 | N30: =SUMIF(Катеринополь!B:B,B30,Катеринополь!S:S) -> 0 | Q30: =SUMIF('ООН 2025'!B:B,B30,'ООН 2025'!S:S) -> 0 | R30: =SUMIF('Червоний хрест'!B:B,B30,'Червоний хрест'!S:S) -> 0 | T30: =SUMIF(Кернел!B:B,B30,Кернел!S:S) -> 0 | U30: =SUMIF('Глобино Мк'!B:B,B30,'Глобино Мк'!S:S) -> 0 | V30: =SUMIF('МД Франківськ'!B:B,B30,'МД Франківськ'!S:S) -> 0 | W30: =SUM(K30:V30)-I30 -> 0 | X30: =IFERROR(K30/$I30*$G30,0) -> 0 | Y30: =IFERROR(L30/$I30*$G30,0) -> 0 | Z30: =IFERROR(M30/$I30*$G30,0) -> 50400 | AA30: =IFERROR(N30/$I30*$G30,0) -> 0 | AB30: =IFERROR(O30/$I30*$G30,0) -> 0 | AC30: =IFERROR(P30/$I30*$G30,0) -> 0 | AD30: =IFERROR(Q30/$I30*$G30,0) -> 0 | AE30: =IFERROR(R30/$I30*$G30,0) -> 0 | ... AI30: =IFERROR(V30/$I30*$G30,0) -> 0 | AJ30: =SUM(X30:AI30) -> 50400 | AK30: =AJ30-G30 -> 0
A31: 27 | B31: Салій Дмитро Миколайович | E31: =I31*J31 -> 50400 | F31: =SUMIF('[1]Табель цех 1 по 15 серпня'!$B:$B,B31,'[1]Табель цех 1 по 15 серпня'!$H:$H) -> 0 | G31: =ROUND(E31-C31-D31,-2) -> 50400 | H31: =F31+E31-D31-G31-C31 -> 0 | I31: =Цо!AI28+IRS!S28+Катеринополь!S28+'Червоний хрест'!S28+'ООН 2025'!S28+Кернел!S28+'Глобино Мк'!S28+'МД Франківськ'!S28 -> 336 | J31: 150 | K31: =SUMIF(ИТР!B:B,B31,ИТР!S:S) -> 0 | L31: =SUMIF(Цо!R:R,B31,Цо!AI:AI) -> 0 | M31: =SUMIF(IRS!B:B,B31,IRS!S:S) -> 336 | N31: =SUMIF(Катеринополь!B:B,B31,Катеринополь!S:S) -> 0 | Q31: =SUMIF('ООН 2025'!B:B,B31,'ООН 2025'!S:S) -> 0 | R31: =SUMIF('Червоний хрест'!B:B,B31,'Червоний хрест'!S:S) -> 0 | T31: =SUMIF(Кернел!B:B,B31,Кернел!S:S) -> 0 | U31: =SUMIF('Глобино Мк'!B:B,B31,'Глобино Мк'!S:S) -> 0 | V31: =SUMIF('МД Франківськ'!B:B,B31,'МД Франківськ'!S:S) -> 0 | W31: =SUM(K31:V31)-I31 -> 0 | X31: =IFERROR(K31/$I31*$G31,0) -> 0 | Y31: =IFERROR(L31/$I31*$G31,0) -> 0 | Z31: =IFERROR(M31/$I31*$G31,0) -> 50400 | AA31: =IFERROR(N31/$I31*$G31,0) -> 0 | AB31: =IFERROR(O31/$I31*$G31,0) -> 0 | AC31: =IFERROR(P31/$I31*$G31,0) -> 0 | AD31: =IFERROR(Q31/$I31*$G31,0) -> 0 | AE31: =IFERROR(R31/$I31*$G31,0) -> 0 | ... AI31: =IFERROR(V31/$I31*$G31,0) -> 0 | AJ31: =SUM(X31:AI31) -> 50400 | AK31: =AJ31-G31 -> 0
A32: 28 | B32: Різніченко Олег Олександрович | E32: =I32*J32 -> 15750 | F32: =SUMIF('[1]Табель цех 1 по 15 серпня'!$B:$B,B32,'[1]Табель цех 1 по 15 серпня'!$H:$H) -> -80 | G32: =ROUND(E32-C32-D32,-2) -> 15800 | H32: =F32+E32-D32-G32-C32 -> -130 | I32: =Цо!AI29+IRS!S29+Катеринополь!S29+'Червоний хрест'!S29+'ООН 2025'!S29+Кернел!S29+'Глобино Мк'!S29+'МД Франківськ'!S29 -> 105 | J32: 150 | K32: =SUMIF(ИТР!B:B,B32,ИТР!S:S) -> 0 | L32: =SUMIF(Цо!R:R,B32,Цо!AI:AI) -> 0 | M32: =SUMIF(IRS!B:B,B32,IRS!S:S) -> 0 | N32: =SUMIF(Катеринополь!B:B,B32,Катеринополь!S:S) -> 55 | Q32: =SUMIF('ООН 2025'!B:B,B32,'ООН 2025'!S:S) -> 0 | R32: =SUMIF('Червоний хрест'!B:B,B32,'Червоний хрест'!S:S) -> 0 | T32: =SUMIF(Кернел!B:B,B32,Кернел!S:S) -> 0 | U32: =SUMIF('Глобино Мк'!B:B,B32,'Глобино Мк'!S:S) -> 50 | V32: =SUMIF('МД Франківськ'!B:B,B32,'МД Франківськ'!S:S) -> 0 | W32: =SUM(K32:V32)-I32 -> 0 | X32: =IFERROR(K32/$I32*$G32,0) -> 0 | Y32: =IFERROR(L32/$I32*$G32,0) -> 0 | Z32: =IFERROR(M32/$I32*$G32,0) -> 0 | AA32: =IFERROR(N32/$I32*$G32,0) -> 8276.1905 | AB32: =IFERROR(O32/$I32*$G32,0) -> 0 | AC32: =IFERROR(P32/$I32*$G32,0) -> 0 | AD32: =IFERROR(Q32/$I32*$G32,0) -> 0 | AE32: =IFERROR(R32/$I32*$G32,0) -> 0 | ... AI32: =IFERROR(V32/$I32*$G32,0) -> 0 | AJ32: =SUM(X32:AI32) -> 15800 | AK32: =AJ32-G32 -> 0
A33: 29 | B33: Рогозовець Андрій Вікторович | D33: 3739.99 | E33: =I33*J33 -> 18300 | F33: =SUMIF('[1]Табель цех 1 по 15 серпня'!$B:$B,B33,'[1]Табель цех 1 по 15 серпня'!$H:$H) -> 51.99 | G33: =ROUND(E33-C33-D33,-2) -> 14600 | H33: =F33+E33-D33-G33-C33 -> 12 | I33: =Цо!AI30+IRS!S30+Катеринополь!S30+'Червоний хрест'!S30+'ООН 2025'!S30+Кернел!S30+'Глобино Мк'!S30+'МД Франківськ'!S30 -> 122 | J33: 150 | K33: =SUMIF(ИТР!B:B,B33,ИТР!S:S) -> 0 | L33: =SUMIF(Цо!R:R,B33,Цо!AI:AI) -> 0 | M33: =SUMIF(IRS!B:B,B33,IRS!S:S) -> 0 | N33: =SUMIF(Катеринополь!B:B,B33,Катеринополь!S:S) -> 89 | Q33: =SUMIF('ООН 2025'!B:B,B33,'ООН 2025'!S:S) -> 0 | R33: =SUMIF('Червоний хрест'!B:B,B33,'Червоний хрест'!S:S) -> 0 | T33: =SUMIF(Кернел!B:B,B33,Кернел!S:S) -> 0 | U33: =SUMIF('Глобино Мк'!B:B,B33,'Глобино Мк'!S:S) -> 33 | V33: =SUMIF('МД Франківськ'!B:B,B33,'МД Франківськ'!S:S) -> 0 | W33: =SUM(K33:V33)-I33 -> 0 | X33: =IFERROR(K33/$I33*$G33,0) -> 0 | Y33: =IFERROR(L33/$I33*$G33,0) -> 0 | Z33: =IFERROR(M33/$I33*$G33,0) -> 0 | AA33: =IFERROR(N33/$I33*$G33,0) -> 10650.82 | AB33: =IFERROR(O33/$I33*$G33,0) -> 0 | AC33: =IFERROR(P33/$I33*$G33,0) -> 0 | AD33: =IFERROR(Q33/$I33*$G33,0) -> 0 | AE33: =IFERROR(R33/$I33*$G33,0) -> 0 | ... AI33: =IFERROR(V33/$I33*$G33,0) -> 0 | AJ33: =SUM(X33:AI33) -> 14600 | AK33: =AJ33-G33 -> 0
A34: 30 | B34: Старков Кирило Юрійович | E34: =I34*J34 -> 0 | F34: =SUMIF('[1]Табель цех 1 по 15 серпня'!$B:$B,B34,'[1]Табель цех 1 по 15 серпня'!$H:$H) -> 0 | G34: =ROUND(E34-C34-D34,-2) -> 0 | H34: =F34+E34-D34-G34-C34 -> 0 | I34: =Цо!AI31+IRS!S31+Катеринополь!S31+'Червоний хрест'!S31+'ООН 2025'!S31+Кернел!S31+'Глобино Мк'!S31+'МД Франківськ'!S31 -> 0 | J34: 150 | K34: =SUMIF(ИТР!B:B,B34,ИТР!S:S) -> 0 | L34: =SUMIF(Цо!R:R,B34,Цо!AI:AI) -> 0 | M34: =SUMIF(IRS!B:B,B34,IRS!S:S) -> 0 | N34: =SUMIF(Катеринополь!B:B,B34,Катеринополь!S:S) -> 0 | Q34: =SUMIF('ООН 2025'!B:B,B34,'ООН 2025'!S:S) -> 0 | R34: =SUMIF('Червоний хрест'!B:B,B34,'Червоний хрест'!S:S) -> 0 | T34: =SUMIF(Кернел!B:B,B34,Кернел!S:S) -> 0 | U34: =SUMIF('Глобино Мк'!B:B,B34,'Глобино Мк'!S:S) -> 0 | V34: =SUMIF('МД Франківськ'!B:B,B34,'МД Франківськ'!S:S) -> 0 | W34: =SUM(K34:V34)-I34 -> 0 | X34: =IFERROR(K34/$I34*$G34,0) -> 0 | Y34: =IFERROR(L34/$I34*$G34,0) -> 0 | Z34: =IFERROR(M34/$I34*$G34,0) -> 0 | AA34: =IFERROR(N34/$I34*$G34,0) -> 0 | AB34: =IFERROR(O34/$I34*$G34,0) -> 0 | AC34: =IFERROR(P34/$I34*$G34,0) -> 0 | AD34: =IFERROR(Q34/$I34*$G34,0) -> 0 | AE34: =IFERROR(R34/$I34*$G34,0) -> 0 | ... AI34: =IFERROR(V34/$I34*$G34,0) -> 0 | AJ34: =SUM(X34:AI34) -> 0 | AK34: =AJ34-G34 -> 0
A35: 31 | B35: Зубахін Сергій Александрович | E35: =I35*J35 -> 0 | F35: =SUMIF('[1]Табель цех 1 по 15 серпня'!$B:$B,B35,'[1]Табель цех 1 по 15 серпня'!$H:$H) -> 0 | G35: =ROUND(E35-C35-D35,-2) -> 0 | H35: =F35+E35-D35-G35-C35 -> 0 | I35: =Цо!AI32+IRS!S32+Катеринополь!S32+'Червоний хрест'!S32+'ООН 2025'!S32+Кернел!S32+'Глобино Мк'!S32+'МД Франківськ'!S32 -> 0 | J35: 150 | K35: =SUMIF(ИТР!B:B,B35,ИТР!S:S) -> 0 | L35: =SUMIF(Цо!R:R,B35,Цо!AI:AI) -> 0 | M35: =SUMIF(IRS!B:B,B35,IRS!S:S) -> 0 | N35: =SUMIF(Катеринополь!B:B,B35,Катеринополь!S:S) -> 0 | Q35: =SUMIF('ООН 2025'!B:B,B35,'ООН 2025'!S:S) -> 0 | R35: =SUMIF('Червоний хрест'!B:B,B35,'Червоний хрест'!S:S) -> 0 | T35: =SUMIF(Кернел!B:B,B35,Кернел!S:S) -> 0 | U35: =SUMIF('Глобино Мк'!B:B,B35,'Глобино Мк'!S:S) -> 0 | V35: =SUMIF('МД Франківськ'!B:B,B35,'МД Франківськ'!S:S) -> 0 | W35: =SUM(K35:V35)-I35 -> 0 | X35: =IFERROR(K35/$I35*$G35,0) -> 0 | Y35: =IFERROR(L35/$I35*$G35,0) -> 0 | Z35: =IFERROR(M35/$I35*$G35,0) -> 0 | AA35: =IFERROR(N35/$I35*$G35,0) -> 0 | AB35: =IFERROR(O35/$I35*$G35,0) -> 0 | AC35: =IFERROR(P35/$I35*$G35,0) -> 0 | AD35: =IFERROR(Q35/$I35*$G35,0) -> 0 | AE35: =IFERROR(R35/$I35*$G35,0) -> 0 | ... AI35: =IFERROR(V35/$I35*$G35,0) -> 0 | AJ35: =SUM(X35:AI35) -> 0 | AK35: =AJ35-G35 -> 0
