Workbook

Sheet Лист2
B1: Код (Таб. №) | C1: Наименование | D1: Код по ДРФО | E1: Вид договора | F1: Вид занятости | G1: Подразделение организации | H1: Должность организации | I1: Дата приема
B2: 1 | C2: Оренда авто
B3: д000000007 | C3: Воронцов Олександр Володимирович (оренда авто) | D3: 3244112838 | E3: Договор подряда (выполнение работ, оказание услуг)
B4: д000000023 | C4: Гавриченко Тетяна Василівна (оренда авто) | D4: 2890614789 | E4: Договор подряда (выполнение работ, оказание услуг)
B5: д000000010 | C5: Гриценко Олександр Вікторович (оренда авто) | D5: 2751711415 | E5: Договор подряда (выполнение работ, оказание услуг)
B6: д000000001 | C6: Гриценко Сергій Миколайович (дг.) | D6: 3382914593 | E6: Договор подряда (выполнение работ, оказание услуг)
B7: д000000013 | C7: Гриценко Сергій Миколайович (оренда авто) | D7: 3382914593 | E7: Договор подряда (выполнение работ, оказание услуг)
B8: д000000019 | C8: Гуняга Олег Володимирович (оренда авто) | D8: 2711822114 | E8: Договор подряда (выполнение работ, оказание услуг)
B9: д000000008 | C9: Манжула Максим Анатолійович (оренда авто) | D9: 3281710375 | E9: Договор подряда (выполнение работ, оказание услуг)
B10: д000000014 | C10: Огоновський Дмитро Анатолійович (оренда авто) | D10: 2866215672 | E10: Договор подряда (выполнение работ, оказание услуг)
B11: д000000015 | C11: Потьомко Михайло Володимирович (оренда авто) | D11: 3575508457 | E11: Договор подряда (выполнение работ, оказание услуг)
B12: д000000016 | C12: Сикал Павло Анатолійович (оренда авто) | D12: 3306506991 | E12: Договор подряда (выполнение работ, оказание услуг)
B13: д000000012 | C13: Старіков Сергій Вікторович (оренда авто) | D13: 2899410750 | E13: Договор подряда (выполнение работ, оказание услуг)
B14: д000000020 | C14: Шевченко Євген Анатолійович (оренда авто) | D14: 3194113635 | E14: Договор подряда (выполнение работ, оказание услуг)
B15: д000000009 | C15: Ширшов Олександр Леонідович (оренда авто) | D15: 2234022693 | E15: Договор подряда (выполнение работ, оказание услуг)
B16: 23 | C16: Адаменко Віталій Вікторович | D16: 3153900053 | E16: Трудовой договор | F16: Основное место работы | G16: Виробничий (Цех металоконструкцій) | H16: Монтажник будівельний | I16: 05.10.2022
B17: 4 | C17: Аксенчіков Сергій Олександрович | D17: 3457309598 | E17: Трудовой договор | F17: Основное место работы | G17: Адміністративний відділ | H17: Майстер будівельних та монтажних робіт | I17: 01.07.2022
B18: д000000001 | C18: Аксенчіков Сергій Олександрович (оренда авто) | D18: 3457309598 | E18: Договор подряда (выполнение работ, оказание услуг)
B19: 48 | C19: Александров Артем Анатолійович | D19: 2618119132 | E19: Трудовой договор | F19: Основное место работы | G19: Адміністративний відділ | H19: Діловод | I19: 25.09.2018
B20: 203 | C20: Александров Денис Анатолійович | D20: 2765913876 | E20: Трудовой договор | F20: Основное место работы | G20: Адміністративний відділ | H20: Помічник економіста | I20: 01.02.2021
B21: 156 | C21: Александрова Жанна Валентинівна | D21: 2693717247 | E21: Трудовой договор | F21: Основное место работы | G21: Адміністративний відділ | H21: Прибиральник службових приміщень | I21: 01.07.2020
B22: 2289516770 | C22: Антонович Тетяна Сергіївна | D22: 2894801342 | E22: Трудовой договор | F22: Основное место работы | G22: Адміністративний відділ | H22: Директор фінансовий | I22: 22.12.2022
B23: 16 | C23: Антонович Тетяна Сергіївна (сум.) | D23: 2894801342 | E23: Трудовой договор | F23: Внешнее совместительство | G23: Адміністративний відділ | H23: Директор фінансовий | I23: 26.05.2023
B24: 17 | C24: Аулова Маргарита Володимирівна | D24: 3036417408 | E24: Трудовой договор | F24: Внешнее совместительство | G24: Адміністративний відділ | H24: Головний бухгалтер | I24: 01.04.2024
B25: 2289516882 | C25: Аулова Маргарита Володимирівна (осн.) | D25: 3036417408 | E25: Трудовой договор | F25: Основное место работы | G25: Адміністративний відділ | H25: Головний бухгалтер | I25: 27.03.2024
B26: 2289516833 | C26: Ахмедов Тавакгюль Сардар огли | D26: 2358421934 | E26: Трудовой договор | F26: Основное место работы | G26: Виробничий (Ладижин-3) | H26: Маляр | I26: 08.09.2023
B27: 37 | C27: Бабіленко Микола Олександрович | D27: 2564424513 | E27: Трудовой договор | F27: Основное место работы | G27: Виробничий (Цех металоконструкцій) | H27: Слюсар із складання металевих конструкцій | I27: 01.12.2022
B28: 11 | C28: Багацький Вадим Геннадійович | D28: 3247506159 | E28: Трудовой договор | F28: Основное место работы | G28: Виробничий (Цех металоконструкцій) | H28: Електрозварник ручного зварювання | I28: 05.08.2022
B29: 2289516701 | C29: Безкоровайний Дмитро Миколайович | D29: 3358009052 | E29: Трудовой договор | F29: Основное место работы | G29: Виробничий (Підгірці) | H29: Водій автотранспортних засобів | I29: 04.02.2022
B30: 62 | C30: Білоусов Євген Вікторович | D30: 3421002151 | E30: Трудовой договор | F30: Основное место работы | G30: Виробничий (Старокостянтинів) | H30: Арматурник (будівельні, монтажні й ремонтно-будівельні роботи) | I30: 01.02.2019
B31: д000000006 | C31: Бічковський Максим Петрович | D31: 2922419813 | E31: Договор подряда (выполнение работ, оказание услуг)
B32: 2289516746 | C32: Блоха Євген Валерійович | D32: 2919308010 | E32: Трудовой договор | F32: Основное место работы | G32: Виробничий (Старокостянтинів) | H32: Бетоняр | I32: 27.09.2022
B33: 2289516849 | C33: Богданюк Дмитро Леонтійович | D33: 3036408418 | E33: Трудовой договор | F33: Основное место работы | G33: Адміністративний відділ | H33: Інженер з проєктно-кошторисної роботи | I33: 02.11.2023
B34: 19 | C34: Богун Олена Миколаївна | D34: 3813305164 | E34: Трудовой договор | F34: Основное место работы | G34: Виробничій цех | H34: Лаборант | I34: 02.07.2024
B35: 2289516863 | C35: Божков Валерій Вікторович | D35: 2753702532 | E35: Трудовой договор | F35: Основное место работы | G35: Виробничий (Крушинка) | H35: Водій автотранспортних засобів | I35: 19.12.2023
B36: 46 | C36: Бокоч Галина Михайлівна (осн.) | D36: 3018718189 | E36: Трудовой договор | F36: Основное место работы | G36: Адміністративний відділ | H36: Діловод | I36: 24.11.2023
B37: 157 | C37: Болох Володимир Васильович | D37: 2794610037 | E37: Трудовой договор | F37: Основное место работы | G37: Виробничий (Старокостянтинів) | H37: Машиніст крана автомобільного | I37: 03.08.2020
B38: 71 | C38: Борецька Людмила Сергіївна | D38: 3280710149 | E38: Трудовой договор | F38: Основное место работы | G38: Адміністративний відділ | H38: Економіст | I38: 08.04.2019
B39: 2289516756 | C39: Борисенко Олексій Миколайович | D39: 2957816213 | E39: Трудовой договор | F39: Основное место работы | G39: Виробничий (Крушинка) | H39: Машиніст крана автомобільного | I39: 01.11.2022
B40: 49 | C40: Бреус Віталій Григорович | D40: 3143007035 | E40: Трудовой договор | F40: Основное место работы | G40: Адміністративний відділ | H40: Менеджер (управитель) з постачання | I40: 18.07.2023
...

Sheet Лист1
B2: N | C2: Работник (основное назначение) | D2: Период взаиморасчетов | E2: Счет учета | F2: Сумма | G2: Сумма (окр.) | J2: Админ
B3: 1 | C3: Аксенчіков Сергій Олександрович | D3: 01.07.2024 | E3: 661 | F3: 4326 | H3: =MATCH(I3,#REF!,0) -> #REF! | I3: =TRIM(C3) -> Аксенчіков Сергій Олександрович | J3: 1
B4: 2 | C4: Бабіленко Микола Олександрович | D4: 01.07.2024 | E4: 661 | F4: 3990 | H4: =MATCH(I4,#REF!,0) -> #REF! | I4: =TRIM(C4) -> Бабіленко Микола Олександрович | K4: =INDEX(Лист2!D:D,MATCH(C4,Лист2!C:C,0)) -> 2564424513
B5: 3 | C5: Багацький Вадим Геннадійович | D5: 01.07.2024 | E5: 661 | F5: 3990 | H5: =MATCH(I5,#REF!,0) -> #REF! | I5: =TRIM(C5) -> Багацький Вадим Геннадійович | K5: =INDEX(Лист2!D:D,MATCH(C5,Лист2!C:C,0)) -> 3247506159
B6: 4 | C6: Бреус Віталій Григорович | D6: 01.07.2024 | E6: 661 | F6: 5417.99 | H6: =MATCH(I6,#REF!,0) -> #REF! | I6: =TRIM(C6) -> Бреус Віталій Григорович | J6: 1
B7: 5 | C7: Бутенко Матвій Анатолійович | D7: 01.07.2024 | E7: 661 | F7: 4326 | H7: =MATCH(I7,#REF!,0) -> #REF! | I7: =TRIM(C7) -> Бутенко Матвій Анатолійович | J7: 1
B8: 6 | C8: Васильєв Віталій Юрійович | D8: 01.07.2024 | E8: 661 | F8: 3990 | H8: =MATCH(I8,#REF!,0) -> #REF! | I8: =TRIM(C8) -> Васильєв Віталій Юрійович | K8: =INDEX(Лист2!D:D,MATCH(C8,Лист2!C:C,0)) -> 3746304158
B9: 7 | C9: Власенко В'ячеслав Валентинович | D9: 01.07.2024 | E9: 661 | F9: 3990 | H9: =MATCH(I9,#REF!,0) -> #REF! | I9: =TRIM(C9) -> Власенко В'ячеслав Валентинович | K9: =INDEX(Лист2!D:D,MATCH(C9,Лист2!C:C,0)) -> 2831710277
B10: 8 | C10: Горєлов Микита Євгенович | D10: 01.07.2024 | E10: 661 | F10: 2660 | H10: =MATCH(I10,#REF!,0) -> #REF! | I10: =TRIM(C10) -> Горєлов Микита Євгенович | K10: =INDEX(Лист2!D:D,MATCH(C10,Лист2!C:C,0)) -> 3596200395
B11: 9 | C11: Григор'єв Микола Андрійович | D11: 01.07.2024 | E11: 661 | F11: 1662.5 | H11: =MATCH(I11,#REF!,0) -> #REF! | I11: =TRIM(C11) -> Григор'єв Микола Андрійович | K11: =INDEX(Лист2!D:D,MATCH(C11,Лист2!C:C,0)) -> 3422005391
B12: 10 | C12: Григор'єв Михайло Андрійович | D12: 01.07.2024 | E12: 661 | F12: 3990 | H12: =MATCH(I12,#REF!,0) -> #REF! | I12: =TRIM(C12) -> Григор'єв Михайло Андрійович | K12: =INDEX(Лист2!D:D,MATCH(C12,Лист2!C:C,0)) -> 3720407672
B13: 11 | C13: Григоренко Олександр Миколайович | D13: 01.07.2024 | E13: 661 | F13: 3990 | H13: =MATCH(I13,#REF!,0) -> #REF! | I13: =TRIM(C13) -> Григоренко Олександр Миколайович | K13: =INDEX(Лист2!D:D,MATCH(C13,Лист2!C:C,0)) -> 2436600937
B14: 12 | C14: Гриценко Олександр Вікторович | D14: 01.07.2024 | E14: 661 | F14: 5197.5 | H14: =MATCH(I14,#REF!,0) -> #REF! | I14: =TRIM(C14) -> Гриценко Олександр Вікторович | J14: 1
B15: 13 | C15: Грушко Лариса Вікторівна | D15: 01.07.2024 | E15: 661 | F15: 4427.5 | H15: =MATCH(I15,#REF!,0) -> #REF! | I15: =TRIM(C15) -> Грушко Лариса Вікторівна | J15: 1
B16: 14 | C16: Дехтяр Владислав Олександрович | D16: 01.07.2024 | E16: 661 | F16: 3990 | H16: =MATCH(I16,#REF!,0) -> #REF! | I16: =#REF! -> #REF! | K16: =INDEX(Лист2!D:D,MATCH(C16,Лист2!C:C,0)) -> 3374502899
B17: 15 | C17: Желтяков Ігор Юрійович | D17: 01.07.2024 | E17: 661 | F17: 3990 | H17: =MATCH(I17,#REF!,0) -> #REF! | I17: =TRIM(C17) -> Желтяков Ігор Юрійович | K17: =INDEX(Лист2!D:D,MATCH(C17,Лист2!C:C,0)) -> 2637303953
B18: 16 | C18: Іванов Олексій Вікторович | D18: 01.07.2024 | E18: 661 | F18: 3990 | H18: =MATCH(I18,#REF!,0) -> #REF! | I18: =TRIM(C18) -> Іванов Олексій Вікторович | K18: =INDEX(Лист2!D:D,MATCH(C18,Лист2!C:C,0)) -> 3705902230
B19: 17 | C19: Іскрицький Денис Русланович | D19: 01.07.2024 | E19: 661 | F19: 3990 | H19: =MATCH(I19,#REF!,0) -> #REF! | I19: =TRIM(C19) -> Іскрицький Денис Русланович | K19: =INDEX(Лист2!D:D,MATCH(C19,Лист2!C:C,0)) -> 3779110293
B20: 18 | C20: Кіфор Юрій Михайлович | D20: 01.07.2024 | E20: 661 | F20: 3990.02 | H20: =MATCH(I20,#REF!,0) -> #REF! | I20: =TRIM(C20) -> Кіфор Юрій Михайлович | K20: =INDEX(Лист2!D:D,MATCH(C20,Лист2!C:C,0)) -> 2521518612
B21: 19 | C21: Корнієнко Станіслав Володимирович | D21: 01.07.2024 | E21: 661 | F21: 3428.01 | H21: =MATCH(I21,#REF!,0) -> #REF! | I21: =C21 -> Корнієнко Станіслав Володимирович | K21: =INDEX(Лист2!D:D,MATCH(C21,Лист2!C:C,0)) -> 2579305831
B22: 20 | C22: Масливець Ігор Валерійович | D22: 01.07.2024 | E22: 661 | F22: 3990 | H22: =MATCH(I22,#REF!,0) -> #REF! | I22: =TRIM(C22) -> Масливець Ігор Валерійович | K22: =INDEX(Лист2!D:D,MATCH(C22,Лист2!C:C,0)) -> 2880313812
B23: 21 | C23: Мельниченко Максим Вікторович | D23: 01.07.2024 | E23: 661 | F23: 6650 | H23: =MATCH(I23,#REF!,0) -> #REF! | I23: =TRIM(C23) -> Мельниченко Максим Вікторович | K23: =INDEX(Лист2!D:D,MATCH(C23,Лист2!C:C,0)) -> 3348501613
B24: 22 | C24: Мороз Віталій Миколайович | D24: 01.07.2024 | E24: 661 | F24: 6650 | H24: =MATCH(I24,#REF!,0) -> #REF! | I24: =TRIM(C24) -> Мороз Віталій Миколайович | K24: =INDEX(Лист2!D:D,MATCH(C24,Лист2!C:C,0)) -> 3216804294
B25: 23 | C25: Нестерук Сергій Петрович | D25: 01.07.2024 | E25: 661 | F25: 3990.02 | H25: =MATCH(I25,#REF!,0) -> #REF! | I25: =TRIM(C25) -> Нестерук Сергій Петрович | K25: =INDEX(Лист2!D:D,MATCH(C25,Лист2!C:C,0)) -> 3283102618
B26: 24 | C26: Паламарчук Вячеслав Володимирович | D26: 01.07.2024 | E26: 661 | F26: 3990 | H26: =MATCH(I26,#REF!,0) -> #REF! | I26: =TRIM(C26) -> Паламарчук Вячеслав Володимирович | K26: =INDEX(Лист2!D:D,MATCH(C26,Лист2!C:C,0)) -> 3230316597
B27: 25 | C27: Парнєва Олена Вікторівна | D27: 01.07.2024 | E27: 661 | F27: 840 | H27: =MATCH(I27,#REF!,0) -> #REF! | I27: =TRIM(C27) -> Парнєва Олена Вікторівна | K27: =INDEX(Лист2!D:D,MATCH(C27,Лист2!C:C,0)) -> 2938511042
B28: 26 | C28: Пилипчук Олександр Анатолійович | D28: 01.07.2024 | E28: 661 | F28: 3990 | H28: =MATCH(I28,#REF!,0) -> #REF! | I28: =TRIM(C28) -> Пилипчук Олександр Анатолійович | K28: =INDEX(Лист2!D:D,MATCH(C28,Лист2!C:C,0)) -> 3067218612
B29: 27 | C29: Поліщук Олександр Олександрович | D29: 01.07.2024 | E29: 661 | F29: 3990 | H29: =MATCH(I29,#REF!,0) -> #REF! | I29: =TRIM(C29) -> Поліщук Олександр Олександрович | K29: =INDEX(Лист2!D:D,MATCH(C29,Лист2!C:C,0)) -> 3289716153
B30: 28 | C30: Пономаренко Віталій Вікторович | D30: 01.07.2024 | E30: 661 | F30: 3990 | H30: =MATCH(I30,#REF!,0) -> #REF! | I30: =TRIM(C30) -> Пономаренко Віталій Вікторович | K30: =INDEX(Лист2!D:D,MATCH(C30,Лист2!C:C,0)) -> 3185119514
B31: 29 | C31: Пономаренко Олександр Вікторович | D31: 01.07.2024 | E31: 661 | F31: 5460 | H31: =MATCH(I31,#REF!,0) -> #REF! | I31: =TRIM(C31) -> Пономаренко Олександр Вікторович | K31: =INDEX(Лист2!D:D,MATCH(C31,Лист2!C:C,0)) -> 2944519172
B32: 30 | C32: Пономарьов Микола Вікторович | D32: 01.07.2024 | E32: 661 | F32: 3990 | H32: =MATCH(I32,#REF!,0) -> #REF! | I32: =TRIM(C32) -> Пономарьов Микола Вікторович | K32: =INDEX(Лист2!D:D,MATCH(C32,Лист2!C:C,0)) -> 3008300898
B33: 31 | C33: Понуркін Євген Григорович | D33: 01.07.2024 | E33: 661 | F33: 3990 | H33: =MATCH(I33,#REF!,0) -> #REF! | I33: =TRIM(C33) -> Понуркін Євген Григорович | K33: =INDEX(Лист2!D:D,MATCH(C33,Лист2!C:C,0)) -> 3005702873
... B38: 36 | C38: Скрипник Сергій Павлович | D38: 01.07.2024 | E38: 661 | F38: 5460 | H38: =MATCH(I38,#REF!,0) -> #REF! | I38: =TRIM(C38) -> Скрипник Сергій Павлович | K38: =INDEX(Лист2!D:D,MATCH(C38,Лист2!C:C,0)) -> 3219619831
B39: 37 | C39: Стецюк Тетяна Леонідівна | D39: 01.07.2024 | E39: 661 | F39: 5460 | H39: =MATCH(I39,#REF!,0) -> #REF! | I39: =TRIM(C39) -> Стецюк Тетяна Леонідівна | J39: 1
B40: 38 | C40: Тужиков Валерій Владиславович (осн.) | D40: 01.07.2024 | E40: 661 | F40: 3990 | H40: =MATCH(I40,#REF!,0) -> #REF! | I40: =#REF! -> #REF! | K40: =INDEX(Лист2!D:D,MATCH(C40,Лист2!C:C,0)) -> 3233009756
B41: 39 | C41: Тужиков Юрій Владиславович | D41: 01.07.2024 | E41: 661 | F41: 3324.99 | H41: =MATCH(I41,#REF!,0) -> #REF! | I41: =TRIM(C41) -> Тужиков Юрій Владиславович | K41: =INDEX(Лист2!D:D,MATCH(C41,Лист2!C:C,0)) -> 3153508799
B42: 40 | C42: Федорчук Денис Сергійович | D42: 01.07.2024 | E42: 661 | F42: 1995 | H42: =MATCH(I42,#REF!,0) -> #REF! | I42: =TRIM(C42) -> Федорчук Денис Сергійович | K42: =INDEX(Лист2!D:D,MATCH(C42,Лист2!C:C,0)) -> 3428705315
B43: 41 | C43: Чілібін Микола Євгенович | D43: 01.07.2024 | E43: 661 | F43: 5460 | H43: =MATCH(I43,#REF!,0) -> #REF! | I43: =TRIM(C43) -> Чілібін Микола Євгенович | J43: 1
B44: 42 | C44: Чуб Владислав Володимирович | D44: 01.07.2024 | E44: 661 | F44: 840 | H44: =MATCH(I44,#REF!,0) -> #REF! | I44: =TRIM(C44) -> Чуб Владислав Володимирович | K44: =INDEX(Лист2!D:D,MATCH(C44,Лист2!C:C,0)) -> 2858519154
B45: 43 | C45: Щербак Петро Іванович | D45: 01.07.2024 | E45: 661 | F45: 4620 | H45: =MATCH(I45,#REF!,0) -> #REF! | I45: =C45 -> Щербак Петро Іванович | K45: =INDEX(Лист2!D:D,MATCH(C45,Лист2!C:C,0)) -> 2537500655
...

Sheet Табель цех 16 по 30 вересня
A1: N | B1: Сотрудник | C1: Удержание за обеды на объекте | D1: виплати на картку за період 16-30.09.25 | E1: ЗП 16-30.09.25 | F1: Сальдо на -15.09.2025 | G1: до виплати | H1: Сальдо на 30.09.2025 | I1: Відпрацьовано годин | J1: ставка
B2: Пономаренко Віталій Вікторович | D2: 8662.5 | E2: =I2*J2 -> 20880 | F2: =SUMIF('[1]Табель цех 1 по 15 вересня'!$B:$B,B2,'[1]Табель цех 1 по 15 вересня'!$H:$H) -> 29.98 | G2: =IF(ROUND(E2+F2-C2-D2,-2)<0,0,ROUND(E2+F2-C2-D2,-2)) -> 12200 | H2: =F2+E2-D2-G2-C2 -> 47.48 | I2: 116 | J2: 180
B3: Скрипник Сергій Павлович | D3: 8610 | E3: =I3*J3 -> 14940 | F3: =SUMIF('[1]Табель цех 1 по 15 вересня'!$B:$B,B3,'[1]Табель цех 1 по 15 вересня'!$H:$H) -> -2423.56 | G3: =IF(ROUND(E3+F3-C3-D3,-2)<0,0,ROUND(E3+F3-C3-D3,-2)) -> 3900 | H3: =F3+E3-D3-G3-C3 -> 6.44 | I3: 83 | J3: 180
A4: 1 | B4: Багацький Вадим Геннадійович | D4: 3927 | E4: =I4*J4 -> 24150 | F4: =SUMIF('[1]Табель цех 1 по 15 вересня'!$B:$B,B4,'[1]Табель цех 1 по 15 вересня'!$H:$H) -> -14.75 | G4: =IF(ROUND(E4+F4-C4-D4,-2)<0,0,ROUND(E4+F4-C4-D4,-2)) -> 20200 | H4: =F4+E4-D4-G4-C4 -> 8.25 | I4: =_ЦО!T2+'МХП лазня'!T2+Катеринополь!T2+ВООЗ!T2+Кернел!T2+'Глобино Мк'!T2+'ВООЗ ЕМС'!T2+'ООН 36'!T2+'ООН 37'!T2+'ООН 38'!T2+ООН39!T2+'ООН 40'!T2+'ООН №43'!T2+'ООН 44'!T2+'ООН 45'!V2+ООН46!T2+ООН47!T2+ООН48!T2+ООН49!T2+ООн50!T2+ООН51!T2+Форшахта!T2+'ГАлерея 25.6'!T2+ГРП!AI2+'Парк меляси'!T2+'ООН 42'!T2 -> 161 | J4: 150
A5: 2 | B5: Васильєв Віталій Юрійович | D5: 3927 | E5: =I5*J5 -> 17850 | F5: =SUMIF('[1]Табель цех 1 по 15 вересня'!$B:$B,B5,'[1]Табель цех 1 по 15 вересня'!$H:$H) -> 2.26 | G5: =IF(ROUND(E5+F5-C5-D5,-2)<0,0,ROUND(E5+F5-C5-D5,-2)) -> 13900 | H5: =F5+E5-D5-G5-C5 -> 25.26 | I5: =_ЦО!T3+'МХП лазня'!T3+Катеринополь!T3+ВООЗ!T3+Кернел!T3+'Глобино Мк'!T3+'ВООЗ ЕМС'!T3+'ООН 36'!T3+'ООН 37'!T3+'ООН 38'!T3+ООН39!T3+'ООН 40'!T3+'ООН №43'!T3+'ООН 44'!T3+'ООН 45'!V3+ООН46!T3+ООН47!T3+ООН48!T3+ООН49!T3+ООн50!T3+ООН51!T3+Форшахта!T3+'ГАлерея 25.6'!T3+ГРП!AI3+'Парк меляси'!T3+'ООН 42'!T3 -> 119 | J5: 150
A6: 3 | B6: Григоренко Олександр Миколайович | C6: 10324.25 | D6: 3927 | E6: =I6*J6 -> 54000 | F6: =SUMIF('[1]Табель цех 1 по 15 вересня'!$B:$B,B6,'[1]Табель цех 1 по 15 вересня'!$H:$H) -> 39.75 | G6: =IF(ROUND(E6+F6-C6-D6,-2)<0,0,ROUND(E6+F6-C6-D6,-2)) -> 39800 | H6: =F6+E6-D6-G6-C6 -> -11.5 | I6: =_ЦО!T4+'МХП лазня'!T4+Катеринополь!T4+ВООЗ!T4+Кернел!T4+'Глобино Мк'!T4+'ВООЗ ЕМС'!T4+'ООН 36'!T4+'ООН 37'!T4+'ООН 38'!T4+ООН39!T4+'ООН 40'!T4+'ООН №43'!T4+'ООН 44'!T4+'ООН 45'!V4+ООН46!T4+ООН47!T4+ООН48!T4+ООН49!T4+ООн50!T4+ООН51!T4+Форшахта!T4+'ГАлерея 25.6'!T4+ГРП!AI4+'Парк меляси'!T4+'ООН 42'!T4 -> 360 | J6: 150
A7: 4 | B7: Григорьєв Микола Андрійович | D7: 3927 | E7: =I7*J7 -> 18150 | F7: =SUMIF('[1]Табель цех 1 по 15 вересня'!$B:$B,B7,'[1]Табель цех 1 по 15 вересня'!$H:$H) -> -28.74 | G7: =IF(ROUND(E7+F7-C7-D7,-2)<0,0,ROUND(E7+F7-C7-D7,-2)) -> 14200 | H7: =F7+E7-D7-G7-C7 -> -5.74 | I7: =_ЦО!T5+'МХП лазня'!T5+Катеринополь!T5+ВООЗ!T5+Кернел!T5+'Глобино Мк'!T5+'ВООЗ ЕМС'!T5+'ООН 36'!T5+'ООН 37'!T5+'ООН 38'!T5+ООН39!T5+'ООН 40'!T5+'ООН №43'!T5+'ООН 44'!T5+'ООН 45'!V5+ООН46!T5+ООН47!T5+ООН48!T5+ООН49!T5+ООн50!T5+ООН51!T5+Форшахта!T5+'ГАлерея 25.6'!T5+ГРП!AI5+'Парк меляси'!T5+'ООН 42'!T5 -> 121 | J7: 150
A8: 5 | B8: Григор'єв Михайло Андрійович | D8: 3927 | E8: =I8*J8 -> 19050 | F8: =SUMIF('[1]Табель цех 1 по 15 вересня'!$B:$B,B8,'[1]Табель цех 1 по 15 вересня'!$H:$H) -> 6.17 | G8: =IF(ROUND(E8+F8-C8-D8,-2)<0,0,ROUND(E8+F8-C8-D8,-2)) -> 15100 | H8: =F8+E8-D8-G8-C8 -> 29.17 | I8: =_ЦО!T6+'МХП лазня'!T6+Катеринополь!T6+ВООЗ!T6+Кернел!T6+'Глобино Мк'!T6+'ВООЗ ЕМС'!T6+'ООН 36'!T6+'ООН 37'!T6+'ООН 38'!T6+ООН39!T6+'ООН 40'!T6+'ООН №43'!T6+'ООН 44'!T6+'ООН 45'!V6+ООН46!T6+ООН47!T6+ООН48!T6+ООН49!T6+ООн50!T6+ООН51!T6+Форшахта!T6+'ГАлерея 25.6'!T6+ГРП!AI6+'Парк меляси'!T6+'ООН 42'!T6 -> 127 | J8: 150
A9: 6 | B9: Іванов Олексій Вікторович | D9: 3927 | E9: =I9*J9 -> 19050 | F9: =SUMIF('[1]Табель цех 1 по 15 вересня'!$B:$B,B9,'[1]Табель цех 1 по 15 вересня'!$H:$H) -> -18.45 | G9: =IF(ROUND(E9+F9-C9-D9,-2)<0,0,ROUND(E9+F9-C9-D9,-2)) -> 15100 | H9: =F9+E9-D9-G9-C9 -> 4.55 | I9: =_ЦО!T7+'МХП лазня'!T7+Катеринополь!T7+ВООЗ!T7+Кернел!T7+'Глобино Мк'!T7+'ВООЗ ЕМС'!T7+'ООН 36'!T7+'ООН 37'!T7+'ООН 38'!T7+ООН39!T7+'ООН 40'!T7+'ООН №43'!T7+'ООН 44'!T7+'ООН 45'!V7+ООН46!T7+ООН47!T7+ООН48!T7+ООН49!T7+ООн50!T7+ООН51!T7+Форшахта!T7+'ГАлерея 25.6'!T7+ГРП!AI7+'Парк меляси'!T7+'ООН 42'!T7 -> 127 | J9: 150
A10: 7 | B10: Іскрицький Денис Русланович | D10: 18640.48 | E10: =I10*J10 -> 23400 | F10: =SUMIF('[1]Табель цех 1 по 15 вересня'!$B:$B,B10,'[1]Табель цех 1 по 15 вересня'!$H:$H) -> -10.24 | G10: =IF(ROUND(E10+F10-C10-D10,-2)<0,0,ROUND(E10+F10-C10-D10,-2)) -> 4700 | H10: =F10+E10-D10-G10-C10 -> 49.28 | I10: =_ЦО!T8+'МХП лазня'!T8+Катеринополь!T8+ВООЗ!T8+Кернел!T8+'Глобино Мк'!T8+'ВООЗ ЕМС'!T8+'ООН 36'!T8+'ООН 37'!T8+'ООН 38'!T8+ООН39!T8+'ООН 40'!T8+'ООН №43'!T8+'ООН 44'!T8+'ООН 45'!V8+ООН46!T8+ООН47!T8+ООН48!T8+ООН49!T8+ООн50!T8+ООН51!T8+Форшахта!T8+'ГАлерея 25.6'!T8+ГРП!AI8+'Парк меляси'!T8+'ООН 42'!T8 -> 156 | J10: 150
A11: 8 | B11: Корнієнко Станіслав Володимирович | C11: 10324.25 | D11: 3927 | E11: =I11*J11 -> 54000 | F11: =SUMIF('[1]Табель цех 1 по 15 вересня'!$B:$B,B11,'[1]Табель цех 1 по 15 вересня'!$H:$H) -> 32.54 | G11: =IF(ROUND(E11+F11-C11-D11,-2)<0,0,ROUND(E11+F11-C11-D11,-2)) -> 39800 | H11: =F11+E11-D11-G11-C11 -> -18.71 | I11: =_ЦО!T9+'МХП лазня'!T9+Катеринополь!T9+ВООЗ!T9+Кернел!T9+'Глобино Мк'!T9+'ВООЗ ЕМС'!T9+'ООН 36'!T9+'ООН 37'!T9+'ООН 38'!T9+ООН39!T9+'ООН 40'!T9+'ООН №43'!T9+'ООН 44'!T9+'ООН 45'!V9+ООН46!T9+ООН47!T9+ООН48!T9+ООН49!T9+ООн50!T9+ООН51!T9+Форшахта!T9+'ГАлерея 25.6'!T9+ГРП!AI9+'Парк меляси'!T9+'ООН 42'!T9 -> 360 | J11: 150
A12: 9 | B12: Масливець Ігор Валерійович | D12: 3927 | E12: =I12*J12 -> 20700 | F12: =SUMIF('[1]Табель цех 1 по 15 вересня'!$B:$B,B12,'[1]Табель цех 1 по 15 вересня'!$H:$H) -> 34.95 | G12: =IF(ROUND(E12+F12-C12-D12,-2)<0,0,ROUND(E12+F12-C12-D12,-2)) -> 16800 | H12: =F12+E12-D12-G12-C12 -> 7.95 | I12: =_ЦО!T10+'МХП лазня'!T10+Катеринополь!T10+ВООЗ!T10+Кернел!T10+'Глобино Мк'!T10+'ВООЗ ЕМС'!T10+'ООН 36'!T10+'ООН 37'!T10+'ООН 38'!T10+ООН39!T10+'ООН 40'!T10+'ООН №43'!T10+'ООН 44'!T10+'ООН 45'!V10+ООН46!T10+ООН47!T10+ООН48!T10+ООН49!T10+ООн50!T10+ООН51!T10+Форшахта!T10+'ГАлерея 25.6'!T10+ГРП!AI10+'Парк меляси'!T10+'ООН 42'!T10 -> 138 | J12: 150
A13: 10 | B13: Скрипник Олександр Павлович | D13: 3927 | E13: =I13*J13 -> 19050 | F13: =SUMIF('[1]Табель цех 1 по 15 вересня'!$B:$B,B13,'[1]Табель цех 1 по 15 вересня'!$H:$H) -> -25 | G13: =IF(ROUND(E13+F13-C13-D13,-2)<0,0,ROUND(E13+F13-C13-D13,-2)) -> 15100 | H13: =F13+E13-D13-G13-C13 -> -2 | I13: =_ЦО!T11+'МХП лазня'!T11+Катеринополь!T11+ВООЗ!T11+Кернел!T11+'Глобино Мк'!T11+'ВООЗ ЕМС'!T11+'ООН 36'!T11+'ООН 37'!T11+'ООН 38'!T11+ООН39!T11+'ООН 40'!T11+'ООН №43'!T11+'ООН 44'!T11+'ООН 45'!V11+ООН46!T11+ООН47!T11+ООН48!T11+ООН49!T11+ООн50!T11+ООН51!T11+Форшахта!T11+'ГАлерея 25.6'!T11+ГРП!AI11+'Парк меляси'!T11+'ООН 42'!T11 -> 127 | J13: 150
A14: 11 | B14: Паламарчук Вячеслав Володимирович | D14: 14676.63 | E14: =I14*J14 -> 19800 | F14: =SUMIF('[1]Табель цех 1 по 15 вересня'!$B:$B,B14,'[1]Табель цех 1 по 15 вересня'!$H:$H) -> -36.63 | G14: =IF(ROUND(E14+F14-C14-D14,-2)<0,0,ROUND(E14+F14-C14-D14,-2)) -> 5100 | H14: =F14+E14-D14-G14-C14 -> -13.26 | I14: =_ЦО!T12+'МХП лазня'!T12+Катеринополь!T12+ВООЗ!T12+Кернел!T12+'Глобино Мк'!T12+'ВООЗ ЕМС'!T12+'ООН 36'!T12+'ООН 37'!T12+'ООН 38'!T12+ООН39!T12+'ООН 40'!T12+'ООН №43'!T12+'ООН 44'!T12+'ООН 45'!V12+ООН46!T12+ООН47!T12+ООН48!T12+ООН49!T12+ООн50!T12+ООН51!T12+Форшахта!T12+'ГАлерея 25.6'!T12+ГРП!AI12+'Парк меляси'!T12+'ООН 42'!T12 -> 132 | J14: 150
A15: 12 | B15: Дехтяр Владислав Олександрович | C15: 10324.25 | D15: 3927 | E15: =I15*J15 -> 54000 | F15: =SUMIF('[1]Табель цех 1 по 15 вересня'!$B:$B,B15,'[1]Табель цех 1 по 15 вересня'!$H:$H) -> -21.27 | G15: =IF(ROUND(E15+F15-C15-D15,-2)<0,0,ROUND(E15+F15-C15-D15,-2)) -> 39700 | H15: =F15+E15-D15-G15-C15 -> 27.48 | I15: =_ЦО!T13+'МХП лазня'!T13+Катеринополь!T13+ВООЗ!T13+Кернел!T13+'Глобино Мк'!T13+'ВООЗ ЕМС'!T13+'ООН 36'!T13+'ООН 37'!T13+'ООН 38'!T13+ООН39!T13+'ООН 40'!T13+'ООН №43'!T13+'ООН 44'!T13+'ООН 45'!V13+ООН46!T13+ООН47!T13+ООН48!T13+ООН49!T13+ООн50!T13+ООН51!T13+Форшахта!T13+'ГАлерея 25.6'!T13+ГРП!AI13+'Парк меляси'!T13+'ООН 42'!T13 -> 360 | J15: 150
A16: 13 | B16: Тужиков Валерій Владиславович | D16: 4575.09 | E16: =I16*J16 -> 17400 | F16: =SUMIF('[1]Табель цех 1 по 15 вересня'!$B:$B,B16,'[1]Табель цех 1 по 15 вересня'!$H:$H) -> -40.34 | G16: =IF(ROUND(E16+F16-C16-D16,-2)<0,0,ROUND(E16+F16-C16-D16,-2)) -> 12800 | H16: =F16+E16-D16-G16-C16 -> -15.43 | I16: =_ЦО!T14+'МХП лазня'!T14+Катеринополь!T14+ВООЗ!T14+Кернел!T14+'Глобино Мк'!T14+'ВООЗ ЕМС'!T14+'ООН 36'!T14+'ООН 37'!T14+'ООН 38'!T14+ООН39!T14+'ООН 40'!T14+'ООН №43'!T14+'ООН 44'!T14+'ООН 45'!V14+ООН46!T14+ООН47!T14+ООН48!T14+ООН49!T14+ООн50!T14+ООН51!T14+Форшахта!T14+'ГАлерея 25.6'!T14+ГРП!AI14+'Парк меляси'!T14+'ООН 42'!T14 -> 116 | J16: 150
A17: 14 | B17: Сівов Євген Миколайович | D17: 3927 | E17: =I17*J17 -> 27300 | F17: =SUMIF('[1]Табель цех 1 по 15 вересня'!$B:$B,B17,'[1]Табель цех 1 по 15 вересня'!$H:$H) -> 37.77 | G17: =IF(ROUND(E17+F17-C17-D17,-2)<0,0,ROUND(E17+F17-C17-D17,-2)) -> 23400 | H17: =F17+E17-D17-G17-C17 -> 10.77 | I17: =_ЦО!T15+'МХП лазня'!T15+Катеринополь!T15+ВООЗ!T15+Кернел!T15+'Глобино Мк'!T15+'ВООЗ ЕМС'!T15+'ООН 36'!T15+'ООН 37'!T15+'ООН 38'!T15+ООН39!T15+'ООН 40'!T15+'ООН №43'!T15+'ООН 44'!T15+'ООН 45'!V15+ООН46!T15+ООН47!T15+ООН48!T15+ООН49!T15+ООн50!T15+ООН51!T15+Форшахта!T15+'ГАлерея 25.6'!T15+ГРП!AI15+'Парк меляси'!T15+'ООН 42'!T15 -> 182 | J17: 150
A18: 15 | B18: Кіфор Юрій Михайлович | D18: 3927 | E18: =I18*J18 -> 19050 | F18: =SUMIF('[1]Табель цех 1 по 15 вересня'!$B:$B,B18,'[1]Табель цех 1 по 15 вересня'!$H:$H) -> -15.5 | G18: =IF(ROUND(E18+F18-C18-D18,-2)<0,0,ROUND(E18+F18-C18-D18,-2)) -> 15100 | H18: =F18+E18-D18-G18-C18 -> 7.5 | I18: =_ЦО!T16+'МХП лазня'!T16+Катеринополь!T16+ВООЗ!T16+Кернел!T16+'Глобино Мк'!T16+'ВООЗ ЕМС'!T16+'ООН 36'!T16+'ООН 37'!T16+'ООН 38'!T16+ООН39!T16+'ООН 40'!T16+'ООН №43'!T16+'ООН 44'!T16+'ООН 45'!V16+ООН46!T16+ООН47!T16+ООН48!T16+ООН49!T16+ООн50!T16+ООН51!T16+Форшахта!T16+'ГАлерея 25.6'!T16+ГРП!AI16+'Парк меляси'!T16+'ООН 42'!T16 -> 127 | J18: 150
A19: 16 | B19: Петренко Микола Григорович | D19: 9625 | E19: =I19*J19 -> 14700 | F19: =SUMIF('[1]Табель цех 1 по 15 вересня'!$B:$B,B19,'[1]Табель цех 1 по 15 вересня'!$H:$H) -> -41.49 | G19: =IF(ROUND(E19+F19-C19-D19,-2)<0,0,ROUND(E19+F19-C19-D19,-2)) -> 5000 | H19: =F19+E19-D19-G19-C19 -> 33.51 | I19: =_ЦО!T17+'МХП лазня'!T17+Катеринополь!T17+ВООЗ!T17+Кернел!T17+'Глобино Мк'!T17+'ВООЗ ЕМС'!T17+'ООН 36'!T17+'ООН 37'!T17+'ООН 38'!T17+ООН39!T17+'ООН 40'!T17+'ООН №43'!T17+'ООН 44'!T17+'ООН 45'!V17+ООН46!T17+ООН47!T17+ООН48!T17+ООН49!T17+ООн50!T17+ООН51!T17+Форшахта!T17+'ГАлерея 25.6'!T17+ГРП!AI17+'Парк меляси'!T17+'ООН 42'!T17 -> 98 | J19: 150
A20: 17 | B20: Рубленко Микола Іванович | D20: 3927 | E20: =I20*J20 -> 17850 | F20: =SUMIF('[1]Табель цех 1 по 15 вересня'!$B:$B,B20,'[1]Табель цех 1 по 15 вересня'!$H:$H) -> 34.5 | G20: =IF(ROUND(E20+F20-C20-D20,-2)<0,0,ROUND(E20+F20-C20-D20,-2)) -> 14000 | H20: =F20+E20-D20-G20-C20 -> -42.5 | I20: =_ЦО!T18+'МХП лазня'!T18+Катеринополь!T18+ВООЗ!T18+Кернел!T18+'Глобино Мк'!T18+'ВООЗ ЕМС'!T18+'ООН 36'!T18+'ООН 37'!T18+'ООН 38'!T18+ООН39!T18+'ООН 40'!T18+'ООН №43'!T18+'ООН 44'!T18+'ООН 45'!V18+ООН46!T18+ООН47!T18+ООН48!T18+ООН49!T18+ООн50!T18+ООН51!T18+Форшахта!T18+'ГАлерея 25.6'!T18+ГРП!AI18+'Парк меляси'!T18+'ООН 42'!T18 -> 119 | J20: 150
A21: 18 | B21: Серебренніков Володимир Олександрович | D21: 3927 | E21: =I21*J21 -> 10200 | F21: =SUMIF('[1]Табель цех 1 по 15 вересня'!$B:$B,B21,'[1]Табель цех 1 по 15 вересня'!$H:$H) -> 10.52 | G21: =IF(ROUND(E21+F21-C21-D21,-2)<0,0,ROUND(E21+F21-C21-D21,-2)) -> 6300 | H21: =F21+E21-D21-G21-C21 -> -16.48 | I21: =_ЦО!T19+'МХП лазня'!T19+Катеринополь!T19+ВООЗ!T19+Кернел!T19+'Глобино Мк'!T19+'ВООЗ ЕМС'!T19+'ООН 36'!T19+'ООН 37'!T19+'ООН 38'!T19+ООН39!T19+'ООН 40'!T19+'ООН №43'!T19+'ООН 44'!T19+'ООН 45'!V19+ООН46!T19+ООН47!T19+ООН48!T19+ООН49!T19+ООн50!T19+ООН51!T19+Форшахта!T19+'ГАлерея 25.6'!T19+ГРП!AI19+'Парк меляси'!T19+'ООН 42'!T19 -> 68 | J21: 150
A22: 19 | B22: Чешко Сергій Анатолійович | D22: 8662.5 | E22: =I22*J22 -> 50400 | F22: =SUMIF('[1]Табель цех 1 по 15 вересня'!$B:$B,B22,'[1]Табель цех 1 по 15 вересня'!$H:$H) -> -4239.34 | G22: =IF(ROUND(E22+F22-C22-D22,-2)<0,0,ROUND(E22+F22-C22-D22,-2)) -> 37500 | H22: =F22+E22-D22-G22-C22 -> -1.84 | I22: =_ЦО!T20+'МХП лазня'!T20+Катеринополь!T20+ВООЗ!T20+Кернел!T20+'Глобино Мк'!T20+'ВООЗ ЕМС'!T20+'ООН 36'!T20+'ООН 37'!T20+'ООН 38'!T20+ООН39!T20+'ООН 40'!T20+'ООН №43'!T20+'ООН 44'!T20+'ООН 45'!V20+ООН46!T20+ООН47!T20+ООН48!T20+ООН49!T20+ООн50!T20+ООН51!T20+Форшахта!T20+'ГАлерея 25.6'!T20+ГРП!AI20+'Парк меляси'!T20+'ООН 42'!T20 -> 336 | J22: 150
A23: 20 | B23: Нерезенко Євгеній Віктоорович | D23: 0 | E23: =I23*J23 -> 0 | F23: =SUMIF('[1]Табель цех 1 по 15 вересня'!$B:$B,B23,'[1]Табель цех 1 по 15 вересня'!$H:$H) -> 46 | G23: =IF(ROUND(E23+F23-C23-D23,-2)<0,0,ROUND(E23+F23-C23-D23,-2)) -> 0 | H23: =F23+E23-D23-G23-C23 -> 46 | I23: =_ЦО!T21+'МХП лазня'!T21+Катеринополь!T21+ВООЗ!T21+Кернел!T21+'Глобино Мк'!T21+'ВООЗ ЕМС'!T21+'ООН 36'!T21+'ООН 37'!T21+'ООН 38'!T21+ООН39!T21+'ООН 40'!T21+'ООН №43'!T21+'ООН 44'!T21+'ООН 45'!V21+ООН46!T21+ООН47!T21+ООН48!T21+ООН49!T21+ООн50!T21+ООН51!T21+Форшахта!T21+'ГАлерея 25.6'!T21+ГРП!AI21+'Парк меляси'!T21+'ООН 42'!T21 -> 0 | J23: 150
A24: 21 | B24: Шавкун Максим Анатолійович | D24: 9625 | E24: =I24*J24 -> 50400 | F24: =SUMIF('[1]Табель цех 1 по 15 вересня'!$B:$B,B24,'[1]Табель цех 1 по 15 вересня'!$H:$H) -> -2224.26 | G24: =IF(ROUND(E24+F24-C24-D24,-2)<0,0,ROUND(E24+F24-C24-D24,-2)) -> 38600 | H24: =F24+E24-D24-G24-C24 -> -49.26 | I24: =_ЦО!T22+'МХП лазня'!T22+Катеринополь!T22+ВООЗ!T22+Кернел!T22+'Глобино Мк'!T22+'ВООЗ ЕМС'!T22+'ООН 36'!T22+'ООН 37'!T22+'ООН 38'!T22+ООН39!T22+'ООН 40'!T22+'ООН №43'!T22+'ООН 44'!T22+'ООН 45'!V22+ООН46!T22+ООН47!T22+ООН48!T22+ООН49!T22+ООн50!T22+ООН51!T22+Форшахта!T22+'ГАлерея 25.6'!T22+ГРП!AI22+'Парк меляси'!T22+'ООН 42'!T22 -> 336 | J24: 150
A25: 22 | B25: Чуйко Олег Олегович | D25: 3927 | E25: =I25*J25 -> 20100 | F25: =SUMIF('[1]Табель цех 1 по 15 вересня'!$B:$B,B25,'[1]Табель цех 1 по 15 вересня'!$H:$H) -> -15 | G25: =IF(ROUND(E25+F25-C25-D25,-2)<0,0,ROUND(E25+F25-C25-D25,-2)) -> 16200 | H25: =F25+E25-D25-G25-C25 -> -42 | I25: =_ЦО!T23+'МХП лазня'!T23+Катеринополь!T23+ВООЗ!T23+Кернел!T23+'Глобино Мк'!T23+'ВООЗ ЕМС'!T23+'ООН 36'!T23+'ООН 37'!T23+'ООН 38'!T23+ООН39!T23+'ООН 40'!T23+'ООН №43'!T23+'ООН 44'!T23+'ООН 45'!V23+ООН46!T23+ООН47!T23+ООН48!T23+ООН49!T23+ООн50!T23+ООН51!T23+Форшахта!T23+'ГАлерея 25.6'!T23+ГРП!AI23+'Парк меляси'!T23+'ООН 42'!T23 -> 134 | J25: 150
A26: 23 | B26: Салюк Дмитро Андрійович | E26: =I26*J26 -> 14850 | F26: =SUMIF('[1]Табель цех 1 по 15 вересня'!$B:$B,B26,'[1]Табель цех 1 по 15 вересня'!$H:$H) -> 20 | G26: =IF(ROUND(E26+F26-C26-D26,-2)<0,0,ROUND(E26+F26-C26-D26,-2)) -> 14900 | H26: =F26+E26-D26-G26-C26 -> -30 | I26: =_ЦО!T24+'МХП лазня'!T24+Катеринополь!T24+ВООЗ!T24+Кернел!T24+'Глобино Мк'!T24+'ВООЗ ЕМС'!T24+'ООН 36'!T24+'ООН 37'!T24+'ООН 38'!T24+ООН39!T24+'ООН 40'!T24+'ООН №43'!T24+'ООН 44'!T24+'ООН 45'!V24+ООН46!T24+ООН47!T24+ООН48!T24+ООН49!T24+ООн50!T24+ООН51!T24+Форшахта!T24+'ГАлерея 25.6'!T24+ГРП!AI24+'Парк меляси'!T24+'ООН 42'!T24 -> 99 | J26: 150
A27: 24 | B27: Маковецький Юрій Миколайович | D27: 2887.5 | E27: =I27*J27 -> 25800 | F27: =SUMIF('[1]Табель цех 1 по 15 вересня'!$B:$B,B27,'[1]Табель цех 1 по 15 вересня'!$H:$H) -> -40.18 | G27: =IF(ROUND(E27+F27-C27-D27,-2)<0,0,ROUND(E27+F27-C27-D27,-2)) -> 22900 | H27: =F27+E27-D27-G27-C27 -> -27.68 | I27: =_ЦО!T25+'МХП лазня'!T25+Катеринополь!T25+ВООЗ!T25+Кернел!T25+'Глобино Мк'!T25+'ВООЗ ЕМС'!T25+'ООН 36'!T25+'ООН 37'!T25+'ООН 38'!T25+ООН39!T25+'ООН 40'!T25+'ООН №43'!T25+'ООН 44'!T25+'ООН 45'!V25+ООН46!T25+ООН47!T25+ООН48!T25+ООН49!T25+ООн50!T25+ООН51!T25+Форшахта!T25+'ГАлерея 25.6'!T25+ГРП!AI25+'Парк меляси'!T25+'ООН 42'!T25 -> 172 | J27: 150
A28: 25 | B28: Міненко Олександр Андрійович | E28: =I28*J28 -> 16200 | F28: =SUMIF('[1]Табель цех 1 по 15 вересня'!$B:$B,B28,'[1]Табель цех 1 по 15 вересня'!$H:$H) -> 0 | G28: =IF(ROUND(E28+F28-C28-D28,-2)<0,0,ROUND(E28+F28-C28-D28,-2)) -> 16200 | H28: =F28+E28-D28-G28-C28 -> 0 | I28: =_ЦО!T26+'МХП лазня'!T26+Катеринополь!T26+ВООЗ!T26+Кернел!T26+'Глобино Мк'!T26+'ВООЗ ЕМС'!T26+'ООН 36'!T26+'ООН 37'!T26+'ООН 38'!T26+ООН39!T26+'ООН 40'!T26+'ООН №43'!T26+'ООН 44'!T26+'ООН 45'!V26+ООН46!T26+ООН47!T26+ООН48!T26+ООН49!T26+ООн50!T26+ООН51!T26+Форшахта!T26+'ГАлерея 25.6'!T26+ГРП!AI26+'Парк меляси'!T26+'ООН 42'!T26 -> 108 | J28: 150
A29: 26 | B29: Салій Дмитро Миколайович | E29: =I29*J29 -> 16200 | F29: =SUMIF('[1]Табель цех 1 по 15 вересня'!$B:$B,B29,'[1]Табель цех 1 по 15 вересня'!$H:$H) -> 0 | G29: =IF(ROUND(E29+F29-C29-D29,-2)<0,0,ROUND(E29+F29-C29-D29,-2)) -> 16200 | H29: =F29+E29-D29-G29-C29 -> 0 | I29: =_ЦО!T27+'МХП лазня'!T27+Катеринополь!T27+ВООЗ!T27+Кернел!T27+'Глобино Мк'!T27+'ВООЗ ЕМС'!T27+'ООН 36'!T27+'ООН 37'!T27+'ООН 38'!T27+ООН39!T27+'ООН 40'!T27+'ООН №43'!T27+'ООН 44'!T27+'ООН 45'!V27+ООН46!T27+ООН47!T27+ООН48!T27+ООН49!T27+ООн50!T27+ООН51!T27+Форшахта!T27+'ГАлерея 25.6'!T27+ГРП!AI27+'Парк меляси'!T27+'ООН 42'!T27 -> 108 | J29: 150
A30: 27 | B30: Різніченко Олег Олександрович | E30: =I30*J30 -> 23400 | F30: =SUMIF('[1]Табель цех 1 по 15 вересня'!$B:$B,B30,'[1]Табель цех 1 по 15 вересня'!$H:$H) -> -30 | G30: =IF(ROUND(E30+F30-C30-D30,-2)<0,0,ROUND(E30+F30-C30-D30,-2)) -> 23400 | H30: =F30+E30-D30-G30-C30 -> -30 | I30: =_ЦО!T28+'МХП лазня'!T28+Катеринополь!T28+ВООЗ!T28+Кернел!T28+'Глобино Мк'!T28+'ВООЗ ЕМС'!T28+'ООН 36'!T28+'ООН 37'!T28+'ООН 38'!T28+ООН39!T28+'ООН 40'!T28+'ООН №43'!T28+'ООН 44'!T28+'ООН 45'!V28+ООН46!T28+ООН47!T28+ООН48!T28+ООН49!T28+ООн50!T28+ООН51!T28+Форшахта!T28+'ГАлерея 25.6'!T28+ГРП!AI28+'Парк меляси'!T28+'ООН 42'!T28 -> 156 | J30: 150
A31: 28 | B31: Рогозовець Андрій Вікторович | D31: 3927 | E31: =I31*J31 -> 29250 | F31: =SUMIF('[1]Табель цех 1 по 15 вересня'!$B:$B,B31,'[1]Табель цех 1 по 15 вересня'!$H:$H) -> -15 | G31: =IF(ROUND(E31+F31-C31-D31,-2)<0,0,ROUND(E31+F31-C31-D31,-2)) -> 25300 | H31: =F31+E31-D31-G31-C31 -> 8 | I31: =_ЦО!T29+'МХП лазня'!T29+Катеринополь!T29+ВООЗ!T29+Кернел!T29+'Глобино Мк'!T29+'ВООЗ ЕМС'!T29+'ООН 36'!T29+'ООН 37'!T29+'ООН 38'!T29+ООН39!T29+'ООН 40'!T29+'ООН №43'!T29+'ООН 44'!T29+'ООН 45'!V29+ООН46!T29+ООН47!T29+ООН48!T29+ООН49!T29+ООн50!T29+ООН51!T29+Форшахта!T29+'ГАлерея 25.6'!T29+ГРП!AI29+'Парк меляси'!T29+'ООН 42'!T29 -> 195 | J31: 150
A32: 29 | B32: Старков Кирило Юрійович | E32: =I32*J32 -> 0 | F32: =SUMIF('[1]Табель цех 1 по 15 вересня'!$B:$B,B32,'[1]Табель цех 1 по 15 вересня'!$H:$H) -> 0 | G32: =IF(ROUND(E32+F32-C32-D32,-2)<0,0,ROUND(E32+F32-C32-D32,-2)) -> 0 | H32: =F32+E32-D32-G32-C32 -> 0 | I32: =_ЦО!T30+'МХП лазня'!T30+Катеринополь!T30+ВООЗ!T30+Кернел!T30+'Глобино Мк'!T30+'ВООЗ ЕМС'!T30+'ООН 36'!T30+'ООН 37'!T30+'ООН 38'!T30+ООН39!T30+'ООН 40'!T30+'ООН №43'!T30+'ООН 44'!T30+'ООН 45'!V30+ООН46!T30+ООН47!T30+ООН48!T30+ООН49!T30+ООн50!T30+ООН51!T30+Форшахта!T30+'ГАлерея 25.6'!T30+ГРП!AI30+'Парк меляси'!T30+'ООН 42'!T30 -> 0 | J32: 150
A33: 30 | B33: Зубахін Сергій Александрович | E33: =I33*J33 -> 0 | F33: =SUMIF('[1]Табель цех 1 по 15 вересня'!$B:$B,B33,'[1]Табель цех 1 по 15 вересня'!$H:$H) -> 0 | G33: =IF(ROUND(E33+F33-C33-D33,-2)<0,0,ROUND(E33+F33-C33-D33,-2)) -> 0 | H33: =F33+E33-D33-G33-C33 -> 0 | I33: =_ЦО!T31+'МХП лазня'!T31+Катеринополь!T31+ВООЗ!T31+Кернел!T31+'Глобино Мк'!T31+'ВООЗ ЕМС'!T31+'ООН 36'!T31+'ООН 37'!T31+'ООН 38'!T31+ООН39!T31+'ООН 40'!T31+'ООН №43'!T31+'ООН 44'!T31+'ООН 45'!V31+ООН46!T31+ООН47!T31+ООН48!T31+ООН49!T31+ООн50!T31+ООН51!T31+Форшахта!T31+'ГАлерея 25.6'!T31+ГРП!AI31+'Парк меляси'!T31+'ООН 42'!T31 -> 0 | J33: 150
A34: 31 | B34: Корнієнко Віталій Олегович | D34: 9625 | E34: =I34*J34 -> 14550 | F34: =SUMIF('[1]Табель цех 1 по 15 вересня'!$B:$B,B34,'[1]Табель цех 1 по 15 вересня'!$H:$H) -> -4.8 | G34: =IF(ROUND(E34+F34-C34-D34,-2)<0,0,ROUND(E34+F34-C34-D34,-2)) -> 4900 | H34: =F34+E34-D34-G34-C34 -> 20.2 | I34: =_ЦО!T32+'МХП лазня'!T32+Катеринополь!T32+ВООЗ!T32+Кернел!T32+'Глобино Мк'!T32+'ВООЗ ЕМС'!T32+'ООН 36'!T32+'ООН 37'!T32+'ООН 38'!T32+ООН39!T32+'ООН 40'!T32+'ООН №43'!T32+'ООН 44'!T32+'ООН 45'!V32+ООН46!T32+ООН47!T32+ООН48!T32+ООН49!T32+ООн50!T32+ООН51!T32+Форшахта!T32+'ГАлерея 25.6'!T32+ГРП!AI32+'Парк меляси'!T32+'ООН 42'!T32 -> 97 | J34: 150
A35: 32 | B35: Щербак Петро Іванович | E35: =I35*J35 -> 19800 | F35: =SUMIF('[1]Табель цех 1 по 15 вересня'!$B:$B,B35,'[1]Табель цех 1 по 15 вересня'!$H:$H) -> 0 | G35: =IF(ROUND(E35+F35-C35-D35,-2)<0,0,ROUND(E35+F35-C35-D35,-2)) -> 19800 | H35: =F35+E35-D35-G35-C35 -> 0 | I35: =_ЦО!T33+'МХП лазня'!T33+Катеринополь!T33+ВООЗ!T33+Кернел!T33+'Глобино Мк'!T33+'ВООЗ ЕМС'!T33+'ООН 36'!T33+'ООН 37'!T33+'ООН 38'!T33+ООН39!T33+'ООН 40'!T33+'ООН №43'!T33+'ООН 44'!T33+'ООН 45'!V33+ООН46!T33+ООН47!T33+ООН48!T33+ООН49!T33+ООн50!T33+ООН51!T33+Форшахта!T33+'ГАлерея 25.6'!T33+ГРП!AI33+'Парк меляси'!T33+'ООН 42'!T33 -> 132 | J35: 150
A36: 33 | B36: Онучак Віктор Іванович | D36: 3927 | E36: =I36*J36 -> 22350 | F36: =SUMIF('[1]Табель цех 1 по 15 вересня'!$B:$B,B36,'[1]Табель цех 1 по 15 вересня'!$H:$H) -> 15 | G36: =IF(ROUND(E36+F36-C36-D36,-2)<0,0,ROUND(E36+F36-C36-D36,-2)) -> 18400 | H36: =F36+E36-D36-G36-C36 -> 38 | I36: =_ЦО!T34+'МХП лазня'!T34+Катеринополь!T34+ВООЗ!T34+Кернел!T34+'Глобино Мк'!T34+'ВООЗ ЕМС'!T34+'ООН 36'!T34+'ООН 37'!T34+'ООН 38'!T34+ООН39!T34+'ООН 40'!T34+'ООН №43'!T34+'ООН 44'!T34+'ООН 45'!V34+ООН46!T34+ООН47!T34+ООН48!T34+ООН49!T34+ООн50!T34+ООН51!T34+Форшахта!T34+'ГАлерея 25.6'!T34+ГРП!AI34+'Парк меляси'!T34+'ООН 42'!T34 -> 149 | J36: 150
A37: 34 | B37: Батрак Віктор Володимирович | D37: 9624.99 | E37: =I37*J37 -> 19800 | F37: =SUMIF('[1]Табель цех 1 по 15 вересня'!$B:$B,B37,'[1]Табель цех 1 по 15 вересня'!$H:$H) -> 22.06 | G37: =IF(ROUND(E37+F37-C37-D37,-2)<0,0,ROUND(E37+F37-C37-D37,-2)) -> 10200 | H37: =F37+E37-D37-G37-C37 -> -2.93 | I37: =_ЦО!T35+'МХП лазня'!T35+Катеринополь!T35+ВООЗ!T35+Кернел!T35+'Глобино Мк'!T35+'ВООЗ ЕМС'!T35+'ООН 36'!T35+'ООН 37'!T35+'ООН 38'!T35+ООН39!T35+'ООН 40'!T35+'ООН №43'!T35+'ООН 44'!T35+'ООН 45'!V35+ООН46!T35+ООН47!T35+ООН48!T35+ООН49!T35+ООн50!T35+ООН51!T35+Форшахта!T35+'ГАлерея 25.6'!T35+ГРП!AI35+'Парк меляси'!T35+'ООН 42'!T35 -> 132 | J37: 150
A38: 35 | B38: Бондаренко Іван Олександрович | D38: 0 | E38: =I38*J38 -> 0 | F38: =SUMIF('[1]Табель цех 1 по 15 вересня'!$B:$B,B38,'[1]Табель цех 1 по 15 вересня'!$H:$H) -> -44 | G38: =IF(ROUND(E38+F38-C38-D38,-2)<0,0,ROUND(E38+F38-C38-D38,-2)) -> 0 | H38: =F38+E38-D38-G38-C38 -> -44 | I38: =_ЦО!T36+'МХП лазня'!T36+Катеринополь!T36+ВООЗ!T36+Кернел!T36+'Глобино Мк'!T36+'ВООЗ ЕМС'!T36+'ООН 36'!T36+'ООН 37'!T36+'ООН 38'!T36+ООН39!T36+'ООН 40'!T36+'ООН №43'!T36+'ООН 44'!T36+'ООН 45'!V36+ООН46!T36+ООН47!T36+ООН48!T36+ООН49!T36+ООн50!T36+ООН51!T36+Форшахта!T36+'ГАлерея 25.6'!T36+ГРП!AI36+'Парк меляси'!T36+'ООН 42'!T36 -> 0 | J38: 150
A39: 36 | B39: Підлісний Володимир Сергійович | D39: 3927 | E39: =I39*J39 -> 18900 | F39: =SUMIF('[1]Табель цех 1 по 15 вересня'!$B:$B,B39,'[1]Табель цех 1 по 15 вересня'!$H:$H) -> 15 | G39: =IF(ROUND(E39+F39-C39-D39,-2)<0,0,ROUND(E39+F39-C39-D39,-2)) -> 15000 | H39: =F39+E39-D39-G39-C39 -> -12 | I39: =_ЦО!T37+'МХП лазня'!T37+Катеринополь!T37+ВООЗ!T37+Кернел!T37+'Глобино Мк'!T37+'ВООЗ ЕМС'!T37+'ООН 36'!T37+'ООН 37'!T37+'ООН 38'!T37+ООН39!T37+'ООН 40'!T37+'ООН №43'!T37+'ООН 44'!T37+'ООН 45'!V37+ООН46!T37+ООН47!T37+ООН48!T37+ООН49!T37+ООн50!T37+ООН51!T37+Форшахта!T37+'ГАлерея 25.6'!T37+ГРП!AI37+'Парк меляси'!T37+'ООН 42'!T37 -> 126 | J39: 150
A40: 37 | B40: Григоренко Ілля Олександрович | D40: 3141.6 | E40: =I40*J40 -> 12450 | F40: =SUMIF('[1]Табель цех 1 по 15 вересня'!$B:$B,B40,'[1]Табель цех 1 по 15 вересня'!$H:$H) -> 32.01 | G40: =IF(ROUND(E40+F40-C40-D40,-2)<0,0,ROUND(E40+F40-C40-D40,-2)) -> 9300 | H40: =F40+E40-D40-G40-C40 -> 40.41 | I40: =_ЦО!T38+'МХП лазня'!T38+Катеринополь!T38+ВООЗ!T38+Кернел!T38+'Глобино Мк'!T38+'ВООЗ ЕМС'!T38+'ООН 36'!T38+'ООН 37'!T38+'ООН 38'!T38+ООН39!T38+'ООН 40'!T38+'ООН №43'!T38+'ООН 44'!T38+'ООН 45'!V38+ООН46!T38+ООН47!T38+ООН48!T38+ООН49!T38+ООн50!T38+ООН51!T38+Форшахта!T38+'ГАлерея 25.6'!T38+ГРП!AI38+'Парк меляси'!T38+'ООН 42'!T38 -> 83 | J40: 150
...

Sheet ИТР
A1: N | B1: Сотрудник | C1: 16 | D1: 17 | E1: 18 | F1: 19 | G1: 20 | H1: 21 | I1: 22 | J1: 23 | K1: 24 | L1: 25 | M1: 26 | N1: 27 | O1: 28 | P1: 29 | Q1: 30
A2: 9 | B2: Скрипник Сергій Павлович | I2: 11 | J2: 11 | K2: 11 | L2: 11 | M2: 11 | N2: 6 | P2: 11 | Q2: 11 | R2: =C2+D2+E2+F2+G2+H2+I2+J2+K2+L2+M2+N2+O2+P2+Q2 -> 83
A3: 10 | B3: Пономаренко Віталій Вікторович | C3: 11 | D3: 11 | E3: 11 | F3: 11 | G3: 11 | K3: 11 | L3: 11 | M3: 11 | N3: 6 | P3: 11 | Q3: 11 | R3: =C3+D3+E3+F3+G3+H3+I3+J3+K3+L3+M3+N3+O3+P3+Q3 -> 116

Sheet _ЦО
A1: N | B1: Сотрудник | C1: 16 | D1: 17 | E1: 18 | F1: 19 | G1: 20 | H1: 21 | I1: 22 | J1: 23 | K1: 24 | L1: 25 | M1: 26 | N1: 27 | O1: 28 | P1: 29 | Q1: 30
A2: 1 | B2: Багацький Вадим Геннадійович | T2: =C2+D2+E2+F2+G2+H2+I2+J2+K2+L2+M2+N2+O2+P2+Q2 -> 0
A3: 2 | B3: Васильєв Віталій Юрійович | D3: 11 | E3: 11 | F3: 11 | G3: 9 | I3: 11 | J3: 9 | K3: 9 | L3: 11 | M3: 11 | N3: 6 | P3: 11 | Q3: 9 | T3: =C3+D3+E3+F3+G3+H3+I3+J3+K3+L3+M3+N3+O3+P3+Q3 -> 119
A4: 3 | B4: Григоренко Олександр Миколайович | T4: =C4+D4+E4+F4+G4+H4+I4+J4+K4+L4+M4+N4+O4+P4+Q4 -> 0
A5: 4 | B5: Григорьєв Микола Андрійович | T5: =C5+D5+E5+F5+G5+H5+I5+J5+K5+L5+M5+N5+O5+P5+Q5 -> 0
A6: 5 | B6: Григор'єв Михайло Андрійович | T6: =C6+D6+E6+F6+G6+H6+I6+J6+K6+L6+M6+N6+O6+P6+Q6 -> 0
A7: 6 | B7: Іванов Олексій Вікторович | T7: =C7+D7+E7+F7+G7+H7+I7+J7+K7+L7+M7+N7+O7+P7+Q7 -> 0
A8: 7 | B8: Іскрицький Денис Русланович | T8: =C8+D8+E8+F8+G8+H8+I8+J8+K8+L8+M8+N8+O8+P8+Q8 -> 0
A9: 8 | B9: Корнієнко Станіслав Володимирович | T9: =C9+D9+E9+F9+G9+H9+I9+J9+K9+L9+M9+N9+O9+P9+Q9 -> 0
A10: 9 | B10: Масливець Ігор Валерійович | T10: =C10+D10+E10+F10+G10+H10+I10+J10+K10+L10+M10+N10+O10+P10+Q10 -> 0
A11: 10 | B11: Скрипник Олександр Павлович | T11: =C11+D11+E11+F11+G11+H11+I11+J11+K11+L11+M11+N11+O11+P11+Q11 -> 0
A12: 11 | B12: Паламарчук Вячеслав Володимирович | T12: =C12+D12+E12+F12+G12+H12+I12+J12+K12+L12+M12+N12+O12+P12+Q12 -> 0
A13: 12 | B13: Дехтяр Владислав Олександрович | T13: =C13+D13+E13+F13+G13+H13+I13+J13+K13+L13+M13+N13+O13+P13+Q13 -> 0
A14: 13 | B14: Тужиков Валерій Владиславович | T14: =C14+D14+E14+F14+G14+H14+I14+J14+K14+L14+M14+N14+O14+P14+Q14 -> 0
A15: 14 | B15: Сівов Євген Миколайович | T15: =C15+D15+E15+F15+G15+H15+I15+J15+K15+L15+M15+N15+O15+P15+Q15 -> 0
... A27: 26 | B27: Салій Дмитро Миколайович | T27: =C27+D27+E27+F27+G27+H27+I27+J27+K27+L27+M27+N27+O27+P27+Q27 -> 0
A28: 27 | B28: Різніченко Олег Олександрович | D28: 9 | T28: =C28+D28+E28+F28+G28+H28+I28+J28+K28+L28+M28+N28+O28+P28+Q28 -> 9
A29: 28 | B29: Рогозовець Андрій Вікторович | T29: =C29+D29+E29+F29+G29+H29+I29+J29+K29+L29+M29+N29+O29+P29+Q29 -> 0
A30: 29 | B30: Старков Кирило Юрійович | T30: =C30+D30+E30+F30+G30+H30+I30+J30+K30+L30+M30+N30+O30+P30+Q30 -> 0
A31: 30 | B31: Зубахін Сергій Александрович | T31: =C31+D31+E31+F31+G31+H31+I31+J31+K31+L31+M31+N31+O31+P31+Q31 -> 0
A32: 31 | B32: Корнієнко Віталій Олегович | T32: =C32+D32+E32+F32+G32+H32+I32+J32+K32+L32+M32+N32+O32+P32+Q32 -> 0
A33: 32 | B33: Щербак Петро Іванович | T33: =C33+D33+E33+F33+G33+H33+I33+J33+K33+L33+M33+N33+O33+P33+Q33 -> 0
A34: 33 | B34: Онучак Віктор Іванович | T34: =C34+D34+E34+F34+G34+H34+I34+J34+K34+L34+M34+N34+O34+P34+Q34 -> 0
A35: 34 | B35: Батрак Віктор Володимирович | T35: =C35+D35+E35+F35+G35+H35+I35+J35+K35+L35+M35+N35+O35+P35+Q35 -> 0
A36: 35 | B36: Бондаренко Іван Олександрович | T36: =C36+D36+E36+F36+G36+H36+I36+J36+K36+L36+M36+N36+O36+P36+Q36 -> 0
A37: 36 | B37: Підлісний Володимир Сергійович | T37: =C37+D37+E37+F37+G37+H37+I37+J37+K37+L37+M37+N37+O37+P37+Q37 -> 0
A38: 37 | B38: Григоренко Ілля Олександрович | T38: =C38+D38+E38+F38+G38+H38+I38+J38+K38+L38+M38+N38+O38+P38+Q38 -> 0
A39: 38 | B39: Зінченко Дмитро Володимирович | T39: =C39+D39+E39+F39+G39+H39+I39+J39+K39+L39+M39+N39+O39+P39+Q39 -> 0
A40: 39 | B40: Гребінник Олексій Васильович | T40: =C40+D40+E40+F40+G40+H40+I40+J40+K40+L40+M40+N40+O40+P40+Q40 -> 0
... A44: 43 | B44: Самогородський Ігор Віталійович | T44: =C44+D44+E44+F44+G44+H44+I44+J44+K44+L44+M44+N44+O44+P44+Q44 -> 0
A45: 44 | B45: Іванова Світлана Юріївна | C45: 11 | D45: 11 | K45: 11 | L45: 11 | M45: 11 | N45: 3 | P45: 11 | T45: =C45+D45+E45+F45+G45+H45+I45+J45+K45+L45+M45+N45+O45+P45+Q45 -> 69
A46: 45 | B46: Ісайкіна Тетяна Іванівна | C46: 11 | D46: 9 | E46: 11 | F46: 11 | G46: 6 | I46: 11 | J46: 11 | K46: 11 | L46: 11 | M46: 11 | P46: 11 | Q46: 11 | T46: =C46+D46+E46+F46+G46+H46+I46+J46+K46+L46+M46+N46+O46+P46+Q46 -> 125
A47: 46 | B47: Деркс Сергій Анатолійович | T47: =C47+D47+E47+F47+G47+H47+I47+J47+K47+L47+M47+N47+O47+P47+Q47 -> 0
A48: 47 | B48: Гусаков Роман Давидович | T48: =C48+D48+E48+F48+G48+H48+I48+J48+K48+L48+M48+N48+O48+P48+Q48 -> 0
A49: 48 | B49: Гусаков Давид Давидович | T49: =C49+D49+E49+F49+G49+H49+I49+J49+K49+L49+M49+N49+O49+P49+Q49 -> 0
A50: 49 | B50: Тужиков Артем Денисович | T50: =C50+D50+E50+F50+G50+H50+I50+J50+K50+L50+M50+N50+O50+P50+Q50 -> 0
A51: 50 | B51: Ластовка Андрій Михайлович | T51: =C51+D51+E51+F51+G51+H51+I51+J51+K51+L51+M51+N51+O51+P51+Q51 -> 0
A52: 51 | B52: Шомін Вадим Сергійович | T52: =C52+D52+E52+F52+G52+H52+I52+J52+K52+L52+M52+N52+O52+P52+Q52 -> 0
A53: 52 | B53: Дзюба Едуард Іванович | T53: =C53+D53+E53+F53+G53+H53+I53+J53+K53+L53+M53+N53+O53+P53+Q53 -> 0
A54: 53 | B54: Туркевич Дмитро Миколайович | T54: =C54+D54+E54+F54+G54+H54+I54+J54+K54+L54+M54+N54+O54+P54+Q54 -> 0
...

Sheet МХП лазня
A1: N | B1: Сотрудник | C1: 16 | D1: 17 | E1: 18 | F1: 19 | G1: 20 | H1: 21 | I1: 22 | J1: 23 | K1: 24 | L1: 25 | M1: 26 | N1: 27 | O1: 28 | P1: 29 | Q1: 30
A2: 1 | B2: Багацький Вадим Геннадійович | T2: =C2+D2+E2+F2+G2+H2+I2+J2+K2+L2+M2+N2+O2+P2+Q2 -> 0
A3: 2 | B3: Васильєв Віталій Юрійович | T3: =C3+D3+E3+F3+G3+H3+I3+J3+K3+L3+M3+N3+O3+P3+Q3 -> 0
A4: 3 | B4: Григоренко Олександр Миколайович | T4: =C4+D4+E4+F4+G4+H4+I4+J4+K4+L4+M4+N4+O4+P4+Q4 -> 0
A5: 4 | B5: Григорьєв Микола Андрійович | T5: =C5+D5+E5+F5+G5+H5+I5+J5+K5+L5+M5+N5+O5+P5+Q5 -> 0
A6: 5 | B6: Григор'єв Михайло Андрійович | T6: =C6+D6+E6+F6+G6+H6+I6+J6+K6+L6+M6+N6+O6+P6+Q6 -> 0
A7: 6 | B7: Іванов Олексій Вікторович | T7: =C7+D7+E7+F7+G7+H7+I7+J7+K7+L7+M7+N7+O7+P7+Q7 -> 0
A8: 7 | B8: Іскрицький Денис Русланович | T8: =C8+D8+E8+F8+G8+H8+I8+J8+K8+L8+M8+N8+O8+P8+Q8 -> 0
A9: 8 | B9: Корнієнко Станіслав Володимирович | T9: =C9+D9+E9+F9+G9+H9+I9+J9+K9+L9+M9+N9+O9+P9+Q9 -> 0
A10: 9 | B10: Масливець Ігор Валерійович | T10: =C10+D10+E10+F10+G10+H10+I10+J10+K10+L10+M10+N10+O10+P10+Q10 -> 0
A11: 10 | B11: Скрипник Олександр Павлович | I11: 11 | J11: 11 | K11: 11 | L11: 11 | M11: 11 | N11: 6 | P11: 11 | Q11: 11 | T11: =C11+D11+E11+F11+G11+H11+I11+J11+K11+L11+M11+N11+O11+P11+Q11 -> 83
A12: 11 | B12: Паламарчук Вячеслав Володимирович | T12: =C12+D12+E12+F12+G12+H12+I12+J12+K12+L12+M12+N12+O12+P12+Q12 -> 0
A13: 12 | B13: Дехтяр Владислав Олександрович | T13: =C13+D13+E13+F13+G13+H13+I13+J13+K13+L13+M13+N13+O13+P13+Q13 -> 0
A14: 13 | B14: Тужиков Валерій Владиславович | T14: =C14+D14+E14+F14+G14+H14+I14+J14+K14+L14+M14+N14+O14+P14+Q14 -> 0
A15: 14 | B15: Сівов Євген Миколайович | T15: =C15+D15+E15+F15+G15+H15+I15+J15+K15+L15+M15+N15+O15+P15+Q15 -> 0
A16: 15 | B16: Кіфор Юрій Михайлович | K16: 11 | L16: 11 | T16: =C16+D16+E16+F16+G16+H16+I16+J16+K16+L16+M16+N16+O16+P16+Q16 -> 22
A17: 16 | B17: Петренко Микола Григорович | K17: 11 | L17: 9 | T17: =C17+D17+E17+F17+G17+H17+I17+J17+K17+L17+M17+N17+O17+P17+Q17 -> 20
A18: 17 | B18: Рубленко Микола Іванович | I18: 11 | J18: 11 | K18: 11 | L18: 11 | M18: 11 | P18: 11 | Q18: 11 | T18: =C18+D18+E18+F18+G18+H18+I18+J18+K18+L18+M18+N18+O18+P18+Q18 -> 77
A19: 18 | B19: Серебренніков Володимир Олександрович | T19: =C19+D19+E19+F19+G19+H19+I19+J19+K19+L19+M19+N19+O19+P19+Q19 -> 0
A20: 19 | B20: Чешко Сергій Анатолійович | T20: =C20+D20+E20+F20+G20+H20+I20+J20+K20+L20+M20+N20+O20+P20+Q20 -> 0
A21: 20 | B21: Нерезенко Євгеній Віктоорович | T21: =C21+D21+E21+F21+G21+H21+I21+J21+K21+L21+M21+N21+O21+P21+Q21 -> 0
A22: 21 | B22: Шавкун Максим Анатолійович | T22: =C22+D22+E22+F22+G22+H22+I22+J22+K22+L22+M22+N22+O22+P22+Q22 -> 0
A23: 22 | B23: Чуйко Олег Олегович | T23: =C23+D23+E23+F23+G23+H23+I23+J23+K23+L23+M23+N23+O23+P23+Q23 -> 0
A24: 23 | B24: Салюк Дмитро Андрійович | T24: =C24+D24+E24+F24+G24+H24+I24+J24+K24+L24+M24+N24+O24+P24+Q24 -> 0
A25: 24 | B25: Маковецький Юрій Миколайович | T25: =C25+D25+E25+F25+G25+H25+I25+J25+K25+L25+M25+N25+O25+P25+Q25 -> 0
A26: 25 | B26: Міненко Олександр Андрійович | T26: =C26+D26+E26+F26+G26+H26+I26+J26+K26+L26+M26+N26+O26+P26+Q26 -> 0
A27: 26 | B27: Салій Дмитро Миколайович | T27: =C27+D27+E27+F27+G27+H27+I27+J27+K27+L27+M27+N27+O27+P27+Q27 -> 0
A28: 27 | B28: Різніченко Олег Олександрович | T28: =C28+D28+E28+F28+G28+H28+I28+J28+K28+L28+M28+N28+O28+P28+Q28 -> 0
A29: 28 | B29: Рогозовець Андрій Вікторович | T29: =C29+D29+E29+F29+G29+H29+I29+J29+K29+L29+M29+N29+O29+P29+Q29 -> 0
A30: 29 | B30: Старков Кирило Юрійович | T30: =C30+D30+E30+F30+G30+H30+I30+J30+K30+L30+M30+N30+O30+P30+Q30 -> 0
A31: 30 | B31: Зубахін Сергій Александрович | T31: =C31+D31+E31+F31+G31+H31+I31+J31+K31+L31+M31+N31+O31+P31+Q31 -> 0
A32: 31 | B32: Корнієнко Віталій Олегович | I32: 11 | J32: 11 | K32: 11 | L32: 11 | M32: 11 | N32: 6 | P32: 9 | Q32: 8 | T32: =C32+D32+E32+F32+G32+H32+I32+J32+K32+L32+M32+N32+O32+P32+Q32 -> 78
A33: 32 | B33: Щербак Петро Іванович | T33: =C33+D33+E33+F33+G33+H33+I33+J33+K33+L33+M33+N33+O33+P33+Q33 -> 0
A34: 33 | B34: Онучак Віктор Іванович | T34: =C34+D34+E34+F34+G34+H34+I34+J34+K34+L34+M34+N34+O34+P34+Q34 -> 0
A35: 34 | B35: Батрак Віктор Володимирович | T35: =C35+D35+E35+F35+G35+H35+I35+J35+K35+L35+M35+N35+O35+P35+Q35 -> 0
A36: 35 | B36: Бондаренко Іван Олександрович | T36: =C36+D36+E36+F36+G36+H36+I36+J36+K36+L36+M36+N36+O36+P36+Q36 -> 0
A37: 36 | B37: Підлісний Володимир Сергійович | T37: =C37+D37+E37+F37+G37+H37+I37+J37+K37+L37+M37+N37+O37+P37+Q37 -> 0
A38: 37 | B38: Григоренко Ілля Олександрович | T38: =C38+D38+E38+F38+G38+H38+I38+J38+K38+L38+M38+N38+O38+P38+Q38 -> 0
A39: 38 | B39: Зінченко Дмитро Володимирович | T39: =C39+D39+E39+F39+G39+H39+I39+J39+K39+L39+M39+N39+O39+P39+Q39 -> 0
A40: 39 | B40: Гребінник Олексій Васильович | T40: =C40+D40+E40+F40+G40+H40+I40+J40+K40+L40+M40+N40+O40+P40+Q40 -> 0
...

Sheet Катеринополь
A1: N | B1: Сотрудник | C1: 16 | D1: 17 | E1: 18 | F1: 19 | G1: 20 | H1: 21 | I1: 22 | J1: 23 | K1: 24 | L1: 25 | M1: 26 | N1: 27 | O1: 28 | P1: 29 | Q1: 30 | R1: Всего часов
A2: 1 | B2: Багацький Вадим Геннадійович | C2: 11 | D2: 11 | E2: 11 | R2: 83 | T2: =C2+D2+E2+F2+G2+H2+I2+J2+K2+L2+M2+N2+O2+P2+Q2 -> 33
A3: 2 | B3: Васильєв Віталій Юрійович | R3: 0 | T3: =C3+D3+E3+F3+G3+H3+I3+J3+K3+L3+M3+N3+O3+P3+Q3 -> 0
A4: 3 | B4: Григоренко Олександр Миколайович | R4: 0 | T4: =C4+D4+E4+F4+G4+H4+I4+J4+K4+L4+M4+N4+O4+P4+Q4 -> 0
A5: 4 | B5: Григорьєв Микола Андрійович | R5: 0 | T5: =C5+D5+E5+F5+G5+H5+I5+J5+K5+L5+M5+N5+O5+P5+Q5 -> 0
A6: 5 | B6: Григор'єв Михайло Андрійович | R6: 0 | T6: =C6+D6+E6+F6+G6+H6+I6+J6+K6+L6+M6+N6+O6+P6+Q6 -> 0
A7: 6 | B7: Іванов Олексій Вікторович | R7: 76 | T7: =C7+D7+E7+F7+G7+H7+I7+J7+K7+L7+M7+N7+O7+P7+Q7 -> 0
A8: 7 | B8: Іскрицький Денис Русланович | R8: 11 | T8: =C8+D8+E8+F8+G8+H8+I8+J8+K8+L8+M8+N8+O8+P8+Q8 -> 0
A9: 8 | B9: Корнієнко Станіслав Володимирович | R9: 0 | T9: =C9+D9+E9+F9+G9+H9+I9+J9+K9+L9+M9+N9+O9+P9+Q9 -> 0
A10: 9 | B10: Масливець Ігор Валерійович | D10: 11 | R10: 11 | T10: =C10+D10+E10+F10+G10+H10+I10+J10+K10+L10+M10+N10+O10+P10+Q10 -> 11
A11: 10 | B11: Скрипник Олександр Павлович | R11: 0 | T11: =C11+D11+E11+F11+G11+H11+I11+J11+K11+L11+M11+N11+O11+P11+Q11 -> 0
A12: 11 | B12: Паламарчук Вячеслав Володимирович | R12: 0 | T12: =C12+D12+E12+F12+G12+H12+I12+J12+K12+L12+M12+N12+O12+P12+Q12 -> 0
A13: 12 | B13: Дехтяр Владислав Олександрович | R13: 0 | T13: =C13+D13+E13+F13+G13+H13+I13+J13+K13+L13+M13+N13+O13+P13+Q13 -> 0
A14: 13 | B14: Тужиков Валерій Владиславович | R14: 33 | T14: =C14+D14+E14+F14+G14+H14+I14+J14+K14+L14+M14+N14+O14+P14+Q14 -> 0
A15: 14 | B15: Сівов Євген Миколайович | R15: 57 | T15: =C15+D15+E15+F15+G15+H15+I15+J15+K15+L15+M15+N15+O15+P15+Q15 -> 0
A16: 15 | B16: Кіфор Юрій Михайлович | R16: 0 | T16: =C16+D16+E16+F16+G16+H16+I16+J16+K16+L16+M16+N16+O16+P16+Q16 -> 0
A17: 16 | B17: Петренко Микола Григорович | R17: 0 | T17: =C17+D17+E17+F17+G17+H17+I17+J17+K17+L17+M17+N17+O17+P17+Q17 -> 0
A18: 17 | B18: Рубленко Микола Іванович | R18: 0 | T18: =C18+D18+E18+F18+G18+H18+I18+J18+K18+L18+M18+N18+O18+P18+Q18 -> 0
A19: 18 | B19: Серебренніков Володимир Олександрович | R19: 0 | T19: =C19+D19+E19+F19+G19+H19+I19+J19+K19+L19+M19+N19+O19+P19+Q19 -> 0
A20: 19 | B20: Чешко Сергій Анатолійович | R20: 0 | T20: =C20+D20+E20+F20+G20+H20+I20+J20+K20+L20+M20+N20+O20+P20+Q20 -> 0
A21: 20 | B21: Нерезенко Євгеній Віктоорович | R21: 0 | T21: =C21+D21+E21+F21+G21+H21+I21+J21+K21+L21+M21+N21+O21+P21+Q21 -> 0
A22: 21 | B22: Шавкун Максим Анатолійович | R22: 0 | T22: =C22+D22+E22+F22+G22+H22+I22+J22+K22+L22+M22+N22+O22+P22+Q22 -> 0
... A24: 23 | B24: Салюк Дмитро Андрійович | R24: 0 | T24: =C24+D24+E24+F24+G24+H24+I24+J24+K24+L24+M24+N24+O24+P24+Q24 -> 0
A25: 24 | B25: Маковецький Юрій Миколайович | E25: 11 | R25: 39 | T25: =C25+D25+E25+F25+G25+H25+I25+J25+K25+L25+M25+N25+O25+P25+Q25 -> 11
A26: 25 | B26: Міненко Олександр Андрійович | R26: 0 | T26: =C26+D26+E26+F26+G26+H26+I26+J26+K26+L26+M26+N26+O26+P26+Q26 -> 0
A27: 26 | B27: Салій Дмитро Миколайович | R27: 0 | T27: =C27+D27+E27+F27+G27+H27+I27+J27+K27+L27+M27+N27+O27+P27+Q27 -> 0
A28: 27 | B28: Різніченко Олег Олександрович | C28: 11 | E28: 9 | R28: 58 | T28: =C28+D28+E28+F28+G28+H28+I28+J28+K28+L28+M28+N28+O28+P28+Q28 -> 20
A29: 28 | B29: Рогозовець Андрій Вікторович | D29: 11 | R29: 33 | T29: =C29+D29+E29+F29+G29+H29+I29+J29+K29+L29+M29+N29+O29+P29+Q29 -> 11
A30: 29 | B30: Старков Кирило Юрійович | R30: 0 | T30: =C30+D30+E30+F30+G30+H30+I30+J30+K30+L30+M30+N30+O30+P30+Q30 -> 0
A31: 30 | B31: Зубахін Сергій Александрович | R31: 0 | T31: =C31+D31+E31+F31+G31+H31+I31+J31+K31+L31+M31+N31+O31+P31+Q31 -> 0
A32: 31 | B32: Корнієнко Віталій Олегович | E32: 8 | R32: 8 | T32: =C32+D32+E32+F32+G32+H32+I32+J32+K32+L32+M32+N32+O32+P32+Q32 -> 8
A33: 32 | B33: Щербак Петро Іванович | R33: 0 | T33: =C33+D33+E33+F33+G33+H33+I33+J33+K33+L33+M33+N33+O33+P33+Q33 -> 0
A34: 33 | B34: Онучак Віктор Іванович | D34: 11 | E34: 11 | R34: 50 | T34: =C34+D34+E34+F34+G34+H34+I34+J34+K34+L34+M34+N34+O34+P34+Q34 -> 22
A35: 34 | B35: Батрак Віктор Володимирович | R35: 0 | T35: =C35+D35+E35+F35+G35+H35+I35+J35+K35+L35+M35+N35+O35+P35+Q35 -> 0
A36: 35 | B36: Бондаренко Іван Олександрович | R36: 0 | T36: =C36+D36+E36+F36+G36+H36+I36+J36+K36+L36+M36+N36+O36+P36+Q36 -> 0
A37: 36 | B37: Підлісний Володимир Сергійович | R37: 0 | T37: =C37+D37+E37+F37+G37+H37+I37+J37+K37+L37+M37+N37+O37+P37+Q37 -> 0
A38: 37 | B38: Григоренко Ілля Олександрович | R38: 0 | T38: =C38+D38+E38+F38+G38+H38+I38+J38+K38+L38+M38+N38+O38+P38+Q38 -> 0
A39: 38 | B39: Зінченко Дмитро Володимирович | D39: 11 | E39: 11 | R39: 66 | T39: =C39+D39+E39+F39+G39+H39+I39+J39+K39+L39+M39+N39+O39+P39+Q39 -> 22
A40: 39 | B40: Гребінник Олексій Васильович | D40: 11 | R40: 22 | T40: =C40+D40+E40+F40+G40+H40+I40+J40+K40+L40+M40+N40+O40+P40+Q40 -> 11
A41: 40 | B41: Ізюмець Олександр Евгенович | R41: 0 | T41: =C41+D41+E41+F41+G41+H41+I41+J41+K41+L41+M41+N41+O41+P41+Q41 -> 0
...

Sheet ВООЗ
A1: N | B1: Сотрудник | C1: 16 | D1: 17 | E1: 18 | F1: 19 | G1: 20 | H1: 21 | I1: 22 | J1: 23 | K1: 24 | L1: 25 | M1: 26 | N1: 27 | O1: 28 | P1: 29 | Q1: 30 | R1: Всего часов
A2: 1 | B2: Багацький Вадим Геннадійович | R2: 0 | T2: =C2+D2+E2+F2+G2+H2+I2+J2+K2+L2+M2+N2+O2+P2+Q2 -> 0
A3: 2 | B3: Васильєв Віталій Юрійович | R3: 0 | T3: =C3+D3+E3+F3+G3+H3+I3+J3+K3+L3+M3+N3+O3+P3+Q3 -> 0
A4: 3 | B4: Григоренко Олександр Миколайович | R4: 0 | T4: =C4+D4+E4+F4+G4+H4+I4+J4+K4+L4+M4+N4+O4+P4+Q4 -> 0
A5: 4 | B5: Григорьєв Микола Андрійович | R5: 0 | T5: =C5+D5+E5+F5+G5+H5+I5+J5+K5+L5+M5+N5+O5+P5+Q5 -> 0
A6: 5 | B6: Григор'єв Михайло Андрійович | R6: 0 | T6: =C6+D6+E6+F6+G6+H6+I6+J6+K6+L6+M6+N6+O6+P6+Q6 -> 0
A7: 6 | B7: Іванов Олексій Вікторович | R7: 0 | T7: =C7+D7+E7+F7+G7+H7+I7+J7+K7+L7+M7+N7+O7+P7+Q7 -> 0
A8: 7 | B8: Іскрицький Денис Русланович | R8: 0 | T8: =C8+D8+E8+F8+G8+H8+I8+J8+K8+L8+M8+N8+O8+P8+Q8 -> 0
A9: 8 | B9: Корнієнко Станіслав Володимирович | R9: 0 | T9: =C9+D9+E9+F9+G9+H9+I9+J9+K9+L9+M9+N9+O9+P9+Q9 -> 0
A10: 9 | B10: Масливець Ігор Валерійович | R10: 0 | T10: =C10+D10+E10+F10+G10+H10+I10+J10+K10+L10+M10+N10+O10+P10+Q10 -> 0
A11: 10 | B11: Скрипник Олександр Павлович | R11: 0 | T11: =C11+D11+E11+F11+G11+H11+I11+J11+K11+L11+M11+N11+O11+P11+Q11 -> 0
A12: 11 | B12: Паламарчук Вячеслав Володимирович | R12: 0 | T12: =C12+D12+E12+F12+G12+H12+I12+J12+K12+L12+M12+N12+O12+P12+Q12 -> 0
A13: 12 | B13: Дехтяр Владислав Олександрович | R13: 0 | T13: =C13+D13+E13+F13+G13+H13+I13+J13+K13+L13+M13+N13+O13+P13+Q13 -> 0
... A25: 24 | B25: Маковецький Юрій Миколайович | R25: 0 | T25: =C25+D25+E25+F25+G25+H25+I25+J25+K25+L25+M25+N25+O25+P25+Q25 -> 0
A26: 25 | B26: Міненко Олександр Андрійович | M26: 24 | P26: 24 | R26: 48 | T26: =C26+D26+E26+F26+G26+H26+I26+J26+K26+L26+M26+N26+O26+P26+Q26 -> 48
A27: 26 | B27: Салій Дмитро Миколайович | M27: 24 | P27: 24 | R27: 48 | T27: =C27+D27+E27+F27+G27+H27+I27+J27+K27+L27+M27+N27+O27+P27+Q27 -> 48
A28: 27 | B28: Різніченко Олег Олександрович | R28: 0 | T28: =C28+D28+E28+F28+G28+H28+I28+J28+K28+L28+M28+N28+O28+P28+Q28 -> 0
A29: 28 | B29: Рогозовець Андрій Вікторович | R29: 0 | T29: =C29+D29+E29+F29+G29+H29+I29+J29+K29+L29+M29+N29+O29+P29+Q29 -> 0
A30: 29 | B30: Старков Кирило Юрійович | R30: 0 | T30: =C30+D30+E30+F30+G30+H30+I30+J30+K30+L30+M30+N30+O30+P30+Q30 -> 0
A31: 30 | B31: Зубахін Сергій Александрович | R31: 0 | T31: =C31+D31+E31+F31+G31+H31+I31+J31+K31+L31+M31+N31+O31+P31+Q31 -> 0
A32: 31 | B32: Корнієнко Віталій Олегович | R32: 0 | T32: =C32+D32+E32+F32+G32+H32+I32+J32+K32+L32+M32+N32+O32+P32+Q32 -> 0
A33: 32 | B33: Щербак Петро Іванович | R33: 0 | T33: =C33+D33+E33+F33+G33+H33+I33+J33+K33+L33+M33+N33+O33+P33+Q33 -> 0
A34: 33 | B34: Онучак Віктор Іванович | R34: 0 | T34: =C34+D34+E34+F34+G34+H34+I34+J34+K34+L34+M34+N34+O34+P34+Q34 -> 0
A35: 34 | B35: Батрак Віктор Володимирович | R35: 0 | T35: =C35+D35+E35+F35+G35+H35+I35+J35+K35+L35+M35+N35+O35+P35+Q35 -> 0
A36: 35 | B36: Бондаренко Іван Олександрович | R36: 0 | T36: =C36+D36+E36+F36+G36+H36+I36+J36+K36+L36+M36+N36+O36+P36+Q36 -> 0
A37: 36 | B37: Підлісний Володимир Сергійович | R37: 0 | T37: =C37+D37+E37+F37+G37+H37+I37+J37+K37+L37+M37+N37+O37+P37+Q37 -> 0
A38: 37 | B38: Григоренко Ілля Олександрович | R38: 0 | T38: =C38+D38+E38+F38+G38+H38+I38+J38+K38+L38+M38+N38+O38+P38+Q38 -> 0
A39: 38 | B39: Зінченко Дмитро Володимирович | R39: 0 | T39: =C39+D39+E39+F39+G39+H39+I39+J39+K39+L39+M39+N39+O39+P39+Q39 -> 0
... A64: 63 | B64: Осовіцький Ростислав Олександрович | R64: 0 | T64: =C64+D64+E64+F64+G64+H64+I64+J64+K64+L64+M64+N64+O64+P64+Q64 -> 0
R65: 96

Sheet Кернел
A1: N | B1: Сотрудник | C1: 16 | D1: 17 | E1: 18 | F1: 19 | G1: 20 | H1: 21 | I1: 22 | J1: 23 | K1: 24 | L1: 25 | M1: 26 | N1: 27 | O1: 28 | P1: 29 | Q1: 30 | R1: Всего часов
A2: 1 | B2: Багацький Вадим Геннадійович | R2: 0 | T2: =C2+D2+E2+F2+G2+H2+I2+J2+K2+L2+M2+N2+O2+P2+Q2 -> 0
A3: 2 | B3: Васильєв Віталій Юрійович | R3: 0 | T3: =C3+D3+E3+F3+G3+H3+I3+J3+K3+L3+M3+N3+O3+P3+Q3 -> 0
A4: 3 | B4: Григоренко Олександр Миколайович | C4: 24 | D4: 24 | E4: 24 | F4: 24 | G4: 24 | H4: 24 | I4: 24 | J4: 24 | K4: 24 | L4: 24 | M4: 24 | N4: 24 | O4: 24 | P4: 24 | Q4: 24 | R4: 720 | T4: =C4+D4+E4+F4+G4+H4+I4+J4+K4+L4+M4+N4+O4+P4+Q4 -> 360
A5: 4 | B5: Григорьєв Микола Андрійович | R5: 0 | T5: =C5+D5+E5+F5+G5+H5+I5+J5+K5+L5+M5+N5+O5+P5+Q5 -> 0
A6: 5 | B6: Григор'єв Михайло Андрійович | R6: 0 | T6: =C6+D6+E6+F6+G6+H6+I6+J6+K6+L6+M6+N6+O6+P6+Q6 -> 0
A7: 6 | B7: Іванов Олексій Вікторович | R7: 0 | T7: =C7+D7+E7+F7+G7+H7+I7+J7+K7+L7+M7+N7+O7+P7+Q7 -> 0
A8: 7 | B8: Іскрицький Денис Русланович | R8: 0 | T8: =C8+D8+E8+F8+G8+H8+I8+J8+K8+L8+M8+N8+O8+P8+Q8 -> 0
