Workbook

Sheet Лист2
B1: Код (Таб. №) | C1: Наименование | D1: Код по ДРФО | E1: Вид договора | F1: Вид занятости | G1: Подразделение организации | H1: Должность организации | I1: Дата приема
B2: 1 | C2: Оренда авто
B3: д000000007 | C3: Воронцов Олександр Володимирович (оренда авто) | D3: 3244112838 | E3: Договор подряда (выполнение работ, оказание услуг)
B4: д000000023 | C4: Гавриченко Тетяна Василівна (оренда авто) | D4: 2890614789 | E4: Договор подряда (выполнение работ, оказание услуг)
B5: д000000010 | C5: Гриценко Олександр Вікторович (оренда авто) | D5: 2751711415 | E5: Договор подряда (выполнение работ, оказание услуг)
B6: д000000001 | C6: Гриценко Сергій Миколайович (дг.) | D6: 3382914593 | E6: Договор подряда (выполнение работ, оказание услуг)
B7: д000000013 | C7: Гриценко Сергій Миколайович (оренда авто) | D7: 3382914593 | E7: Договор подряда (выполнение работ, оказание услуг)
B8: д000000019 | C8: Гуняга Олег Володимирович (оренда авто) | D8: 2711822114 | E8: Договор подряда (выполнение работ, оказание услуг)
B9: д000000008 | C9: Манжула Максим Анатолійович (оренда авто) | D9: 3281710375 | E9: Договор подряда (выполнение работ, оказание услуг)
B10: д000000014 | C10: Огоновський Дмитро Анатолійович (оренда авто) | D10: 2866215672 | E10: Договор подряда (выполнение работ, оказание услуг)
B11: д000000015 | C11: Потьомко Михайло Володимирович (оренда авто) | D11: 3575508457 | E11: Договор подряда (выполнение работ, оказание услуг)
B12: д000000016 | C12: Сикал Павло Анатолійович (оренда авто) | D12: 3306506991 | E12: Договор подряда (выполнение работ, оказание услуг)
B13: д000000012 | C13: Старіков Сергій Вікторович (оренда авто) | D13: 2899410750 | E13: Договор подряда (выполнение работ, оказание услуг)
B14: д000000020 | C14: Шевченко Євген Анатолійович (оренда авто) | D14: 3194113635 | E14: Договор подряда (выполнение работ, оказание услуг)
B15: д000000009 | C15: Ширшов Олександр Леонідович (оренда авто) | D15: 2234022693 | E15: Договор подряда (выполнение работ, оказание услуг)
B16: 23 | C16: Адаменко Віталій Вікторович | D16: 3153900053 | E16: Трудовой договор | F16: Основное место работы | G16: Виробничий (Цех металоконструкцій) | H16: Монтажник будівельний | I16: 05.10.2022
B17: 4 | C17: Аксенчіков Сергій Олександрович | D17: 3457309598 | E17: Трудовой договор | F17: Основное место работы | G17: Адміністративний відділ | H17: Майстер будівельних та монтажних робіт | I17: 01.07.2022
B18: д000000001 | C18: Аксенчіков Сергій Олександрович (оренда авто) | D18: 3457309598 | E18: Договор подряда (выполнение работ, оказание услуг)
B19: 48 | C19: Александров Артем Анатолійович | D19: 2618119132 | E19: Трудовой договор | F19: Основное место работы | G19: Адміністративний відділ | H19: Діловод | I19: 25.09.2018
B20: 203 | C20: Александров Денис Анатолійович | D20: 2765913876 | E20: Трудовой договор | F20: Основное место работы | G20: Адміністративний відділ | H20: Помічник економіста | I20: 01.02.2021
B21: 156 | C21: Александрова Жанна Валентинівна | D21: 2693717247 | E21: Трудовой договор | F21: Основное место работы | G21: Адміністративний відділ | H21: Прибиральник службових приміщень | I21: 01.07.2020
B22: 2289516770 | C22: Антонович Тетяна Сергіївна | D22: 2894801342 | E22: Трудовой договор | F22: Основное место работы | G22: Адміністративний відділ | H22: Директор фінансовий | I22: 22.12.2022
B23: 16 | C23: Антонович Тетяна Сергіївна (сум.) | D23: 2894801342 | E23: Трудовой договор | F23: Внешнее совместительство | G23: Адміністративний відділ | H23: Директор фінансовий | I23: 26.05.2023
B24: 17 | C24: Аулова Маргарита Володимирівна | D24: 3036417408 | E24: Трудовой договор | F24: Внешнее совместительство | G24: Адміністративний відділ | H24: Головний бухгалтер | I24: 01.04.2024
B25: 2289516882 | C25: Аулова Маргарита Володимирівна (осн.) | D25: 3036417408 | E25: Трудовой договор | F25: Основное место работы | G25: Адміністративний відділ | H25: Головний бухгалтер | I25: 27.03.2024
B26: 2289516833 | C26: Ахмедов Тавакгюль Сардар огли | D26: 2358421934 | E26: Трудовой договор | F26: Основное место работы | G26: Виробничий (Ладижин-3) | H26: Маляр | I26: 08.09.2023
B27: 37 | C27: Бабіленко Микола Олександрович | D27: 2564424513 | E27: Трудовой договор | F27: Основное место работы | G27: Виробничий (Цех металоконструкцій) | H27: Слюсар із складання металевих конструкцій | I27: 01.12.2022
B28: 11 | C28: Багацький Вадим Геннадійович | D28: 3247506159 | E28: Трудовой договор | F28: Основное место работы | G28: Виробничий (Цех металоконструкцій) | H28: Електрозварник ручного зварювання | I28: 05.08.2022
B29: 2289516701 | C29: Безкоровайний Дмитро Миколайович | D29: 3358009052 | E29: Трудовой договор | F29: Основное место работы | G29: Виробничий (Підгірці) | H29: Водій автотранспортних засобів | I29: 04.02.2022
B30: 62 | C30: Білоусов Євген Вікторович | D30: 3421002151 | E30: Трудовой договор | F30: Основное место работы | G30: Виробничий (Старокостянтинів) | H30: Арматурник (будівельні, монтажні й ремонтно-будівельні роботи) | I30: 01.02.2019
B31: д000000006 | C31: Бічковський Максим Петрович | D31: 2922419813 | E31: Договор подряда (выполнение работ, оказание услуг)
B32: 2289516746 | C32: Блоха Євген Валерійович | D32: 2919308010 | E32: Трудовой договор | F32: Основное место работы | G32: Виробничий (Старокостянтинів) | H32: Бетоняр | I32: 27.09.2022
B33: 2289516849 | C33: Богданюк Дмитро Леонтійович | D33: 3036408418 | E33: Трудовой договор | F33: Основное место работы | G33: Адміністративний відділ | H33: Інженер з проєктно-кошторисної роботи | I33: 02.11.2023
B34: 19 | C34: Богун Олена Миколаївна | D34: 3813305164 | E34: Трудовой договор | F34: Основное место работы | G34: Виробничій цех | H34: Лаборант | I34: 02.07.2024
B35: 2289516863 | C35: Божков Валерій Вікторович | D35: 2753702532 | E35: Трудовой договор | F35: Основное место работы | G35: Виробничий (Крушинка) | H35: Водій автотранспортних засобів | I35: 19.12.2023
B36: 46 | C36: Бокоч Галина Михайлівна (осн.) | D36: 3018718189 | E36: Трудовой договор | F36: Основное место работы | G36: Адміністративний відділ | H36: Діловод | I36: 24.11.2023
B37: 157 | C37: Болох Володимир Васильович | D37: 2794610037 | E37: Трудовой договор | F37: Основное место работы | G37: Виробничий (Старокостянтинів) | H37: Машиніст крана автомобільного | I37: 03.08.2020
B38: 71 | C38: Борецька Людмила Сергіївна | D38: 3280710149 | E38: Трудовой договор | F38: Основное место работы | G38: Адміністративний відділ | H38: Економіст | I38: 08.04.2019
B39: 2289516756 | C39: Борисенко Олексій Миколайович | D39: 2957816213 | E39: Трудовой договор | F39: Основное место работы | G39: Виробничий (Крушинка) | H39: Машиніст крана автомобільного | I39: 01.11.2022
B40: 49 | C40: Бреус Віталій Григорович | D40: 3143007035 | E40: Трудовой договор | F40: Основное место работы | G40: Адміністративний відділ | H40: Менеджер (управитель) з постачання | I40: 18.07.2023
...

Sheet Лист1
B2: N | C2: Работник (основное назначение) | D2: Период взаиморасчетов | E2: Счет учета | F2: Сумма | G2: Сумма (окр.) | J2: Админ
B3: 1 | C3: Аксенчіков Сергій Олександрович | D3: 01.07.2024 | E3: 661 | F3: 4326 | H3: =MATCH(I3,#REF!,0) -> #REF! | I3: =TRIM(C3) -> Аксенчіков Сергій Олександрович | J3: 1
B4: 2 | C4: Бабіленко Микола Олександрович | D4: 01.07.2024 | E4: 661 | F4: 3990 | H4: =MATCH(I4,#REF!,0) -> #REF! | I4: =TRIM(C4) -> Бабіленко Микола Олександрович | K4: =INDEX(Лист2!D:D,MATCH(C4,Лист2!C:C,0)) -> 2564424513
B5: 3 | C5: Багацький Вадим Геннадійович | D5: 01.07.2024 | E5: 661 | F5: 3990 | H5: =MATCH(I5,#REF!,0) -> #REF! | I5: =TRIM(C5) -> Багацький Вадим Геннадійович | K5: =INDEX(Лист2!D:D,MATCH(C5,Лист2!C:C,0)) -> 3247506159
B6: 4 | C6: Бреус Віталій Григорович | D6: 01.07.2024 | E6: 661 | F6: 5417.99 | H6: =MATCH(I6,#REF!,0) -> #REF! | I6: =TRIM(C6) -> Бреус Віталій Григорович | J6: 1
B7: 5 | C7: Бутенко Матвій Анатолійович | D7: 01.07.2024 | E7: 661 | F7: 4326 | H7: =MATCH(I7,#REF!,0) -> #REF! | I7: =TRIM(C7) -> Бутенко Матвій Анатолійович | J7: 1
B8: 6 | C8: Васильєв Віталій Юрійович | D8: 01.07.2024 | E8: 661 | F8: 3990 | H8: =MATCH(I8,#REF!,0) -> #REF! | I8: =TRIM(C8) -> Васильєв Віталій Юрійович | K8: =INDEX(Лист2!D:D,MATCH(C8,Лист2!C:C,0)) -> 3746304158
B9: 7 | C9: Власенко В'ячеслав Валентинович | D9: 01.07.2024 | E9: 661 | F9: 3990 | H9: =MATCH(I9,#REF!,0) -> #REF! | I9: =TRIM(C9) -> Власенко В'ячеслав Валентинович | K9: =INDEX(Лист2!D:D,MATCH(C9,Лист2!C:C,0)) -> 2831710277
B10: 8 | C10: Горєлов Микита Євгенович | D10: 01.07.2024 | E10: 661 | F10: 2660 | H10: =MATCH(I10,#REF!,0) -> #REF! | I10: =TRIM(C10) -> Горєлов Микита Євгенович | K10: =INDEX(Лист2!D:D,MATCH(C10,Лист2!C:C,0)) -> 3596200395
B11: 9 | C11: Григор'єв Микола Андрійович | D11: 01.07.2024 | E11: 661 | F11: 1662.5 | H11: =MATCH(I11,#REF!,0) -> #REF! | I11: =TRIM(C11) -> Григор'єв Микола Андрійович | K11: =INDEX(Лист2!D:D,MATCH(C11,Лист2!C:C,0)) -> 3422005391
B12: 10 | C12: Григор'єв Михайло Андрійович | D12: 01.07.2024 | E12: 661 | F12: 3990 | H12: =MATCH(I12,#REF!,0) -> #REF! | I12: =TRIM(C12) -> Григор'єв Михайло Андрійович | K12: =INDEX(Лист2!D:D,MATCH(C12,Лист2!C:C,0)) -> 3720407672
B13: 11 | C13: Григоренко Олександр Миколайович | D13: 01.07.2024 | E13: 661 | F13: 3990 | H13: =MATCH(I13,#REF!,0) -> #REF! | I13: =TRIM(C13) -> Григоренко Олександр Миколайович | K13: =INDEX(Лист2!D:D,MATCH(C13,Лист2!C:C,0)) -> 2436600937
B14: 12 | C14: Гриценко Олександр Вікторович | D14: 01.07.2024 | E14: 661 | F14: 5197.5 | H14: =MATCH(I14,#REF!,0) -> #REF! | I14: =TRIM(C14) -> Гриценко Олександр Вікторович | J14: 1
B15: 13 | C15: Грушко Лариса Вікторівна | D15: 01.07.2024 | E15: 661 | F15: 4427.5 | H15: =MATCH(I15,#REF!,0) -> #REF! | I15: =TRIM(C15) -> Грушко Лариса Вікторівна | J15: 1
B16: 14 | C16: Дехтяр Владислав Олександрович | D16: 01.07.2024 | E16: 661 | F16: 3990 | H16: =MATCH(I16,#REF!,0) -> #REF! | I16: =#REF! -> #REF! | K16: =INDEX(Лист2!D:D,MATCH(C16,Лист2!C:C,0)) -> 3374502899
B17: 15 | C17: Желтяков Ігор Юрійович | D17: 01.07.2024 | E17: 661 | F17: 3990 | H17: =MATCH(I17,#REF!,0) -> #REF! | I17: =TRIM(C17) -> Желтяков Ігор Юрійович | K17: =INDEX(Лист2!D:D,MATCH(C17,Лист2!C:C,0)) -> 2637303953
B18: 16 | C18: Іванов Олексій Вікторович | D18: 01.07.2024 | E18: 661 | F18: 3990 | H18: =MATCH(I18,#REF!,0) -> #REF! | I18: =TRIM(C18) -> Іванов Олексій Вікторович | K18: =INDEX(Лист2!D:D,MATCH(C18,Лист2!C:C,0)) -> 3705902230
B19: 17 | C19: Іскрицький Денис Русланович | D19: 01.07.2024 | E19: 661 | F19: 3990 | H19: =MATCH(I19,#REF!,0) -> #REF! | I19: =TRIM(C19) -> Іскрицький Денис Русланович | K19: =INDEX(Лист2!D:D,MATCH(C19,Лист2!C:C,0)) -> 3779110293
B20: 18 | C20: Кіфор Юрій Михайлович | D20: 01.07.2024 | E20: 661 | F20: 3990.02 | H20: =MATCH(I20,#REF!,0) -> #REF! | I20: =TRIM(C20) -> Кіфор Юрій Михайлович | K20: =INDEX(Лист2!D:D,MATCH(C20,Лист2!C:C,0)) -> 2521518612
B21: 19 | C21: Корнієнко Станіслав Володимирович | D21: 01.07.2024 | E21: 661 | F21: 3428.01 | H21: =MATCH(I21,#REF!,0) -> #REF! | I21: =C21 -> Корнієнко Станіслав Володимирович | K21: =INDEX(Лист2!D:D,MATCH(C21,Лист2!C:C,0)) -> 2579305831
B22: 20 | C22: Масливець Ігор Валерійович | D22: 01.07.2024 | E22: 661 | F22: 3990 | H22: =MATCH(I22,#REF!,0) -> #REF! | I22: =TRIM(C22) -> Масливець Ігор Валерійович | K22: =INDEX(Лист2!D:D,MATCH(C22,Лист2!C:C,0)) -> 2880313812
B23: 21 | C23: Мельниченко Максим Вікторович | D23: 01.07.2024 | E23: 661 | F23: 6650 | H23: =MATCH(I23,#REF!,0) -> #REF! | I23: =TRIM(C23) -> Мельниченко Максим Вікторович | K23: =INDEX(Лист2!D:D,MATCH(C23,Лист2!C:C,0)) -> 3348501613
B24: 22 | C24: Мороз Віталій Миколайович | D24: 01.07.2024 | E24: 661 | F24: 6650 | H24: =MATCH(I24,#REF!,0) -> #REF! | I24: =TRIM(C24) -> Мороз Віталій Миколайович | K24: =INDEX(Лист2!D:D,MATCH(C24,Лист2!C:C,0)) -> 3216804294
B25: 23 | C25: Нестерук Сергій Петрович | D25: 01.07.2024 | E25: 661 | F25: 3990.02 | H25: =MATCH(I25,#REF!,0) -> #REF! | I25: =TRIM(C25) -> Нестерук Сергій Петрович | K25: =INDEX(Лист2!D:D,MATCH(C25,Лист2!C:C,0)) -> 3283102618
B26: 24 | C26: Паламарчук Вячеслав Володимирович | D26: 01.07.2024 | E26: 661 | F26: 3990 | H26: =MATCH(I26,#REF!,0) -> #REF! | I26: =TRIM(C26) -> Паламарчук Вячеслав Володимирович | K26: =INDEX(Лист2!D:D,MATCH(C26,Лист2!C:C,0)) -> 3230316597
B27: 25 | C27: Парнєва Олена Вікторівна | D27: 01.07.2024 | E27: 661 | F27: 840 | H27: =MATCH(I27,#REF!,0) -> #REF! | I27: =TRIM(C27) -> Парнєва Олена Вікторівна | K27: =INDEX(Лист2!D:D,MATCH(C27,Лист2!C:C,0)) -> 2938511042
B28: 26 | C28: Пилипчук Олександр Анатолійович | D28: 01.07.2024 | E28: 661 | F28: 3990 | H28: =MATCH(I28,#REF!,0) -> #REF! | I28: =TRIM(C28) -> Пилипчук Олександр Анатолійович | K28: =INDEX(Лист2!D:D,MATCH(C28,Лист2!C:C,0)) -> 3067218612
B29: 27 | C29: Поліщук Олександр Олександрович | D29: 01.07.2024 | E29: 661 | F29: 3990 | H29: =MATCH(I29,#REF!,0) -> #REF! | I29: =TRIM(C29) -> Поліщук Олександр Олександрович | K29: =INDEX(Лист2!D:D,MATCH(C29,Лист2!C:C,0)) -> 3289716153
B30: 28 | C30: Пономаренко Віталій Вікторович | D30: 01.07.2024 | E30: 661 | F30: 3990 | H30: =MATCH(I30,#REF!,0) -> #REF! | I30: =TRIM(C30) -> Пономаренко Віталій Вікторович | K30: =INDEX(Лист2!D:D,MATCH(C30,Лист2!C:C,0)) -> 3185119514
B31: 29 | C31: Пономаренко Олександр Вікторович | D31: 01.07.2024 | E31: 661 | F31: 5460 | H31: =MATCH(I31,#REF!,0) -> #REF! | I31: =TRIM(C31) -> Пономаренко Олександр Вікторович | K31: =INDEX(Лист2!D:D,MATCH(C31,Лист2!C:C,0)) -> 2944519172
B32: 30 | C32: Пономарьов Микола Вікторович | D32: 01.07.2024 | E32: 661 | F32: 3990 | H32: =MATCH(I32,#REF!,0) -> #REF! | I32: =TRIM(C32) -> Пономарьов Микола Вікторович | K32: =INDEX(Лист2!D:D,MATCH(C32,Лист2!C:C,0)) -> 3008300898
B33: 31 | C33: Понуркін Євген Григорович | D33: 01.07.2024 | E33: 661 | F33: 3990 | H33: =MATCH(I33,#REF!,0) -> #REF! | I33: =TRIM(C33) -> Понуркін Євген Григорович | K33: =INDEX(Лист2!D:D,MATCH(C33,Лист2!C:C,0)) -> 3005702873
... B38: 36 | C38: Скрипник Сергій Павлович | D38: 01.07.2024 | E38: 661 | F38: 5460 | H38: =MATCH(I38,#REF!,0) -> #REF! | I38: =TRIM(C38) -> Скрипник Сергій Павлович | K38: =INDEX(Лист2!D:D,MATCH(C38,Лист2!C:C,0)) -> 3219619831
B39: 37 | C39: Стецюк Тетяна Леонідівна | D39: 01.07.2024 | E39: 661 | F39: 5460 | H39: =MATCH(I39,#REF!,0) -> #REF! | I39: =TRIM(C39) -> Стецюк Тетяна Леонідівна | J39: 1
B40: 38 | C40: Тужиков Валерій Владиславович (осн.) | D40: 01.07.2024 | E40: 661 | F40: 3990 | H40: =MATCH(I40,#REF!,0) -> #REF! | I40: =#REF! -> #REF! | K40: =INDEX(Лист2!D:D,MATCH(C40,Лист2!C:C,0)) -> 3233009756
B41: 39 | C41: Тужиков Юрій Владиславович | D41: 01.07.2024 | E41: 661 | F41: 3324.99 | H41: =MATCH(I41,#REF!,0) -> #REF! | I41: =TRIM(C41) -> Тужиков Юрій Владиславович | K41: =INDEX(Лист2!D:D,MATCH(C41,Лист2!C:C,0)) -> 3153508799
B42: 40 | C42: Федорчук Денис Сергійович | D42: 01.07.2024 | E42: 661 | F42: 1995 | H42: =MATCH(I42,#REF!,0) -> #REF! | I42: =TRIM(C42) -> Федорчук Денис Сергійович | K42: =INDEX(Лист2!D:D,MATCH(C42,Лист2!C:C,0)) -> 3428705315
B43: 41 | C43: Чілібін Микола Євгенович | D43: 01.07.2024 | E43: 661 | F43: 5460 | H43: =MATCH(I43,#REF!,0) -> #REF! | I43: =TRIM(C43) -> Чілібін Микола Євгенович | J43: 1
B44: 42 | C44: Чуб Владислав Володимирович | D44: 01.07.2024 | E44: 661 | F44: 840 | H44: =MATCH(I44,#REF!,0) -> #REF! | I44: =TRIM(C44) -> Чуб Владислав Володимирович | K44: =INDEX(Лист2!D:D,MATCH(C44,Лист2!C:C,0)) -> 2858519154
B45: 43 | C45: Щербак Петро Іванович | D45: 01.07.2024 | E45: 661 | F45: 4620 | H45: =MATCH(I45,#REF!,0) -> #REF! | I45: =C45 -> Щербак Петро Іванович | K45: =INDEX(Лист2!D:D,MATCH(C45,Лист2!C:C,0)) -> 2537500655
...

Sheet Табель цех 16 по 30 вересня
A1: N | B1: Сотрудник | C1: Удержание за обеды на объекте | D1: виплати на картку за період 16-30.09.25 | E1: ЗП 16-30.09.25 | F1: Сальдо на -15.09.2025 | G1: до виплати | H1: Сальдо на 30.09.2025 | I1: Відпрацьовано годин | J1: ставка | K1: ИТР | L1: ЦО | M1: МХП лазня | N1: катеринопіль | O1: МД ВООЗ ЕМС | P1: кернел | Q1: глобино | R1: Вооз ЕМС | S1: ООН 36 | T1: ООН 37 | U1: ООН 38 | V1: ООН 39 | W1: ООН 40 | X1: ООН 43 | Y1: ООН 44 | Z1: ООН 45 | AA1: ООН 46 | AB1: ООН 47 | AC1: ООН 48 | AD1: ООН 49 | AE1: ООН 50 | AF1: ООН 51 | AG1: Форшахта | AH1: галерея 25,6 | AI1: ГРП | AJ1: Парк меляси | AK1: ООН42 | AL1: перевірка | AM1: ИТР | AN1: ЦО | AO1: МХП лазня | AP1: катеринопіль | AQ1: МД ВООЗ ЕМС | AR1: кернел | AS1: глобино | AT1: Вооз ЕМС | AU1: ООН 36 | AV1: ООН 37 | AW1: ООН 38 | AX1: ООН 39 | AY1: ООН 40 | AZ1: ООН 43 | BA1: ООН 44 | BB1: ООН 45 | BC1: ООН 46 | BD1: ООН 47 | BE1: ООН 48 | BF1: ООН 49 | BG1: ООН 50 | BH1: ООН 51 | BI1: Форшахта | BJ1: галерея 25,6 | BK1: ГРП | BL1: Парк меляси | BM1: ООН42 | BN1: перевірка
B2: Пономаренко Віталій Вікторович | D2: 8662.5 | E2: =I2*J2 -> 20880 | F2: 29.98 | G2: =IF(ROUND(E2+F2-C2-D2,-2)<0,0,ROUND(E2+F2-C2-D2,-2)) -> 12200 | H2: =E2+F2-G2-C2-D2 -> 47.48 | I2: 116 | J2: 180 | K2: =SUMIF(ИТР!B:B,B2,ИТР!R:R) -> 116 | L2: =SUMIF(_ЦО!$B:$B,B2,_ЦО!T:T) -> 0 | M2: =SUMIF('МХП лазня'!B:B,B2,'МХП лазня'!T:T) -> 0 | N2: =SUMIF(Катеринополь!$B:$B,B2,Катеринополь!$T:$T) -> 0 | O2: =SUMIF(ВООЗ!B:B,B2,ВООЗ!T:T) -> 0 | P2: =SUMIF(Кернел!B:B,B2,Кернел!T:T) -> 0 | Q2: =SUMIF('Глобино Мк'!B:B,B2,'Глобино Мк'!T:T) -> 0 | R2: =SUMIF('ВООЗ ЕМС'!B:B,B2,'ВООЗ ЕМС'!T:T) -> 0 | S2: =SUMIF('ООН 36'!B:B,B2,'ООН 36'!T:T) -> 0 | T2: =SUMIF('ООН 37'!B:B,B2,'ООН 37'!T:T) -> 0 | U2: =SUMIF('ООН 38'!B:B,B2,'ООН 38'!T:T) -> 0 | V2: =SUMIF(ООН39!B:B,B2,ООН39!T:T) -> 0 | W2: =SUMIF('ООН 40'!B:B,B2,'ООН 40'!T:T) -> 0 | X2: =SUMIF('ООН 43'!B:B,B2,'ООН 43'!T:T) -> 0 | Y2: =SUMIF('ООН 44'!B:B,B2,'ООН 44'!T:T) -> 0 | Z2: =SUMIF('ООН 45'!B:B,B2,'ООН 45'!V:V) -> 0 | AA2: =SUMIF(ООН46!B:B,B2,ООН46!T:T) -> 0 | AB2: =SUMIF(ООН47!B:B,B2,ООН47!T:T) -> 0 | AC2: =SUMIF(ООН48!B:B,B2,ООН48!T:T) -> 0 | AD2: =SUMIF(ООН49!B:B,B2,ООН49!T:T) -> 0 | AE2: =SUMIF(ООн50!B:B,B2,ООн50!T:T) -> 0 | AF2: =SUMIF(ООН51!B:B,B2,ООН51!T:T) -> 0 | AG2: =SUMIF(Форшахта!B:B,B2,Форшахта!T:T) -> 0 | AH2: =SUMIF('ГАлерея 25.6'!B:B,B2,'ГАлерея 25.6'!T:T) -> 0 | AI2: =SUMIF(ГРП!B:B,B2,ГРП!AI:AI) -> 0 | AJ2: =SUMIF('Парк меляси'!B:B,B2,'Парк меляси'!T:T) -> 0 | AK2: =SUMIF('ООН 42'!B:B,B2,'ООН 42'!T:T) -> 0 | AL2: =SUM(K2:AK2)-I2 -> 0 | AM2: =IFERROR($G2/$I2*K2,0) -> 12200 | AN2: =IFERROR($G2/$I2*L2,0) -> 0 | AO2: =IFERROR($G2/$I2*M2,0) -> 0 | AP2: =IFERROR($G2/$I2*N2,0) -> 0 | AQ2: =IFERROR($G2/$I2*O2,0) -> 0 | AR2: =IFERROR($G2/$I2*P2,0) -> 0 | AS2: =IFERROR($G2/$I2*Q2,0) -> 0 | AT2: =IFERROR($G2/$I2*R2,0) -> 0 | ... BM2: =IFERROR($G2/$I2*AK2,0) -> 0 | BN2: =SUM(AM2:BM2) -> 12200 | BO2: =BN2-G2 -> 0
B3: Скрипник Сергій Павлович | D3: 8610 | E3: =I3*J3 -> 14940 | F3: -2423.56 | G3: =IF(ROUND(E3+F3-C3-D3,-2)<0,0,ROUND(E3+F3-C3-D3,-2)) -> 3900 | H3: =E3+F3-G3-C3-D3 -> 6.44 | I3: 83 | J3: 180 | K3: =SUMIF(ИТР!B:B,B3,ИТР!R:R) -> 83 | L3: =SUMIF(_ЦО!$B:$B,B3,_ЦО!T:T) -> 0 | M3: =SUMIF('МХП лазня'!B:B,B3,'МХП лазня'!T:T) -> 0 | N3: =SUMIF(Катеринополь!$B:$B,B3,Катеринополь!$T:$T) -> 0 | O3: =SUMIF(ВООЗ!B:B,B3,ВООЗ!T:T) -> 0 | P3: =SUMIF(Кернел!B:B,B3,Кернел!T:T) -> 0 | Q3: =SUMIF('Глобино Мк'!B:B,B3,'Глобино Мк'!T:T) -> 0 | R3: =SUMIF('ВООЗ ЕМС'!B:B,B3,'ВООЗ ЕМС'!T:T) -> 0 | S3: =SUMIF('ООН 36'!B:B,B3,'ООН 36'!T:T) -> 0 | T3: =SUMIF('ООН 37'!B:B,B3,'ООН 37'!T:T) -> 0 | U3: =SUMIF('ООН 38'!B:B,B3,'ООН 38'!T:T) -> 0 | V3: =SUMIF(ООН39!B:B,B3,ООН39!T:T) -> 0 | W3: =SUMIF('ООН 40'!B:B,B3,'ООН 40'!T:T) -> 0 | X3: =SUMIF('ООН 43'!B:B,B3,'ООН 43'!T:T) -> 0 | Y3: =SUMIF('ООН 44'!B:B,B3,'ООН 44'!T:T) -> 0 | Z3: =SUMIF('ООН 45'!B:B,B3,'ООН 45'!V:V) -> 0 | AA3: =SUMIF(ООН46!B:B,B3,ООН46!T:T) -> 0 | AB3: =SUMIF(ООН47!B:B,B3,ООН47!T:T) -> 0 | AC3: =SUMIF(ООН48!B:B,B3,ООН48!T:T) -> 0 | AD3: =SUMIF(ООН49!B:B,B3,ООН49!T:T) -> 0 | AE3: =SUMIF(ООн50!B:B,B3,ООн50!T:T) -> 0 | AF3: =SUMIF(ООН51!B:B,B3,ООН51!T:T) -> 0 | AG3: =SUMIF(Форшахта!B:B,B3,Форшахта!T:T) -> 0 | AH3: =SUMIF('ГАлерея 25.6'!B:B,B3,'ГАлерея 25.6'!T:T) -> 0 | AI3: =SUMIF(ГРП!B:B,B3,ГРП!AI:AI) -> 0 | AJ3: =SUMIF('Парк меляси'!B:B,B3,'Парк меляси'!T:T) -> 0 | AK3: =SUMIF('ООН 42'!B:B,B3,'ООН 42'!T:T) -> 0 | AL3: =SUM(K3:AK3)-I3 -> 0 | AM3: =IFERROR($G3/$I3*K3,0) -> 3900 | AN3: =IFERROR($G3/$I3*L3,0) -> 0 | AO3: =IFERROR($G3/$I3*M3,0) -> 0 | AP3: =IFERROR($G3/$I3*N3,0) -> 0 | AQ3: =IFERROR($G3/$I3*O3,0) -> 0 | AR3: =IFERROR($G3/$I3*P3,0) -> 0 | AS3: =IFERROR($G3/$I3*Q3,0) -> 0 | AT3: =IFERROR($G3/$I3*R3,0) -> 0 | ... BM3: =IFERROR($G3/$I3*AK3,0) -> 0 | BN3: =SUM(AM3:BM3) -> 3900 | BO3: =BN3-G3 -> 0
A4: 1 | B4: Багацький Вадим Геннадійович | D4: 3927 | E4: =I4*J4 -> 24150 | F4: -14.75 | G4: =IF(ROUND(E4+F4-C4-D4,-2)<0,0,ROUND(E4+F4-C4-D4,-2)) -> 20200 | H4: =E4+F4-G4-C4-D4 -> 8.25 | I4: =_ЦО!T2+'МХП лазня'!T2+Катеринополь!T2+ВООЗ!T2+Кернел!T2+'Глобино Мк'!T2+'ВООЗ ЕМС'!T2+'ООН 36'!T2+'ООН 37'!T2+'ООН 38'!T2+ООН39!T2+'ООН 40'!T2+'ООН 43'!T2+'ООН 44'!T2+'ООН 45'!V2+ООН46!T2+ООН47!T2+ООН48!T2+ООН49!T2+ООн50!T2+ООН51!T2+Форшахта!T2+'ГАлерея 25.6'!T2+ГРП!AI2+'Парк меляси'!T2+'ООН 42'!T2 -> 161 | J4: 150 | K4: =SUMIF(ИТР!B:B,B4,ИТР!R:R) -> 0 | L4: =SUMIF(_ЦО!$B:$B,B4,_ЦО!T:T) -> 0 | M4: =SUMIF('МХП лазня'!B:B,B4,'МХП лазня'!T:T) -> 0 | N4: =SUMIF(Катеринополь!$B:$B,B4,Катеринополь!$T:$T) -> 33 | O4: =SUMIF(ВООЗ!B:B,B4,ВООЗ!T:T) -> 0 | P4: =SUMIF(Кернел!B:B,B4,Кернел!T:T) -> 0 | Q4: =SUMIF('Глобино Мк'!B:B,B4,'Глобино Мк'!T:T) -> 28 | R4: =SUMIF('ВООЗ ЕМС'!B:B,B4,'ВООЗ ЕМС'!T:T) -> 0 | S4: =SUMIF('ООН 36'!B:B,B4,'ООН 36'!T:T) -> 0 | T4: =SUMIF('ООН 37'!B:B,B4,'ООН 37'!T:T) -> 0 | U4: =SUMIF('ООН 38'!B:B,B4,'ООН 38'!T:T) -> 0 | V4: =SUMIF(ООН39!B:B,B4,ООН39!T:T) -> 0 | W4: =SUMIF('ООН 40'!B:B,B4,'ООН 40'!T:T) -> 0 | X4: =SUMIF('ООН 43'!B:B,B4,'ООН 43'!T:T) -> 0 | Y4: =SUMIF('ООН 44'!B:B,B4,'ООН 44'!T:T) -> 0 | Z4: =SUMIF('ООН 45'!B:B,B4,'ООН 45'!V:V) -> 0 | AA4: =SUMIF(ООН46!B:B,B4,ООН46!T:T) -> 11 | AB4: =SUMIF(ООН47!B:B,B4,ООН47!T:T) -> 0 | AC4: =SUMIF(ООН48!B:B,B4,ООН48!T:T) -> 0 | AD4: =SUMIF(ООН49!B:B,B4,ООН49!T:T) -> 0 | AE4: =SUMIF(ООн50!B:B,B4,ООн50!T:T) -> 0 | AF4: =SUMIF(ООН51!B:B,B4,ООН51!T:T) -> 0 | AG4: =SUMIF(Форшахта!B:B,B4,Форшахта!T:T) -> 0 | AH4: =SUMIF('ГАлерея 25.6'!B:B,B4,'ГАлерея 25.6'!T:T) -> 0 | AI4: =SUMIF(ГРП!B:B,B4,ГРП!AI:AI) -> 39 | AJ4: =SUMIF('Парк меляси'!B:B,B4,'Парк меляси'!T:T) -> 50 | AK4: =SUMIF('ООН 42'!B:B,B4,'ООН 42'!T:T) -> 0 | AL4: =SUM(K4:AK4)-I4 -> 0 | AM4: =IFERROR($G4/$I4*K4,0) -> 0 | AN4: =IFERROR($G4/$I4*L4,0) -> 0 | AO4: =IFERROR($G4/$I4*M4,0) -> 0 | AP4: =IFERROR($G4/$I4*N4,0) -> 4140.3727 | AQ4: =IFERROR($G4/$I4*O4,0) -> 0 | AR4: =IFERROR($G4/$I4*P4,0) -> 0 | AS4: =IFERROR($G4/$I4*Q4,0) -> 3513.0435 | AT4: =IFERROR($G4/$I4*R4,0) -> 0 | ... BM4: =IFERROR($G4/$I4*AK4,0) -> 0 | BN4: =SUM(AM4:BM4) -> 20200 | BO4: =BN4-G4 -> 0
A5: 2 | B5: Васильєв Віталій Юрійович | D5: 3927 | E5: =I5*J5 -> 17850 | F5: 2.26 | G5: =IF(ROUND(E5+F5-C5-D5,-2)<0,0,ROUND(E5+F5-C5-D5,-2)) -> 13900 | H5: =E5+F5-G5-C5-D5 -> 25.26 | I5: =_ЦО!T3+'МХП лазня'!T3+Катеринополь!T3+ВООЗ!T3+Кернел!T3+'Глобино Мк'!T3+'ВООЗ ЕМС'!T3+'ООН 36'!T3+'ООН 37'!T3+'ООН 38'!T3+ООН39!T3+'ООН 40'!T3+'ООН 43'!T3+'ООН 44'!T3+'ООН 45'!V3+ООН46!T3+ООН47!T3+ООН48!T3+ООН49!T3+ООн50!T3+ООН51!T3+Форшахта!T3+'ГАлерея 25.6'!T3+ГРП!AI3+'Парк меляси'!T3+'ООН 42'!T3 -> 119 | J5: 150 | K5: =SUMIF(ИТР!B:B,B5,ИТР!R:R) -> 0 | L5: =SUMIF(_ЦО!$B:$B,B5,_ЦО!T:T) -> 119 | M5: =SUMIF('МХП лазня'!B:B,B5,'МХП лазня'!T:T) -> 0 | N5: =SUMIF(Катеринополь!$B:$B,B5,Катеринополь!$T:$T) -> 0 | O5: =SUMIF(ВООЗ!B:B,B5,ВООЗ!T:T) -> 0 | P5: =SUMIF(Кернел!B:B,B5,Кернел!T:T) -> 0 | Q5: =SUMIF('Глобино Мк'!B:B,B5,'Глобино Мк'!T:T) -> 0 | R5: =SUMIF('ВООЗ ЕМС'!B:B,B5,'ВООЗ ЕМС'!T:T) -> 0 | S5: =SUMIF('ООН 36'!B:B,B5,'ООН 36'!T:T) -> 0 | T5: =SUMIF('ООН 37'!B:B,B5,'ООН 37'!T:T) -> 0 | U5: =SUMIF('ООН 38'!B:B,B5,'ООН 38'!T:T) -> 0 | V5: =SUMIF(ООН39!B:B,B5,ООН39!T:T) -> 0 | W5: =SUMIF('ООН 40'!B:B,B5,'ООН 40'!T:T) -> 0 | X5: =SUMIF('ООН 43'!B:B,B5,'ООН 43'!T:T) -> 0 | Y5: =SUMIF('ООН 44'!B:B,B5,'ООН 44'!T:T) -> 0 | Z5: =SUMIF('ООН 45'!B:B,B5,'ООН 45'!V:V) -> 0 | AA5: =SUMIF(ООН46!B:B,B5,ООН46!T:T) -> 0 | AB5: =SUMIF(ООН47!B:B,B5,ООН47!T:T) -> 0 | AC5: =SUMIF(ООН48!B:B,B5,ООН48!T:T) -> 0 | AD5: =SUMIF(ООН49!B:B,B5,ООН49!T:T) -> 0 | AE5: =SUMIF(ООн50!B:B,B5,ООн50!T:T) -> 0 | AF5: =SUMIF(ООН51!B:B,B5,ООН51!T:T) -> 0 | AG5: =SUMIF(Форшахта!B:B,B5,Форшахта!T:T) -> 0 | AH5: =SUMIF('ГАлерея 25.6'!B:B,B5,'ГАлерея 25.6'!T:T) -> 0 | AI5: =SUMIF(ГРП!B:B,B5,ГРП!AI:AI) -> 0 | AJ5: =SUMIF('Парк меляси'!B:B,B5,'Парк меляси'!T:T) -> 0 | AK5: =SUMIF('ООН 42'!B:B,B5,'ООН 42'!T:T) -> 0 | AL5: =SUM(K5:AK5)-I5 -> 0 | AM5: =IFERROR($G5/$I5*K5,0) -> 0 | AN5: =IFERROR($G5/$I5*L5,0) -> 13900 | AO5: =IFERROR($G5/$I5*M5,0) -> 0 | AP5: =IFERROR($G5/$I5*N5,0) -> 0 | AQ5: =IFERROR($G5/$I5*O5,0) -> 0 | AR5: =IFERROR($G5/$I5*P5,0) -> 0 | AS5: =IFERROR($G5/$I5*Q5,0) -> 0 | AT5: =IFERROR($G5/$I5*R5,0) -> 0 | ... BM5: =IFERROR($G5/$I5*AK5,0) -> 0 | BN5: =SUM(AM5:BM5) -> 13900 | BO5: =BN5-G5 -> 0
A6: 3 | B6: Григоренко Олександр Миколайович | C6: 10324.25 | D6: 3927 | E6: =I6*J6 -> 54000 | F6: 39.75 | G6: =IF(ROUND(E6+F6-C6-D6,-2)<0,0,ROUND(E6+F6-C6-D6,-2)) -> 39800 | H6: =E6+F6-G6-C6-D6 -> -11.5 | I6: =_ЦО!T4+'МХП лазня'!T4+Катеринополь!T4+ВООЗ!T4+Кернел!T4+'Глобино Мк'!T4+'ВООЗ ЕМС'!T4+'ООН 36'!T4+'ООН 37'!T4+'ООН 38'!T4+ООН39!T4+'ООН 40'!T4+'ООН 43'!T4+'ООН 44'!T4+'ООН 45'!V4+ООН46!T4+ООН47!T4+ООН48!T4+ООН49!T4+ООн50!T4+ООН51!T4+Форшахта!T4+'ГАлерея 25.6'!T4+ГРП!AI4+'Парк меляси'!T4+'ООН 42'!T4 -> 360 | J6: 150 | K6: =SUMIF(ИТР!B:B,B6,ИТР!R:R) -> 0 | L6: =SUMIF(_ЦО!$B:$B,B6,_ЦО!T:T) -> 0 | M6: =SUMIF('МХП лазня'!B:B,B6,'МХП лазня'!T:T) -> 0 | N6: =SUMIF(Катеринополь!$B:$B,B6,Катеринополь!$T:$T) -> 0 | O6: =SUMIF(ВООЗ!B:B,B6,ВООЗ!T:T) -> 0 | P6: =SUMIF(Кернел!B:B,B6,Кернел!T:T) -> 360 | Q6: =SUMIF('Глобино Мк'!B:B,B6,'Глобино Мк'!T:T) -> 0 | R6: =SUMIF('ВООЗ ЕМС'!B:B,B6,'ВООЗ ЕМС'!T:T) -> 0 | S6: =SUMIF('ООН 36'!B:B,B6,'ООН 36'!T:T) -> 0 | T6: =SUMIF('ООН 37'!B:B,B6,'ООН 37'!T:T) -> 0 | U6: =SUMIF('ООН 38'!B:B,B6,'ООН 38'!T:T) -> 0 | V6: =SUMIF(ООН39!B:B,B6,ООН39!T:T) -> 0 | W6: =SUMIF('ООН 40'!B:B,B6,'ООН 40'!T:T) -> 0 | X6: =SUMIF('ООН 43'!B:B,B6,'ООН 43'!T:T) -> 0 | Y6: =SUMIF('ООН 44'!B:B,B6,'ООН 44'!T:T) -> 0 | Z6: =SUMIF('ООН 45'!B:B,B6,'ООН 45'!V:V) -> 0 | AA6: =SUMIF(ООН46!B:B,B6,ООН46!T:T) -> 0 | AB6: =SUMIF(ООН47!B:B,B6,ООН47!T:T) -> 0 | AC6: =SUMIF(ООН48!B:B,B6,ООН48!T:T) -> 0 | AD6: =SUMIF(ООН49!B:B,B6,ООН49!T:T) -> 0 | AE6: =SUMIF(ООн50!B:B,B6,ООн50!T:T) -> 0 | AF6: =SUMIF(ООН51!B:B,B6,ООН51!T:T) -> 0 | AG6: =SUMIF(Форшахта!B:B,B6,Форшахта!T:T) -> 0 | AH6: =SUMIF('ГАлерея 25.6'!B:B,B6,'ГАлерея 25.6'!T:T) -> 0 | AI6: =SUMIF(ГРП!B:B,B6,ГРП!AI:AI) -> 0 | AJ6: =SUMIF('Парк меляси'!B:B,B6,'Парк меляси'!T:T) -> 0 | AK6: =SUMIF('ООН 42'!B:B,B6,'ООН 42'!T:T) -> 0 | AL6: =SUM(K6:AK6)-I6 -> 0 | AM6: =IFERROR($G6/$I6*K6,0) -> 0 | AN6: =IFERROR($G6/$I6*L6,0) -> 0 | AO6: =IFERROR($G6/$I6*M6,0) -> 0 | AP6: =IFERROR($G6/$I6*N6,0) -> 0 | AQ6: =IFERROR($G6/$I6*O6,0) -> 0 | AR6: =IFERROR($G6/$I6*P6,0) -> 39800 | AS6: =IFERROR($G6/$I6*Q6,0) -> 0 | AT6: =IFERROR($G6/$I6*R6,0) -> 0 | ... BM6: =IFERROR($G6/$I6*AK6,0) -> 0 | BN6: =SUM(AM6:BM6) -> 39800 | BO6: =BN6-G6 -> 0
A7: 4 | B7: Григорьєв Микола Андрійович | D7: 3927 | E7: =I7*J7 -> 18150 | F7: -28.74 | G7: =IF(ROUND(E7+F7-C7-D7,-2)<0,0,ROUND(E7+F7-C7-D7,-2)) -> 14200 | H7: =E7+F7-G7-C7-D7 -> -5.74 | I7: =_ЦО!T5+'МХП лазня'!T5+Катеринополь!T5+ВООЗ!T5+Кернел!T5+'Глобино Мк'!T5+'ВООЗ ЕМС'!T5+'ООН 36'!T5+'ООН 37'!T5+'ООН 38'!T5+ООН39!T5+'ООН 40'!T5+'ООН 43'!T5+'ООН 44'!T5+'ООН 45'!V5+ООН46!T5+ООН47!T5+ООН48!T5+ООН49!T5+ООн50!T5+ООН51!T5+Форшахта!T5+'ГАлерея 25.6'!T5+ГРП!AI5+'Парк меляси'!T5+'ООН 42'!T5 -> 121 | J7: 150 | K7: =SUMIF(ИТР!B:B,B7,ИТР!R:R) -> 0 | L7: =SUMIF(_ЦО!$B:$B,B7,_ЦО!T:T) -> 0 | M7: =SUMIF('МХП лазня'!B:B,B7,'МХП лазня'!T:T) -> 0 | N7: =SUMIF(Катеринополь!$B:$B,B7,Катеринополь!$T:$T) -> 0 | O7: =SUMIF(ВООЗ!B:B,B7,ВООЗ!T:T) -> 0 | P7: =SUMIF(Кернел!B:B,B7,Кернел!T:T) -> 0 | Q7: =SUMIF('Глобино Мк'!B:B,B7,'Глобино Мк'!T:T) -> 0 | R7: =SUMIF('ВООЗ ЕМС'!B:B,B7,'ВООЗ ЕМС'!T:T) -> 0 | S7: =SUMIF('ООН 36'!B:B,B7,'ООН 36'!T:T) -> 0 | T7: =SUMIF('ООН 37'!B:B,B7,'ООН 37'!T:T) -> 0 | U7: =SUMIF('ООН 38'!B:B,B7,'ООН 38'!T:T) -> 0 | V7: =SUMIF(ООН39!B:B,B7,ООН39!T:T) -> 0 | W7: =SUMIF('ООН 40'!B:B,B7,'ООН 40'!T:T) -> 0 | X7: =SUMIF('ООН 43'!B:B,B7,'ООН 43'!T:T) -> 0 | Y7: =SUMIF('ООН 44'!B:B,B7,'ООН 44'!T:T) -> 0 | Z7: =SUMIF('ООН 45'!B:B,B7,'ООН 45'!V:V) -> 22 | AA7: =SUMIF(ООН46!B:B,B7,ООН46!T:T) -> 44 | AB7: =SUMIF(ООН47!B:B,B7,ООН47!T:T) -> 44 | AC7: =SUMIF(ООН48!B:B,B7,ООН48!T:T) -> 11 | AD7: =SUMIF(ООН49!B:B,B7,ООН49!T:T) -> 0 | AE7: =SUMIF(ООн50!B:B,B7,ООн50!T:T) -> 0 | AF7: =SUMIF(ООН51!B:B,B7,ООН51!T:T) -> 0 | AG7: =SUMIF(Форшахта!B:B,B7,Форшахта!T:T) -> 0 | AH7: =SUMIF('ГАлерея 25.6'!B:B,B7,'ГАлерея 25.6'!T:T) -> 0 | AI7: =SUMIF(ГРП!B:B,B7,ГРП!AI:AI) -> 0 | AJ7: =SUMIF('Парк меляси'!B:B,B7,'Парк меляси'!T:T) -> 0 | AK7: =SUMIF('ООН 42'!B:B,B7,'ООН 42'!T:T) -> 0 | AL7: =SUM(K7:AK7)-I7 -> 0 | AM7: =IFERROR($G7/$I7*K7,0) -> 0 | AN7: =IFERROR($G7/$I7*L7,0) -> 0 | AO7: =IFERROR($G7/$I7*M7,0) -> 0 | AP7: =IFERROR($G7/$I7*N7,0) -> 0 | AQ7: =IFERROR($G7/$I7*O7,0) -> 0 | AR7: =IFERROR($G7/$I7*P7,0) -> 0 | AS7: =IFERROR($G7/$I7*Q7,0) -> 0 | AT7: =IFERROR($G7/$I7*R7,0) -> 0 | ... BM7: =IFERROR($G7/$I7*AK7,0) -> 0 | BN7: =SUM(AM7:BM7) -> 14200 | BO7: =BN7-G7 -> 0
A8: 5 | B8: Григор'єв Михайло Андрійович | D8: 3927 | E8: =I8*J8 -> 19050 | F8: 6.17 | G8: =IF(ROUND(E8+F8-C8-D8,-2)<0,0,ROUND(E8+F8-C8-D8,-2)) -> 15100 | H8: =E8+F8-G8-C8-D8 -> 29.17 | I8: =_ЦО!T6+'МХП лазня'!T6+Катеринополь!T6+ВООЗ!T6+Кернел!T6+'Глобино Мк'!T6+'ВООЗ ЕМС'!T6+'ООН 36'!T6+'ООН 37'!T6+'ООН 38'!T6+ООН39!T6+'ООН 40'!T6+'ООН 43'!T6+'ООН 44'!T6+'ООН 45'!V6+ООН46!T6+ООН47!T6+ООН48!T6+ООН49!T6+ООн50!T6+ООН51!T6+Форшахта!T6+'ГАлерея 25.6'!T6+ГРП!AI6+'Парк меляси'!T6+'ООН 42'!T6 -> 127 | J8: 150 | K8: =SUMIF(ИТР!B:B,B8,ИТР!R:R) -> 0 | L8: =SUMIF(_ЦО!$B:$B,B8,_ЦО!T:T) -> 0 | M8: =SUMIF('МХП лазня'!B:B,B8,'МХП лазня'!T:T) -> 0 | N8: =SUMIF(Катеринополь!$B:$B,B8,Катеринополь!$T:$T) -> 0 | O8: =SUMIF(ВООЗ!B:B,B8,ВООЗ!T:T) -> 0 | P8: =SUMIF(Кернел!B:B,B8,Кернел!T:T) -> 0 | Q8: =SUMIF('Глобино Мк'!B:B,B8,'Глобино Мк'!T:T) -> 0 | R8: =SUMIF('ВООЗ ЕМС'!B:B,B8,'ВООЗ ЕМС'!T:T) -> 0 | S8: =SUMIF('ООН 36'!B:B,B8,'ООН 36'!T:T) -> 0 | T8: =SUMIF('ООН 37'!B:B,B8,'ООН 37'!T:T) -> 0 | U8: =SUMIF('ООН 38'!B:B,B8,'ООН 38'!T:T) -> 0 | V8: =SUMIF(ООН39!B:B,B8,ООН39!T:T) -> 0 | W8: =SUMIF('ООН 40'!B:B,B8,'ООН 40'!T:T) -> 0 | X8: =SUMIF('ООН 43'!B:B,B8,'ООН 43'!T:T) -> 0 | Y8: =SUMIF('ООН 44'!B:B,B8,'ООН 44'!T:T) -> 0 | Z8: =SUMIF('ООН 45'!B:B,B8,'ООН 45'!V:V) -> 22 | AA8: =SUMIF(ООН46!B:B,B8,ООН46!T:T) -> 44 | AB8: =SUMIF(ООН47!B:B,B8,ООН47!T:T) -> 44 | AC8: =SUMIF(ООН48!B:B,B8,ООН48!T:T) -> 17 | AD8: =SUMIF(ООН49!B:B,B8,ООН49!T:T) -> 0 | AE8: =SUMIF(ООн50!B:B,B8,ООн50!T:T) -> 0 | AF8: =SUMIF(ООН51!B:B,B8,ООН51!T:T) -> 0 | AG8: =SUMIF(Форшахта!B:B,B8,Форшахта!T:T) -> 0 | AH8: =SUMIF('ГАлерея 25.6'!B:B,B8,'ГАлерея 25.6'!T:T) -> 0 | AI8: =SUMIF(ГРП!B:B,B8,ГРП!AI:AI) -> 0 | AJ8: =SUMIF('Парк меляси'!B:B,B8,'Парк меляси'!T:T) -> 0 | AK8: =SUMIF('ООН 42'!B:B,B8,'ООН 42'!T:T) -> 0 | AL8: =SUM(K8:AK8)-I8 -> 0 | AM8: =IFERROR($G8/$I8*K8,0) -> 0 | AN8: =IFERROR($G8/$I8*L8,0) -> 0 | AO8: =IFERROR($G8/$I8*M8,0) -> 0 | AP8: =IFERROR($G8/$I8*N8,0) -> 0 | AQ8: =IFERROR($G8/$I8*O8,0) -> 0 | AR8: =IFERROR($G8/$I8*P8,0) -> 0 | AS8: =IFERROR($G8/$I8*Q8,0) -> 0 | AT8: =IFERROR($G8/$I8*R8,0) -> 0 | ... BM8: =IFERROR($G8/$I8*AK8,0) -> 0 | BN8: =SUM(AM8:BM8) -> 15100 | BO8: =BN8-G8 -> 0
A9: 6 | B9: Іванов Олексій Вікторович | D9: 3927 | E9: =I9*J9 -> 19050 | F9: -18.45 | G9: =IF(ROUND(E9+F9-C9-D9,-2)<0,0,ROUND(E9+F9-C9-D9,-2)) -> 15100 | H9: =E9+F9-G9-C9-D9 -> 4.55 | I9: =_ЦО!T7+'МХП лазня'!T7+Катеринополь!T7+ВООЗ!T7+Кернел!T7+'Глобино Мк'!T7+'ВООЗ ЕМС'!T7+'ООН 36'!T7+'ООН 37'!T7+'ООН 38'!T7+ООН39!T7+'ООН 40'!T7+'ООН 43'!T7+'ООН 44'!T7+'ООН 45'!V7+ООН46!T7+ООН47!T7+ООН48!T7+ООН49!T7+ООн50!T7+ООН51!T7+Форшахта!T7+'ГАлерея 25.6'!T7+ГРП!AI7+'Парк меляси'!T7+'ООН 42'!T7 -> 127 | J9: 150 | K9: =SUMIF(ИТР!B:B,B9,ИТР!R:R) -> 0 | L9: =SUMIF(_ЦО!$B:$B,B9,_ЦО!T:T) -> 0 | M9: =SUMIF('МХП лазня'!B:B,B9,'МХП лазня'!T:T) -> 0 | N9: =SUMIF(Катеринополь!$B:$B,B9,Катеринополь!$T:$T) -> 0 | O9: =SUMIF(ВООЗ!B:B,B9,ВООЗ!T:T) -> 0 | P9: =SUMIF(Кернел!B:B,B9,Кернел!T:T) -> 0 | Q9: =SUMIF('Глобино Мк'!B:B,B9,'Глобино Мк'!T:T) -> 33 | R9: =SUMIF('ВООЗ ЕМС'!B:B,B9,'ВООЗ ЕМС'!T:T) -> 0 | S9: =SUMIF('ООН 36'!B:B,B9,'ООН 36'!T:T) -> 0 | T9: =SUMIF('ООН 37'!B:B,B9,'ООН 37'!T:T) -> 0 | U9: =SUMIF('ООН 38'!B:B,B9,'ООН 38'!T:T) -> 0 | V9: =SUMIF(ООН39!B:B,B9,ООН39!T:T) -> 0 | W9: =SUMIF('ООН 40'!B:B,B9,'ООН 40'!T:T) -> 0 | X9: =SUMIF('ООН 43'!B:B,B9,'ООН 43'!T:T) -> 0 | Y9: =SUMIF('ООН 44'!B:B,B9,'ООН 44'!T:T) -> 0 | Z9: =SUMIF('ООН 45'!B:B,B9,'ООН 45'!V:V) -> 0 | AA9: =SUMIF(ООН46!B:B,B9,ООН46!T:T) -> 0 | AB9: =SUMIF(ООН47!B:B,B9,ООН47!T:T) -> 0 | AC9: =SUMIF(ООН48!B:B,B9,ООН48!T:T) -> 0 | AD9: =SUMIF(ООН49!B:B,B9,ООН49!T:T) -> 0 | AE9: =SUMIF(ООн50!B:B,B9,ООн50!T:T) -> 0 | AF9: =SUMIF(ООН51!B:B,B9,ООН51!T:T) -> 0 | AG9: =SUMIF(Форшахта!B:B,B9,Форшахта!T:T) -> 11 | AH9: =SUMIF('ГАлерея 25.6'!B:B,B9,'ГАлерея 25.6'!T:T) -> 22 | AI9: =SUMIF(ГРП!B:B,B9,ГРП!AI:AI) -> 11 | AJ9: =SUMIF('Парк меляси'!B:B,B9,'Парк меляси'!T:T) -> 50 | AK9: =SUMIF('ООН 42'!B:B,B9,'ООН 42'!T:T) -> 0 | AL9: =SUM(K9:AK9)-I9 -> 0 | AM9: =IFERROR($G9/$I9*K9,0) -> 0 | AN9: =IFERROR($G9/$I9*L9,0) -> 0 | AO9: =IFERROR($G9/$I9*M9,0) -> 0 | AP9: =IFERROR($G9/$I9*N9,0) -> 0 | AQ9: =IFERROR($G9/$I9*O9,0) -> 0 | AR9: =IFERROR($G9/$I9*P9,0) -> 0 | AS9: =IFERROR($G9/$I9*Q9,0) -> 3923.622 | AT9: =IFERROR($G9/$I9*R9,0) -> 0 | ... BM9: =IFERROR($G9/$I9*AK9,0) -> 0 | BN9: =SUM(AM9:BM9) -> 15100 | BO9: =BN9-G9 -> 0
A10: 7 | B10: Іскрицький Денис Русланович | D10: 18640.48 | E10: =I10*J10 -> 23400 | F10: -10.24 | G10: =IF(ROUND(E10+F10-C10-D10,-2)<0,0,ROUND(E10+F10-C10-D10,-2)) -> 4700 | H10: =E10+F10-G10-C10-D10 -> 49.28 | I10: =_ЦО!T8+'МХП лазня'!T8+Катеринополь!T8+ВООЗ!T8+Кернел!T8+'Глобино Мк'!T8+'ВООЗ ЕМС'!T8+'ООН 36'!T8+'ООН 37'!T8+'ООН 38'!T8+ООН39!T8+'ООН 40'!T8+'ООН 43'!T8+'ООН 44'!T8+'ООН 45'!V8+ООН46!T8+ООН47!T8+ООН48!T8+ООН49!T8+ООн50!T8+ООН51!T8+Форшахта!T8+'ГАлерея 25.6'!T8+ГРП!AI8+'Парк меляси'!T8+'ООН 42'!T8 -> 156 | J10: 150 | K10: =SUMIF(ИТР!B:B,B10,ИТР!R:R) -> 0 | L10: =SUMIF(_ЦО!$B:$B,B10,_ЦО!T:T) -> 0 | M10: =SUMIF('МХП лазня'!B:B,B10,'МХП лазня'!T:T) -> 0 | N10: =SUMIF(Катеринополь!$B:$B,B10,Катеринополь!$T:$T) -> 0 | O10: =SUMIF(ВООЗ!B:B,B10,ВООЗ!T:T) -> 0 | P10: =SUMIF(Кернел!B:B,B10,Кернел!T:T) -> 0 | Q10: =SUMIF('Глобино Мк'!B:B,B10,'Глобино Мк'!T:T) -> 44 | R10: =SUMIF('ВООЗ ЕМС'!B:B,B10,'ВООЗ ЕМС'!T:T) -> 0 | S10: =SUMIF('ООН 36'!B:B,B10,'ООН 36'!T:T) -> 0 | T10: =SUMIF('ООН 37'!B:B,B10,'ООН 37'!T:T) -> 0 | U10: =SUMIF('ООН 38'!B:B,B10,'ООН 38'!T:T) -> 0 | V10: =SUMIF(ООН39!B:B,B10,ООН39!T:T) -> 0 | W10: =SUMIF('ООН 40'!B:B,B10,'ООН 40'!T:T) -> 0 | X10: =SUMIF('ООН 43'!B:B,B10,'ООН 43'!T:T) -> 0 | Y10: =SUMIF('ООН 44'!B:B,B10,'ООН 44'!T:T) -> 0 | Z10: =SUMIF('ООН 45'!B:B,B10,'ООН 45'!V:V) -> 0 | AA10: =SUMIF(ООН46!B:B,B10,ООН46!T:T) -> 0 | AB10: =SUMIF(ООН47!B:B,B10,ООН47!T:T) -> 0 | AC10: =SUMIF(ООН48!B:B,B10,ООН48!T:T) -> 0 | AD10: =SUMIF(ООН49!B:B,B10,ООН49!T:T) -> 0 | AE10: =SUMIF(ООн50!B:B,B10,ООн50!T:T) -> 0 | AF10: =SUMIF(ООН51!B:B,B10,ООН51!T:T) -> 0 | AG10: =SUMIF(Форшахта!B:B,B10,Форшахта!T:T) -> 22 | AH10: =SUMIF('ГАлерея 25.6'!B:B,B10,'ГАлерея 25.6'!T:T) -> 22 | AI10: =SUMIF(ГРП!B:B,B10,ГРП!AI:AI) -> 22 | AJ10: =SUMIF('Парк меляси'!B:B,B10,'Парк меляси'!T:T) -> 46 | AK10: =SUMIF('ООН 42'!B:B,B10,'ООН 42'!T:T) -> 0 | AL10: =SUM(K10:AK10)-I10 -> 0 | AM10: =IFERROR($G10/$I10*K10,0) -> 0 | AN10: =IFERROR($G10/$I10*L10,0) -> 0 | AO10: =IFERROR($G10/$I10*M10,0) -> 0 | AP10: =IFERROR($G10/$I10*N10,0) -> 0 | AQ10: =IFERROR($G10/$I10*O10,0) -> 0 | AR10: =IFERROR($G10/$I10*P10,0) -> 0 | AS10: =IFERROR($G10/$I10*Q10,0) -> 1325.641 | AT10: =IFERROR($G10/$I10*R10,0) -> 0 | ... BM10: =IFERROR($G10/$I10*AK10,0) -> 0 | BN10: =SUM(AM10:BM10) -> 4700 | BO10: =BN10-G10 -> 0
A11: 8 | B11: Корнієнко Станіслав Володимирович | C11: 10324.25 | D11: 3927 | E11: =I11*J11 -> 54000 | F11: 32.54 | G11: =IF(ROUND(E11+F11-C11-D11,-2)<0,0,ROUND(E11+F11-C11-D11,-2)) -> 39800 | H11: =E11+F11-G11-C11-D11 -> -18.71 | I11: =_ЦО!T9+'МХП лазня'!T9+Катеринополь!T9+ВООЗ!T9+Кернел!T9+'Глобино Мк'!T9+'ВООЗ ЕМС'!T9+'ООН 36'!T9+'ООН 37'!T9+'ООН 38'!T9+ООН39!T9+'ООН 40'!T9+'ООН 43'!T9+'ООН 44'!T9+'ООН 45'!V9+ООН46!T9+ООН47!T9+ООН48!T9+ООН49!T9+ООн50!T9+ООН51!T9+Форшахта!T9+'ГАлерея 25.6'!T9+ГРП!AI9+'Парк меляси'!T9+'ООН 42'!T9 -> 360 | J11: 150 | K11: =SUMIF(ИТР!B:B,B11,ИТР!R:R) -> 0 | L11: =SUMIF(_ЦО!$B:$B,B11,_ЦО!T:T) -> 0 | M11: =SUMIF('МХП лазня'!B:B,B11,'МХП лазня'!T:T) -> 0 | N11: =SUMIF(Катеринополь!$B:$B,B11,Катеринополь!$T:$T) -> 0 | O11: =SUMIF(ВООЗ!B:B,B11,ВООЗ!T:T) -> 0 | P11: =SUMIF(Кернел!B:B,B11,Кернел!T:T) -> 360 | Q11: =SUMIF('Глобино Мк'!B:B,B11,'Глобино Мк'!T:T) -> 0 | R11: =SUMIF('ВООЗ ЕМС'!B:B,B11,'ВООЗ ЕМС'!T:T) -> 0 | S11: =SUMIF('ООН 36'!B:B,B11,'ООН 36'!T:T) -> 0 | T11: =SUMIF('ООН 37'!B:B,B11,'ООН 37'!T:T) -> 0 | U11: =SUMIF('ООН 38'!B:B,B11,'ООН 38'!T:T) -> 0 | V11: =SUMIF(ООН39!B:B,B11,ООН39!T:T) -> 0 | W11: =SUMIF('ООН 40'!B:B,B11,'ООН 40'!T:T) -> 0 | X11: =SUMIF('ООН 43'!B:B,B11,'ООН 43'!T:T) -> 0 | Y11: =SUMIF('ООН 44'!B:B,B11,'ООН 44'!T:T) -> 0 | Z11: =SUMIF('ООН 45'!B:B,B11,'ООН 45'!V:V) -> 0 | AA11: =SUMIF(ООН46!B:B,B11,ООН46!T:T) -> 0 | AB11: =SUMIF(ООН47!B:B,B11,ООН47!T:T) -> 0 | AC11: =SUMIF(ООН48!B:B,B11,ООН48!T:T) -> 0 | AD11: =SUMIF(ООН49!B:B,B11,ООН49!T:T) -> 0 | AE11: =SUMIF(ООн50!B:B,B11,ООн50!T:T) -> 0 | AF11: =SUMIF(ООН51!B:B,B11,ООН51!T:T) -> 0 | AG11: =SUMIF(Форшахта!B:B,B11,Форшахта!T:T) -> 0 | AH11: =SUMIF('ГАлерея 25.6'!B:B,B11,'ГАлерея 25.6'!T:T) -> 0 | AI11: =SUMIF(ГРП!B:B,B11,ГРП!AI:AI) -> 0 | AJ11: =SUMIF('Парк меляси'!B:B,B11,'Парк меляси'!T:T) -> 0 | AK11: =SUMIF('ООН 42'!B:B,B11,'ООН 42'!T:T) -> 0 | AL11: =SUM(K11:AK11)-I11 -> 0 | AM11: =IFERROR($G11/$I11*K11,0) -> 0 | AN11: =IFERROR($G11/$I11*L11,0) -> 0 | AO11: =IFERROR($G11/$I11*M11,0) -> 0 | AP11: =IFERROR($G11/$I11*N11,0) -> 0 | AQ11: =IFERROR($G11/$I11*O11,0) -> 0 | AR11: =IFERROR($G11/$I11*P11,0) -> 39800 | AS11: =IFERROR($G11/$I11*Q11,0) -> 0 | AT11: =IFERROR($G11/$I11*R11,0) -> 0 | ... BM11: =IFERROR($G11/$I11*AK11,0) -> 0 | BN11: =SUM(AM11:BM11) -> 39800 | BO11: =BN11-G11 -> 0
A12: 9 | B12: Масливець Ігор Валерійович | D12: 3927 | E12: =I12*J12 -> 20700 | F12: 34.95 | G12: =IF(ROUND(E12+F12-C12-D12,-2)<0,0,ROUND(E12+F12-C12-D12,-2)) -> 16800 | H12: =E12+F12-G12-C12-D12 -> 7.95 | I12: =_ЦО!T10+'МХП лазня'!T10+Катеринополь!T10+ВООЗ!T10+Кернел!T10+'Глобино Мк'!T10+'ВООЗ ЕМС'!T10+'ООН 36'!T10+'ООН 37'!T10+'ООН 38'!T10+ООН39!T10+'ООН 40'!T10+'ООН 43'!T10+'ООН 44'!T10+'ООН 45'!V10+ООН46!T10+ООН47!T10+ООН48!T10+ООН49!T10+ООн50!T10+ООН51!T10+Форшахта!T10+'ГАлерея 25.6'!T10+ГРП!AI10+'Парк меляси'!T10+'ООН 42'!T10 -> 138 | J12: 150 | K12: =SUMIF(ИТР!B:B,B12,ИТР!R:R) -> 0 | L12: =SUMIF(_ЦО!$B:$B,B12,_ЦО!T:T) -> 0 | M12: =SUMIF('МХП лазня'!B:B,B12,'МХП лазня'!T:T) -> 0 | N12: =SUMIF(Катеринополь!$B:$B,B12,Катеринополь!$T:$T) -> 11 | O12: =SUMIF(ВООЗ!B:B,B12,ВООЗ!T:T) -> 0 | P12: =SUMIF(Кернел!B:B,B12,Кернел!T:T) -> 0 | Q12: =SUMIF('Глобино Мк'!B:B,B12,'Глобино Мк'!T:T) -> 0 | R12: =SUMIF('ВООЗ ЕМС'!B:B,B12,'ВООЗ ЕМС'!T:T) -> 0 | S12: =SUMIF('ООН 36'!B:B,B12,'ООН 36'!T:T) -> 0 | T12: =SUMIF('ООН 37'!B:B,B12,'ООН 37'!T:T) -> 0 | U12: =SUMIF('ООН 38'!B:B,B12,'ООН 38'!T:T) -> 0 | V12: =SUMIF(ООН39!B:B,B12,ООН39!T:T) -> 0 | W12: =SUMIF('ООН 40'!B:B,B12,'ООН 40'!T:T) -> 0 | X12: =SUMIF('ООН 43'!B:B,B12,'ООН 43'!T:T) -> 0 | Y12: =SUMIF('ООН 44'!B:B,B12,'ООН 44'!T:T) -> 22 | Z12: =SUMIF('ООН 45'!B:B,B12,'ООН 45'!V:V) -> 0 | AA12: =SUMIF(ООН46!B:B,B12,ООН46!T:T) -> 44 | AB12: =SUMIF(ООН47!B:B,B12,ООН47!T:T) -> 61 | AC12: =SUMIF(ООН48!B:B,B12,ООН48!T:T) -> 0 | AD12: =SUMIF(ООН49!B:B,B12,ООН49!T:T) -> 0 | AE12: =SUMIF(ООн50!B:B,B12,ООн50!T:T) -> 0 | AF12: =SUMIF(ООН51!B:B,B12,ООН51!T:T) -> 0 | AG12: =SUMIF(Форшахта!B:B,B12,Форшахта!T:T) -> 0 | AH12: =SUMIF('ГАлерея 25.6'!B:B,B12,'ГАлерея 25.6'!T:T) -> 0 | AI12: =SUMIF(ГРП!B:B,B12,ГРП!AI:AI) -> 0 | AJ12: =SUMIF('Парк меляси'!B:B,B12,'Парк меляси'!T:T) -> 0 | AK12: =SUMIF('ООН 42'!B:B,B12,'ООН 42'!T:T) -> 0 | AL12: =SUM(K12:AK12)-I12 -> 0 | AM12: =IFERROR($G12/$I12*K12,0) -> 0 | AN12: =IFERROR($G12/$I12*L12,0) -> 0 | AO12: =IFERROR($G12/$I12*M12,0) -> 0 | AP12: =IFERROR($G12/$I12*N12,0) -> 1339.1304 | AQ12: =IFERROR($G12/$I12*O12,0) -> 0 | AR12: =IFERROR($G12/$I12*P12,0) -> 0 | AS12: =IFERROR($G12/$I12*Q12,0) -> 0 | AT12: =IFERROR($G12/$I12*R12,0) -> 0 | ... BM12: =IFERROR($G12/$I12*AK12,0) -> 0 | BN12: =SUM(AM12:BM12) -> 16800 | BO12: =BN12-G12 -> 0
A13: 10 | B13: Скрипник Олександр Павлович | D13: 3927 | E13: =I13*J13 -> 19050 | F13: -25 | G13: =IF(ROUND(E13+F13-C13-D13,-2)<0,0,ROUND(E13+F13-C13-D13,-2)) -> 15100 | H13: =E13+F13-G13-C13-D13 -> -2 | I13: =_ЦО!T11+'МХП лазня'!T11+Катеринополь!T11+ВООЗ!T11+Кернел!T11+'Глобино Мк'!T11+'ВООЗ ЕМС'!T11+'ООН 36'!T11+'ООН 37'!T11+'ООН 38'!T11+ООН39!T11+'ООН 40'!T11+'ООН 43'!T11+'ООН 44'!T11+'ООН 45'!V11+ООН46!T11+ООН47!T11+ООН48!T11+ООН49!T11+ООн50!T11+ООН51!T11+Форшахта!T11+'ГАлерея 25.6'!T11+ГРП!AI11+'Парк меляси'!T11+'ООН 42'!T11 -> 127 | J13: 150 | K13: =SUMIF(ИТР!B:B,B13,ИТР!R:R) -> 0 | L13: =SUMIF(_ЦО!$B:$B,B13,_ЦО!T:T) -> 0 | M13: =SUMIF('МХП лазня'!B:B,B13,'МХП лазня'!T:T) -> 83 | N13: =SUMIF(Катеринополь!$B:$B,B13,Катеринополь!$T:$T) -> 0 | O13: =SUMIF(ВООЗ!B:B,B13,ВООЗ!T:T) -> 0 | P13: =SUMIF(Кернел!B:B,B13,Кернел!T:T) -> 0 | Q13: =SUMIF('Глобино Мк'!B:B,B13,'Глобино Мк'!T:T) -> 0 | R13: =SUMIF('ВООЗ ЕМС'!B:B,B13,'ВООЗ ЕМС'!T:T) -> 0 | S13: =SUMIF('ООН 36'!B:B,B13,'ООН 36'!T:T) -> 0 | T13: =SUMIF('ООН 37'!B:B,B13,'ООН 37'!T:T) -> 0 | U13: =SUMIF('ООН 38'!B:B,B13,'ООН 38'!T:T) -> 0 | V13: =SUMIF(ООН39!B:B,B13,ООН39!T:T) -> 0 | W13: =SUMIF('ООН 40'!B:B,B13,'ООН 40'!T:T) -> 0 | X13: =SUMIF('ООН 43'!B:B,B13,'ООН 43'!T:T) -> 0 | Y13: =SUMIF('ООН 44'!B:B,B13,'ООН 44'!T:T) -> 22 | Z13: =SUMIF('ООН 45'!B:B,B13,'ООН 45'!V:V) -> 22 | AA13: =SUMIF(ООН46!B:B,B13,ООН46!T:T) -> 0 | AB13: =SUMIF(ООН47!B:B,B13,ООН47!T:T) -> 0 | AC13: =SUMIF(ООН48!B:B,B13,ООН48!T:T) -> 0 | AD13: =SUMIF(ООН49!B:B,B13,ООН49!T:T) -> 0 | AE13: =SUMIF(ООн50!B:B,B13,ООн50!T:T) -> 0 | AF13: =SUMIF(ООН51!B:B,B13,ООН51!T:T) -> 0 | AG13: =SUMIF(Форшахта!B:B,B13,Форшахта!T:T) -> 0 | AH13: =SUMIF('ГАлерея 25.6'!B:B,B13,'ГАлерея 25.6'!T:T) -> 0 | AI13: =SUMIF(ГРП!B:B,B13,ГРП!AI:AI) -> 0 | AJ13: =SUMIF('Парк меляси'!B:B,B13,'Парк меляси'!T:T) -> 0 | AK13: =SUMIF('ООН 42'!B:B,B13,'ООН 42'!T:T) -> 0 | AL13: =SUM(K13:AK13)-I13 -> 0 | AM13: =IFERROR($G13/$I13*K13,0) -> 0 | AN13: =IFERROR($G13/$I13*L13,0) -> 0 | AO13: =IFERROR($G13/$I13*M13,0) -> 9868.5039 | AP13: =IFERROR($G13/$I13*N13,0) -> 0 | AQ13: =IFERROR($G13/$I13*O13,0) -> 0 | AR13: =IFERROR($G13/$I13*P13,0) -> 0 | AS13: =IFERROR($G13/$I13*Q13,0) -> 0 | AT13: =IFERROR($G13/$I13*R13,0) -> 0 | ... BM13: =IFERROR($G13/$I13*AK13,0) -> 0 | BN13: =SUM(AM13:BM13) -> 15100 | BO13: =BN13-G13 -> 0
A14: 11 | B14: Паламарчук Вячеслав Володимирович | D14: 14676.63 | E14: =I14*J14 -> 19800 | F14: -36.63 | G14: =IF(ROUND(E14+F14-C14-D14,-2)<0,0,ROUND(E14+F14-C14-D14,-2)) -> 5100 | H14: =E14+F14-G14-C14-D14 -> -13.26 | I14: =_ЦО!T12+'МХП лазня'!T12+Катеринополь!T12+ВООЗ!T12+Кернел!T12+'Глобино Мк'!T12+'ВООЗ ЕМС'!T12+'ООН 36'!T12+'ООН 37'!T12+'ООН 38'!T12+ООН39!T12+'ООН 40'!T12+'ООН 43'!T12+'ООН 44'!T12+'ООН 45'!V12+ООН46!T12+ООН47!T12+ООН48!T12+ООН49!T12+ООн50!T12+ООН51!T12+Форшахта!T12+'ГАлерея 25.6'!T12+ГРП!AI12+'Парк меляси'!T12+'ООН 42'!T12 -> 132 | J14: 150 | K14: =SUMIF(ИТР!B:B,B14,ИТР!R:R) -> 0 | L14: =SUMIF(_ЦО!$B:$B,B14,_ЦО!T:T) -> 0 | M14: =SUMIF('МХП лазня'!B:B,B14,'МХП лазня'!T:T) -> 0 | N14: =SUMIF(Катеринополь!$B:$B,B14,Катеринополь!$T:$T) -> 0 | O14: =SUMIF(ВООЗ!B:B,B14,ВООЗ!T:T) -> 0 | P14: =SUMIF(Кернел!B:B,B14,Кернел!T:T) -> 0 | Q14: =SUMIF('Глобино Мк'!B:B,B14,'Глобино Мк'!T:T) -> 0 | R14: =SUMIF('ВООЗ ЕМС'!B:B,B14,'ВООЗ ЕМС'!T:T) -> 0 | S14: =SUMIF('ООН 36'!B:B,B14,'ООН 36'!T:T) -> 0 | T14: =SUMIF('ООН 37'!B:B,B14,'ООН 37'!T:T) -> 0 | U14: =SUMIF('ООН 38'!B:B,B14,'ООН 38'!T:T) -> 0 | V14: =SUMIF(ООН39!B:B,B14,ООН39!T:T) -> 0 | W14: =SUMIF('ООН 40'!B:B,B14,'ООН 40'!T:T) -> 0 | X14: =SUMIF('ООН 43'!B:B,B14,'ООН 43'!T:T) -> 0 | Y14: =SUMIF('ООН 44'!B:B,B14,'ООН 44'!T:T) -> 0 | Z14: =SUMIF('ООН 45'!B:B,B14,'ООН 45'!V:V) -> 22 | AA14: =SUMIF(ООН46!B:B,B14,ООН46!T:T) -> 39 | AB14: =SUMIF(ООН47!B:B,B14,ООН47!T:T) -> 55 | AC14: =SUMIF(ООН48!B:B,B14,ООН48!T:T) -> 16 | AD14: =SUMIF(ООН49!B:B,B14,ООН49!T:T) -> 0 | AE14: =SUMIF(ООн50!B:B,B14,ООн50!T:T) -> 0 | AF14: =SUMIF(ООН51!B:B,B14,ООН51!T:T) -> 0 | AG14: =SUMIF(Форшахта!B:B,B14,Форшахта!T:T) -> 0 | AH14: =SUMIF('ГАлерея 25.6'!B:B,B14,'ГАлерея 25.6'!T:T) -> 0 | AI14: =SUMIF(ГРП!B:B,B14,ГРП!AI:AI) -> 0 | AJ14: =SUMIF('Парк меляси'!B:B,B14,'Парк меляси'!T:T) -> 0 | AK14: =SUMIF('ООН 42'!B:B,B14,'ООН 42'!T:T) -> 0 | AL14: =SUM(K14:AK14)-I14 -> 0 | AM14: =IFERROR($G14/$I14*K14,0) -> 0 | AN14: =IFERROR($G14/$I14*L14,0) -> 0 | AO14: =IFERROR($G14/$I14*M14,0) -> 0 | AP14: =IFERROR($G14/$I14*N14,0) -> 0 | AQ14: =IFERROR($G14/$I14*O14,0) -> 0 | AR14: =IFERROR($G14/$I14*P14,0) -> 0 | AS14: =IFERROR($G14/$I14*Q14,0) -> 0 | AT14: =IFERROR($G14/$I14*R14,0) -> 0 | ... BM14: =IFERROR($G14/$I14*AK14,0) -> 0 | BN14: =SUM(AM14:BM14) -> 5100 | BO14: =BN14-G14 -> 0
A15: 12 | B15: Дехтяр Владислав Олександрович | C15: 10324.25 | D15: 3927 | E15: =I15*J15 -> 54000 | F15: -21.27 | G15: =IF(ROUND(E15+F15-C15-D15,-2)<0,0,ROUND(E15+F15-C15-D15,-2)) -> 39700 | H15: =E15+F15-G15-C15-D15 -> 27.48 | I15: =_ЦО!T13+'МХП лазня'!T13+Катеринополь!T13+ВООЗ!T13+Кернел!T13+'Глобино Мк'!T13+'ВООЗ ЕМС'!T13+'ООН 36'!T13+'ООН 37'!T13+'ООН 38'!T13+ООН39!T13+'ООН 40'!T13+'ООН 43'!T13+'ООН 44'!T13+'ООН 45'!V13+ООН46!T13+ООН47!T13+ООН48!T13+ООН49!T13+ООн50!T13+ООН51!T13+Форшахта!T13+'ГАлерея 25.6'!T13+ГРП!AI13+'Парк меляси'!T13+'ООН 42'!T13 -> 360 | J15: 150 | K15: =SUMIF(ИТР!B:B,B15,ИТР!R:R) -> 0 | L15: =SUMIF(_ЦО!$B:$B,B15,_ЦО!T:T) -> 0 | M15: =SUMIF('МХП лазня'!B:B,B15,'МХП лазня'!T:T) -> 0 | N15: =SUMIF(Катеринополь!$B:$B,B15,Катеринополь!$T:$T) -> 0 | O15: =SUMIF(ВООЗ!B:B,B15,ВООЗ!T:T) -> 0 | P15: =SUMIF(Кернел!B:B,B15,Кернел!T:T) -> 360 | Q15: =SUMIF('Глобино Мк'!B:B,B15,'Глобино Мк'!T:T) -> 0 | R15: =SUMIF('ВООЗ ЕМС'!B:B,B15,'ВООЗ ЕМС'!T:T) -> 0 | S15: =SUMIF('ООН 36'!B:B,B15,'ООН 36'!T:T) -> 0 | T15: =SUMIF('ООН 37'!B:B,B15,'ООН 37'!T:T) -> 0 | U15: =SUMIF('ООН 38'!B:B,B15,'ООН 38'!T:T) -> 0 | V15: =SUMIF(ООН39!B:B,B15,ООН39!T:T) -> 0 | W15: =SUMIF('ООН 40'!B:B,B15,'ООН 40'!T:T) -> 0 | X15: =SUMIF('ООН 43'!B:B,B15,'ООН 43'!T:T) -> 0 | Y15: =SUMIF('ООН 44'!B:B,B15,'ООН 44'!T:T) -> 0 | Z15: =SUMIF('ООН 45'!B:B,B15,'ООН 45'!V:V) -> 0 | AA15: =SUMIF(ООН46!B:B,B15,ООН46!T:T) -> 0 | AB15: =SUMIF(ООН47!B:B,B15,ООН47!T:T) -> 0 | AC15: =SUMIF(ООН48!B:B,B15,ООН48!T:T) -> 0 | AD15: =SUMIF(ООН49!B:B,B15,ООН49!T:T) -> 0 | AE15: =SUMIF(ООн50!B:B,B15,ООн50!T:T) -> 0 | AF15: =SUMIF(ООН51!B:B,B15,ООН51!T:T) -> 0 | AG15: =SUMIF(Форшахта!B:B,B15,Форшахта!T:T) -> 0 | AH15: =SUMIF('ГАлерея 25.6'!B:B,B15,'ГАлерея 25.6'!T:T) -> 0 | AI15: =SUMIF(ГРП!B:B,B15,ГРП!AI:AI) -> 0 | AJ15: =SUMIF('Парк меляси'!B:B,B15,'Парк меляси'!T:T) -> 0 | AK15: =SUMIF('ООН 42'!B:B,B15,'ООН 42'!T:T) -> 0 | AL15: =SUM(K15:AK15)-I15 -> 0 | AM15: =IFERROR($G15/$I15*K15,0) -> 0 | AN15: =IFERROR($G15/$I15*L15,0) -> 0 | AO15: =IFERROR($G15/$I15*M15,0) -> 0 | AP15: =IFERROR($G15/$I15*N15,0) -> 0 | AQ15: =IFERROR($G15/$I15*O15,0) -> 0 | AR15: =IFERROR($G15/$I15*P15,0) -> 39700 | AS15: =IFERROR($G15/$I15*Q15,0) -> 0 | AT15: =IFERROR($G15/$I15*R15,0) -> 0 | ... BM15: =IFERROR($G15/$I15*AK15,0) -> 0 | BN15: =SUM(AM15:BM15) -> 39700 | BO15: =BN15-G15 -> 0
A16: 13 | B16: Тужиков Валерій Владиславович | D16: 4575.09 | E16: =I16*J16 -> 17400 | F16: -40.34 | G16: =IF(ROUND(E16+F16-C16-D16,-2)<0,0,ROUND(E16+F16-C16-D16,-2)) -> 12800 | H16: =E16+F16-G16-C16-D16 -> -15.43 | I16: =_ЦО!T14+'МХП лазня'!T14+Катеринополь!T14+ВООЗ!T14+Кернел!T14+'Глобино Мк'!T14+'ВООЗ ЕМС'!T14+'ООН 36'!T14+'ООН 37'!T14+'ООН 38'!T14+ООН39!T14+'ООН 40'!T14+'ООН 43'!T14+'ООН 44'!T14+'ООН 45'!V14+ООН46!T14+ООН47!T14+ООН48!T14+ООН49!T14+ООн50!T14+ООН51!T14+Форшахта!T14+'ГАлерея 25.6'!T14+ГРП!AI14+'Парк меляси'!T14+'ООН 42'!T14 -> 116 | J16: 150 | K16: =SUMIF(ИТР!B:B,B16,ИТР!R:R) -> 0 | L16: =SUMIF(_ЦО!$B:$B,B16,_ЦО!T:T) -> 0 | M16: =SUMIF('МХП лазня'!B:B,B16,'МХП лазня'!T:T) -> 0 | N16: =SUMIF(Катеринополь!$B:$B,B16,Катеринополь!$T:$T) -> 0 | O16: =SUMIF(ВООЗ!B:B,B16,ВООЗ!T:T) -> 0 | P16: =SUMIF(Кернел!B:B,B16,Кернел!T:T) -> 0 | Q16: =SUMIF('Глобино Мк'!B:B,B16,'Глобино Мк'!T:T) -> 22 | R16: =SUMIF('ВООЗ ЕМС'!B:B,B16,'ВООЗ ЕМС'!T:T) -> 0 | S16: =SUMIF('ООН 36'!B:B,B16,'ООН 36'!T:T) -> 0 | T16: =SUMIF('ООН 37'!B:B,B16,'ООН 37'!T:T) -> 0 | U16: =SUMIF('ООН 38'!B:B,B16,'ООН 38'!T:T) -> 0 | V16: =SUMIF(ООН39!B:B,B16,ООН39!T:T) -> 0 | W16: =SUMIF('ООН 40'!B:B,B16,'ООН 40'!T:T) -> 0 | X16: =SUMIF('ООН 43'!B:B,B16,'ООН 43'!T:T) -> 0 | Y16: =SUMIF('ООН 44'!B:B,B16,'ООН 44'!T:T) -> 0 | Z16: =SUMIF('ООН 45'!B:B,B16,'ООН 45'!V:V) -> 0 | AA16: =SUMIF(ООН46!B:B,B16,ООН46!T:T) -> 11 | AB16: =SUMIF(ООН47!B:B,B16,ООН47!T:T) -> 0 | AC16: =SUMIF(ООН48!B:B,B16,ООН48!T:T) -> 0 | AD16: =SUMIF(ООН49!B:B,B16,ООН49!T:T) -> 0 | AE16: =SUMIF(ООн50!B:B,B16,ООн50!T:T) -> 0 | AF16: =SUMIF(ООН51!B:B,B16,ООН51!T:T) -> 0 | AG16: =SUMIF(Форшахта!B:B,B16,Форшахта!T:T) -> 0 | AH16: =SUMIF('ГАлерея 25.6'!B:B,B16,'ГАлерея 25.6'!T:T) -> 0 | AI16: =SUMIF(ГРП!B:B,B16,ГРП!AI:AI) -> 22 | AJ16: =SUMIF('Парк меляси'!B:B,B16,'Парк меляси'!T:T) -> 61 | AK16: =SUMIF('ООН 42'!B:B,B16,'ООН 42'!T:T) -> 0 | AL16: =SUM(K16:AK16)-I16 -> 0 | AM16: =IFERROR($G16/$I16*K16,0) -> 0 | AN16: =IFERROR($G16/$I16*L16,0) -> 0 | AO16: =IFERROR($G16/$I16*M16,0) -> 0 | AP16: =IFERROR($G16/$I16*N16,0) -> 0 | AQ16: =IFERROR($G16/$I16*O16,0) -> 0 | AR16: =IFERROR($G16/$I16*P16,0) -> 0 | AS16: =IFERROR($G16/$I16*Q16,0) -> 2427.5862 | AT16: =IFERROR($G16/$I16*R16,0) -> 0 | ... BM16: =IFERROR($G16/$I16*AK16,0) -> 0 | BN16: =SUM(AM16:BM16) -> 12800 | BO16: =BN16-G16 -> 0
A17: 14 | B17: Сівов Євген Миколайович | D17: 3927 | E17: =I17*J17 -> 27300 | F17: 37.77 | G17: =IF(ROUND(E17+F17-C17-D17,-2)<0,0,ROUND(E17+F17-C17-D17,-2)) -> 23400 | H17: =E17+F17-G17-C17-D17 -> 10.77 | I17: =_ЦО!T15+'МХП лазня'!T15+Катеринополь!T15+ВООЗ!T15+Кернел!T15+'Глобино Мк'!T15+'ВООЗ ЕМС'!T15+'ООН 36'!T15+'ООН 37'!T15+'ООН 38'!T15+ООН39!T15+'ООН 40'!T15+'ООН 43'!T15+'ООН 44'!T15+'ООН 45'!V15+ООН46!T15+ООН47!T15+ООН48!T15+ООН49!T15+ООн50!T15+ООН51!T15+Форшахта!T15+'ГАлерея 25.6'!T15+ГРП!AI15+'Парк меляси'!T15+'ООН 42'!T15 -> 182 | J17: 150 | K17: =SUMIF(ИТР!B:B,B17,ИТР!R:R) -> 0 | L17: =SUMIF(_ЦО!$B:$B,B17,_ЦО!T:T) -> 0 | M17: =SUMIF('МХП лазня'!B:B,B17,'МХП лазня'!T:T) -> 0 | N17: =SUMIF(Катеринополь!$B:$B,B17,Катеринополь!$T:$T) -> 0 | O17: =SUMIF(ВООЗ!B:B,B17,ВООЗ!T:T) -> 0 | P17: =SUMIF(Кернел!B:B,B17,Кернел!T:T) -> 0 | Q17: =SUMIF('Глобино Мк'!B:B,B17,'Глобино Мк'!T:T) -> 55 | R17: =SUMIF('ВООЗ ЕМС'!B:B,B17,'ВООЗ ЕМС'!T:T) -> 0 | S17: =SUMIF('ООН 36'!B:B,B17,'ООН 36'!T:T) -> 0 | T17: =SUMIF('ООН 37'!B:B,B17,'ООН 37'!T:T) -> 0 | U17: =SUMIF('ООН 38'!B:B,B17,'ООН 38'!T:T) -> 0 | V17: =SUMIF(ООН39!B:B,B17,ООН39!T:T) -> 0 | W17: =SUMIF('ООН 40'!B:B,B17,'ООН 40'!T:T) -> 0 | X17: =SUMIF('ООН 43'!B:B,B17,'ООН 43'!T:T) -> 0 | Y17: =SUMIF('ООН 44'!B:B,B17,'ООН 44'!T:T) -> 0 | Z17: =SUMIF('ООН 45'!B:B,B17,'ООН 45'!V:V) -> 0 | AA17: =SUMIF(ООН46!B:B,B17,ООН46!T:T) -> 0 | AB17: =SUMIF(ООН47!B:B,B17,ООН47!T:T) -> 0 | AC17: =SUMIF(ООН48!B:B,B17,ООН48!T:T) -> 0 | AD17: =SUMIF(ООН49!B:B,B17,ООН49!T:T) -> 0 | AE17: =SUMIF(ООн50!B:B,B17,ООн50!T:T) -> 0 | AF17: =SUMIF(ООН51!B:B,B17,ООН51!T:T) -> 0 | AG17: =SUMIF(Форшахта!B:B,B17,Форшахта!T:T) -> 11 | AH17: =SUMIF('ГАлерея 25.6'!B:B,B17,'ГАлерея 25.6'!T:T) -> 94 | AI17: =SUMIF(ГРП!B:B,B17,ГРП!AI:AI) -> 0 | AJ17: =SUMIF('Парк меляси'!B:B,B17,'Парк меляси'!T:T) -> 22 | AK17: =SUMIF('ООН 42'!B:B,B17,'ООН 42'!T:T) -> 0 | AL17: =SUM(K17:AK17)-I17 -> 0 | AM17: =IFERROR($G17/$I17*K17,0) -> 0 | AN17: =IFERROR($G17/$I17*L17,0) -> 0 | AO17: =IFERROR($G17/$I17*M17,0) -> 0 | AP17: =IFERROR($G17/$I17*N17,0) -> 0 | AQ17: =IFERROR($G17/$I17*O17,0) -> 0 | AR17: =IFERROR($G17/$I17*P17,0) -> 0 | AS17: =IFERROR($G17/$I17*Q17,0) -> 7071.4286 | AT17: =IFERROR($G17/$I17*R17,0) -> 0 | ... BM17: =IFERROR($G17/$I17*AK17,0) -> 0 | BN17: =SUM(AM17:BM17) -> 23400 | BO17: =BN17-G17 -> 0
A18: 15 | B18: Кіфор Юрій Михайлович | D18: 3927 | E18: =I18*J18 -> 19050 | F18: -15.5 | G18: =IF(ROUND(E18+F18-C18-D18,-2)<0,0,ROUND(E18+F18-C18-D18,-2)) -> 15100 | H18: =E18+F18-G18-C18-D18 -> 7.5 | I18: =_ЦО!T16+'МХП лазня'!T16+Катеринополь!T16+ВООЗ!T16+Кернел!T16+'Глобино Мк'!T16+'ВООЗ ЕМС'!T16+'ООН 36'!T16+'ООН 37'!T16+'ООН 38'!T16+ООН39!T16+'ООН 40'!T16+'ООН 43'!T16+'ООН 44'!T16+'ООН 45'!V16+ООН46!T16+ООН47!T16+ООН48!T16+ООН49!T16+ООн50!T16+ООН51!T16+Форшахта!T16+'ГАлерея 25.6'!T16+ГРП!AI16+'Парк меляси'!T16+'ООН 42'!T16 -> 127 | J18: 150 | K18: =SUMIF(ИТР!B:B,B18,ИТР!R:R) -> 0 | L18: =SUMIF(_ЦО!$B:$B,B18,_ЦО!T:T) -> 0 | M18: =SUMIF('МХП лазня'!B:B,B18,'МХП лазня'!T:T) -> 22 | N18: =SUMIF(Катеринополь!$B:$B,B18,Катеринополь!$T:$T) -> 0 | O18: =SUMIF(ВООЗ!B:B,B18,ВООЗ!T:T) -> 0 | P18: =SUMIF(Кернел!B:B,B18,Кернел!T:T) -> 0 | Q18: =SUMIF('Глобино Мк'!B:B,B18,'Глобино Мк'!T:T) -> 0 | R18: =SUMIF('ВООЗ ЕМС'!B:B,B18,'ВООЗ ЕМС'!T:T) -> 0 | S18: =SUMIF('ООН 36'!B:B,B18,'ООН 36'!T:T) -> 0 | T18: =SUMIF('ООН 37'!B:B,B18,'ООН 37'!T:T) -> 0 | U18: =SUMIF('ООН 38'!B:B,B18,'ООН 38'!T:T) -> 0 | V18: =SUMIF(ООН39!B:B,B18,ООН39!T:T) -> 0 | W18: =SUMIF('ООН 40'!B:B,B18,'ООН 40'!T:T) -> 0 | X18: =SUMIF('ООН 43'!B:B,B18,'ООН 43'!T:T) -> 0 | Y18: =SUMIF('ООН 44'!B:B,B18,'ООН 44'!T:T) -> 22 | Z18: =SUMIF('ООН 45'!B:B,B18,'ООН 45'!V:V) -> 0 | AA18: =SUMIF(ООН46!B:B,B18,ООН46!T:T) -> 44 | AB18: =SUMIF(ООН47!B:B,B18,ООН47!T:T) -> 22 | AC18: =SUMIF(ООН48!B:B,B18,ООН48!T:T) -> 17 | AD18: =SUMIF(ООН49!B:B,B18,ООН49!T:T) -> 0 | AE18: =SUMIF(ООн50!B:B,B18,ООн50!T:T) -> 0 | AF18: =SUMIF(ООН51!B:B,B18,ООН51!T:T) -> 0 | AG18: =SUMIF(Форшахта!B:B,B18,Форшахта!T:T) -> 0 | AH18: =SUMIF('ГАлерея 25.6'!B:B,B18,'ГАлерея 25.6'!T:T) -> 0 | AI18: =SUMIF(ГРП!B:B,B18,ГРП!AI:AI) -> 0 | AJ18: =SUMIF('Парк меляси'!B:B,B18,'Парк меляси'!T:T) -> 0 | AK18: =SUMIF('ООН 42'!B:B,B18,'ООН 42'!T:T) -> 0 | AL18: =SUM(K18:AK18)-I18 -> 0 | AM18: =IFERROR($G18/$I18*K18,0) -> 0 | AN18: =IFERROR($G18/$I18*L18,0) -> 0 | AO18: =IFERROR($G18/$I18*M18,0) -> 2615.748 | AP18: =IFERROR($G18/$I18*N18,0) -> 0 | AQ18: =IFERROR($G18/$I18*O18,0) -> 0 | AR18: =IFERROR($G18/$I18*P18,0) -> 0 | AS18: =IFERROR($G18/$I18*Q18,0) -> 0 | AT18: =IFERROR($G18/$I18*R18,0) -> 0 | ... BM18: =IFERROR($G18/$I18*AK18,0) -> 0 | BN18: =SUM(AM18:BM18) -> 15100 | BO18: =BN18-G18 -> 0
A19: 16 | B19: Петренко Микола Григорович | D19: 9625 | E19: =I19*J19 -> 14700 | F19: -41.49 | G19: =IF(ROUND(E19+F19-C19-D19,-2)<0,0,ROUND(E19+F19-C19-D19,-2)) -> 5000 | H19: =E19+F19-G19-C19-D19 -> 33.51 | I19: =_ЦО!T17+'МХП лазня'!T17+Катеринополь!T17+ВООЗ!T17+Кернел!T17+'Глобино Мк'!T17+'ВООЗ ЕМС'!T17+'ООН 36'!T17+'ООН 37'!T17+'ООН 38'!T17+ООН39!T17+'ООН 40'!T17+'ООН 43'!T17+'ООН 44'!T17+'ООН 45'!V17+ООН46!T17+ООН47!T17+ООН48!T17+ООН49!T17+ООн50!T17+ООН51!T17+Форшахта!T17+'ГАлерея 25.6'!T17+ГРП!AI17+'Парк меляси'!T17+'ООН 42'!T17 -> 98 | J19: 150 | K19: =SUMIF(ИТР!B:B,B19,ИТР!R:R) -> 0 | L19: =SUMIF(_ЦО!$B:$B,B19,_ЦО!T:T) -> 0 | M19: =SUMIF('МХП лазня'!B:B,B19,'МХП лазня'!T:T) -> 20 | N19: =SUMIF(Катеринополь!$B:$B,B19,Катеринополь!$T:$T) -> 0 | O19: =SUMIF(ВООЗ!B:B,B19,ВООЗ!T:T) -> 0 | P19: =SUMIF(Кернел!B:B,B19,Кернел!T:T) -> 0 | Q19: =SUMIF('Глобино Мк'!B:B,B19,'Глобино Мк'!T:T) -> 0 | R19: =SUMIF('ВООЗ ЕМС'!B:B,B19,'ВООЗ ЕМС'!T:T) -> 0 | S19: =SUMIF('ООН 36'!B:B,B19,'ООН 36'!T:T) -> 0 | T19: =SUMIF('ООН 37'!B:B,B19,'ООН 37'!T:T) -> 0 | U19: =SUMIF('ООН 38'!B:B,B19,'ООН 38'!T:T) -> 0 | V19: =SUMIF(ООН39!B:B,B19,ООН39!T:T) -> 0 | W19: =SUMIF('ООН 40'!B:B,B19,'ООН 40'!T:T) -> 0 | X19: =SUMIF('ООН 43'!B:B,B19,'ООН 43'!T:T) -> 0 | Y19: =SUMIF('ООН 44'!B:B,B19,'ООН 44'!T:T) -> 18 | Z19: =SUMIF('ООН 45'!B:B,B19,'ООН 45'!V:V) -> 18 | AA19: =SUMIF(ООН46!B:B,B19,ООН46!T:T) -> 18 | AB19: =SUMIF(ООН47!B:B,B19,ООН47!T:T) -> 9 | AC19: =SUMIF(ООН48!B:B,B19,ООН48!T:T) -> 15 | AD19: =SUMIF(ООН49!B:B,B19,ООН49!T:T) -> 0 | AE19: =SUMIF(ООн50!B:B,B19,ООн50!T:T) -> 0 | AF19: =SUMIF(ООН51!B:B,B19,ООН51!T:T) -> 0 | AG19: =SUMIF(Форшахта!B:B,B19,Форшахта!T:T) -> 0 | AH19: =SUMIF('ГАлерея 25.6'!B:B,B19,'ГАлерея 25.6'!T:T) -> 0 | AI19: =SUMIF(ГРП!B:B,B19,ГРП!AI:AI) -> 0 | AJ19: =SUMIF('Парк меляси'!B:B,B19,'Парк меляси'!T:T) -> 0 | AK19: =SUMIF('ООН 42'!B:B,B19,'ООН 42'!T:T) -> 0 | AL19: =SUM(K19:AK19)-I19 -> 0 | AM19: =IFERROR($G19/$I19*K19,0) -> 0 | AN19: =IFERROR($G19/$I19*L19,0) -> 0 | AO19: =IFERROR($G19/$I19*M19,0) -> 1020.4082 | AP19: =IFERROR($G19/$I19*N19,0) -> 0 | AQ19: =IFERROR($G19/$I19*O19,0) -> 0 | AR19: =IFERROR($G19/$I19*P19,0) -> 0 | AS19: =IFERROR($G19/$I19*Q19,0) -> 0 | AT19: =IFERROR($G19/$I19*R19,0) -> 0 | ... BM19: =IFERROR($G19/$I19*AK19,0) -> 0 | BN19: =SUM(AM19:BM19) -> 5000 | BO19: =BN19-G19 -> 0
A20: 17 | B20: Рубленко Микола Іванович | D20: 3927 | E20: =I20*J20 -> 17850 | F20: 34.5 | G20: =IF(ROUND(E20+F20-C20-D20,-2)<0,0,ROUND(E20+F20-C20-D20,-2)) -> 14000 | H20: =E20+F20-G20-C20-D20 -> -42.5 | I20: =_ЦО!T18+'МХП лазня'!T18+Катеринополь!T18+ВООЗ!T18+Кернел!T18+'Глобино Мк'!T18+'ВООЗ ЕМС'!T18+'ООН 36'!T18+'ООН 37'!T18+'ООН 38'!T18+ООН39!T18+'ООН 40'!T18+'ООН 43'!T18+'ООН 44'!T18+'ООН 45'!V18+ООН46!T18+ООН47!T18+ООН48!T18+ООН49!T18+ООн50!T18+ООН51!T18+Форшахта!T18+'ГАлерея 25.6'!T18+ГРП!AI18+'Парк меляси'!T18+'ООН 42'!T18 -> 119 | J20: 150 | K20: =SUMIF(ИТР!B:B,B20,ИТР!R:R) -> 0 | L20: =SUMIF(_ЦО!$B:$B,B20,_ЦО!T:T) -> 0 | M20: =SUMIF('МХП лазня'!B:B,B20,'МХП лазня'!T:T) -> 77 | N20: =SUMIF(Катеринополь!$B:$B,B20,Катеринополь!$T:$T) -> 0 | O20: =SUMIF(ВООЗ!B:B,B20,ВООЗ!T:T) -> 0 | P20: =SUMIF(Кернел!B:B,B20,Кернел!T:T) -> 0 | Q20: =SUMIF('Глобино Мк'!B:B,B20,'Глобино Мк'!T:T) -> 0 | R20: =SUMIF('ВООЗ ЕМС'!B:B,B20,'ВООЗ ЕМС'!T:T) -> 0 | S20: =SUMIF('ООН 36'!B:B,B20,'ООН 36'!T:T) -> 0 | T20: =SUMIF('ООН 37'!B:B,B20,'ООН 37'!T:T) -> 0 | U20: =SUMIF('ООН 38'!B:B,B20,'ООН 38'!T:T) -> 0 | V20: =SUMIF(ООН39!B:B,B20,ООН39!T:T) -> 0 | W20: =SUMIF('ООН 40'!B:B,B20,'ООН 40'!T:T) -> 0 | X20: =SUMIF('ООН 43'!B:B,B20,'ООН 43'!T:T) -> 0 | Y20: =SUMIF('ООН 44'!B:B,B20,'ООН 44'!T:T) -> 20 | Z20: =SUMIF('ООН 45'!B:B,B20,'ООН 45'!V:V) -> 22 | AA20: =SUMIF(ООН46!B:B,B20,ООН46!T:T) -> 0 | AB20: =SUMIF(ООН47!B:B,B20,ООН47!T:T) -> 0 | AC20: =SUMIF(ООН48!B:B,B20,ООН48!T:T) -> 0 | AD20: =SUMIF(ООН49!B:B,B20,ООН49!T:T) -> 0 | AE20: =SUMIF(ООн50!B:B,B20,ООн50!T:T) -> 0 | AF20: =SUMIF(ООН51!B:B,B20,ООН51!T:T) -> 0 | AG20: =SUMIF(Форшахта!B:B,B20,Форшахта!T:T) -> 0 | AH20: =SUMIF('ГАлерея 25.6'!B:B,B20,'ГАлерея 25.6'!T:T) -> 0 | AI20: =SUMIF(ГРП!B:B,B20,ГРП!AI:AI) -> 0 | AJ20: =SUMIF('Парк меляси'!B:B,B20,'Парк меляси'!T:T) -> 0 | AK20: =SUMIF('ООН 42'!B:B,B20,'ООН 42'!T:T) -> 0 | AL20: =SUM(K20:AK20)-I20 -> 0 | AM20: =IFERROR($G20/$I20*K20,0) -> 0 | AN20: =IFERROR($G20/$I20*L20,0) -> 0 | AO20: =IFERROR($G20/$I20*M20,0) -> 9058.8235 | AP20: =IFERROR($G20/$I20*N20,0) -> 0 | AQ20: =IFERROR($G20/$I20*O20,0) -> 0 | AR20: =IFERROR($G20/$I20*P20,0) -> 0 | AS20: =IFERROR($G20/$I20*Q20,0) -> 0 | AT20: =IFERROR($G20/$I20*R20,0) -> 0 | ... BM20: =IFERROR($G20/$I20*AK20,0) -> 0 | BN20: =SUM(AM20:BM20) -> 14000 | BO20: =BN20-G20 -> 0
