Workbook

Sheet СВОД
F1: ГРН без НДС
B2: Наименование склада | C2: Списание, грн. без НДС | D2: Списание, грн. с НДС | F2: Октябрь 24 | G2: Ноябрь 24 | H2: Декабрь 24
B3: Глобине-2 | C3: ='Глобине-2'!J362 -> 21742.48 | D3: =C3*1.2 -> 26090.976 | G3: ='Глобине-2'!M273 -> 1000 | H3: ='Глобине-2'!M359 -> 20742.48 | I3: =C3-F3-G3-H3 -> 0
B4: Котельна (Глобине) | C4: ='Котельна (Глобине)'!J297 -> 2562806.8 | D4: =C4*1.2 -> 3075368.1 | F4: ='Котельна (Глобине)'!M26 -> 529703.6 | G4: ='Котельна (Глобине)'!M216 -> 1376069.7 | H4: ='Котельна (Глобине)'!M292 -> 657033.43 | I4: =C4-F4-G4-H4 -> 0
B5: Насосна Градирня (Глобине) | C5: ='Насосна Градирня (Глобине)'!J51 -> 982966.73 | D5: =C5*1.2 -> 1179560.1 | F5: ='Насосна Градирня (Глобине)'!M15 -> 225602.62 | G5: ='Насосна Градирня (Глобине)'!M27 -> 202007.62 | H5: ='Насосна Градирня (Глобине)'!M47 -> 555356.49 | I5: =C5-F5-G5-H5 -> 0
B6: Резервуар для зберігання розчинника(Глобине) | C6: ='Р-р для зб. розч.(Глобине)'!J43 -> 670974.92 | D6: =C6*1.2 -> 805169.9 | G6: ='Р-р для зб. розч.(Глобине)'!M40 -> 670974.92 | I6: =C6-F6-G6-H6 -> 0
B7: СПК (Глобине) | C7: ='СПК (Глобине)'!J146 -> 1364638.2 | D7: =C7*1.2 -> 1637565.8 | G7: ='СПК (Глобине)'!M47 -> 245996.95 | H7: ='СПК (Глобине)'!M143 -> 1118641.2 | I7: =C7-F7-G7-H7 -> 0
B8: Цех екстракції (Глобине) | C8: ='Цех екстракції (Глобине)'!J618 -> 12423243 | D8: =C8*1.2 -> 14907892 | F8: ='Цех екстракції (Глобине)'!M26 -> 1652430.8 | G8: ='Цех екстракції (Глобине)'!M254 -> 2104295.9 | H8: ='Цех екстракції (Глобине)'!M615 -> 8666516.4 | I8: =C8-F8-G8-H8 -> 0
B9: Цех_Глобино | C9: =Цех_Глобино!J179 -> 4480857.2 | D9: =C9*1.2 -> 5377028.7 | H9: =Цех_Глобино!M176 -> 4480857.2 | I9: =C9-F9-G9-H9 -> 0
B10: ВСЕГО | C10: =SUM(C3:C9) -> 22507229 | D10: =SUM(D3:D9) -> 27008675 | F10: =SUM(F3:F9) -> 2407737 | G10: =SUM(G3:G9) -> 4600345.1 | H10: =SUM(H3:H9) -> 15499147
F12: =F10*1.2 -> 2889284.4 | G12: =G10*1.2 -> 5520414.1 | H12: =H10*1.2 -> 18598977 | I12: * ГРН С НДС
F14: 2901051.2 | G14: 5520874.1 | H14: 18599292 | I14: * в отчете PL
F15: =F14-F12 -> 11766.84 | G15: =G14-G12 -> 459.998 | H15: =H14-H12 -> 315.004 | I15: НП

Sheet Глобине-2
A1: ТОВ "ІНДАСТРІАЛБУД"
A2: Картка рахунку 205 за ... - 2024 р.
A4: Виведені дані: | B4: БО (дані бухгалтерського обліку)
A6: Відбір: | B6: Склади Дорівнює "Глобине-2" и Склади.Найменування містить "гло"
A8: Період | B8: Документ | C8: Аналітика Дт | D8: Аналітика Кт | E8: Дебет | H8: Кредит | K8: Поточне сальдо
E9: Рахунок | H9: Рахунок
A10: 20.09.2024 | B10: Надходження товарів і послуг ІБ00-004375 від 20.09.2024 18:19:18 Оприходованы ТМЦ | C10: Обл. НДС Дріт 1,2 мм Н-О-Ч Надходження товарів і послуг ІБ00-004375 від 20.09.2024 18:19:18 Глобине-2 | D10: МЕТІНВЕСТ-СМЦ ТОВ №1778403/01/2023-С от 11.01.2023 РАХУНКИ_Глобино-2 Рахунок на оплату постачальника ІБ00-003425 від 19.09.2024 00:00:00 | E10: 205 | F10: 13720 | H10: 631 | K10: Д | L10: 13720
A11: 20.09.2024 | B11: Надходження товарів і послуг ІБ00-004380 від 20.09.2024 18:19:30 Оприходованы ТМЦ | C11: Обл. НДС Провід ПВ-1нгLs 6 білий Надходження товарів і послуг ІБ00-004380 від 20.09.2024 18:19:30 Глобине-2 | D11: ЕЛЕКТРОКОМПЛЕКТ ЕК ТОВ РАХУНКИ_Глобине 2 Рахунок на оплату постачальника ІБ00-003600 від 20.09.2024 18:19:21 | E11: 205 | F11: 699.79 | H11: 631 | K11: Д | L11: 14419.79
A12: 21.09.2024 | B12: Надходження товарів і послуг ІБ00-004377 від 21.09.2024 23:45:37 Оприходованы ТМЦ | C12: Обл. НДС Арматура №14 А500С L=12000 мм Надходження товарів і послуг ІБ00-004377 від 21.09.2024 23:45:37 Глобине-2 | D12: МЕТІНВЕСТ-СМЦ ТОВ №1778403/01/2023-С от 11.01.2023 РАХУНКИ_Глобино-2 Рахунок на оплату постачальника ІБ00-003425 від 19.09.2024 00:00:00 | E12: 205 | F12: 24320 | H12: 631 | K12: Д | L12: 38739.79
A13: 21.09.2024 | B13: Надходження товарів і послуг ІБ00-004378 від 21.09.2024 23:45:38 Оприходованы ТМЦ | C13: Обл. НДС Арматура №10 А240С L=6000 мм Надходження товарів і послуг ІБ00-004378 від 21.09.2024 23:45:38 Глобине-2 | D13: МЕТІНВЕСТ-СМЦ ТОВ №1778403/01/2023-С от 11.01.2023 РАХУНКИ_Глобино-2 Рахунок на оплату постачальника ІБ00-003425 від 19.09.2024 00:00:00 | E13: 205 | F13: 48979.99 | H13: 631 | K13: Д | L13: 87719.78
A14: 21.09.2024 | B14: Надходження товарів і послуг ІБ00-004378 від 21.09.2024 23:45:38 Оприходованы ТМЦ | C14: Обл. НДС Арматура №12 А240С L=6000 мм Надходження товарів і послуг ІБ00-004378 від 21.09.2024 23:45:38 Глобине-2 | D14: МЕТІНВЕСТ-СМЦ ТОВ №1778403/01/2023-С от 11.01.2023 РАХУНКИ_Глобино-2 Рахунок на оплату постачальника ІБ00-003425 від 19.09.2024 00:00:00 | E14: 205 | F14: 124556.65 | H14: 631 | K14: Д | L14: 212276.43
A15: 21.09.2024 | B15: Надходження товарів і послуг ІБ00-004378 від 21.09.2024 23:45:38 Оприходованы ТМЦ | C15: Обл. НДС Арматура №12 А500С L=12000 мм Надходження товарів і послуг ІБ00-004378 від 21.09.2024 23:45:38 Глобине-2 | D15: МЕТІНВЕСТ-СМЦ ТОВ №1778403/01/2023-С от 11.01.2023 РАХУНКИ_Глобино-2 Рахунок на оплату постачальника ІБ00-003425 від 19.09.2024 00:00:00 | E15: 205 | F15: 208746.64 | H15: 631 | K15: Д | L15: 421023.07
A16: 21.09.2024 | B16: Надходження товарів і послуг ІБ00-004378 від 21.09.2024 23:45:38 Оприходованы ТМЦ | C16: Обл. НДС Арматура №16 А500С L=12000 мм Надходження товарів і послуг ІБ00-004378 від 21.09.2024 23:45:38 Глобине-2 | D16: МЕТІНВЕСТ-СМЦ ТОВ №1778403/01/2023-С от 11.01.2023 РАХУНКИ_Глобино-2 Рахунок на оплату постачальника ІБ00-003425 від 19.09.2024 00:00:00 | E16: 205 | F16: 118306.65 | H16: 631 | K16: Д | L16: 539329.72
A17: 24.09.2024 | B17: Надходження товарів і послуг ІБ00-004740 від 24.09.2024 23:00:02 Оприходованы ТМЦ | C17: Обл. НДС Шафа тимчас ел/забезпеч ЯРП ІР54 Надходження товарів і послуг ІБ00-004740 від 24.09.2024 23:00:02 Глобине-2 | D17: ТЕХЕЛЕКТРОМОНТАЖ ТОВ Договір 29/04-1 від 29.04.2024_Глобине 2 Рахунок на оплату постачальника ІБ00-003717 від 06.09.2024 17:46:24 | E17: 205 | F17: 10519.1 | H17: 631 | K17: Д | L17: 549848.82
A18: 25.09.2024 | B18: Надходження товарів і послуг ІБ00-004376 від 25.09.2024 18:38:35 Оприходованы ТМЦ | C18: Обл. НДС Арматура №12 А500С L=12000 мм Надходження товарів і послуг ІБ00-004376 від 25.09.2024 18:38:35 Глобине-2 | D18: МЕТІНВЕСТ-СМЦ ТОВ №1778403/01/2023-С от 11.01.2023 РАХУНКИ_Глобино-2 Рахунок на оплату постачальника ІБ00-003425 від 19.09.2024 00:00:00 | E18: 205 | F18: 511606.6 | H18: 631 | K18: Д | L18: 1061455.4
A19: 25.09.2024 | B19: Надходження товарів і послуг ІБ00-004397 від 25.09.2024 18:38:36 Оприходованы ТМЦ | C19: Обл. НДС Арматура №12 А500С L=12000 мм Надходження товарів і послуг ІБ00-004397 від 25.09.2024 18:38:36 Глобине-2 | D19: МЕТІНВЕСТ-СМЦ ТОВ №1778403/01/2023-С от 11.01.2023 РАХУНКИ_Глобино-2 Рахунок на оплату постачальника ІБ00-003425 від 19.09.2024 00:00:00 | E19: 205 | F19: 551506.59 | H19: 631 | K19: Д | L19: 1612962
A20: 25.09.2024 | B20: Надходження товарів і послуг ІБ00-004600 від 25.09.2024 23:00:14 Оприходованы ТМЦ | C20: Обл. НДС Брус 50х40 4м Надходження товарів і послуг ІБ00-004600 від 25.09.2024 23:00:14 Глобине-2 | D20: Мошинець Ю.П. ФОП Рахунки_Глобине-2 Рахунок на оплату постачальника ІБ00-003808 від 25.09.2024 23:00:13 | E20: 205 | F20: 14212 | H20: 631 | K20: Д | L20: 1627174
A21: 25.09.2024 | B21: Надходження товарів і послуг ІБ00-004600 від 25.09.2024 23:00:14 Оприходованы ТМЦ | C21: Обл. НДС Брус 75*50 мм 6,0 м Надходження товарів і послуг ІБ00-004600 від 25.09.2024 23:00:14 Глобине-2 | D21: Мошинець Ю.П. ФОП Рахунки_Глобине-2 Рахунок на оплату постачальника ІБ00-003808 від 25.09.2024 23:00:13 | E21: 205 | F21: 3424 | H21: 631 | K21: Д | L21: 1630598
... A26: 01.10.2024 | B26: Надходження товарів і послуг ІБ00-004643 від 01.10.2024 18:35:04 Оприходованы ТМЦ | C26: Обл. НДС Арматура №14 А500С L=12000 мм Надходження товарів і послуг ІБ00-004643 від 01.10.2024 18:35:04 Глобине-2 | D26: МЕТІНВЕСТ-СМЦ ТОВ №1778403/01/2023-С от 11.01.2023 РАХУНКИ_Глобино-2 Рахунок на оплату постачальника ІБ00-003425 від 19.09.2024 00:00:00 | E26: 205 | F26: 516039.93 | H26: 631 | K26: Д | L26: 2179395.9
A27: 01.10.2024 | B27: Переміщення товарів ІБ00-000070 від 01.10.2024 18:35:33 Перемещение ТМЦ | C27: Обл. НДС Арматура №10 А240С L=6000 мм Надходження товарів і послуг ІБ00-004378 від 21.09.2024 23:45:38 Цех екстракції (Глобине) | D27: Обл. НДС Арматура №10 А240С L=6000 мм Надходження товарів і послуг ІБ00-004378 від 21.09.2024 23:45:38 Глобине-2 | E27: 205 | H27: 205 | I27: 20566.33 | K27: Д | L27: 2158829.6
A28: 01.10.2024 | B28: Переміщення товарів ІБ00-000070 від 01.10.2024 18:35:33 Перемещение ТМЦ | C28: Обл. НДС Арматура №12 А500С L=12000 мм Надходження товарів і послуг ІБ00-004378 від 21.09.2024 23:45:38 Цех екстракції (Глобине) | D28: Обл. НДС Арматура №12 А500С L=12000 мм Надходження товарів і послуг ІБ00-004378 від 21.09.2024 23:45:38 Глобине-2 | E28: 205 | H28: 205 | I28: 77190.66 | K28: Д | L28: 2081638.9
A29: 01.10.2024 | B29: Переміщення товарів ІБ00-000071 від 01.10.2024 18:35:34 Перемещение ТМЦ | C29: Обл. НДС Арматура №10 А240С L=6000 мм Надходження товарів і послуг ІБ00-004378 від 21.09.2024 23:45:38 Резервуар для зберігання розчинника(Глобине) | D29: Обл. НДС Арматура №10 А240С L=6000 мм Надходження товарів і послуг ІБ00-004378 від 21.09.2024 23:45:38 Глобине-2 | E29: 205 | H29: 205 | I29: 3686.67 | K29: Д | L29: 2077952.3
A30: 01.10.2024 | B30: Переміщення товарів ІБ00-000071 від 01.10.2024 18:35:34 Перемещение ТМЦ | C30: Обл. НДС Арматура №12 А500С L=12000 мм Надходження товарів і послуг ІБ00-004378 від 21.09.2024 23:45:38 Резервуар для зберігання розчинника(Глобине) | D30: Обл. НДС Арматура №12 А500С L=12000 мм Надходження товарів і послуг ІБ00-004378 від 21.09.2024 23:45:38 Глобине-2 | E30: 205 | H30: 205 | I30: 43623.99 | K30: Д | L30: 2034328.3
A31: 01.10.2024 | B31: Переміщення товарів ІБ00-000071 від 01.10.2024 18:35:34 Перемещение ТМЦ | C31: Обл. НДС Арматура №14 А500С L=12000 мм Надходження товарів і послуг ІБ00-004377 від 21.09.2024 23:45:37 Резервуар для зберігання розчинника(Глобине) | D31: Обл. НДС Арматура №14 А500С L=12000 мм Надходження товарів і послуг ІБ00-004377 від 21.09.2024 23:45:37 Глобине-2 | E31: 205 | H31: 205 | I31: 24320 | K31: Д | L31: 2010008.3
A32: 01.10.2024 | B32: Переміщення товарів ІБ00-000071 від 01.10.2024 18:35:34 Перемещение ТМЦ | C32: Обл. НДС Арматура №16 А500С L=12000 мм Надходження товарів і послуг ІБ00-004378 від 21.09.2024 23:45:38 Резервуар для зберігання розчинника(Глобине) | D32: Обл. НДС Арматура №16 А500С L=12000 мм Надходження товарів і послуг ІБ00-004378 від 21.09.2024 23:45:38 Глобине-2 | E32: 205 | H32: 205 | I32: 6586.67 | K32: Д | L32: 2003421.6
A33: 01.10.2024 | B33: Переміщення товарів ІБ00-000072 від 01.10.2024 18:35:35 Перемещение ТМЦ | C33: Обл. НДС Арматура №10 А240С L=6000 мм Надходження товарів і послуг ІБ00-004378 від 21.09.2024 23:45:38 Котельна (Глобине) | D33: Обл. НДС Арматура №10 А240С L=6000 мм Надходження товарів і послуг ІБ00-004378 від 21.09.2024 23:45:38 Глобине-2 | E33: 205 | H33: 205 | I33: 24726.99 | K33: Д | L33: 1978694.6
A34: 01.10.2024 | B34: Переміщення товарів ІБ00-000072 від 01.10.2024 18:35:35 Перемещение ТМЦ | C34: Обл. НДС Арматура №12 А500С L=12000 мм Надходження товарів і послуг ІБ00-004378 від 21.09.2024 23:45:38 Котельна (Глобине) | D34: Обл. НДС Арматура №12 А500С L=12000 мм Надходження товарів і послуг ІБ00-004378 від 21.09.2024 23:45:38 Глобине-2 | E34: 205 | H34: 205 | I34: 83498.66 | K34: Д | L34: 1895196
A35: 01.10.2024 | B35: Переміщення товарів ІБ00-000073 від 01.10.2024 18:35:36 Перемещение ТМЦ | C35: Обл. НДС Арматура №16 А500С L=12000 мм Надходження товарів і послуг ІБ00-004378 від 21.09.2024 23:45:38 Насосна Градирня (Глобине) | D35: Обл. НДС Арматура №16 А500С L=12000 мм Надходження товарів і послуг ІБ00-004378 від 21.09.2024 23:45:38 Глобине-2 | E35: 205 | H35: 205 | I35: 111719.98 | K35: Д | L35: 1783476
A36: 01.10.2024 | B36: Переміщення товарів ІБ00-000076 від 01.10.2024 18:35:53 Перемещение ТМЦ | C36: Обл. НДС дошка 25*150 4,5 шт Надходження товарів і послуг ІБ00-004600 від 25.09.2024 23:00:14 Цех екстракції (Глобине) | D36: Обл. НДС дошка 25*150 4,5 шт Надходження товарів і послуг ІБ00-004600 від 25.09.2024 23:00:14 Глобине-2 | E36: 205 | H36: 205 | I36: 19668 | K36: Д | L36: 1763808
A37: 01.10.2024 | B37: Переміщення товарів ІБ00-000077 від 01.10.2024 18:35:54 Перемещение ТМЦ | C37: Обл. НДС дошка 25*120 4,5 м шт Надходження товарів і послуг ІБ00-004600 від 25.09.2024 23:00:14 Котельна (Глобине) | D37: Обл. НДС дошка 25*120 4,5 м шт Надходження товарів і послуг ІБ00-004600 від 25.09.2024 23:00:14 Глобине-2 | E37: 205 | H37: 205 | I37: 8260 | K37: Д | L37: 1755548
A38: 01.10.2024 | B38: Переміщення товарів ІБ00-000078 від 01.10.2024 18:35:55 Перемещение ТМЦ | C38: Обл. НДС Арматура №12 А500С L=12000 мм Надходження товарів і послуг ІБ00-004378 від 21.09.2024 23:45:38 Цех екстракції (Глобине) | D38: Обл. НДС Арматура №12 А500С L=12000 мм Надходження товарів і послуг ІБ00-004378 від 21.09.2024 23:45:38 Глобине-2 | E38: 205 | H38: 205 | I38: 4433.33 | K38: Д | L38: 1751114.7
... A44: 02.10.2024 | B44: Переміщення товарів ІБ00-000086 від 02.10.2024 00:00:00 Перемещение ТМЦ | C44: Обл. НДС Арматура №14 А500С L=12000 мм Надходження товарів і послуг ІБ00-004643 від 01.10.2024 18:35:04 Цех екстракції (Глобине) | D44: Обл. НДС Арматура №14 А500С L=12000 мм Надходження товарів і послуг ІБ00-004643 від 01.10.2024 18:35:04 Глобине-2 | E44: 205 | H44: 205 | I44: 399253.28 | K44: Д | L44: 64682.22
A45: 02.10.2024 | B45: Надходження товарів і послуг ІБ00-004644 від 02.10.2024 17:19:53 Оприходованы ТМЦ | C45: Обл. НДС Арматура №14 А500С L=12000 мм Надходження товарів і послуг ІБ00-004644 від 02.10.2024 17:19:53 Глобине-2 | D45: МЕТІНВЕСТ-СМЦ ТОВ №1778403/01/2023-С от 11.01.2023 РАХУНКИ_Глобино-2 Рахунок на оплату постачальника ІБ00-003425 від 19.09.2024 00:00:00 | E45: 205 | F45: 564426.59 | H45: 631 | K45: Д | L45: 629108.81
A46: 02.10.2024 | B46: Надходження товарів і послуг ІБ00-004646 від 02.10.2024 17:19:54 Оприходованы ТМЦ | C46: Обл. НДС Арматура №12 А240С L=6000 мм Надходження товарів і послуг ІБ00-004646 від 02.10.2024 17:19:54 Глобине-2 | D46: МЕТІНВЕСТ-СМЦ ТОВ №1778403/01/2023-С от 11.01.2023 РАХУНКИ_Глобино-2 Рахунок на оплату постачальника ІБ00-003425 від 19.09.2024 00:00:00 | E46: 205 | F46: 75313.32 | H46: 631 | K46: Д | L46: 704422.13
A47: 02.10.2024 | B47: Надходження товарів і послуг ІБ00-004646 від 02.10.2024 17:19:54 Оприходованы ТМЦ | C47: Обл. НДС Арматура №12 А500С L=12000 мм Надходження товарів і послуг ІБ00-004646 від 02.10.2024 17:19:54 Глобине-2 | D47: МЕТІНВЕСТ-СМЦ ТОВ №1778403/01/2023-С от 11.01.2023 РАХУНКИ_Глобино-2 Рахунок на оплату постачальника ІБ00-003425 від 19.09.2024 00:00:00 | E47: 205 | F47: 270559.96 | H47: 631 | K47: Д | L47: 974982.09
A48: 02.10.2024 | B48: Надходження товарів і послуг ІБ00-004646 від 02.10.2024 17:19:54 Оприходованы ТМЦ | C48: Обл. НДС Арматура №14 А500С L=12000 мм Надходження товарів і послуг ІБ00-004646 від 02.10.2024 17:19:54 Глобине-2 | D48: МЕТІНВЕСТ-СМЦ ТОВ №1778403/01/2023-С от 11.01.2023 РАХУНКИ_Глобино-2 Рахунок на оплату постачальника ІБ00-003425 від 19.09.2024 00:00:00 | E48: 205 | F48: 186199.98 | H48: 631 | K48: Д | L48: 1161182.1
A49: 02.10.2024 | B49: Надходження товарів і послуг ІБ00-004646 від 02.10.2024 17:19:54 Оприходованы ТМЦ | C49: Обл. НДС Арматура №16 А500С L=12000 мм Надходження товарів і послуг ІБ00-004646 від 02.10.2024 17:19:54 Глобине-2 | D49: МЕТІНВЕСТ-СМЦ ТОВ №1778403/01/2023-С от 11.01.2023 РАХУНКИ_Глобино-2 Рахунок на оплату постачальника ІБ00-003425 від 19.09.2024 00:00:00 | E49: 205 | F49: 22546.66 | H49: 631 | K49: Д | L49: 1183728.7
A50: 02.10.2024 | B50: Переміщення товарів ІБ00-000085 від 02.10.2024 17:20:12 Перемещение ТМЦ | C50: Обл. НДС Арматура №14 А500С L=12000 мм Надходження товарів і послуг ІБ00-004643 від 01.10.2024 18:35:04 Резервуар для зберігання розчинника(Глобине) | D50: Обл. НДС Арматура №14 А500С L=12000 мм Надходження товарів і послуг ІБ00-004643 від 01.10.2024 18:35:04 Глобине-2 | E50: 205 | H50: 205 | I50: 12844 | K50: Д | L50: 1170884.7
A51: 03.10.2024 | B51: Переміщення товарів ІБ00-000080 від 03.10.2024 17:50:17 Перемещение ТМЦ | C51: Обл. НДС Арматура №14 А500С L=12000 мм Надходження товарів і послуг ІБ00-004644 від 02.10.2024 17:19:53 Резервуар для зберігання розчинника(Глобине) | D51: Обл. НДС Арматура №14 А500С L=12000 мм Надходження товарів і послуг ІБ00-004644 від 02.10.2024 17:19:53 Глобине-2 | E51: 205 | H51: 205 | I51: 564426.59 | K51: Д | L51: 606458.14
A52: 03.10.2024 | B52: Переміщення товарів ІБ00-000081 від 03.10.2024 17:50:18 Перемещение ТМЦ | C52: Обл. НДС Арматура №16 А500С L=12000 мм Надходження товарів і послуг ІБ00-004646 від 02.10.2024 17:19:54 Резервуар для зберігання розчинника(Глобине) | D52: Обл. НДС Арматура №16 А500С L=12000 мм Надходження товарів і послуг ІБ00-004646 від 02.10.2024 17:19:54 Глобине-2 | E52: 205 | H52: 205 | I52: 22546.66 | K52: Д | L52: 583911.48
...

Sheet Котельна (Глобине)
A1: ТОВ "ІНДАСТРІАЛБУД"
A2: Картка рахунку 205 за ... - 2024 р.
A4: Виведені дані: | B4: БО (дані бухгалтерського обліку)
A6: Відбір: | B6: Склади Дорівнює "Котельна (Глобине)" и Склади.Найменування містить "гло"
A8: Період | B8: Документ | C8: Аналітика Дт | D8: Аналітика Кт | E8: Дебет | H8: Кредит | K8: Поточне сальдо
E9: Рахунок | H9: Рахунок
A10: 01.10.2024 | B10: Переміщення товарів ІБ00-000072 від 01.10.2024 18:35:35 Перемещение ТМЦ | C10: Обл. НДС Арматура №10 А240С L=6000 мм Надходження товарів і послуг ІБ00-004378 від 21.09.2024 23:45:38 Котельна (Глобине) | D10: Обл. НДС Арматура №10 А240С L=6000 мм Надходження товарів і послуг ІБ00-004378 від 21.09.2024 23:45:38 Глобине-2 | E10: 205 | F10: 24726.99 | H10: 205 | K10: Д | L10: 24726.99
A11: 01.10.2024 | B11: Переміщення товарів ІБ00-000072 від 01.10.2024 18:35:35 Перемещение ТМЦ | C11: Обл. НДС Арматура №12 А500С L=12000 мм Надходження товарів і послуг ІБ00-004378 від 21.09.2024 23:45:38 Котельна (Глобине) | D11: Обл. НДС Арматура №12 А500С L=12000 мм Надходження товарів і послуг ІБ00-004378 від 21.09.2024 23:45:38 Глобине-2 | E11: 205 | F11: 83498.66 | H11: 205 | K11: Д | L11: 108225.65
A12: 01.10.2024 | B12: Переміщення товарів ІБ00-000077 від 01.10.2024 18:35:54 Перемещение ТМЦ | C12: Обл. НДС дошка 25*120 4,5 м шт Надходження товарів і послуг ІБ00-004600 від 25.09.2024 23:00:14 Котельна (Глобине) | D12: Обл. НДС дошка 25*120 4,5 м шт Надходження товарів і послуг ІБ00-004600 від 25.09.2024 23:00:14 Глобине-2 | E12: 205 | F12: 8260 | H12: 205 | K12: Д | L12: 116485.65
A13: 03.10.2024 | B13: Переміщення товарів ІБ00-000082 від 03.10.2024 17:50:19 Перемещение ТМЦ | C13: Обл. НДС Арматура №12 А240С L=6000 мм Надходження товарів і послуг ІБ00-004646 від 02.10.2024 17:19:54 Котельна (Глобине) | D13: Обл. НДС Арматура №12 А240С L=6000 мм Надходження товарів і послуг ІБ00-004646 від 02.10.2024 17:19:54 Глобине-2 | E13: 205 | F13: 18565 | H13: 205 | K13: Д | L13: 135050.65
A14: 03.10.2024 | B14: Переміщення товарів ІБ00-000082 від 03.10.2024 17:50:19 Перемещение ТМЦ | C14: Обл. НДС Арматура №12 А500С L=12000 мм Надходження товарів і послуг ІБ00-004397 від 25.09.2024 18:38:36 Котельна (Глобине) | D14: Обл. НДС Арматура №12 А500С L=12000 мм Надходження товарів і послуг ІБ00-004397 від 25.09.2024 18:38:36 Глобине-2 | E14: 205 | F14: 4433.33 | H14: 205 | K14: Д | L14: 139483.98
A15: 03.10.2024 | B15: Переміщення товарів ІБ00-000082 від 03.10.2024 17:50:19 Перемещение ТМЦ | C15: Обл. НДС Арматура №12 А500С L=12000 мм Надходження товарів і послуг ІБ00-004646 від 02.10.2024 17:19:54 Котельна (Глобине) | D15: Обл. НДС Арматура №12 А500С L=12000 мм Надходження товарів і послуг ІБ00-004646 від 02.10.2024 17:19:54 Глобине-2 | E15: 205 | F15: 266126.63 | H15: 205 | K15: Д | L15: 405610.61
A16: 03.10.2024 | B16: Переміщення товарів ІБ00-000082 від 03.10.2024 17:50:19 Перемещение ТМЦ | C16: Обл. НДС Арматура №14 А500С L=12000 мм Надходження товарів і послуг ІБ00-004646 від 02.10.2024 17:19:54 Котельна (Глобине) | D16: Обл. НДС Арматура №14 А500С L=12000 мм Надходження товарів і послуг ІБ00-004646 від 02.10.2024 17:19:54 Глобине-2 | E16: 205 | F16: 186199.98 | H16: 205 | K16: Д | L16: 591810.59
A17: 03.10.2024 | B17: Надходження товарів і послуг ІБ00-005299 від 03.10.2024 17:50:40 Оприходованы ТМЦ | C17: Обл. НДС Бетон М-150 Надходження товарів і послуг ІБ00-005299 від 03.10.2024 17:50:40 Котельна (Глобине) | D17: Глобинський свинокомплекс НВП ТОВ Глобіне2_рахунки Рахунок на оплату постачальника ІБ00-004352 від 03.10.2024 17:50:39 | E17: 205 | F17: 4511.8 | H17: 631 | K17: Д | L17: 596322.39
A18: 04.10.2024 | B18: Переміщення товарів ІБ00-000094 від 04.10.2024 20:00:00 Перемещение ТМЦ | C18: Обл. НДС Бетон М-150 (Р-3) Надходження товарів і послуг ІБ00-005012 від 04.10.2024 18:41:13 Котельна (Глобине) | D18: Обл. НДС Бетон М-150 (Р-3) Надходження товарів і послуг ІБ00-005012 від 04.10.2024 18:41:13 Глобине-2 | E18: 205 | F18: 9525 | H18: 205 | K18: Д | L18: 605847.39
A19: 04.10.2024 | B19: Переміщення товарів ІБ00-000095 від 04.10.2024 20:00:00 Перемещение ТМЦ | C19: Обл. НДС Бетон М-150 (Р-3) Надходження товарів і послуг ІБ00-005012 від 04.10.2024 18:41:13 Котельна (Глобине) | D19: Обл. НДС Бетон М-150 (Р-3) Надходження товарів і послуг ІБ00-005012 від 04.10.2024 18:41:13 Глобине-2 | E19: 205 | F19: 5334 | H19: 205 | K19: Д | L19: 611181.39
A20: 08.10.2024 | B20: Вимога-накладна ІБ00-000535 від 08.10.2024 22:00:14 Списаны ТМЦ | C20: Обл. НДС Виробничий (Глобине-2) Глобине-2 Прямі материальні виробничі витрати крім зворотніх відходів | D20: Обл. НДС Арматура №10 А240С L=6000 мм Надходження товарів і послуг ІБ00-004378 від 21.09.2024 23:45:38 Котельна (Глобине) | E20: 231 | H20: 205 | I20: 24726.99 | K20: Д | L20: 586454.4
A21: 08.10.2024 | B21: Вимога-накладна ІБ00-000535 від 08.10.2024 22:00:14 Списаны ТМЦ | C21: Обл. НДС Виробничий (Глобине-2) Глобине-2 Прямі материальні виробничі витрати крім зворотніх відходів | D21: Обл. НДС Арматура №12 А240С L=6000 мм Надходження товарів і послуг ІБ00-004646 від 02.10.2024 17:19:54 Котельна (Глобине) | E21: 231 | H21: 205 | I21: 15536.67 | K21: Д | L21: 570917.73
A22: 08.10.2024 | B22: Вимога-накладна ІБ00-000535 від 08.10.2024 22:00:14 Списаны ТМЦ | C22: Обл. НДС Виробничий (Глобине-2) Глобине-2 Прямі материальні виробничі витрати крім зворотніх відходів | D22: Обл. НДС Арматура №12 А500С L=12000 мм Надходження товарів і послуг ІБ00-004378 від 21.09.2024 23:45:38 Котельна (Глобине) | E22: 231 | H22: 205 | I22: 83498.66 | K22: Д | L22: 487419.07
A23: 08.10.2024 | B23: Вимога-накладна ІБ00-000535 від 08.10.2024 22:00:14 Списаны ТМЦ | C23: Обл. НДС Виробничий (Глобине-2) Глобине-2 Прямі материальні виробничі витрати крім зворотніх відходів | D23: Обл. НДС Арматура №12 А500С L=12000 мм Надходження товарів і послуг ІБ00-004397 від 25.09.2024 18:38:36 Котельна (Глобине) | E23: 231 | H23: 205 | I23: 4433.33 | K23: Д | L23: 482985.74
A24: 08.10.2024 | B24: Вимога-накладна ІБ00-000535 від 08.10.2024 22:00:14 Списаны ТМЦ | C24: Обл. НДС Виробничий (Глобине-2) Глобине-2 Прямі материальні виробничі витрати крім зворотніх відходів | D24: Обл. НДС Арматура №12 А500С L=12000 мм Надходження товарів і послуг ІБ00-004646 від 02.10.2024 17:19:54 Котельна (Глобине) | E24: 231 | H24: 205 | I24: 178194.64 | K24: Д | L24: 304791.1
A25: 08.10.2024 | B25: Вимога-накладна ІБ00-000535 від 08.10.2024 22:00:14 Списаны ТМЦ | C25: Обл. НДС Виробничий (Глобине-2) Глобине-2 Прямі материальні виробничі витрати крім зворотніх відходів | D25: Обл. НДС Арматура №12 А500С L=12000 мм Надходження товарів і послуг ІБ00-004646 від 02.10.2024 17:19:54 Котельна (Глобине) | E25: 231 | H25: 205 | I25: 58646.66 | K25: Д | L25: 246144.44
A26: 08.10.2024 | B26: Вимога-накладна ІБ00-000535 від 08.10.2024 22:00:14 Списаны ТМЦ | C26: Обл. НДС Виробничий (Глобине-2) Глобине-2 Прямі материальні виробничі витрати крім зворотніх відходів | D26: Обл. НДС Арматура №14 А500С L=12000 мм Надходження товарів і послуг ІБ00-004646 від 02.10.2024 17:19:54 Котельна (Глобине) | E26: 231 | H26: 205 | I26: 164666.65 | K26: Д | L26: 81477.79 | M26: =SUBTOTAL(9,I20:J26) -> 529703.6 | N26: октябрь
A27: 09.10.2024 | B27: Переміщення товарів ІБ00-000097 від 09.10.2024 19:00:00 Перемещение ТМЦ | C27: Обл. НДС Бетон М-350 (Р-4) Надходження товарів і послуг ІБ00-005013 від 09.10.2024 18:37:38 Котельна (Глобине) | D27: Обл. НДС Бетон М-350 (Р-4) Надходження товарів і послуг ІБ00-005013 від 09.10.2024 18:37:38 Глобине-2 | E27: 205 | F27: 269 | H27: 205 | K27: Д | L27: 81746.79
A28: 09.10.2024 | B28: Надходження товарів і послуг ІБ00-005265 від 09.10.2024 22:00:04 Оприходованы ТМЦ (Зачет аванса поставщику) | C28: Обл. НДС Анкерний блок БФБ-1 Надходження товарів і послуг ІБ00-005265 від 09.10.2024 22:00:04 Котельна (Глобине) | D28: МАЛИН МЕТАЛ ТОВ 2709-П от 27.09.2023від 27.09.2023_Глобине 2 Рахунок на оплату постачальника ІБ00-003594 від 19.09.2024 18:10:28 | E28: 205 | F28: 19500 | H28: 631 | K28: Д | L28: 101246.79
A29: 09.10.2024 | B29: Надходження товарів і послуг ІБ00-005265 від 09.10.2024 22:00:04 Оприходованы ТМЦ (Зачет аванса поставщику) | C29: Обл. НДС Анкерний блок БФБ-2 Надходження товарів і послуг ІБ00-005265 від 09.10.2024 22:00:04 Котельна (Глобине) | D29: МАЛИН МЕТАЛ ТОВ 2709-П от 27.09.2023від 27.09.2023_Глобине 2 Рахунок на оплату постачальника ІБ00-003594 від 19.09.2024 18:10:28 | E29: 205 | F29: 11424.99 | H29: 631 | K29: Д | L29: 112671.78
A30: 11.10.2024 | B30: Переміщення товарів ІБ00-000100 від 11.10.2024 18:06:40 Перемещение ТМЦ | C30: Обл. НДС Бетон М-150 (Р-4) Надходження товарів і послуг ІБ00-005014 від 10.10.2024 18:57:57 Котельна (Глобине) | D30: Обл. НДС Бетон М-150 (Р-4) Надходження товарів і послуг ІБ00-005014 від 10.10.2024 18:57:57 Глобине-2 | E30: 205 | F30: 7892.5 | H30: 205 | K30: Д | L30: 120564.28
A31: 15.10.2024 | B31: Переміщення товарів ІБ00-000108 від 15.10.2024 18:37:04 Перемещение ТМЦ | C31: Обл. НДС Бетон С 20/25 F75 W6 Р4 Надходження товарів і послуг ІБ00-005226 від 15.10.2024 18:37:02 Котельна (Глобине) | D31: Обл. НДС Бетон С 20/25 F75 W6 Р4 Надходження товарів і послуг ІБ00-005226 від 15.10.2024 18:37:02 Глобине-2 | E31: 205 | F31: 17505.87 | H31: 205 | K31: Д | L31: 138070.15
A32: 16.10.2024 | B32: Надходження товарів і послуг ІБ00-005216 від 16.10.2024 18:38:25 Оприходованы ТМЦ | C32: Обл. НДС Бетон С 20/25 F75 W6 Р4 Надходження товарів і послуг ІБ00-005216 від 16.10.2024 18:38:25 Котельна (Глобине) | D32: Кременчуцький річковий порт ПРАТ Договір 112/Б від 15.10.2024_Глобине-2 Надходження товарів і послуг ІБ00-005216 від 16.10.2024 18:38:25 | E32: 205 | F32: 30532.5 | H32: 631 | K32: Д | L32: 168602.65
A33: 16.10.2024 | B33: Надходження дод. витрат ІБ00-000435 від 16.10.2024 18:38:26 Доп. расходы при поступлении товаров | C33: Обл. НДС Бетон С 20/25 F75 W6 Р4 Надходження товарів і послуг ІБ00-005216 від 16.10.2024 18:38:25 Котельна (Глобине) | D33: Кременчуцький річковий порт ПРАТ Договір 112/Б від 15.10.2024_Глобине-2 Надходження дод. витрат ІБ00-000435 від 16.10.2024 18:38:26 | E33: 205 | F33: 14626.5 | H33: 631 | K33: Д | L33: 183229.15
A34: 17.10.2024 | B34: Надходження товарів і послуг ІБ00-005215 від 17.10.2024 18:07:50 Оприходованы ТМЦ | C34: Обл. НДС Анкерний блок БФБ-1 Надходження товарів і послуг ІБ00-005215 від 17.10.2024 18:07:50 Котельна (Глобине) | D34: МАЛИН МЕТАЛ ТОВ 2709-П от 27.09.2023від 27.09.2023_Глобине 2 Рахунок на оплату постачальника ІБ00-003594 від 19.09.2024 18:10:28 | E34: 205 | F34: 10386 | H34: 631 | K34: Д | L34: 193615.15
A35: 17.10.2024 | B35: Надходження товарів і послуг ІБ00-005215 від 17.10.2024 18:07:50 Оприходованы ТМЦ (Зачет аванса поставщику) | C35: Обл. НДС Анкерний блок БФБ-1 Надходження товарів і послуг ІБ00-005215 від 17.10.2024 18:07:50 Котельна (Глобине) | D35: МАЛИН МЕТАЛ ТОВ 2709-П от 27.09.2023від 27.09.2023_Глобине 2 Рахунок на оплату постачальника ІБ00-003594 від 19.09.2024 18:10:28 | E35: 205 | F35: 63714 | H35: 631 | K35: Д | L35: 257329.15
A36: 17.10.2024 | B36: Переміщення товарів ІБ00-000110 від 17.10.2024 18:07:54 Перемещение ТМЦ | C36: Обл. НДС Бетон С 8/10 Р4 Надходження товарів і послуг ІБ00-005227 від 17.10.2024 18:07:52 Котельна (Глобине) | D36: Обл. НДС Бетон С 8/10 Р4 Надходження товарів і послуг ІБ00-005227 від 17.10.2024 18:07:52 Глобине-2 | E36: 205 | F36: 8633.03 | H36: 205 | K36: Д | L36: 265962.18
A37: 17.10.2024 | B37: Переміщення товарів ІБ00-000110 від 17.10.2024 18:07:54 Перемещение ТМЦ | C37: Обл. НДС Бетон С 20/25 F75 W6 Р4 Надходження товарів і послуг ІБ00-005227 від 17.10.2024 18:07:52 Котельна (Глобине) | D37: Обл. НДС Бетон С 20/25 F75 W6 Р4 Надходження товарів і послуг ІБ00-005227 від 17.10.2024 18:07:52 Глобине-2 | E37: 205 | F37: 19844.76 | H37: 205 | K37: Д | L37: 285806.94
A38: 17.10.2024 | B38: Надходження товарів і послуг ІБ00-005682 від 17.10.2024 19:38:55 Оприходованы ТМЦ | C38: Обл. НДС Анкерний блок БФБ-1 Надходження товарів і послуг ІБ00-005682 від 17.10.2024 19:38:55 Котельна (Глобине) | D38: МАЛИН МЕТАЛ ТОВ 2709-П от 27.09.2023від 27.09.2023_Глобине 2 Рахунок на оплату постачальника ІБ00-004544 від 01.11.2024 19:56:51 | E38: 205 | F38: 46800 | H38: 631 | K38: Д | L38: 332606.94
... A133: 29.11.2024 | B133: Переміщення товарів ІБ00-000229 від 29.11.2024 14:58:38 Перемещение ТМЦ | C133: Обл. НДС Бетон С 8/10 Р4 (-5*) Надходження товарів і послуг ІБ00-005917 від 29.11.2024 12:58:33 Котельна (Глобине) | D133: Обл. НДС Бетон С 8/10 Р4 (-5*) Надходження товарів і послуг ІБ00-005917 від 29.11.2024 12:58:33 Глобине-2 | E133: 205 | F133: 16331.59 | H133: 205 | K133: Д | L133: 2016851.3
A134: 30.11.2024 | B134: Списання товарів ІБ00-000728 від 30.11.2024 00:00:00 Списаны ТМЦ | C134: Обл. НДС Виробничий (Глобине-2) Глобине-2 Прямі материальні виробничі витрати крім зворотніх відходів | D134: Обл. НДС Фіксатор зірочка 50 Надходження товарів і послуг ІБ00-005520 від 30.10.2024 21:00:06 Котельна (Глобине) | E134: 231 | H134: 205 | I134: 982.5 | K134: Д | L134: 2015868.8
A135: 30.11.2024 | B135: Списання товарів ІБ00-000728 від 30.11.2024 00:00:00 Списаны ТМЦ | C135: Обл. НДС Виробничий (Глобине-2) Глобине-2 Прямі материальні виробничі витрати крім зворотніх відходів | D135: Обл. НДС дошка 25*120 4,5 м шт Надходження товарів і послуг ІБ00-004600 від 25.09.2024 23:00:14 Котельна (Глобине) | E135: 231 | H135: 205 | I135: 4602 | K135: Д | L135: 2011266.8
A136: 30.11.2024 | B136: Списання товарів ІБ00-000649 від 30.11.2024 20:00:00 Списаны ТМЦ | C136: Обл. НДС Виробничий (Глобине-2) Глобине-2 Прямі материальні виробничі витрати крім зворотніх відходів | D136: Обл. НДС Шуруп г/к по дереву 3,5*45 мм Надходження товарів і послуг ІБ00-005405 від 30.10.2024 00:00:00 Котельна (Глобине) | E136: 231 | H136: 205 | I136: 146.8 | K136: Д | L136: 2011120
A137: 30.11.2024 | B137: Списання товарів ІБ00-000649 від 30.11.2024 20:00:00 Списаны ТМЦ | C137: Обл. НДС Виробничий (Глобине-2) Глобине-2 Прямі материальні виробничі витрати крім зворотніх відходів | D137: Обл. НДС Шуруп г/к по дереву 4,2*76 мм Надходження товарів і послуг ІБ00-005521 від 04.11.2024 17:13:08 Котельна (Глобине) | E137: 231 | H137: 205 | I137: 182.5 | K137: Д | L137: 2010937.5
...

Sheet Насосна Градирня (Глобине)
A1: ТОВ "ІНДАСТРІАЛБУД"
A2: Картка рахунку 205 за ... - 2024 р.
A4: Виведені дані: | B4: БО (дані бухгалтерського обліку)
A6: Відбір: | B6: Склади Дорівнює "Насосна Градирня (Глобине)" и Склади.Найменування містить "гло"
A8: Період | B8: Документ | C8: Аналітика Дт | D8: Аналітика Кт | E8: Дебет | H8: Кредит | K8: Поточне сальдо
E9: Рахунок | H9: Рахунок
A10: 01.10.2024 | B10: Переміщення товарів ІБ00-000073 від 01.10.2024 18:35:36 Перемещение ТМЦ | C10: Обл. НДС Арматура №16 А500С L=12000 мм Надходження товарів і послуг ІБ00-004378 від 21.09.2024 23:45:38 Насосна Градирня (Глобине) | D10: Обл. НДС Арматура №16 А500С L=12000 мм Надходження товарів і послуг ІБ00-004378 від 21.09.2024 23:45:38 Глобине-2 | E10: 205 | F10: 111719.98 | H10: 205 | K10: Д | L10: 111719.98
A11: 01.10.2024 | B11: Переміщення товарів ІБ00-000087 від 01.10.2024 18:35:57 Перемещение ТМЦ | C11: Обл. НДС Арматура №14 А500С L=12000 мм Надходження товарів і послуг ІБ00-004643 від 01.10.2024 18:35:04 Насосна Градирня (Глобине) | D11: Обл. НДС Арматура №14 А500С L=12000 мм Надходження товарів і послуг ІБ00-004643 від 01.10.2024 18:35:04 Глобине-2 | E11: 205 | F11: 103942.65 | H11: 205 | K11: Д | L11: 215662.63
A12: 03.10.2024 | B12: Переміщення товарів ІБ00-000084 від 03.10.2024 17:50:21 Перемещение ТМЦ | C12: Обл. НДС Арматура №12 А240С L=6000 мм Надходження товарів і послуг ІБ00-004646 від 02.10.2024 17:19:54 Насосна Градирня (Глобине) | D12: Обл. НДС Арматура №12 А240С L=6000 мм Надходження товарів і послуг ІБ00-004646 від 02.10.2024 17:19:54 Глобине-2 | E12: 205 | F12: 20592.66 | H12: 205 | K12: Д | L12: 236255.29
A13: 08.10.2024 | B13: Вимога-накладна ІБ00-000534 від 08.10.2024 22:00:11 Списаны ТМЦ | C13: Обл. НДС Виробничий (Глобине-2) Глобине-2 Прямі материальні виробничі витрати крім зворотніх відходів | D13: Обл. НДС Арматура №12 А240С L=6000 мм Надходження товарів і послуг ІБ00-004646 від 02.10.2024 17:19:54 Насосна Градирня (Глобине) | E13: 231 | H13: 205 | I13: 17590.66 | K13: Д | L13: 218664.63
A14: 08.10.2024 | B14: Вимога-накладна ІБ00-000534 від 08.10.2024 22:00:11 Списаны ТМЦ | C14: Обл. НДС Виробничий (Глобине-2) Глобине-2 Прямі материальні виробничі витрати крім зворотніх відходів | D14: Обл. НДС Арматура №14 А500С L=12000 мм Надходження товарів і послуг ІБ00-004643 від 01.10.2024 18:35:04 Насосна Градирня (Глобине) | E14: 231 | H14: 205 | I14: 103942.65 | K14: Д | L14: 114721.98
A15: 08.10.2024 | B15: Вимога-накладна ІБ00-000534 від 08.10.2024 22:00:11 Списаны ТМЦ | C15: Обл. НДС Виробничий (Глобине-2) Глобине-2 Прямі материальні виробничі витрати крім зворотніх відходів | D15: Обл. НДС Арматура №16 А500С L=12000 мм Надходження товарів і послуг ІБ00-004378 від 21.09.2024 23:45:38 Насосна Градирня (Глобине) | E15: 231 | H15: 205 | I15: 104069.31 | K15: Д | L15: 10652.67 | M15: =SUBTOTAL(9,I13:J15) -> 225602.62 | N15: октябрь
A16: 11.11.2024 | B16: Надходження товарів і послуг ІБ00-005729 від 11.11.2024 18:00:18 Оприходованы ТМЦ | C16: Обл. НДС Пісок з відсіву дроблення щебеню фр. 0-5мм. Надходження товарів і послуг ІБ00-005729 від 11.11.2024 18:00:18 Насосна Градирня (Глобине) | D16: Венкрас Авто ПП Договір 05/09/2024 від 05.09.2024_Глобине-2 Рахунок на оплату постачальника ІБ00-004660 від 11.11.2024 18:00:17 | E16: 205 | F16: 30656.17 | H16: 631 | K16: Д | L16: 41308.84
A17: 11.11.2024 | B17: Надходження товарів і послуг ІБ00-005729 від 11.11.2024 18:00:18 Оприходованы ТМЦ | C17: Обл. НДС Щебінь 40-70 Надходження товарів і послуг ІБ00-005729 від 11.11.2024 18:00:18 Насосна Градирня (Глобине) | D17: Венкрас Авто ПП Договір 05/09/2024 від 05.09.2024_Глобине-2 Рахунок на оплату постачальника ІБ00-004660 від 11.11.2024 18:00:17 | E17: 205 | F17: 31789.83 | H17: 631 | K17: Д | L17: 73098.67
A18: 11.11.2024 | B18: Надходження дод. витрат ІБ00-000501 від 11.11.2024 18:00:20 Доп. расходы при поступлении товаров | C18: Обл. НДС Пісок з відсіву дроблення щебеню фр. 0-5мм. Надходження товарів і послуг ІБ00-005729 від 11.11.2024 18:00:18 Насосна Градирня (Глобине) | D18: Венкрас Авто ПП Договір 05/09/2024 від 05.09.2024_Глобине-2 Рахунок на оплату постачальника ІБ00-004660 від 11.11.2024 18:00:17 | E18: 205 | F18: 44805.16 | H18: 631 | K18: Д | L18: 117903.83
A19: 11.11.2024 | B19: Надходження дод. витрат ІБ00-000501 від 11.11.2024 18:00:20 Доп. расходы при поступлении товаров | C19: Обл. НДС Щебінь 40-70 Надходження товарів і послуг ІБ00-005729 від 11.11.2024 18:00:18 Насосна Градирня (Глобине) | D19: Венкрас Авто ПП Договір 05/09/2024 від 05.09.2024_Глобине-2 Рахунок на оплату постачальника ІБ00-004660 від 11.11.2024 18:00:17 | E19: 205 | F19: 26261.17 | H19: 631 | K19: Д | L19: 144165
A20: 12.11.2024 | B20: Надходження товарів і послуг ІБ00-005730 від 12.11.2024 18:12:59 Оприходованы ТМЦ | C20: Обл. НДС Щебінь 40-70 Надходження товарів і послуг ІБ00-005730 від 12.11.2024 18:12:59 Насосна Градирня (Глобине) | D20: Венкрас Авто ПП Договір 05/09/2024 від 05.09.2024_Глобине-2 Рахунок на оплату постачальника ІБ00-004661 від 12.11.2024 18:12:58 | E20: 205 | F20: 6198.5 | H20: 631 | K20: Д | L20: 150363.5
A21: 12.11.2024 | B21: Надходження дод. витрат ІБ00-000502 від 12.11.2024 18:13:00 Доп. расходы при поступлении товаров | C21: Обл. НДС Щебінь 40-70 Надходження товарів і послуг ІБ00-005730 від 12.11.2024 18:12:59 Насосна Градирня (Глобине) | D21: Венкрас Авто ПП Договір 05/09/2024 від 05.09.2024_Глобине-2 Рахунок на оплату постачальника ІБ00-004661 від 12.11.2024 18:12:58 | E21: 205 | F21: 5120.5 | H21: 631 | K21: Д | L21: 155484
A22: 13.11.2024 | B22: Надходження товарів і послуг ІБ00-005605 від 13.11.2024 10:00:00 Оприходованы ТМЦ | C22: Обл. НДС Щебінь 40-70 Надходження товарів і послуг ІБ00-005605 від 13.11.2024 10:00:00 Насосна Градирня (Глобине) | D22: Гірник ПрАТ Договір 45 від 11.11.2024_Глобине-2 Надходження товарів і послуг ІБ00-005605 від 13.11.2024 10:00:00 | E22: 205 | F22: 90691.99 | H22: 631 | K22: Д | L22: 246175.99
A23: 16.11.2024 | B23: Переміщення товарів ІБ00-000176 від 16.11.2024 12:00:07 Перемещение ТМЦ | C23: Обл. НДС Щебінь 40-70 Надходження товарів і послуг ІБ00-005704 від 16.11.2024 12:00:06 Насосна Градирня (Глобине) | D23: Обл. НДС Щебінь 40-70 Надходження товарів і послуг ІБ00-005704 від 16.11.2024 12:00:06 Глобине-2 | E23: 205 | F23: 47690.5 | H23: 205 | K23: Д | L23: 293866.49
A24: 18.11.2024 | B24: Переміщення товарів ІБ00-000178 від 18.11.2024 17:48:42 Перемещение ТМЦ | C24: Обл. НДС Щебінь 40-70 Надходження товарів і послуг ІБ00-005706 від 18.11.2024 17:48:41 Насосна Градирня (Глобине) | D24: Обл. НДС Щебінь 40-70 Надходження товарів і послуг ІБ00-005706 від 18.11.2024 17:48:41 Глобине-2 | E24: 205 | F24: 63625.13 | H24: 205 | K24: Д | L24: 357491.62
A25: 28.11.2024 | B25: Вимога-накладна ІБ00-000657 від 28.11.2024 23:00:02 Списаны ТМЦ | C25: Обл. НДС Виробничий (Глобине-2) Глобине-2 Прямі материальні виробничі витрати крім зворотніх відходів | D25: Обл. НДС Щебінь 40-70 Надходження товарів і послуг ІБ00-005605 від 13.11.2024 10:00:00 Насосна Градирня (Глобине) | E25: 231 | H25: 205 | I25: 90691.99 | K25: Д | L25: 266799.63
A26: 28.11.2024 | B26: Вимога-накладна ІБ00-000657 від 28.11.2024 23:00:02 Списаны ТМЦ | C26: Обл. НДС Виробничий (Глобине-2) Глобине-2 Прямі материальні виробничі витрати крім зворотніх відходів | D26: Обл. НДС Щебінь 40-70 Надходження товарів і послуг ІБ00-005704 від 16.11.2024 12:00:06 Насосна Градирня (Глобине) | E26: 231 | H26: 205 | I26: 47690.5 | K26: Д | L26: 219109.13
A27: 28.11.2024 | B27: Вимога-накладна ІБ00-000657 від 28.11.2024 23:00:02 Списаны ТМЦ | C27: Обл. НДС Виробничий (Глобине-2) Глобине-2 Прямі материальні виробничі витрати крім зворотніх відходів | D27: Обл. НДС Щебінь 40-70 Надходження товарів і послуг ІБ00-005706 від 18.11.2024 17:48:41 Насосна Градирня (Глобине) | E27: 231 | H27: 205 | I27: 63625.13 | K27: Д | L27: 155484 | M27: =SUBTOTAL(9,I25:J27) -> 202007.62 | N27: ноябрь
A28: 05.12.2024 | B28: Переміщення товарів ІБ00-000247 від 05.12.2024 19:22:23 Перемещение ТМЦ | C28: Обл. НДС Бетон С 8/10 Р4 (-5*) Надходження товарів і послуг ІБ00-006118 від 05.12.2024 19:00:21 Насосна Градирня (Глобине) | D28: Обл. НДС Бетон С 8/10 Р4 (-5*) Надходження товарів і послуг ІБ00-006118 від 05.12.2024 19:00:21 Глобине-2 | E28: 205 | F28: 78539.13 | H28: 205 | K28: Д | L28: 234023.13
A29: 12.12.2024 | B29: Переміщення товарів ІБ00-000266 від 12.12.2024 18:00:30 Перемещение ТМЦ | C29: Обл. НДС Бетон С20/25 W6 F75 P4 доб-5 Надходження товарів і послуг ІБ00-006223 від 12.12.2024 18:00:26 Насосна Градирня (Глобине) | D29: Обл. НДС Бетон С20/25 W6 F75 P4 доб-5 Надходження товарів і послуг ІБ00-006223 від 12.12.2024 18:00:26 Глобине-2 | E29: 205 | F29: 174968.16 | H29: 205 | K29: Д | L29: 408991.29
A30: 23.12.2024 | B30: Надходження товарів і послуг ІБ00-006411 від 23.12.2024 17:16:15 Оприходованы ТМЦ | C30: Обл. НДС Кутник 50х50 мм 5,0 мм, 6 м Надходження товарів і послуг ІБ00-006411 від 23.12.2024 17:16:15 Насосна Градирня (Глобине) | D30: АВ МЕТАЛ ГРУП ТОВ Дог 2420/Р от 05.10.2023від 05.10.2023_Глобино-2 Рахунок на оплату постачальника ІБ00-005202 від 19.12.2024 18:26:28 | E30: 205 | F30: 1173.7 | H30: 631 | K30: Д | L30: 410164.99
A31: 24.12.2024 | B31: Надходження товарів і послуг ІБ00-006541 від 24.12.2024 12:00:00 Оприходованы ТМЦ (Зачет аванса поставщику) | C31: Обл. НДС Бетон С20/25 W6 F75 P4 доб-5 Надходження товарів і послуг ІБ00-006541 від 24.12.2024 12:00:00 Насосна Градирня (Глобине) | D31: Кременчуцький річковий порт ПРАТ Договір 112/Б від 15.10.2024_Глобине-2 Списання з банківського рахунку 00000022328 від 20.12.2024 19:27:44 | E31: 205 | F31: 168281.25 | H31: 631 | K31: Д | L31: 578446.24
A32: 24.12.2024 | B32: Надходження дод. витрат ІБ00-000636 від 24.12.2024 12:01:00 Доп. расходы при поступлении товаров (Зачет аванса поставщику) | C32: Обл. НДС Бетон С20/25 W6 F75 P4 доб-5 Надходження товарів і послуг ІБ00-006541 від 24.12.2024 12:00:00 Насосна Градирня (Глобине) | D32: Кременчуцький річковий порт ПРАТ Договір 112/Б від 15.10.2024_Глобине-2 Списання з банківського рахунку 00000022328 від 20.12.2024 19:27:44 | E32: 205 | F32: 50132.75 | H32: 631 | K32: Д | L32: 628578.99
A33: 30.12.2024 | B33: Переміщення товарів ІБ00-000294 від 30.12.2024 08:00:00 Перемещение ТМЦ | C33: Обл. НДС Фіксатор конус Надходження товарів і послуг ІБ00-005516 від 05.11.2024 17:28:14 Насосна Градирня (Глобине) | D33: Обл. НДС Фіксатор конус Надходження товарів і послуг ІБ00-005516 від 05.11.2024 17:28:14 Глобине-2 | E33: 205 | F33: 1000 | H33: 205 | K33: Д | L33: 629578.99
A34: 30.12.2024 | B34: Переміщення товарів ІБ00-000294 від 30.12.2024 08:00:00 Перемещение ТМЦ | C34: Обл. НДС Очисник для піни С45 450 мл укр Надходження товарів і послуг ІБ00-004709 від 04.10.2024 18:40:29 Насосна Градирня (Глобине) | D34: Обл. НДС Очисник для піни С45 450 мл укр Надходження товарів і послуг ІБ00-004709 від 04.10.2024 18:40:29 Глобине-2 | E34: 205 | F34: 224.4 | H34: 205 | K34: Д | L34: 629803.39
A35: 30.12.2024 | B35: Переміщення товарів ІБ00-000294 від 30.12.2024 08:00:00 Перемещение ТМЦ | C35: Обл. НДС Піна монтажна 750 мл Надходження товарів і послуг ІБ00-004709 від 04.10.2024 18:40:29 Насосна Градирня (Глобине) | D35: Обл. НДС Піна монтажна 750 мл Надходження товарів і послуг ІБ00-004709 від 04.10.2024 18:40:29 Глобине-2 | E35: 205 | F35: 1620 | H35: 205 | K35: Д | L35: 631423.39
A36: 30.12.2024 | B36: Переміщення товарів ІБ00-000294 від 30.12.2024 08:00:00 Перемещение ТМЦ | C36: Обл. НДС Фанера ламінована 1250*2500*21 мм гл/гл Надходження товарів і послуг ІБ00-004394 від 20.09.2024 18:19:40 Насосна Градирня (Глобине) | D36: Обл. НДС Фанера ламінована 1250*2500*21 мм гл/гл Надходження товарів і послуг ІБ00-004394 від 20.09.2024 18:19:40 Глобине-2 | E36: 205 | F36: 5158.46 | H36: 205 | K36: Д | L36: 636581.85
A37: 30.12.2024 | B37: Вимога-накладна ІБ00-000691 від 30.12.2024 20:00:00 Списаны ТМЦ | C37: Обл. НДС Виробничий (Глобине-2) Глобине-2 Прямі матеріальні виробничі витрати крім зворотних відходів | D37: Обл. НДС Арматура №12 А240С L=6000 мм Надходження товарів і послуг ІБ00-004646 від 02.10.2024 17:19:54 Насосна Градирня (Глобине) | E37: 231 | H37: 205 | I37: 869 | K37: Д | L37: 635712.85
A38: 30.12.2024 | B38: Вимога-накладна ІБ00-000691 від 30.12.2024 20:00:00 Списаны ТМЦ | C38: Обл. НДС Виробничий (Глобине-2) Глобине-2 Прямі матеріальні виробничі витрати крім зворотних відходів | D38: Обл. НДС Арматура №16 А500С L=12000 мм Надходження товарів і послуг ІБ00-004378 від 21.09.2024 23:45:38 Насосна Градирня (Глобине) | E38: 231 | H38: 205 | I38: 5193.34 | K38: Д | L38: 630519.51
A39: 30.12.2024 | B39: Вимога-накладна ІБ00-000691 від 30.12.2024 20:00:00 Списаны ТМЦ | C39: Обл. НДС Виробничий (Глобине-2) Глобине-2 Прямі матеріальні виробничі витрати крім зворотних відходів | D39: Обл. НДС Бетон С20/25 W6 F75 P4 доб-5 Надходження товарів і послуг ІБ00-006223 від 12.12.2024 18:00:26 Насосна Градирня (Глобине) | E39: 231 | H39: 205 | I39: 174968.16 | K39: Д | L39: 455551.35
A40: 30.12.2024 | B40: Вимога-накладна ІБ00-000691 від 30.12.2024 20:00:00 Списаны ТМЦ | C40: Обл. НДС Виробничий (Глобине-2) Глобине-2 Прямі матеріальні виробничі витрати крім зворотних відходів | D40: Обл. НДС Фанера ламінована 1250*2500*21 мм гл/гл Надходження товарів і послуг ІБ00-004394 від 20.09.2024 18:19:40 Насосна Градирня (Глобине) | E40: 231 | H40: 205 | I40: 5158.46 | K40: Д | L40: 450392.89
A41: 30.12.2024 | B41: Вимога-накладна ІБ00-000690 від 30.12.2024 21:00:06 Списаны ТМЦ | C41: Обл. НДС Виробничий (Глобине-2) Глобине-2 Прямі матеріальні виробничі витрати крім зворотних відходів | D41: Обл. НДС Щебінь 40-70 Надходження товарів і послуг ІБ00-005729 від 11.11.2024 18:00:18 Насосна Градирня (Глобине) | E41: 231 | H41: 205 | I41: 58051 | K41: Д | L41: 392341.89
A42: 30.12.2024 | B42: Вимога-накладна ІБ00-000690 від 30.12.2024 21:00:06 Списаны ТМЦ | C42: Обл. НДС Виробничий (Глобине-2) Глобине-2 Прямі матеріальні виробничі витрати крім зворотних відходів | D42: Обл. НДС Щебінь 40-70 Надходження товарів і послуг ІБ00-005730 від 12.11.2024 18:12:59 Насосна Градирня (Глобине) | E42: 231 | H42: 205 | I42: 11319 | K42: Д | L42: 381022.89
A43: 30.12.2024 | B43: Вимога-накладна ІБ00-000690 від 30.12.2024 21:00:06 Списаны ТМЦ | C43: Обл. НДС Виробничий (Глобине-2) Глобине-2 Прямі матеріальні виробничі витрати крім зворотних відходів | D43: Обл. НДС Бетон С 8/10 Р4 (-5*) Надходження товарів і послуг ІБ00-006118 від 05.12.2024 19:00:21 Насосна Градирня (Глобине) | E43: 231 | H43: 205 | I43: 78539.13 | K43: Д | L43: 302483.76
...

Sheet Р-р для зб. розч.(Глобине)
A1: ТОВ "ІНДАСТРІАЛБУД"
A2: Картка рахунку 205 за ... - 2024 р.
A4: Виведені дані: | B4: БО (дані бухгалтерського обліку)
A6: Відбір: | B6: Склади Дорівнює "Резервуар для зберігання розчинника(Глобине)" и Склади.Найменування містить "гло"
A8: Період | B8: Документ | C8: Аналітика Дт | D8: Аналітика Кт | E8: Дебет | H8: Кредит | K8: Поточне сальдо
E9: Рахунок | H9: Рахунок
A10: 01.10.2024 | B10: Переміщення товарів ІБ00-000071 від 01.10.2024 18:35:34 Перемещение ТМЦ | C10: Обл. НДС Арматура №10 А240С L=6000 мм Надходження товарів і послуг ІБ00-004378 від 21.09.2024 23:45:38 Резервуар для зберігання розчинника(Глобине) | D10: Обл. НДС Арматура №10 А240С L=6000 мм Надходження товарів і послуг ІБ00-004378 від 21.09.2024 23:45:38 Глобине-2 | E10: 205 | F10: 3686.67 | H10: 205 | K10: Д | L10: 3686.67
A11: 01.10.2024 | B11: Переміщення товарів ІБ00-000071 від 01.10.2024 18:35:34 Перемещение ТМЦ | C11: Обл. НДС Арматура №12 А500С L=12000 мм Надходження товарів і послуг ІБ00-004378 від 21.09.2024 23:45:38 Резервуар для зберігання розчинника(Глобине) | D11: Обл. НДС Арматура №12 А500С L=12000 мм Надходження товарів і послуг ІБ00-004378 від 21.09.2024 23:45:38 Глобине-2 | E11: 205 | F11: 43623.99 | H11: 205 | K11: Д | L11: 47310.66
A12: 01.10.2024 | B12: Переміщення товарів ІБ00-000071 від 01.10.2024 18:35:34 Перемещение ТМЦ | C12: Обл. НДС Арматура №14 А500С L=12000 мм Надходження товарів і послуг ІБ00-004377 від 21.09.2024 23:45:37 Резервуар для зберігання розчинника(Глобине) | D12: Обл. НДС Арматура №14 А500С L=12000 мм Надходження товарів і послуг ІБ00-004377 від 21.09.2024 23:45:37 Глобине-2 | E12: 205 | F12: 24320 | H12: 205 | K12: Д | L12: 71630.66
A13: 01.10.2024 | B13: Переміщення товарів ІБ00-000071 від 01.10.2024 18:35:34 Перемещение ТМЦ | C13: Обл. НДС Арматура №16 А500С L=12000 мм Надходження товарів і послуг ІБ00-004378 від 21.09.2024 23:45:38 Резервуар для зберігання розчинника(Глобине) | D13: Обл. НДС Арматура №16 А500С L=12000 мм Надходження товарів і послуг ІБ00-004378 від 21.09.2024 23:45:38 Глобине-2 | E13: 205 | F13: 6586.67 | H13: 205 | K13: Д | L13: 78217.33
A14: 02.10.2024 | B14: Переміщення товарів ІБ00-000085 від 02.10.2024 17:20:12 Перемещение ТМЦ | C14: Обл. НДС Арматура №14 А500С L=12000 мм Надходження товарів і послуг ІБ00-004643 від 01.10.2024 18:35:04 Резервуар для зберігання розчинника(Глобине) | D14: Обл. НДС Арматура №14 А500С L=12000 мм Надходження товарів і послуг ІБ00-004643 від 01.10.2024 18:35:04 Глобине-2 | E14: 205 | F14: 12844 | H14: 205 | K14: Д | L14: 91061.33
A15: 03.10.2024 | B15: Переміщення товарів ІБ00-000080 від 03.10.2024 17:50:17 Перемещение ТМЦ | C15: Обл. НДС Арматура №14 А500С L=12000 мм Надходження товарів і послуг ІБ00-004644 від 02.10.2024 17:19:53 Резервуар для зберігання розчинника(Глобине) | D15: Обл. НДС Арматура №14 А500С L=12000 мм Надходження товарів і послуг ІБ00-004644 від 02.10.2024 17:19:53 Глобине-2 | E15: 205 | F15: 564426.59 | H15: 205 | K15: Д | L15: 655487.92
A16: 03.10.2024 | B16: Переміщення товарів ІБ00-000081 від 03.10.2024 17:50:18 Перемещение ТМЦ | C16: Обл. НДС Арматура №16 А500С L=12000 мм Надходження товарів і послуг ІБ00-004646 від 02.10.2024 17:19:54 Резервуар для зберігання розчинника(Глобине) | D16: Обл. НДС Арматура №16 А500С L=12000 мм Надходження товарів і послуг ІБ00-004646 від 02.10.2024 17:19:54 Глобине-2 | E16: 205 | F16: 22546.66 | H16: 205 | K16: Д | L16: 678034.58
A17: 03.10.2024 | B17: Переміщення товарів ІБ00-000083 від 03.10.2024 17:50:20 Перемещение ТМЦ | C17: Обл. НДС Арматура №12 А240С L=6000 мм Надходження товарів і послуг ІБ00-004646 від 02.10.2024 17:19:54 Резервуар для зберігання розчинника(Глобине) | D17: Обл. НДС Арматура №12 А240С L=6000 мм Надходження товарів і послуг ІБ00-004646 від 02.10.2024 17:19:54 Глобине-2 | E17: 205 | F17: 36155.66 | H17: 205 | K17: Д | L17: 714190.24
A18: 23.10.2024 | B18: Надходження товарів і послуг ІБ00-005212 від 23.10.2024 18:16:34 Оприходованы ТМЦ | C18: Обл. НДС Анкерний блок БФБ-1 Надходження товарів і послуг ІБ00-005212 від 23.10.2024 18:16:34 Резервуар для зберігання розчинника(Глобине) | D18: МАЛИН МЕТАЛ ТОВ 2709-П от 27.09.2023від 27.09.2023_Глобине 2 Рахунок на оплату постачальника ІБ00-003596 від 19.09.2024 18:10:30 | E18: 205 | F18: 1137.5 | H18: 631 | K18: Д | L18: 715327.74
A19: 23.10.2024 | B19: Надходження товарів і послуг ІБ00-005212 від 23.10.2024 18:16:34 Оприходованы ТМЦ (Зачет аванса поставщику) | C19: Обл. НДС Анкерний блок БФБ-1 Надходження товарів і послуг ІБ00-005212 від 23.10.2024 18:16:34 Резервуар для зберігання розчинника(Глобине) | D19: МАЛИН МЕТАЛ ТОВ 2709-П от 27.09.2023від 27.09.2023_Глобине 2 Рахунок на оплату постачальника ІБ00-003596 від 19.09.2024 18:10:30 | E19: 205 | F19: 27300 | H19: 631 | K19: Д | L19: 742627.74
A20: 02.11.2024 | B20: Переміщення товарів ІБ00-000124 від 02.11.2024 12:00:00 Перемещение ТМЦ | C20: Обл. НДС Арматура №10 А240С L=6000 мм Надходження товарів і послуг ІБ00-004378 від 21.09.2024 23:45:38 СПК (Глобине) | D20: Обл. НДС Арматура №10 А240С L=6000 мм Надходження товарів і послуг ІБ00-004378 від 21.09.2024 23:45:38 Резервуар для зберігання розчинника(Глобине) | E20: 205 | H20: 205 | I20: 2554.34 | K20: Д | L20: 740073.4
A21: 02.11.2024 | B21: Переміщення товарів ІБ00-000124 від 02.11.2024 12:00:00 Перемещение ТМЦ | C21: Обл. НДС Арматура №12 А240С L=6000 мм Надходження товарів і послуг ІБ00-004646 від 02.10.2024 17:19:54 СПК (Глобине) | D21: Обл. НДС Арматура №12 А240С L=6000 мм Надходження товарів і послуг ІБ00-004646 від 02.10.2024 17:19:54 Резервуар для зберігання розчинника(Глобине) | E21: 205 | H21: 205 | I21: 14694 | K21: Д | L21: 725379.4
A22: 02.11.2024 | B22: Переміщення товарів ІБ00-000124 від 02.11.2024 12:00:00 Перемещение ТМЦ | C22: Обл. НДС Арматура №12 А500С L=12000 мм Надходження товарів і послуг ІБ00-004378 від 21.09.2024 23:45:38 СПК (Глобине) | D22: Обл. НДС Арматура №12 А500С L=12000 мм Надходження товарів і послуг ІБ00-004378 від 21.09.2024 23:45:38 Резервуар для зберігання розчинника(Глобине) | E22: 205 | H22: 205 | I22: 31894.66 | K22: Д | L22: 693484.74
A23: 02.11.2024 | B23: Переміщення товарів ІБ00-000124 від 02.11.2024 12:00:00 Перемещение ТМЦ | C23: Обл. НДС Арматура №14 А500С L=12000 мм Надходження товарів і послуг ІБ00-004377 від 21.09.2024 23:45:37 СПК (Глобине) | D23: Обл. НДС Арматура №14 А500С L=12000 мм Надходження товарів і послуг ІБ00-004377 від 21.09.2024 23:45:37 Резервуар для зберігання розчинника(Глобине) | E23: 205 | H23: 205 | I23: 24320 | K23: Д | L23: 669164.74
A24: 02.11.2024 | B24: Переміщення товарів ІБ00-000124 від 02.11.2024 12:00:00 Перемещение ТМЦ | C24: Обл. НДС Арматура №14 А500С L=12000 мм Надходження товарів і послуг ІБ00-004643 від 01.10.2024 18:35:04 СПК (Глобине) | D24: Обл. НДС Арматура №14 А500С L=12000 мм Надходження товарів і послуг ІБ00-004643 від 01.10.2024 18:35:04 Резервуар для зберігання розчинника(Глобине) | E24: 205 | H24: 205 | I24: 12844 | K24: Д | L24: 656320.74
A25: 02.11.2024 | B25: Переміщення товарів ІБ00-000124 від 02.11.2024 12:00:00 Перемещение ТМЦ | C25: Обл. НДС Арматура №14 А500С L=12000 мм Надходження товарів і послуг ІБ00-004644 від 02.10.2024 17:19:53 СПК (Глобине) | D25: Обл. НДС Арматура №14 А500С L=12000 мм Надходження товарів і послуг ІБ00-004644 від 02.10.2024 17:19:53 Резервуар для зберігання розчинника(Глобине) | E25: 205 | H25: 205 | I25: 125222.65 | K25: Д | L25: 531098.09
A26: 08.11.2024 | B26: Переміщення товарів ІБ00-000161 від 08.11.2024 17:54:24 Перемещение ТМЦ | C26: Обл. НДС Арматура №10 А240С L=6000 мм Надходження товарів і послуг ІБ00-004378 від 21.09.2024 23:45:38 Резервуар для зберігання розчинника(Глобине) | D26: Обл. НДС Арматура №10 А240С L=6000 мм Надходження товарів і послуг ІБ00-004378 від 21.09.2024 23:45:38 СПК (Глобине) | E26: 205 | F26: 2554.34 | H26: 205 | K26: Д | L26: 533652.43
A27: 08.11.2024 | B27: Переміщення товарів ІБ00-000161 від 08.11.2024 17:54:24 Перемещение ТМЦ | C27: Обл. НДС Арматура №12 А240С L=6000 мм Надходження товарів і послуг ІБ00-004646 від 02.10.2024 17:19:54 Резервуар для зберігання розчинника(Глобине) | D27: Обл. НДС Арматура №12 А240С L=6000 мм Надходження товарів і послуг ІБ00-004646 від 02.10.2024 17:19:54 СПК (Глобине) | E27: 205 | F27: 14694 | H27: 205 | K27: Д | L27: 548346.43
A28: 08.11.2024 | B28: Переміщення товарів ІБ00-000161 від 08.11.2024 17:54:24 Перемещение ТМЦ | C28: Обл. НДС Арматура №12 А500С L=12000 мм Надходження товарів і послуг ІБ00-004378 від 21.09.2024 23:45:38 Резервуар для зберігання розчинника(Глобине) | D28: Обл. НДС Арматура №12 А500С L=12000 мм Надходження товарів і послуг ІБ00-004378 від 21.09.2024 23:45:38 СПК (Глобине) | E28: 205 | F28: 31894.66 | H28: 205 | K28: Д | L28: 580241.09
A29: 08.11.2024 | B29: Переміщення товарів ІБ00-000161 від 08.11.2024 17:54:24 Перемещение ТМЦ | C29: Обл. НДС Арматура №14 А500С L=12000 мм Надходження товарів і послуг ІБ00-004377 від 21.09.2024 23:45:37 Резервуар для зберігання розчинника(Глобине) | D29: Обл. НДС Арматура №14 А500С L=12000 мм Надходження товарів і послуг ІБ00-004377 від 21.09.2024 23:45:37 СПК (Глобине) | E29: 205 | F29: 24320 | H29: 205 | K29: Д | L29: 604561.09
A30: 08.11.2024 | B30: Переміщення товарів ІБ00-000161 від 08.11.2024 17:54:24 Перемещение ТМЦ | C30: Обл. НДС Арматура №14 А500С L=12000 мм Надходження товарів і послуг ІБ00-004643 від 01.10.2024 18:35:04 Резервуар для зберігання розчинника(Глобине) | D30: Обл. НДС Арматура №14 А500С L=12000 мм Надходження товарів і послуг ІБ00-004643 від 01.10.2024 18:35:04 СПК (Глобине) | E30: 205 | F30: 12844 | H30: 205 | K30: Д | L30: 617405.09
A31: 08.11.2024 | B31: Переміщення товарів ІБ00-000161 від 08.11.2024 17:54:24 Перемещение ТМЦ | C31: Обл. НДС Арматура №14 А500С L=12000 мм Надходження товарів і послуг ІБ00-004644 від 02.10.2024 17:19:53 Резервуар для зберігання розчинника(Глобине) | D31: Обл. НДС Арматура №14 А500С L=12000 мм Надходження товарів і послуг ІБ00-004644 від 02.10.2024 17:19:53 СПК (Глобине) | E31: 205 | F31: 125222.65 | H31: 205 | K31: Д | L31: 742627.74
A32: 08.11.2024 | B32: Вимога-накладна ІБ00-000533 від 08.11.2024 20:00:00 Списаны ТМЦ | C32: Обл. НДС Виробничий (Глобине-2) Глобине-2 Прямі материальні виробничі витрати крім зворотніх відходів | D32: Обл. НДС Арматура №10 А240С L=6000 мм Надходження товарів і послуг ІБ00-004378 від 21.09.2024 23:45:38 Резервуар для зберігання розчинника(Глобине) | E32: 231 | H32: 205 | I32: 2554.34 | K32: Д | L32: 740073.4
A33: 08.11.2024 | B33: Вимога-накладна ІБ00-000533 від 08.11.2024 20:00:00 Списаны ТМЦ | C33: Обл. НДС Виробничий (Глобине-2) Глобине-2 Прямі материальні виробничі витрати крім зворотніх відходів | D33: Обл. НДС Арматура №12 А500С L=12000 мм Надходження товарів і послуг ІБ00-004378 від 21.09.2024 23:45:38 Резервуар для зберігання розчинника(Глобине) | E33: 231 | H33: 205 | I33: 31894.66 | K33: Д | L33: 708178.74
A34: 08.11.2024 | B34: Вимога-накладна ІБ00-000533 від 08.11.2024 20:00:00 Списаны ТМЦ | C34: Обл. НДС Виробничий (Глобине-2) Глобине-2 Прямі материальні виробничі витрати крім зворотніх відходів | D34: Обл. НДС Арматура №12 А240С L=6000 мм Надходження товарів і послуг ІБ00-004646 від 02.10.2024 17:19:54 Резервуар для зберігання розчинника(Глобине) | E34: 231 | H34: 205 | I34: 14694 | K34: Д | L34: 693484.74
A35: 08.11.2024 | B35: Вимога-накладна ІБ00-000533 від 08.11.2024 20:00:00 Списаны ТМЦ | C35: Обл. НДС Виробничий (Глобине-2) Глобине-2 Прямі материальні виробничі витрати крім зворотніх відходів | D35: Обл. НДС Арматура №14 А500С L=12000 мм Надходження товарів і послуг ІБ00-004377 від 21.09.2024 23:45:37 Резервуар для зберігання розчинника(Глобине) | E35: 231 | H35: 205 | I35: 24320 | K35: Д | L35: 669164.74
A36: 08.11.2024 | B36: Вимога-накладна ІБ00-000533 від 08.11.2024 20:00:00 Списаны ТМЦ | C36: Обл. НДС Виробничий (Глобине-2) Глобине-2 Прямі материальні виробничі витрати крім зворотніх відходів | D36: Обл. НДС Арматура №14 А500С L=12000 мм Надходження товарів і послуг ІБ00-004643 від 01.10.2024 18:35:04 Резервуар для зберігання розчинника(Глобине) | E36: 231 | H36: 205 | I36: 3952 | K36: Д | L36: 665212.74
A37: 08.11.2024 | B37: Вимога-накладна ІБ00-000533 від 08.11.2024 20:00:00 Списаны ТМЦ | C37: Обл. НДС Виробничий (Глобине-2) Глобине-2 Прямі материальні виробничі витрати крім зворотніх відходів | D37: Обл. НДС Арматура №14 А500С L=12000 мм Надходження товарів і послуг ІБ00-004643 від 01.10.2024 18:35:04 Резервуар для зберігання розчинника(Глобине) | E37: 231 | H37: 205 | I37: 8892 | K37: Д | L37: 656320.74
A38: 08.11.2024 | B38: Вимога-накладна ІБ00-000533 від 08.11.2024 20:00:00 Списаны ТМЦ | C38: Обл. НДС Виробничий (Глобине-2) Глобине-2 Прямі материальні виробничі витрати крім зворотніх відходів | D38: Обл. НДС Арматура №14 А500С L=12000 мм Надходження товарів і послуг ІБ00-004644 від 02.10.2024 17:19:53 Резервуар для зберігання розчинника(Глобине) | E38: 231 | H38: 205 | I38: 555534.59 | K38: Д | L38: 100786.15
A39: 08.11.2024 | B39: Вимога-накладна ІБ00-000533 від 08.11.2024 20:00:00 Списаны ТМЦ | C39: Обл. НДС Виробничий (Глобине-2) Глобине-2 Прямі материальні виробничі витрати крім зворотніх відходів | D39: Обл. НДС Арматура №16 А500С L=12000 мм Надходження товарів і послуг ІБ00-004378 від 21.09.2024 23:45:38 Резервуар для зберігання розчинника(Глобине) | E39: 231 | H39: 205 | I39: 6586.67 | K39: Д | L39: 94199.48
A40: 08.11.2024 | B40: Вимога-накладна ІБ00-000533 від 08.11.2024 20:00:00 Списаны ТМЦ | C40: Обл. НДС Виробничий (Глобине-2) Глобине-2 Прямі материальні виробничі витрати крім зворотніх відходів | D40: Обл. НДС Арматура №16 А500С L=12000 мм Надходження товарів і послуг ІБ00-004646 від 02.10.2024 17:19:54 Резервуар для зберігання розчинника(Глобине) | E40: 231 | H40: 205 | I40: 22546.66 | K40: Д | L40: 71652.82 | M40: =SUBTOTAL(9,I32:J40) -> 670974.92 | N40: ноябрь
A41: Обороти за період та сальдо на кінець | E41: 954157.39 | H41: 882504.57 | K41: Д | L41: 71652.82
J43: =SUBTOTAL(9,I32:J40) -> 670974.92

Sheet СПК (Глобине)
A1: ТОВ "ІНДАСТРІАЛБУД"
A2: Картка рахунку 205 за ... - 2024 р.
A4: Виведені дані: | B4: БО (дані бухгалтерського обліку)
A6: Відбір: | B6: Склади Дорівнює "СПК (Глобине)" и Склади.Найменування містить "гло"
A8: Період | B8: Документ | C8: Аналітика Дт | D8: Аналітика Кт | E8: Дебет | H8: Кредит | K8: Поточне сальдо
E9: Рахунок | H9: Рахунок
