Workbook

Sheet Акты заказчика
A1: Дата | B1: Номер | C1: Контрагент | D1: Сума | E1: Валюта | F1: Підрозділ | G1: Організація | H1: Відповідальний | I1: Коментар
A2: 01.04.2024 15:17:04 | B2: ІБ00-000086 | C2: Вінницька птахофабрика ВКВК філія ТОВ | D2: 1197761.4 | E2: грн | F2: Виробничий (Ладижин) | G2: ТОВ "ІНДАСТРІАЛБУД" | H2: Хлань Елена | I2: Акт №35
A3: 09.04.2024 17:42:57 | B3: ІБ00-000103 | C3: Вінницька птахофабрика ВКВК філія ТОВ | D3: 1007909.5 | E3: грн | F3: Виробничий (Ладижин) | G3: ТОВ "ІНДАСТРІАЛБУД" | H3: Хлань Елена | I3: Акт №36
A4: 09.04.2024 17:42:58 | B4: ІБ00-000104 | C4: Вінницька птахофабрика ВКВК філія ТОВ | D4: 141577.06 | E4: грн | F4: Виробничий (Ладижин) | G4: ТОВ "ІНДАСТРІАЛБУД" | H4: Хлань Елена | I4: Акт №1
A5: 10.04.2024 16:27:53 | B5: ІБ00-000087 | C5: ЗАПОРІЗЬКИЙ ОЛІЙНОЕКСТРАКЦІЙНИЙ ЗАВОД ПРАТ | D5: 19998.64 | E5: грн | F5: Виробничий (Запоріж_Турбіна2) | G5: ТОВ "ІНДАСТРІАЛБУД" | H5: Хлань Елена | I5: По рахунку (не підписаний)
A6: 11.04.2024 08:18:33 | B6: ІБ00-000085 | C6: Старокостянтинівський олійноекстраційний завод ТОВ | D6: 316521.03 | E6: грн | F6: Виробничий (Старокостянтинів | G6: ТОВ "ІНДАСТРІАЛБУД" | H6: Хлань Елена | I6: Акт № 1ДОГОВІР ПІДРЯДУ № 22/01/2024 -КМ -СтОЕ від 22.01.2024
A7: 15.04.2024 12:00:00 | B7: ІБ00-000088 | C7: АВІА ВЕНЧУРС ТОВ | D7: 813895.61 | E7: грн | F7: Виробничий (Крушинка) | G7: ТОВ "ІНДАСТРІАЛБУД" | H7: Хлань Елена | I7: акт №25 за квітень 2024
A8: 15.04.2024 12:00:01 | B8: ІБ00-000089 | C8: АВІА ВЕНЧУРС ТОВ | D8: 161785.3 | E8: грн | F8: Виробничий (Крушинка) | G8: ТОВ "ІНДАСТРІАЛБУД" | H8: Хлань Елена | I8: акт №23 за квітень 2024
A9: 15.04.2024 17:43:17 | B9: ІБ00-000110 | C9: АВІА ВЕНЧУРС ТОВ | D9: 934814.87 | E9: грн | F9: Виробничий (Крушинка) | G9: ТОВ "ІНДАСТРІАЛБУД" | H9: Хлань Елена | I9: акт №24 за квітень 2024
A10: 18.04.2024 15:14:16 | B10: ІБ00-000100 | C10: ЗАПОРІЗЬКИЙ ОЛІЯЖИРКОМБІНАТ ПРАТ | D10: 251957.66 | E10: грн | F10: Виробничий Щедро_Флексітанки | G10: ТОВ "ІНДАСТРІАЛБУД" | H10: Хлань Елена | I10: акт № 2 ТК
A11: 18.04.2024 15:14:59 | B11: ІБ00-000101 | C11: ЗАПОРІЗЬКИЙ ОЛІЯЖИРКОМБІНАТ ПРАТ | D11: 445544.56 | E11: грн | F11: Виробничий Щедро_Флексітанки | G11: ТОВ "ІНДАСТРІАЛБУД" | H11: Хлань Елена | I11: Без списання акт № 2 архітектурні рішення
A12: 18.04.2024 15:16:20 | B12: ІБ00-000102 | C12: ЗАПОРІЗЬКИЙ ОЛІЯЖИРКОМБІНАТ ПРАТ | D12: 14156.68 | E12: грн | F12: Виробничий Щедро_Флексітанки | G12: ТОВ "ІНДАСТРІАЛБУД" | H12: Хлань Елена | I12: акт №3 влаштування дорожних плит
A13: 18.04.2024 17:41:21 | B13: ІБ00-000106 | C13: ЗАПОРІЗЬКИЙ ОЛІЯЖИРКОМБІНАТ ПРАТ | D13: 4912771.3 | E13: грн | F13: Виробничий Щедро_Флексітанки | G13: ТОВ "ІНДАСТРІАЛБУД" | H13: Хлань Елена | I13: акт №2
... A21: 30.04.2024 15:58:01 | B21: ІБ00-000124 | C21: ЗАПОРІЗЬКИЙ ОЛІЯЖИРКОМБІНАТ ПРАТ | D21: 526875.01 | E21: грн | F21: Виробничий Щедро_Флексітанки | G21: ТОВ "ІНДАСТРІАЛБУД" | H21: Хлань Елена | I21: акт №1 розробка грунту
D22: =SUM(D1:D21) -> 14482080
D23: =D22-D29 -> 0
C24: Крушинка | D24: =D7+D8+D9 -> 1910495.8
C25: Ладыжин-3 | D25: =D2+D3+D4+D17 -> 2574701
C26: Турбина-2 | D26: =D5 -> 19998.64
C27: Щедро.Флекситанки | D27: =D10+D11+D12+D13+D14+D15+D16+D18+D19+D20+D21 -> 9660363.6 | F27: =D27+D58 -> 10298773 | G27: * всего с продажей
C28: Староконстантинов | D28: =D6 -> 316521.03
C29: ИТОГО | D29: =SUBTOTAL(9,D24:D28) -> 14482080
A31: Дата | B31: Номер | C31: Контрагент | D31: Сума | E31: Валюта | F31: Підрозділ | G31: Організація | H31: Відповідальний | I31: Коментар
A32: 01.05.2024 12:00:00 | B32: ІБ00-000090 | C32: НІЖИНСЬКИЙ ЖИРКОМБІНАТ ПрАТ | D32: 74844.2 | E32: грн | F32: Виробничий (Ніжин-3) | G32: ТОВ "ІНДАСТРІАЛБУД" | H32: Хлань Елена | I32: Акт № 1 без дати проведення | J32: * в Марте 24
A33: 01.05.2024 12:00:01 | B33: ІБ00-000091 | C33: НІЖИНСЬКИЙ ЖИРКОМБІНАТ ПрАТ | D33: 585276.82 | E33: грн | F33: Виробничий (Ніжин-3) | G33: ТОВ "ІНДАСТРІАЛБУД" | H33: Хлань Елена | I33: Акт № 2 без дати проведення | J33: * в Марте 24
A34: 01.05.2024 12:00:02 | B34: ІБ00-000092 | C34: НІЖИНСЬКИЙ ЖИРКОМБІНАТ ПрАТ | D34: 585218.82 | E34: грн | F34: Виробничий (Ніжин-3) | G34: ТОВ "ІНДАСТРІАЛБУД" | H34: Хлань Елена | I34: Акт № 3 без дати проведення | J34: * в Марте 24
A35: 01.05.2024 12:00:03 | B35: ІБ00-000093 | C35: НІЖИНСЬКИЙ ЖИРКОМБІНАТ ПрАТ | D35: 70000 | E35: грн | F35: Виробничий (Ніжин-3) | G35: ТОВ "ІНДАСТРІАЛБУД" | H35: Хлань Елена | I35: Акт № 4 без дати проведення | J35: * в Марте 24
A36: 01.05.2024 12:00:04 | B36: ІБ00-000095 | C36: НІЖИНСЬКИЙ ЖИРКОМБІНАТ ПрАТ | D36: 92115.83 | E36: грн | F36: Виробничий (Ніжин-3) | G36: ТОВ "ІНДАСТРІАЛБУД" | H36: Хлань Елена | I36: Акт № 5 без дати проведення | J36: * в Марте 24
A37: 01.05.2024 12:00:05 | B37: ІБ00-000096 | C37: НІЖИНСЬКИЙ ЖИРКОМБІНАТ ПрАТ | D37: 69692.79 | E37: грн | F37: Виробничий (Ніжин-3) | G37: ТОВ "ІНДАСТРІАЛБУД" | H37: Хлань Елена | I37: Акт № 6 без дати проведення | J37: * в Марте 24
A38: 01.05.2024 12:00:06 | B38: ІБ00-000097 | C38: НІЖИНСЬКИЙ ЖИРКОМБІНАТ ПрАТ | D38: 220420.19 | E38: грн | F38: Виробничий (Ніжин-3) | G38: ТОВ "ІНДАСТРІАЛБУД" | H38: Хлань Елена | I38: Акт № 7 без дати проведення | J38: * в Марте 24
A39: 01.05.2024 12:00:07 | B39: ІБ00-000098 | C39: НІЖИНСЬКИЙ ЖИРКОМБІНАТ ПрАТ | D39: 19075.72 | E39: грн | F39: Виробничий (Ніжин-3) | G39: ТОВ "ІНДАСТРІАЛБУД" | H39: Хлань Елена | I39: Акт № 8 без дати проведення | J39: * в Марте 24
A40: 01.05.2024 12:00:08 | B40: ІБ00-000099 | C40: НІЖИНСЬКИЙ ЖИРКОМБІНАТ ПрАТ | D40: 8730 | E40: грн | F40: Виробничий (Ніжин-3) | G40: ТОВ "ІНДАСТРІАЛБУД" | H40: Хлань Елена | I40: Акт № 9 без дати проведення | J40: * в Марте 24
A41: 01.05.2024 12:00:14 | B41: ІБ00-000115 | C41: НІЖИНСЬКИЙ ЖИРКОМБІНАТ ПрАТ | D41: 1609186.5 | E41: грн | F41: Виробничий (Ніжин-3) | G41: ТОВ "ІНДАСТРІАЛБУД" | H41: Хлань Елена | I41: Акт № 10 без дати проведення
A42: 01.05.2024 12:00:15 | B42: ІБ00-000116 | C42: НІЖИНСЬКИЙ ЖИРКОМБІНАТ ПрАТ | D42: 231000 | E42: грн | F42: Виробничий (Ніжин-3) | G42: ТОВ "ІНДАСТРІАЛБУД" | H42: Хлань Елена | I42: Акт № 11 без дати проведення
A43: 01.05.2024 12:00:16 | B43: ІБ00-000117 | C43: НІЖИНСЬКИЙ ЖИРКОМБІНАТ ПрАТ | D43: 27868 | E43: грн | F43: Виробничий (Ніжин-3) | G43: ТОВ "ІНДАСТРІАЛБУД" | H43: Хлань Елена | I43: Акт № 14 без дати проведення
A44: 01.05.2024 12:00:17 | B44: ІБ00-000118 | C44: НІЖИНСЬКИЙ ЖИРКОМБІНАТ ПрАТ | D44: 554353 | E44: грн | F44: Виробничий (Ніжин-3) | G44: ТОВ "ІНДАСТРІАЛБУД" | H44: Хлань Елена | I44: Акт № 15 без дати проведення
A45: 01.05.2024 12:00:18 | B45: ІБ00-000119 | C45: НІЖИНСЬКИЙ ЖИРКОМБІНАТ ПрАТ | D45: 446461.48 | E45: грн | F45: Виробничий (Ніжин-3) | G45: ТОВ "ІНДАСТРІАЛБУД" | H45: Хлань Елена | I45: Акт № 16 без дати проведення
A46: 01.05.2024 12:00:19 | B46: ІБ00-000120 | C46: НІЖИНСЬКИЙ ЖИРКОМБІНАТ ПрАТ | D46: 47254.52 | E46: грн | F46: Виробничий (Ніжин-3) | G46: ТОВ "ІНДАСТРІАЛБУД" | H46: Хлань Елена | I46: Акт № 17 без дати проведення
A47: 01.05.2024 12:00:20 | B47: ІБ00-000121 | C47: НІЖИНСЬКИЙ ЖИРКОМБІНАТ ПрАТ | D47: 2044 | E47: грн | F47: Виробничий (Ніжин-3) | G47: ТОВ "ІНДАСТРІАЛБУД" | H47: Хлань Елена | I47: Акт № 18 без дати проведення
A48: 10.05.2024 11:49:48 | B48: ІБ00-000129 | C48: НІЖИНСЬКИЙ ЖИРКОМБІНАТ ПрАТ | D48: 1027136 | E48: грн | F48: Виробничий (Ніжин-3) | G48: ТОВ "ІНДАСТРІАЛБУД" | H48: Хлань Елена | I48: Акт № 12 без дати проведення
...

Sheet Списание стройматериалов
A1: Дата | B1: Номер | C1: Склад відправник | D1: Сумма без НДС | E1: Сумма С НДС | F1: Склад одержувач | G1: Відповідальний | H1: Коментар
A2: 30.04.2024 00:00:00 | B2: ІБ00-000020 | C2: Ніжин-3 | D2: 509666.2 | E2: =D2*1.2 -> 611599.44 | F2: Склад списання Ніжин-3 | G2: Хлань Елена | H2: Переміщення до акту № 10 (ІБ00-000115 в 1С)
A3: 30.04.2024 18:47:46 | B3: ІБ00-000021 | C3: Ніжин-3 | D3: 58885.82 | E3: =D3*1.2 -> 70662.984 | F3: Склад списання Ніжин-3 | G3: Хлань Елена | H3: Переміщення до акту № 16 (ІБ00-000119 в 1С)
E4: =SUM(E2:E3) -> 682262.42
A6: Дата | B6: Номер | C6: Склад | D6: Сумма без НДС | E6: Сумма С НДС | F6: Підрозділ | G6: Відповідальний | H6: Коментар
A7: 01.04.2024 16:00:04 | B7: ІБ00-000132 | C7: Ладижин-3 | D7: 540044.05 | E7: =D7*1.2 -> 648052.86 | F7: Виробничий (Ладижин) | G7: Хлань Елена
A8: 09.04.2024 17:43:06 | B8: ІБ00-000133 | C8: Ладижин-3 | D8: 450953.98 | E8: =D8*1.2 -> 541144.78 | F8: Виробничий (Ладижин) | G8: Хлань Елена
A9: 09.04.2024 17:43:10 | B9: ІБ00-000134 | C9: Ладижин-3 | D9: 29397.85 | E9: =D9*1.2 -> 35277.42 | F9: Виробничий (Ладижин) | G9: Хлань Елена
A10: 10.04.2024 09:26:17 | B10: ІБ00-000179 | C10: Запоріжжя_Турбіна 2 | D10: 13333.34 | E10: =D10*1.2 -> 16000.008 | F10: Виробничий (Запоріж_Турбіна2) | G10: Хлань Елена
A11: 11.04.2024 18:00:01 | B11: ІБ00-000194 | C11: Старокостянтинів | D11: 1963.05 | E11: =D11*1.2 -> 2355.66 | F11: Виробничий (Старокостянтинів | G11: Хлань Елена
A12: 15.04.2024 00:00:00 | B12: ІБ00-000199 | C12: Крушинка | D12: 78762.61 | E12: =D12*1.2 -> 94515.132 | F12: Виробничий (Крушинка) | G12: Хлань Елена
A13: 15.04.2024 18:32:08 | B13: ІБ00-000200 | C13: Крушинка | D13: 390783.1 | E13: =D13*1.2 -> 468939.72 | F13: Виробничий (Крушинка) | G13: Хлань Елена
A14: 18.04.2024 11:13:24 | B14: ІБ00-000183 | C14: Щедро_Флекситанки | D14: 152523.88 | E14: =D14*1.2 -> 183028.66 | F14: Виробничий Щедро_Флексітанки | G14: Хлань Елена
A15: 18.04.2024 11:18:54 | B15: ІБ00-000186 | C15: Щедро_Флекситанки | D15: 284508.78 | E15: =D15*1.2 -> 341410.54 | F15: Виробничий Щедро_Флексітанки | G15: Хлань Елена
A16: 18.04.2024 12:52:12 | B16: ІБ00-000187 | C16: Щедро_Флекситанки | D16: 3749.47 | E16: =D16*1.2 -> 4499.364 | F16: Виробничий Щедро_Флексітанки | G16: Хлань Елена
A17: 18.04.2024 14:55:36 | B17: ІБ00-000188 | C17: Щедро_Флекситанки | D17: 58378.47 | E17: =D17*1.2 -> 70054.164 | F17: Виробничий Щедро_Флексітанки | G17: Хлань Елена
A18: 18.04.2024 18:21:56 | B18: ІБ00-000182 | C18: Щедро_Флекситанки | D18: 3519759.1 | E18: =D18*1.2 -> 4223711 | F18: Виробничий Щедро_Флексітанки | G18: Хлань Елена
... A20: 23.04.2024 18:04:37 | B20: ІБ00-000195 | C20: Ладижин-3 | D20: 41821.54 | E20: =D20*1.2 -> 50185.848 | F20: Виробничий (Ладижин) | G20: Хлань Елена
A21: 24.04.2024 00:00:00 | B21: ІБ00-000110 | C21: Запоріжжя_Турбіна 2 | D21: 14442.23 | E21: =D21*1.2 -> 17330.676 | F21: Виробничий (Запоріж_Турбіна2) | G21: Хлань Елена | H21: Досписання згідно листа
A22: 24.04.2024 13:17:07 | B22: ІБ00-000185 | C22: ООН Київ | D22: 15511.61 | E22: =D22*1.2 -> 18613.932 | F22: Виробничий (ООН Київ) | G22: Хлань Елена | H22: Досписання
A23: 30.04.2024 00:00:00 | B23: ІБ00-000201 | C23: Щедро_Флекситанки | D23: 129647.84 | E23: =D23*1.2 -> 155577.41 | F23: Виробничий Щедро_Флексітанки | G23: Хлань Елена
A24: 30.04.2024 20:00:00 | B24: ІБ00-000203 | C24: Щедро_Флекситанки | D24: 97877.6 | E24: =D24*1.2 -> 117453.12 | F24: Виробничий Щедро_Флексітанки | G24: Хлань Елена
A25: 30.04.2024 21:49:03 | B25: ІБ00-000202 | C25: Щедро_Флекситанки | D25: 306596.68 | E25: =D25*1.2 -> 367916.02 | F25: Виробничий Щедро_Флексітанки | G25: Хлань Елена
A26: 30.04.2024 21:49:14 | B26: ІБ00-000204 | C26: Щедро_Флекситанки | D26: 385806.97 | E26: =D26*1.2 -> 462968.36 | F26: Виробничий Щедро_Флексітанки | G26: Хлань Елена
D27: =SUM(D7:D26) -> 7119066 | E27: =SUM(E7:E26) -> 8542879.2
D28: =D27-D36 -> 0 | E28: =E27-E36 -> 0
C30: Ладижин-3 | D30: =SUMIF($C$7:$C$26,C30,$D$7:$D$26) -> 1062217.4 | E30: =SUMIF($C$7:$C$26,C30,$E$7:$E$26) -> 1274660.9
C31: Запоріжжя_Турбіна 2 | D31: =SUMIF($C$7:$C$26,C31,$D$7:$D$26) -> 27775.57 | E31: =SUMIF($C$7:$C$26,C31,$E$7:$E$26) -> 33330.684 | F31: =E21 -> 17330.676 | G31: * досписание
C32: Старокостянтинів | D32: =SUMIF($C$7:$C$26,C32,$D$7:$D$26) -> 1963.05 | E32: =SUMIF($C$7:$C$26,C32,$E$7:$E$26) -> 2355.66
C33: Крушинка | D33: =SUMIF($C$7:$C$26,C33,$D$7:$D$26) -> 469545.71 | E33: =SUMIF($C$7:$C$26,C33,$E$7:$E$26) -> 563454.85
C34: ООН Київ | D34: =SUMIF($C$7:$C$26,C34,$D$7:$D$26) -> 15511.61 | E34: =SUMIF($C$7:$C$26,C34,$E$7:$E$26) -> 18613.932 | F34: *досписание
C35: Щедро_Флекситанки | D35: =SUMIF($C$7:$C$26,C35,$D$7:$D$26) -> 5542052.6 | E35: =SUMIF($C$7:$C$26,C35,$E$7:$E$26) -> 6650463.1
C36: ИТОГО | D36: =SUM(D30:D35) -> 7119066 | E36: =SUM(E30:E35) -> 8542879.2

Sheet ВаловаяПрибыль
A1: Контрагент | B1: Дохід | C1: ПДВ | D1: Собівартість | E1: Інші витрати (Послуги транспортні, проектні та інші)
A2: Договір
A3: Акт
A4: АВІА ВЕНЧУРС ТОВ | B4: 1910495.8 | C4: 318415.97 | D4: 469545.71
A5: ДОГОВІР ПІДРЯДУ № 20230815-3 від 15.08.2023 | B5: 1910495.8 | C5: 318415.97 | D5: 469545.71
A6: Надання виробничих послуг ІБ00-000088 от 15.04.2024 12:00:00 | B6: 813895.61 | C6: 135649.27
A7: Надання виробничих послуг ІБ00-000089 от 15.04.2024 12:00:01 | B7: 161785.3 | C7: 26964.22 | D7: 78762.61 | F7: ='Списание стройматериалов'!D12 -> 78762.61 | G7: =D7-F7 -> 0
A8: Надання виробничих послуг ІБ00-000110 от 15.04.2024 17:43:17 | B8: 934814.87 | C8: 155802.48 | D8: 390783.1 | F8: ='Списание стройматериалов'!D13 -> 390783.1 | G8: =D8-F8 -> 0
A9: Вінницька птахофабрика ВКВК філія ТОВ | B9: 2574701 | C9: 429116.83 | D9: 1062217.4
A10: Договір №0502/24/Л/1 від 05.02.2024 року | B10: 141577.06 | C10: 23596.18 | D10: 29397.85
A11: Надання виробничих послуг ІБ00-000104 от 09.04.2024 17:42:58 | B11: 141577.06 | C11: 23596.18 | D11: 29397.85 | F11: ='Списание стройматериалов'!D9 -> 29397.85 | G11: =D11-F11 -> 0
A12: Договір №2909/2023/ЛА від 29.09.2023 року | B12: 2433123.9 | C12: 405520.65 | D12: 1032819.6
A13: Надання виробничих послуг ІБ00-000086 от 01.04.2024 15:17:04 | B13: 1197761.4 | C13: 199626.89 | D13: 540044.05 | F13: ='Списание стройматериалов'!D7 -> 540044.05 | G13: =D13-F13 -> 0
A14: Надання виробничих послуг ІБ00-000103 от 09.04.2024 17:42:57 | B14: 1007909.5 | C14: 167984.91 | D14: 450953.98 | F14: ='Списание стройматериалов'!D8 -> 450953.98 | G14: =D14-F14 -> 0
A15: Надання виробничих послуг ІБ00-000112 от 23.04.2024 18:04:26 | B15: 227453.08 | C15: 37908.85 | D15: 41821.54 | F15: ='Списание стройматериалов'!D20 -> 41821.54 | G15: =D15-F15 -> 0
A16: ЗАПОРІЗЬКИЙ ОЛІЙНОЕКСТРАКЦІЙНИЙ ЗАВОД ПРАТ | B16: 19998.64 | C16: 3333.11 | D16: 13333.34
A17: рахунок 58 | B17: 19998.64 | C17: 3333.11 | D17: 13333.34
A18: Надання виробничих послуг ІБ00-000087 от 10.04.2024 16:27:53 | B18: 19998.64 | C18: 3333.11 | D18: 13333.34 | F18: ='Списание стройматериалов'!D10 -> 13333.34 | G18: =D18-F18 -> 0
A19: ЗАПОРІЗЬКИЙ ОЛІЯЖИРКОМБІНАТ ПРАТ | B19: 9660363.6 | C19: 1610060.6 | D19: 5542052.6 | E19: 436834.69
A20: Договір підряду №26 | B20: 9660363.6 | C20: 1610060.6 | D20: 5542052.6 | E20: 436834.69
A21: Надання виробничих послуг ІБ00-000100 от 18.04.2024 15:14:16 | B21: 251957.66 | C21: 41992.94 | D21: 58378.47 | E21: 42866.35 | F21: ='Списание стройматериалов'!D17 -> 58378.47 | G21: =D21-F21 -> 0 | H21: МІКС-ІНВЕСТ ТОВ
A22: Надання виробничих послуг ІБ00-000101 от 18.04.2024 15:14:59 | B22: 445544.56 | C22: 74257.43 | D22: 284508.78 | F22: ='Списание стройматериалов'!D15 -> 284508.78 | G22: =D22-F22 -> 0
A23: Надання виробничих послуг ІБ00-000102 от 18.04.2024 15:16:20 | B23: 14156.68 | C23: 2359.45 | D23: 3749.47 | F23: ='Списание стройматериалов'!D16 -> 3749.47 | G23: =D23-F23 -> 0
A24: Надання виробничих послуг ІБ00-000106 от 18.04.2024 17:41:21 | B24: 4912771.3 | C24: 818795.21 | D24: 3519759.1 | F24: ='Списание стройматериалов'!D18 -> 3519759.1 | G24: =D24-F24 -> 0
A25: Надання виробничих послуг ІБ00-000107 от 18.04.2024 17:42:22 | B25: 407309.86 | C25: 67884.98 | D25: 152523.88 | F25: ='Списание стройматериалов'!D14 -> 152523.88 | G25: =D25-F25 -> 0
A26: Надання виробничих послуг ІБ00-000108 от 18.04.2024 17:43:09 | B26: 154324.64 | C26: 25720.77 | F26: * списание по 209 сч
A27: Надання виробничих послуг ІБ00-000109 от 22.04.2024 16:54:19 | B27: 949942.85 | C27: 158323.81 | D27: 603203.77 | E27: 48256.07 | F27: ='Списание стройматериалов'!D19 -> 603203.77 | G27: =D27-F27 -> 0 | H27: МІКС-ІНВЕСТ ТОВ
A28: Надання виробничих послуг ІБ00-000114 от 30.04.2024 08:53:35 | B28: 410142.29 | C28: 68357.05 | D28: 97877.6 | E28: 70186.78 | F28: ='Списание стройматериалов'!D24 -> 97877.6 | G28: =D28-F28 -> 0 | H28: МІКС-ІНВЕСТ ТОВ
A29: Надання виробничих послуг ІБ00-000122 от 30.04.2024 13:04:12 | B29: 586626.11 | C29: 97771.02 | D29: 306596.68 | E29: 81666.67 | F29: ='Списание стройматериалов'!D25 -> 306596.68 | G29: =D29-F29 -> 0 | H29: СПЕЦТЕХІНВЕСТ БТО ТОВ
A30: Надання виробничих послуг ІБ00-000123 от 30.04.2024 15:51:54 | B30: 1000712.7 | C30: 166785.44 | D30: 385806.97 | E30: 120125.49 | F30: ='Списание стройматериалов'!D26 -> 385806.97 | G30: =D30-F30 -> 0 | H30: МІКС-ІНВЕСТ ТОВ
A31: Надання виробничих послуг ІБ00-000124 от 30.04.2024 15:58:01 | B31: 526875.01 | C31: 87812.5 | D31: 129647.84 | E31: 73733.33 | F31: ='Списание стройматериалов'!D23 -> 129647.84 | G31: =D31-F31 -> 0 | H31: СКОЧ ПЛЮС ТОВ
A32: Старокостянтинівський олійноекстраційний завод ТОВ | B32: 316521.03 | C32: 52753.5 | D32: 1963.05 | E32: 78083.05
A33: ДОГОВІР ПІДРЯДУ № 22/01/2024 -КМ -СтОЕ від 22.01.2 | B33: 316521.03 | C33: 52753.5 | D33: 1963.05 | E33: 78083.05
A34: Надання виробничих послуг ІБ00-000085 от 11.04.2024 08:18:33 | B34: 316521.03 | C34: 52753.5 | D34: 1963.05 | E34: 78083.05 | F34: ='Списание стройматериалов'!D32 -> 1963.05 | G34: =D34-F34 -> 0
A35: Итого | B35: 15404580 | C35: 2567430 | D35: 7089112.1 | E35: 514917.74

Sheet Услуги_сторонних
A1: Дата | B1: Номер | C1: Вид операції | D1: Сума | E1: Валюта | F1: Склад | G1: Контрагент | H1: Дата вх.
A2: 15.05.2024 11:13:56 | B2: ІБ00-001707 | C2: Покупка, комісія | D2: 418537.66 | E2: грн | F2: Ніжин-3 | G2: ІНДЕПТ СТІЛ ТОВ | I2: * в Мае 24
A3: 15.05.2024 11:14:32 | B3: ІБ00-001708 | C3: Покупка, комісія | D3: 122216.93 | E3: грн | F3: Ніжин-3 | G3: ІНДЕПТ СТІЛ ТОВ | I3: * в Мае 24
A4: 15.05.2024 11:17:09 | B4: ІБ00-001709 | C4: Покупка, комісія | D4: 459424.54 | E4: грн | F4: Ніжин-3 | G4: ІНДЕПТ СТІЛ ТОВ | I4: * в Мае 24
A5: 15.05.2024 15:00:00 | B5: ІБ00-001486 | C5: Покупка, комісія | D5: 3307.28 | E5: грн | F5: Ніжин-3 | G5: ІНДЕПТ СТІЛ ТОВ | I5: * в Апреле 24
A6: 15.05.2024 15:00:00 | B6: ІБ00-001487 | C6: Покупка, комісія | D6: 327145.93 | E6: грн | F6: Ніжин-3 | G6: ІНДЕПТ СТІЛ ТОВ | I6: * в Апреле 24
A7: 15.05.2024 15:00:00 | B7: ІБ00-001488 | C7: Покупка, комісія | D7: 67466.33 | E7: грн | F7: Ніжин-3 | G7: ІНДЕПТ СТІЛ ТОВ | I7: * в Апреле 24
D8: =SUM(D5:D7) -> 397919.54
A10: Дата | B10: Номер | C10: Вид операції | D10: Сума | E10: Валюта | F10: Склад | G10: Контрагент | H10: Дата вх. | I10: Номер вх. | J10: Договір | K10: Документ розрахунків | L10: Організація | M10: Відповідальний
A11: 18.04.2024 18:22:00 | B11: ІБ00-001485 | C11: Покупка, комісія | D11: 51439.62 | E11: грн | F11: Щедро_Флекситанки | G11: МІКС-ІНВЕСТ ТОВ | H11: 18.04.2024 | I11: АКТ 2/ТК/2 | J11: Договір 07-02/2024 від 07.02.2024_Щедро.Флексі | K11: Рахунок на оплату постачальника ІБ00-000315 от 08.02.2024 17:53:06 | L11: ТОВ "ІНДАСТРІАЛБУД" | M11: Хлань Елена
A12: 22.04.2024 16:54:28 | B12: ІБ00-001496 | C12: Покупка, комісія | D12: 57907.28 | E12: грн | F12: Щедро_Флекситанки | G12: МІКС-ІНВЕСТ ТОВ | H12: 22.04.2024 | I12: АКТ 3/ТХ/2 | J12: Договір 07-02/2024 від 07.02.2024_Щедро.Флексі | K12: Рахунок на оплату постачальника ІБ00-000315 от 08.02.2024 17:53:06 | L12: ТОВ "ІНДАСТРІАЛБУД" | M12: Хлань Елена
A13: 30.04.2024 18:47:56 | B13: ІБ00-001609 | C13: Покупка, комісія | D13: 144150.59 | E13: грн | F13: Щедро_Флекситанки | G13: МІКС-ІНВЕСТ ТОВ | H13: 30.04.2024 | I13: АКТ 3/ТХ/3 | J13: Договір 07-02/2024 від 07.02.2024_Щедро.Флексі | K13: Рахунок на оплату постачальника ІБ00-000315 от 08.02.2024 17:53:06 | L13: ТОВ "ІНДАСТРІАЛБУД" | M13: Хлань Елена
A14: 30.04.2024 18:47:57 | B14: ІБ00-001610 | C14: Покупка, комісія | D14: 84224.14 | E14: грн | F14: Щедро_Флекситанки | G14: МІКС-ІНВЕСТ ТОВ | H14: 30.04.2024 | I14: АКТ 2/ТК/3 | J14: Договір 07-02/2024 від 07.02.2024_Щедро.Флексі | K14: Рахунок на оплату постачальника ІБ00-000315 от 08.02.2024 17:53:06 | L14: ТОВ "ІНДАСТРІАЛБУД" | M14: Хлань Елена
D15: =SUM(D11:D14) -> 337721.63
A17: Дата | B17: Номер | C17: Вид операції | D17: Сума | E17: Валюта | F17: Склад | G17: Контрагент | H17: Дата вх. | I17: Номер вх. | J17: Договір | K17: Документ розрахунків | L17: Організація | M17: Відповідальний | N17: Коментар
A18: 30.04.2024 18:47:58 | B18: ІБ00-001611 | C18: Покупка, комісія | D18: 98000 | E18: грн | F18: Щедро_Флекситанки | G18: СПЕЦТЕХІНВЕСТ БТО ТОВ | H18: 30.04.2024 | I18: Акт 1 | J18: Договір 26/03/2024 від 26.03.2024_Щедро.Флексі | K18: Рахунок на оплату постачальника ІБ00-000835 от 26.03.2024 17:57:27 | L18: ТОВ "ІНДАСТРІАЛБУД" | M18: Хлань Елена | N18: Вентиляція
D19: =SUM(D18) -> 98000
A21: Дата | B21: Номер | C21: Вид операції | D21: Сума | E21: Валюта | F21: Склад | G21: Контрагент | H21: Дата вх. | I21: Номер вх. | J21: Договір | K21: Документ розрахунків | L21: Організація | M21: Відповідальний | N21: Коментар
A22: 30.04.2024 23:00:00 | B22: ІБ00-001679 | C22: Покупка, комісія | D22: 88480 | E22: грн | F22: Щедро_Флекситанки | G22: СКОЧ ПЛЮС ТОВ | H22: 30.04.2024 | I22: Акт 1 | J22: Договір № 14032024 від 14.03.2024_Щедро.Флексі | K22: Рахунок на оплату постачальника ІБ00-000786 от 18.03.2024 16:35:56 | L22: ТОВ "ІНДАСТРІАЛБУД" | M22: Хлань Елена | N22: Скан електрика
D23: =SUM(D22) -> 88480
