Workbook

Sheet ноябрь
A5: Замовник: ТОВ "СІА"
A6: Генпідрядник: ТОВ "ДИПРОІНБУД"
A7: Найменування будови та її адреса - Будівництво житлово-громадської забудови з об’єктами соціальної та інженерно-транспортної інфраструктури по вул. Євгена Сверстюка, 4 (колишня вул. Марини Раскової) у Дніпровському районі м. Києва.
A8: Найменування об'єкта - Житловий будинок № 3, секції 5 та 6.
A9: Договір: №14/08/2017-ГПР-III/ГЛ від 14.08.2017 р.
A11: РЕЄСТР АКТІВ ВИКОНАНИХ РОБІТ ПО ОБ'ЄКТУ | J11: 1.03 | V11: 100
A13: № п/п | B13: Вид робіт (витрат) | C13: Найменування робіт | D13: ДЦ | E13: Сума ДЦ | F13: Управлінський облік | H13: Всего управлінський облік | J13: Діпроинбуд | M13: Підрядник | Q13: Перевірка | V13: г/п
F14: листопад 2017()
A15: 1 | B15: 2 | C15: 3 | D15: 4 | F15: 4 | G15: 5 | I15: 7
J16: всього | K16: робота | L16: мат-ли | M16: всього | N16: робота | O16: мат-ли | P16: найменув. | Q16: робота | R16: мат-ли | S16: зараб. 3% | T16: перевірка
A17: 1 | B17: Розробка котловану | C17: грунт | D17: 12102-1 | E17: 657140 | F17: 12102-1/1 | G17: =301810.6 -> 301810.6 | H17: =F17 -> 12102-1/1 | I17: 301810.6 | J17: =(K17+L17)*$J$11 -> 251508.83 | K17: =244183.33 -> 244183.33 | L17: 0 | M17: =N17+O17 -> 336378.6 | N17: =280315.5*1.2 -> 336378.6 | P17: Индустрія | Q17: =K17-N17 -> -92195.27 | R17: =L17-O17 -> 0 | S17: =J17-M17*1.03 -> -94961.128 | T17: =M17*1.03 -> 346469.96 | U17: =J17-M17 -> -84869.77 | V17: =Q17/$V$11*W17 -> -2765.8581 | W17: 3
A18: 2 | B18: Палі основні | C18: палі | D18: 12103-1 | E18: =7254070.69 -> 7254070.7 | F18: 12103-1/1 | G18: =3195761.59 -> 3195761.6 | H18: =F18 -> 12103-1/1 | I18: =G18 -> 3195761.6 | J18: =L18*$J$11+K18 -> 3195761.6 | K18: =743034.22*1.2 -> 891641.06 | L18: =1864175.18*1.2 -> 2237010.2 | M18: =N18+O18 -> 3128651.3 | N18: =743034.22*1.2 -> 891641.06 | O18: =1864175.18*1.2 -> 2237010.2 | P18: Фундамент | Q18: =K19-N18 -> -876120.53 | R18: =L19-O18 -> -2187140.3 | S18: =J18-M18*1.03 -> -26749.232 | T18: =M18*1.03 -> 3222510.8 | U18: =J18-M18 -> 67110.306 | V18: =Q18/$V$11*W18 -> -13141.808 | W18: 1.5
A19: 3 | B19: Палі під баштовий кран | C19: палі кран | D19: 12104-1 | F19: 12104-1/1 | G19: =66886.52 -> 66886.52 | H19: =F19 -> 12104-1/1 | I19: =G19 -> 66886.52 | J19: =L19*$J$11+K19 -> 66886.521 | K19: =12933.78*1.2 -> 15520.536 | L19: =41558.24*1.2 -> 49869.888 | M19: =N19+O19 -> 0 | Q19: =#REF!-N19 -> #REF! | R19: =#REF!-O19 -> #REF! | S19: =J19-M19*1.03 -> 66886.521 | T19: =M19*1.03 -> 0 | U19: =J19-M19 -> 66886.521 | V19: =Q19/$V$11*W19 -> #REF!
A20: 4 | B20: Зняття електроенергії | C20: г/п доп | F20: г/п доп | G20: =-27521.64*1.2 -> -33025.968
B21: ВСЬОГО: | G21: =SUM(G17:G20) -> 3531432.7
B23: Виконав: __________________Кириченко Р.Л. 097-434-82-92
B27: Погоджено __________________________

Sheet Реєстр ДЦ
A1: ДОВІДКА по об'єктам ТОВ "ІНДАСТРІАЛБУД"
A3: № з/п | B3: Об'єкт | C3: Замовник | D3: Найменування робіт (витрат) | E3: №, дата Договору | F3: ДЦ до Договру, грн. з ПДВ | I3: Статус | J3: Собівартість, грн. з ПДВ | M3: Примітки
F4: Разом | G4: Матеріали | H4: Робота | J4: Разом | K4: Матеріали | L4: Робота
A5: 1 | B5: 2 | C5: 3 | D5: 4 | E5: 5 | F5: 6 | G5: 7 | H5: 8 | I5: 9 | J5: 10 | K5: 11 | L5: 12 | M5: 10
A6: 4 | B6: «Нове будівництво олієпресового цеху по переробці насіння соняшника потужністю 1200т/добу з допоміжними будівлями та спорудами внутрішньогосподарського комплексу по виробництву кормів" м.Ладижин, Вінницької області» | C6: ПрАТ "МХП" | D6: Будівництво каркасу оліє-пресового цеху №2 з трансформаторною підстанцією, м.Ладижин, Вінницька область | E6: №389-10 від 19.02.2021 | F6: =9670800 -> 9670800 | G6: =980219.27 -> 980219.27 | H6: =F6-G6 -> 8690580.7 | I6: Погоджено замовником
D7: Додаткові роботи по монтажу/демонтажу з/б балок каркасу, згідно дефектного акту №1 | E7: Д/У№1 до дог. №389-10 від 19.02.2021 | F7: 131336.26 | G7: 41465.11 | H7: =F7-G7 -> 89871.15 | I7: Погоджено замовником | J7: =102739.6 -> 102739.6 | K7: =16812.5 -> 16812.5 | L7: =J7-K7 -> 85927.1 | M7: 0.2783
D8: Влаштування фундаментів допоміжних споруд оліє-пресового цеху по переробці насіння соняшника 1200т/добу | E8: №396-10 від 31.03.2021 | F8: =4080000 -> 4080000 | G8: =2262472.26 -> 2262472.3 | H8: =F8-G8 -> 1817527.7 | I8: Погоджено замовником
D9: Мурування ТП | F9: =1100452.22 -> 1100452.2 | G9: =F9-H9 -> 410866.37 | H9: =689585.85 -> 689585.85 | I9: Внутр. погодження
F10: =SUM(F6:F9) -> 14982588 | G10: =SUM(G6:G9) -> 3695023 | H10: =SUM(H6:H9) -> 11287565
F11: =F10+#REF!+#REF!+#REF! -> #REF! | G11: =G10+#REF!+#REF!+#REF! -> #REF! | H11: =H10+#REF!+#REF!+#REF! -> #REF!

Sheet Реєстр АВР
B1: ДОВІДКА по об'єктам ТОВ "ІНДАСТРІАЛБУД" | D1: 44336
A2: № з/п | B2: Найменування об'єкту | C2: Замовник | D2: № Договору | E2: Загальна вартість Договору з урах.ДУ | H2: Сума АВР | N2: Залишок по Договору
E3: Разом | F3: Матеріали | G3: Робота | H3: № | I3: Разом | J3: Матеріали | K3: Робота | L3: Дата | M3: Статус | N3: Разом | O3: Матеріали | P3: Робота
A4: 4 | B4: «Нове будівництво олієпресового цеху по переробці насіння соняшника потужністю 1200т/добу з допоміжними будівлями та спорудами внутрішньогосподарського комплексу по виробництву кормів" м.Ладижин, Вінницької області» | C4: ПрАТ "МХП" | D4: №389-10 від 19.02.2021 | E4: ='Реєстр ДЦ'!F6 -> 9670800 | F4: ='Реєстр ДЦ'!G6 -> 980219.27 | G4: ='Реєстр ДЦ'!H6 -> 8690580.7 | H4: 1 | I4: =288379.22 -> 288379.22 | J4: =7494.3*1.2 -> 8993.16 | K4: =I4-J4 -> 279386.06 | L4: 44314 | M4: Підписаний | N4: =E4-I8 -> 7863750.8 | O4: =F4-J8 -> 950795.63 | P4: =G4-K8 -> 6912955.1
H5: 2 | I5: =193609.49 -> 193609.49 | J5: 0 | K5: =I5 -> 193609.49 | L5: 44314 | M5: Підписаний
H6: 3 | I6: 266283.61 | J6: =7768.48*1.2 -> 9322.176 | K6: =I6-J6 -> 256961.43 | L6: травень 2021 | M6: Підписаний
H7: 4 | I7: 1058776.9 | J7: =9256.92*1.2 -> 11108.304 | K7: =I7-J7 -> 1047668.6 | L7: травень 2022 | M7: Підписаний
I8: =SUM(I4:I7) -> 1807049.2 | J8: =SUM(J4:J7) -> 29423.64 | K8: =SUM(K4:K7) -> 1777625.6
D9: Д/У№1 до дог.№389-10 від 19.02.2021 | E9: ='Реєстр ДЦ'!F7 -> 131336.26 | F9: ='Реєстр ДЦ'!G7 -> 41465.11 | G9: ='Реєстр ДЦ'!H7 -> 89871.15 | I9: 5042.8 | J9: 0 | K9: =I9-J9 -> 5042.8 | M9: На розгляді у замовника | N9: =E9-I11 -> 126293.46 | O9: =F9-J11 -> 41465.11 | P9: =G9-K11 -> 84828.35
I11: =SUM(I9:I10) -> 5042.8 | J11: =SUM(J9:J10) -> 0 | K11: =SUM(K9:K10) -> 5042.8
D12: №396-10 від 31.03.2021 | E12: ='Реєстр ДЦ'!F8 -> 4080000 | F12: =1885393.55*1.2 -> 2262472.3 | G12: =E12-F12 -> 1817527.7 | N12: =E12-I14 -> 4080000 | O12: =F12-J14 -> 2262472.3 | P12: =G12-K14 -> 1817527.7
I14: =SUM(I12:I13) -> 0 | J14: =SUM(J12:J13) -> 0 | K14: =SUM(K12:K13) -> 0
D15: Нет номера договора | E15: ='Реєстр ДЦ'!F9 -> 1100452.2 | F15: =410866.37 -> 410866.37 | G15: =E15-F15 -> 689585.85 | N15: =E15-I16 -> 1100452.2 | O15: =F15-J16 -> 410866.37 | P15: =G15-K16 -> 689585.85
I16: =SUM(I15) -> 0 | J16: =SUM(J15) -> 0 | K16: =SUM(K15) -> 0
I17: =I8+I11+I14+I16 -> 1812092.1 | J17: =J8+J11+J14+J16 -> 29423.64 | K17: =K8+K11+K14+K16 -> 1782668.4
E18: =SUM(E4:E16) -> 14982588 | F18: =SUM(F4:F16) -> 3695023 | G18: =SUM(G4:G16) -> 11287565 | I18: =#REF!+#REF!+#REF!+I17 -> #REF! | J18: =#REF!+#REF!+#REF!+J17 -> #REF! | K18: =#REF!+#REF!+#REF!+K17 -> #REF! | N18: =SUM(N4:N16) -> 13170496 | O18: =SUM(O4:O16) -> 3665599.4 | P18: =SUM(P4:P16) -> 9504897.1

Sheet Реєстр ДЦ 
A1: Реєстр ДЦ по об'єкту "комплекс підготовчих робіт та монтаж пальового поля для будівництва об’єкту: «Нове будівництво заводу з переробки соєвого шроту продуктивністю 500т/добу за адресою: вул. Володимирівська, 65-Д, м. Глобине, Кременчуцький район, Полтавська область»"
I2: *********Вимоги
A3: № ДЦ | B3: Найменування договірної ціни | C3: Роботи з ПДВ, грн | D3: Матеріали з ПДВ, грн | E3: Всього по ДЦ з ПДВ, грн | F3: Статус | G3: Дата | H3: Коментарі | I3: Для заповнення колонки статус | J3: Для заповнення колонки коментарі | K3: оплата
I4: Варіанти статусу | J4: Побажання до коментарів (основне)
A5: (Договір № 14/06/2024) | B5: Підготовчі роботи та монтаж пальового поля (Договір № 14/06/2024) | H5: Договор будет переподписываться в новой редакции с учетом аванса) | I5: ДЦ у відділі ВТВ | J5: заповнюємо колонку коли отримали інформацію і планова дата ССДЦ, або ДЦ ДУ планується і вказуємо що маємо отримати інформацію
A6: Додаткова угода №1 к договору 14/06/2024 | B6: Пересчет КП в новой редакции (согласно проекта) | C6: =E6-D6 -> 7142088 | D6: 11448535 | E6: 18590623 | F6: подписано | K6: =1000000+3797805.45+4030999.51+2619730.3 -> 11448535
A7: Договор №19/07/2024 | B7: Демонтажніе работі+разница земляных работ | C7: =E7-D7 -> 698867.58 | D7: 6410.88 | E7: 705278.46 | F7: подписано | I7: На внутрішньому погодженні | J7: заповнюємо колонку зауваження до ССДЦ якщо є і на кому затримка в погодженні
A8: ДУ №1 до № 19/07/2024 | B8: Временные дороги | C8: =E8-D8 -> 1349448.1 | D8: 1422704.5 | E8: 2772152.6 | F8: подписано | I8: Подано на Замовника | J8: заповнюємо колонку коли замовник обіцяє погодити, зауваження якщо є
A9: ДУ №2 до №19/07/2024 | B9: Планування території (земляні роботи та влаштування паркану) | C9: =E9-D9 -> 165933.8 | D9: 110802.61 | E9: 276736.41 | F9: На подписи у Директора | G9: 45553 | H9: Оплата по авансам согласно договора планируеться в пятницу на слудующую неделю(вт или чт),согласно счета фактуры поданой до четверга | I9: Погоджено Замовником | J9: заповнюємо колонку коментарі з датою коли буде оригінал
B10: Подготовительные работы (ППР) | C10: =E10-D10 -> 388830.76 | D10: 236042.45 | E10: 624873.21 | F10: на согласовании у Заказчика после корректировки замечаний | G10: 45554 | H10: Согласование договоров:после принципиального согласования юрид отделами заказчика и подрядчика,договор отсылаеться на представителя заказчика(Москалев).2)Москалев загружает в программу согласований.3)Согласовуеться 2-3дня финансистами,бухгалтерией и юристами Филиала Глобино.4)Согласовуеться 2-3дня финансистами,бухгалтерией и юристами Филиала Киев.4)Согласовывает служба СБ.5)Согласовывает Директора | I10: Оригінал в офісі | J10: не заповнюємо колонку коментарі
A11: Рахунок | B11: Доп. Работы | C11: =E11 -> 30193.73 | D11: 0 | E11: 30193.73 | F11: на подписи у директора АВР
B12: ВСЬОГО: | C12: =SUM(C5:C11) -> 9775362 | D12: =SUM(D5:D11) -> 13224496 | E12: =SUM(E5:E11) -> 22999858

Sheet РеєстрАВР
A1: Реєстр актів виконаних робіт по об'єкту ""комплекс підготовчих робіт та монтаж пальового поля для будівництва об’єкту: «Нове будівництво заводу з переробки соєвого шроту продуктивністю 500т/добу за адресою: вул. Володимирівська, 65-Д, м. Глобине, Кременчуцький район, Полтавська область»""
K2: *********Вимоги
A3: № ДЦ | B3: Найменування договірної ціни | C3: Всього по ДЦ з ПДВ, грн | D3: АКТИ | J3: Коментарі | K3: Для заповнення колонки статус | U3: Для заповнення колонки коментарі
D4: № акта | E4: Всього, грн з ПДВ | F4: Матеріали з ПДВ, грн | G4: Роботи з ПДВ, грн | H4: Статус | I4: Дата | K4: Варіанти статусу | L4: Об'єми подані в ВТВ для КБ6 | M4: Погодження КБ6 технаглядом | N4: АВР підписаний діректором Індастріалбуд | O4: АВР та рахунок відправлений на підпис Астарта | P4: АВР підписаний технаглядом | Q4: АВР підписаний директором замовника | R4: Орігінал АВР в офісі | S4: Оплата по АВР | T4: Списання М29 | U4: Побажання до коментарів (основне)
A5: №1 | B5: Підготовчі роботи та монтаж пальового поля (Договір №14/06/2024) | C5: 18590623 | D5: №1 | E5: 728783.74 | F5: =186569.78*1.2 -> 223883.74 | G5: =420750*1.2 -> 504900 | H5: Оригинал в офисе | J5: оплачено | K5: АВР у відділі ВТВ | L5: + | M5: + | N5: + | O5: + | P5: + | Q5: + | R5: + | S5: 727783.74 | T5: + | U5: заповнюємо колонку коментарі з датами коли отримали об'єми і коли відправите акт, або коли АВР планується і маєте отримати дані
D6: №2 | E6: 1941984 | F6: 0 | G6: =E6 -> 1941984 | H6: Оригинал в офисе | J6: оплачено | K6: Подано на Замовника | L6: + | M6: + | N6: + | O6: + | P6: + | Q6: + | R6: + | S6: =E6 -> 1941984 | T6: + | U6: заповнюємо колонку коментарі з датою коли замовник обіцяє перевірити і в разі питань пишете які є, не важливо стосовно розцінок чи супутньої документації (основне)
D7: №3 | E7: 1131739.1 | F7: 997219.1 | G7: =E7-F7 -> 134520.02 | H7: Оригинал в офисе (подписан без даты) | K7: Погоджено Замовником | L7: + | M7: + | N7: + | O7: + | P7: + | Q7: + | R7: + | T7: + | U7: заповнюємо колонку коментарі з датою коли буде оригінал
D8: №4 | E8: 2437104.3 | F8: 1992504.3 | G8: =E8-F8 -> 444600 | H8: Оригинал в офисе (подписан без даты) | L8: + | M8: + | N8: + | O8: + | P8: + | Q8: + | R8: + | T8: + | U8: Після подачи рахунку до п'ятниці,планується оплата на наступному тижні вівторок,четвер
D9: №5 | E9: ='[1]АВР №3'!$F$31 -> 2917816.8 | F9: 2747273 | G9: 170544 | H9: Оригинал в офисе (подписан без даты) | L9: + | M9: + | N9: + | O9: + | P9: + | Q9: + | R9: + | T9: +
D10: №6 | E10: 2603926.9 | F10: =943299.09*1.2 -> 1131958.9 | G10: =1226640*1.2 -> 1471968 | H10: Оригинал в офисе (подписан без даты) | L10: + | M10: + | N10: + | O10: + | P10: + | Q10: + | R10: + | T10: +
D11: №7 | E11: 2571099.5 | F11: =1733322.96*1.2 -> 2079987.6 | G11: =E11-F11 -> 491112 | H11: Оригинал в офисе (подписан без даты) | L11: + | M11: + | N11: + | O11: + | P11: + | Q11: + | R11: + | T11: +
D12: №8 | E12: 3356872.5 | F12: 2199544.5 | G12: =E12-F12 -> 1157328 | H12: Оригинал в офисе (подписан без даты) | L12: + | M12: + | N12: + | O12: + | P12: + | Q12: + | R12: + | T12: +
D13: №9 | E13: 291840 | G13: =E13 -> 291840 | H13: подписано
B14: Підготовчі роботи та монтаж пальового поля (Договір № 19/07/2024) | C14: 705278.46 | D14: №1 | E14: 500621.1 | F14: 0 | G14: =E14 -> 500621.1 | H14: Оригинал в офисе | J14: оплачено | K14: Оригінал | L14: + | M14: + | N14: + | O14: + | P14: + | Q14: + | R14: + | S14: =E14 -> 500621.1 | T14: + | U14: списання так/ні
D15: №2 | E15: 166743.25 | F15: =4712.4*1.2 -> 5654.88 | G15: =E15-F15 -> 161088.37 | H15: Оригинал в офисе | J15: оплачено | L15: + | M15: + | N15: + | O15: + | P15: + | Q15: + | R15: + | T15: +
D16: №3 | E16: 34908.25 | G16: =E16 -> 34908.25 | H16: подписано
B17: влаштування тимчасових доріг (ДУ №1 до договору 19.07.2024) | C17: 2772152.4 | D17: №1 | E17: 1281386.9 | F17: 639618.88 | G17: =E17-F17 -> 641768 | H17: после подписания будет отправлен на Заказчика
B18: АВР по рахунку | C18: =E18 -> 30193.728 | D18: №1 | E18: 30193.728 | G18: =E18 -> 30193.728 | H18: на подписи у директора | L18: + | M18: + | N18: + | O18: + | P18: +
B19: ВСЬОГО: | C19: =SUM(C5:C18) -> 22098248 | E19: =SUM(E5:E18) -> 19995020 | F19: =SUM(F5:F18) -> 12017645 | G19: =SUM(G5:G18) -> 7977375.5
C20: =SUBTOTAL(9,C5:C18) -> 22098248 | E20: =SUBTOTAL(9,E5:E18) -> 19995020 | F20: =SUBTOTAL(9,F5:F18) -> 12017645 | G20: =SUBTOTAL(9,G5:G18) -> 7977375.5

Sheet 10 акт переносится
A2: Реєстр актів виконаних робіт по об'єкту "Ладижин -2"
A4: Акт №1 | B4: Вид робіт (витрат) | C4: Договірна ціна | E4: Зміст актів виконаних робіт | F4: Управлінський облік 2021 р. | Y4: Всього управлінський облік | AB4: ТОВ "ІНДАСТРІАЛБУД"
F5: квітень 2021 р. | H5: травень 2021 р. | J5: червень 2021 р. | L5: липень 2021 р. | N5: серпень 2021 р. | P5: вересень 2021 р. | R5: жовтень 2021 р.
C6: № ДЦ | D6: Сумма ДЦ | F6: № акта | G6: сума, грн з ПДВ | H6: № акта | I6: сума, грн з ПДВ | J6: № акта | K6: сума, грн з ПДВ | L6: № акта | M6: сума, грн з ПДВ | N6: № акта | O6: сума, грн з ПДВ | P6: № акта | Q6: сума, грн з ПДВ | R6: № акта | S6: сума, грн з ПДВ | T6: № акта | U6: сума, грн з ПДВ | V6: № акта | W6: сума, грн з ПДВ | Y6: № акта | Z6: сума, грн з ПДВ | AA6: загальна сума | AB6: всього | AC6: робота | AD6: мат-ли
A7: 1 | B7: 2 | C7: 3 | D7: 4 | E7: 5 | F7: 8 | G7: 9 | Y7: 10 | Z7: 11 | AA7: 12 | AB7: 19 | AC7: 20 | AD7: 21
A8: 1 | B8: Будівництво каркасу оліє-пресового цеху №2 з трансформаторною підстанцією, м.Ладижин, Вінницька область | C8: №1 | D8: 9670800 | E8: земля та фундаменти 7.1-7.9, 12.1-12.3 | F8: №1 | G8: =288379.22 -> 288379.22 | Y8: 1 | Z8: 288379.22 | AA8: =SUM(AB8:AB22) -> 8579031.9 | AB8: 288379.22 | AC8: 279386.06 | AD8: 8993.16
E9: земля 10.6, 10.12 | F9: №2 | G9: 193609.49 | Y9: 2 | Z9: 193609.49 | AB9: 193609.49 | AC9: 193609.49 | AD9: 0
E10: земля, фундаменти 7.1-7.9, 12.1-12.3 | H10: №3 | I10: 266283.61 | Y10: 3 | Z10: 266283.61 | AB10: 266283.61 | AC10: 256961.43 | AD10: 9322.176
E11: земля 8.1-8.4 | H11: №4 | I11: 1054954.1 | Y11: 4 | Z11: 1054954.1 | AB11: =Z11 -> 1054954.1 | AC11: 1043855.2 | AD11: 11098.87
E12: земля, фундаменти 16.2 | J12: №5 | K12: 70786.21 | Y12: 5 | Z12: 70786.21 | AB12: 70786.21 | AC12: 68044.39 | AD12: 2741.82
J13: №6 | K13: 862817.57 | Y13: 6 | Z13: 862817.57 | AB13: 862817.57 | AC13: 805192.25 | AD13: 57625.32
J14: №7 | K14: 291462.71 | Y14: 7 | Z14: 291462.71 | AB14: 291462.71 | AC14: 280166.43 | AD14: 11296.28
J15: №8 | K15: 449187.01 | Y15: 8 | Z15: =K15 -> 449187.01 | AB15: =Z15 -> 449187.01 | AC15: 439722.83 | AD15: 9464.18
J16: №9 | K16: 603287.62 | Y16: 9 | Z16: 603287.62 | AB16: 603287.62 | AC16: 595984.13 | AD16: 7303.49
E17: земля, фунд.7.1-7.9, 8.1-8.4, з/б 16.2 | L17: №10 | M17: 941673.71 | Y17: 10 | Z17: =M17 -> 941673.71 | AB17: =Z17 -> 941673.71 | AC17: =AB17-AD17 -> 921997.47 | AD17: 19676.244
E18: земля, щеб., арм.7.1-7.9, 8.1-8.4, з/б 16.2 | L18: №11 | M18: =Z18 -> 293363.47 | Y18: 11 | Z18: 293363.47 | AB18: =Z18 -> 293363.47 | AC18: 290271.42 | AD18: 3092.05
E19: бет.подг., фунд, гідроіз.7.1-7-9,8.1-8.4,16.2 | L19: №12 | M19: 372983.72 | Y19: 12 | Z19: =M19 -> 372983.72 | AB19: =Z19 -> 372983.72 | AC19: 368468.62 | AD19: 4515.1
E20: земля, фунд.7.1-7.9, 8.1-8.4, м/к 16.2 | N20: №13 | O20: 354144.6 | Y20: №13 | Z20: 354144.6 | AB20: 354144.6 | AC20: =Z20-AD20 -> 349857.55 | AD20: 4287.05
E21: перевез, засипка, ущільн 7.1-7.9, 12.1-12.3 | N21: №14 | O21: 177987.94 | Y21: №14 | Z21: =O21 -> 177987.94 | AB21: 177987.94 | AC21: =AB21-AD21 -> 160077.57 | AD21: 17910.37
E22: фундаменти зерносушарки | P22: №15 | Q22: 2358110.9 | Y22: №15 | Z22: =Q22 -> 2358110.9 | AB22: =Z22 -> 2358110.9 | AC22: 1910403.6 | AD22: 447707.33
Y23: всего | Z23: =SUM(Z8:Z22) -> 8579031.9 | AB23: =SUM(AB8:AB22) -> 8579031.9 | AC23: =SUM(AC8:AC22) -> 7963998.4 | AD23: =SUM(AD8:AD22) -> 615033.44
A25: 2 | B25: ДУ 2 від 19.02.2021 Влаштування шпильок під балки покриття ОПЦ №2 | C25: ДУ 2 | D25: 281803.98 | P25: №1 | Q25: 281803.98 | Y25: №1 | Z25: 281803.98 | AA25: =SUM(AB25:AB26) -> 281803.98 | AB25: =AC25+AD25 -> 281803.98 | AC25: =Z25-AD25 -> 251804.03 | AD25: 29999.95
A27: 3 | B27: Додаткові роботи по монтажу/демонтажу з/б балок каркасу, згідно дефектного акту №1 | D27: 131336.26 | H27: №1 | I27: 110363.99 | Y27: 1 | Z27: =I27 -> 110363.99 | AA27: =AB27 -> 110363.99 | AB27: =I27 -> 110363.99 | AC27: =AB27-AD27 -> 85118.37 | AD27: 25245.62
A30: =A8+1 -> 2 | B30: Влаштування фундаментів допоміжних споруд оліє-пресового цеху по переробці насіння соняшника 1200т/добу №396-10 від 23.03.2021 ДУ 1 | C30: №2 | D30: =#REF! -> #REF! | E30: земля, фундаменти ПРм1 9.5-9.6 | H30: №1 | I30: 111154.22 | Y30: №1 | Z30: 111154.22 | AA30: =SUM(AB30:AB44) -> 2293462.3 | AB30: 111154.22 | AC30: =AB30-AD30 -> 44105.48 | AD30: =55873.95*1.2 -> 67048.74
E31: земля, фундаменти ПРм1 9.7-9.8 | J31: №2 | K31: 99020.51 | Y31: №2 | Z31: =K31 -> 99020.51 | AB31: =K31 -> 99020.51 | AC31: 53748.15 | AD31: 45272.36
J32: №3 | K32: 345752.57 | Y32: №3 | Z32: 345752.57 | AB32: 345752.57 | AC32: 231533.51 | AD32: 114219.06
J33: №4 | K33: 103230.59 | V33: =D30-Z45 -> #REF! | Y33: №4 | Z33: 103230.59 | AB33: 103230.59 | AC33: 30347.27 | AD33: 72883.32
J34: №5 | K34: 58541.36 | Y34: №5 | Z34: 58541.36 | AB34: 58541.36 | AC34: 33049.98 | AD34: 25491.38
L35: №6 | M35: 20510.87 | Y35: №6 | Z35: 20510.87 | AB35: 20510.87 | AC35: =Z35-AD35 -> 19006.322 | AD35: 1504.548
L36: №7 | M36: =Z36 -> 112396.12 | Y36: №7 | Z36: 112396.12 | AB36: =Z36 -> 112396.12 | AC36: 57471.424 | AD36: 54924.696
L37: №8 | M37: 36533.03 | Y37: №8 | Z37: =M37 -> 36533.03 | AB37: =Z37 -> 36533.03 | AC37: 32587.68 | AD37: 3945.35
L38: №9 | M38: 282807.74 | Y38: №9 | Z38: =M38 -> 282807.74 | AB38: =Z38 -> 282807.74 | AC38: =AB38-AD38 -> 157013.31 | AD38: 125794.43
R39: №10 | S39: 236670.38 | W39: ВО 27 | X39: =Z39+Z43+Z44 -> 596567.15 | Y39: №10 | Z39: 236670.38 | AB39: 236670.38 | AC39: =AB39-AD39 -> 135826.63 | AD39: 100843.75
R40: №11 | S40: 78675.94 | W40: ВО 24 | X40: =X39+'Реєстр ДЦ '!#REF!+'Реєстр ДЦ '!#REF!+'Реєстр ДЦ '!#REF!+'Реєстр ДЦ '!#REF! -> #REF! | Y40: №11 | Z40: 78675.94 | AB40: 78675.94 | AC40: =AB40-AD40 -> 32607.32 | AD40: 46068.62
R41: №12 | S41: 83218.66 | W41: ВО 23 | Y41: №12 | Z41: 75489.29 | AB41: =Z41 -> 75489.29 | AC41: =AB41-AD41 -> 31514.7 | AD41: 43974.59
R42: №13 | S42: =Z42 -> 372782.87 | W42: ВО 25 | Y42: №13 | Z42: 372782.87 | AB42: =Z42 -> 372782.87 | AC42: =AB42-AD42 -> 152785.19 | AD42: 219997.68
R43: №14 | S43: 328788.29 | W43: ВО 26 | Y43: №14 | Z43: 356228.86 | AB43: =Z43 -> 356228.86 | AC43: =AB43-AD43 -> 201417.04 | AD43: 154811.82
R44: №15 | S44: 12657.74 | W44: ВО 22 | Y44: №15 | Z44: 3667.91 | AB44: =Z44 -> 3667.91 | AC44: =AB44-AD44 -> 2114.51 | AD44: 1553.4
Y45: всего | Z45: =SUM(Z30:Z44) -> 2293462.3 | AB45: =SUM(AB30:AB44) -> 2293462.3 | AC45: =SUM(AC30:AC40) -> 827297.08 | AD45: =AB45-AC45 -> 1466165.2
A47: 3 | B47: Виготовлення і монтаж металоконструкцій ТХ | C47: №3 | D47: 1540968 | N47: №1 | O47: 248026.63 | Y47: №1 | Z47: 248026.63 | AA47: =SUM(AB47:AB51) -> 672881.95 | AB47: 248026.63 | AC47: =Z47-AD47 -> 242763.11 | AD47: 5263.52
...

Sheet материал Ладижин
A2: АВР "Ладижин -2"
D3: МАТЕРІАЛИ
A4: п/п | B4: ДОГОВІР | C4: № акта | D4: БЕЗ ПДВ | E4: З ПДВ
A5: 1 | B5: Будівництво каркасу оліє-пресового цеху №2 з трансформаторною підстанцією, м.Ладижин, Вінницька область №389-10 від 19.02.2021 | C5: №1 | D5: 7494.3 | E5: =D5*1.2 -> 8993.16
C6: №2 | D6: 23.05 | E6: =D6*1.2 -> 27.66
C7: №3 | D7: 7768.48 | E7: =D7*1.2 -> 9322.176
C8: №4 | D8: 9249.06 | E8: =D8*1.2 -> 11098.872
C9: №5 | D9: 2284.84 | E9: =D9*1.2 -> 2741.808
C10: №6 | D10: 48021.11 | E10: =D10*1.2 -> 57625.332
C11: №7 | D11: 9413.57 | E11: =D11*1.2 -> 11296.284
C12: №8 | D12: 7886.82 | E12: =D12*1.2 -> 9464.184
C13: №9 | D13: 6086.26 | E13: =D13*1.2 -> 7303.512
C14: №10 | D14: 16396.86 | E14: =D14*1.2 -> 19676.232
C15: №11 | D15: 2576.71 | E15: =D15*1.2 -> 3092.052
C16: №12 | D16: 3762.57 | E16: =D16*1.2 -> 4515.084
C17: №13 | D17: 3572.55 | E17: =D17*1.2 -> 4287.06
... C19: №15 | D19: 373089.66 | E19: =D19*1.2 -> 447707.59
C20: всего | E20: =SUM(E5:E19) -> 615061.38
A21: 2 | B21: ДУ 2 від 19.02.2021 Влаштування шпильок під балки покриття ОПЦ №2 №389-10 від 19.02.2021 ДУ 2 від 19.02.2021 | C21: №1 | D21: 24999.96 | E21: =D21*1.2 -> 29999.952
A22: 3 | B22: Додаткові роботи по монтажу/демонтажу з/б балок каркасу, згідно дефектного акту №1 Д/У№1 до дог. №389-10 від 19.02.2021 | C22: №1 | D22: 21038.02 | E22: =D22*1.2 -> 25245.624
A23: =A5+1 -> 2 | B23: Влаштування фундаментів допоміжних споруд оліє-пресового цеху по переробці насіння соняшника 1200т/добу №396-10 від 23.03.2021 ДУ 1 | C23: №1 | D23: 55874.91 | E23: =D23*1.2 -> 67049.892
C24: №2 | D24: 37726.97 | E24: =D24*1.2 -> 45272.364
C25: №3 | D25: 95182.55 | E25: =D25*1.2 -> 114219.06
C26: №4 | D26: 60736.1 | E26: =D26*1.2 -> 72883.32
C27: №5 | D27: 21242.81 | E27: =D27*1.2 -> 25491.372
C28: №6 | D28: 1253.78 | E28: =D28*1.2 -> 1504.536
C29: №7 | D29: 45770.58 | E29: =D29*1.2 -> 54924.696
C30: №8 | D30: 3287.79 | E30: =D30*1.2 -> 3945.348
C31: №9 | D31: 104828.68 | E31: =D31*1.2 -> 125794.42
C32: №10 | D32: 38390.54 | E32: =D32*1.2 -> 46068.648
C33: №11 | D33: 33164.52 | E33: =D33*1.2 -> 39797.424
C34: №12 | D34: 171056.73 | E34: =D34*1.2 -> 205268.08
C35: №13 | D35: 59510.96 | E35: =D35*1.2 -> 71413.152
... C41: №19 | D41: 766.9 | E41: =D41*1.2 -> 920.28
C42: всего | E42: =SUM(E23:E41) -> 1193453.6
A43: 3 | B43: Виготовлення і монтаж металоконструкцій ТХ №406-10 від 02.06.2021 | C43: №1 | D43: 4386.25 | E43: =D43*1.2 -> 5263.5
C44: №2 | D44: 4018.36 | E44: =D44*1.2 -> 4822.032
C45: №3 | D45: 3494.95 | E45: =D45*1.2 -> 4193.94
C46: №4 | D46: 3400.86 | E46: =D46*1.2 -> 4081.032
C47: всего | E47: =SUM(E43:E46) -> 18360.504
...

Sheet Пожарка подрядчик
A1: РЕЄСТР ДОГОВІРНИХ ЦІН
A3: № п/п | B3: Вид робіт (витрат) | C3: ознака робіт | D3: Номер ДЦ | E3: Сумма | F3: Статус
A4: 1 | B4: Монтаж системи газ.пожежогасіння машинного приміщення ЛТПП секц.5 | C4: пожарка | D4: №1 | E4: 107970.18 | F4: погоджено
A5: =A4+1 -> 2 | B5: Монтаж системи контролю загазованості секц.5 | C5: пожарка | D5: №2 | E5: 38378.59 | F5: погоджено
A6: =A5+1 -> 3 | B6: Монтаж автоматичної системи оповіщення людей про пожежу секц.5 | C6: пожарка | D6: №3 | E6: 82852.78 | F6: погоджено
A7: =A6+1 -> 4 | B7: Монтаж системи автоматичної пожежної сигналізації секц.5 | C7: пожарка | D7: №4 | E7: 979787.02 | F7: погоджено
A8: =A7+1 -> 5 | B8: Монтаж системи автоматизації протидимного захисту секц.5 | C8: пожарка | D8: №5 | E8: 565478.29 | F8: погоджено
A9: =A8+1 -> 6 | B9: Монтаж системи димовидалення (технологічна частина) секц.5 | C9: пожарка | D9: №6 | E9: 573308.27 | F9: погоджено
A10: =A9+1 -> 7 | B10: Монтаж системи димовидалення (технологічна частина) секц.5 (дод.роботи) | C10: пожарка | D10: №7 | E10: 88842.36 | F10: погоджено
A11: =A10+1 -> 8 | B11: Монтаж системи автоматизації протидимного захисту секц.6 | C11: пожарка | D11: №12 | E11: 589296.65 | F11: погоджено
A12: =A11+1 -> 9 | B12: Монтаж автоматичної системи оповіщення людей про пожежу секц.6 | C12: пожарка | D12: №10 | E12: 100485.89 | F12: погоджено
A13: =A12+1 -> 10 | B13: Монтаж системи газ.пожежогасіння машинного приміщення ЛТПП секц.6 | C13: пожарка | D13: №8 | E13: 107970.18 | F13: погоджено
A14: =A13+1 -> 11 | B14: Монтаж системи контролю загазованості секц.6 | C14: пожарка | D14: №9 | E14: 55788.36 | F14: погоджено
A15: =A14+1 -> 12 | B15: Монтаж системи автоматичної пожежної сигналізації секц.6 | C15: пожарка | D15: №11 | E15: 1129114.1 | F15: погоджено
A16: =A15+1 -> 13 | B16: Монтаж системи димовидалення (технологічна частина) секц.6 | C16: пожарка | D16: №13 | E16: 542099.16 | F16: погоджено
A17: =A16+1 -> 14 | B17: Монтаж системи димовидалення (технологічна частина) секц.6 (дод.роботи) | C17: пожарка | D17: №14 | E17: 91400.04 | F17: погоджено
B18: ВСЬОГО | E18: =SUBTOTAL(109,E4:E17) -> 5052771.8

Sheet Лист1
