Workbook
Name Excel_BuiltIn_Print_Area_4: "#REF!"
Name Excel_BuiltIn_Print_Area_4_1: "#REF!"
Name Excel_BuiltIn_Print_Area_7: "#REF!"
Name Excel_BuiltIn_Print_Area_7_1: "#REF!"
Name Механизаторі: МЕХАНИЗАТОРЫ!#REF!
Name Механизаторы: МЕХАНИЗАТОРЫ!#REF!
Name Объекты: [1]Объекты!$B$2:$B$12
Name Объекты: [2]Объекты!$B$2:$B$12

Sheet Июнь 2024 
A1: Наименование | B1: Отчетный период | C1: Остаток на начало | D1: Топливо заправленное | E1: Остаток на конец | F1: Расход топлива за период | G1: Моточасы на начало | H1: Моточасы на конец | I1: Разница | J1: Перегон на доругой объект, л | K1: Перегон на доругой объект, км | L1: Часы работы на обьекте | M1: Норма на 1 мото час | N1: Факт витрат на 1 мото/год, км витрат (л/год) | O1: PL план , грн | P1: PL факт , грн | Q1: Diff, грн
A2: Телескоп 1 | B2: 45444 | C2: ='[3]Май 2024 '!E2 -> 80 | D2: =SUMIF($A$30:$A$99,A2,$B$30:$B$99) -> 0 | E2: 80 | F2: =C2+D2-E2 -> 0 | G2: ='[3]Май 2024 '!H2 -> 14075 | H2: 14075 | I2: =H2-G2 -> 0 | J2: 0 | L2: 0 | M2: =VLOOKUP(A2,[3]Тарас!$C$4:$P$23,14,0) -> 3.4 | O2: =194.94*I2 -> 0 | P2: =F2*$K$25 -> 0 | Q2: =O2-P2 -> 0
A3: Телескоп 2 | B3: 45444 | C3: ='[3]Май 2024 '!E3 -> 110 | D3: =SUMIF($A$30:$A$99,A3,$B$30:$B$99) -> 500 | E3: 120 | F3: =C3+D3-E3 -> 490 | G3: ='[3]Май 2024 '!H3 -> 10563 | H3: 10647 | I3: =H3-G3 -> 84 | J3: 0 | L3: 191 | M3: =VLOOKUP(A3,[3]Тарас!$C$4:$P$23,14,0) -> 3.4 | N3: =F3/I3 -> 5.8333333 | O3: =194.94*I3 -> 16374.96 | P3: =F3*$K$25 -> 26100.364 | Q3: =O3-P3 -> -9725.4036
A4: Телескоп JCB 533-105 (№3) | B4: 45444 | C4: ='[3]Май 2024 '!E4 -> 0 | D4: =SUMIF($A$30:$A$99,A4,$B$30:$B$99) -> 0 | F4: =C4+D4-E4 -> 0 | G4: ='[3]Май 2024 '!H4 -> #N/A | J4: 0 | M4: =VLOOKUP(A4,[3]Тарас!$C$4:$P$23,14,0) -> #N/A | N4: =F4/I4 -> #DIV/0! | O4: =194.94*I4 -> 0 | P4: =F4*$K$25 -> 0 | Q4: =O4-P4 -> 0
A5: Телескоп JCB 535-140 (№4) | B5: 45444 | C5: ='[3]Май 2024 '!E5 -> 60 | D5: =SUMIF($A$30:$A$99,A5,$B$30:$B$99) -> 600 | E5: 110 | F5: =C5+D5-E5 -> 550 | G5: ='[3]Май 2024 '!H5 -> 9096 | H5: 9280 | I5: =H5-G5 -> 184 | J5: 0 | L5: 210 | M5: =VLOOKUP(A5,[3]Тарас!$C$4:$P$23,14,0) -> 3.4 | N5: =F5/I5 -> 2.9891304 | O5: =194.94*I5 -> 35868.96 | P5: =F5*$K$25 -> 29296.326 | Q5: =O5-P5 -> 6572.6335
A6: Телескоп JCB 540-170 №5 | B6: 45444 | C6: ='[3]Май 2024 '!E6 -> 110 | D6: =SUMIF($A$30:$A$99,A6,$B$30:$B$99) -> 0 | E6: 60 | F6: =C6+D6-E6 -> 50 | G6: ='[3]Май 2024 '!H6 -> 0 | H6: 0 | I6: =L6*0.53 -> 2.65 | J6: 0 | L6: 5 | M6: =VLOOKUP(A6,[3]Тарас!$C$4:$P$23,14,0) -> 3.4 | N6: =F6/I6 -> 18.867925 | O6: =194.94*I6 -> 516.591 | P6: =F6*$K$25 -> 2663.3024 | Q6: =O6-P6 -> -2146.7114
A7: Виброкаток | B7: 45444 | C7: ='[3]Май 2024 '!E7 -> 90 | D7: =SUMIF($A$30:$A$99,A7,$B$30:$B$99) -> 100 | E7: 85 | F7: =C7+D7-E7 -> 105 | G7: ='[3]Май 2024 '!H7 -> 4934 | H7: 4948 | I7: =H7-G7 -> 14 | J7: 0 | L7: 66 | M7: =VLOOKUP(A7,[3]Тарас!$C$4:$P$23,14,0) -> 5 | N7: =F7/I7 -> 7.5 | O7: =285*I7 -> 3990 | P7: =F7*$K$25 -> 5592.9351 | Q7: =O7-P7 -> -1602.9351
A8: Ротор Пегасус | B8: 45444 | C8: ='[3]Май 2024 '!E8 -> 0 | D8: =SUMIF($A$30:$A$99,A8,$B$30:$B$99) -> 0 | F8: =C8+D8-E8 -> 0 | G8: ='[3]Май 2024 '!H8 -> 0 | I8: =H8-G8 -> 0 | J8: 0 | M8: =VLOOKUP(A8,[3]Тарас!$C$4:$P$23,14,0) -> #N/A | N8: =F8/I8 -> #DIV/0! | P8: =F8*$K$25 -> 0 | Q8: =O8-P8 -> 0
A9: Экскаватор JCB | B9: 45444 | C9: ='[3]Май 2024 '!E9 -> 90 | D9: =SUMIF($A$30:$A$99,A9,$B$30:$B$99) -> 695.86 | E9: 70 | F9: =C9+D9-E9 -> 715.86 | G9: ='[3]Май 2024 '!H9 -> 17188 | H9: 17307 | I9: =H9-G9 -> 119 | J9: 0 | L9: 152 | M9: =VLOOKUP(A9,[3]Тарас!$C$4:$P$23,14,0) -> 4.1 | N9: =F9/I9 -> 6.0156303 | O9: =235.41*I9 -> 28013.79 | P9: =F9*$K$25 -> 38131.033 | Q9: =O9-P9 -> -10117.243
A10: Экскаватор JCB 3CX 2008 | B10: 45444 | C10: ='[3]Май 2024 '!E10 -> 20 | D10: =SUMIF($A$30:$A$99,A10,$B$30:$B$99) -> 200 | E10: 20 | F10: =C10+D10-E10 -> 200 | G10: ='[3]Май 2024 '!H10 -> 3915 | H10: 39553 | I10: =H10-G10 -> 35638 | J10: 0 | L10: 113 | M10: =VLOOKUP(A10,[3]Тарас!$C$4:$P$23,14,0) -> 4.1 | N10: =F10/I10 -> 0.0056119872 | O10: =235.41*I10 -> 8389541.6 | P10: =F10*$K$25 -> 10653.21 | Q10: =O10-P10 -> 8378888.4
A11: Экскаватор JCB 2013 | B11: 45444 | C11: ='[3]Май 2024 '!E11 -> 10 | D11: =SUMIF($A$30:$A$99,A11,$B$30:$B$99) -> 800 | E11: 10 | F11: =C11+D11-E11 -> 800 | G11: ='[3]Май 2024 '!H11 -> 11698 | H11: 11904 | I11: =H11-G11 -> 206 | J11: 0 | L11: 193 | M11: =VLOOKUP(A11,[3]Тарас!$C$4:$P$23,14,0) -> 4.1 | N11: =F11/I11 -> 3.8834951 | O11: =235.41*I11 -> 48494.46 | P11: =F11*$K$25 -> 42612.839 | Q11: =O11-P11 -> 5881.6215
A12: Экскаватор JCB 220 | B12: 45444 | C12: ='[3]Май 2024 '!E12 -> 169 | D12: =SUMIF($A$30:$A$99,A12,$B$30:$B$99) -> 100 | E12: 80 | F12: =C12+D12-E12 -> 189 | G12: ='[3]Май 2024 '!H12 -> 7064 | H12: 7096 | I12: =H12-G12 -> 32 | J12: 0 | L12: 10 | M12: =VLOOKUP(A12,[3]Тарас!$C$4:$P$23,14,0) -> 10.5 | N12: =F12/I12 -> 5.90625 | O12: =595.65*I12 -> 19060.8 | P12: =F12*$K$25 -> 10067.283 | Q12: =O12-P12 -> 8993.5169
A13: МАЗ 264 | B13: 45444 | C13: ='[3]Май 2024 '!E13 -> 150 | D13: =SUMIF($A$30:$A$99,A13,$B$30:$B$99) -> 537.12 | E13: 40 | F13: =C13+D13-E13 -> 647.12 | G13: ='[3]Май 2024 '!H13 -> 30838 | H13: 31643 | I13: =H13-G13 -> 805 | J13: 0 | K13: 260 | L13: 194 | M13: =VLOOKUP(A13,[3]Тарас!$C$4:$P$23,14,0) -> 0.9 | N13: =F13/I13 -> 0.80387578 | O13: =(51.3*(I13-K13))+(K13*14.25) -> 31663.5 | P13: =F13*$K$25 -> 34469.525 | Q13: =O13-P13 -> -2806.0251
A14: МАЗ 265 | B14: 45444 | C14: ='[3]Май 2024 '!E14 -> 120 | D14: =SUMIF($A$30:$A$99,A14,$B$30:$B$99) -> 459.42 | E14: 140 | F14: =C14+D14-E14 -> 439.42 | G14: ='[3]Май 2024 '!H14 -> 34272 | H14: 34719 | I14: =H14-G14 -> 447 | J14: 0 | K14: 320 | L14: 81 | M14: =VLOOKUP(A14,[3]Тарас!$C$4:$P$23,14,0) -> 0.9 | N14: =F14/I14 -> 0.98304251 | O14: =(51.3*(I14-K14))+(K14*14.25) -> 11075.1 | P14: =F14*$K$25 -> 23406.167 | Q14: =O14-P14 -> -12331.067
A15: Самосвал Камаз | B15: 45444 | C15: ='[3]Май 2024 '!E15 -> 229 | D15: =SUMIF($A$30:$A$99,A15,$B$30:$B$99) -> 129.65 | E15: 130 | F15: =C15+D15-E15 -> 228.65 | G15: ='[3]Май 2024 '!H15 -> 559189 | H15: 559553 | I15: =H15-G15 -> 364 | J15: 0 | L15: 76 | M15: =VLOOKUP(A15,[3]Тарас!$C$4:$P$23,14,0) -> 0.9 | N15: =F15/I15 -> 0.62815934 | O15: =(51.3*(I15-K15))+(K15*19.85) -> 18673.2 | P15: =F15*$K$25 -> 12179.282 | Q15: =O15-P15 -> 6493.9181
A16: Самосвал МАЗ | B16: 45444 | C16: ='[3]Май 2024 '!E16 -> 143 | D16: =SUMIF($A$30:$A$99,A16,$B$30:$B$99) -> 179.71 | E16: 240 | F16: =C16+D16-E16 -> 82.71 | G16: ='[3]Май 2024 '!H16 -> 64107 | H16: 64160 | I16: =H16-G16 -> 53 | J16: 0 | L16: 22 | M16: =VLOOKUP(A16,[3]Тарас!$C$4:$P$23,14,0) -> 0.9 | N16: =F16/I16 -> 1.560566 | O16: =(51.3*(I16-K16)) -> 2718.9 | P16: =F16*$K$25 -> 4405.6348 | Q16: =O16-P16 -> -1686.7348
A17: РДК 250 | B17: 45444 | C17: ='[3]Май 2024 '!E17 -> 0 | D17: =SUMIF($A$30:$A$99,A17,$B$30:$B$99) -> 0 | F17: =C17+D17-E17 -> 0 | G17: ='[3]Май 2024 '!H17 -> #N/A | I17: =H17-G17 -> #N/A | J17: 0 | M17: =VLOOKUP(A17,[3]Тарас!$C$4:$P$23,14,0) -> #N/A | N17: =F17/I17 -> #N/A | P17: =F17*$K$25 -> 0 | Q17: =O17-P17 -> 0
A18: Автокран XCMG 55 | B18: 45444 | C18: ='[3]Май 2024 '!E18 -> 130 | D18: =SUMIF($A$30:$A$99,A18,$B$30:$B$99) -> 400 | E18: 130 | F18: =C18+D18-E18 -> 400 | G18: ='[3]Май 2024 '!H18 -> 0 | H18: 0 | I18: =L18*0.7 -> 49.7 | J18: 0 | L18: 71 | M18: 5.1 | N18: =F18/I18 -> 8.0482897 | P18: =F18*$K$25 -> 21306.419 | Q18: =O18-P18 -> -21306.419
A19: Автокран XCMG | B19: 45444 | C19: ='[3]Май 2024 '!E19 -> 20 | D19: =SUMIF($A$30:$A$99,A19,$B$30:$B$99) -> 320 | E19: 100 | F19: =C19+D19-E19 -> 240 | G19: ='[3]Май 2024 '!H19 -> 5749 | H19: 5827 | I19: =H19-G19 -> 78 | J19: 0 | L19: 215 | M19: =VLOOKUP(A19,[3]Тарас!$C$4:$P$23,14,0) -> 3.2 | N19: =F19/I19 -> 3.0769231 | O19: =182.4*I19 -> 14227.2 | P19: =F19*$K$25 -> 12783.852 | Q19: =O19-P19 -> 1443.3484
A20: Автокран Клинцы | B20: 45444 | C20: ='[3]Май 2024 '!E20 -> 0 | D20: =SUMIF($A$30:$A$99,A20,$B$30:$B$99) -> 0 | F20: =C20+D20-E20 -> 0 | G20: ='[3]Май 2024 '!H20 -> 0 | I20: 0 | J20: 0 | N20: =VLOOKUP(A20,[3]Тарас!$C$4:$N$23,12,0) -> #N/A | O20: =194.94*I20 -> 0 | P20: =F20*$K$25 -> 0 | Q20: =O20-P20 -> 0
A21: Подъемник Haulotte №1 | B21: 45383 | C21: ='[3]Апрель 2024'!E21 -> 0 | D21: =SUMIF($A$30:$A$99,A21,$B$30:$B$99) -> 0 | F21: =C21+D21-E21 -> 0 | I21: 0 | J21: 0 | N21: =VLOOKUP(A21,[3]Тарас!$C$4:$N$23,12,0) -> #N/A | O21: =194.94*I21 -> 0 | P21: =F21*$K$25 -> 0 | Q21: =O21-P21 -> 0
C22: =SUM(C2:C21) -> 1531 | D22: =SUM(D2:D21) -> 5021.76 | E22: =SUM(E2:E21) -> 1415
C23: =C22='[3]Май 2024 '!E22 -> TRUE | D23: =D22-B100 -> 0
J25: Стоимость 1 л | K25: =SUM(C30:C99)/B100 -> 53.266048
A28: Заправки АЗС
A29: Наименование | B29: Количество | C29: Сумма | D29: АЗС
A30: Автокран XCMG | B30: 160 | C30: 8638.4 | D30: Амик
A31: Автокран XCMG | B31: 160 | C31: 8638.4 | D31: Амик
A32: Самосвал Камаз | B32: 129.65 | C32: 6999.8 | D32: Амик
A33: Экскаватор JCB 2013 | B33: 100 | C33: 5399 | D33: Амик
A34: Экскаватор JCB 2013 | B34: 100 | C34: 5399 | D34: Амик
A35: Экскаватор JCB 2013 | B35: 100 | C35: 5199 | D35: Амик
A36: Экскаватор JCB 2013 | B36: 100 | C36: 5399 | D36: Амик
A37: Экскаватор JCB 2013 | B37: 100 | C37: 5399 | D37: Амик
A38: Экскаватор JCB 2013 | B38: 100 | C38: 5199 | D38: Амик
A39: Экскаватор JCB 2013 | B39: 100 | C39: 5399 | D39: Амик
A40: Экскаватор JCB 2013 | B40: 100 | C40: 5299 | D40: Амик
A41: Телескоп JCB 535-140 (№4) | B41: 100 | C41: 5399 | D41: Амик
... A50: МАЗ 264 | B50: 37.12 | C50: 1929.87 | D50: Амик
A51: МАЗ 264 | B51: 100 | C51: 5299 | D51: Амик | E51: =SUM(C30:C51) -> 122388.47
...

Sheet Топливо Июль 2024.
A1: Наименование | B1: Отчетный период | C1: Остаток на начало | D1: Топливо заправленное | E1: Остаток на конец | F1: Расход топлива за период, л | G1: Моточасы на начало | H1: Моточасы на конец | I1: Отработано техникой моточасов | J1: Перегон на доругой объект, л | K1: Перегон на доругой объект, км | L1: Часы работы на обьекте | M1: Норма расхода топлива литр/1 мото час согласно сс | N1: Факт витрат на 1 мото/год, км витрат (л/год) | O1: PL план , грн | P1: PL факт , грн | Q1: Diff, грн | R1: Примечание по строке
A2: Телескоп 1 | B2: 45474 | C2: 80 | D2: =SUMIF($A$30:$A$112,A2,$B$30:$B$112) -> 0 | F2: =C2+D2-E2 -> 80 | G2: ='[4]Июнь 2024 '!H2 -> 14075 | I2: =H2-G2 -> -14075 | J2: 0 | L2: 0 | M2: =VLOOKUP(A2,[4]Тарас!$C$4:$P$23,14,0) -> 3.4 | O2: =194.94*I2 -> -2743780.5 | P2: =F2*$K$25 -> 4116.5561 | Q2: =O2-P2 -> -2747897.1
A3: Телескоп 2 | B3: 45474 | C3: 120 | D3: =SUMIF($A$30:$A$112,A3,$B$30:$B$112) -> 100 | E3: 40 | F3: =C3+D3-E3 -> 180 | G3: 10647 | H3: 10718 | I3: =H3-G3 -> 71 | J3: 0 | L3: 82 | M3: 3.4 | N3: =F3/I3 -> 2.5352113 | O3: =194.94*I3 -> 13840.74 | P3: =F3*$K$25 -> 9262.2512 | Q3: =O3-P3 -> 4578.4888
A4: Телескоп JCB 533-105 (№3) | B4: 45474 | C4: 0 | D4: =SUMIF($A$30:$A$112,A4,$B$30:$B$112) -> 0 | F4: =C4+D4-E4 -> 0 | G4: 0 | J4: 0 | M4: #N/A | N4: =F4/I4 -> #DIV/0! | O4: =194.94*I4 -> 0 | P4: =F4*$K$25 -> 0 | Q4: =O4-P4 -> 0
A5: Телескоп JCB 535-140 (№4) | B5: 45474 | C5: 110 | D5: =SUMIF($A$30:$A$112,A5,$B$30:$B$112) -> 860 | E5: 115 | F5: =C5+D5-E5 -> 855 | G5: 9280 | H5: 9455 | I5: =H5-G5 -> 175 | J5: 0 | L5: 242 | M5: 3.4 | N5: =F5/I5 -> 4.8857143 | O5: =194.94*I5 -> 34114.5 | P5: =F5*$K$25 -> 43995.693 | Q5: =O5-P5 -> -9881.1932
A6: Телескоп JCB 540-170 №5 | B6: 45474 | C6: 60 | D6: =SUMIF($A$30:$A$112,A6,$B$30:$B$112) -> 0 | E6: 50 | F6: =C6+D6-E6 -> 10 | G6: 0 | I6: =L6*0.53 -> 1.59 | J6: 0 | L6: 3 | M6: 3.4 | N6: =F6/I6 -> 6.2893082 | O6: =194.94*I6 -> 309.9546 | P6: =F6*$K$25 -> 514.56951 | Q6: =O6-P6 -> -204.61491 | R6: не работает мотосчетчик
A7: Виброкаток | B7: 45474 | C7: 85 | D7: =SUMIF($A$30:$A$112,A7,$B$30:$B$112) -> 83 | E7: 150 | F7: =C7+D7-E7 -> 18 | G7: 4948 | H7: 4958 | I7: =H7-G7 -> 10 | J7: 0 | L7: 9 | M7: 5 | N7: =F7/I7 -> 1.8 | O7: =285*I7 -> 2850 | P7: =F7*$K$25 -> 926.22512 | Q7: =O7-P7 -> 1923.7749
A8: Ротор Пегасус | B8: 45474 | C8: 0 | D8: =SUMIF($A$30:$A$112,A8,$B$30:$B$112) -> 0 | F8: =C8+D8-E8 -> 0 | G8: 0 | I8: =H8-G8 -> 0 | J8: 0 | M8: #N/A | N8: =F8/I8 -> #DIV/0! | P8: =F8*$K$25 -> 0 | Q8: =O8-P8 -> 0
A9: Экскаватор JCB | B9: 45474 | C9: 70 | D9: =SUMIF($A$30:$A$112,A9,$B$30:$B$112) -> 800 | E9: 70 | F9: =C9+D9-E9 -> 800 | G9: 17307 | H9: 17434 | I9: =H9-G9 -> 127 | J9: 0 | L9: 198 | M9: 4.1 | N9: =F9/I9 -> 6.2992126 | O9: =235.41*I9 -> 29897.07 | P9: =F9*$K$25 -> 41165.561 | Q9: =O9-P9 -> -11268.491
A10: Экскаватор JCB 3CX 2008 | B10: 45474 | C10: 20 | D10: =SUMIF($A$30:$A$112,A10,$B$30:$B$112) -> 799.94 | E10: 30 | F10: =C10+D10-E10 -> 789.94 | G10: 39553 | H10: 39728 | I10: =H10-G10 -> 175 | J10: 0 | L10: 233 | M10: 4.1 | N10: =F10/I10 -> 4.5139429 | O10: =235.41*I10 -> 41196.75 | P10: =F10*$K$25 -> 40647.904 | Q10: =O10-P10 -> 548.84607
A11: Экскаватор JCB 2013 | B11: 45474 | C11: 10 | D11: =SUMIF($A$30:$A$112,A11,$B$30:$B$112) -> 850 | E11: 15 | F11: =C11+D11-E11 -> 845 | G11: 11904 | H11: 12082 | I11: =H11-G11 -> 178 | J11: 0 | L11: 237 | M11: 4.1 | N11: =F11/I11 -> 4.747191 | O11: =235.41*I11 -> 41902.98 | P11: =F11*$K$25 -> 43481.124 | Q11: =O11-P11 -> -1578.1437
A12: Экскаватор JCB 220 | B12: 45474 | C12: 80 | D12: =SUMIF($A$30:$A$112,A12,$B$30:$B$112) -> 0 | F12: =C12+D12-E12 -> 80 | G12: 7096 | I12: =H12-G12 -> -7096 | J12: 0 | M12: 10.5 | N12: =F12/I12 -> -0.011273957 | O12: =595.65*I12 -> -4226732.4 | P12: =F12*$K$25 -> 4116.5561 | Q12: =O12-P12 -> -4230849
A13: МАЗ 264 | B13: 45474 | C13: 40 | D13: =SUMIF($A$30:$A$112,A13,$B$30:$B$112) -> 400 | E13: 130 | F13: =C13+D13-E13 -> 310 | G13: 31643 | H13: 31832 | I13: =H13-G13 -> 189 | J13: 0 | L13: 175 | M13: 0.9 | N13: =F13/I13 -> 1.6402116 | O13: =(51.3*(I13-K13))+(K13*14.25) -> 9695.7 | P13: =F13*$K$25 -> 15951.655 | Q13: =O13-P13 -> -6255.9548 | R13: слив 15.2 л
A14: МАЗ 265 | B14: 45474 | C14: 140 | D14: =SUMIF($A$30:$A$112,A14,$B$30:$B$112) -> 500 | E14: 150 | F14: =C14+D14-E14 -> 490 | G14: 34719 | H14: 35350 | I14: =H14-G14 -> 631 | J14: 0 | L14: 135 | M14: 0.9 | N14: =F14/I14 -> 0.77654517 | O14: =(51.3*(I14-K14))+(K14*14.25) -> 32370.3 | P14: =F14*$K$25 -> 25213.906 | Q14: =O14-P14 -> 7156.394 | R14: слив 10,47 л
A15: Самосвал Камаз | B15: 45474 | C15: 130 | D15: =SUMIF($A$30:$A$112,A15,$B$30:$B$112) -> 200 | E15: 137 | F15: =C15+D15-E15 -> 193 | G15: 559353 | H15: 559550 | I15: =H15-G15 -> 197 | J15: 0 | L15: 128 | M15: 0.9 | N15: =F15/I15 -> 0.97969543 | O15: =(51.3*(I15-K15))+(K15*19.85) -> 10106.1 | P15: =F15*$K$25 -> 9931.1916 | Q15: =O15-P15 -> 174.90844 | R15: слив 509 л
A16: Самосвал МАЗ | B16: 45474 | C16: 240 | D16: =SUMIF($A$30:$A$112,A16,$B$30:$B$112) -> 59.54 | E16: 160 | F16: =C16+D16-E16 -> 139.54 | G16: 64160 | H16: 64239 | I16: =H16-G16 -> 79 | J16: 0 | L16: 16 | M16: 0.9 | N16: =F16/I16 -> 1.7663291 | O16: =(51.3*(I16-K16))+(K16*19.85) -> 4052.7 | P16: =F16*$K$25 -> 7180.303 | Q16: =O16-P16 -> -3127.603 | R16: слив 16,5 л
A17: РДК 250 | B17: 45474 | C17: 0 | D17: =SUMIF($A$30:$A$112,A17,$B$30:$B$112) -> 0 | F17: =C17+D17-E17 -> 0 | G17: 0 | I17: =H17-G17 -> 0 | J17: 0 | M17: #N/A | N17: =F17/I17 -> #DIV/0! | P17: =F17*$K$25 -> 0 | Q17: =O17-P17 -> 0
A18: Автокран XCMG 55 | B18: 45474 | C18: 130 | D18: =SUMIF($A$30:$A$112,A18,$B$30:$B$112) -> 380 | E18: 190 | F18: =C18+D18-E18 -> 320 | G18: 0 | I18: =L18*0.7 -> 70 | J18: 0 | L18: 100 | M18: 5.1 | N18: =F18/I18 -> 4.5714286 | O18: =290.07*I18 -> 20304.9 | P18: =F18*$K$25 -> 16466.224 | Q18: =O18-P18 -> 3838.6757 | R18: не работает мотосчетчик, слив 127 л
A19: Автокран XCMG | B19: 45474 | C19: 100 | D19: =SUMIF($A$30:$A$112,A19,$B$30:$B$112) -> 570 | E19: 180 | F19: =C19+D19-E19 -> 490 | G19: 5827 | H19: 5973 | I19: =H19-G19 -> 146 | J19: 0 | L19: 274 | M19: 3.2 | N19: =F19/I19 -> 3.3561644 | O19: =182.4*I19 -> 26630.4 | P19: =F19*$K$25 -> 25213.906 | Q19: =O19-P19 -> 1416.494 | R19: слив 3435 л
A20: Автокран Клинцы | B20: 45474 | C20: 230 | D20: =SUMIF($A$30:$A$112,A20,$B$30:$B$112) -> 300 | E20: 230 | F20: =C20+D20-E20 -> 300 | G20: ='[4]Июнь 2024 '!H20 -> 0 | I20: =L20*0.7 -> 16.1 | J20: 0 | K20: 360 | L20: 23 | M20: 2.9 | N20: =F20/I20 -> 18.63354 | O20: =I20*165.3+28.5*K20 -> 12921.33 | P20: =F20*$K$25 -> 15437.085 | Q20: =O20-P20 -> -2515.7553 | R20: не работает мотосчетчик слив 400 л
A21: Подъемник Haulotte №1 | B21: 45474 | C21: ='[4]Июнь 2024 '!E21 -> 0 | D21: =SUMIF($A$30:$A$112,A21,$B$30:$B$112) -> 0 | F21: =C21+D21-E21 -> 0 | G21: ='[4]Июнь 2024 '!H21 -> 0 | I21: 0 | J21: 0 | N21: =VLOOKUP(A21,[4]Тарас!$C$4:$N$23,12,0) -> #N/A | O21: =194.94*I21 -> 0 | P21: =F21*$K$25 -> 0 | Q21: =O21-P21 -> 0
C22: =SUM(C2:C21) -> 1645 | D22: =SUM(D2:D21) -> 5902.48 | E22: =SUM(E2:E21) -> 1647
D23: =D22-B113 -> 0
J25: Стоимость 1 л | K25: =SUM(C30:C112)/B113 -> 51.456951
A28: Заправки АЗС
A29: Наименование | B29: Количество | C29: Сумма | D29: АЗС
A30: Экскаватор JCB | B30: 100 | C30: =B30*47.63 -> 4763 | D30: Авиас
A31: Экскаватор JCB | B31: 100 | C31: =B31*47.63 -> 4763 | D31: Авиас
A32: Экскаватор JCB | B32: 100 | C32: =B32*47.63 -> 4763 | D32: Авиас
A33: Экскаватор JCB | B33: 100 | C33: =B33*47.63 -> 4763 | D33: Авиас
A34: Экскаватор JCB | B34: 100 | C34: =B34*47.63 -> 4763 | D34: Авиас
A35: Экскаватор JCB | B35: 100 | C35: =B35*47.63 -> 4763 | D35: Авиас
A36: Экскаватор JCB | B36: 100 | C36: =B36*47.63 -> 4763 | D36: Авиас
A37: Экскаватор JCB | B37: 100 | C37: =B37*47.63 -> 4763 | D37: Авиас
A38: МАЗ 265 | B38: 100 | C38: =B38*47.63 -> 4763 | D38: Авиас
A39: МАЗ 265 | B39: 100 | C39: =B39*47.63 -> 4763 | D39: Авиас
A40: МАЗ 265 | B40: 100 | C40: =B40*47.63 -> 4763 | D40: Авиас
A41: МАЗ 265 | B41: 100 | C41: =B41*47.63 -> 4763 | D41: Авиас
... A47: МАЗ 264 | B47: 100 | C47: =B47*47.63 -> 4763 | D47: Авиас
E48: =SUM(C30:C48) -> 85734
...

Sheet Топливо Август 2024
A1: Наименование | B1: Отчетный период | C1: Остаток на начало | D1: Топливо заправленное | E1: Остаток на конец | F1: Расход топлива за период, л | G1: Моточасы на начало | H1: Моточасы на конец | I1: Отработано техникой моточасов | J1: Перегон на доругой объект, л | K1: Перегон на доругой объект, км | L1: Часы работы на обьекте | M1: Норма расхода топлива литр/1 мото час согласно сс | N1: Факт витрат на 1 мото/год, км витрат (л/год) | O1: PL план , грн | P1: PL факт , грн | Q1: Diff, грн | R1: Примечание по строке
A2: Телескоп 1 | B2: 45474 | C2: 80 | D2: =SUMIF($A$29:$A$128,A2,$B$29:$B$128) -> 0 | F2: =C2+D2-E2 -> 80 | G2: ='[4]Июнь 2024 '!H2 -> 14075 | I2: =H2-G2 -> -14075 | J2: 0 | L2: 0 | M2: =VLOOKUP(A2,[4]Тарас!$C$4:$P$23,14,0) -> 3.4 | O2: =194.94*I2 -> -2743780.5 | P2: =F2*$K$24 -> 4081.149 | Q2: =O2-P2 -> -2747861.6
A3: Телескоп 2 | B3: 45474
A4: Телескоп JCB 533-105 (№3) | B4: 45474 | C4: 0 | D4: =SUMIF($A$29:$A$128,A4,$B$29:$B$128) -> 0 | F4: =C4+D4-E4 -> 0 | G4: 0 | J4: 0 | M4: #N/A | N4: =F4/I4 -> #DIV/0! | O4: =194.94*I4 -> 0 | P4: =F4*$K$24 -> 0 | Q4: =O4-P4 -> 0
A5: Телескоп JCB 535-140 (№4) | B5: 45474 | C5: 115 | D5: =SUMIF($A$29:$A$128,A5,$B$29:$B$128) -> 926.25 | E5: 70 | F5: =C5+D5-E5 -> 971.25 | G5: 9455 | H5: 9655 | I5: =H5-G5 -> 200 | J5: 0 | L5: 254 | M5: 3.4 | N5: =F5/I5 -> 4.85625 | O5: =194.94*I5 -> 38988 | P5: =F5*$K$24 -> 49547.699 | Q5: =O5-P5 -> -10559.699
A6: Телескоп JCB 540-170 №5 | B6: 45474 | C6: 50 | D6: =SUMIF($A$29:$A$128,A6,$B$29:$B$128) -> 210 | E6: 120 | F6: =C6+D6-E6 -> 140 | I6: =L6*0.53 -> 36.57 | J6: 0 | L6: 69 | M6: 3.4 | N6: =F6/I6 -> 3.8282745 | O6: =194.94*I6 -> 7128.9558 | P6: =F6*$K$24 -> 7142.0107 | Q6: =O6-P6 -> -13.05492 | R6: не работает мотосчетчик
A7: Виброкаток | B7: 45474 | C7: 150 | D7: =SUMIF($A$29:$A$128,A7,$B$29:$B$128) -> 0 | E7: 125 | F7: =C7+D7-E7 -> 25 | G7: 4958 | H7: 4970 | I7: =H7-G7 -> 12 | J7: 0 | L7: 20 | M7: 5 | N7: =F7/I7 -> 2.0833333 | O7: =285*I7 -> 3420 | P7: =F7*$K$24 -> 1275.3591 | Q7: =O7-P7 -> 2144.6409
A8: Ротор Пегасус | B8: 45474 | D8: =SUMIF($A$29:$A$128,A8,$B$29:$B$128) -> 0 | F8: =C8+D8-E8 -> 0 | I8: =H8-G8 -> 0 | J8: 0 | M8: #N/A | N8: =F8/I8 -> #DIV/0! | P8: =F8*$K$24 -> 0 | Q8: =O8-P8 -> 0
A9: Экскаватор JCB | B9: 45474 | C9: 70 | D9: =SUMIF($A$29:$A$128,A9,$B$29:$B$128) -> 789.18 | E9: 55 | F9: =C9+D9-E9 -> 804.18 | G9: 17434 | H9: 17608 | I9: =H9-G9 -> 174 | J9: 0 | L9: 198 | M9: 4.1 | N9: =F9/I9 -> 4.6217241 | O9: =235.41*I9 -> 40961.34 | P9: =F9*$K$24 -> 41024.73 | Q9: =O9-P9 -> -63.389865
A10: Экскаватор JCB 3CX 2008 | B10: 45474 | C10: 30 | D10: =SUMIF($A$29:$A$128,A10,$B$29:$B$128) -> 874 | E10: 0 | F10: =C10+D10-E10 -> 904 | G10: 39728 | I10: =L10*0.55 -> 116.6 | J10: 0 | L10: 212 | M10: 4.1 | N10: =F10/I10 -> 7.7530017 | O10: =235.41*I10 -> 27448.806 | P10: =F10*$K$24 -> 46116.984 | Q10: =O10-P10 -> -18668.178 | R10: не работает счетчик на топливо и на моточасы, поламался в августе
A11: Экскаватор JCB 2013 | B11: 45474 | C11: 15 | D11: =SUMIF($A$29:$A$128,A11,$B$29:$B$128) -> 849.99 | E11: 10 | F11: =C11+D11-E11 -> 854.99 | G11: 12082 | H11: 12270 | I11: =H11-G11 -> 188 | J11: 0 | L11: 251 | M11: 4.1 | N11: =F11/I11 -> 4.5478191 | O11: =235.41*I11 -> 44257.08 | P11: =F11*$K$24 -> 43616.77 | Q11: =O11-P11 -> 640.31039
A12: Экскаватор JCB 220 | B12: 45474 | C12: 80 | D12: =SUMIF($A$29:$A$128,A12,$B$29:$B$128) -> 1811.92 | E12: 394 | F12: =C12+D12-E12 -> 1497.92 | G12: 7096 | H12: 7255 | I12: =H12-G12 -> 159 | J12: 0 | L12: 240 | M12: 10.5 | N12: =F12/I12 -> 9.4208805 | O12: =595.65*I12 -> 94708.35 | P12: =F12*$K$24 -> 76415.434 | Q12: =O12-P12 -> 18292.916 | R12: слив 85 л
A13: МАЗ 264 | B13: 45474 | C13: 130 | D13: =SUMIF($A$29:$A$128,A13,$B$29:$B$128) -> 472.27 | E13: 150 | F13: =C13+D13-E13 -> 452.27 | G13: 31832 | H13: 32189 | I13: =H13-G13 -> 357 | J13: 0 | L13: 143 | M13: 0.9 | N13: =F13/I13 -> 1.2668627 | O13: =(51.3*(I13-K13))+(K13*14.25) -> 18314.1 | P13: =F13*$K$24 -> 23072.266 | Q13: =O13-P13 -> -4758.1656 | R13: слив 51 л
A14: МАЗ 265 | B14: 45474 | C14: 150 | D14: =SUMIF($A$29:$A$128,A14,$B$29:$B$128) -> 524.92 | E14: 150 | F14: =C14+D14-E14 -> 524.92 | G14: 35350 | H14: 35800 | I14: =H14-G14 -> 450 | J14: 0 | L14: 180 | M14: 0.9 | N14: =F14/I14 -> 1.1664889 | O14: =(51.3*(I14-K14))+(K14*14.25) -> 23085 | P14: =F14*$K$24 -> 26778.459 | Q14: =O14-P14 -> -3693.4591
A15: Самосвал Камаз | B15: 45474 | C15: 137 | D15: =SUMIF($A$29:$A$128,A15,$B$29:$B$128) -> 500 | E15: 170 | F15: =C15+D15-E15 -> 467 | G15: 559550 | H15: 559867 | I15: =H15-G15 -> 317 | J15: 0 | L15: 124 | M15: 0.9 | N15: =F15/I15 -> 1.4731861 | O15: =(51.3*(I15-K15))+(K15*19.85) -> 16262.1 | P15: =F15*$K$24 -> 23823.707 | Q15: =O15-P15 -> -7561.6072 | R15: слив 1277 л
A16: Самосвал МАЗ | B16: 45474 | C16: 160 | D16: =SUMIF($A$29:$A$128,A16,$B$29:$B$128) -> 626.98 | E16: 161 | F16: =C16+D16-E16 -> 625.98 | G16: 64239 | H16: 65010 | I16: =H16-G16 -> 771 | J16: 0 | K16: 220 | L16: 108 | M16: 0.9 | N16: =F16/I16 -> 0.81190661 | O16: =(51.3*(I16-K16))+(K16*19.85) -> 32633.3 | P16: =F16*$K$24 -> 31933.971 | Q16: =O16-P16 -> 699.3295 | R16: слив 32,57
A17: РДК 250 | B17: 45474 | D17: =SUMIF($A$29:$A$128,A17,$B$29:$B$128) -> 0 | F17: =C17+D17-E17 -> 0 | I17: =H17-G17 -> 0 | J17: 0 | M17: #N/A | N17: =F17/I17 -> #DIV/0! | P17: =F17*$K$24 -> 0 | Q17: =O17-P17 -> 0
A18: Автокран XCMG 55 | B18: 45474 | C18: 190 | D18: =SUMIF($A$29:$A$128,A18,$B$29:$B$128) -> 559.99 | E18: 170 | F18: =C18+D18-E18 -> 579.99 | I18: =L18*0.7 -> 105 | J18: 0 | L18: 150 | M18: 5.1 | N18: =F18/I18 -> 5.5237143 | O18: =290.07*I18 -> 30457.35 | P18: =F18*$K$24 -> 29587.82 | Q18: =O18-P18 -> 869.53002 | R18: не работает мотосчетчик, слив 114 л
A19: Автокран XCMG | B19: 45474 | C19: 180 | D19: =SUMIF($A$29:$A$128,A19,$B$29:$B$128) -> 424.84 | E19: 230 | F19: =C19+D19-E19 -> 374.84 | G19: 5973 | H19: 6073 | I19: =H19-G19 -> 100 | J19: 0 | L19: 280 | M19: 3.2 | N19: =F19/I19 -> 3.7484 | O19: =182.4*I19 -> 18240 | P19: =F19*$K$24 -> 19122.224 | Q19: =O19-P19 -> -882.22356 | R19: слив 188 л
A20: Автокран Клинцы | B20: 45474 | C20: 230 | D20: =SUMIF($A$29:$A$128,A20,$B$29:$B$128) -> 401.42 | E20: 230 | F20: =C20+D20-E20 -> 401.42 | I20: =L20*0.7 -> 140.7 | J20: 0 | L20: 201 | M20: 2.9 | N20: =F20/I20 -> 2.8530206 | O20: =I20*165.3+28.5*K20 -> 23257.71 | P20: =F20*$K$24 -> 20478.185 | Q20: =O20-P20 -> 2779.5247 | R20: не работает мотосчетчик, слив 99 л
C21: =SUM(C5:C20) -> 1687 | D21: =SUM(D2:D20) -> 8971.76 | E21: =SUM(E2:E20) -> 2035
D22: =D21-B129 -> 0
J24: Стоимость 1 л | K24: =SUM(C29:C128)/B129 -> 51.014362
A27: Заправки АЗС
A28: Наименование | B28: Количество | C28: Сумма | D28: АЗС
A29: Экскаватор JCB | B29: 92.08 | C29: =B29*50.5 -> 4650.04 | D29: Авиас
A30: Экскаватор JCB | B30: 45.87 | C30: =B30*50.5 -> 2316.435 | D30: Авиас
A31: Экскаватор JCB | B31: 100 | C31: =B31*50.5 -> 5050 | D31: Авиас
A32: Экскаватор JCB | B32: 100 | C32: =B32*50.5 -> 5050 | D32: Авиас
A33: Экскаватор JCB | B33: 96.46 | C33: =B33*50.5 -> 4871.23 | D33: Авиас
A34: Экскаватор JCB | B34: 54.77 | C34: =B34*50.5 -> 2765.885 | D34: Авиас
A35: Экскаватор JCB | B35: 100 | C35: =B35*50.5 -> 5050 | D35: Авиас
A36: Экскаватор JCB | B36: 100 | C36: =B36*50.5 -> 5050 | D36: Авиас
A37: Экскаватор JCB | B37: 100 | C37: =B37*50.5 -> 5050 | D37: Авиас
A38: Автокран Клинцы | B38: 50 | C38: =B38*50.5 -> 2525 | D38: Авиас
A39: Автокран Клинцы | B39: 138.42 | C39: =B39*50.5 -> 6990.21 | D39: Авиас
A40: Автокран Клинцы | B40: 13 | C40: =B40*50.5 -> 656.5 | D40: Авиас
... A47: МАЗ 264 | B47: 100 | C47: =B47*50.5 -> 5050 | D47: Авиас
E48: =SUM(C29:C48) -> 83974.935
A49: Автокран XCMG | B49: 100 | C49: 5349 | D49: Амик
...

Sheet Топливо Сентябрь 2024
A1: Наименование | B1: Отчетный период | C1: Остаток на начало | D1: Топливо заправленное | E1: Остаток на конец | F1: Расход топлива за период, л | G1: Моточасы на начало | H1: Моточасы на конец | I1: Отработано техникой моточасов | J1: Перегон на доругой объект, л | K1: Перегон на доругой объект, км | L1: Часы работы на обьекте | M1: Норма расхода топлива литр/1 мото час согласно сс | N1: Факт витрат на 1 мото/год, км витрат (л/год) | O1: PL план , грн | P1: PL факт , грн | Q1: Diff, грн | R1: Примечание по строке
A2: Телескоп 1 | B2: 45474 | C2: 80 | D2: =SUMIF($A$30:$A$149,A2,$B$30:$B$149) -> 0 | F2: =C2+D2-E2 -> 80 | G2: ='[4]Июнь 2024 '!H2 -> 14075 | I2: =H2-G2 -> -14075 | J2: 0 | L2: 0 | M2: =VLOOKUP(A2,[4]Тарас!$C$4:$P$23,14,0) -> 3.4 | O2: =194.94*I2 -> -2743780.5 | P2: =F2*$K$25 -> 4049.5087 | Q2: =O2-P2 -> -2747830
A3: Телескоп 2 | B3: 45536 | C3: 40 | D3: =SUMIF($A$30:$A$149,A3,$B$30:$B$149) -> 400 | E3: 30 | F3: =C3+D3-E3 -> 410 | G3: 10718 | I3: =L3*0.53 -> 60.42 | L3: 114 | M3: 3.4 | N3: =F3/I3 -> 6.7858325 | O3: =194.94*I3 -> 11778.275 | P3: =F3*$K$25 -> 20753.732 | Q3: =O3-P3 -> -8975.457 | R3: мотосчетчик дал сбой, на табло ошибка
A4: Телескоп JCB 533-105 (№3) | B4: 45536 | D4: =SUMIF($A$30:$A$149,A4,$B$30:$B$149) -> 0 | F4: =C4+D4-E4 -> 0 | J4: 0 | M4: #N/A | N4: =F4/I4 -> #DIV/0! | O4: =194.94*I4 -> 0 | P4: =F4*$K$25 -> 0 | Q4: =O4-P4 -> 0
A5: Телескоп JCB 535-140 (№4) | B5: 45536 | C5: 70 | D5: =SUMIF($A$30:$A$149,A5,$B$30:$B$149) -> 775.34 | E5: 10 | F5: =C5+D5-E5 -> 835.34 | G5: 9655 | H5: 9842 | I5: =H5-G5 -> 187 | J5: 0 | L5: 186 | M5: 3.4 | N5: =F5/I5 -> 4.4670588 | O5: =194.94*I5 -> 36453.78 | P5: =F5*$K$25 -> 42283.957 | Q5: =O5-P5 -> -5830.177
A6: Телескоп JCB 540-170 №5 | B6: 45536 | C6: 120 | D6: =SUMIF($A$30:$A$149,A6,$B$30:$B$149) -> 319.49 | E6: 20 | F6: =C6+D6-E6 -> 419.49 | I6: =L6*0.53 -> 33.92 | J6: 0 | L6: 64 | M6: 3.4 | N6: =F6/I6 -> 12.36704 | O6: =194.94*I6 -> 6612.3648 | P6: =F6*$K$25 -> 21234.105 | Q6: =O6-P6 -> -14621.74 | R6: не работает мотосчетчик
A7: Виброкаток | B7: 45536 | C7: 125 | D7: =SUMIF($A$30:$A$149,A7,$B$30:$B$149) -> 0 | E7: 65 | F7: =C7+D7-E7 -> 60 | G7: 4970 | H7: 4981 | I7: =H7-G7 -> 11 | J7: 0 | L7: 10 | M7: 5 | N7: =F7/I7 -> 5.4545455 | O7: =285*I7 -> 3135 | P7: =F7*$K$25 -> 3037.1315 | Q7: =O7-P7 -> 97.868512
A8: Ротор Пегасус | B8: 45536 | D8: =SUMIF($A$30:$A$149,A8,$B$30:$B$149) -> 0 | F8: =C8+D8-E8 -> 0 | I8: =H8-G8 -> 0 | J8: 0 | M8: #N/A | N8: =F8/I8 -> #DIV/0! | P8: =F8*$K$25 -> 0 | Q8: =O8-P8 -> 0
A9: Экскаватор JCB | B9: 45536 | C9: 55 | D9: =SUMIF($A$30:$A$149,A9,$B$30:$B$149) -> 974.88 | E9: 10 | F9: =C9+D9-E9 -> 1019.88 | G9: 17608 | H9: 17802 | I9: =H9-G9 -> 194 | J9: 0 | L9: 242 | M9: 4.1 | N9: =F9/I9 -> 5.2571134 | O9: =235.41*I9 -> 45669.54 | P9: =F9*$K$25 -> 51625.161 | Q9: =O9-P9 -> -5955.621
A10: Экскаватор JCB 3CX 2008 | B10: 45536 | C10: 0 | D10: =SUMIF($A$30:$A$149,A10,$B$30:$B$149) -> 1111.37 | E10: 20 | F10: =C10+D10-E10 -> 1091.37 | I10: =L10*0.55 -> 114.4 | J10: 0 | L10: 208 | M10: 4.1 | N10: =F10/I10 -> 9.5399476 | O10: =235.41*I10 -> 26930.904 | P10: =F10*$K$25 -> 55243.903 | Q10: =O10-P10 -> -28312.999
A11: Экскаватор JCB 2013 | B11: 45536 | C11: 10 | D11: =SUMIF($A$30:$A$149,A11,$B$30:$B$149) -> 400 | E11: 20 | F11: =C11+D11-E11 -> 390 | G11: 12270 | I11: =H11-G11 -> -12270 | J11: 0 | L11: 91 | M11: 4.1 | R11: на ремонте, не можем получить данные счетчика
A12: Экскаватор JCB 220 | B12: 45536 | C12: 394 | D12: =SUMIF($A$30:$A$149,A12,$B$30:$B$149) -> 1831.05 | E12: 301 | F12: =C12+D12-E12 -> 1924.05 | G12: 7255 | H12: 7387 | I12: =H12-G12 -> 132 | J12: 0 | L12: 230 | M12: 10.5 | N12: =F12/I12 -> 14.576136 | O12: =595.65*I12 -> 78625.8 | P12: =F12*$K$25 -> 97393.214 | Q12: =O12-P12 -> -18767.414 | R12: gps показывает слив топлива 396 л
A13: МАЗ 264 | B13: 45536 | C13: 150 | D13: =SUMIF($A$30:$A$149,A13,$B$30:$B$149) -> 580.43 | E13: 150 | F13: =C13+D13-E13 -> 580.43 | G13: 32189 | H13: 32692 | I13: =H13-G13 -> 503 | J13: 0 | L13: 222 | M13: 0.9 | N13: =F13/I13 -> 1.1539364 | O13: =(51.3*(I13-K13))+(K13*14.25) -> 25803.9 | P13: =F13*$K$25 -> 29380.704 | Q13: =O13-P13 -> -3576.8038
A14: МАЗ 265 | B14: 45536 | C14: 150 | D14: =SUMIF($A$30:$A$149,A14,$B$30:$B$149) -> 547.46 | E14: 160 | F14: =C14+D14-E14 -> 537.46 | G14: 35800 | H14: 37210 | I14: =H14-G14 -> 1410 | J14: 0 | K14: 450 | L14: 189 | M14: 0.9 | N14: =F14/I14 -> 0.3811773 | O14: =(51.3*(I14-K14))+(K14*14.25) -> 55660.5 | P14: =F14*$K$25 -> 27205.611 | Q14: =O14-P14 -> 28454.889
A15: Самосвал Камаз | B15: 45536 | C15: 170 | D15: =SUMIF($A$30:$A$149,A15,$B$30:$B$149) -> 254.47 | E15: 204 | F15: =C15+D15-E15 -> 220.47 | G15: 559867 | H15: 560504 | I15: =H15-G15 -> 637 | J15: 0 | K15: 413 | L15: 4 | M15: 0.9 | N15: =F15/I15 -> 0.34610675 | O15: =(51.3*(I15-K15))+(K15*19.85) -> 19689.25 | P15: =F15*$K$25 -> 11159.94 | Q15: =O15-P15 -> 8529.3103
A16: Самосвал МАЗ | B16: 45536 | C16: 161 | D16: =SUMIF($A$30:$A$149,A16,$B$30:$B$149) -> 1498.88 | E16: 181 | F16: =C16+D16-E16 -> 1478.88 | G16: 65010 | H16: 68211 | I16: =H16-G16 -> 3201 | J16: 0 | K16: 250 | L16: 89 | M16: 0.9 | N16: =F16/I16 -> 0.46200562 | O16: =(51.3*(I16-K16))+(K16*19.85) -> 156348.8 | P16: =F16*$K$25 -> 74859.217 | Q16: =O16-P16 -> 81489.583 | R16: gps показывает слив топлива 11 л
A17: Самосвал МАЗ №2 | B17: 45536 | C17: 0 | D17: =SUMIF($A$30:$A$149,A17,$B$30:$B$149) -> 940.02 | E17: 160 | F17: =C17+D17-E17 -> 780.02 | G17: 63140 | H17: 64118 | I17: =H17-G17 -> 978 | J17: 0 | K17: 480 | L17: 76 | M17: 0.9 | N17: =F17/I17 -> 0.79756646 | O17: =(51.3*(I17-K17))+(K17*19.85) -> 35075.4 | P17: =F17*$K$25 -> 39483.722 | Q17: =O17-P17 -> -4408.3217 | R17: gps показывает слив топлива 27 л
A18: РДК 250 | B18: 45536 | D18: =SUMIF($A$30:$A$149,A18,$B$30:$B$149) -> 0 | F18: =C18+D18-E18 -> 0 | I18: =H18-G18 -> 0 | J18: 0 | M18: #N/A | N18: =F18/I18 -> #DIV/0! | P18: =F18*$K$25 -> 0 | Q18: =O18-P18 -> 0
A19: Автокран XCMG 55 | B19: 45536 | C19: 170 | D19: =SUMIF($A$30:$A$149,A19,$B$30:$B$149) -> 299.95 | E19: 40 | F19: =C19+D19-E19 -> 429.95 | I19: =L19*0.7 -> 35 | J19: 0 | L19: 50 | M19: 5.1 | N19: =F19/I19 -> 12.284286 | O19: =290.07*I19 -> 10152.45 | P19: =F19*$K$25 -> 21763.578 | Q19: =O19-P19 -> -11611.128 | R19: не работает мотосчетчик
A20: Автокран XCMG | B20: 45536 | C20: 230 | D20: =SUMIF($A$30:$A$149,A20,$B$30:$B$149) -> 250 | E20: 60 | F20: =C20+D20-E20 -> 420 | G20: 6073 | H20: 6142 | I20: =H20-G20 -> 69 | J20: 0 | L20: 195 | M20: 3.2 | N20: =F20/I20 -> 6.0869565 | O20: =182.4*I20 -> 12585.6 | P20: =F20*$K$25 -> 21259.92 | Q20: =O20-P20 -> -8674.3204 | R20: gps показывает слив топлива 242 л
A21: Автокран Клинцы | B21: 45536 | C21: 230 | D21: =SUMIF($A$30:$A$149,A21,$B$30:$B$149) -> 229.83 | E21: 152 | F21: =C21+D21-E21 -> 307.83 | I21: =L21*0.7 -> 110.6 | J21: 0 | L21: 158 | M21: 2.9 | N21: =F21/I21 -> 2.7832731 | O21: =I21*165.3+28.5*K21 -> 18282.18 | P21: =F21*$K$25 -> 15582.003 | Q21: =O21-P21 -> 2700.1769 | R21: не работает мотосчетчик , gps показывает слив топлива 784 л
C22: =SUM(C5:C21) -> 2035 | D22: =SUM(D2:D21) -> 10413.17 | E22: =SUM(E2:E21) -> 1583
D23: =D22-B150 -> 0
J25: Стоимость 1 л | K25: =SUM(C30:C149)/B150 -> 50.618858
A28: Заправки АЗС
A29: Наименование | B29: Количество | C29: Сумма | D29: АЗС
A30: Экскаватор JCB | B30: 78.63 | C30: =B30*50.5 -> 3970.815 | D30: Авиас
A31: Экскаватор JCB | B31: 100 | C31: =B31*50.5 -> 5050 | D31: Авиас
A32: Экскаватор JCB | B32: 100 | C32: =B32*50.5 -> 5050 | D32: Авиас
A33: Экскаватор JCB | B33: 100 | C33: =B33*50.5 -> 5050 | D33: Авиас
A34: Экскаватор JCB | B34: 97.24 | C34: =B34*50.5 -> 4910.62 | D34: Авиас
A35: Экскаватор JCB | B35: 35.71 | C35: =B35*50.5 -> 1803.355 | D35: Авиас
A36: Экскаватор JCB | B36: 100 | C36: =B36*50.5 -> 5050 | D36: Авиас
A37: Экскаватор JCB | B37: 100 | C37: =B37*50.5 -> 5050 | D37: Авиас
A38: Автокран Клинцы | B38: 100 | C38: =B38*50.5 -> 5050 | D38: Авиас
A39: Автокран Клинцы | B39: 123.63 | C39: =B39*50.5 -> 6243.315 | D39: Авиас
A40: Автокран Клинцы | B40: 6.2 | C40: =B40*50.5 -> 313.1 | D40: Авиас
A41: МАЗ 264 | B41: 100 | C41: =B41*50.5 -> 5050 | D41: Авиас
... A64: Самосвал МАЗ | B64: 158 | C64: =B64*50.5 -> 7979 | D64: Авиас
C65: =B65*50.5 -> 0 | D65: Авиас
...

Sheet Топливо Июль 2024
A1: Наименование | B1: Отчетный период | C1: Остаток на начало | D1: Топливо заправленное | E1: Остаток на конец | F1: Расход топлива за период, л | G1: Моточасы на начало | H1: Моточасы на конец | I1: Отработано техникой моточасов | J1: Перегон на доругой объект, л | K1: Перегон на доругой объект, км | L1: Часы работы на обьекте | M1: Норма расхода топлива литр/1 мото час согласно сс | N1: Факт витрат на 1 мото/год, км витрат (л/год) | O1: PL план , грн | P1: PL факт , грн | Q1: Diff, грн | R1: Примечание по строке
A2: Телескоп 1 | B2: 45474 | C2: 80 | D2: =SUMIF($A$30:$A$112,A2,$B$30:$B$112) -> 0 | F2: =C2+D2-E2 -> 80 | G2: ='[4]Июнь 2024 '!H2 -> 14075 | I2: =H2-G2 -> -14075 | J2: 0 | L2: 0 | M2: =VLOOKUP(A2,[4]Тарас!$C$4:$P$23,14,0) -> 3.4 | O2: =194.94*I2 -> -2743780.5 | P2: =F2*$K$25 -> 4116.5561 | Q2: =O2-P2 -> -2747897.1
A3: Телескоп 2 | B3: 45474 | C3: 120 | D3: =SUMIF($A$30:$A$112,A3,$B$30:$B$112) -> 100 | E3: 40 | F3: =C3+D3-E3 -> 180 | G3: 10647 | H3: 10718 | I3: =H3-G3 -> 71 | J3: 0 | L3: 82 | M3: 3.4 | N3: =F3/I3 -> 2.5352113 | O3: =194.94*I3 -> 13840.74 | P3: =F3*$K$25 -> 9262.2512 | Q3: =O3-P3 -> 4578.4888
A4: Телескоп JCB 533-105 (№3) | B4: 45474 | C4: 0 | D4: =SUMIF($A$30:$A$112,A4,$B$30:$B$112) -> 0 | F4: =C4+D4-E4 -> 0 | G4: 0 | J4: 0 | M4: #N/A | N4: =F4/I4 -> #DIV/0! | O4: =194.94*I4 -> 0 | P4: =F4*$K$25 -> 0 | Q4: =O4-P4 -> 0
A5: Телескоп JCB 535-140 (№4) | B5: 45474 | C5: 110 | D5: =SUMIF($A$30:$A$112,A5,$B$30:$B$112) -> 860 | E5: 115 | F5: =C5+D5-E5 -> 855 | G5: 9280 | H5: 9455 | I5: =H5-G5 -> 175 | J5: 0 | L5: 242 | M5: 3.4 | N5: =F5/I5 -> 4.8857143 | O5: =194.94*I5 -> 34114.5 | P5: =F5*$K$25 -> 43995.693 | Q5: =O5-P5 -> -9881.1932
A6: Телескоп JCB 540-170 №5 | B6: 45474 | C6: 60 | D6: =SUMIF($A$30:$A$112,A6,$B$30:$B$112) -> 0 | E6: 50 | F6: =C6+D6-E6 -> 10 | G6: 0 | I6: =L6*0.53 -> 1.59 | J6: 0 | L6: 3 | M6: 3.4 | N6: =F6/I6 -> 6.2893082 | O6: =194.94*I6 -> 309.9546 | P6: =F6*$K$25 -> 514.56951 | Q6: =O6-P6 -> -204.61491 | R6: не работает мотосчетчик
A7: Виброкаток | B7: 45474 | C7: 85 | D7: =SUMIF($A$30:$A$112,A7,$B$30:$B$112) -> 83 | E7: 150 | F7: =C7+D7-E7 -> 18 | G7: 4948 | H7: 4958 | I7: =H7-G7 -> 10 | J7: 0 | L7: 9 | M7: 5 | N7: =F7/I7 -> 1.8 | O7: =285*I7 -> 2850 | P7: =F7*$K$25 -> 926.22512 | Q7: =O7-P7 -> 1923.7749
A8: Ротор Пегасус | B8: 45474 | C8: 0 | D8: =SUMIF($A$30:$A$112,A8,$B$30:$B$112) -> 0 | F8: =C8+D8-E8 -> 0 | G8: 0 | I8: =H8-G8 -> 0 | J8: 0 | M8: #N/A | N8: =F8/I8 -> #DIV/0! | P8: =F8*$K$25 -> 0 | Q8: =O8-P8 -> 0
A9: Экскаватор JCB | B9: 45474 | C9: 70 | D9: =SUMIF($A$30:$A$112,A9,$B$30:$B$112) -> 800 | E9: 70 | F9: =C9+D9-E9 -> 800 | G9: 17307 | H9: 17434 | I9: =H9-G9 -> 127 | J9: 0 | L9: 198 | M9: 4.1 | N9: =F9/I9 -> 6.2992126 | O9: =235.41*I9 -> 29897.07 | P9: =F9*$K$25 -> 41165.561 | Q9: =O9-P9 -> -11268.491
A10: Экскаватор JCB 3CX 2008 | B10: 45474 | C10: 20 | D10: =SUMIF($A$30:$A$112,A10,$B$30:$B$112) -> 799.94 | E10: 30 | F10: =C10+D10-E10 -> 789.94 | G10: 39553 | H10: 39728 | I10: =H10-G10 -> 175 | J10: 0 | L10: 233 | M10: 4.1 | N10: =F10/I10 -> 4.5139429 | O10: =235.41*I10 -> 41196.75 | P10: =F10*$K$25 -> 40647.904 | Q10: =O10-P10 -> 548.84607
A11: Экскаватор JCB 2013 | B11: 45474 | C11: 10 | D11: =SUMIF($A$30:$A$112,A11,$B$30:$B$112) -> 850 | E11: 15 | F11: =C11+D11-E11 -> 845 | G11: 11904 | H11: 12082 | I11: =H11-G11 -> 178 | J11: 0 | L11: 237 | M11: 4.1 | N11: =F11/I11 -> 4.747191 | O11: =235.41*I11 -> 41902.98 | P11: =F11*$K$25 -> 43481.124 | Q11: =O11-P11 -> -1578.1437
A12: Экскаватор JCB 220 | B12: 45474 | C12: 80 | D12: =SUMIF($A$30:$A$112,A12,$B$30:$B$112) -> 0 | F12: =C12+D12-E12 -> 80 | G12: 7096 | I12: =H12-G12 -> -7096 | J12: 0 | M12: 10.5 | N12: =F12/I12 -> -0.011273957 | O12: =595.65*I12 -> -4226732.4 | P12: =F12*$K$25 -> 4116.5561 | Q12: =O12-P12 -> -4230849
A13: МАЗ 264 | B13: 45474 | C13: 40 | D13: =SUMIF($A$30:$A$112,A13,$B$30:$B$112) -> 400 | E13: 130 | F13: =C13+D13-E13 -> 310 | G13: 31643 | H13: 31832 | I13: =H13-G13 -> 189 | J13: 0 | L13: 175 | M13: 0.9 | N13: =F13/I13 -> 1.6402116 | O13: =(51.3*(I13-K13))+(K13*14.25) -> 9695.7 | P13: =F13*$K$25 -> 15951.655 | Q13: =O13-P13 -> -6255.9548 | R13: слив 15.2 л
A14: МАЗ 265 | B14: 45474 | C14: 140 | D14: =SUMIF($A$30:$A$112,A14,$B$30:$B$112) -> 500 | E14: 150 | F14: =C14+D14-E14 -> 490 | G14: 34719 | H14: 35350 | I14: =H14-G14 -> 631 | J14: 0 | L14: 135 | M14: 0.9 | N14: =F14/I14 -> 0.77654517 | O14: =(51.3*(I14-K14))+(K14*14.25) -> 32370.3 | P14: =F14*$K$25 -> 25213.906 | Q14: =O14-P14 -> 7156.394 | R14: слив 10,47 л
A15: Самосвал Камаз | B15: 45474 | C15: 130 | D15: =SUMIF($A$30:$A$112,A15,$B$30:$B$112) -> 200 | E15: 137 | F15: =C15+D15-E15 -> 193 | G15: 559353 | H15: 559550 | I15: =H15-G15 -> 197 | J15: 0 | L15: 128 | M15: 0.9 | N15: =F15/I15 -> 0.97969543 | O15: =(51.3*(I15-K15))+(K15*19.85) -> 10106.1 | P15: =F15*$K$25 -> 9931.1916 | Q15: =O15-P15 -> 174.90844 | R15: слив 509 л
A16: Самосвал МАЗ | B16: 45474 | C16: 240 | D16: =SUMIF($A$30:$A$112,A16,$B$30:$B$112) -> 59.54 | E16: 160 | F16: =C16+D16-E16 -> 139.54 | G16: 64160 | H16: 64239 | I16: =H16-G16 -> 79 | J16: 0 | L16: 16 | M16: 0.9 | N16: =F16/I16 -> 1.7663291 | O16: =(51.3*(I16-K16))+(K16*19.85) -> 4052.7 | P16: =F16*$K$25 -> 7180.303 | Q16: =O16-P16 -> -3127.603 | R16: слив 16,5 л
A17: РДК 250 | B17: 45474 | C17: 0 | D17: =SUMIF($A$30:$A$112,A17,$B$30:$B$112) -> 0 | F17: =C17+D17-E17 -> 0 | G17: 0 | I17: =H17-G17 -> 0 | J17: 0 | M17: #N/A | N17: =F17/I17 -> #DIV/0! | P17: =F17*$K$25 -> 0 | Q17: =O17-P17 -> 0
A18: Автокран XCMG 55 | B18: 45474 | C18: 130 | D18: =SUMIF($A$30:$A$112,A18,$B$30:$B$112) -> 380 | E18: 190 | F18: =C18+D18-E18 -> 320 | G18: 0 | I18: =L18*0.7 -> 70 | J18: 0 | L18: 100 | M18: 5.1 | N18: =F18/I18 -> 4.5714286 | O18: =290.07*I18 -> 20304.9 | P18: =F18*$K$25 -> 16466.224 | Q18: =O18-P18 -> 3838.6757 | R18: не работает мотосчетчик, слив 127 л
A19: Автокран XCMG | B19: 45474 | C19: 100 | D19: =SUMIF($A$30:$A$112,A19,$B$30:$B$112) -> 570 | E19: 180 | F19: =C19+D19-E19 -> 490 | G19: 5827 | H19: 5973 | I19: =H19-G19 -> 146 | J19: 0 | L19: 274 | M19: 3.2 | N19: =F19/I19 -> 3.3561644 | O19: =182.4*I19 -> 26630.4 | P19: =F19*$K$25 -> 25213.906 | Q19: =O19-P19 -> 1416.494 | R19: слив 3435 л
A20: Автокран Клинцы | B20: 45474 | C20: 230 | D20: =SUMIF($A$30:$A$112,A20,$B$30:$B$112) -> 300 | E20: 230 | F20: =C20+D20-E20 -> 300 | G20: ='[4]Июнь 2024 '!H20 -> 0 | I20: =L20*0.7 -> 16.1 | J20: 0 | K20: 360 | L20: 23 | M20: 2.9 | N20: =F20/I20 -> 18.63354 | O20: =I20*165.3+28.5*K20 -> 12921.33 | P20: =F20*$K$25 -> 15437.085 | Q20: =O20-P20 -> -2515.7553 | R20: не работает мотосчетчик слив 400 л
A21: Подъемник Haulotte №1 | B21: 45474 | C21: ='[4]Июнь 2024 '!E21 -> 0 | D21: =SUMIF($A$30:$A$112,A21,$B$30:$B$112) -> 0 | F21: =C21+D21-E21 -> 0 | G21: ='[4]Июнь 2024 '!H21 -> 0 | I21: 0 | J21: 0 | N21: =VLOOKUP(A21,[4]Тарас!$C$4:$N$23,12,0) -> #N/A | O21: =194.94*I21 -> 0 | P21: =F21*$K$25 -> 0 | Q21: =O21-P21 -> 0
C22: =SUM(C2:C21) -> 1645 | D22: =SUM(D2:D21) -> 5902.48 | E22: =SUM(E2:E21) -> 1647
D23: =D22-B113 -> 0
J25: Стоимость 1 л | K25: =SUM(C30:C112)/B113 -> 51.456951
A28: Заправки АЗС
A29: Наименование | B29: Количество | C29: Сумма | D29: АЗС
A30: Экскаватор JCB | B30: 100 | C30: =B30*47.63 -> 4763 | D30: Авиас
A31: Экскаватор JCB | B31: 100 | C31: =B31*47.63 -> 4763 | D31: Авиас
A32: Экскаватор JCB | B32: 100 | C32: =B32*47.63 -> 4763 | D32: Авиас
A33: Экскаватор JCB | B33: 100 | C33: =B33*47.63 -> 4763 | D33: Авиас
A34: Экскаватор JCB | B34: 100 | C34: =B34*47.63 -> 4763 | D34: Авиас
A35: Экскаватор JCB | B35: 100 | C35: =B35*47.63 -> 4763 | D35: Авиас
A36: Экскаватор JCB | B36: 100 | C36: =B36*47.63 -> 4763 | D36: Авиас
A37: Экскаватор JCB | B37: 100 | C37: =B37*47.63 -> 4763 | D37: Авиас
A38: МАЗ 265 | B38: 100 | C38: =B38*47.63 -> 4763 | D38: Авиас
A39: МАЗ 265 | B39: 100 | C39: =B39*47.63 -> 4763 | D39: Авиас
A40: МАЗ 265 | B40: 100 | C40: =B40*47.63 -> 4763 | D40: Авиас
A41: МАЗ 265 | B41: 100 | C41: =B41*47.63 -> 4763 | D41: Авиас
... A47: МАЗ 264 | B47: 100 | C47: =B47*47.63 -> 4763 | D47: Авиас
E48: =SUM(C30:C48) -> 85734
...

Sheet Топливо Октябрь  2024  (2)
A1: Наименование | B1: Отчетный период | C1: Остаток на начало | D1: Топливо заправленное | E1: Остаток на конец | F1: Расход топлива за период, л | G1: Моточасы на начало | H1: Моточасы на конец | I1: Отработано техникой моточасов | J1: Перегон на доругой объект, л | K1: Перегон на доругой объект, км | L1: Часы работы на обьекте | M1: Норма расхода топлива литр/1 мото час согласно сс | N1: Факт витрат на 1 мото/год, км витрат (л/год) | O1: Отклонения л/мотогод | P1: Отклонения, грн/мес | Q1: Водитель | R1: Примечание по строке | S1: Начислено зп, грн | T1: Разница начисление от недостачи топлива, грн
A2: Телескоп 1 | B2: 45474 | C2: 80 | D2: =SUMIF($A$30:$A$188,A2,$B$30:$B$188) -> 0 | F2: =C2+D2-E2 -> 80 | G2: ='[4]Июнь 2024 '!H2 -> 14075 | I2: =H2-G2 -> -14075 | J2: 0 | L2: 0 | M2: =VLOOKUP(A2,[4]Тарас!$C$4:$P$23,14,0) -> 3.4 | O2: =194.94*I2 -> -2743780.5 | P2: =F2*$K$25 -> 3915.4135 | Q2: =O2-P2 -> -2747695.9
A3: Телескоп 2 | B3: 45566 | C3: 30 | D3: =SUMIF($A$30:$A$188,A3,$B$30:$B$188) -> 1057.02 | E3: 60 | F3: =C3+D3-E3 -> 1027.02 | H3: 10943 | I3: =L3*0.53 -> 94.34 | L3: 178 | M3: 3.4 | N3: =F3/I3 -> 10.886368 | O3: =N3-M3 -> 7.4863685 | P3: =O3*I3*$K$25 -> 34566.445 | Q3: Косик Ю.А. | S3: 2900
A4: Телескоп JCB 533-105 (№3) | B4: 45536 | D4: =SUMIF($A$30:$A$188,A4,$B$30:$B$188) -> 0 | F4: =C4+D4-E4 -> 0 | J4: 0 | M4: #N/A | N4: =F4/I4 -> #DIV/0! | O4: =N4-M4 -> #DIV/0! | P4: =O4*I4*K26 -> #DIV/0!
A5: Телескоп JCB 535-140 (№4) | B5: 45566 | C5: 10 | D5: =SUMIF($A$30:$A$188,A5,$B$30:$B$188) -> 890 | E5: 60 | F5: =C5+D5-E5 -> 840 | G5: 9842 | H5: 10004 | I5: =H5-G5 -> 162 | J5: 0 | L5: 253 | M5: 3.4 | N5: =F5/I5 -> 5.1851852 | O5: =N5-M5 -> 1.7851852 | P5: =O5*I5*$K$25 -> 14154.22 | Q5: Мазуренко Е.В. | S5: 57000 | T5: =S5-P5 -> 42845.78
A6: Телескоп JCB 540-170 №5 | B6: 45566 | C6: 20 | D6: =SUMIF($A$30:$A$188,A6,$B$30:$B$188) -> 828 | E6: 70 | F6: =C6+D6-E6 -> 778 | I6: =L6*0.53 -> 108.65 | J6: 0 | L6: 205 | M6: 3.4 | N6: =F6/I6 -> 7.1606075 | O6: =N6-M6 -> 3.7606075 | P6: =O6*I6*$K$25 -> 19997.485 | Q6: Косик Ю.А. | S6: 33300
A7: Виброкаток | B7: 45566 | C7: 65 | D7: =SUMIF($A$30:$A$188,A7,$B$30:$B$188) -> 60 | E7: 85 | F7: =C7+D7-E7 -> 40 | G7: 4981 | H7: 4992 | I7: =H7-G7 -> 11 | J7: 0 | L7: 3 | M7: 5 | N7: =F7/I7 -> 3.6363636 | O7: =N7-M7 -> -1.3636364 | P7: =O7*I7*K29 -> 0
A8: Ротор Пегасус | B8: 45566 | D8: =SUMIF($A$30:$A$188,A8,$B$30:$B$188) -> 0 | F8: =C8+D8-E8 -> 0 | I8: =H8-G8 -> 0 | J8: 0 | M8: #N/A | N8: =F8/I8 -> #DIV/0! | O8: =N8-M8 -> #DIV/0! | P8: =O8*I8*K30 -> #DIV/0!
A9: Экскаватор JCB | B9: 45566 | C9: 10 | D9: =SUMIF($A$30:$A$188,A9,$B$30:$B$188) -> 840.05 | E9: 50 | F9: =C9+D9-E9 -> 800.05 | G9: 17802 | H9: 18010 | I9: =H9-G9 -> 208 | J9: 0 | L9: 216 | M9: 4.1 | N9: =F9/I9 -> 3.8463942 | O9: =N9-M9 -> -0.25360577 | P9: =O9*I9*K31 -> 0
A10: Экскаватор JCB 3CX 2008 | B10: 45566 | C10: 20 | D10: =SUMIF($A$30:$A$188,A10,$B$30:$B$188) -> 830 | E10: 80 | F10: =C10+D10-E10 -> 770 | I10: =L10*0.55 -> 97.35 | J10: 0 | L10: 177 | M10: 4.1 | N10: =F10/I10 -> 7.9096045 | O10: =N10-M10 -> 3.8096045 | P10: =O10*I10*$K$25 -> 18151.123 | Q10: Ковальчук В.В. | S10: 36400 | T10: =S10-P10 -> 18248.877
A11: Экскаватор JCB 2013 | B11: 45566 | C11: 20 | D11: =SUMIF($A$30:$A$188,A11,$B$30:$B$188) -> 0 | E11: 20 | F11: =C11+D11-E11 -> 0 | I11: =H11-G11 -> 0 | J11: 0 | M11: 4.1 | O11: =N11-M11 -> -4.1 | P11: =O11*I11*K33 -> 0
A12: Экскаватор JCB 220 | B12: 45566 | C12: 301 | D12: =SUMIF($A$30:$A$188,A12,$B$30:$B$188) -> 2127.9 | E12: 129 | F12: =C12+D12-E12 -> 2299.9 | G12: 7387 | H12: 7583 | I12: =H12-G12 -> 196 | J12: 0 | L12: 230 | M12: 10.5 | N12: =F12/I12 -> 11.734184 | O12: =N12-M12 -> 1.2341837 | P12: =O12*I12*K34 -> 0 | R12: gps показывает слив топлива 539 л
A13: МАЗ 264 | B13: 45566 | C13: 150 | D13: =SUMIF($A$30:$A$188,A13,$B$30:$B$188) -> 788.69 | E13: 40 | F13: =C13+D13-E13 -> 898.69 | G13: 32692 | H13: 33450 | I13: =H13-G13 -> 758 | J13: 0 | L13: 214 | M13: 0.9 | N13: =F13/I13 -> 1.1856069 | O13: =N13-M13 -> 0.28560686 | P13: =O13*I13*$K$25 -> 10595.598 | Q13: Черненко А.С/Самойленко | S13: 35300 | T13: =S13-P13 -> 24704.402
A14: МАЗ 265 | B14: 45566 | C14: 160 | D14: =SUMIF($A$30:$A$188,A14,$B$30:$B$188) -> 876.11 | E14: 150 | F14: =C14+D14-E14 -> 886.11 | G14: 37210 | H14: 38463 | I14: =H14-G14 -> 1253 | J14: 0 | K14: 730 | L14: 197 | M14: 0.9 | N14: =F14/I14 -> 0.70719074 | O14: =(51.3*(I14-K14))+(K14*14.25) -> 37232.4 | P14: =F14*$K$25 -> 43368.588 | Q14: =O14-P14 -> -6136.1883
A15: Самосвал Камаз | B15: 45566 | C15: 204 | D15: =SUMIF($A$30:$A$188,A15,$B$30:$B$188) -> 0 | E15: 204 | F15: =C15+D15-E15 -> 0 | G15: 560504 | I15: =H15-G15 -> -560504 | J15: 0 | M15: 0.9 | N15: =F15/I15 -> 0 | O15: =(51.3*(I15-K15))+(K15*19.85) -> -28753855 | P15: =F15*$K$25 -> 0 | Q15: =O15-P15 -> -28753855
A16: Самосвал МАЗ | B16: 45566 | C16: 181 | D16: =SUMIF($A$30:$A$188,A16,$B$30:$B$188) -> 1545.02 | E16: 130 | F16: =C16+D16-E16 -> 1596.02 | G16: 68211 | H16: 70039 | I16: =H16-G16 -> 1828 | J16: 0 | L16: 228 | M16: 0.9 | N16: =F16/I16 -> 0.87309628 | O16: =(51.3*(I16-K16))+(K16*19.85) -> 93776.4 | P16: =F16*$K$25 -> 78113.478 | Q16: =O16-P16 -> 15662.922 | R16: gps показывает слив топлива 169 л
A17: Самосвал МАЗ №2 | B17: 45566 | C17: 160 | D17: =SUMIF($A$30:$A$188,A17,$B$30:$B$188) -> 2237.81 | E17: 150 | F17: =C17+D17-E17 -> 2247.81 | G17: 64118 | H17: 67426 | I17: =H17-G17 -> 3308 | J17: 0 | K17: 730 | L17: 243 | M17: 0.9 | N17: =F17/I17 -> 0.67950726 | O17: =(51.3*(I17-K17))+(K17*19.85) -> 146741.9 | P17: =F17*$K$25 -> 110013.82 | Q17: =O17-P17 -> 36728.079 | R17: gps показывает слив топлива 206 л
A18: РДК 250 | B18: 45566 | D18: =SUMIF($A$30:$A$188,A18,$B$30:$B$188) -> 0 | F18: =C18+D18-E18 -> 0 | I18: =H18-G18 -> 0 | J18: 0 | M18: #N/A | N18: =F18/I18 -> #DIV/0! | P18: =F18*$K$25 -> 0 | Q18: =O18-P18 -> 0
A19: Автокран XCMG 55 | B19: 45566 | C19: 40 | D19: =SUMIF($A$30:$A$188,A19,$B$30:$B$188) -> 260 | E19: 70 | F19: =C19+D19-E19 -> 230 | I19: =L19*0.7 -> 32.2 | J19: 0 | L19: 46 | M19: 5.1 | N19: =F19/I19 -> 7.1428571 | O19: =290.07*I19 -> 9340.254 | P19: =F19*$K$25 -> 11256.814 | Q19: =O19-P19 -> -1916.5598
A20: Автокран XCMG | B20: 45566 | C20: 60 | D20: =SUMIF($A$30:$A$188,A20,$B$30:$B$188) -> 280 | E20: 224 | F20: =C20+D20-E20 -> 116 | G20: 6142 | H20: 6213 | I20: =H20-G20 -> 71 | J20: 0 | L20: 239 | M20: 3.2 | N20: =F20/I20 -> 1.6338028 | O20: =182.4*I20 -> 12950.4 | P20: =F20*$K$25 -> 5677.3496 | Q20: =O20-P20 -> 7273.0504 | R20: gps показывает слив топлива 37,82 л
A21: Автокран Клинцы | B21: 45566 | C21: 152 | D21: =SUMIF($A$30:$A$188,A21,$B$30:$B$188) -> 493.92 | E21: 40 | F21: =C21+D21-E21 -> 605.92 | I21: =L21*0.7 -> 155.4 | J21: 0 | L21: 222 | M21: 2.9 | N21: =F21/I21 -> 3.8990991 | O21: =I21*165.3+28.5*K21 -> 25687.62 | P21: =F21*$K$25 -> 29655.342 | Q21: =O21-P21 -> -3967.7219 | R21: gps показывает слив топлива 168 л
C22: =SUM(C3:C21) -> 1583 | D22: =SUM(D2:D21) -> 13114.52 | E22: =SUM(E2:E21) -> 1562
D23: =D22-B189 -> 0
J25: Стоимость 1 л | K25: =SUM(C30:C188)/B189 -> 48.942669
A28: Заправки АЗС
A29: Наименование | B29: Количество | C29: Сумма | D29: АЗС
A30: Экскаватор JCB | B30: 46.11 | C30: =B30*48.625 -> 2242.0988 | D30: Авиас
A31: Экскаватор JCB | B31: 53.89 | C31: =B31*48.625 -> 2620.4012 | D31: Авиас
A32: Экскаватор JCB | B32: 114.64 | C32: =B32*48.625 -> 5574.37 | D32: Авиас
A33: Экскаватор JCB | B33: 85.36 | C33: =B33*48.625 -> 4150.63 | D33: Авиас
A34: Экскаватор JCB | B34: 100 | C34: =B34*48.625 -> 4862.5 | D34: Авиас
A35: Экскаватор JCB | B35: 100 | C35: =B35*48.625 -> 4862.5 | D35: Авиас
A36: Экскаватор JCB | B36: 100 | C36: =B36*48.625 -> 4862.5 | D36: Авиас
A37: Экскаватор JCB | B37: 40.05 | C37: =B37*48.625 -> 1947.4312 | D37: Авиас
A38: Экскаватор JCB | B38: 100 | C38: =B38*48.625 -> 4862.5 | D38: Авиас
A39: Экскаватор JCB | B39: 100 | C39: =B39*48.625 -> 4862.5 | D39: Авиас
A40: МАЗ 265 | B40: 100 | C40: =B40*48.625 -> 4862.5 | D40: Авиас
A41: МАЗ 265 | B41: 140.01 | C41: =B41*48.625 -> 6807.9862 | D41: Авиас
... A110: Экскаватор JCB 220 | B110: 150 | C110: =B110*48.625 -> 7293.75 | D110: Авиас
A111: Виброкаток | B111: 60 | C111: =B111*48.625 -> 2917.5 | D111: Авиас | E111: =SUM(C30:C111) -> 467974.78
...

Sheet Топливо Октябрь  2024 
A1: Наименование | B1: Отчетный период | C1: Остаток на начало | D1: Топливо заправленное | E1: Остаток на конец | F1: Расход топлива за период, л | G1: Моточасы на начало | H1: Моточасы на конец | I1: Отработано техникой моточасов | J1: Перегон на доругой объект, л | K1: Перегон на доругой объект, км | L1: Часы работы на обьекте | M1: Норма расхода топлива литр/1 мото час согласно сс | N1: Факт витрат на 1 мото/год, км витрат (л/год) | O1: PL план , грн | P1: PL факт , грн | Q1: Diff, грн | R1: Примечание по строке
A2: Телескоп 1 | B2: 45474 | C2: 80 | D2: =SUMIF($A$30:$A$188,A2,$B$30:$B$188) -> 0 | F2: =C2+D2-E2 -> 80 | G2: ='[4]Июнь 2024 '!H2 -> 14075 | I2: =H2-G2 -> -14075 | J2: 0 | L2: 0 | M2: =VLOOKUP(A2,[4]Тарас!$C$4:$P$23,14,0) -> 3.4 | O2: =194.94*I2 -> -2743780.5 | P2: =F2*$K$25 -> 3915.4135 | Q2: =O2-P2 -> -2747695.9
A3: Телескоп 2 | B3: 45566 | C3: 30 | D3: =SUMIF($A$30:$A$188,A3,$B$30:$B$188) -> 1057.02 | E3: 60 | F3: =C3+D3-E3 -> 1027.02 | H3: 10943 | I3: =L3*0.53 -> 94.34 | L3: 178 | M3: 3.4 | N3: =F3/I3 -> 10.886368 | O3: =194.94*I3 -> 18390.64 | P3: =F3*$K$25 -> 50265.1 | Q3: =O3-P3 -> -31874.46
A4: Телескоп JCB 533-105 (№3) | B4: 45536 | D4: =SUMIF($A$30:$A$188,A4,$B$30:$B$188) -> 0 | F4: =C4+D4-E4 -> 0 | J4: 0 | M4: #N/A | N4: =F4/I4 -> #DIV/0! | O4: =194.94*I4 -> 0 | P4: =F4*$K$25 -> 0 | Q4: =O4-P4 -> 0
A5: Телескоп JCB 535-140 (№4) | B5: 45566 | C5: 10 | D5: =SUMIF($A$30:$A$188,A5,$B$30:$B$188) -> 890 | E5: 60 | F5: =C5+D5-E5 -> 840 | G5: 9842 | H5: 10004 | I5: =H5-G5 -> 162 | J5: 0 | L5: 253 | M5: 3.4 | N5: =F5/I5 -> 5.1851852 | O5: =194.94*I5 -> 31580.28 | P5: =F5*$K$25 -> 41111.842 | Q5: =O5-P5 -> -9531.5619
A6: Телескоп JCB 540-170 №5 | B6: 45566 | C6: 20 | D6: =SUMIF($A$30:$A$188,A6,$B$30:$B$188) -> 828 | E6: 70 | F6: =C6+D6-E6 -> 778 | I6: =L6*0.53 -> 108.65 | J6: 0 | L6: 205 | M6: 3.4 | N6: =F6/I6 -> 7.1606075 | O6: =194.94*I6 -> 21180.231 | P6: =F6*$K$25 -> 38077.396 | Q6: =O6-P6 -> -16897.165
A7: Виброкаток | B7: 45566 | C7: 65 | D7: =SUMIF($A$30:$A$188,A7,$B$30:$B$188) -> 60 | E7: 85 | F7: =C7+D7-E7 -> 40 | G7: 4981 | H7: 4992 | I7: =H7-G7 -> 11 | J7: 0 | L7: 3 | M7: 5 | N7: =F7/I7 -> 3.6363636 | O7: =285*I7 -> 3135 | P7: =F7*$K$25 -> 1957.7068 | Q7: =O7-P7 -> 1177.2932
A8: Ротор Пегасус | B8: 45566 | D8: =SUMIF($A$30:$A$188,A8,$B$30:$B$188) -> 0 | F8: =C8+D8-E8 -> 0 | I8: =H8-G8 -> 0 | J8: 0 | M8: #N/A | N8: =F8/I8 -> #DIV/0! | P8: =F8*$K$25 -> 0 | Q8: =O8-P8 -> 0
A9: Экскаватор JCB | B9: 45566 | C9: 10 | D9: =SUMIF($A$30:$A$188,A9,$B$30:$B$188) -> 840.05 | E9: 50 | F9: =C9+D9-E9 -> 800.05 | G9: 17802 | H9: 18010 | I9: =H9-G9 -> 208 | J9: 0 | L9: 216 | M9: 4.1 | N9: =F9/I9 -> 3.8463942 | O9: =235.41*I9 -> 48965.28 | P9: =F9*$K$25 -> 39156.582 | Q9: =O9-P9 -> 9808.6978
A10: Экскаватор JCB 3CX 2008 | B10: 45566 | C10: 20 | D10: =SUMIF($A$30:$A$188,A10,$B$30:$B$188) -> 830 | E10: 80 | F10: =C10+D10-E10 -> 770 | I10: =L10*0.55 -> 97.35 | J10: 0 | L10: 177 | M10: 4.1 | N10: =F10/I10 -> 7.9096045 | O10: =235.41*I10 -> 22917.164 | P10: =F10*$K$25 -> 37685.855 | Q10: =O10-P10 -> -14768.692
A11: Экскаватор JCB 2013 | B11: 45566 | C11: 20 | D11: =SUMIF($A$30:$A$188,A11,$B$30:$B$188) -> 0 | E11: 20 | F11: =C11+D11-E11 -> 0 | I11: =H11-G11 -> 0 | J11: 0 | M11: 4.1 | O11: =235.41*I11 -> 0 | P11: =F11*$K$25 -> 0 | Q11: =O11-P11 -> 0
A12: Экскаватор JCB 220 | B12: 45566 | C12: 301 | D12: =SUMIF($A$30:$A$188,A12,$B$30:$B$188) -> 2127.9 | E12: 129 | F12: =C12+D12-E12 -> 2299.9 | G12: 7387 | H12: 7583 | I12: =H12-G12 -> 196 | J12: 0 | L12: 230 | M12: 10.5 | N12: =F12/I12 -> 11.734184 | O12: =595.65*I12 -> 116747.4 | P12: =F12*$K$25 -> 112563.24 | Q12: =O12-P12 -> 4184.1558 | R12: gps показывает слив топлива 539 л
A13: МАЗ 264 | B13: 45566 | C13: 150 | D13: =SUMIF($A$30:$A$188,A13,$B$30:$B$188) -> 788.69 | E13: 40 | F13: =C13+D13-E13 -> 898.69 | G13: 32692 | H13: 33450 | I13: =H13-G13 -> 758 | J13: 0 | L13: 214 | M13: 0.9 | N13: =F13/I13 -> 1.1856069 | O13: =(51.3*(I13-K13))+(K13*14.25) -> 38885.4 | P13: =F13*$K$25 -> 43984.287 | Q13: =O13-P13 -> -5098.8871
A14: МАЗ 265 | B14: 45566 | C14: 160 | D14: =SUMIF($A$30:$A$188,A14,$B$30:$B$188) -> 876.11 | E14: 150 | F14: =C14+D14-E14 -> 886.11 | G14: 37210 | H14: 38463 | I14: =H14-G14 -> 1253 | J14: 0 | K14: 730 | L14: 197 | M14: 0.9 | N14: =F14/I14 -> 0.70719074 | O14: =(51.3*(I14-K14))+(K14*14.25) -> 37232.4 | P14: =F14*$K$25 -> 43368.588 | Q14: =O14-P14 -> -6136.1883
A15: Самосвал Камаз | B15: 45566 | C15: 204 | D15: =SUMIF($A$30:$A$188,A15,$B$30:$B$188) -> 0 | E15: 204 | F15: =C15+D15-E15 -> 0 | G15: 560504 | I15: =H15-G15 -> -560504 | J15: 0 | M15: 0.9 | N15: =F15/I15 -> 0 | O15: =(51.3*(I15-K15))+(K15*19.85) -> -28753855 | P15: =F15*$K$25 -> 0 | Q15: =O15-P15 -> -28753855
A16: Самосвал МАЗ | B16: 45566 | C16: 181 | D16: =SUMIF($A$30:$A$188,A16,$B$30:$B$188) -> 1545.02 | E16: 130 | F16: =C16+D16-E16 -> 1596.02 | G16: 68211 | H16: 70039 | I16: =H16-G16 -> 1828 | J16: 0 | L16: 228 | M16: 0.9 | N16: =F16/I16 -> 0.87309628 | O16: =(51.3*(I16-K16))+(K16*19.85) -> 93776.4 | P16: =F16*$K$25 -> 78113.478 | Q16: =O16-P16 -> 15662.922 | R16: gps показывает слив топлива 169 л
A17: Самосвал МАЗ №2 | B17: 45566 | C17: 160 | D17: =SUMIF($A$30:$A$188,A17,$B$30:$B$188) -> 2237.81 | E17: 150 | F17: =C17+D17-E17 -> 2247.81 | G17: 64118 | H17: 67426 | I17: =H17-G17 -> 3308 | J17: 0 | K17: 730 | L17: 243 | M17: 0.9 | N17: =F17/I17 -> 0.67950726 | O17: =(51.3*(I17-K17))+(K17*19.85) -> 146741.9 | P17: =F17*$K$25 -> 110013.82 | Q17: =O17-P17 -> 36728.079 | R17: gps показывает слив топлива 206 л
A18: РДК 250 | B18: 45566 | D18: =SUMIF($A$30:$A$188,A18,$B$30:$B$188) -> 0 | F18: =C18+D18-E18 -> 0 | I18: =H18-G18 -> 0 | J18: 0 | M18: #N/A | N18: =F18/I18 -> #DIV/0! | P18: =F18*$K$25 -> 0 | Q18: =O18-P18 -> 0
A19: Автокран XCMG 55 | B19: 45566 | C19: 40 | D19: =SUMIF($A$30:$A$188,A19,$B$30:$B$188) -> 260 | E19: 70 | F19: =C19+D19-E19 -> 230 | I19: =L19*0.7 -> 32.2 | J19: 0 | L19: 46 | M19: 5.1 | N19: =F19/I19 -> 7.1428571 | O19: =290.07*I19 -> 9340.254 | P19: =F19*$K$25 -> 11256.814 | Q19: =O19-P19 -> -1916.5598
A20: Автокран XCMG | B20: 45566 | C20: 60 | D20: =SUMIF($A$30:$A$188,A20,$B$30:$B$188) -> 280 | E20: 224 | F20: =C20+D20-E20 -> 116 | G20: 6142 | H20: 6213 | I20: =H20-G20 -> 71 | J20: 0 | L20: 239 | M20: 3.2 | N20: =F20/I20 -> 1.6338028 | O20: =182.4*I20 -> 12950.4 | P20: =F20*$K$25 -> 5677.3496 | Q20: =O20-P20 -> 7273.0504 | R20: gps показывает слив топлива 37,82 л
A21: Автокран Клинцы | B21: 45566 | C21: 152 | D21: =SUMIF($A$30:$A$188,A21,$B$30:$B$188) -> 493.92 | E21: 40 | F21: =C21+D21-E21 -> 605.92 | I21: =L21*0.7 -> 155.4 | J21: 0 | L21: 222 | M21: 2.9 | N21: =F21/I21 -> 3.8990991 | O21: =I21*165.3+28.5*K21 -> 25687.62 | P21: =F21*$K$25 -> 29655.342 | Q21: =O21-P21 -> -3967.7219 | R21: gps показывает слив топлива 168 л
C22: =SUM(C3:C21) -> 1583 | D22: =SUM(D2:D21) -> 13114.52 | E22: =SUM(E2:E21) -> 1562
D23: =D22-B189 -> 0
J25: Стоимость 1 л | K25: =SUM(C30:C188)/B189 -> 48.942669
A28: Заправки АЗС
A29: Наименование | B29: Количество | C29: Сумма | D29: АЗС
A30: Экскаватор JCB | B30: 46.11 | C30: =B30*48.625 -> 2242.0988 | D30: Авиас
A31: Экскаватор JCB | B31: 53.89 | C31: =B31*48.625 -> 2620.4012 | D31: Авиас
A32: Экскаватор JCB | B32: 114.64 | C32: =B32*48.625 -> 5574.37 | D32: Авиас
A33: Экскаватор JCB | B33: 85.36 | C33: =B33*48.625 -> 4150.63 | D33: Авиас
A34: Экскаватор JCB | B34: 100 | C34: =B34*48.625 -> 4862.5 | D34: Авиас
A35: Экскаватор JCB | B35: 100 | C35: =B35*48.625 -> 4862.5 | D35: Авиас
A36: Экскаватор JCB | B36: 100 | C36: =B36*48.625 -> 4862.5 | D36: Авиас
A37: Экскаватор JCB | B37: 40.05 | C37: =B37*48.625 -> 1947.4312 | D37: Авиас
A38: Экскаватор JCB | B38: 100 | C38: =B38*48.625 -> 4862.5 | D38: Авиас
A39: Экскаватор JCB | B39: 100 | C39: =B39*48.625 -> 4862.5 | D39: Авиас
A40: МАЗ 265 | B40: 100 | C40: =B40*48.625 -> 4862.5 | D40: Авиас
A41: МАЗ 265 | B41: 140.01 | C41: =B41*48.625 -> 6807.9862 | D41: Авиас
... A110: Экскаватор JCB 220 | B110: 150 | C110: =B110*48.625 -> 7293.75 | D110: Авиас
A111: Виброкаток | B111: 60 | C111: =B111*48.625 -> 2917.5 | D111: Авиас | E111: =SUM(C30:C111) -> 467974.78
...

Sheet Топливо Ноябрь  2024 
A1: Наименование | B1: Отчетный период | C1: Остаток на начало | D1: Топливо заправленное | E1: Остаток на конец | F1: Расход топлива за период, л | G1: Моточасы на начало | H1: Моточасы на конец | I1: Отработано техникой моточасов | J1: Перегон на доругой объект, л | K1: Перегон на доругой объект, км | L1: Часы работы на обьекте | M1: Норма расхода топлива литр/1 мото час согласно сс | N1: Факт витрат на 1 мото/год, км витрат (л/год) | O1: Отклонения л/мотогод | P1: Отклонения, грн/мес | Q1: Примечание по строке
A2: Телескоп 1 | B2: 45474 | D2: =SUMIF($A$28:$A$203,A2,$B$28:$B$203) -> 0 | F2: =C2+D2-E2 -> 0 | I2: =H2-G2 -> 0 | J2: 0 | M2: =VLOOKUP(A2,[4]Тарас!$C$4:$P$23,14,0) -> 3.4 | P2: =194.94*I2 -> 0
A3: Телескоп 2 | B3: 45597 | C3: 60 | D3: =SUMIF($A$28:$A$203,A3,$B$28:$B$203) -> 1158.9321 | E3: 80 | F3: =C3+D3-E3 -> 1138.9321 | G3: =10943 -> 10943 | H3: 11154 | I3: =H3-G3 -> 211 | L3: 218 | M3: 4.73 | N3: =F3/I3 -> 5.3977827 | O3: =N3-M3 -> 0.66778269 | P3: =(I3*O3*$K$23) -> 6758.677
A4: Телескоп JCB 535-140 (№4) | B4: 45597 | C4: 60 | D4: =SUMIF($A$28:$A$203,A4,$B$28:$B$203) -> 710 | E4: 30 | F4: =C4+D4-E4 -> 740 | G4: 10004 | H4: 10160 | I4: =H4-G4 -> 156 | J4: 0 | L4: 198 | M4: 4.73 | N4: =F4/I4 -> 4.7435897
A5: Телескоп JCB 540-170 №5 | B5: 45597 | C5: 70 | D5: =SUMIF($A$28:$A$203,A5,$B$28:$B$203) -> 779.92 | E5: 65 | F5: =C5+D5-E5 -> 784.92 | H5: 7961 | I5: =L5*0.65 -> 87.75 | J5: 0 | L5: 135 | M5: 4.73 | N5: =F5/I5 -> 8.9449573 | O5: =N5-M5 -> 4.2149573 | P5: =(I5*O5*$K$23) -> 17741.257 | Q5: моточасы расчетные, данные мотосчетчика на 30.11
A6: Виброкаток | B6: 45597 | C6: 85 | D6: =SUMIF($A$28:$A$203,A6,$B$28:$B$203) -> 352.30256 | E6: 40 | F6: =C6+D6-E6 -> 397.30256 | G6: 4992 | H6: 5089 | I6: =H6-G6 -> 97 | J6: 0 | L6: 194 | M6: 5 | N6: =F6/I6 -> 4.0959027
