Workbook

Sheet ИТОГ
B2: Наименование | C2: Данные PL | D2: Данные ПТО | E2: Разница
B3: АВР закрытые по 30.06.24 | C3: =акты!F55+акты!F56+акты!F57+акты!F58 -> 15836438 | D3: =пто!F4+пто!F5+пто!F12+пто!F13+пто!F14+пто!F16+пто!F18+пто!F20+пто!F21+пто!F22+пто!F23+пто!F24+пто!F25+пто!F26+пто!F27+пто!F28+пто!F29+пто!F30+пто!F32+пто!F33+пто!F34+пто!F39+пто!F40+пто!F41+пто!F45+пто!F46+пто!F47+пто!F48+пто!F51+пто!F52+пто!F53+пто!F55+пто!F58+пто!F60+пто!F61+пто!F67+пто!F69 -> 15836438 | E3: =C3-D3 -> 0
B5: Списание материалов и МШП в бух.учете | C5: =-(списания!E18+списания!E54) -> -4313945.6 | D5: =-(SUM(пто!K4:K69)-пто!K9-пто!K15+списания!E54) -> -4313945.6 | E5: =C5-D5 -> 0 | F5: * в том числе материалы привезенные на ЦЕХ - 199 311,43
B6: Списание материалов Ф2 - арматура | C6: -738944.15 | E6: =C6-D6 -> -738944.15
B7: Производственные затраты без Материалов и МШП | C7: =-14088414.684-C5-C6 -> -9035525
B8: Расход от ивест. Деятельности (ОС) | C8: -488403.69
B9: Общепроизводственные затраты | C9: -19375.688
B10: Административные затраты | C10: =-306715.91 -> -306715.91
B11: Комиссия фин.агента | C11: -539038.97
B13: Прибыль на 30.06.24 | C13: =SUM(C3:C11) -> 394488.81 | E13: =C13/C3 -> 0.024910198 | F13: * % прибыли
B15: АВР проведены в июЛе | C15: =SUM(списания!B43:B48) -> 2600739.4 | D15: =пто!F6+пто!F8+пто!F9+пто!F15+пто!F49+пто!F50 -> 2600739.4 | E15: =C15-D15 -> 0
B16: АВР будут в июЛе | C16: =пто!F7+пто!F10+пто!F11+пто!F17+пто!F31+пто!F36+пто!F37+пто!F44+пто!F57+пто!F62 -> 4358835.5 | D16: =C16 -> 4358835.5 | E16: =C16-D16 -> 0
B17: Списание материалов и МШП к проведенным АВР | C17: =-списания!E43 -> -306048.7 | D17: =C17 -> -306048.7 | E17: =C17-D17 -> 0
B18: Работы к проведенным АВР | C18: =-(пто!H6+пто!H8+пто!H9+пто!H15+пто!H49+пто!H50)*0.5 -> -1142512.8
B19: Списание материалов и МШП к будущим АВР | C19: =-(пто!G7+пто!G11+пто!G17+пто!G44+пто!G57+пто!G62) -> -1822876.3
B20: Работы к будущим АВР | C20: =-(пто!H7+пто!H10+пто!H11+пто!H17+пто!H31+пто!H36+пто!H37+пто!H44+пто!H57+пто!H62)*0.5 -> -1267979.6
B21: Общепроизводственные затраты | C21: =-(C15+C16)*'План-Факт'!D37 -> -22391.202
B22: Административные затраты | C22: =-(C15+C16)*'План-Факт'!D13 -> -721643.3
B23: Комиссия фин.агента | C23: =C11/C3*(C15+C16) -> -236889.26
B24: Ожидаемая прибыль за июль | C24: =SUM(C15:C23) -> 1439233.7 | E24: =C24/(C15+C16) -> 0.20679909 | F24: * % прибыли
B26: Ожидаемая прибыль на 31.07.24 | C26: =C13+C24 -> 1833722.6 | E26: =C26/(C16+C15+C3) -> 0.080440496 | F26: * % прибыли
B27: Данные из бюджета объекта
B28: АВР которые необходимо еще закрыть по объекту | C28: =47882934-C3-C15-C16 -> 25086921
B29: Материалы | C29: ='План-Факт'!B78+'План-Факт'!B75-C19-C17-C5-C6 -> -1268038.3
B30: Работы | C30: ='План-Факт'!B69+'План-Факт'!B68+'План-Факт'!B72-C20-C18-'План-Факт'!C69+'План-Факт'!B61+'План-Факт'!B66+'План-Факт'!B70 -> -4620948.6
B31: Общепроизводственные затраты | C31: =-C28*'План-Факт'!D37 -> -80712.735
B32: Административные затраты | C32: =-C28*'План-Факт'!D13 -> -2601280.8
B33: Комиссия фин.агента | C33: =C11/C3*C28 -> -853905.95
B34: Планируемая прибыль с 01.08 до окончания объекта | C34: =SUM(C28:C33) -> 15662035 | E34: =C34/C28 -> 0.62431076 | F34: * % прибыли
B36: Ожидаемая прибыль с объекта | C36: =C24+C34 -> 17101269 | E36: =C36/(C28+C16+C15+C3) -> 0.35714747 | F36: * % прибыли

Sheet пто
A1: № ДЦ | B1: Найменування договірної ціни | C1: Всього по ДЦ з ПДВ, грн | D1: АКТИ
G2: ЗАКАЗЧИКУ | K2: Списано Бухг
D3: № акта | F3: Всього, грн з ПДВ | G3: Матеріали з ПДВ, грн | H3: Роботи з ПДВ, грн | I3: Статус | J3: Дата | K3: Матеріали з ПДВ, грн
A4: №1 | B4: Деф.акт-Ескіз фундаментної основи під ємність д.12500 та д.8500 мм | C4: 69779.8 | D4: №1 | E4: =IFERROR(VALUE(MID(D4,2,LEN(D4)-1)),"") -> 1 | F4: 74844.2 | G4: 0 | H4: 74844.2 | I4: Оригінал в офісі | J4: 10 04 2024 | L4: =VLOOKUP(F4,списания!B:F,5,0) -> май
A5: №2 | B5: Деф. акт- Демонтажні робіти по пожводопровіду | C5: 2044 | D5: №18 | E5: =IFERROR(VALUE(MID(D5,2,LEN(D5)-1)),"") -> 18 | F5: 2044 | G5: 0 | H5: 2044 | I5: Орігінал в офісі | J5: 26 04 2024 | L5: =VLOOKUP(F5,списания!B:F,5,0) -> май
A6: №3.5.1.5 | B6: 310-2020-5.1.5-КБ-Р-Силос металевий для зберігання насіння | C6: 7883363.1 | D6: №29 | E6: =IFERROR(VALUE(MID(D6,2,LEN(D6)-1)),"") -> 29 | F6: 359694.36 | G6: - | H6: 359694.36 | I6: Орігінал в офісі | J6: 21 06 2024 | L6: =VLOOKUP(F6,списания!B:F,5,0) -> июль
D7: №53 | F7: 1041800.1 | G7: 358436.37 | H7: 683363.7 | I7: Погоджено Замовником | J7: 22 07 2024
A8: №3.5.1.6 | B8: 310-2020-5.1.6-КБ-Р-Силос металевий для зберігання насіння | C8: 7051600.8 | D8: №27 | E8: =IFERROR(VALUE(MID(D8,2,LEN(D8)-1)),"") -> 27 | F8: 330648.58 | G8: 0 | H8: 330648.58 | I8: Орігінал в офісі | J8: 24 05 2024 | L8: =VLOOKUP(F8,списания!B:F,5,0) -> июль
D9: №42 | E9: =IFERROR(VALUE(MID(D9,2,LEN(D9)-1)),"") -> 42 | F9: 908895.93 | G9: 307721.33 | H9: 601174.6 | I9: Орігінал в офісі | J9: 21 06 2024 | K9: =списания!D43 -> 298286 | L9: =VLOOKUP(F9,списания!B:F,5,0) -> июль
D10: №50 | F10: 15568.8 | H10: 15568.8 | I10: Погоджено Замовником | J10: 18 07 2024
D11: №54 | F11: 2738195.3 | G11: 1165791.8 | H11: 1572403.5 | I11: Погоджено Замовником | J11: 22 07 2024
A12: №3.5.1.7 | B12: 310-2020-5.1.7-КБ-Р-Силос металевий для зберігання насіння | C12: 7766307.5 | D12: №15 | E12: =IFERROR(VALUE(MID(D12,2,LEN(D12)-1)),"") -> 15 | F12: 554353 | G12: 0 | H12: 554353 | I12: Орігінал в офісі | J12: 26 04 2024 | L12: =VLOOKUP(F12,списания!B:F,5,0) -> июнь
D13: №28 | E13: =IFERROR(VALUE(MID(D13,2,LEN(D13)-1)),"") -> 28 | F13: 5437399.7 | G13: 2649255.2 | H13: 2788144.5 | I13: Орігінал в офісі | J13: 24 05 2024 | K13: =списания!D31 -> 2607455 | L13: =VLOOKUP(F13,списания!B:F,5,0) -> июнь
D14: №36 | E14: =IFERROR(VALUE(MID(D14,2,LEN(D14)-1)),"") -> 36 | F14: 887716.17 | G14: 122464.17 | H14: 765252 | I14: Оригінал в офісі | J14: 07 06 2024 | K14: =списания!D26 -> 122016.28 | L14: =VLOOKUP(F14,списания!B:F,5,0) -> июнь
D15: №37 | E15: =IFERROR(VALUE(MID(D15,2,LEN(D15)-1)),"") -> 37 | F15: 426150.52 | G15: 7992.5166 | H15: 418158 | I15: Орігінал в офісі | J15: 21 06 2024 | K15: =списания!D45 -> 7762.692 | L15: =VLOOKUP(F15,списания!B:F,5,0) -> июль
A16: №4 | B16: 310-2024-13-КБ Градирня | C16: 403929.07 | D16: №16 | E16: =IFERROR(VALUE(MID(D16,2,LEN(D16)-1)),"") -> 16 | F16: 446461.48 | G16: 95684.599 | H16: 350776.88 | I16: Орігінал в офісі | J16: 26 04 2024 | K16: =списания!D36 -> 69242.124 | L16: =VLOOKUP(F16,списания!B:F,5,0) -> июнь
D17: №49 | F17: 73982.732 | G17: 46197.162 | H17: 27785.57 | I17: Погоджено Замовником | J17: 22 07 2024
A18: №4.1 | B18: Нарощення опор Градирні | C18: 47254.52 | D18: №17 | E18: =IFERROR(VALUE(MID(D18,2,LEN(D18)-1)),"") -> 17 | F18: 47254.52 | G18: 9854.52 | H18: 37400 | I18: Орігінал в офісі | J18: 26 04 2024 | L18: =VLOOKUP(F18,списания!B:F,5,0) -> июнь
A19: №5 | B19: 310-66.3- КБ-Р-Транспортна галерея | C19: 37950.6 | E19: =IFERROR(VALUE(MID(D19,2,LEN(D19)-1)),"")
A20: №6.1 | B20: 310-11.1-КБ-Р-Склад олії; V=4000м3 | C20: 994922 | D20: №10 | E20: =IFERROR(VALUE(MID(D20,2,LEN(D20)-1)),"") -> 10 | F20: 1609186.5 | G20: 680569.72 | H20: 928616.79 | I20: Орігінал в офісі | J20: 26 04 2024 | K20: =списания!D41 -> 599623.55 | L20: =VLOOKUP(F20,списания!B:F,5,0) -> июнь
A21: №6.2 | B21: 310-11.2-КБ-Р-Склад олії; V=2000м3 | C21: 401488.07 | D21: №2 | E21: =IFERROR(VALUE(MID(D21,2,LEN(D21)-1)),"") -> 2 | F21: 585276.82 | G21: 236280.52 | H21: 348996.3 | I21: Орігінал в офісі | J21: 05 04 2024 | K21: =списания!D18 -> 233090.15 | L21: =VLOOKUP(F21,списания!B:F,5,0) -> июнь
A22: №6.3 | B22: 310-11.3-КБ-Р-Склад олії; V=2000м3 | C22: 401488.07 | D22: №3 | E22: =IFERROR(VALUE(MID(D22,2,LEN(D22)-1)),"") -> 3 | F22: 585218.82 | G22: 236280.52 | H22: 348938.3 | I22: Орігінал в офісі | J22: 05 04 2024 | K22: =списания!D19 -> 226340.05 | L22: =VLOOKUP(F22,списания!B:F,5,0) -> июнь
A23: №7 | B23: Демонтаж маслобаку | C23: 70000 | D23: №4 | E23: =IFERROR(VALUE(MID(D23,2,LEN(D23)-1)),"") -> 4 | F23: 70000 | G23: 0 | H23: 70000 | I23: Оригінал в офісі | J23: 10 04 2024 | L23: =VLOOKUP(F23,списания!B:F,5,0) -> май
A24: №8 | B24: 310-66-2-КМ-Норія | C24: 2183910 | D24: №12 | E24: =IFERROR(VALUE(MID(D24,2,LEN(D24)-1)),"") -> 12 | F24: 1027136 | H24: 1027136 | I24: Оригінал в офісі | J24: 10 05 2024 | L24: =VLOOKUP(F24,списания!B:F,5,0) -> июнь
D25: №12.1 | E25: 12.1 | F25: 33000 | H25: 33000 | I25: Оригінал в офісі | J25: 20 05 2024 | L25: =VLOOKUP(F25,списания!B:F,5,0) -> июнь
A26: №9 | B26: 310-66.3-КМ-Транспортна галерея | C26: 644106.1 | D26: №13 | E26: =IFERROR(VALUE(MID(D26,2,LEN(D26)-1)),"") -> 13 | F26: 309258.4 | H26: 309258.4 | I26: Оригінал в офісі | J26: 10 05 2024 | L26: =VLOOKUP(F26,списания!B:F,5,0) -> июнь
A27: №10 | B27: 310-10-КБ-Р-Ділянка експандування | C27: 526703.78 | D27: №23 | E27: =IFERROR(VALUE(MID(D27,2,LEN(D27)-1)),"") -> 23 | F27: 593059.22 | G27: 150765.3 | H27: 442293.92 | I27: Оригінал в офісі | J27: 10 05 2024 | K27: =списания!D34 -> 141649.56 | L27: =VLOOKUP(F27,списания!B:F,5,0) -> июнь
A28: №11 | B28: Влаштування додаткової основи з щебня | C28: 76937.85 | D28: №14 | E28: =IFERROR(VALUE(MID(D28,2,LEN(D28)-1)),"") -> 14 | F28: 27868 | G28: 0 | H28: 27868 | I28: Орігінал в офісі | J28: 26 04 2024 | L28: =VLOOKUP(F28,списания!B:F,5,0) -> июнь
D29: №30 | E29: =IFERROR(VALUE(MID(D29,2,LEN(D29)-1)),"") -> 30 | F29: 27224 | G29: 0 | H29: 27224 | I29: Орігінал в офісі | J29: 24 05 2024 | L29: =VLOOKUP(F29,списания!B:F,5,0) -> июнь
D30: №33 | E30: =IFERROR(VALUE(MID(D30,2,LEN(D30)-1)),"") -> 33 | F30: 28858 | G30: 0 | H30: 28858 | I30: Оригінал в офісі | J30: 07 06 2024 | L30: =VLOOKUP(F30,списания!B:F,5,0) -> июнь
D31: №51 | F31: 5193.4 | G31: 0 | H31: 5193.4 | I31: Погоджено Замовником | J31: 22 07 2024
A32: №12 | B32: Почасовка | C32: 300000 | D32: №11 | E32: =IFERROR(VALUE(MID(D32,2,LEN(D32)-1)),"") -> 11 | F32: 231000 | G32: 0 | H32: 231000 | I32: Орігінал в офісі | J32: 26 04 2024 | L32: =VLOOKUP(F32,списания!B:F,5,0) -> май
D33: №22 | E33: =IFERROR(VALUE(MID(D33,2,LEN(D33)-1)),"") -> 22 | F33: 111000 | G33: 0 | H33: 111000 | I33: Оригінал в офісі | J33: 10 05 2024 | L33: =VLOOKUP(F33,списания!B:F,5,0) -> май
D34: №38 | E34: =IFERROR(VALUE(MID(D34,2,LEN(D34)-1)),"") -> 38 | F34: 106875 | G34: 0 | H34: 106875 | I34: Орігінал в офісі | J34: 21 06 2024 | L34: =VLOOKUP(F34,списания!B:F,5,0) -> июнь
D35: №43 | E35: =IFERROR(VALUE(MID(D35,2,LEN(D35)-1)),"") -> 43 | F35: 83250 | G35: 0 | H35: 83250 | I35: Орігінал в офісі | J35: 15 07 2024
D36: №44 | E36: =IFERROR(VALUE(MID(D36,2,LEN(D36)-1)),"") -> 44 | F36: 33750 | G36: 0 | H36: 33750 | I36: Подано на Замовника | J36: 27 06 2024
D37: №45 | E37: =IFERROR(VALUE(MID(D37,2,LEN(D37)-1)),"") -> 45 | F37: 30375 | G37: 0 | H37: 30375 | I37: Подано на Замовника | J37: 27 06 2024
A38: №13 | B38: 310-ЗВК-Р | E38: =IFERROR(VALUE(MID(D38,2,LEN(D38)-1)),"")
A39: №14 | B39: Дефектовка на демонтаж дорожнього покриття | C39: 92115.83 | D39: №5 | E39: =IFERROR(VALUE(MID(D39,2,LEN(D39)-1)),"") -> 5 | F39: 92115.83 | G39: 0 | H39: 92115.83 | I39: Оригінал в офісі | J39: 12 04 2024 | L39: =VLOOKUP(F39,списания!B:F,5,0) -> май
A40: №15.1 | B40: Дефектовка на тимчасові дороги (під наш кран РДК 250) | C40: 69692.79 | D40: №6 | E40: =IFERROR(VALUE(MID(D40,2,LEN(D40)-1)),"") -> 6 | F40: 69692.79 | G40: 0 | H40: 69692.79 | I40: Оригінал в офісі | J40: 12 04 2024 | L40: =VLOOKUP(F40,списания!B:F,5,0) -> май
...

Sheet акты
A1: Дата | B1: Номер | C1: Контрагент | D1: Сума | E1: Валюта | F1: Підрозділ | G1: Організація | H1: Відповідальний | I1: Коментар
A2: 24.05.2024 09:41:45 | B2: ІБ00-000154 | C2: НІЖИНСЬКИЙ ЖИРКОМБІНАТ ПрАТ | D2: =40920.07*0 -> 0 | E2: грн | F2: Виробничий (Ніжин-3) | G2: ТОВ "ІНДАСТРІАЛБУД" | H2: Хлань Елена | I2: ДЦ № 34 без дати проведення | J2: * в Мае 24
A3: 24.05.2024 09:41:46 | B3: ІБ00-000157 | C3: НІЖИНСЬКИЙ ЖИРКОМБІНАТ ПрАТ | D3: =330648.58*0 -> 0 | E3: грн | F3: Виробничий (Ніжин-3) | G3: ТОВ "ІНДАСТРІАЛБУД" | H3: Хлань Елена | I3: ДЦ № 27 без дати проведення | J3: * в Мае 24
A4: 24.05.2024 09:42:29 | B4: ІБ00-000155 | C4: НІЖИНСЬКИЙ ЖИРКОМБІНАТ ПрАТ | D4: =337206.36*0 -> 0 | E4: грн | F4: Виробничий (Ніжин-3) | G4: ТОВ "ІНДАСТРІАЛБУД" | H4: Хлань Елена | I4: ДЦ № 32 без дати проведення | J4: * в Мае 24
A5: 24.05.2024 09:45:33 | B5: ІБ00-000156 | C5: НІЖИНСЬКИЙ ЖИРКОМБІНАТ ПрАТ | D5: =1900000*0 -> 0 | E5: грн | F5: Виробничий (Ніжин-3) | G5: ТОВ "ІНДАСТРІАЛБУД" | H5: Хлань Елена | I5: ДЦ № 28 без дати проведення | J5: * в Мае 24
A6: 24.05.2024 11:32:39 | B6: ІБ00-000147 | C6: НІЖИНСЬКИЙ ЖИРКОМБІНАТ ПрАТ | D6: 111000 | E6: грн | F6: Виробничий (Ніжин-3) | G6: ТОВ "ІНДАСТРІАЛБУД" | H6: Хлань Елена | I6: Акт № 22 без дати проведення | J6: * в Мае 24
A7: 24.05.2024 11:34:02 | B7: ІБ00-000149 | C7: НІЖИНСЬКИЙ ЖИРКОМБІНАТ ПрАТ | D7: 40991.12 | E7: грн | F7: Виробничий (Ніжин-3) | G7: ТОВ "ІНДАСТРІАЛБУД" | H7: Хлань Елена | I7: Акт № 24 без дати проведення | J7: * в Мае 24
A8: 24.05.2024 11:51:48 | B8: ІБ00-000131 | C8: НІЖИНСЬКИЙ ЖИРКОМБІНАТ ПрАТ | D8: 151220.25 | E8: грн | F8: Виробничий (Ніжин-3) | G8: ТОВ "ІНДАСТРІАЛБУД" | H8: Хлань Елена | I8: Акт № 19 без дати проведення | J8: * в Апреле 24
A9: 24.05.2024 11:52:19 | B9: ІБ00-000132 | C9: НІЖИНСЬКИЙ ЖИРКОМБІНАТ ПрАТ | D9: =48963.26*0 -> 0 | E9: грн | F9: Виробничий (Ніжин-3) | G9: ТОВ "ІНДАСТРІАЛБУД" | H9: Хлань Елена | I9: Акт № 27 без дати проведення | J9: * в Апреле 24
A10: 24.05.2024 11:53:24 | B10: ІБ00-000133 | C10: НІЖИНСЬКИЙ ЖИРКОМБІНАТ ПрАТ | D10: =25935.46*0 -> 0 | E10: грн | F10: Виробничий (Ніжин-3) | G10: ТОВ "ІНДАСТРІАЛБУД" | H10: Хлань Елена | I10: ЦД 31 Акт № без дати проведення | J10: * в Апреле 24
A11: 24.05.2024 12:00:00 | B11: ІБ00-000090 | C11: НІЖИНСЬКИЙ ЖИРКОМБІНАТ ПрАТ | D11: 74844.2 | E11: грн | F11: Виробничий (Ніжин-3) | G11: ТОВ "ІНДАСТРІАЛБУД" | H11: Хлань Елена | I11: Акт № 1 без дати проведення | J11: * в Марте 24
A12: 24.05.2024 12:00:03 | B12: ІБ00-000093 | C12: НІЖИНСЬКИЙ ЖИРКОМБІНАТ ПрАТ | D12: 70000 | E12: грн | F12: Виробничий (Ніжин-3) | G12: ТОВ "ІНДАСТРІАЛБУД" | H12: Хлань Елена | I12: Акт № 4 без дати проведення | J12: * в Марте 24
A13: 24.05.2024 12:00:04 | B13: ІБ00-000095 | C13: НІЖИНСЬКИЙ ЖИРКОМБІНАТ ПрАТ | D13: 92115.83 | E13: грн | F13: Виробничий (Ніжин-3) | G13: ТОВ "ІНДАСТРІАЛБУД" | H13: Хлань Елена | I13: Акт № 5 без дати проведення | J13: * в Марте 24
A14: 24.05.2024 12:00:05 | B14: ІБ00-000096 | C14: НІЖИНСЬКИЙ ЖИРКОМБІНАТ ПрАТ | D14: 69692.79 | E14: грн | F14: Виробничий (Ніжин-3) | G14: ТОВ "ІНДАСТРІАЛБУД" | H14: Хлань Елена | I14: Акт № 6 без дати проведення | J14: * в Марте 24
A15: 24.05.2024 12:00:06 | B15: ІБ00-000097 | C15: НІЖИНСЬКИЙ ЖИРКОМБІНАТ ПрАТ | D15: 220420.19 | E15: грн | F15: Виробничий (Ніжин-3) | G15: ТОВ "ІНДАСТРІАЛБУД" | H15: Хлань Елена | I15: Акт № 7 без дати проведення | J15: * в Марте 24
A16: 24.05.2024 12:00:08 | B16: ІБ00-000099 | C16: НІЖИНСЬКИЙ ЖИРКОМБІНАТ ПрАТ | D16: 8730 | E16: грн | F16: Виробничий (Ніжин-3) | G16: ТОВ "ІНДАСТРІАЛБУД" | H16: Хлань Елена | I16: Акт № 9 без дати проведення | J16: * в Марте 24
A17: 24.05.2024 12:00:15 | B17: ІБ00-000116 | C17: НІЖИНСЬКИЙ ЖИРКОМБІНАТ ПрАТ | D17: 231000 | E17: грн | F17: Виробничий (Ніжин-3) | G17: ТОВ "ІНДАСТРІАЛБУД" | H17: Хлань Елена | I17: Акт № 11 без дати проведення | J17: * в Апреле 24
A18: 24.05.2024 12:00:20 | B18: ІБ00-000121 | C18: НІЖИНСЬКИЙ ЖИРКОМБІНАТ ПрАТ | D18: 2044 | E18: грн | F18: Виробничий (Ніжин-3) | G18: ТОВ "ІНДАСТРІАЛБУД" | H18: Хлань Елена | I18: Акт № 18 без дати проведення | J18: * в Апреле 24
A19: 45474 | B19: ІБ00-000165 | C19: НІЖИНСЬКИЙ ЖИРКОМБІНАТ ПрАТ | D19: =330648.58 -> 330648.58 | E19: грн | F19: Виробничий (Ніжин-3) | G19: ТОВ "ІНДАСТРІАЛБУД" | H19: Хлань Елена | I19: Акт № 27 без дати проведення | J19: * в Мае 24
A20: 31.05.2024 00:00:00 | B20: ІБ00-000181 | C20: НІЖИНСЬКИЙ ЖИРКОМБІНАТ ПрАТ | D20: 337206.36 | E20: грн | F20: Виробничий (Ніжин-3) | G20: ТОВ "ІНДАСТРІАЛБУД" | H20: Хлань Елена | I20: Акт № 31 без дати проведення | J20: * в ИЮНЬ 24
A21: 03.06.2024 00:00:00 | B21: ІБ00-000091 | C21: НІЖИНСЬКИЙ ЖИРКОМБІНАТ ПрАТ | D21: 585276.82 | E21: грн | F21: Виробничий (Ніжин-3) | G21: ТОВ "ІНДАСТРІАЛБУД" | H21: Хлань Елена | I21: Акт № 2 без дати проведення | J21: * в Марте 24
A22: 03.06.2024 00:00:00 | B22: ІБ00-000092 | C22: НІЖИНСЬКИЙ ЖИРКОМБІНАТ ПрАТ | D22: 585218.82 | E22: грн | F22: Виробничий (Ніжин-3) | G22: ТОВ "ІНДАСТРІАЛБУД" | H22: Хлань Елена | I22: Акт № 3 без дати проведення | J22: * в Марте 24
A23: 10.06.2024 00:00:00 | B23: ІБ00-000098 | C23: НІЖИНСЬКИЙ ЖИРКОМБІНАТ ПрАТ | D23: 19075.72 | E23: грн | F23: Виробничий (Ніжин-3) | G23: ТОВ "ІНДАСТРІАЛБУД" | H23: Хлань Елена | I23: Акт № 8 без дати проведення | J23: * в Марте 24
A24: 10.06.2024 00:00:00 | B24: ІБ00-000115 | C24: НІЖИНСЬКИЙ ЖИРКОМБІНАТ ПрАТ | D24: 1609186.5 | E24: грн | F24: Виробничий (Ніжин-3) | G24: ТОВ "ІНДАСТРІАЛБУД" | H24: Хлань Елена | I24: Акт № 10 без дати проведення | J24: * в Апреле 24
A25: 10.06.2024 00:00:00 | B25: ІБ00-000129 | C25: НІЖИНСЬКИЙ ЖИРКОМБІНАТ ПрАТ | D25: 1027136 | E25: грн | F25: Виробничий (Ніжин-3) | G25: ТОВ "ІНДАСТРІАЛБУД" | H25: Хлань Елена | I25: Акт № 12 без дати проведення | J25: * в Апреле 24
A26: 10.06.2024 00:00:00 | B26: ІБ00-000130 | C26: НІЖИНСЬКИЙ ЖИРКОМБІНАТ ПрАТ | D26: 309258.4 | E26: грн | F26: Виробничий (Ніжин-3) | G26: ТОВ "ІНДАСТРІАЛБУД" | H26: Хлань Елена | I26: Акт № 13 без дати проведення | J26: * в Апреле 24
A27: 10.06.2024 00:00:00 | B27: ІБ00-000153 | C27: НІЖИНСЬКИЙ ЖИРКОМБІНАТ ПрАТ | D27: 33000 | E27: грн | F27: Виробничий (Ніжин-3) | G27: ТОВ "ІНДАСТРІАЛБУД" | H27: Хлань Елена | I27: Акт № 12.1 без дати проведення | J27: * в Мае 24
A28: 14.06.2024 00:00:00 | B28: ІБ00-000117 | C28: НІЖИНСЬКИЙ ЖИРКОМБІНАТ ПрАТ | D28: 27868 | E28: грн | F28: Виробничий (Ніжин-3) | G28: ТОВ "ІНДАСТРІАЛБУД" | H28: Хлань Елена | I28: Акт № 14 без дати проведення | J28: * в Апреле 24
A29: 14.06.2024 00:00:00 | B29: ІБ00-000118 | C29: НІЖИНСЬКИЙ ЖИРКОМБІНАТ ПрАТ | D29: 554353 | E29: грн | F29: Виробничий (Ніжин-3) | G29: ТОВ "ІНДАСТРІАЛБУД" | H29: Хлань Елена | I29: Акт № 15 без дати проведення | J29: * в Апреле 24
A30: 14.06.2024 00:00:00 | B30: ІБ00-000119 | C30: НІЖИНСЬКИЙ ЖИРКОМБІНАТ ПрАТ | D30: 446461.48 | E30: грн | F30: Виробничий (Ніжин-3) | G30: ТОВ "ІНДАСТРІАЛБУД" | H30: Хлань Елена | I30: Акт № 16 без дати проведення | J30: * в Апреле 24
A31: 14.06.2024 00:00:00 | B31: ІБ00-000120 | C31: НІЖИНСЬКИЙ ЖИРКОМБІНАТ ПрАТ | D31: 47254.52 | E31: грн | F31: Виробничий (Ніжин-3) | G31: ТОВ "ІНДАСТРІАЛБУД" | H31: Хлань Елена | I31: Акт № 17 без дати проведення | J31: * в Апреле 24
... A42: 17.06.2024 00:00:00 | B42: ІБ00-000185 | C42: НІЖИНСЬКИЙ ЖИРКОМБІНАТ ПрАТ | D42: 887716.17 | E42: грн | F42: Виробничий (Ніжин-3) | G42: ТОВ "ІНДАСТРІАЛБУД" | H42: Хлань Елена | I42: Акт № 36 без дати проведення | J42: * в ИЮНЬ 24
A43: 45448 | B43: ІБ00-000207 | C43: НІЖИНСЬКИЙ ЖИРКОМБІНАТ ПрАТ | D43: 121976.77 | E43: грн | F43: Виробничий (Ніжин-3) | G43: ТОВ "ІНДАСТРІАЛБУД" | H43: Хлань Елена | I43: Акт № 41 | J43: * в ИЮНЬ 24
A44: 01.07.2024 10:05:34 | B44: ІБ00-000208 | C44: НІЖИНСЬКИЙ ЖИРКОМБІНАТ ПрАТ | D44: 908895.93 | E44: грн | F44: Виробничий (Ніжин-3) | G44: ТОВ "ІНДАСТРІАЛБУД" | H44: Хлань Елена | I44: Акт № 42 | J44: * в июЛь 24
A45: 45448 | B45: ІБ00-000209 | C45: НІЖИНСЬКИЙ ЖИРКОМБІНАТ ПрАТ | D45: 69314.5 | E45: грн | F45: Виробничий (Ніжин-3) | G45: ТОВ "ІНДАСТРІАЛБУД" | H45: Хлань Елена | I45: Акт № 40 | J45: * в ИЮНЬ 24
A46: 01.07.2024 10:07:26 | B46: ІБ00-000210 | C46: НІЖИНСЬКИЙ ЖИРКОМБІНАТ ПрАТ | D46: 255300 | E46: грн | F46: Виробничий (Ніжин-3) | G46: ТОВ "ІНДАСТРІАЛБУД" | H46: Хлань Елена | I46: Акт № 39 | J46: * в июЛь 24
A47: 45448 | B47: ІБ00-000211 | C47: НІЖИНСЬКИЙ ЖИРКОМБІНАТ ПрАТ | D47: 106875 | E47: грн | F47: Виробничий (Ніжин-3) | G47: ТОВ "ІНДАСТРІАЛБУД" | H47: Хлань Елена | I47: Акт № 38 | J47: * в ИЮНЬ 24
A48: 01.07.2024 10:08:35 | B48: ІБ00-000212 | C48: НІЖИНСЬКИЙ ЖИРКОМБІНАТ ПрАТ | D48: 426150.52 | E48: грн | F48: Виробничий (Ніжин-3) | G48: ТОВ "ІНДАСТРІАЛБУД" | H48: Хлань Елена | I48: Акт № 37 | J48: * в июЛь 24
A49: 01.07.2024 10:09:56 | B49: ІБ00-000213 | C49: НІЖИНСЬКИЙ ЖИРКОМБІНАТ ПрАТ | D49: 359694.36 | E49: грн | F49: Виробничий (Ніжин-3) | G49: ТОВ "ІНДАСТРІАЛБУД" | H49: Хлань Елена | I49: Акт № 29 | J49: * в июЛь 24
A50: 03.07.2024 00:00:00 | B50: ІБ00-000188 | C50: НІЖИНСЬКИЙ ЖИРКОМБІНАТ ПрАТ | D50: 320050 | E50: грн | F50: Виробничий (Ніжин-3) | G50: ТОВ "ІНДАСТРІАЛБУД" | H50: Хлань Елена | I50: Акт № 35 | J50: * в июЛь 24
...

Sheet списания
A1: Контрагент | B1: Дохід | C1: Собівартість без ПДВ | D1: Собівартість з ПДВ
A2: Договір
A3: Акт
A4: НІЖИНСЬКИЙ ЖИРКОМБІНАТ ПрАТ | B4: =B5 -> 18437177 | C4: =C5 -> 3683902.4 | D4: =D5 -> 4420682.8 | E4: =C4*1.2-D4 -> 0
A5: Договір генпідряду №14/02/24-1ГП від 14.02.2024 | B5: =SUM(B6:B48) -> 18437177 | C5: =SUM(C6:C48) -> 3683902.4 | D5: =SUM(D6:D48) -> 4420682.8
A6: Надання виробничих послуг ІБ00-000090 від 24.05.2024 12:00:00 | B6: 74844.2 | E6: =SUM(D6:D17) -> 0 | F6: май
A7: Надання виробничих послуг ІБ00-000093 від 24.05.2024 12:00:03 | B7: 70000 | F7: май
A8: Надання виробничих послуг ІБ00-000095 від 24.05.2024 12:00:04 | B8: 92115.83 | F8: май
A9: Надання виробничих послуг ІБ00-000096 від 24.05.2024 12:00:05 | B9: 69692.79 | F9: май
A10: Надання виробничих послуг ІБ00-000116 від 24.05.2024 12:00:15 | B10: 231000 | F10: май
A11: Надання виробничих послуг ІБ00-000147 від 24.05.2024 11:32:39 | B11: 111000 | F11: май
A12: Надання виробничих послуг ІБ00-000131 від 24.05.2024 11:51:48 | B12: 151220.25 | F12: май
A13: Надання виробничих послуг ІБ00-000149 від 24.05.2024 11:34:02 | B13: 40991.12 | F13: май
A14: Надання виробничих послуг ІБ00-000121 від 24.05.2024 12:00:20 | B14: 2044 | F14: май
A15: Надання виробничих послуг ІБ00-000097 від 24.05.2024 12:00:06 | B15: 220420.19 | F15: май
A16: Надання виробничих послуг ІБ00-000099 від 24.05.2024 12:00:08 | B16: 8730 | F16: май
A17: Надання виробничих послуг ІБ00-000181 від 31.05.2024 00:00:00 | B17: 337206.36 | F17: май
A18: Надання виробничих послуг ІБ00-000091 від 03.06.2024 00:00:00 | B18: 585276.82 | C18: 194241.79 | D18: =C18*1.2 -> 233090.15 | E18: =SUM(D18:D42) -> 4114634.1 | F18: июнь
A19: Надання виробничих послуг ІБ00-000092 від 03.06.2024 00:00:00 | B19: 585218.82 | C19: 188616.71 | D19: =C19*1.2 -> 226340.05 | F19: июнь
A20: Надання виробничих послуг ІБ00-000207 від 05.06.2024 00:00:00 | B20: 121976.77 | C20: 207.93 | D20: =C20*1.2 -> 249.516 | F20: июнь
A21: Надання виробничих послуг ІБ00-000209 від 05.06.2024 00:00:00 | B21: 69314.5 | F21: июнь
A22: Надання виробничих послуг ІБ00-000211 від 05.06.2024 00:00:00 | B22: 106875 | F22: июнь
A23: Надання виробничих послуг ІБ00-000182 від 05.06.2024 00:00:00 | B23: 145228.5 | F23: июнь
A24: Надання виробничих послуг ІБ00-000183 від 17.06.2024 00:00:00 | B24: 28858 | F24: июнь
A25: Надання виробничих послуг ІБ00-000184 від 05.06.2024 00:00:00 | B25: 325313.9 | F25: июнь
A26: Надання виробничих послуг ІБ00-000185 від 17.06.2024 00:00:00 | B26: 887716.17 | C26: 101680.23 | D26: =C26*1.2 -> 122016.28 | F26: июнь
A27: Надання виробничих послуг ІБ00-000151 від 05.06.2024 00:00:00 | B27: 290457 | F27: июнь
A28: Надання виробничих послуг ІБ00-000152 від 17.06.2024 00:00:00 | B28: 954520.6 | F28: июнь
A29: Надання виробничих послуг ІБ00-000153 від 10.06.2024 00:00:00 | B29: 33000 | F29: июнь
A30: Надання виробничих послуг ІБ00-000163 від 17.06.2024 00:00:00 | B30: 27224 | F30: июнь
A31: Надання виробничих послуг ІБ00-000164 від 17.06.2024 00:00:00 | B31: 5437399.7 | C31: 2172879.2 | D31: =C31*1.2 -> 2607455 | F31: июнь
A32: Надання виробничих послуг ІБ00-000145 від 05.06.2024 00:00:00 | B32: 46960.61 | C32: 7120.18 | D32: =C32*1.2 -> 8544.216 | F32: июнь
A33: Надання виробничих послуг ІБ00-000146 від 17.06.2024 00:00:00 | B33: 148179.73 | C33: 88686.41 | D33: =C33*1.2 -> 106423.69 | F33: июнь
A34: Надання виробничих послуг ІБ00-000148 від 17.06.2024 00:00:00 | B34: 593059.22 | C34: 118041.3 | D34: =C34*1.2 -> 141649.56 | F34: июнь
A35: Надання виробничих послуг ІБ00-000118 від 14.06.2024 00:00:00 | B35: 554353 | F35: июнь
A36: Надання виробничих послуг ІБ00-000119 від 05.06.2024 00:00:00 | B36: 446461.48 | C36: 57701.77 | D36: =C36*1.2 -> 69242.124 | F36: июнь
A37: Надання виробничих послуг ІБ00-000120 від 05.06.2024 00:00:00 | B37: 47254.52 | F37: июнь
A38: Надання виробничих послуг ІБ00-000129 від 10.06.2024 00:00:00 | B38: 1027136 | F38: июнь
A39: Надання виробничих послуг ІБ00-000130 від 10.06.2024 00:00:00 | B39: 309258.4 | F39: июнь
A40: Надання виробничих послуг ІБ00-000098 від 10.06.2024 00:00:00 | B40: 19075.72 | F40: июнь
...

Sheet План-Факт
A1: Статья движения денежных средств | B1: Сумма план объект | C1: Сумма Факт
A2: Доходы | B2: 57463611 | C2: 35121175
A3: Операционная деятельность | B3: 47882934 | C3: 32167708
A4: Поступление от возврата денежных средств | C4: 10000
A5: Поступление от заказчика | B5: 47882934 | C5: 32157708
A6: Прочие поступления
A7: Финансовая деятельность | B7: 9580677 | C7: 2953466.3
A8: Внутригрупповые доходы | C8: 2893466.3
A9: Поступление от Фин агента | B9: 9580677
A10: Транзит Вх | C10: 60000
A11: Списание | B11: -39565497 | C11: -24754361
A12: 1.Операционная деятельность | B12: -28135190 | C12: -21047616
A13: Административные затраты | B13: -2917358 | C13: -900255.84 | D13: =B13/B12 -> 0.10369072
A14: Аренда квартиры | B14: -606500 | C14: -469661.57
A15: Аренда квартиры | B15: -508500 | C15: -413000
A16: Коммунальные платежи | B16: -98000 | C16: -56661.57
A17: Зарплата управленческого персонала | B17: -390670 | C17: -106900
A18: Зарплата PM | B18: -350000 | C18: -106900
A19: Начисления на зарплату PM | B19: -21560
A20: Удержание с зарплаты РМ | B20: -19110
A21: Затраты на командировку | B21: -171700 | C21: -134207.8
A22: Проезд | B22: -40000 | C22: -16896
A23: Суточные | B23: -131700 | C23: -117311.8
A24: Затраты на персонал | C24: -50000
A25: Затраты по корпоративной культуре | C25: -50000
A26: Налоги и сборы | B26: -1436488
A27: Прочие налоги | B27: -1436488
A28: Транспортные затраты | B28: -105000 | C28: -32482.58
A29: ГСМ (топливо) | B29: -105000 | C29: -32482.58
A30: Услуги | B30: -200000 | C30: -106105.49
A31: Представительские затраты | B31: -200000 | C31: -105847.49
A32: Прочие затраты | C32: -258
A33: Услуги банков | B33: -7000 | C33: -398.4
A34: Комиссия банков и др.платежи по РКО | B34: -7000 | C34: -398.4
A35: Юридические услуги | C35: -500
A36: Штраф | C36: -500
A37: Общепроизводственные затраты | B37: -90520 | C37: -46618.05 | D37: =B37/B12 -> 0.0032173232
A38: ИТ расходы | B38: -2520 | C38: -300
A39: Заправка картриджа | B39: -2520
A40: Обслуживание офисной техники | C40: -300
...

Sheet Лист1
A1: Рахунок | B1: 20 | C1: 205 | D1: 207 | E1: 209 | F1: 221
A2: Підрозділи
A3: Податкове призначення
A4: Період
A5: Виробничий (Ніжин-3) | B5: =SUM(B6:B11) -> 4409033.6 | C5: =SUM(C6:C11) -> 4335674.4 | D5: =SUM(D6:D11) -> 2667.7 | E5: =SUM(E6:E11) -> 10194.69 | F5: =SUM(F6:F11) -> 60496.77
A6: 01.02.2024 00:00:00 | B6: =SUM(C6:F6) -> 0
A7: 01.03.2024 00:00:00 | B7: =SUM(C7:F7) -> 497938.51 | C7: 497789.46 | E7: 149.05 | F7: =44599.44*0 -> 0
A8: 01.04.2024 00:00:00 | B8: =SUM(C8:F8) -> 0
A9: 01.05.2024 00:00:00 | B9: =SUM(C9:F9) -> 0
A10: 01.06.2024 00:00:00 | B10: =SUM(C10:F10) -> 3648694.5 | C10: 3583004.6 | D10: 2527.7 | E10: 10025.39 | F10: 53136.82 | G10: =F10*1.2 -> 63764.184
A11: 01.07.2024 00:00:00 | B11: =SUM(C11:F11) -> 262400.53 | C11: 254880.33 | D11: 140 | E11: 20.25 | F11: 7359.95
A13: С НДС | B13: =SUM(C13:F13) -> 5290840.3 | C13: =C5*1.2 -> 5202809.3 | D13: =D5*1.2 -> 3201.24 | E13: =E5*1.2 -> 12233.628 | F13: =F5*1.2 -> 72596.124
A17: МШП | B17: 64740.984
A18: Строительные материалы | B18: 4295429.7
