Workbook

Sheet ноябрь
A5: Замовник: ТОВ "СІА"
A6: Генпідрядник: ТОВ "ДИПРОІНБУД"
A7: Найменування будови та її адреса - Будівництво житлово-громадської забудови з об’єктами соціальної та інженерно-транспортної інфраструктури по вул. Євгена Сверстюка, 4 (колишня вул. Марини Раскової) у Дніпровському районі м. Києва.
A8: Найменування об'єкта - Житловий будинок № 3, секції 5 та 6.
A9: Договір: №14/08/2017-ГПР-III/ГЛ від 14.08.2017 р.
A11: РЕЄСТР АКТІВ ВИКОНАНИХ РОБІТ ПО ОБ'ЄКТУ | J11: 1.03 | V11: 100
A13: № п/п | B13: Вид робіт (витрат) | C13: Найменування робіт | D13: ДЦ | E13: Сума ДЦ | F13: Управлінський облік | H13: Всего управлінський облік | J13: Діпроинбуд | M13: Підрядник | Q13: Перевірка | V13: г/п
F14: листопад 2017()
A15: 1 | B15: 2 | C15: 3 | D15: 4 | F15: 4 | G15: 5 | I15: 7
J16: всього | K16: робота | L16: мат-ли | M16: всього | N16: робота | O16: мат-ли | P16: найменув. | Q16: робота | R16: мат-ли | S16: зараб. 3% | T16: перевірка
A17: 1 | B17: Розробка котловану | C17: грунт | D17: 12102-1 | E17: 657140 | F17: 12102-1/1 | G17: =301810.6 -> 301810.6 | H17: =F17 -> 12102-1/1 | I17: 301810.6 | J17: =(K17+L17)*$J$11 -> 251508.83 | K17: =244183.33 -> 244183.33 | L17: 0 | M17: =N17+O17 -> 336378.6 | N17: =280315.5*1.2 -> 336378.6 | P17: Индустрія | Q17: =K17-N17 -> -92195.27 | R17: =L17-O17 -> 0 | S17: =J17-M17*1.03 -> -94961.128 | T17: =M17*1.03 -> 346469.96 | U17: =J17-M17 -> -84869.77 | V17: =Q17/$V$11*W17 -> -2765.8581 | W17: 3
A18: 2 | B18: Палі основні | C18: палі | D18: 12103-1 | E18: =7254070.69 -> 7254070.7 | F18: 12103-1/1 | G18: =3195761.59 -> 3195761.6 | H18: =F18 -> 12103-1/1 | I18: =G18 -> 3195761.6 | J18: =L18*$J$11+K18 -> 3195761.6 | K18: =743034.22*1.2 -> 891641.06 | L18: =1864175.18*1.2 -> 2237010.2 | M18: =N18+O18 -> 3128651.3 | N18: =743034.22*1.2 -> 891641.06 | O18: =1864175.18*1.2 -> 2237010.2 | P18: Фундамент | Q18: =K19-N18 -> -876120.53 | R18: =L19-O18 -> -2187140.3 | S18: =J18-M18*1.03 -> -26749.232 | T18: =M18*1.03 -> 3222510.8 | U18: =J18-M18 -> 67110.306 | V18: =Q18/$V$11*W18 -> -13141.808 | W18: 1.5
A19: 3 | B19: Палі під баштовий кран | C19: палі кран | D19: 12104-1 | F19: 12104-1/1 | G19: =66886.52 -> 66886.52 | H19: =F19 -> 12104-1/1 | I19: =G19 -> 66886.52 | J19: =L19*$J$11+K19 -> 66886.521 | K19: =12933.78*1.2 -> 15520.536 | L19: =41558.24*1.2 -> 49869.888 | M19: =N19+O19 -> 0 | Q19: =#REF!-N19 -> #REF! | R19: =#REF!-O19 -> #REF! | S19: =J19-M19*1.03 -> 66886.521 | T19: =M19*1.03 -> 0 | U19: =J19-M19 -> 66886.521 | V19: =Q19/$V$11*W19 -> #REF!
A20: 4 | B20: Зняття електроенергії | C20: г/п доп | F20: г/п доп | G20: =-27521.64*1.2 -> -33025.968
B21: ВСЬОГО: | G21: =SUM(G17:G20) -> 3531432.7
B23: Виконав: __________________Кириченко Р.Л. 097-434-82-92
B27: Погоджено __________________________

Sheet Реєстр ДЦ
A1: ДОВІДКА по об'єктам ТОВ "ІНДАСТРІАЛБУД"
A3: № з/п | B3: Об'єкт | C3: Замовник | D3: Найменування робіт (витрат) | E3: №, дата Договору | F3: ДЦ до Договру, грн. з ПДВ | I3: Статус | J3: Собівартість, грн. з ПДВ | M3: Примітки
F4: Разом | G4: Матеріали | H4: Робота | J4: Разом | K4: Матеріали | L4: Робота
A5: 1 | B5: 2 | C5: 3 | D5: 4 | E5: 5 | F5: 6 | G5: 7 | H5: 8 | I5: 9 | J5: 10 | K5: 11 | L5: 12 | M5: 10
A6: 4 | B6: «Нове будівництво олієпресового цеху по переробці насіння соняшника потужністю 1200т/добу з допоміжними будівлями та спорудами внутрішньогосподарського комплексу по виробництву кормів" м.Ладижин, Вінницької області» | C6: ПрАТ "МХП" | D6: Будівництво каркасу оліє-пресового цеху №2 з трансформаторною підстанцією, м.Ладижин, Вінницька область | E6: №389-10 від 19.02.2021 | F6: =9670800 -> 9670800 | G6: =980219.27 -> 980219.27 | H6: =F6-G6 -> 8690580.7 | I6: Погоджено замовником
D7: Додаткові роботи по монтажу/демонтажу з/б балок каркасу, згідно дефектного акту №1 | E7: Д/У№1 до дог. №389-10 від 19.02.2021 | F7: 131336.26 | G7: 41465.11 | H7: =F7-G7 -> 89871.15 | I7: Погоджено замовником | J7: =102739.6 -> 102739.6 | K7: =16812.5 -> 16812.5 | L7: =J7-K7 -> 85927.1 | M7: 0.2783
D8: Влаштування фундаментів допоміжних споруд оліє-пресового цеху по переробці насіння соняшника 1200т/добу | E8: №396-10 від 31.03.2021 | F8: =4080000 -> 4080000 | G8: =2262472.26 -> 2262472.3 | H8: =F8-G8 -> 1817527.7 | I8: Погоджено замовником
D9: Мурування ТП | F9: =1100452.22 -> 1100452.2 | G9: =F9-H9 -> 410866.37 | H9: =689585.85 -> 689585.85 | I9: Внутр. погодження
F10: =SUM(F6:F9) -> 14982588 | G10: =SUM(G6:G9) -> 3695023 | H10: =SUM(H6:H9) -> 11287565
F11: =F10+#REF!+#REF!+#REF! -> #REF! | G11: =G10+#REF!+#REF!+#REF! -> #REF! | H11: =H10+#REF!+#REF!+#REF! -> #REF!

Sheet Реєстр АВР
B1: ДОВІДКА по об'єктам ТОВ "ІНДАСТРІАЛБУД" | D1: 44336
A2: № з/п | B2: Найменування об'єкту | C2: Замовник | D2: № Договору | E2: Загальна вартість Договору з урах.ДУ | H2: Сума АВР | N2: Залишок по Договору
E3: Разом | F3: Матеріали | G3: Робота | H3: № | I3: Разом | J3: Матеріали | K3: Робота | L3: Дата | M3: Статус | N3: Разом | O3: Матеріали | P3: Робота
A4: 4 | B4: «Нове будівництво олієпресового цеху по переробці насіння соняшника потужністю 1200т/добу з допоміжними будівлями та спорудами внутрішньогосподарського комплексу по виробництву кормів" м.Ладижин, Вінницької області» | C4: ПрАТ "МХП" | D4: №389-10 від 19.02.2021 | E4: ='Реєстр ДЦ'!F6 -> 9670800 | F4: ='Реєстр ДЦ'!G6 -> 980219.27 | G4: ='Реєстр ДЦ'!H6 -> 8690580.7 | H4: 1 | I4: =288379.22 -> 288379.22 | J4: =7494.3*1.2 -> 8993.16 | K4: =I4-J4 -> 279386.06 | L4: 44314 | M4: Підписаний | N4: =E4-I8 -> 7863750.8 | O4: =F4-J8 -> 950795.63 | P4: =G4-K8 -> 6912955.1
H5: 2 | I5: =193609.49 -> 193609.49 | J5: 0 | K5: =I5 -> 193609.49 | L5: 44314 | M5: Підписаний
H6: 3 | I6: 266283.61 | J6: =7768.48*1.2 -> 9322.176 | K6: =I6-J6 -> 256961.43 | L6: травень 2021 | M6: Підписаний
H7: 4 | I7: 1058776.9 | J7: =9256.92*1.2 -> 11108.304 | K7: =I7-J7 -> 1047668.6 | L7: травень 2022 | M7: Підписаний
I8: =SUM(I4:I7) -> 1807049.2 | J8: =SUM(J4:J7) -> 29423.64 | K8: =SUM(K4:K7) -> 1777625.6
D9: Д/У№1 до дог.№389-10 від 19.02.2021 | E9: ='Реєстр ДЦ'!F7 -> 131336.26 | F9: ='Реєстр ДЦ'!G7 -> 41465.11 | G9: ='Реєстр ДЦ'!H7 -> 89871.15 | I9: 5042.8 | J9: 0 | K9: =I9-J9 -> 5042.8 | M9: На розгляді у замовника | N9: =E9-I11 -> 126293.46 | O9: =F9-J11 -> 41465.11 | P9: =G9-K11 -> 84828.35
I11: =SUM(I9:I10) -> 5042.8 | J11: =SUM(J9:J10) -> 0 | K11: =SUM(K9:K10) -> 5042.8
D12: №396-10 від 31.03.2021 | E12: ='Реєстр ДЦ'!F8 -> 4080000 | F12: =1885393.55*1.2 -> 2262472.3 | G12: =E12-F12 -> 1817527.7 | N12: =E12-I14 -> 4080000 | O12: =F12-J14 -> 2262472.3 | P12: =G12-K14 -> 1817527.7
I14: =SUM(I12:I13) -> 0 | J14: =SUM(J12:J13) -> 0 | K14: =SUM(K12:K13) -> 0
D15: Нет номера договора | E15: ='Реєстр ДЦ'!F9 -> 1100452.2 | F15: =410866.37 -> 410866.37 | G15: =E15-F15 -> 689585.85 | N15: =E15-I16 -> 1100452.2 | O15: =F15-J16 -> 410866.37 | P15: =G15-K16 -> 689585.85
I16: =SUM(I15) -> 0 | J16: =SUM(J15) -> 0 | K16: =SUM(K15) -> 0
I17: =I8+I11+I14+I16 -> 1812092.1 | J17: =J8+J11+J14+J16 -> 29423.64 | K17: =K8+K11+K14+K16 -> 1782668.4
E18: =SUM(E4:E16) -> 14982588 | F18: =SUM(F4:F16) -> 3695023 | G18: =SUM(G4:G16) -> 11287565 | I18: =#REF!+#REF!+#REF!+I17 -> #REF! | J18: =#REF!+#REF!+#REF!+J17 -> #REF! | K18: =#REF!+#REF!+#REF!+K17 -> #REF! | N18: =SUM(N4:N16) -> 13170496 | O18: =SUM(O4:O16) -> 3665599.4 | P18: =SUM(P4:P16) -> 9504897.1

Sheet Реєстр ДЦ 
A1: Реєстр ДЦ по об'єкту "Реконструкція олійноекстракційного заводу на території ПрАТ «Ніжинський жиркомбінат» за адресою: Чернігівська область м. Ніжин вул. Прилуцька, 2"
A3: № ДЦ | B3: Найменування договірної ціни | C3: Роботи з ПДВ, грн | D3: Матеріали з ПДВ, грн | E3: Всього по ДЦ з ПДВ, грн | F3: Собівартість, грн | G3: Статус | I3: Коментарі
H4: Дата
A6: №1 | B6: Деф.акт-Ескіз фундаментної основи під ємність д.12500 та д.8500 мм | C6: 69779.8 | D6: 0 | E6: 69779.8 | F6: 53555.704 | G6: Оригінал в офісі | H6: 07 03 2024 | J6: ДЦ у відділі ВТВ | K6: заповнюємо колонку коли отримали інформацію і планова дата ССДЦ, або ДЦ ДУ планується і вказуємо що маємо отримати інформацію
A7: №2 | B7: Деф. акт- Демонтажні робіти по пожводопровіду | C7: 2044 | D7: 0 | E7: 2044 | F7: 1470.9162 | G7: Оригінал в офісі | H7: 10 04 2024 | J7: На внутрішньому погодженні | K7: заповнюємо колонку зауваження до ССДЦ якщо є і на кому затримка в погодженні
A8: №3.5.1.5 | B8: 310-2020-5.1.5-КБ-Р-Силос металевий для зберігання насіння | C8: 5179518.5 | D8: 2703844.7 | E8: 7883363.1 | F8: 4754646.8 | G8: Подано на Замовника | H8: 04 06 2024 | J8: Подано на Замовника | K8: заповнюємо колонку коли замовник обіцяє погодити, зауваження якщо є
A9: №3.5.1.6 | B9: 310-2020-5.1.6-КБ-Р-Силос металевий для зберігання насіння | C9: 5158551.5 | D9: 1893049.4 | E9: 7051600.8 | F9: 3860347.5 | G9: Подано на Замовника | H9: 04 06 2024 | J9: Погоджено Замовником | K9: заповнюємо колонку коментарі з датою коли буде оригінал
A10: №3.5.1.7 | B10: 310-2020-5.1.7-КБ-Р-Силос металевий для зберігання насіння | C10: 5110301.6 | D10: 2656005.8 | E10: 7766307.5 | F10: 4730790.1 | G10: Подано на Замовника | H10: 04 06 2024 | J10: Оригінал в офісі | K10: не заповнюємо колонку коментарі
A11: №4 | B11: 310-2024-13-КБ Градирня | C11: =E11-D11 -> 350360.22 | D11: 53568.85 | E11: 403929.07 | F11: 302771.48 | G11: Оригінал в офісі | H11: 13 03 2024
A12: №4.1 | B12: Нарощення опор Градирні | C12: =E12-D12 -> 37400 | D12: 9854.52 | E12: 47254.52 | F12: 29668.176 | G12: Оригінал в офісі | H12: 26 04 2024
A13: №5 | B13: 310-66.3- КБ-Р-Транспортна галерея | C13: =E13-D13 -> 37087.25 | D13: 863.35 | E13: 37950.6 | F13: 19776.593 | G13: Оригінал в офісі | H13: 13 03 2024
A14: №6.1 | B14: 310-11.1-КБ-Р-Склад олії; V=4000м3 | C14: =E14-D14 -> 973903.16 | D14: 21018.84 | E14: 994922 | F14: 401728.42 | G14: Оригінал в офісі | H14: 13 03 2024
A15: №6.2 | B15: 310-11.2-КБ-Р-Склад олії; V=2000м3 | C15: =E15-D15 -> 392335.15 | D15: 9152.92 | E15: 401488.07 | F15: 172537.44 | G15: Оригінал в офісі | H15: 13 03 2024
A16: №6.3 | B16: 310-11.3-КБ-Р-Склад олії; V=2000м3 | C16: =E16-D16 -> 392335.15 | D16: 9152.92 | E16: 401488.07 | F16: 172537.44 | G16: Оригінал в офісі | H16: 13 03 2024
A17: №7 | B17: Демонтаж маслобаку | C17: 70000 | D17: 0 | E17: 70000 | F17: 45779.08 | G17: Оригінал в офісі | H17: 13 03 2024
A18: №8 | B18: 310-66-2-КМ-Норія | C18: =E18-D18 -> 2107510 | D18: 76400 | E18: 2183910 | F18: 1772377.9 | G18: Оригінал в офісі | H18: 13 03 2024
A19: №9 | B19: 310-66.3-КМ-Транспортна галерея | C19: =E19-D19 -> 621686.26 | D19: 22419.84 | E19: 644106.1 | F19: 457768.99 | G19: Оригінал в офісі | H19: 18 03 2024
A20: №10 | B20: 310-10-КБ-Р-Ділянка експандування | C20: =E20-D20 -> 518718.59 | D20: 7985.1936 | E20: 526703.78 | F20: 170608.85 | G20: Оригінал в офісі | H20: 21 03 2024
A21: №11 | B21: Влаштування додаткової основи з щебня | C21: =E21-D21 -> 76937.85 | D21: 0 | E21: 76937.85 | F21: 17455.176 | G21: Оригінал в офісі | H21: 10 04 2024
A22: №12 | B22: Почасовка | C22: =E22-D22 -> 300000 | D22: 0 | E22: 300000 | F22: 164500 | G22: Оригінал в офісі | H22: 10 04 2024
A23: №13 | B23: 310-ЗВК-Р | C23: 660038.21 | D23: 0 | E23: 660038.21 | F23: 300188.17 | G23: Погоджено Замовником | H23: 15 07 2024 | I23: з печаткою у Діми, сьогодні відправить
A24: №14 | B24: Дефектовка на демонтаж дорожнього покриття | C24: 92115.83 | D24: 0 | E24: 92115.83 | F24: 44816.32 | G24: Оригінал в офісі | H24: 05 04 2024
A25: №15.1 | B25: Дефектовка на тимчасові дороги (під наш кран РДК 250) | C25: 69692.79 | D25: 0 | E25: 69692.79 | F25: 44109.52 | G25: Оригінал в офісі | H25: 05 04 2024
A26: №15.2 | B26: Дефектовка на тимчасові дороги (кран замовника) | C26: 130832 | D26: 0 | E26: 130832 | F26: 48252.1 | G26: Оригінал в офісі | H26: 05 04 2024
A27: №15.3 | B27: Демонтаж тимчасові дороги 15.2 | C27: 61643.27 | D27: 0 | E27: 61643.27 | F27: 22365.618 | G27: Оригінал в офісі | H27: 07 06 2024
A28: №16 | B28: ГП310-3-ГП-П- Ніжин Model Благоустрій | C28: 5868795.2 | D28: 0 | E28: 5868795.2 | F28: 2423899.3 | G28: Оригінал в офісі | H28: 12 04 2024
A29: №17 | B29: 310-66-2-КБ-Р Норійна вежа | C29: 1109035 | E29: 1109035 | F29: 656317.54 | G29: Оригінал в офісі | H29: 26 04 2024
A30: №18 | B30: Дефектовка на демонтаж градирні | C30: 220420.19 | D30: 0 | E30: 220420.19 | F30: 172065.93 | G30: Оригінал в офісі | H30: 05 04 2024
A31: №19 | B31: Дефектовка на розроблення та перевезення піску, демонтаж фундаментів | C31: 19075.72 | D31: 0 | E31: 19075.72 | F31: 10869.522 | G31: Оригінал в офісі | H31: 26 04 2024
A32: №20 | B32: Дефектовка на влаштування основи під протипожежний резервуар | C32: 8730 | D32: 0 | E32: 8730 | F32: 4643.86 | G32: Оригінал в офісі | H32: 05 04 2024
A33: №21 | B33: 310-10-КМ-Р- Ділянка експандування | C33: 1821725 | D33: 0 | E33: 1821725 | F33: 1331254.9 | G33: Оригінал в офісі | H33: 12 04 2024
A34: №22 | B34: Монтаж Градирні | C34: 505000 | D34: 0 | E34: 505000 | F34: 298585.15 | G34: Оригінал в офісі | H34: 12 04 2024
A35: №23 | B35: 310-11.4-КБ-Р-Підпірна стінка (склад олії) | C35: 959112.21 | D35: 0 | E35: 959112.21 | F35: 664712.82 | G35: Оригінал в офісі | H35: 12 04 2024
A36: №24.1 | B36: Гідроізоляція Градирні | C36: 16887.37 | D36: 0 | E36: 16887.37 | F36: 9606.6484 | G36: Оригінал в офісі | H36: 01 05 2024
A37: №24.2.1 | B37: Гідроізоляція Силосу 5.1.5 | C37: 35345 | D37: 0 | E37: 35345 | F37: 18769.95 | G37: Оригінал в офісі | H37: 01 05 2024
A38: №24.2.2 | B38: Гідроізоляція Силосу 5.1.6 | C38: 35365.25 | D38: 0 | E38: 35365.25 | F38: 18744.278 | G38: Оригінал в офісі | H38: 01 05 2024
A39: №24.2.3 | B39: Гідроізоляція Силосу 5.1.7 | C39: 35433.65 | D39: 0 | E39: 35433.65 | F39: 18743.161 | G39: Оригінал в офісі | H39: 01 05 2024
A40: №24.3 | B40: Гідроізоляція Норії | C40: 30402.5 | D40: 0 | E40: 30402.5 | F40: 15491.275 | G40: Оригінал в офісі | H40: 01 05 2024
A41: №25 | B41: 310-13-ТХ-Ніжин Градирня | C41: 246953.74 | D41: 0 | E41: 246953.74 | F41: 102324.39 | G41: Оригінал в офісі | H41: 01 05 2024
... A44: №28 | B44: Монтаж транспортоного обладнання | C44: 1900000 | D44: 0 | E44: 1900000 | F44: 798121.95 | G44: Оригінал в офісі | H44: 20 05 2024
...

Sheet РеєстрАВР
A1: Реєстр актів виконаних робіт по об'єкту "Реконструкція олійноекстракційного заводу на території ПрАТ «Ніжинський жиркомбінат» за адресою: Чернігівська область м. Ніжин вул. Прилуцька, 2"
A3: № ДЦ | B3: Найменування договірної ціни | C3: Всього по ДЦ з ПДВ, грн | D3: АКТИ | K3: Коментарі
D5: № акта | F5: Всього, грн з ПДВ | G5: Матеріали з ПДВ, грн | H5: Роботи з ПДВ, грн | I5: Статус | J5: Дата
A6: №1 | B6: Деф.акт-Ескіз фундаментної основи під ємність д.12500 та д.8500 мм | C6: 69779.8 | D6: №1 | E6: =IFERROR(VALUE(MID(D6,2,LEN(D6)-1)),"") -> 1 | F6: 74844.2 | G6: 0 | H6: 74844.2 | I6: Оригінал в офісі | J6: 10 04 2024 | K6: - | L6: АВР у відділі ВТВ | M6: заповнюємо колонку коментарі з датами коли отримали об'єми і коли відправите акт, або коли АВР планується і маєте отримати дані
A7: №2 | B7: Деф. акт- Демонтажні робіти по пожводопровіду | C7: 2044 | D7: №18 | E7: =IFERROR(VALUE(MID(D7,2,LEN(D7)-1)),"") -> 18 | F7: 2044 | G7: 0 | H7: 2044 | I7: Орігінал в офісі | J7: 26 04 2024 | K7: -
A8: №3.5.1.5 | B8: 310-2020-5.1.5-КБ-Р-Силос металевий для зберігання насіння | C8: 7883363.1 | D8: №29 | E8: =IFERROR(VALUE(MID(D8,2,LEN(D8)-1)),"") -> 29 | F8: 359694.36 | G8: - | H8: 359694.36 | I8: Орігінал в офісі | J8: 21 06 2024 | K8: - | L8: Подано на Замовника | M8: заповнюємо колонку коментарі з датою коли замовник обіцяє перевірити і в разі питань пишете які є, не важливо стосовно розцінок чи супутньої документації (основне)
D9: №53 | F9: 1041800.1 | G9: 358436.37 | H9: 683363.7 | I9: Погоджено Замовником | J9: 22 07 2024
A10: №3.5.1.6 | B10: 310-2020-5.1.6-КБ-Р-Силос металевий для зберігання насіння | C10: 7051600.8 | D10: №27 | E10: =IFERROR(VALUE(MID(D10,2,LEN(D10)-1)),"") -> 27 | F10: 330648.58 | G10: 0 | H10: 330648.58 | I10: Орігінал в офісі | J10: 24 05 2024 | K10: - | L10: Погоджено Замовником | M10: заповнюємо колонку коментарі з датою коли буде оригінал
D11: №42 | E11: =IFERROR(VALUE(MID(D11,2,LEN(D11)-1)),"") -> 42 | F11: 908895.93 | G11: 307721.33 | H11: 601174.6 | I11: Орігінал в офісі | J11: 21 06 2024 | K11: так
D12: №50 | F12: 15568.8 | H12: 15568.8 | I12: Погоджено Замовником | J12: 18 07 2024 | K12: з печеткою у Діми
D13: №54 | F13: 2738195.3 | G13: 1165791.8 | H13: 1572403.5 | I13: Погоджено Замовником | J13: 22 07 2024
A14: №3.5.1.7 | B14: 310-2020-5.1.7-КБ-Р-Силос металевий для зберігання насіння | C14: 7766307.5 | D14: №15 | E14: =IFERROR(VALUE(MID(D14,2,LEN(D14)-1)),"") -> 15 | F14: 554353 | G14: 0 | H14: 554353 | I14: Орігінал в офісі | J14: 26 04 2024 | K14: - | L14: Оригінал в офісі | M14: списання так/ні
D15: №28 | E15: =IFERROR(VALUE(MID(D15,2,LEN(D15)-1)),"") -> 28 | F15: 5437399.7 | G15: 2649255.2 | H15: 2788144.5 | I15: Орігінал в офісі | J15: 24 05 2024 | K15: так
D16: №36 | E16: =IFERROR(VALUE(MID(D16,2,LEN(D16)-1)),"") -> 36 | F16: 887716.17 | G16: 122464.17 | H16: 765252 | I16: Оригінал в офісі | J16: 07 06 2024 | K16: так
D17: №37 | E17: =IFERROR(VALUE(MID(D17,2,LEN(D17)-1)),"") -> 37 | F17: 426150.52 | G17: 7992.5166 | H17: 418158 | I17: Орігінал в офісі | J17: 21 06 2024 | K17: так
A18: №4 | B18: 310-2024-13-КБ Градирня | C18: 403929.07 | D18: №16 | E18: =IFERROR(VALUE(MID(D18,2,LEN(D18)-1)),"") -> 16 | F18: 446461.48 | G18: 95684.599 | H18: 350776.88 | I18: Орігінал в офісі | J18: 26 04 2024 | K18: так
D19: №49 | F19: 73982.732 | G19: 46197.162 | H19: 27785.57 | I19: Погоджено Замовником | J19: 22 07 2024 | K19: Свердло?
A20: №4.1 | B20: Нарощення опор Градирні | C20: 47254.52 | D20: №17 | E20: =IFERROR(VALUE(MID(D20,2,LEN(D20)-1)),"") -> 17 | F20: 47254.52 | G20: 9854.52 | H20: 37400 | I20: Орігінал в офісі | J20: 26 04 2024 | K20: так
A21: №5 | B21: 310-66.3- КБ-Р-Транспортна галерея | C21: 37950.6 | E21: =IFERROR(VALUE(MID(D21,2,LEN(D21)-1)),"")
A22: №6.1 | B22: 310-11.1-КБ-Р-Склад олії; V=4000м3 | C22: 994922 | D22: №10 | E22: =IFERROR(VALUE(MID(D22,2,LEN(D22)-1)),"") -> 10 | F22: 1609186.5 | G22: 680569.72 | H22: 928616.79 | I22: Орігінал в офісі | J22: 26 04 2024 | K22: так
A23: №6.2 | B23: 310-11.2-КБ-Р-Склад олії; V=2000м3 | C23: 401488.07 | D23: №2 | E23: =IFERROR(VALUE(MID(D23,2,LEN(D23)-1)),"") -> 2 | F23: 585276.82 | G23: 236280.52 | H23: 348996.3 | I23: Орігінал в офісі | J23: 05 04 2024 | K23: так
A24: №6.3 | B24: 310-11.3-КБ-Р-Склад олії; V=2000м3 | C24: 401488.07 | D24: №3 | E24: =IFERROR(VALUE(MID(D24,2,LEN(D24)-1)),"") -> 3 | F24: 585276.82 | G24: 236280.52 | H24: 348996.3 | I24: Орігінал в офісі | J24: 05 04 2024 | K24: так
A25: №7 | B25: Демонтаж маслобаку | C25: 70000 | D25: №4 | E25: =IFERROR(VALUE(MID(D25,2,LEN(D25)-1)),"") -> 4 | F25: 70000 | G25: 0 | H25: 70000 | I25: Оригінал в офісі | J25: 10 04 2024 | K25: -
A26: №8 | B26: 310-66-2-КМ-Норія | C26: 2183910 | D26: №12 | E26: =IFERROR(VALUE(MID(D26,2,LEN(D26)-1)),"") -> 12 | F26: 1027136 | H26: 1027136 | I26: Оригінал в офісі | J26: 10 05 2024 | K26: -
D27: №12.1 | E27: 12.1 | F27: 33000 | H27: 33000 | I27: Оригінал в офісі | J27: 20 05 2024 | K27: -
A28: №9 | B28: 310-66.3-КМ-Транспортна галерея | C28: 644106.1 | D28: №13 | E28: =IFERROR(VALUE(MID(D28,2,LEN(D28)-1)),"") -> 13 | F28: 309258.4 | H28: 309258.4 | I28: Оригінал в офісі | J28: 10 05 2024 | K28: -
A29: №10 | B29: 310-10-КБ-Р-Ділянка експандування | C29: 526703.78 | D29: №23 | E29: =IFERROR(VALUE(MID(D29,2,LEN(D29)-1)),"") -> 23 | F29: 593059.22 | G29: 150765.3 | H29: 442293.92 | I29: Оригінал в офісі | J29: 10 05 2024 | K29: -
A30: №11 | B30: Влаштування додаткової основи з щебня | C30: 76937.85 | D30: №14 | E30: =IFERROR(VALUE(MID(D30,2,LEN(D30)-1)),"") -> 14 | F30: 27868 | G30: 0 | H30: 27868 | I30: Орігінал в офісі | J30: 26 04 2024 | K30: 5 1 7 -
D31: №30 | E31: =IFERROR(VALUE(MID(D31,2,LEN(D31)-1)),"") -> 30 | F31: 27224 | G31: 0 | H31: 27224 | I31: Орігінал в офісі | J31: 24 05 2024 | K31: 5 1 6 -
D32: №33 | E32: =IFERROR(VALUE(MID(D32,2,LEN(D32)-1)),"") -> 33 | F32: 28858 | G32: 0 | H32: 28858 | I32: Оригінал в офісі | J32: 07 06 2024 | K32: 5 1 5 -
D33: №51 | F33: 5193.4 | G33: 0 | H33: 5193.4 | I33: Погоджено Замовником | J33: 22 07 2024 | K33: планує підпис 19 07
A34: №12 | B34: Почасовка | C34: 300000 | D34: №11 | E34: =IFERROR(VALUE(MID(D34,2,LEN(D34)-1)),"") -> 11 | F34: 231000 | G34: 0 | H34: 231000 | I34: Орігінал в офісі | J34: 26 04 2024 | K34: -
D35: №22 | E35: =IFERROR(VALUE(MID(D35,2,LEN(D35)-1)),"") -> 22 | F35: 111000 | G35: 0 | H35: 111000 | I35: Оригінал в офісі | J35: 10 05 2024 | K35: -
D36: №38 | E36: =IFERROR(VALUE(MID(D36,2,LEN(D36)-1)),"") -> 38 | F36: 106875 | G36: 0 | H36: 106875 | I36: Орігінал в офісі | J36: 21 06 2024 | K36: -
D37: №43 | E37: =IFERROR(VALUE(MID(D37,2,LEN(D37)-1)),"") -> 43 | F37: 83250 | G37: 0 | H37: 83250 | I37: Орігінал в офісі | J37: 15 07 2024 | K37: Переоформлюють табелі, розписують склад робіт
D38: №44 | E38: =IFERROR(VALUE(MID(D38,2,LEN(D38)-1)),"") -> 44 | F38: 33750 | G38: 0 | H38: 33750 | I38: Подано на Замовника | J38: 27 06 2024
D39: №45 | E39: =IFERROR(VALUE(MID(D39,2,LEN(D39)-1)),"") -> 45 | F39: 30375 | G39: 0 | H39: 30375 | I39: Подано на Замовника | J39: 27 06 2024
A40: №13 | B40: 310-ЗВК-Р | E40: =IFERROR(VALUE(MID(D40,2,LEN(D40)-1)),"")
A41: №14 | B41: Дефектовка на демонтаж дорожнього покриття | C41: 92115.83 | D41: №5 | E41: =IFERROR(VALUE(MID(D41,2,LEN(D41)-1)),"") -> 5 | F41: 92115.83 | G41: 0 | H41: 92115.83 | I41: Оригінал в офісі | J41: 12 04 2024 | K41: -
A42: №15.1 | B42: Дефектовка на тимчасові дороги (під наш кран РДК 250) | C42: 69692.79 | D42: №6 | E42: =IFERROR(VALUE(MID(D42,2,LEN(D42)-1)),"") -> 6 | F42: 69692.79 | G42: 0 | H42: 69692.79 | I42: Оригінал в офісі | J42: 12 04 2024 | K42: -
...

Sheet РеєстрАВР (БУХГ)
A1: Реєстр актів виконаних робіт по об'єкту "Реконструкція олійноекстракційного заводу на території ПрАТ «Ніжинський жиркомбінат» за адресою: Чернігівська область м. Ніжин вул. Прилуцька, 2"
A3: № ДЦ | B3: Найменування договірної ціни | C3: Всього по ДЦ з ПДВ, грн | D3: АКТИ | L3: Коментарі
D5: № акта | F5: Всього, грн з ПДВ | G5: Матеріали з ПДВ, грн | H5: Роботи з ПДВ, грн | I5: Статус | J5: Дата | K5: ДАТА В 1С
A6: №1 | B6: Деф.акт-Ескіз фундаментної основи під ємність д.12500 та д.8500 мм | C6: 69779.8 | D6: №1 | E6: =IFERROR(VALUE(MID(D6,2,LEN(D6)-1)),"") -> 1 | F6: 74844.2 | G6: 0 | H6: 74844.2 | I6: Оригінал в офісі | J6: 10 04 2024 | L6: - | M6: АВР у відділі ВТВ | N6: заповнюємо колонку коментарі з датами коли отримали об'єми і коли відправите акт, або коли АВР планується і маєте отримати дані
A7: №2 | B7: Деф. акт- Демонтажні робіти по пожводопровіду | C7: 2044 | D7: №18 | E7: =IFERROR(VALUE(MID(D7,2,LEN(D7)-1)),"") -> 18 | F7: 2044 | G7: 0 | H7: 2044 | I7: Орігінал в офісі | J7: 26 04 2024 | L7: -
A8: №3.5.1.5 | B8: 310-2020-5.1.5-КБ-Р-Силос металевий для зберігання насіння | C8: 7883363.1 | D8: №29 | E8: =IFERROR(VALUE(MID(D8,2,LEN(D8)-1)),"") -> 29 | F8: 359694.36 | G8: - | H8: 359694.36 | I8: Орігінал в офісі | J8: 21 06 2024 | L8: - | M8: Подано на Замовника | N8: заповнюємо колонку коментарі з датою коли замовник обіцяє перевірити і в разі питань пишете які є, не важливо стосовно розцінок чи супутньої документації (основне)
D9: №53 | F9: 1041800.1 | G9: 358436.37 | H9: 683363.7 | I9: Погоджено Замовником | J9: 22 07 2024
A10: №3.5.1.6 | B10: 310-2020-5.1.6-КБ-Р-Силос металевий для зберігання насіння | C10: 7051600.8 | D10: №27 | E10: =IFERROR(VALUE(MID(D10,2,LEN(D10)-1)),"") -> 27 | F10: 330648.58 | G10: 0 | H10: 330648.58 | I10: Орігінал в офісі | J10: 24 05 2024 | L10: - | M10: Погоджено Замовником | N10: заповнюємо колонку коментарі з датою коли буде оригінал
D11: №42 | E11: =IFERROR(VALUE(MID(D11,2,LEN(D11)-1)),"") -> 42 | F11: 908895.93 | G11: 307721.33 | H11: 601174.6 | I11: Орігінал в офісі | J11: 21 06 2024 | L11: так
D12: №50 | F12: 15568.8 | H12: 15568.8 | I12: Погоджено Замовником | J12: 18 07 2024 | L12: з печеткою у Діми
D13: №54 | F13: 2738195.3 | G13: 1165791.8 | H13: 1572403.5 | I13: Погоджено Замовником | J13: 22 07 2024
A14: №3.5.1.7 | B14: 310-2020-5.1.7-КБ-Р-Силос металевий для зберігання насіння | C14: 7766307.5 | D14: №15 | E14: =IFERROR(VALUE(MID(D14,2,LEN(D14)-1)),"") -> 15 | F14: 554353 | G14: 0 | H14: 554353 | I14: Орігінал в офісі | J14: 26 04 2024 | L14: - | M14: Оригінал в офісі | N14: списання так/ні
D15: №28 | E15: =IFERROR(VALUE(MID(D15,2,LEN(D15)-1)),"") -> 28 | F15: 5437399.7 | G15: 2649255.2 | H15: 2788144.5 | I15: Орігінал в офісі | J15: 24 05 2024 | L15: так
D16: №36 | E16: =IFERROR(VALUE(MID(D16,2,LEN(D16)-1)),"") -> 36 | F16: 887716.17 | G16: 122464.17 | H16: 765252 | I16: Оригінал в офісі | J16: 07 06 2024 | L16: так
D17: №37 | E17: =IFERROR(VALUE(MID(D17,2,LEN(D17)-1)),"") -> 37 | F17: 426150.52 | G17: 7992.5166 | H17: 418158 | I17: Орігінал в офісі | J17: 21 06 2024 | L17: так
A18: №4 | B18: 310-2024-13-КБ Градирня | C18: 403929.07 | D18: №16 | E18: =IFERROR(VALUE(MID(D18,2,LEN(D18)-1)),"") -> 16 | F18: 446461.48 | G18: 95684.599 | H18: 350776.88 | I18: Орігінал в офісі | J18: 26 04 2024 | L18: так
D19: №49 | F19: 73982.732 | G19: 46197.162 | H19: 27785.57 | I19: Погоджено Замовником | J19: 22 07 2024 | L19: Свердло?
A20: №4.1 | B20: Нарощення опор Градирні | C20: 47254.52 | D20: №17 | E20: =IFERROR(VALUE(MID(D20,2,LEN(D20)-1)),"") -> 17 | F20: 47254.52 | G20: 9854.52 | H20: 37400 | I20: Орігінал в офісі | J20: 26 04 2024 | L20: так
A21: №5 | B21: 310-66.3- КБ-Р-Транспортна галерея | C21: 37950.6 | E21: =IFERROR(VALUE(MID(D21,2,LEN(D21)-1)),"")
A22: №6.1 | B22: 310-11.1-КБ-Р-Склад олії; V=4000м3 | C22: 994922 | D22: №10 | E22: =IFERROR(VALUE(MID(D22,2,LEN(D22)-1)),"") -> 10 | F22: 1609186.5 | G22: 680569.72 | H22: 928616.79 | I22: Орігінал в офісі | J22: 26 04 2024 | L22: так
A23: №6.2 | B23: 310-11.2-КБ-Р-Склад олії; V=2000м3 | C23: 401488.07 | D23: №2 | E23: =IFERROR(VALUE(MID(D23,2,LEN(D23)-1)),"") -> 2 | F23: 585276.82 | G23: 236280.52 | H23: 348996.3 | I23: Орігінал в офісі | J23: 05 04 2024 | L23: так
A24: №6.3 | B24: 310-11.3-КБ-Р-Склад олії; V=2000м3 | C24: 401488.07 | D24: №3 | E24: =IFERROR(VALUE(MID(D24,2,LEN(D24)-1)),"") -> 3 | F24: 585276.82 | G24: 236280.52 | H24: 348996.3 | I24: Орігінал в офісі | J24: 05 04 2024 | L24: так
A25: №7 | B25: Демонтаж маслобаку | C25: 70000 | D25: №4 | E25: =IFERROR(VALUE(MID(D25,2,LEN(D25)-1)),"") -> 4 | F25: 70000 | G25: 0 | H25: 70000 | I25: Оригінал в офісі | J25: 10 04 2024 | L25: -
A26: №8 | B26: 310-66-2-КМ-Норія | C26: 2183910 | D26: №12 | E26: =IFERROR(VALUE(MID(D26,2,LEN(D26)-1)),"") -> 12 | F26: 1027136 | H26: 1027136 | I26: Оригінал в офісі | J26: 10 05 2024 | L26: -
D27: №12.1 | E27: 12.1 | F27: 33000 | H27: 33000 | I27: Оригінал в офісі | J27: 20 05 2024 | L27: -
A28: №9 | B28: 310-66.3-КМ-Транспортна галерея | C28: 644106.1 | D28: №13 | E28: =IFERROR(VALUE(MID(D28,2,LEN(D28)-1)),"") -> 13 | F28: 309258.4 | H28: 309258.4 | I28: Оригінал в офісі | J28: 10 05 2024 | L28: -
A29: №10 | B29: 310-10-КБ-Р-Ділянка експандування | C29: 526703.78 | D29: №23 | E29: =IFERROR(VALUE(MID(D29,2,LEN(D29)-1)),"") -> 23 | F29: 593059.22 | G29: 150765.3 | H29: 442293.92 | I29: Оригінал в офісі | J29: 10 05 2024 | L29: -
A30: №11 | B30: Влаштування додаткової основи з щебня | C30: 76937.85 | D30: №14 | E30: =IFERROR(VALUE(MID(D30,2,LEN(D30)-1)),"") -> 14 | F30: 27868 | G30: 0 | H30: 27868 | I30: Орігінал в офісі | J30: 26 04 2024 | L30: 5 1 7 -
D31: №30 | E31: =IFERROR(VALUE(MID(D31,2,LEN(D31)-1)),"") -> 30 | F31: 27224 | G31: 0 | H31: 27224 | I31: Орігінал в офісі | J31: 24 05 2024 | L31: 5 1 6 -
D32: №33 | E32: =IFERROR(VALUE(MID(D32,2,LEN(D32)-1)),"") -> 33 | F32: 28858 | G32: 0 | H32: 28858 | I32: Оригінал в офісі | J32: 07 06 2024 | L32: 5 1 5 -
D33: №51 | F33: 5193.4 | G33: 0 | H33: 5193.4 | I33: Погоджено Замовником | J33: 22 07 2024 | L33: планує підпис 19 07
A34: №12 | B34: Почасовка | C34: 300000 | D34: №11 | E34: =IFERROR(VALUE(MID(D34,2,LEN(D34)-1)),"") -> 11 | F34: 231000 | G34: 0 | H34: 231000 | I34: Орігінал в офісі | J34: 26 04 2024 | L34: -
D35: №22 | E35: =IFERROR(VALUE(MID(D35,2,LEN(D35)-1)),"") -> 22 | F35: 111000 | G35: 0 | H35: 111000 | I35: Оригінал в офісі | J35: 10 05 2024 | L35: -
D36: №38 | E36: =IFERROR(VALUE(MID(D36,2,LEN(D36)-1)),"") -> 38 | F36: 106875 | G36: 0 | H36: 106875 | I36: Орігінал в офісі | J36: 21 06 2024 | L36: -
D37: №43 | E37: =IFERROR(VALUE(MID(D37,2,LEN(D37)-1)),"") -> 43 | F37: 83250 | G37: 0 | H37: 83250 | I37: Орігінал в офісі | J37: 15 07 2024 | L37: Переоформлюють табелі, розписують склад робіт
D38: №44 | E38: =IFERROR(VALUE(MID(D38,2,LEN(D38)-1)),"") -> 44 | F38: 33750 | G38: 0 | H38: 33750 | I38: Подано на Замовника | J38: 27 06 2024
D39: №45 | E39: =IFERROR(VALUE(MID(D39,2,LEN(D39)-1)),"") -> 45 | F39: 30375 | G39: 0 | H39: 30375 | I39: Подано на Замовника | J39: 27 06 2024
A40: №13 | B40: 310-ЗВК-Р | E40: =IFERROR(VALUE(MID(D40,2,LEN(D40)-1)),"")
A41: №14 | B41: Дефектовка на демонтаж дорожнього покриття | C41: 92115.83 | D41: №5 | E41: =IFERROR(VALUE(MID(D41,2,LEN(D41)-1)),"") -> 5 | F41: 92115.83 | G41: 0 | H41: 92115.83 | I41: Оригінал в офісі | J41: 12 04 2024 | L41: -
A42: №15.1 | B42: Дефектовка на тимчасові дороги (під наш кран РДК 250) | C42: 69692.79 | D42: №6 | E42: =IFERROR(VALUE(MID(D42,2,LEN(D42)-1)),"") -> 6 | F42: 69692.79 | G42: 0 | H42: 69692.79 | I42: Оригінал в офісі | J42: 12 04 2024 | L42: -
...

Sheet 10 акт переносится
A2: Реєстр актів виконаних робіт по об'єкту "Ладижин -2"
A4: Акт №1 | B4: Вид робіт (витрат) | C4: Договірна ціна | E4: Зміст актів виконаних робіт | F4: Управлінський облік 2021 р. | Y4: Всього управлінський облік | AB4: ТОВ "ІНДАСТРІАЛБУД"
F5: квітень 2021 р. | H5: травень 2021 р. | J5: червень 2021 р. | L5: липень 2021 р. | N5: серпень 2021 р. | P5: вересень 2021 р. | R5: жовтень 2021 р.
C6: № ДЦ | D6: Сумма ДЦ | F6: № акта | G6: сума, грн з ПДВ | H6: № акта | I6: сума, грн з ПДВ | J6: № акта | K6: сума, грн з ПДВ | L6: № акта | M6: сума, грн з ПДВ | N6: № акта | O6: сума, грн з ПДВ | P6: № акта | Q6: сума, грн з ПДВ | R6: № акта | S6: сума, грн з ПДВ | T6: № акта | U6: сума, грн з ПДВ | V6: № акта | W6: сума, грн з ПДВ | Y6: № акта | Z6: сума, грн з ПДВ | AA6: загальна сума | AB6: всього | AC6: робота | AD6: мат-ли
A7: 1 | B7: 2 | C7: 3 | D7: 4 | E7: 5 | F7: 8 | G7: 9 | Y7: 10 | Z7: 11 | AA7: 12 | AB7: 19 | AC7: 20 | AD7: 21
A8: 1 | B8: Будівництво каркасу оліє-пресового цеху №2 з трансформаторною підстанцією, м.Ладижин, Вінницька область | C8: №1 | D8: 9670800 | E8: земля та фундаменти 7.1-7.9, 12.1-12.3 | F8: №1 | G8: =288379.22 -> 288379.22 | Y8: 1 | Z8: 288379.22 | AA8: =SUM(AB8:AB22) -> 8579031.9 | AB8: 288379.22 | AC8: 279386.06 | AD8: 8993.16
E9: земля 10.6, 10.12 | F9: №2 | G9: 193609.49 | Y9: 2 | Z9: 193609.49 | AB9: 193609.49 | AC9: 193609.49 | AD9: 0
E10: земля, фундаменти 7.1-7.9, 12.1-12.3 | H10: №3 | I10: 266283.61 | Y10: 3 | Z10: 266283.61 | AB10: 266283.61 | AC10: 256961.43 | AD10: 9322.176
E11: земля 8.1-8.4 | H11: №4 | I11: 1054954.1 | Y11: 4 | Z11: 1054954.1 | AB11: =Z11 -> 1054954.1 | AC11: 1043855.2 | AD11: 11098.87
E12: земля, фундаменти 16.2 | J12: №5 | K12: 70786.21 | Y12: 5 | Z12: 70786.21 | AB12: 70786.21 | AC12: 68044.39 | AD12: 2741.82
J13: №6 | K13: 862817.57 | Y13: 6 | Z13: 862817.57 | AB13: 862817.57 | AC13: 805192.25 | AD13: 57625.32
J14: №7 | K14: 291462.71 | Y14: 7 | Z14: 291462.71 | AB14: 291462.71 | AC14: 280166.43 | AD14: 11296.28
J15: №8 | K15: 449187.01 | Y15: 8 | Z15: =K15 -> 449187.01 | AB15: =Z15 -> 449187.01 | AC15: 439722.83 | AD15: 9464.18
J16: №9 | K16: 603287.62 | Y16: 9 | Z16: 603287.62 | AB16: 603287.62 | AC16: 595984.13 | AD16: 7303.49
E17: земля, фунд.7.1-7.9, 8.1-8.4, з/б 16.2 | L17: №10 | M17: 941673.71 | Y17: 10 | Z17: =M17 -> 941673.71 | AB17: =Z17 -> 941673.71 | AC17: =AB17-AD17 -> 921997.47 | AD17: 19676.244
E18: земля, щеб., арм.7.1-7.9, 8.1-8.4, з/б 16.2 | L18: №11 | M18: =Z18 -> 293363.47 | Y18: 11 | Z18: 293363.47 | AB18: =Z18 -> 293363.47 | AC18: 290271.42 | AD18: 3092.05
E19: бет.подг., фунд, гідроіз.7.1-7-9,8.1-8.4,16.2 | L19: №12 | M19: 372983.72 | Y19: 12 | Z19: =M19 -> 372983.72 | AB19: =Z19 -> 372983.72 | AC19: 368468.62 | AD19: 4515.1
E20: земля, фунд.7.1-7.9, 8.1-8.4, м/к 16.2 | N20: №13 | O20: 354144.6 | Y20: №13 | Z20: 354144.6 | AB20: 354144.6 | AC20: =Z20-AD20 -> 349857.55 | AD20: 4287.05
E21: перевез, засипка, ущільн 7.1-7.9, 12.1-12.3 | N21: №14 | O21: 177987.94 | Y21: №14 | Z21: =O21 -> 177987.94 | AB21: 177987.94 | AC21: =AB21-AD21 -> 160077.57 | AD21: 17910.37
E22: фундаменти зерносушарки | P22: №15 | Q22: 2358110.9 | Y22: №15 | Z22: =Q22 -> 2358110.9 | AB22: =Z22 -> 2358110.9 | AC22: 1910403.6 | AD22: 447707.33
Y23: всего | Z23: =SUM(Z8:Z22) -> 8579031.9 | AB23: =SUM(AB8:AB22) -> 8579031.9 | AC23: =SUM(AC8:AC22) -> 7963998.4 | AD23: =SUM(AD8:AD22) -> 615033.44
A25: 2 | B25: ДУ 2 від 19.02.2021 Влаштування шпильок під балки покриття ОПЦ №2 | C25: ДУ 2 | D25: 281803.98 | P25: №1 | Q25: 281803.98 | Y25: №1 | Z25: 281803.98 | AA25: =SUM(AB25:AB26) -> 281803.98 | AB25: =AC25+AD25 -> 281803.98 | AC25: =Z25-AD25 -> 251804.03 | AD25: 29999.95
A27: 3 | B27: Додаткові роботи по монтажу/демонтажу з/б балок каркасу, згідно дефектного акту №1 | D27: 131336.26 | H27: №1 | I27: 110363.99 | Y27: 1 | Z27: =I27 -> 110363.99 | AA27: =AB27 -> 110363.99 | AB27: =I27 -> 110363.99 | AC27: =AB27-AD27 -> 85118.37 | AD27: 25245.62
A30: =A8+1 -> 2 | B30: Влаштування фундаментів допоміжних споруд оліє-пресового цеху по переробці насіння соняшника 1200т/добу №396-10 від 23.03.2021 ДУ 1 | C30: №2 | D30: =#REF! -> #REF! | E30: земля, фундаменти ПРм1 9.5-9.6 | H30: №1 | I30: 111154.22 | Y30: №1 | Z30: 111154.22 | AA30: =SUM(AB30:AB44) -> 2293462.3 | AB30: 111154.22 | AC30: =AB30-AD30 -> 44105.48 | AD30: =55873.95*1.2 -> 67048.74
E31: земля, фундаменти ПРм1 9.7-9.8 | J31: №2 | K31: 99020.51 | Y31: №2 | Z31: =K31 -> 99020.51 | AB31: =K31 -> 99020.51 | AC31: 53748.15 | AD31: 45272.36
J32: №3 | K32: 345752.57 | Y32: №3 | Z32: 345752.57 | AB32: 345752.57 | AC32: 231533.51 | AD32: 114219.06
J33: №4 | K33: 103230.59 | V33: =D30-Z45 -> #REF! | Y33: №4 | Z33: 103230.59 | AB33: 103230.59 | AC33: 30347.27 | AD33: 72883.32
J34: №5 | K34: 58541.36 | Y34: №5 | Z34: 58541.36 | AB34: 58541.36 | AC34: 33049.98 | AD34: 25491.38
L35: №6 | M35: 20510.87 | Y35: №6 | Z35: 20510.87 | AB35: 20510.87 | AC35: =Z35-AD35 -> 19006.322 | AD35: 1504.548
L36: №7 | M36: =Z36 -> 112396.12 | Y36: №7 | Z36: 112396.12 | AB36: =Z36 -> 112396.12 | AC36: 57471.424 | AD36: 54924.696
L37: №8 | M37: 36533.03 | Y37: №8 | Z37: =M37 -> 36533.03 | AB37: =Z37 -> 36533.03 | AC37: 32587.68 | AD37: 3945.35
L38: №9 | M38: 282807.74 | Y38: №9 | Z38: =M38 -> 282807.74 | AB38: =Z38 -> 282807.74 | AC38: =AB38-AD38 -> 157013.31 | AD38: 125794.43
R39: №10 | S39: 236670.38 | W39: ВО 27 | X39: =Z39+Z43+Z44 -> 596567.15 | Y39: №10 | Z39: 236670.38 | AB39: 236670.38 | AC39: =AB39-AD39 -> 135826.63 | AD39: 100843.75
R40: №11 | S40: 78675.94 | W40: ВО 24 | X40: =X39+'Реєстр ДЦ '!#REF!+'Реєстр ДЦ '!#REF!+'Реєстр ДЦ '!#REF!+'Реєстр ДЦ '!#REF! -> #REF! | Y40: №11 | Z40: 78675.94 | AB40: 78675.94 | AC40: =AB40-AD40 -> 32607.32 | AD40: 46068.62
R41: №12 | S41: 83218.66 | W41: ВО 23 | Y41: №12 | Z41: 75489.29 | AB41: =Z41 -> 75489.29 | AC41: =AB41-AD41 -> 31514.7 | AD41: 43974.59
R42: №13 | S42: =Z42 -> 372782.87 | W42: ВО 25 | Y42: №13 | Z42: 372782.87 | AB42: =Z42 -> 372782.87 | AC42: =AB42-AD42 -> 152785.19 | AD42: 219997.68
R43: №14 | S43: 328788.29 | W43: ВО 26 | Y43: №14 | Z43: 356228.86 | AB43: =Z43 -> 356228.86 | AC43: =AB43-AD43 -> 201417.04 | AD43: 154811.82
R44: №15 | S44: 12657.74 | W44: ВО 22 | Y44: №15 | Z44: 3667.91 | AB44: =Z44 -> 3667.91 | AC44: =AB44-AD44 -> 2114.51 | AD44: 1553.4
Y45: всего | Z45: =SUM(Z30:Z44) -> 2293462.3 | AB45: =SUM(AB30:AB44) -> 2293462.3 | AC45: =SUM(AC30:AC40) -> 827297.08 | AD45: =AB45-AC45 -> 1466165.2
A47: 3 | B47: Виготовлення і монтаж металоконструкцій ТХ | C47: №3 | D47: 1540968 | N47: №1 | O47: 248026.63 | Y47: №1 | Z47: 248026.63 | AA47: =SUM(AB47:AB51) -> 672881.95 | AB47: 248026.63 | AC47: =Z47-AD47 -> 242763.11 | AD47: 5263.52
...

Sheet материал Ладижин
A2: АВР "Ладижин -2"
D3: МАТЕРІАЛИ
A4: п/п | B4: ДОГОВІР | C4: № акта | D4: БЕЗ ПДВ | E4: З ПДВ
A5: 1 | B5: Будівництво каркасу оліє-пресового цеху №2 з трансформаторною підстанцією, м.Ладижин, Вінницька область №389-10 від 19.02.2021 | C5: №1 | D5: 7494.3 | E5: =D5*1.2 -> 8993.16
C6: №2 | D6: 23.05 | E6: =D6*1.2 -> 27.66
C7: №3 | D7: 7768.48 | E7: =D7*1.2 -> 9322.176
C8: №4 | D8: 9249.06 | E8: =D8*1.2 -> 11098.872
C9: №5 | D9: 2284.84 | E9: =D9*1.2 -> 2741.808
C10: №6 | D10: 48021.11 | E10: =D10*1.2 -> 57625.332
C11: №7 | D11: 9413.57 | E11: =D11*1.2 -> 11296.284
C12: №8 | D12: 7886.82 | E12: =D12*1.2 -> 9464.184
C13: №9 | D13: 6086.26 | E13: =D13*1.2 -> 7303.512
C14: №10 | D14: 16396.86 | E14: =D14*1.2 -> 19676.232
C15: №11 | D15: 2576.71 | E15: =D15*1.2 -> 3092.052
C16: №12 | D16: 3762.57 | E16: =D16*1.2 -> 4515.084
C17: №13 | D17: 3572.55 | E17: =D17*1.2 -> 4287.06
... C19: №15 | D19: 373089.66 | E19: =D19*1.2 -> 447707.59
C20: всего | E20: =SUM(E5:E19) -> 615061.38
A21: 2 | B21: ДУ 2 від 19.02.2021 Влаштування шпильок під балки покриття ОПЦ №2 №389-10 від 19.02.2021 ДУ 2 від 19.02.2021 | C21: №1 | D21: 24999.96 | E21: =D21*1.2 -> 29999.952
A22: 3 | B22: Додаткові роботи по монтажу/демонтажу з/б балок каркасу, згідно дефектного акту №1 Д/У№1 до дог. №389-10 від 19.02.2021 | C22: №1 | D22: 21038.02 | E22: =D22*1.2 -> 25245.624
A23: =A5+1 -> 2 | B23: Влаштування фундаментів допоміжних споруд оліє-пресового цеху по переробці насіння соняшника 1200т/добу №396-10 від 23.03.2021 ДУ 1 | C23: №1 | D23: 55874.91 | E23: =D23*1.2 -> 67049.892
C24: №2 | D24: 37726.97 | E24: =D24*1.2 -> 45272.364
C25: №3 | D25: 95182.55 | E25: =D25*1.2 -> 114219.06
C26: №4 | D26: 60736.1 | E26: =D26*1.2 -> 72883.32
C27: №5 | D27: 21242.81 | E27: =D27*1.2 -> 25491.372
C28: №6 | D28: 1253.78 | E28: =D28*1.2 -> 1504.536
C29: №7 | D29: 45770.58 | E29: =D29*1.2 -> 54924.696
C30: №8 | D30: 3287.79 | E30: =D30*1.2 -> 3945.348
C31: №9 | D31: 104828.68 | E31: =D31*1.2 -> 125794.42
C32: №10 | D32: 38390.54 | E32: =D32*1.2 -> 46068.648
C33: №11 | D33: 33164.52 | E33: =D33*1.2 -> 39797.424
C34: №12 | D34: 171056.73 | E34: =D34*1.2 -> 205268.08
C35: №13 | D35: 59510.96 | E35: =D35*1.2 -> 71413.152
... C41: №19 | D41: 766.9 | E41: =D41*1.2 -> 920.28
C42: всего | E42: =SUM(E23:E41) -> 1193453.6
A43: 3 | B43: Виготовлення і монтаж металоконструкцій ТХ №406-10 від 02.06.2021 | C43: №1 | D43: 4386.25 | E43: =D43*1.2 -> 5263.5
C44: №2 | D44: 4018.36 | E44: =D44*1.2 -> 4822.032
C45: №3 | D45: 3494.95 | E45: =D45*1.2 -> 4193.94
C46: №4 | D46: 3400.86 | E46: =D46*1.2 -> 4081.032
C47: всего | E47: =SUM(E43:E46) -> 18360.504
...

Sheet Пожарка подрядчик
A1: РЕЄСТР ДОГОВІРНИХ ЦІН
A3: № п/п | B3: Вид робіт (витрат) | C3: ознака робіт | D3: Номер ДЦ | E3: Сумма | F3: Статус
A4: 1 | B4: Монтаж системи газ.пожежогасіння машинного приміщення ЛТПП секц.5 | C4: пожарка | D4: №1 | E4: 107970.18 | F4: погоджено
A5: =A4+1 -> 2 | B5: Монтаж системи контролю загазованості секц.5 | C5: пожарка | D5: №2 | E5: 38378.59 | F5: погоджено
A6: =A5+1 -> 3 | B6: Монтаж автоматичної системи оповіщення людей про пожежу секц.5 | C6: пожарка | D6: №3 | E6: 82852.78 | F6: погоджено
A7: =A6+1 -> 4 | B7: Монтаж системи автоматичної пожежної сигналізації секц.5 | C7: пожарка | D7: №4 | E7: 979787.02 | F7: погоджено
A8: =A7+1 -> 5 | B8: Монтаж системи автоматизації протидимного захисту секц.5 | C8: пожарка | D8: №5 | E8: 565478.29 | F8: погоджено
A9: =A8+1 -> 6 | B9: Монтаж системи димовидалення (технологічна частина) секц.5 | C9: пожарка | D9: №6 | E9: 573308.27 | F9: погоджено
A10: =A9+1 -> 7 | B10: Монтаж системи димовидалення (технологічна частина) секц.5 (дод.роботи) | C10: пожарка | D10: №7 | E10: 88842.36 | F10: погоджено
A11: =A10+1 -> 8 | B11: Монтаж системи автоматизації протидимного захисту секц.6 | C11: пожарка | D11: №12 | E11: 589296.65 | F11: погоджено
A12: =A11+1 -> 9 | B12: Монтаж автоматичної системи оповіщення людей про пожежу секц.6 | C12: пожарка | D12: №10 | E12: 100485.89 | F12: погоджено
A13: =A12+1 -> 10 | B13: Монтаж системи газ.пожежогасіння машинного приміщення ЛТПП секц.6 | C13: пожарка | D13: №8 | E13: 107970.18 | F13: погоджено
A14: =A13+1 -> 11 | B14: Монтаж системи контролю загазованості секц.6 | C14: пожарка | D14: №9 | E14: 55788.36 | F14: погоджено
A15: =A14+1 -> 12 | B15: Монтаж системи автоматичної пожежної сигналізації секц.6 | C15: пожарка | D15: №11 | E15: 1129114.1 | F15: погоджено
A16: =A15+1 -> 13 | B16: Монтаж системи димовидалення (технологічна частина) секц.6 | C16: пожарка | D16: №13 | E16: 542099.16 | F16: погоджено
A17: =A16+1 -> 14 | B17: Монтаж системи димовидалення (технологічна частина) секц.6 (дод.роботи) | C17: пожарка | D17: №14 | E17: 91400.04 | F17: погоджено
B18: ВСЬОГО | E18: =SUBTOTAL(109,E4:E17) -> 5052771.8

Sheet Лист1
