Workbook
Name Excel_BuiltIn_Print_Area_4: "#REF!"
Name Excel_BuiltIn_Print_Area_4_1: "#REF!"
Name Excel_BuiltIn_Print_Area_7: "#REF!"
Name Excel_BuiltIn_Print_Area_7_1: "#REF!"
Name Механизаторі: 'МЕХАНИЗАТОРЫ апрель'!$C$7:$C$20
Name Механизаторі: 'МЕХАНИЗАТОРЫ ноябрь'!$C$7:$C$20
Name Механизаторы: 'МЕХАНИЗАТОРЫ апрель'!$C$7:$C$20
Name Механизаторы: 'МЕХАНИЗАТОРЫ ноябрь'!$C$7:$C$20
Name Объекты: [1]Объекты!$B$2:$B$12

Sheet Контакты
A3: № | B3: Наименование | C3: Модель | D3: Год выпуска | E3: Оператор | F3: Место работы на данный момент
A4: 1 | B4: Экскаватор-Погрузчик | C4: JCB 3CX SM 4T | D4: 2007 | E4: Карбунар Ярослав 098-243-50-47 | F4: Староконстантинов
A5: 2 | B5: Экскаватор-Погрузчик | C5: JCB 3CX | D5: 2008 | E5: Горячий Иван 050-560-96-15; Поддубный Гена 050-714-94-57 | F5: Ладыжин
A6: 3 | B6: Экскаватор-Погрузчик | C6: JCB 3CX | D6: 2013 | E6: Нагородняк Славик 098-493-11-38; Чижевский Анатолий 098-613-46-09 | F6: Пологи
A7: 4 | B7: Телескопический Погрузчик | C7: JCB 535-125 | D7: 2008 | E7: Ложечник Богдан 099-451-22-32 Грабищенко Николай 095-462-78-70 | F7: Беловод
A8: 5 | B8: Телескопический Погрузчик | C8: JCB 535-125 | D8: 2011 | E8: Вербицкий Виктор 050-866-01-57 Рудаков Александр 050-130-74-12 | F8: Харьков
A9: 6 | B9: Телескопический Погрузчик | C9: JCB 535-140 | D9: 2013 | E9: Гергель Анатолий 050-859-40-24; Чередниченко Саша 099-264-47-33 | F9: Пологи
A10: 7 | B10: Телескопический Погрузчик | C10: JCB 533-105 | D10: 2012 | E10: Мазуренко Женя 093-340-37-82 | F10: Староконстантинов
A11: 8 | B11: Автокран | C11: Клинцы кс-55713-1к | D11: 2008 | E11: Болох Владимир 068-403-20-82; Вандяк Иван Петрович 096-467-69-88 | F11: Беловод
A12: 9 | B12: Автокран | C12: XCMG Q25K | D12: 2016 | E12: Романюк Миша 097-813-09-30 | F12: Староконстантинов
A13: 10 | B13: Автокран | C13: XCMG QAY55 | D13: 2014 | E13: Січкар Володимир 098-475-35-91 Іванченко Володимир 095-366-69-82 | F13: Ладыжин
A14: 11 | B14: Гусеничный кран | C14: РДК 250 | D14: 1990 | E14: Манчук Сергей 095-003-55-89 | F14: Староконстантинов
A15: 12 | B15: Самосвал | C15: МАЗ 5550 С(№264) | D15: 2019 | E15: Гринько Дима 066-770-58-66; Рябцев Максим 066-619-64-60 | F15: 15.01 перезд Староконстантинов
... A18: 15 | B18: Экскаватор гусеничный | C18: JCB 220 LC | D18: 2013 | E18: Вичев Валерий 066-472-00-73 | F18: Беловод
A19: 16 | B19: Виброкаток | C19: HAMM3307 | D19: 2013 | F19: Староконстантинов
A20: 17 | B20: Роторный телескопический погрузчик | C20: Dieci Pegasus 40.25 | D20: 2008 | E20: Зоря Богдан 097-435-86-58 | F20: Староконстантинов
A21: 18 | B21: Тягач | C21: Ford 1824T | D21: 2020 | E21: Зоря Руслан 068-639-65-53
A22: 19 | B22: Гусеничный кран | C22: РДК 250-3 №2 | E22: Трохименко Виталик 093-114-59-89; | F22: Львов
A23: 20 | B23: Телескопический Погрузчик | C23: 540-170 | E23: Мисюрко Валерий 097-966-15-32 | F23: Львов

Sheet Лист2
A1: ПІБ | B1: ІНН | C1: ІВАН
A2: Аксенчіков Сергій Олександрович | B2: 3457309598 | C2: UA263005280000000262022269551
A3: Антонович Тетяна Сергіївна | B3: 2894801342 | C3: UA093005280000000262062269553
A4: Аулова Маргарита Володимирівна | B4: 3036417408 | C4: UA623005280000000262012269561
A5: Бабошина Ольга Михайлівна | B5: 3584606561 | C5: UA463005280000000262062269566
A6: Бланченко Олександр Миколайович | B6: 2461302113 | C6: UA023005280000000262022282787
A7: Болох Володимир Васильович | B7: 2794610037 | C7: UA643005280000000262041994496
A8: Бондар Ярослав Михайлович | B8: 2772909678 | C8: UA813005280000000262042269573
A9: Борисенко Олексій Миколайович | B9: 2957816213 | C9: UA173005280000000262092288290
A10: Будус Йосип Йосипович | B10: 2892916533 | C10: UA363005280000000262022288286
A11: Бунтило Віталій Іванович | B11: 3000412772 | C11: UA373005280000000262082288297
A12: Бутенко Матвій Анатолійович | B12: 3552110973 | C12: UA933005280000000262062194709
A13: ГАВРИЧЕНКО ОЛЕКСАНДР БОРИСОВИЧ | B13: 2865402633 | C13: UA893005280000000262072265903
... A65: Якубовський Василь Григорович | B65: 2563423013 | C65: UA353005280000000262062288291

Sheet Лист3
G1: год.роботи
F2: + | G2: год.роботы | H2: год.ТО | J2: х | K2: грн
A3: Номер | B3: Подразделение | C3: Ф2 | D3: Назначение платежа | E3: Комментарий | F3: Работы | I3: ТО
A4: 8426 | B4: Телескоп 2 | C4: 25770 | D4: ЗП за 01.01.2024 - 31.01.2024 141 год.роботи х 170 грн. + 18 год.ТО и заправки х 100 грн. = До виплати 25 770 грн. | E4: Савранский І.В. | F4: =VALUE(MID(D4,31,FIND($G$1,D4,1)-31)) -> 141 | G4: =FIND($F$2,D4,1) -> 57 | H4: =FIND($H$2,D4,1) -> 62 | I4: =VALUE(MID(D4,G4+2,H4-G4-2)) -> 18 | J4: =FIND($J$2,D4,1) -> 45 | K4: =FIND($K$2,D4,1) -> 51 | L4: =VALUE(MID(D4,J4+3,K4-J4-3)) -> 170 | M4: 100 | N4: =F4*L4+I4*M4 -> 25770 | O4: 7647.5 | P4: =COUNTIF(#REF!,Лист3!A4) -> #REF!
A5: 8427 | B5: Телескоп JCB 535-140 (№4) | C5: 26350 | D5: ЗП за 01.01.2024 - 31.01.2024 155 год.роботи х 170 грн. + 0 год.ТО и заправки х 100 грн. = До виплати 26 350 грн. | E5: Косік Ю.А. | F5: =VALUE(MID(D5,31,FIND($G$1,D5,1)-31)) -> 155 | G5: =FIND($F$2,D5,1) -> 57 | H5: =FIND($H$2,D5,1) -> 61 | I5: =VALUE(MID(D5,G5+2,H5-G5-2)) -> 0 | J5: =FIND($J$2,D5,1) -> 45 | K5: =FIND($K$2,D5,1) -> 51 | L5: =VALUE(MID(D5,J5+3,K5-J5-3)) -> 170 | M5: 100 | N5: =F5*L5+I5*M5 -> 26350 | O5: 7953.4 | P5: =COUNTIF(#REF!,Лист3!A5) -> #REF!
A6: 8428 | B6: Телескоп JCB 540-170 №5 | C6: 30610 | D6: ЗП за 01.01.2024 - 31.01.2024 163 год.роботи х 170 грн. + 29 год.ТО и заправки х 100 грн. = До виплати 30 610 грн. | E6: Горячий І.В. | F6: =VALUE(MID(D6,31,FIND($G$1,D6,1)-31)) -> 163 | G6: =FIND($F$2,D6,1) -> 57 | H6: =FIND($H$2,D6,1) -> 62 | I6: =VALUE(MID(D6,G6+2,H6-G6-2)) -> 29 | J6: =FIND($J$2,D6,1) -> 45 | K6: =FIND($K$2,D6,1) -> 51 | L6: =VALUE(MID(D6,J6+3,K6-J6-3)) -> 170 | M6: 100 | N6: =F6*L6+I6*M6 -> 30610 | O6: 7953.4 | P6: =COUNTIF(#REF!,Лист3!A6) -> #REF!
A7: 8429 | B7: Экскаватор JCB | C7: 32430 | D7: ЗП за 01.01.2024 - 31.01.2024 179 год.роботи х 170 грн. + 20 год.ТО и заправки х 100 грн. = До виплати 32 430 грн. | E7: Карбунар Я.Д. | F7: =VALUE(MID(D7,31,FIND($G$1,D7,1)-31)) -> 179 | G7: =FIND($F$2,D7,1) -> 57 | H7: =FIND($H$2,D7,1) -> 62 | I7: =VALUE(MID(D7,G7+2,H7-G7-2)) -> 20 | J7: =FIND($J$2,D7,1) -> 45 | K7: =FIND($K$2,D7,1) -> 51 | L7: =VALUE(MID(D7,J7+3,K7-J7-3)) -> 170 | M7: 100 | N7: =F7*L7+I7*M7 -> 32430 | O7: 7953.4 | P7: =COUNTIF(#REF!,Лист3!A7) -> #REF!
A8: 8430 | B8: Экскаватор JCB 3CX 2008 | C8: 35110 | D8: ЗП за 01.01.2024 - 31.01.2024 193 год.роботи х 170 грн. + 23 год.ТО и заправки х 100 грн. = До виплати 35 110 грн. | E8: Ковальчук В.В. | F8: =VALUE(MID(D8,31,FIND($G$1,D8,1)-31)) -> 193 | G8: =FIND($F$2,D8,1) -> 57 | H8: =FIND($H$2,D8,1) -> 62 | I8: =VALUE(MID(D8,G8+2,H8-G8-2)) -> 23 | J8: =FIND($J$2,D8,1) -> 45 | K8: =FIND($K$2,D8,1) -> 51 | L8: =VALUE(MID(D8,J8+3,K8-J8-3)) -> 170 | M8: 100 | N8: =F8*L8+I8*M8 -> 35110 | O8: 7953.4 | P8: =COUNTIF(#REF!,Лист3!A8) -> #REF!
A9: 8431 | B9: Экскаватор JCB 2013 | C9: 24310 | D9: ЗП за 01.01.2024 - 31.01.2024 143 год.роботи х 170 грн. + 0 год.ТО и заправки х 100 грн. = До виплати 24 310 грн. | E9: Трубилко В.Т. | F9: =VALUE(MID(D9,31,FIND($G$1,D9,1)-31)) -> 143 | G9: =FIND($F$2,D9,1) -> 57 | H9: =FIND($H$2,D9,1) -> 61 | I9: =VALUE(MID(D9,G9+2,H9-G9-2)) -> 0 | J9: =FIND($J$2,D9,1) -> 45 | K9: =FIND($K$2,D9,1) -> 51 | L9: =VALUE(MID(D9,J9+3,K9-J9-3)) -> 170 | M9: 100 | N9: =F9*L9+I9*M9 -> 24310 | O9: 2954.7122 | P9: =COUNTIF(#REF!,Лист3!A9) -> #REF!
A10: 8432 | B10: Автокран XCMG | C10: 24180 | D10: ЗП за 01.01.2024 - 31.01.2024 116 год.роботи х 180 грн. + 33 год.ТО и заправки х 100 грн. = До виплати 24 180 грн. | E10: Болох В.В. | F10: =VALUE(MID(D10,31,FIND($G$1,D10,1)-31)) -> 116 | G10: =FIND($F$2,D10,1) -> 57 | H10: =FIND($H$2,D10,1) -> 62 | I10: =VALUE(MID(D10,G10+2,H10-G10-2)) -> 33 | J10: =FIND($J$2,D10,1) -> 45 | K10: =FIND($K$2,D10,1) -> 51 | L10: =VALUE(MID(D10,J10+3,K10-J10-3)) -> 180 | M10: 100 | N10: =F10*L10+I10*M10 -> 24180 | O10: 7647.5 | P10: =COUNTIF(#REF!,Лист3!A10) -> #REF!
A11: 8434 | B11: Самосвал Камаз | C11: 16200 | D11: ЗП за 01.01.2024 - 31.01.2024 110 год.роботи х 140 грн. + 8 год.ТО и заправки х 100 грн. = До виплати 16 200 грн. | E11: Якубовський В.Г. | F11: =VALUE(MID(D11,31,FIND($G$1,D11,1)-31)) -> 110 | G11: =FIND($F$2,D11,1) -> 57 | H11: =FIND($H$2,D11,1) -> 61 | I11: =VALUE(MID(D11,G11+2,H11-G11-2)) -> 8 | J11: =FIND($J$2,D11,1) -> 45 | K11: =FIND($K$2,D11,1) -> 51 | L11: =VALUE(MID(D11,J11+3,K11-J11-3)) -> 140 | M11: 100 | N11: =F11*L11+I11*M11 -> 16200 | O11: 7647.5 | P11: =COUNTIF(#REF!,Лист3!A11) -> #REF!
A12: 8436 | B12: Виброкаток | C12: 14820 | D12: ЗП за 01.01.2024 - 31.01.2024 66 год.роботи х 170 грн. + 36 год.ТО и заправки х 100 грн. = До виплати 14 820 грн. | E12: Скоц С.І. | F12: =VALUE(MID(D12,31,FIND($G$1,D12,1)-31)) -> 66 | G12: =FIND($F$2,D12,1) -> 56 | H12: =FIND($H$2,D12,1) -> 61 | I12: =VALUE(MID(D12,G12+2,H12-G12-2)) -> 36 | J12: =FIND($J$2,D12,1) -> 44 | K12: =FIND($K$2,D12,1) -> 50 | L12: =VALUE(MID(D12,J12+3,K12-J12-3)) -> 170 | M12: 100 | N12: =F12*L12+I12*M12 -> 14820 | O12: 5738.5276 | P12: =COUNTIF(#REF!,Лист3!A12) -> #REF!
A13: 8437 | B13: Экскаватор JCB 220 | C13: 5040 | D13: ЗП за 01.01.2024 - 31.01.2024 12 год.роботи х 170 грн. + 30 год.ТО и заправки х 100 грн. = До виплати 5 040 грн. | E13: Скоц С.І. | F13: =VALUE(MID(D13,31,FIND($G$1,D13,1)-31)) -> 12 | G13: =FIND($F$2,D13,1) -> 56 | H13: =FIND($H$2,D13,1) -> 61 | I13: =VALUE(MID(D13,G13+2,H13-G13-2)) -> 30 | J13: =FIND($J$2,D13,1) -> 44 | K13: =FIND($K$2,D13,1) -> 50 | L13: =VALUE(MID(D13,J13+3,K13-J13-3)) -> 170 | M13: 100 | N13: =F13*L13+I13*M13 -> 5040 | O13: 1951.5638 | P13: =COUNTIF(#REF!,Лист3!A13) -> #REF!
A14: 8438 | B14: Телескоп JCB 540-170 №5 | C14: 680 | D14: ЗП за 01.01.2024 - 31.01.2024 4 год.роботи х 170 грн. + 0 год.ТО и заправки х 100 грн. = До виплати 680 грн. | E14: Скоц С.І. | F14: =VALUE(MID(D14,31,FIND($G$1,D14,1)-31)) -> 4 | G14: =FIND($F$2,D14,1) -> 55 | H14: =FIND($H$2,D14,1) -> 59 | I14: =VALUE(MID(D14,G14+2,H14-G14-2)) -> 0 | J14: =FIND($J$2,D14,1) -> 43 | K14: =FIND($K$2,D14,1) -> 49 | L14: =VALUE(MID(D14,J14+3,K14-J14-3)) -> 170 | M14: 100 | N14: =F14*L14+I14*M14 -> 680 | O14: 263.30861 | P14: =COUNTIF(#REF!,Лист3!A14) -> #REF!
A15: 8439 | B15: МАЗ 264 | C15: 13280 | D15: ЗП за 01.01.2024 - 31.01.2024 92 год.роботи х 140 грн. + 4 год.ТО и заправки х 100 грн. = До виплати 13 280 грн. | E15: Самойленко В.М. | F15: =VALUE(MID(D15,31,FIND($G$1,D15,1)-31)) -> 92 | G15: =FIND($F$2,D15,1) -> 56 | H15: =FIND($H$2,D15,1) -> 60 | I15: =VALUE(MID(D15,G15+2,H15-G15-2)) -> 4 | J15: =FIND($J$2,D15,1) -> 44 | K15: =FIND($K$2,D15,1) -> 50 | L15: =VALUE(MID(D15,J15+3,K15-J15-3)) -> 140 | M15: 100 | N15: =F15*L15+I15*M15 -> 13280 | O15: 7647.5 | P15: =COUNTIF(#REF!,Лист3!A15) -> #REF!
... A20: 8444 | B20: Самосвал МАЗ | C20: 21180 | D20: ЗП за 01.01.2024 - 31.01.2024 147 год.роботи х 140 грн. + 6 год.ТО и заправки х 100 грн. = До виплати 21 180 грн. | E20: Божков В.В. | F20: =VALUE(MID(D20,31,FIND($G$1,D20,1)-31)) -> 147 | G20: =FIND($F$2,D20,1) -> 57 | H20: =FIND($H$2,D20,1) -> 61 | I20: =VALUE(MID(D20,G20+2,H20-G20-2)) -> 6 | J20: =FIND($J$2,D20,1) -> 45 | K20: =FIND($K$2,D20,1) -> 51 | L20: =VALUE(MID(D20,J20+3,K20-J20-3)) -> 140 | M20: 100 | N20: =F20*L20+I20*M20 -> 21180 | O20: 6939.7626 | P20: =COUNTIF(#REF!,Лист3!A20) -> #REF!
O22: 3547.56

Sheet Лист1
B2: Сумма к выплате | C2: РКО | D2: ИНН | E2: IBAN | F2: Фамилия | G2: Имя | H2: Отчество | I2: Отправитель | J2: Банк
B3: 13000 | C3: 130 | D3: 2374714914 | E3: UA503005280000000262022288228 | F3: Мусієнко | G3: Ігор | H3: Іванович | I3: Мусієнко | J3: ОТП
B4: 15900 | C4: 159 | D4: 3132604831 | E4: UA453005280000000262072233715 | F4: Ковальчук | G4: Валентин | H4: Вікторович | I4: Ковальчук | J4: ОТП
B5: 16900 | C5: 169 | D5: 2753702532 | E5: UA883005280000000262002769495 | F5: Божков | G5: Валерій | H5: Вікторович | I5: Божков | J5: ОТП
B6: 5900 | C6: 59 | D6: 2423910335 | E6: UA563005280000000262012773099 | F6: Селівончик | G6: Ігор | H6: Петрович | I6: Селівончик | J6: ОТП
B7: 27400 | C7: 274 | D7: 2334806973 | E7: UA523005280000000262032797754 | F7: Савранский | G7: Іван | H7: Володимирович | I7: Савранский | J7: ОТП
B8: 45000 | C8: 450 | D8: 3013807931 | E8: UA373005280000000262032288289 | F8: Горячий | G8: Іван | H8: Васильович | I8: Горячий | J8: ОТП
B9: 12000 | C9: 120 | D9: 3359108675 | E9: UA623005280000000262082722504 | F9: Кушнірюк | G9: Микола | H9: Володимирович | I9: Кушнірюк | J9: ОТП
B10: 30000 | C10: 300 | D10: 2852918337 | E10: UA733005280000000262041996371 | F10: Косік | G10: Юрій | H10: Анатолійович | I10: Косік | J10: ОТП
B11: 23500 | C11: 235 | D11: 3061614236 | E11: UA983005280000000262092288287 | F11: Трохименко | G11: Віталій | H11: Якович | I11: Трохименко | J11: ОТП
B12: 48500 | C12: 485 | D12: 3166313137 | E12: UA093005280000000262021994474 | F12: Карбунар | G12: Ярослав | H12: Дмитрович | I12: Карбунар | J12: ОТП
B13: 10700 | C13: 107 | D13: 2228715218 | E13: UA593005280000000262022584401 | F13: Зенкін | G13: Дмитро | H13: Юрійович | I13: Зенкін | J13: ОТП
B14: 36200 | C14: 362 | D14: 2794610037 | E14: UA643005280000000262041994496 | F14: Болох | G14: Володимир | H14: Васильович | I14: Болох | J14: ОТП
... B20: 19300 | C20: 193 | D20: 2280303036 | E20: UA303005280000000262062233576 | F20: Скоц | G20: Сергій | H20: Іванович | I20: Скоц | J20: ОТП
B21: 3000 | C21: 0 | D21: Передано через Гриценко С.
A22: ИТОГО: | B22: =SUM(B3:B21) -> 367100 | C22: =SUM(C3:C21) -> 3641
A23: ИТОГО С РКО: | B23: =B22+C22 -> 370741

Sheet IBAN
A1: Аксенчіков Сергій Олександрович | B1: 3457309598 | C1: UA263005280000000262022269551
A2: Антонович Тетяна Сергіївна | B2: 2894801342 | C2: UA093005280000000262062269553
A3: Аулова Маргарита Володимирівна | B3: 3036417408 | C3: UA623005280000000262012269561
A4: Бабошина Ольга Михайлівна | B4: 3584606561 | C4: UA463005280000000262062269566
A5: Бондар Ярослав Михайлович | B5: 2772909678 | C5: UA813005280000000262042269573
A6: Бутенко Матвій Анатолійович | B6: 3552110973 | C6: UA933005280000000262062194709
A7: Глузд Дмитро Михайлович | B7: 3255109619 | C7: UA063005280000000262011992664
A8: Гриценко Олександр Вікторович | B8: 2751711415 | C8: UA833005280000000262062269579
A9: Гриценко Сергій Миколайович | B9: 3382914593 | C9: UA403005280000000262092290107
A10: Гурнік Артем Ігорович | B10: 3185819999 | C10: UA813005280000000262092269581
A11: Демедюк Юрій Юрійович | B11: 2882903815 | C11: UA123005280000000262001993408
A12: Демченко Вадим Олександрович | B12: 3259012714 | C12: UA383005280000000262002269584
... A119: КОВАЛЬ ВАЛЕРІЙ ВАСИЛЬОВИЧ | B119: 2534903359 | C119: UA813005280000000262042330004
A120: Ковальчук В.В.
A121: Шестоковський Ю.А.

Sheet МЕХАНИЗАТОРЫ ноябрь
Y1: 45170
Y2: 45200
B4: ="ЧАСЫ ["&CHAR(10)&TEXT(Y1,"[$-419]ММММ ГГГГ")&"]" -> ЧАСЫ [ Сентябрь 2023]
B6: № п/п | C6: ФИО | E6: Начислено в сентябре 2023 | F6: Всего | I6: Спец.техника | J6: Ставка за работу, грн/час | K6: Ставка за ТО, грн/час | L6: ТО | M6: Заправка | O6: Без ТО и заправок | Q6: ИТОГО ЗП по часам | R6: Начисления на ЗП Ф1 (22%) | S6: Удержано по Ф1 (19,5%) | T6: Начислено ЗП по Ф1 (аванс) | V6: Остаток ЗП за период (по Ф2)
B7: 1 | C7: Болох В.В. | E7: 9500 | F7: =SUMIFS([1]Табель!J:J,[1]Табель!E:E,C7,[1]Табель!B:B,">="&$Y$1,[1]Табель!B:B,"<"&$Y$2) -> #VALUE! | I7: =INDEX([1]ИНФО_СПЕЦТЕХНИКА!$D$4:$D$23,IF(SUMIFS([1]Табель!I:I,[1]Табель!E:E,C7,[1]Табель!B:B,">="&$Y$1,[1]Табель!B:B,"<"&$Y$2)/COUNTIFS([1]Табель!E:E,C7,[1]Табель!B:B,">="&$Y$1,[1]Табель!B:B,"<"&$Y$2)=0,"",SUMIFS([1]Табель!I:I,[1]Табель!E:E,C7,[1]Табель!B:B,">="&$Y$1,[1]Табель!B:B,"<"&$Y$2)/COUNTIFS([1]Табель!E:E,C7,[1]Табель!B:B,">="&$Y$1,[1]Табель!B:B,"<"&$Y$2))) -> #VALUE! | J7: 180 | K7: 100 | L7: =SUMIFS([1]Табель!K:K,[1]Табель!E:E,C7,[1]Табель!B:B,">="&$Y$1,[1]Табель!B:B,"<"&$Y$2) -> #VALUE! | M7: =SUMIFS([1]Табель!L:L,[1]Табель!E:E,C7,[1]Табель!B:B,">="&$Y$1,[1]Табель!B:B,"<"&$Y$2) -> #VALUE! | O7: =F7-L7-M7 -> #VALUE! | Q7: =O7*J7+(L7+M7)*K7 -> #VALUE! | R7: =ROUND(E7*0.22,2) -> 2090 | S7: =E7*0.195 -> 1852.5 | T7: =E7-S7 -> 7647.5 | V7: =Q7-T7 -> #VALUE!
B8: 2 | C8: Боранов В.В. | F8: =SUMIFS([1]Табель!J:J,[1]Табель!E:E,C8,[1]Табель!B:B,">="&$Y$1,[1]Табель!B:B,"<"&$Y$2) -> #VALUE! | I8: =INDEX([1]ИНФО_СПЕЦТЕХНИКА!$D$4:$D$23,IF(SUMIFS([1]Табель!I:I,[1]Табель!E:E,C8,[1]Табель!B:B,">="&$Y$1,[1]Табель!B:B,"<"&$Y$2)/COUNTIFS([1]Табель!E:E,C8,[1]Табель!B:B,">="&$Y$1,[1]Табель!B:B,"<"&$Y$2)=0,"",SUMIFS([1]Табель!I:I,[1]Табель!E:E,C8,[1]Табель!B:B,">="&$Y$1,[1]Табель!B:B,"<"&$Y$2)/COUNTIFS([1]Табель!E:E,C8,[1]Табель!B:B,">="&$Y$1,[1]Табель!B:B,"<"&$Y$2))) -> #VALUE! | J8: 180 | K8: 100 | L8: =SUMIFS([1]Табель!K:K,[1]Табель!E:E,C8,[1]Табель!B:B,">="&$Y$1,[1]Табель!B:B,"<"&$Y$2) -> #VALUE! | M8: =SUMIFS([1]Табель!L:L,[1]Табель!E:E,C8,[1]Табель!B:B,">="&$Y$1,[1]Табель!B:B,"<"&$Y$2) -> #VALUE! | O8: =F8-L8-M8 -> #VALUE! | Q8: =O8*J8+(L8+M8)*K8 -> #VALUE! | R8: =ROUND(E8*0.22,2) -> 0 | S8: =E8*0.195 -> 0 | T8: =E8-S8 -> 0 | V8: =Q8-T8 -> #VALUE!
B9: 3 | C9: Борисенко О.М. | E9: 4523.81 | F9: =SUMIFS([1]Табель!J:J,[1]Табель!E:E,C9,[1]Табель!B:B,">="&$Y$1,[1]Табель!B:B,"<"&$Y$2) -> #VALUE! | I9: =INDEX([1]ИНФО_СПЕЦТЕХНИКА!$D$4:$D$23,IF(SUMIFS([1]Табель!I:I,[1]Табель!E:E,C9,[1]Табель!B:B,">="&$Y$1,[1]Табель!B:B,"<"&$Y$2)/COUNTIFS([1]Табель!E:E,C9,[1]Табель!B:B,">="&$Y$1,[1]Табель!B:B,"<"&$Y$2)=0,"",SUMIFS([1]Табель!I:I,[1]Табель!E:E,C9,[1]Табель!B:B,">="&$Y$1,[1]Табель!B:B,"<"&$Y$2)/COUNTIFS([1]Табель!E:E,C9,[1]Табель!B:B,">="&$Y$1,[1]Табель!B:B,"<"&$Y$2))) -> #VALUE! | J9: 180 | K9: 100 | L9: =SUMIFS([1]Табель!K:K,[1]Табель!E:E,C9,[1]Табель!B:B,">="&$Y$1,[1]Табель!B:B,"<"&$Y$2) -> #VALUE! | M9: =SUMIFS([1]Табель!L:L,[1]Табель!E:E,C9,[1]Табель!B:B,">="&$Y$1,[1]Табель!B:B,"<"&$Y$2) -> #VALUE! | O9: =F9-L9-M9 -> #VALUE! | Q9: =O9*J9+(L9+M9)*K9 -> #VALUE! | R9: =ROUND(E9*0.22,2) -> 995.24 | S9: =E9*0.195 -> 882.14295 | T9: =E9-S9 -> 3641.6671 | V9: =Q9-T9 -> #VALUE!
B10: =B9+1 -> 4 | C10: Горячий І.В. | E10: 9880 | F10: =SUMIFS([1]Табель!J:J,[1]Табель!E:E,C10,[1]Табель!B:B,">="&$Y$1,[1]Табель!B:B,"<"&$Y$2) -> #VALUE! | I10: =INDEX([1]ИНФО_СПЕЦТЕХНИКА!$D$4:$D$23,IF(SUMIFS([1]Табель!I:I,[1]Табель!E:E,C10,[1]Табель!B:B,">="&$Y$1,[1]Табель!B:B,"<"&$Y$2)/COUNTIFS([1]Табель!E:E,C10,[1]Табель!B:B,">="&$Y$1,[1]Табель!B:B,"<"&$Y$2)=0,"",SUMIFS([1]Табель!I:I,[1]Табель!E:E,C10,[1]Табель!B:B,">="&$Y$1,[1]Табель!B:B,"<"&$Y$2)/COUNTIFS([1]Табель!E:E,C10,[1]Табель!B:B,">="&$Y$1,[1]Табель!B:B,"<"&$Y$2))) -> #VALUE! | J10: 170 | K10: 100 | L10: =SUMIFS([1]Табель!K:K,[1]Табель!E:E,C10,[1]Табель!B:B,">="&$Y$1,[1]Табель!B:B,"<"&$Y$2) -> #VALUE! | M10: =SUMIFS([1]Табель!L:L,[1]Табель!E:E,C10,[1]Табель!B:B,">="&$Y$1,[1]Табель!B:B,"<"&$Y$2) -> #VALUE! | O10: =F10-L10-M10 -> #VALUE! | Q10: =O10*J10+(L10+M10)*K10 -> #VALUE! | R10: =ROUND(E10*0.22,2) -> 2173.6 | S10: =E10*0.195 -> 1926.6 | T10: =E10-S10 -> 7953.4 | V10: =Q10-T10 -> #VALUE!
B11: =B10+1 -> 5 | C11: Зенкін Д.Ю. | F11: =SUMIFS([1]Табель!J:J,[1]Табель!E:E,C11,[1]Табель!B:B,">="&$Y$1,[1]Табель!B:B,"<"&$Y$2) -> #VALUE! | I11: =INDEX([1]ИНФО_СПЕЦТЕХНИКА!$D$4:$D$23,IF(SUMIFS([1]Табель!I:I,[1]Табель!E:E,C11,[1]Табель!B:B,">="&$Y$1,[1]Табель!B:B,"<"&$Y$2)/COUNTIFS([1]Табель!E:E,C11,[1]Табель!B:B,">="&$Y$1,[1]Табель!B:B,"<"&$Y$2)=0,"",SUMIFS([1]Табель!I:I,[1]Табель!E:E,C11,[1]Табель!B:B,">="&$Y$1,[1]Табель!B:B,"<"&$Y$2)/COUNTIFS([1]Табель!E:E,C11,[1]Табель!B:B,">="&$Y$1,[1]Табель!B:B,"<"&$Y$2))) -> #VALUE! | J11: 170 | K11: 100 | L11: =SUMIFS([1]Табель!K:K,[1]Табель!E:E,C11,[1]Табель!B:B,">="&$Y$1,[1]Табель!B:B,"<"&$Y$2) -> #VALUE! | M11: =SUMIFS([1]Табель!L:L,[1]Табель!E:E,C11,[1]Табель!B:B,">="&$Y$1,[1]Табель!B:B,"<"&$Y$2) -> #VALUE! | O11: =F11-L11-M11 -> #VALUE! | Q11: =O11*J11+(L11+M11)*K11 -> #VALUE! | R11: =ROUND(E11*0.22,2) -> 0 | S11: =E11*0.195 -> 0 | T11: =E11-S11 -> 0 | V11: =Q11-T11 -> #VALUE!
B12: =B11+1 -> 6 | C12: Карбунар Я.Д. | E12: 9880 | F12: =SUMIFS([1]Табель!J:J,[1]Табель!E:E,C12,[1]Табель!B:B,">="&$Y$1,[1]Табель!B:B,"<"&$Y$2) -> #VALUE! | I12: =INDEX([1]ИНФО_СПЕЦТЕХНИКА!$D$4:$D$23,IF(SUMIFS([1]Табель!I:I,[1]Табель!E:E,C12,[1]Табель!B:B,">="&$Y$1,[1]Табель!B:B,"<"&$Y$2)/COUNTIFS([1]Табель!E:E,C12,[1]Табель!B:B,">="&$Y$1,[1]Табель!B:B,"<"&$Y$2)=0,"",SUMIFS([1]Табель!I:I,[1]Табель!E:E,C12,[1]Табель!B:B,">="&$Y$1,[1]Табель!B:B,"<"&$Y$2)/COUNTIFS([1]Табель!E:E,C12,[1]Табель!B:B,">="&$Y$1,[1]Табель!B:B,"<"&$Y$2))) -> #VALUE! | J12: 170 | K12: 100 | L12: =SUMIFS([1]Табель!K:K,[1]Табель!E:E,C12,[1]Табель!B:B,">="&$Y$1,[1]Табель!B:B,"<"&$Y$2) -> #VALUE! | M12: =SUMIFS([1]Табель!L:L,[1]Табель!E:E,C12,[1]Табель!B:B,">="&$Y$1,[1]Табель!B:B,"<"&$Y$2) -> #VALUE! | O12: =F12-L12-M12 -> #VALUE! | Q12: =O12*J12+(L12+M12)*K12 -> #VALUE! | R12: =ROUND(E12*0.22,2) -> 2173.6 | S12: =E12*0.195 -> 1926.6 | T12: =E12-S12 -> 7953.4 | V12: =Q12-T12 -> #VALUE!
B13: =B12+1 -> 7 | C13: Косік Ю.А. | E13: 9880 | F13: =SUMIFS([1]Табель!J:J,[1]Табель!E:E,C13,[1]Табель!B:B,">="&$Y$1,[1]Табель!B:B,"<"&$Y$2) -> #VALUE! | I13: =INDEX([1]ИНФО_СПЕЦТЕХНИКА!$D$4:$D$23,IF(SUMIFS([1]Табель!I:I,[1]Табель!E:E,C13,[1]Табель!B:B,">="&$Y$1,[1]Табель!B:B,"<"&$Y$2)/COUNTIFS([1]Табель!E:E,C13,[1]Табель!B:B,">="&$Y$1,[1]Табель!B:B,"<"&$Y$2)=0,"",SUMIFS([1]Табель!I:I,[1]Табель!E:E,C13,[1]Табель!B:B,">="&$Y$1,[1]Табель!B:B,"<"&$Y$2)/COUNTIFS([1]Табель!E:E,C13,[1]Табель!B:B,">="&$Y$1,[1]Табель!B:B,"<"&$Y$2))) -> #VALUE! | J13: 170 | K13: 100 | L13: =SUMIFS([1]Табель!K:K,[1]Табель!E:E,C13,[1]Табель!B:B,">="&$Y$1,[1]Табель!B:B,"<"&$Y$2) -> #VALUE! | M13: =SUMIFS([1]Табель!L:L,[1]Табель!E:E,C13,[1]Табель!B:B,">="&$Y$1,[1]Табель!B:B,"<"&$Y$2) -> #VALUE! | O13: =F13-L13-M13 -> #VALUE! | Q13: =O13*J13+(L13+M13)*K13 -> #VALUE! | R13: =ROUND(E13*0.22,2) -> 2173.6 | S13: =E13*0.195 -> 1926.6 | T13: =E13-S13 -> 7953.4 | V13: =Q13-T13 -> #VALUE!
B14: =B13+1 -> 8 | C14: Красношапка М.П. | F14: =SUMIFS([1]Табель!J:J,[1]Табель!E:E,C14,[1]Табель!B:B,">="&$Y$1,[1]Табель!B:B,"<"&$Y$2) -> #VALUE! | I14: =INDEX([1]ИНФО_СПЕЦТЕХНИКА!$D$4:$D$23,IF(SUMIFS([1]Табель!I:I,[1]Табель!E:E,C14,[1]Табель!B:B,">="&$Y$1,[1]Табель!B:B,"<"&$Y$2)/COUNTIFS([1]Табель!E:E,C14,[1]Табель!B:B,">="&$Y$1,[1]Табель!B:B,"<"&$Y$2)=0,"",SUMIFS([1]Табель!I:I,[1]Табель!E:E,C14,[1]Табель!B:B,">="&$Y$1,[1]Табель!B:B,"<"&$Y$2)/COUNTIFS([1]Табель!E:E,C14,[1]Табель!B:B,">="&$Y$1,[1]Табель!B:B,"<"&$Y$2))) -> #VALUE! | J14: 140 | K14: 100 | L14: =SUMIFS([1]Табель!K:K,[1]Табель!E:E,C14,[1]Табель!B:B,">="&$Y$1,[1]Табель!B:B,"<"&$Y$2) -> #VALUE! | M14: =SUMIFS([1]Табель!L:L,[1]Табель!E:E,C14,[1]Табель!B:B,">="&$Y$1,[1]Табель!B:B,"<"&$Y$2) -> #VALUE! | O14: =F14-L14-M14 -> #VALUE! | Q14: =O14*J14+(L14+M14)*K14 -> #VALUE! | R14: =ROUND(E14*0.22,2) -> 0 | S14: =E14*0.195 -> 0 | T14: =E14-S14 -> 0 | V14: =Q14-T14 -> #VALUE!
B15: =B14+1 -> 9 | C15: Михайлов В.О. | F15: =SUMIFS([1]Табель!J:J,[1]Табель!E:E,C15,[1]Табель!B:B,">="&$Y$1,[1]Табель!B:B,"<"&$Y$2) -> #VALUE! | I15: =INDEX([1]ИНФО_СПЕЦТЕХНИКА!$D$4:$D$23,IF(SUMIFS([1]Табель!I:I,[1]Табель!E:E,C15,[1]Табель!B:B,">="&$Y$1,[1]Табель!B:B,"<"&$Y$2)/COUNTIFS([1]Табель!E:E,C15,[1]Табель!B:B,">="&$Y$1,[1]Табель!B:B,"<"&$Y$2)=0,"",SUMIFS([1]Табель!I:I,[1]Табель!E:E,C15,[1]Табель!B:B,">="&$Y$1,[1]Табель!B:B,"<"&$Y$2)/COUNTIFS([1]Табель!E:E,C15,[1]Табель!B:B,">="&$Y$1,[1]Табель!B:B,"<"&$Y$2))) -> #VALUE! | J15: 140 | K15: 100 | L15: =SUMIFS([1]Табель!K:K,[1]Табель!E:E,C15,[1]Табель!B:B,">="&$Y$1,[1]Табель!B:B,"<"&$Y$2) -> #VALUE! | M15: =SUMIFS([1]Табель!L:L,[1]Табель!E:E,C15,[1]Табель!B:B,">="&$Y$1,[1]Табель!B:B,"<"&$Y$2) -> #VALUE! | O15: =F15-L15-M15 -> #VALUE! | Q15: =O15*J15+(L15+M15)*K15 -> #VALUE! | R15: =ROUND(E15*0.22,2) -> 0 | S15: =E15*0.195 -> 0 | T15: =E15-S15 -> 0 | V15: =Q15-T15 -> #VALUE!
B16: =B14+1 -> 9 | C16: Мусієнко І.І. | E16: 9500 | F16: =SUMIFS([1]Табель!J:J,[1]Табель!E:E,C16,[1]Табель!B:B,">="&$Y$1,[1]Табель!B:B,"<"&$Y$2) -> #VALUE! | I16: =INDEX([1]ИНФО_СПЕЦТЕХНИКА!$D$4:$D$23,IF(SUMIFS([1]Табель!I:I,[1]Табель!E:E,C16,[1]Табель!B:B,">="&$Y$1,[1]Табель!B:B,"<"&$Y$2)/COUNTIFS([1]Табель!E:E,C16,[1]Табель!B:B,">="&$Y$1,[1]Табель!B:B,"<"&$Y$2)=0,"",SUMIFS([1]Табель!I:I,[1]Табель!E:E,C16,[1]Табель!B:B,">="&$Y$1,[1]Табель!B:B,"<"&$Y$2)/COUNTIFS([1]Табель!E:E,C16,[1]Табель!B:B,">="&$Y$1,[1]Табель!B:B,"<"&$Y$2))) -> #VALUE! | J16: 170 | K16: 100 | L16: =SUMIFS([1]Табель!K:K,[1]Табель!E:E,C16,[1]Табель!B:B,">="&$Y$1,[1]Табель!B:B,"<"&$Y$2) -> #VALUE! | M16: =SUMIFS([1]Табель!L:L,[1]Табель!E:E,C16,[1]Табель!B:B,">="&$Y$1,[1]Табель!B:B,"<"&$Y$2) -> #VALUE! | O16: =F16-L16-M16 -> #VALUE! | Q16: =O16*J16+(L16+M16)*K16 -> #VALUE! | R16: =ROUND(E16*0.22,2) -> 2090 | S16: =E16*0.195 -> 1852.5 | T16: =E16-S16 -> 7647.5 | V16: =Q16-T16 -> #VALUE!
B17: =B16+1 -> 10 | C17: Самойленко В.М. | E17: 9047.62 | F17: =SUMIFS([1]Табель!J:J,[1]Табель!E:E,C17,[1]Табель!B:B,">="&$Y$1,[1]Табель!B:B,"<"&$Y$2) -> #VALUE! | I17: =INDEX([1]ИНФО_СПЕЦТЕХНИКА!$D$4:$D$23,IF(SUMIFS([1]Табель!I:I,[1]Табель!E:E,C17,[1]Табель!B:B,">="&$Y$1,[1]Табель!B:B,"<"&$Y$2)/COUNTIFS([1]Табель!E:E,C17,[1]Табель!B:B,">="&$Y$1,[1]Табель!B:B,"<"&$Y$2)=0,"",SUMIFS([1]Табель!I:I,[1]Табель!E:E,C17,[1]Табель!B:B,">="&$Y$1,[1]Табель!B:B,"<"&$Y$2)/COUNTIFS([1]Табель!E:E,C17,[1]Табель!B:B,">="&$Y$1,[1]Табель!B:B,"<"&$Y$2))) -> #VALUE! | J17: 140 | K17: 100 | L17: =SUMIFS([1]Табель!K:K,[1]Табель!E:E,C17,[1]Табель!B:B,">="&$Y$1,[1]Табель!B:B,"<"&$Y$2) -> #VALUE! | M17: =SUMIFS([1]Табель!L:L,[1]Табель!E:E,C17,[1]Табель!B:B,">="&$Y$1,[1]Табель!B:B,"<"&$Y$2) -> #VALUE! | O17: =F17-L17-M17 -> #VALUE! | Q17: =O17*J17+(L17+M17)*K17 -> #VALUE! | R17: =ROUND(E17*0.22,2) -> 1990.48 | S17: =E17*0.195 -> 1764.2859 | T17: =E17-S17 -> 7283.3341 | V17: =Q17-T17 -> #VALUE!
B18: =B17+1 -> 11 | C18: Скоц С.І. | E18: 9880 | F18: =SUMIFS([1]Табель!J:J,[1]Табель!E:E,C18,[1]Табель!B:B,">="&$Y$1,[1]Табель!B:B,"<"&$Y$2) -> #VALUE! | I18: =INDEX([1]ИНФО_СПЕЦТЕХНИКА!$D$4:$D$23,IF(SUMIFS([1]Табель!I:I,[1]Табель!E:E,C18,[1]Табель!B:B,">="&$Y$1,[1]Табель!B:B,"<"&$Y$2)/COUNTIFS([1]Табель!E:E,C18,[1]Табель!B:B,">="&$Y$1,[1]Табель!B:B,"<"&$Y$2)=0,"",SUMIFS([1]Табель!I:I,[1]Табель!E:E,C18,[1]Табель!B:B,">="&$Y$1,[1]Табель!B:B,"<"&$Y$2)/COUNTIFS([1]Табель!E:E,C18,[1]Табель!B:B,">="&$Y$1,[1]Табель!B:B,"<"&$Y$2))) -> #VALUE! | J18: 170 | K18: 100 | L18: =SUMIFS([1]Табель!K:K,[1]Табель!E:E,C18,[1]Табель!B:B,">="&$Y$1,[1]Табель!B:B,"<"&$Y$2) -> #VALUE! | M18: =SUMIFS([1]Табель!L:L,[1]Табель!E:E,C18,[1]Табель!B:B,">="&$Y$1,[1]Табель!B:B,"<"&$Y$2) -> #VALUE! | O18: =F18-L18-M18 -> #VALUE! | Q18: =O18*J18+(L18+M18)*K18 -> #VALUE! | R18: =ROUND(E18*0.22,2) -> 2173.6 | S18: =E18*0.195 -> 1926.6 | T18: =E18-S18 -> 7953.4 | V18: =Q18-T18 -> #VALUE!
B19: =B18+1 -> 12 | C19: Шамоян А.Д. | E19: 8595.24 | F19: =SUMIFS([1]Табель!J:J,[1]Табель!E:E,C19,[1]Табель!B:B,">="&$Y$1,[1]Табель!B:B,"<"&$Y$2) -> #VALUE! | I19: =INDEX([1]ИНФО_СПЕЦТЕХНИКА!$D$4:$D$23,IF(SUMIFS([1]Табель!I:I,[1]Табель!E:E,C19,[1]Табель!B:B,">="&$Y$1,[1]Табель!B:B,"<"&$Y$2)/COUNTIFS([1]Табель!E:E,C19,[1]Табель!B:B,">="&$Y$1,[1]Табель!B:B,"<"&$Y$2)=0,"",SUMIFS([1]Табель!I:I,[1]Табель!E:E,C19,[1]Табель!B:B,">="&$Y$1,[1]Табель!B:B,"<"&$Y$2)/COUNTIFS([1]Табель!E:E,C19,[1]Табель!B:B,">="&$Y$1,[1]Табель!B:B,"<"&$Y$2))) -> #VALUE! | J19: 140 | K19: 100 | L19: =SUMIFS([1]Табель!K:K,[1]Табель!E:E,C19,[1]Табель!B:B,">="&$Y$1,[1]Табель!B:B,"<"&$Y$2) -> #VALUE! | M19: =SUMIFS([1]Табель!L:L,[1]Табель!E:E,C19,[1]Табель!B:B,">="&$Y$1,[1]Табель!B:B,"<"&$Y$2) -> #VALUE! | O19: =F19-L19-M19 -> #VALUE! | Q19: =O19*J19+(L19+M19)*K19 -> #VALUE! | R19: =ROUND(E19*0.22,2) -> 1890.95 | S19: =E19*0.195 -> 1676.0718 | T19: =E19-S19 -> 6919.1682 | V19: =Q19-T19 -> #VALUE!
B20: =B19+1 -> 13 | C20: Якубовський В.Г. | E20: 4976.19 | F20: =SUMIFS([1]Табель!J:J,[1]Табель!E:E,C20,[1]Табель!B:B,">="&$Y$1,[1]Табель!B:B,"<"&$Y$2) -> #VALUE! | I20: =INDEX([1]ИНФО_СПЕЦТЕХНИКА!$D$4:$D$23,IF(SUMIFS([1]Табель!I:I,[1]Табель!E:E,C20,[1]Табель!B:B,">="&$Y$1,[1]Табель!B:B,"<"&$Y$2)/COUNTIFS([1]Табель!E:E,C20,[1]Табель!B:B,">="&$Y$1,[1]Табель!B:B,"<"&$Y$2)=0,"",SUMIFS([1]Табель!I:I,[1]Табель!E:E,C20,[1]Табель!B:B,">="&$Y$1,[1]Табель!B:B,"<"&$Y$2)/COUNTIFS([1]Табель!E:E,C20,[1]Табель!B:B,">="&$Y$1,[1]Табель!B:B,"<"&$Y$2))) -> #VALUE! | J20: 140 | K20: 100 | L20: =SUMIFS([1]Табель!K:K,[1]Табель!E:E,C20,[1]Табель!B:B,">="&$Y$1,[1]Табель!B:B,"<"&$Y$2) -> #VALUE! | M20: =SUMIFS([1]Табель!L:L,[1]Табель!E:E,C20,[1]Табель!B:B,">="&$Y$1,[1]Табель!B:B,"<"&$Y$2) -> #VALUE! | O20: =F20-L20-M20 -> #VALUE! | Q20: =O20*J20+(L20+M20)*K20 -> #VALUE! | R20: =ROUND(E20*0.22,2) -> 1094.76 | S20: =E20*0.195 -> 970.35705 | T20: =E20-S20 -> 4005.8329 | V20: =Q20-T20 -> #VALUE!
B21: =B20+1 -> 14 | C21: Яцюк Ю.Г. | F21: =SUMIFS([1]Табель!J:J,[1]Табель!E:E,C21,[1]Табель!B:B,">="&$Y$1,[1]Табель!B:B,"<"&$Y$2) -> #VALUE! | I21: =INDEX([1]ИНФО_СПЕЦТЕХНИКА!$D$4:$D$23,IF(SUMIFS([1]Табель!I:I,[1]Табель!E:E,C21,[1]Табель!B:B,">="&$Y$1,[1]Табель!B:B,"<"&$Y$2)/COUNTIFS([1]Табель!E:E,C21,[1]Табель!B:B,">="&$Y$1,[1]Табель!B:B,"<"&$Y$2)=0,"",SUMIFS([1]Табель!I:I,[1]Табель!E:E,C21,[1]Табель!B:B,">="&$Y$1,[1]Табель!B:B,"<"&$Y$2)/COUNTIFS([1]Табель!E:E,C21,[1]Табель!B:B,">="&$Y$1,[1]Табель!B:B,"<"&$Y$2))) -> #VALUE! | J21: 140 | K21: 100 | L21: =SUMIFS([1]Табель!K:K,[1]Табель!E:E,C21,[1]Табель!B:B,">="&$Y$1,[1]Табель!B:B,"<"&$Y$2) -> #VALUE! | M21: =SUMIFS([1]Табель!L:L,[1]Табель!E:E,C21,[1]Табель!B:B,">="&$Y$1,[1]Табель!B:B,"<"&$Y$2) -> #VALUE! | O21: =F21-L21-M21 -> #VALUE! | Q21: =O21*J21+(L21+M21)*K21 -> #VALUE! | R21: =ROUND(E21*0.22,2) -> 0 | S21: =E21*0.195 -> 0 | T21: =E21-S21 -> 0 | V21: =Q21-T21 -> #VALUE!
C22: ИТОГО | E22: =SUM(E7:E21) -> 85662.86 | F22: =SUM(F7:F21) -> #VALUE! | L22: =SUM(L7:L21) -> #VALUE! | M22: =SUM(M7:M21) -> #VALUE! | O22: =SUM(O7:O21) -> #VALUE! | Q22: =SUM(Q7:Q21) -> #VALUE! | R22: =SUM(R7:R21) -> 18845.83 | S22: =SUM(S7:S21) -> 16704.258 | T22: =SUM(T7:T21) -> 68958.602 | V22: =SUM(V7:V21) -> #VALUE!
Y24: 45200
Y25: 45231
B27: ="ЧАСЫ ["&CHAR(10)&TEXT(Y24,"[$-419]ММММ ГГГГ")&"]" -> ЧАСЫ [ Октябрь 2023]
B29: № п/п | C29: ФИО | D29: 1С Alias | E29: Начислено в Октябре 2023 | F29: Всего | I29: Ед. спецтехник | J29: Ставка за работу, грн/час | K29: Ставка за ТО, грн/час | L29: ТО | M29: Заправка | O29: Без ТО и заправок | Q29: ИТОГО ЗП по часам | R29: Начисления на ЗП Ф1 (22%) | S29: Удержано по Ф1 (19,5%) | T29: Начислено ЗП по Ф1 (аванс) | U29: ФОТ + Начисления | V29: Остаток ЗП за период (по Ф2)
B30: 1 | C30: Болох В.В. | D30: =INDEX([1]ИНФО!C:C,MATCH(C30,[1]ИНФО!B:B,0)) -> Болох Володимир Васильович | E30: 9500 | F30: =SUMIFS([1]Табель!J:J,[1]Табель!E:E,C30,[1]Табель!B:B,">="&$Y$24,[1]Табель!B:B,"<"&$Y$25,[1]Табель!F:F,'МЕХАНИЗАТОРЫ ноябрь'!I30) -> #VALUE! | I30: Автокран XCMG | J30: =INDEX([1]ИНФО_СПЕЦТЕХНИКА!$F$4:$F$23,MATCH(I30,[1]ИНФО_СПЕЦТЕХНИКА!$D$4:$D$23,0)) -> 180 | K30: 100 | L30: =SUMIFS([1]Табель!K:K,[1]Табель!E:E,C30,[1]Табель!B:B,">="&$Y$24,[1]Табель!B:B,"<"&$Y$25,[1]Табель!F:F,I30) -> #VALUE! | M30: =SUMIFS([1]Табель!L:L,[1]Табель!E:E,C30,[1]Табель!B:B,">="&$Y$24,[1]Табель!B:B,"<"&$Y$25,[1]Табель!F:F,I30) -> #VALUE! | O30: =F30-L30-M30 -> #VALUE! | Q30: =O30*J30+(L30+M30)*K30 -> #VALUE! | R30: =ROUND(E30*0.22,2) -> 2090 | S30: =E30*0.195 -> 1852.5 | T30: =E30-S30 -> 7647.5 | U30: =-ROUND((R30+E30),2) -> -11590 | V30: =Q30-T30 -> #VALUE!
B31: 2 | C31: Боранов В.В. | D31: =INDEX([1]ИНФО!C:C,MATCH(C31,[1]ИНФО!B:B,0)) -> 0 | F31: =SUMIFS([1]Табель!J:J,[1]Табель!E:E,C31,[1]Табель!B:B,">="&$Y$24,[1]Табель!B:B,"<"&$Y$25,[1]Табель!F:F,'МЕХАНИЗАТОРЫ ноябрь'!I31) -> #VALUE! | I31: Экскаватор JCB 2013 | J31: =INDEX([1]ИНФО_СПЕЦТЕХНИКА!$F$4:$F$23,MATCH(I31,[1]ИНФО_СПЕЦТЕХНИКА!$D$4:$D$23,0)) -> 170 | K31: 100 | L31: =SUMIFS([1]Табель!K:K,[1]Табель!E:E,C31,[1]Табель!B:B,">="&$Y$24,[1]Табель!B:B,"<"&$Y$25,[1]Табель!F:F,I31) -> #VALUE! | M31: =SUMIFS([1]Табель!L:L,[1]Табель!E:E,C31,[1]Табель!B:B,">="&$Y$24,[1]Табель!B:B,"<"&$Y$25,[1]Табель!F:F,I31) -> #VALUE! | O31: =F31-L31-M31 -> #VALUE! | Q31: =O31*J31+(L31+M31)*K31 -> #VALUE! | R31: =ROUND(E31*0.22,2) -> 0 | S31: =E31*0.195 -> 0 | T31: =E31-S31 -> 0 | U31: =-ROUND((R31+E31),2) -> 0 | V31: =Q31-T31 -> #VALUE!
B32: 3 | C32: Борисенко О.М. | D32: =INDEX([1]ИНФО!C:C,MATCH(C32,[1]ИНФО!B:B,0)) -> Борисенко Олексій Миколайович | E32: =9500*Q32/(Q32+Q33) -> #VALUE! | F32: =SUMIFS([1]Табель!J:J,[1]Табель!E:E,C32,[1]Табель!B:B,">="&$Y$24,[1]Табель!B:B,"<"&$Y$25,[1]Табель!F:F,'МЕХАНИЗАТОРЫ ноябрь'!I32) -> #VALUE! | I32: Виброкаток | J32: =INDEX([1]ИНФО_СПЕЦТЕХНИКА!$F$4:$F$23,MATCH(I32,[1]ИНФО_СПЕЦТЕХНИКА!$D$4:$D$23,0)) -> 170 | K32: 100 | L32: =SUMIFS([1]Табель!K:K,[1]Табель!E:E,C32,[1]Табель!B:B,">="&$Y$24,[1]Табель!B:B,"<"&$Y$25,[1]Табель!F:F,I32) -> #VALUE! | M32: =SUMIFS([1]Табель!L:L,[1]Табель!E:E,C32,[1]Табель!B:B,">="&$Y$24,[1]Табель!B:B,"<"&$Y$25,[1]Табель!F:F,I32) -> #VALUE! | O32: =F32-L32-M32 -> #VALUE! | Q32: =O32*J32+(L32+M32)*K32 -> #VALUE! | R32: =ROUND(E32*0.22,2) -> #VALUE! | S32: =E32*0.195 -> #VALUE! | T32: =E32-S32 -> #VALUE! | U32: =-ROUND((R32+E32),2) -> #VALUE! | V32: =Q32-T32 -> #VALUE!
C33: Борисенко О.М. | D33: =INDEX([1]ИНФО!C:C,MATCH(C33,[1]ИНФО!B:B,0)) -> Борисенко Олексій Миколайович | E33: =9500*Q33/(Q32+Q33) -> #VALUE! | F33: =SUMIFS([1]Табель!J:J,[1]Табель!E:E,C33,[1]Табель!B:B,">="&$Y$24,[1]Табель!B:B,"<"&$Y$25,[1]Табель!F:F,'МЕХАНИЗАТОРЫ ноябрь'!I33) -> #VALUE! | I33: Автокран клинцы | J33: =INDEX([1]ИНФО_СПЕЦТЕХНИКА!$F$4:$F$23,MATCH(I33,[1]ИНФО_СПЕЦТЕХНИКА!$D$4:$D$23,0)) -> 180 | K33: 100 | L33: =SUMIFS([1]Табель!K:K,[1]Табель!E:E,C33,[1]Табель!B:B,">="&$Y$24,[1]Табель!B:B,"<"&$Y$25,[1]Табель!F:F,I33) -> #VALUE! | M33: =SUMIFS([1]Табель!L:L,[1]Табель!E:E,C33,[1]Табель!B:B,">="&$Y$24,[1]Табель!B:B,"<"&$Y$25,[1]Табель!F:F,I33) -> #VALUE! | O33: =F33-L33-M33 -> #VALUE! | Q33: =O33*J33+(L33+M33)*K33 -> #VALUE! | R33: =ROUND(E33*0.22,2) -> #VALUE! | S33: =E33*0.195 -> #VALUE! | T33: =E33-S33 -> #VALUE! | U33: =-ROUND((R33+E33),2) -> #VALUE! | V33: =Q33-T33 -> #VALUE!
B34: 4 | C34: Божков В.В. | D34: =INDEX([1]ИНФО!C:C,MATCH(C34,[1]ИНФО!B:B,0)) -> Божков Валерій Вікторович | F34: =SUMIFS([1]Табель!J:J,[1]Табель!E:E,C34,[1]Табель!B:B,">="&$Y$24,[1]Табель!B:B,"<"&$Y$25,[1]Табель!F:F,'МЕХАНИЗАТОРЫ ноябрь'!I34) -> #VALUE! | I34: МАЗ 264 | J34: =INDEX([1]ИНФО_СПЕЦТЕХНИКА!$F$4:$F$23,MATCH(I34,[1]ИНФО_СПЕЦТЕХНИКА!$D$4:$D$23,0)) -> 140 | K34: 100 | L34: =SUMIFS([1]Табель!K:K,[1]Табель!E:E,C34,[1]Табель!B:B,">="&$Y$24,[1]Табель!B:B,"<"&$Y$25,[1]Табель!F:F,I34) -> #VALUE! | M34: =SUMIFS([1]Табель!L:L,[1]Табель!E:E,C34,[1]Табель!B:B,">="&$Y$24,[1]Табель!B:B,"<"&$Y$25,[1]Табель!F:F,I34) -> #VALUE! | O34: =F34-L34-M34 -> #VALUE! | Q34: =O34*J34+(L34+M34)*K34 -> #VALUE! | R34: =ROUND(E34*0.22,2) -> 0 | S34: =E34*0.195 -> 0 | T34: =E34-S34 -> 0 | U34: =-ROUND((R34+E34),2) -> 0 | V34: =Q34-T34 -> #VALUE!
B35: 5 | C35: Бунтило В.І. | D35: =INDEX([1]ИНФО!C:C,MATCH(C35,[1]ИНФО!B:B,0)) -> Бунтило Віталій Іванович | E35: 5181.82 | F35: =SUMIFS([1]Табель!J:J,[1]Табель!E:E,C35,[1]Табель!B:B,">="&$Y$24,[1]Табель!B:B,"<"&$Y$25,[1]Табель!F:F,'МЕХАНИЗАТОРЫ ноябрь'!I35) -> #VALUE! | I35: Самосвал камаз | J35: =INDEX([1]ИНФО_СПЕЦТЕХНИКА!$F$4:$F$23,MATCH(I35,[1]ИНФО_СПЕЦТЕХНИКА!$D$4:$D$23,0)) -> 140 | K35: 100 | L35: =SUMIFS([1]Табель!K:K,[1]Табель!E:E,C35,[1]Табель!B:B,">="&$Y$24,[1]Табель!B:B,"<"&$Y$25,[1]Табель!F:F,I35) -> #VALUE! | M35: =SUMIFS([1]Табель!L:L,[1]Табель!E:E,C35,[1]Табель!B:B,">="&$Y$24,[1]Табель!B:B,"<"&$Y$25,[1]Табель!F:F,I35) -> #VALUE! | O35: =F35-L35-M35 -> #VALUE! | Q35: =O35*J35+(L35+M35)*K35 -> #VALUE! | R35: =ROUND(E35*0.22,2) -> 1140 | S35: =E35*0.195 -> 1010.4549 | T35: =E35-S35 -> 4171.3651 | U35: =-ROUND((R35+E35),2) -> -6321.82 | V35: =Q35-T35 -> #VALUE! | Y35: перегон на ладыжины (16 часов - 4 часа ТО - 1 час заправка)
B36: 6 | C36: Горячий І.В. | D36: =INDEX([1]ИНФО!C:C,MATCH(C36,[1]ИНФО!B:B,0)) -> Горячий Іван Васильович | E36: 9880 | F36: =SUMIFS([1]Табель!J:J,[1]Табель!E:E,C36,[1]Табель!B:B,">="&$Y$24,[1]Табель!B:B,"<"&$Y$25,[1]Табель!F:F,'МЕХАНИЗАТОРЫ ноябрь'!I36) -> #VALUE! | I36: Телескоп №2 | J36: =INDEX([1]ИНФО_СПЕЦТЕХНИКА!$F$4:$F$23,MATCH(I36,[1]ИНФО_СПЕЦТЕХНИКА!$D$4:$D$23,0)) -> 170 | K36: 100 | L36: =SUMIFS([1]Табель!K:K,[1]Табель!E:E,C36,[1]Табель!B:B,">="&$Y$24,[1]Табель!B:B,"<"&$Y$25,[1]Табель!F:F,I36) -> #VALUE! | M36: =SUMIFS([1]Табель!L:L,[1]Табель!E:E,C36,[1]Табель!B:B,">="&$Y$24,[1]Табель!B:B,"<"&$Y$25,[1]Табель!F:F,I36) -> #VALUE! | O36: =F36-L36-M36 -> #VALUE! | Q36: =O36*J36+(L36+M36)*K36 -> #VALUE! | R36: =ROUND(E36*0.22,2) -> 2173.6 | S36: =E36*0.195 -> 1926.6 | T36: =E36-S36 -> 7953.4 | U36: =-ROUND((R36+E36),2) -> -12053.6 | V36: =Q36-T36 -> #VALUE!
B37: 7 | C37: Зенкін Д.Ю. | D37: =INDEX([1]ИНФО!C:C,MATCH(C37,[1]ИНФО!B:B,0)) -> Зенкін Дмитро Юрійович | E37: 8204.55 | F37: =SUMIFS([1]Табель!J:J,[1]Табель!E:E,C37,[1]Табель!B:B,">="&$Y$24,[1]Табель!B:B,"<"&$Y$25,[1]Табель!F:F,'МЕХАНИЗАТОРЫ ноябрь'!I37) -> #VALUE! | I37: Экскаватор JCB 3CX 2008 | J37: =INDEX([1]ИНФО_СПЕЦТЕХНИКА!$F$4:$F$23,MATCH(I37,[1]ИНФО_СПЕЦТЕХНИКА!$D$4:$D$23,0)) -> 170 | K37: 100 | L37: =SUMIFS([1]Табель!K:K,[1]Табель!E:E,C37,[1]Табель!B:B,">="&$Y$24,[1]Табель!B:B,"<"&$Y$25,[1]Табель!F:F,I37) -> #VALUE! | M37: =SUMIFS([1]Табель!L:L,[1]Табель!E:E,C37,[1]Табель!B:B,">="&$Y$24,[1]Табель!B:B,"<"&$Y$25,[1]Табель!F:F,I37) -> #VALUE! | O37: =F37-L37-M37 -> #VALUE! | Q37: =O37*J37+(L37+M37)*K37 -> #VALUE! | R37: =ROUND(E37*0.22,2) -> 1805 | S37: =E37*0.195 -> 1599.8872 | T37: =E37-S37 -> 6604.6627 | U37: =-ROUND((R37+E37),2) -> -10009.55 | V37: =Q37-T37 -> #VALUE!
B38: 8 | C38: Карбунар Я.Д. | D38: =INDEX([1]ИНФО!C:C,MATCH(C38,[1]ИНФО!B:B,0)) -> Карбунар Ярослав Дмитрович | E38: =8981.81*Q38/(Q38+Q39) -> #VALUE! | F38: =SUMIFS([1]Табель!J:J,[1]Табель!E:E,C38,[1]Табель!B:B,">="&$Y$24,[1]Табель!B:B,"<"&$Y$25,[1]Табель!F:F,'МЕХАНИЗАТОРЫ ноябрь'!I38) -> #VALUE! | I38: Экскаватор JCB 2007 | J38: =INDEX([1]ИНФО_СПЕЦТЕХНИКА!$F$4:$F$23,MATCH(I38,[1]ИНФО_СПЕЦТЕХНИКА!$D$4:$D$23,0)) -> 170 | K38: 100 | L38: =SUMIFS([1]Табель!K:K,[1]Табель!E:E,C38,[1]Табель!B:B,">="&$Y$24,[1]Табель!B:B,"<"&$Y$25,[1]Табель!F:F,I38) -> #VALUE! | M38: =SUMIFS([1]Табель!L:L,[1]Табель!E:E,C38,[1]Табель!B:B,">="&$Y$24,[1]Табель!B:B,"<"&$Y$25,[1]Табель!F:F,I38) -> #VALUE! | O38: =F38-L38-M38 -> #VALUE! | Q38: =O38*J38+(L38+M38)*K38 -> #VALUE! | R38: =ROUND(E38*0.22,2) -> #VALUE! | S38: =E38*0.195 -> #VALUE! | T38: =E38-S38 -> #VALUE! | U38: =-ROUND((R38+E38),2) -> #VALUE! | V38: =Q38-T38 -> #VALUE!
C39: Карбунар Я.Д. | D39: =INDEX([1]ИНФО!C:C,MATCH(C39,[1]ИНФО!B:B,0)) -> Карбунар Ярослав Дмитрович | E39: =8981.81*Q39/(Q38+Q39) -> #VALUE! | F39: =SUMIFS([1]Табель!J:J,[1]Табель!E:E,C39,[1]Табель!B:B,">="&$Y$24,[1]Табель!B:B,"<"&$Y$25,[1]Табель!F:F,'МЕХАНИЗАТОРЫ ноябрь'!I39) -> #VALUE! | I39: Виброкаток | J39: =INDEX([1]ИНФО_СПЕЦТЕХНИКА!$F$4:$F$23,MATCH(I39,[1]ИНФО_СПЕЦТЕХНИКА!$D$4:$D$23,0)) -> 170 | K39: 100 | O39: =F39-L39-M39 -> #VALUE! | Q39: =O39*J39+(L39+M39)*K39 -> #VALUE! | R39: =ROUND(E39*0.22,2) -> #VALUE! | S39: =E39*0.195 -> #VALUE! | T39: =E39-S39 -> #VALUE! | U39: =-ROUND((R39+E39),2) -> #VALUE! | V39: =Q39-T39 -> #VALUE!
B40: 9 | C40: Косік Ю.А. | D40: =INDEX([1]ИНФО!C:C,MATCH(C40,[1]ИНФО!B:B,0)) -> Косік Юрій Анатолійович | E40: 9880 | F40: =SUMIFS([1]Табель!J:J,[1]Табель!E:E,C40,[1]Табель!B:B,">="&$Y$24,[1]Табель!B:B,"<"&$Y$25,[1]Табель!F:F,'МЕХАНИЗАТОРЫ ноябрь'!I40) -> #VALUE! | I40: Телескоп №4 | J40: =INDEX([1]ИНФО_СПЕЦТЕХНИКА!$F$4:$F$23,MATCH(I40,[1]ИНФО_СПЕЦТЕХНИКА!$D$4:$D$23,0)) -> 170 | K40: 100 | L40: =SUMIFS([1]Табель!K:K,[1]Табель!E:E,C40,[1]Табель!B:B,">="&$Y$24,[1]Табель!B:B,"<"&$Y$25,[1]Табель!F:F,I40) -> #VALUE! | M40: =SUMIFS([1]Табель!L:L,[1]Табель!E:E,C40,[1]Табель!B:B,">="&$Y$24,[1]Табель!B:B,"<"&$Y$25,[1]Табель!F:F,I40) -> #VALUE! | O40: =F40-L40-M40 -> #VALUE! | Q40: =O40*J40+(L40+M40)*K40 -> #VALUE! | R40: =ROUND(E40*0.22,2) -> 2173.6 | S40: =E40*0.195 -> 1926.6 | T40: =E40-S40 -> 7953.4 | U40: =-ROUND((R40+E40),2) -> -12053.6 | V40: =Q40-T40 -> #VALUE!
B41: 10 | C41: Красношапка М.П. | D41: =INDEX([1]ИНФО!C:C,MATCH(C41,[1]ИНФО!B:B,0)) -> 0 | F41: =SUMIFS([1]Табель!J:J,[1]Табель!E:E,C41,[1]Табель!B:B,">="&$Y$24,[1]Табель!B:B,"<"&$Y$25,[1]Табель!F:F,'МЕХАНИЗАТОРЫ ноябрь'!I41) -> #VALUE! | I41: РДК 250 (2) | J41: =INDEX([1]ИНФО_СПЕЦТЕХНИКА!$F$4:$F$23,MATCH(I41,[1]ИНФО_СПЕЦТЕХНИКА!$D$4:$D$23,0)) -> 140 | K41: 100 | L41: =SUMIFS([1]Табель!K:K,[1]Табель!E:E,C41,[1]Табель!B:B,">="&$Y$24,[1]Табель!B:B,"<"&$Y$25,[1]Табель!F:F,I41) -> #VALUE! | M41: =SUMIFS([1]Табель!L:L,[1]Табель!E:E,C41,[1]Табель!B:B,">="&$Y$24,[1]Табель!B:B,"<"&$Y$25,[1]Табель!F:F,I41) -> #VALUE! | O41: =F41-L41-M41 -> #VALUE! | Q41: =O41*J41+(L41+M41)*K41 -> #VALUE! | R41: =ROUND(E41*0.22,2) -> 0 | S41: =E41*0.195 -> 0 | T41: =E41-S41 -> 0 | U41: =-ROUND((R41+E41),2) -> 0 | V41: =Q41-T41 -> #VALUE!
B42: 11 | C42: Мусієнко І.І. | D42: =INDEX([1]ИНФО!C:C,MATCH(C42,[1]ИНФО!B:B,0)) -> Мусієнко Ігор Іванович | E42: 9500 | F42: =SUMIFS([1]Табель!J:J,[1]Табель!E:E,C42,[1]Табель!B:B,">="&$Y$24,[1]Табель!B:B,"<"&$Y$25,[1]Табель!F:F,'МЕХАНИЗАТОРЫ ноябрь'!I42) -> #VALUE! | I42: Телескоп №1 | J42: =INDEX([1]ИНФО_СПЕЦТЕХНИКА!$F$4:$F$23,MATCH(I42,[1]ИНФО_СПЕЦТЕХНИКА!$D$4:$D$23,0)) -> 170 | K42: 100 | L42: =SUMIFS([1]Табель!K:K,[1]Табель!E:E,C42,[1]Табель!B:B,">="&$Y$24,[1]Табель!B:B,"<"&$Y$25,[1]Табель!F:F,I42) -> #VALUE! | M42: =SUMIFS([1]Табель!L:L,[1]Табель!E:E,C42,[1]Табель!B:B,">="&$Y$24,[1]Табель!B:B,"<"&$Y$25,[1]Табель!F:F,I42) -> #VALUE! | O42: =F42-L42-M42 -> #VALUE! | Q42: =O42*J42+(L42+M42)*K42 -> #VALUE! | R42: =ROUND(E42*0.22,2) -> 2090 | S42: =E42*0.195 -> 1852.5 | T42: =E42-S42 -> 7647.5 | U42: =-ROUND((R42+E42),2) -> -11590 | V42: =Q42-T42 -> #VALUE!
B43: 12 | C43: Самойленко В.М. | D43: =INDEX([1]ИНФО!C:C,MATCH(C43,[1]ИНФО!B:B,0)) -> Самойленко Віктор Миколайович | E43: 9500 | F43: =SUMIFS([1]Табель!J:J,[1]Табель!E:E,C43,[1]Табель!B:B,">="&$Y$24,[1]Табель!B:B,"<"&$Y$25,[1]Табель!F:F,'МЕХАНИЗАТОРЫ ноябрь'!I43) -> #VALUE! | I43: МАЗ 264 | J43: =INDEX([1]ИНФО_СПЕЦТЕХНИКА!$F$4:$F$23,MATCH(I43,[1]ИНФО_СПЕЦТЕХНИКА!$D$4:$D$23,0)) -> 140 | K43: 100 | L43: =SUMIFS([1]Табель!K:K,[1]Табель!E:E,C43,[1]Табель!B:B,">="&$Y$24,[1]Табель!B:B,"<"&$Y$25,[1]Табель!F:F,I43) -> #VALUE! | M43: =SUMIFS([1]Табель!L:L,[1]Табель!E:E,C43,[1]Табель!B:B,">="&$Y$24,[1]Табель!B:B,"<"&$Y$25,[1]Табель!F:F,I43) -> #VALUE! | O43: =F43-L43-M43 -> #VALUE! | Q43: =O43*J43+(L43+M43)*K43 -> #VALUE! | R43: =ROUND(E43*0.22,2) -> 2090 | S43: =E43*0.195 -> 1852.5 | T43: =E43-S43 -> 7647.5 | U43: =-ROUND((R43+E43),2) -> -11590 | V43: =Q43-T43 -> #VALUE!
B44: 13 | C44: Скоц С.І. | D44: =INDEX([1]ИНФО!C:C,MATCH(C44,[1]ИНФО!B:B,0)) -> Скоц Сергій Іванович | E44: 9880 | F44: =SUMIFS([1]Табель!J:J,[1]Табель!E:E,C44,[1]Табель!B:B,">="&$Y$24,[1]Табель!B:B,"<"&$Y$25,[1]Табель!F:F,'МЕХАНИЗАТОРЫ ноябрь'!I44) -> #VALUE! | I44: Экскаватор JCB 220 | J44: =INDEX([1]ИНФО_СПЕЦТЕХНИКА!$F$4:$F$23,MATCH(I44,[1]ИНФО_СПЕЦТЕХНИКА!$D$4:$D$23,0)) -> 170 | K44: 100 | L44: =SUMIFS([1]Табель!K:K,[1]Табель!E:E,C44,[1]Табель!B:B,">="&$Y$24,[1]Табель!B:B,"<"&$Y$25,[1]Табель!F:F,I44) -> #VALUE! | M44: =SUMIFS([1]Табель!L:L,[1]Табель!E:E,C44,[1]Табель!B:B,">="&$Y$24,[1]Табель!B:B,"<"&$Y$25,[1]Табель!F:F,I44) -> #VALUE! | O44: =F44-L44-M44 -> #VALUE! | Q44: =O44*J44+(L44+M44)*K44 -> #VALUE! | R44: =ROUND(E44*0.22,2) -> 2173.6 | S44: =E44*0.195 -> 1926.6 | T44: =E44-S44 -> 7953.4 | U44: =-ROUND((R44+E44),2) -> -12053.6 | V44: =Q44-T44 -> #VALUE!
B45: 14 | C45: Трохименко В.Я. | D45: =INDEX([1]ИНФО!C:C,MATCH(C45,[1]ИНФО!B:B,0)) -> Трохименко Віталій Якович | E45: =(4750+4700)*Q45/(Q45+Q46) -> #VALUE! | F45: =SUMIFS([1]Табель!J:J,[1]Табель!E:E,C45,[1]Табель!B:B,">="&$Y$24,[1]Табель!B:B,"<"&$Y$25,[1]Табель!F:F,'МЕХАНИЗАТОРЫ ноябрь'!I45) -> #VALUE! | I45: Телескоп №1 | J45: =INDEX([1]ИНФО_СПЕЦТЕХНИКА!$F$4:$F$23,MATCH(I45,[1]ИНФО_СПЕЦТЕХНИКА!$D$4:$D$23,0)) -> 170 | K45: 100 | L45: =SUMIFS([1]Табель!K:K,[1]Табель!E:E,C45,[1]Табель!B:B,">="&$Y$24,[1]Табель!B:B,"<"&$Y$25,[1]Табель!F:F,I45) -> #VALUE! | M45: =SUMIFS([1]Табель!L:L,[1]Табель!E:E,C45,[1]Табель!B:B,">="&$Y$24,[1]Табель!B:B,"<"&$Y$25,[1]Табель!F:F,I45) -> #VALUE! | O45: =F45-L45-M45 -> #VALUE! | Q45: =O45*J45+(L45+M45)*K45 -> #VALUE! | R45: =ROUND(E45*0.22,2) -> #VALUE! | S45: =E45*0.195 -> #VALUE! | T45: =E45-S45 -> #VALUE! | U45: =-ROUND((R45+E45),2) -> #VALUE! | V45: =Q45-T45 -> #VALUE!
...

Sheet 2025_01_01
E2: =SUM(E4:E40) -> 2216 | F2: =SUM(F4:F40) -> 1987 | G2: =SUM(G4:G40) -> 229 | J2: =SUM(J4:J38) -> 472770 | U2: Січень 2025 =
A3: Счет в 1С | B3: Працівники організацій | C3: Начальное сальдно | D3: Соколнеко Т. | E3: Всего часы/ рейсы | F3: Раб. Часов / ко-во рейсов | G3: ТО / простой / коротк. рейс | H3: Цена за час/рейс | I3: ТО грн/час | J3: Итого | K3: Проверка | L3: ФОТ за январь 2025 | M3: Подразделение | N3: Ед. спецтехник | O3: К выплате | P3: конечное сальдо | U3: с 01.01-31.01(
A4: 958 | B4: Василиу Р.Г. | C4: 40 | D4: 48540 | E4: 215 | F4: 208 | G4: 7 | H4: 230 | I4: 100 | J4: =F4*H4+G4*I4 -> 48540 | K4: =J4-D4 -> 0 | L4: 7700 | M4: Глобино | N4: Телескоп 2 | O4: =ROUND(C4+D4-L4,-2) -> 40900 | P4: =C4+D4-L4-O4 -> -20 | Q4: на карту | U4: =B4&" ЗП "&$U$3&F4&" год. роботи*"&H4&") + ТО "&G4&" год.*100="&TEXT(J4,"# #0,00")&" ФОТ "&$U$2&TEXT(L4,"# #0,00")&". Борг компании: "&TEXT(P4,"# #0,00")&". До виплати - "&TEXT(O4,"# #0,00")&" грн." -> Василиу Р.Г. ЗП с 01.01-31.01(208 год. роботи*230) + ТО 7 год.*100=48 540,00 ФОТ Січень 2025 = 7 700,00. Борг компании: -20,00. До виплати - 40 900,00 грн.
A5: 961 | B5: Зубко О.В. | C5: 20 | D5: 9070 | E5: 40 | F5: 39 | G5: 1 | H5: 230 | I5: 100 | J5: =F5*H5+G5*I5 -> 9070 | K5: =J5-D5 -> 0 | L5: 0 | M5: Глобино | N5: Телескоп JCB 535-140 (№4) | O5: =ROUND(C5+D5-L5,-2) -> 9100 | P5: =C5+D5+D6-L5-O5-O6 -> 10 | U5: =B5&" ЗП "&$U$3&F5&" год. роботи*"&H5&") + ТО "&G5&" год.*100="&TEXT(J5,"# #0,00")&" ФОТ "&$U$2&TEXT(L5,"# #0,00")&". Борг компании: "&TEXT(P5,"# #0,00")&". До виплати - "&TEXT(O5,"# #0,00")&" грн." -> Зубко О.В. ЗП с 01.01-31.01(39 год. роботи*230) + ТО 1 год.*100=9 070,00 ФОТ Січень 2025 = 0,00. Борг компании: 10,00. До виплати - 9 100,00 грн.
A6: 960 | B6: Зубко О.В. | D6: 34620 | E6: 159 | F6: 144 | G6: 15 | H6: 230 | I6: 100 | J6: =F6*H6+G6*I6 -> 34620 | K6: =J6-D6 -> 0 | L6: 0 | M6: Глобино | N6: Телескоп JCB 540-170 №5 | O6: =ROUND(C6+D6-L6,-2) -> 34600 | Q6: Гриценко | U6: =B6&" ЗП "&$U$3&F6&" год. роботи*"&H6&") + ТО "&G6&" год.*100="&TEXT(J6,"# #0,00")&" ФОТ "&$U$2&TEXT(L6,"# #0,00")&". Борг компании: "&TEXT(P6,"# #0,00")&". До виплати - "&TEXT(O6,"# #0,00")&" грн." -> Зубко О.В. ЗП с 01.01-31.01(144 год. роботи*230) + ТО 15 год.*100=34 620,00 ФОТ Січень 2025 = 0,00. Борг компании: 0,00. До виплати - 34 600,00 грн.
A7: 959 | B7: Грунковский В.В. | C7: 0 | D7: 30150 | E7: 139 | F7: 125 | G7: 14 | H7: 230 | I7: 100 | J7: =F7*H7+G7*I7 -> 30150 | K7: =J7-D7 -> 0 | L7: 0 | M7: Глобино | N7: Телескоп JCB 535-140 (№4) | O7: =ROUND(C7+D7-L7,-2) -> 30200 | P7: =C7+D7-L7-O7 -> -50 | Q7: Гриценко | U7: =B7&" ЗП "&$U$3&F7&" год. роботи*"&H7&") + ТО "&G7&" год.*100="&TEXT(J7,"# #0,00")&" ФОТ "&$U$2&TEXT(L7,"# #0,00")&". Борг компании: "&TEXT(P7,"# #0,00")&". До виплати - "&TEXT(O7,"# #0,00")&" грн." -> Грунковский В.В. ЗП с 01.01-31.01(125 год. роботи*230) + ТО 14 год.*100=30 150,00 ФОТ Січень 2025 = 0,00. Борг компании: -50,00. До виплати - 30 200,00 грн.
A8: 964 | B8: Карбунар Я.Д. | C8: 25.75 | D8: 42760 | E8: 191 | F8: 182 | G8: 9 | H8: 230 | I8: 100 | J8: =F8*H8+G8*I8 -> 42760 | K8: =J8-D8 -> 0 | L8: 8008 | M8: Глобино | N8: Экскаватор JCB | O8: =ROUND(C8+D8-L8,-2) -> 34800 | P8: =C8+D8-L8-O8 -> -22.25 | Q8: карта | U8: =B8&" ЗП "&$U$3&F8&" год. роботи*"&H8&") + ТО "&G8&" год.*100="&TEXT(J8,"# #0,00")&" ФОТ "&$U$2&TEXT(L8,"# #0,00")&". Борг компании: "&TEXT(P8,"# #0,00")&". До виплати - "&TEXT(O8,"# #0,00")&" грн." -> Карбунар Я.Д. ЗП с 01.01-31.01(182 год. роботи*230) + ТО 9 год.*100=42 760,00 ФОТ Січень 2025 = 8 008,00. Борг компании: -22,25. До виплати - 34 800,00 грн.
A9: 965 | B9: Скоц С.И. | C9: -43.94 | D9: 38510 | E9: 181 | F9: 157 | G9: 24 | H9: 230 | I9: 100 | J9: =F9*H9+G9*I9 -> 38510 | K9: =J9-D9 -> 0 | L9: 8008 | M9: Глобино | N9: Экскаватор JCB 2013 | O9: =ROUND(C9+D9-L9,-2) -> 30500 | P9: =C9+D9-L9-O9 -> -41.94 | Q9: карта | U9: =B9&" ЗП "&$U$3&F9&" год. роботи*"&H9&") + ТО "&G9&" год.*100="&TEXT(J9,"# #0,00")&" ФОТ "&$U$2&TEXT(L9,"# #0,00")&". Борг компании: "&TEXT(P9,"# #0,00")&". До виплати - "&TEXT(O9,"# #0,00")&" грн." -> Скоц С.И. ЗП с 01.01-31.01(157 год. роботи*230) + ТО 24 год.*100=38 510,00 ФОТ Січень 2025 = 8 008,00. Борг компании: -41,94. До виплати - 30 500,00 грн.
A10: 1056 | B10: Ляшко С.М. | C10: 36.25 | D10: 690 | E10: 3 | F10: 3 | G10: 0 | H10: 230 | I10: 100 | J10: =F10*H10+G10*I10 -> 690 | K10: =J10-D10 -> 0 | L10: 405.87994 | M10: Глобино | N10: Экскаватор JCB 2013 | O10: =ROUND(C10+D10-L10,-2) -> 300 | P10: =C10+D10+D11+D12-L10-L11-L12-O10-O11-O12 -> 26.26 | Q10: карта | U10: =B10&" ЗП "&$U$3&F10&" год. роботи*"&H10&") + ТО "&G10&" год.*100="&TEXT(J10,"# #0,00")&" ФОТ "&$U$2&TEXT(L10,"# #0,00")&". Борг компании: "&TEXT(P10,"# #0,00")&". До виплати - "&TEXT(O10,"# #0,00")&" грн." -> Ляшко С.М. ЗП с 01.01-31.01(3 год. роботи*230) + ТО 0 год.*100=690,00 ФОТ Січень 2025 = 405,88. Борг компании: 26,26. До виплати - 300,00 грн.
A11: 968 | B11: Ляшко С.М. | D11: 4920 | E11: 24 | F11: 21 | G11: 3 | H11: 220 | I11: 100 | J11: =F11*H11+G11*I11 -> 4920 | K11: =J11-D11 -> 0 | L11: 2894.1143 | M11: Глобино | N11: Виброкаток | O11: =ROUND(C11+D11-L11,-2) -> 2000 | U11: =B11&" ЗП "&$U$3&F11&" год. роботи*"&H11&") + ТО "&G11&" год.*100="&TEXT(J11,"# #0,00")&" ФОТ "&$U$2&TEXT(L11,"# #0,00")&". Борг компании: "&TEXT(P11,"# #0,00")&". До виплати - "&TEXT(O11,"# #0,00")&" грн." -> Ляшко С.М. ЗП с 01.01-31.01(21 год. роботи*220) + ТО 3 год.*100=4 920,00 ФОТ Січень 2025 = 2 894,11. Борг компании: 0,00. До виплати - 2 000,00 грн.
A12: 970 | B12: Ляшко С.М. | D12: 7480 | E12: 54 | F12: 16 | G12: 38 | H12: 230 | I12: 100 | J12: =F12*H12+G12*I12 -> 7480 | K12: =J12-D12 -> 0 | L12: 4399.9957 | M12: Глобино | N12: Экскаватор JCB 220 | O12: =ROUND(C12+D12-L12,-2) -> 3100 | U12: =B12&" ЗП "&$U$3&F12&" год. роботи*"&H12&") + ТО "&G12&" год.*100="&TEXT(J12,"# #0,00")&" ФОТ "&$U$2&TEXT(L12,"# #0,00")&". Борг компании: "&TEXT(P12,"# #0,00")&". До виплати - "&TEXT(O12,"# #0,00")&" грн." -> Ляшко С.М. ЗП с 01.01-31.01(16 год. роботи*230) + ТО 38 год.*100=7 480,00 ФОТ Січень 2025 = 4 400,00. Борг компании: 0,00. До виплати - 3 100,00 грн.
A13: 971 | B13: Болох В.В. | C13: 10 | D13: 49100 | E13: 185 | F13: 180 | G13: 5 | H13: 270 | I13: 100 | J13: =F13*H13+G13*I13 -> 49100 | K13: =J13-D13 -> 0 | L13: 7700 | M13: Глобино | N13: Автокран XCMG | O13: =ROUND(C13+D13-L13,-2) -> 41400 | P13: =C13+D13-L13-O13 -> 10 | Q13: карта | U13: =B13&" ЗП "&$U$3&F13&" год. роботи*"&H13&") + ТО "&G13&" год.*100="&TEXT(J13,"# #0,00")&" ФОТ "&$U$2&TEXT(L13,"# #0,00")&". Борг компании: "&TEXT(P13,"# #0,00")&". До виплати - "&TEXT(O13,"# #0,00")&" грн." -> Болох В.В. ЗП с 01.01-31.01(180 год. роботи*270) + ТО 5 год.*100=49 100,00 ФОТ Січень 2025 = 7 700,00. Борг компании: 10,00. До виплати - 41 400,00 грн.
A14: 967 | B14: Борисенко О.М. | C14: 72.5 | D14: 1760 | E14: 8 | F14: 8 | G14: 0 | H14: 220 | I14: 100 | J14: =F14*H14+G14*I14 -> 1760 | K14: =J14-D14 -> 0 | L14: 314.94696 | M14: Глобино | N14: Виброкаток | O14: =ROUND(C14+D14-L14,-2) -> 1500 | P14: =C14+D14+D15-L14-L15-O14-O15 -> 2.5 | Q14: карта | U14: =B14&" ЗП "&$U$3&F14&" год. роботи*"&H14&") + ТО "&G14&" год.*100="&TEXT(J14,"# #0,00")&" ФОТ "&$U$2&TEXT(L14,"# #0,00")&". Борг компании: "&TEXT(P14,"# #0,00")&". До виплати - "&TEXT(O14,"# #0,00")&" грн." -> Борисенко О.М. ЗП с 01.01-31.01(8 год. роботи*220) + ТО 0 год.*100=1 760,00 ФОТ Січень 2025 = 314,95. Борг компании: 2,50. До виплати - 1 500,00 грн.
A15: 966 | B15: Борисенко О.М. | D15: 41270 | E15: 156 | F15: 151 | G15: 5 | H15: 270 | I15: 100 | J15: =F15*H15+G15*I15 -> 41270 | K15: =J15-D15 -> 0 | L15: 7385.053 | M15: Глобино | N15: Автокран Клинцы | O15: =ROUND(C15+D15-L15,-2) -> 33900 | U15: =B15&" ЗП "&$U$3&F15&" год. роботи*"&H15&") + ТО "&G15&" год.*100="&TEXT(J15,"# #0,00")&" ФОТ "&$U$2&TEXT(L15,"# #0,00")&". Борг компании: "&TEXT(P15,"# #0,00")&". До виплати - "&TEXT(O15,"# #0,00")&" грн." -> Борисенко О.М. ЗП с 01.01-31.01(151 год. роботи*270) + ТО 5 год.*100=41 270,00 ФОТ Січень 2025 = 7 385,05. Борг компании: 0,00. До виплати - 33 900,00 грн.
A16: 969 | B16: Гончаренко О.П. | C16: -20 | D16: 27600 | E16: 126 | F16: 125 | G16: 1 | H16: 220 | I16: 100 | J16: =F16*H16+G16*I16 -> 27600 | K16: =J16-D16 -> 0 | L16: 0 | M16: Глобино | N16: Виброкаток | O16: 0 | P16: =C16+D16-L16-O16 -> 27580 | Q16: заморожено | U16: =B16&" ЗП "&$U$3&F16&" год. роботи*"&H16&") + ТО "&G16&" год.*100="&TEXT(J16,"# #0,00")&" ФОТ "&$U$2&TEXT(L16,"# #0,00")&". Борг компании: "&TEXT(P16,"# #0,00")&". До виплати - "&TEXT(O16,"# #0,00")&" грн." -> Гончаренко О.П. ЗП с 01.01-31.01(125 год. роботи*220) + ТО 1 год.*100=27 600,00 ФОТ Січень 2025 = 0,00. Борг компании: 27 580,00. До виплати - 0,00 грн.
A17: 972 | B17: Черненко А.С. | C17: 0 | D17: 33500 | E17: 179 | F17: 156 | G17: 23 | H17: 200 | I17: 100 | J17: =F17*H17+G17*I17 -> 33500 | K17: =J17-D17 -> 0 | L17: 7700 | M17: Глобино | N17: МАЗ 264 | O17: =ROUND(C17+D17-L17,-2) -> 25800 | P17: =C17+D17-L17-O17 -> 0 | Q17: карта | U17: =B17&" ЗП "&$U$3&F17&" год. роботи*"&H17&") + ТО "&G17&" год.*100="&TEXT(J17,"# #0,00")&" ФОТ "&$U$2&TEXT(L17,"# #0,00")&". Борг компании: "&TEXT(P17,"# #0,00")&". До виплати - "&TEXT(O17,"# #0,00")&" грн." -> Черненко А.С. ЗП с 01.01-31.01(156 год. роботи*200) + ТО 23 год.*100=33 500,00 ФОТ Січень 2025 = 7 700,00. Борг компании: 0,00. До виплати - 25 800,00 грн.
A18: 973 | B18: Комаров Д.В. | C18: 0 | D18: 9400 | E18: 56 | F18: 38 | G18: 18 | H18: 200 | I18: 100 | J18: =F18*H18+G18*I18 -> 9400 | K18: =J18-D18 -> 0 | L18: 2678.2602 | M18: Глобино | N18: МАЗ 265 | O18: =ROUND(C18+D18-L18,-2) -> 6700 | P18: =C18+D18-L18-O18 -> 21.7398 | Q18: карта | U18: =B18&" ЗП "&$U$3&F18&" год. роботи*"&H18&") + ТО "&G18&" год.*100="&TEXT(J18,"# #0,00")&" ФОТ "&$U$2&TEXT(L18,"# #0,00")&". Борг компании: "&TEXT(P18,"# #0,00")&". До виплати - "&TEXT(O18,"# #0,00")&" грн." -> Комаров Д.В. ЗП с 01.01-31.01(38 год. роботи*200) + ТО 18 год.*100=9 400,00 ФОТ Січень 2025 = 2 678,26. Борг компании: 21,74. До виплати - 6 700,00 грн.
A19: 974 | B19: Сокур С.О. | C19: 0 | D19: 19300 | E19: 101 | F19: 92 | G19: 9 | H19: 200 | I19: 100 | J19: =F19*H19+G19*I19 -> 19300 | K19: =J19-D19 -> 0 | L19: 0 | M19: Глобино | N19: МАЗ 265 | O19: =ROUND(C19+D19-L19,-2) -> 19300 | P19: =C19+D19-L19-O19 -> 0 | U19: =B19&" ЗП "&$U$3&F19&" год. роботи*"&H19&") + ТО "&G19&" год.*100="&TEXT(J19,"# #0,00")&" ФОТ "&$U$2&TEXT(L19,"# #0,00")&". Борг компании: "&TEXT(P19,"# #0,00")&". До виплати - "&TEXT(O19,"# #0,00")&" грн." -> Сокур С.О. ЗП с 01.01-31.01(92 год. роботи*200) + ТО 9 год.*100=19 300,00 ФОТ Січень 2025 = 0,00. Борг компании: 0,00. До виплати - 19 300,00 грн.
A20: 980 | B20: Запара С.М | C20: -20.8 | D20: 39000 | E20: 195 | F20: 195 | G20: 0 | H20: 200 | I20: 100 | J20: =F20*H20+G20*I20 -> 39000 | K20: =J20-D20 -> 0 | L20: 7700 | M20: Глобино | N20: РДК 250-3№2 | O20: =ROUND(C20+D20-L20,-2) -> 31300 | P20: =C20+D20-L20-O20 -> -20.8 | Q20: карта | U20: =B20&" ЗП "&$U$3&F20&" год. роботи*"&H20&") + ТО "&G20&" год.*100="&TEXT(J20,"# #0,00")&" ФОТ "&$U$2&TEXT(L20,"# #0,00")&". Борг компании: "&TEXT(P20,"# #0,00")&". До виплати - "&TEXT(O20,"# #0,00")&" грн." -> Запара С.М ЗП с 01.01-31.01(195 год. роботи*200) + ТО 0 год.*100=39 000,00 ФОТ Січень 2025 = 7 700,00. Борг компании: -20,80. До виплати - 31 300,00 грн.
A21: 975 | B21: Гончаренко В.П. | C21: 0 | D21: 16100 | E21: 90 | F21: 71 | G21: 19 | H21: 200 | I21: 100 | J21: =F21*H21+G21*I21 -> 16100 | K21: =J21-D21 -> 0 | L21: 0 | M21: Глобино | N21: Самосвал МАЗ | O21: =ROUND(C21+D21-L21,-2) -> 16100 | P21: =C21+D21+D22+D23-L21-O21-O22-O23 -> 0 | Q21: Гриценко | U21: =B21&" ЗП "&$U$3&F21&" год. роботи*"&H21&") + ТО "&G21&" год.*100="&TEXT(J21,"# #0,00")&" ФОТ "&$U$2&TEXT(L21,"# #0,00")&". Борг компании: "&TEXT(P21,"# #0,00")&". До виплати - "&TEXT(O21,"# #0,00")&" грн." -> Гончаренко В.П. ЗП с 01.01-31.01(71 год. роботи*200) + ТО 19 год.*100=16 100,00 ФОТ Січень 2025 = 0,00. Борг компании: 0,00. До виплати - 16 100,00 грн.
B22: Гончаренко В.П. | D22: 8800 | E22: 44 | F22: 44 | G22: 0 | H22: 200 | I22: 100 | J22: =F22*H22+G22*I22 -> 8800 | K22: =J22-D22 -> 0 | L22: 0 | M22: Глобино Щебень | N22: Самосвал МАЗ | O22: =ROUND(C22+D22-L22,-2) -> 8800 | U22: =B22&" ЗП "&$U$3&F22&" год. роботи*"&H22&") + ТО "&G22&" год.*100="&TEXT(J22,"# #0,00")&" ФОТ "&$U$2&TEXT(L22,"# #0,00")&". Борг компании: "&TEXT(P22,"# #0,00")&". До виплати - "&TEXT(O22,"# #0,00")&" грн." -> Гончаренко В.П. ЗП с 01.01-31.01(44 год. роботи*200) + ТО 0 год.*100=8 800,00 ФОТ Січень 2025 = 0,00. Борг компании: 0,00. До виплати - 8 800,00 грн.
A23: 976 | B23: Гончаренко В.П. | D23: 5800 | E23: 32 | F23: 26 | G23: 6 | H23: 200 | I23: 100 | J23: =F23*H23+G23*I23 -> 5800 | K23: =J23-D23 -> 0 | L23: 0 | M23: Глобино | N23: Самосвал МАЗ №2 | O23: =ROUND(C23+D23-L23,-2) -> 5800 | U23: =B23&" ЗП "&$U$3&F23&" год. роботи*"&H23&") + ТО "&G23&" год.*100="&TEXT(J23,"# #0,00")&" ФОТ "&$U$2&TEXT(L23,"# #0,00")&". Борг компании: "&TEXT(P23,"# #0,00")&". До виплати - "&TEXT(O23,"# #0,00")&" грн." -> Гончаренко В.П. ЗП с 01.01-31.01(26 год. роботи*200) + ТО 6 год.*100=5 800,00 ФОТ Січень 2025 = 0,00. Борг компании: 0,00. До виплати - 5 800,00 грн.
A24: 979 | B24: Селивончик И.П. | C24: 0 | D24: 2800 | E24: 22 | F24: 6 | G24: 16 | H24: 200 | I24: 100 | J24: =F24*H24+G24*I24 -> 2800 | K24: =J24-D24 -> 0 | M24: Путровка | N24: Самосвал Камаз | O24: =ROUND(C24+D24-L24,-2) -> 2800 | P24: =C24+D24-L24-O24 -> 0 | Q24: заморожено | U24: =B24&" ЗП "&$U$3&F24&" год. роботи*"&H24&") + ТО "&G24&" год.*100="&TEXT(J24,"# #0,00")&" ФОТ "&$U$2&TEXT(L24,"# #0,00")&". Борг компании: "&TEXT(P24,"# #0,00")&". До виплати - "&TEXT(O24,"# #0,00")&" грн." -> Селивончик И.П. ЗП с 01.01-31.01(6 год. роботи*200) + ТО 16 год.*100=2 800,00 ФОТ Січень 2025 = 0,00. Борг компании: 0,00. До виплати - 2 800,00 грн.
A25: 977 | B25: Роменский В.В. | C25: 22.5 | D25: 1600 | E25: 16 | F25: 0 | G25: 16 | H25: 200 | I25: 100 | J25: =F25*H25+G25*I25 -> 1600 | K25: =J25-D25 -> 0 | M25: Глобино | N25: Самосвал МАЗ №2 | O25: =ROUND(C25+D25-L25,-2) -> 1600 | P25: =C25+D25-L25-O25 -> 22.5 | Q25: Гриценко | U25: =B25&" ЗП "&$U$3&F25&" год. роботи*"&H25&") + ТО "&G25&" год.*100="&TEXT(J25,"# #0,00")&" ФОТ "&$U$2&TEXT(L25,"# #0,00")&". Борг компании: "&TEXT(P25,"# #0,00")&". До виплати - "&TEXT(O25,"# #0,00")&" грн." -> Роменский В.В. ЗП с 01.01-31.01(0 год. роботи*200) + ТО 16 год.*100=1 600,00 ФОТ Січень 2025 = 0,00. Борг компании: 22,50. До виплати - 1 600,00 грн.
I26: 100 | J26: =F26*H26+G26*I26 -> 0 | K26: =J26-D26 -> 0 | O26: =ROUND(C26+D26-L26,-2) -> 0 | P26: =C26+D26-L26-O26 -> 0 | U26: =B26&" ЗП "&$U$3&F26&" год. роботи*"&H26&") + ТО "&G26&" год.*100="&TEXT(J26,"# #0,00")&" ФОТ "&$U$2&TEXT(L26,"# #0,00")&". Борг компании: "&TEXT(P26,"# #0,00")&". До виплати - "&TEXT(O26,"# #0,00")&" грн." -> ЗП с 01.01-31.01( год. роботи*) + ТО год.*100=0,00 ФОТ Січень 2025 = 0,00. Борг компании: 0,00. До виплати - 0,00 грн.
I27: 100 | J27: =F27*H27+G27*I27 -> 0 | K27: =J27-D27 -> 0 | O27: =ROUND(C27+D27-L27,-2) -> 0 | P27: =C27+D27-L27-O27 -> 0 | U27: =B27&" ЗП "&$U$3&F27&" год. роботи*"&H27&") + ТО "&G27&" год.*100="&TEXT(J27,"# #0,00")&" ФОТ "&$U$2&TEXT(L27,"# #0,00")&". Борг компании: "&TEXT(P27,"# #0,00")&". До виплати - "&TEXT(O27,"# #0,00")&" грн." -> ЗП с 01.01-31.01( год. роботи*) + ТО год.*100=0,00 ФОТ Січень 2025 = 0,00. Борг компании: 0,00. До виплати - 0,00 грн.
I28: 100 | J28: =F28*H28+G28*I28 -> 0 | K28: =J28-D28 -> 0 | O28: =ROUND(C28+D28-L28,-2) -> 0 | P28: =C28+D28-L28-O28 -> 0 | U28: =B28&" ЗП "&$U$3&F28&" год. роботи*"&H28&") + ТО "&G28&" год.*100="&TEXT(J28,"# #0,00")&" ФОТ "&$U$2&TEXT(L28,"# #0,00")&". Борг компании: "&TEXT(P28,"# #0,00")&". До виплати - "&TEXT(O28,"# #0,00")&" грн." -> ЗП с 01.01-31.01( год. роботи*) + ТО год.*100=0,00 ФОТ Січень 2025 = 0,00. Борг компании: 0,00. До виплати - 0,00 грн.
