Workbook

Sheet Взаиморасчеты
A1: Отработанно за ноябрь 2022 | B1: =Ноябрь!H24 -> 0
A2: Оплаты с р/с Индастриалбуда
A3: Статья ДДС | B3: Сумма | C3: Комментарий
A4: топливо | B4: 30823.45 | C4: переходящий остаток
A5: топливо | B5: 29176.55 | C5: переходящий остаток
A6: топливо | B6: 293020 | C6: оплаты за месяц
A7: Разрешительная документация | B7: 960 | C7: Навчання Борисенко
A8: Страхование | B8: 3744 | C8: Телескоп 4, JCB 3CX 2008
A9: ЗП с налогами | B9: 130516.49 | C9: Выплаченная ЗП, удержания из ЗП и налоги на ЗП
B10: =SUM(B4:B9) -> 488240.49
A11: Полученная предоплата | B11: 599456 | C11: 60% предоплаты от бюджета на ноябрь
A12: К выплате с Индастриалбуда | B12: =B1-B10-B11 -> -1087696.5 | C12: Итог по ноябрю по взаиморасчетам
A14: Предоплата на декабрь | B14: 649978.86 | C14: 60% предоплаты от бюджета на декабрь
A16: К выплате с Индастриалбуда | B16: =B12+B14 -> -437717.63

Sheet Ноябрь
A1: Техника | B1: Объект | C1: Стоимость за 1 час, грн | D1: План | F1: предоплата 60% | G1: Факт | I1: Распределение предоплаты по факту отработанного на объектах | J1: Сумма к взаиморасчетам, грн | K1: Оплаты с Индастриалбуд | P1: Поступление на Индастриал от сторонних заказчиков, грн | Q1: Сумма к взаиморасчетам с учетом движения ДС на р/с Индастриалбуд, грн | S1: Распределение предоплаты по факту отработанного на объектах
D2: кол-во часов | E2: сумма, грн | G2: Кол-во Часов | H2: Сума | K2: ЗП механизаторов с налогами, грн. | L2: Разрешительная документация, грн. | M2: Страховка, грн | N2: Топливо, грн | O2: вместе оплаченно, грн
A3: Телескоп 1 | B3: Староконстантинов | C3: =467.63 -> 467.63 | D3: =18*8 -> 144 | E3: =C3*D3 -> 67338.72 | F3: =E3*0.6 -> 40403.232 | G3: 155 | H3: =C3*G3 -> 72482.65 | I3: =ROUND($F$9/$H$9*H3,2) -> 152671.27 | J3: =H3-I3 -> -80188.62 | K3: -8187.98 | N3: -44609.48 | O3: =SUM(K3:N3) -> -52797.46 | Q3: =J3+O3+P3 -> -132986.08 | S3: =ROUND($F$9/$H$9*R3,2) -> 0
A4: Экскаватор JCB 220 | B4: Староконстантинов | C4: 995.97 | D4: =15*8 -> 120 | E4: =C4*D4 -> 119516.4 | F4: =E4*0.6 -> 71709.84 | G4: 22 | H4: =C4*G4 -> 21911.34 | I4: =ROUND($F$9/$H$9*H4,2) -> 46152.18 | J4: =H4-I4 -> -24240.84 | K4: -12053.6 | N4: -70565.54 | O4: =SUM(K4:N4) -> -82619.14 | P4: =12000+12000+12000+12000+9000+12000 -> 69000 | Q4: =J4+O4+P4 -> -37859.98 | S4: =ROUND($F$9/$H$9*R4,2) -> 0
A5: Виброкаток | B5: Староконстантинов | C5: 544.05 | D5: =5*8 -> 40 | E5: =C5*D5 -> 21762 | F5: =E5*0.6 -> 13057.2 | H5: =C5*G5 -> 0 | I5: =ROUND($F$9/$H$9*H5,2) -> 0 | J5: =H5-I5 -> 0 | K5: -860.11 | O5: =SUM(K5:N5) -> -860.11 | P5: 8800 | Q5: =J5+O5+P5 -> 7939.89 | S5: =ROUND($F$9/$H$9*R5,2) -> 0
A6: МАЗ 264 | B6: Староконстантинов | C6: 355.37 | D6: =15*8 -> 120 | E6: =C6*D6 -> 42644.4 | F6: =E6*0.6 -> 25586.64 | H6: =C6*G6 -> 0 | I6: =ROUND($F$9/$H$9*H6,2) -> 0 | J6: =H6-I6 -> 0 | K6: -6224 | N6: -969 | O6: =SUM(K6:N6) -> -7193 | Q6: =J6+O6+P6 -> -7193 | S6: =ROUND($F$9/$H$9*R6,2) -> 0
A7: РДК 250 | B7: Староконстантинов | C7: 304.15 | D7: =21*8 -> 168 | E7: =C7*D7 -> 51097.2 | F7: =E7*0.6 -> 30658.32 | H7: =C7*G7 -> 0 | I7: =ROUND($F$9/$H$9*H7,2) -> 0 | J7: =H7-I7 -> 0 | O7: =SUM(K7:N7) -> 0 | Q7: =J7+O7+P7 -> 0 | S7: =ROUND($F$9/$H$9*R7,2) -> 0
A8: КАМАЗ | B8: Староконстантинов | C8: 430.84 | D8: =15*8 -> 120 | E8: =C8*D8 -> 51700.8 | F8: =E8*0.6 -> 31020.48 | G8: 15 | H8: =C8*G8 -> 6462.6 | I8: =ROUND($F$9/$H$9*H8,2) -> 13612.27 | J8: =H8-I8 -> -7149.67 | K8: -6224 | O8: =SUM(K8:N8) -> -6224 | Q8: =J8+O8+P8 -> -13373.67 | S8: =ROUND($F$9/$H$9*R8,2) -> 0
A9: Вместе по объекту Староконстантинов | E9: =SUM(E3:E8) -> 354059.52 | F9: =SUM(F3:F8) -> 212435.71 | H9: =SUM(H3:H8) -> 100856.59 | I9: =SUM(I3:I8) -> 212435.72 | J9: =SUM(J3:J8) -> -111579.13 | O9: =SUM(O3:O8) -> -149693.71 | P9: =SUM(P3:P8) -> 77800 | Q9: =SUM(Q3:Q8) -> -183472.84 | S9: =Q9 -> -183472.84
A10: Телескоп 2 | B10: Приднепровский МЕТАЛЛ | C10: 467.63 | D10: =15*8 -> 120 | E10: =C10*D10 -> 56115.6 | F10: =E10*0.6 -> 33669.36 | G10: 149 | H10: =C10*G10 -> 69676.87 | I10: =ROUND($F$12/$H$12*H10,2) -> 41203.42 | J10: =H10-F10 -> 36007.51 | K10: -7578 | N10: -13042.04 | O10: =SUM(K10:N10) -> -20620.04 | Q10: =J10+O10+P10 -> 15387.47 | S10: =ROUND($R$12/$H$12*H10,2) -> 10604.39
A11: Экскаватор JCB 2013 | B11: Приднепровский МЕТАЛЛ | C11: 496.93 | D11: =14*8 -> 112 | E11: =C11*D11 -> 55656.16 | F11: =E11*0.6 -> 33393.696 | G11: 88 | H11: =C11*G11 -> 43729.84 | I11: =ROUND($F$12/$H$12*H11,2) -> 25859.64 | J11: =H11-F11 -> 10336.144 | K11: -4475.6 | N11: -5888.21 | O11: =SUM(K11:N11) -> -10363.81 | P11: 1900 | Q11: =J11+O11+P11 -> 1872.334 | S11: =ROUND($R$12/$H$12*H11,2) -> 6655.41
A12: Вместе по объекту Приднепровский МЕТАЛЛ | E12: =E10 -> 56115.6 | F12: =SUM(F10:F11) -> 67063.056 | H12: =SUM(H10:H11) -> 113406.71 | I12: =SUM(I10:I11) -> 67063.06 | J12: =SUM(J10:J11) -> 46343.654 | O12: =SUM(O10:O11) -> -30983.85 | P12: =SUM(P10:P11) -> 1900 | Q12: =SUM(Q10:Q11) -> 17259.804 | R12: =J12+O12+P12 -> 17259.804 | S12: =SUM(S10:S11) -> 17259.8
A13: Телескоп 5 | B13: Ретал | C13: 467.63 | D13: =22*8 -> 176 | E13: =C13*D13 -> 82302.88 | F13: =E13*0.6 -> 49381.728 | G13: 280 | H13: =C13*G13 -> 130936.4 | I13: =ROUND($F$17/$H$17*H13,2) -> 62309.95 | J13: =H13-F13 -> 81554.672 | K13: -12053.6 | N13: -33558.39 | O13: =SUM(K13:N13) -> -45611.99 | Q13: =J13+O13+P13 -> 35942.682 | S13: =ROUND($Q$17/$H$17*H13,2) -> 29699.9
A14: Экскаватор JCB 2008 | B14: Ретал | C14: 496.93 | D14: =22*8 -> 176 | E14: =C14*D14 -> 87459.68 | F14: =E14*0.6 -> 52475.808 | G14: 153 | H14: =C14*G14 -> 76030.29 | I14: =ROUND($F$17/$H$17*H14,2) -> 36181.25 | J14: =H14-F14 -> 23554.482 | K14: -11480.73 | M14: -1872 | N14: -10562.68 | O14: =SUM(K14:N14) -> -23915.41 | Q14: =J14+O14+P14 -> -360.928 | S14: =ROUND($Q$17/$H$17*H14,2) -> 17245.72
A15: Haulotte | B15: Ретал | C15: 802.86 | D15: 22 | E15: =C15*D15 -> 17662.92 | F15: =E15*0.6 -> 10597.752 | G15: 26 | H15: =C15*G15 -> 20874.36 | I15: =ROUND($F$17/$H$17*H15,2) -> 9933.68 | J15: =H15-F15 -> 10276.608 | O15: =SUM(K15:N15) -> 0 | Q15: =J15+O15+P15 -> 10276.608 | S15: =ROUND($Q$17/$H$17*H15,2) -> 4734.87
A16: Клинцы | B16: Ретал | C16: 490.46 | D16: =20*8 -> 160 | E16: =C16*D16 -> 78473.6 | F16: =E16*0.6 -> 47084.16 | G16: 219 | H16: =C16*G16 -> 107410.74 | I16: =ROUND($F$17/$H$17*H16,2) -> 51114.57 | J16: =H16-F16 -> 60326.58 | K16: -12448 | L16: -960 | N16: -16732.81 | O16: =SUM(K16:N16) -> -30140.81 | Q16: =J16+O16+P16 -> 30185.77 | S16: =ROUND($Q$17/$H$17*H16,2) -> 24363.65
A17: Вместе по объекту Ретал | E17: =SUM(E13:E16) -> 265899.08 | F17: =SUM(F13:F16) -> 159539.45 | H17: =SUM(H13:H16) -> 335251.79 | I17: =SUM(I13:I16) -> 159539.45 | J17: =SUM(J13:J16) -> 175712.34 | O17: =SUM(O13:O16) -> -99668.21 | P17: =SUM(P13:P16) -> 0 | Q17: =SUM(Q13:Q16) -> 76044.132 | R17: =J17+O17+P17 -> 76044.132 | S17: =SUM(S13:S16) -> 76044.14
A18: Ротор Пегасус | B18: Биогаз | C18: 592.98 | D18: =24*8 -> 192 | E18: =C18*D18 -> 113852.16 | F18: =E18*0.6 -> 68311.296 | G18: 138 | H18: =C18*G18 -> 81831.24 | I18: =ROUND($F$22/$H$22*H18,2) -> 44997.06 | J18: =H18-F18 -> 13519.944 | K18: -7902.27 | N18: -27620 | O18: =SUM(K18:N18) -> -35522.27 | Q18: =J18+O18+P18 -> -22002.326 | S18: =ROUND($Q$22/$H$22*H18,2) -> 7849.63
A19: Виброкаток | B19: Биогаз | C19: 544.05 | D19: =10*8 -> 80 | E19: =C19*D19 -> 43524 | F19: =E19*0.6 -> 26114.4 | H19: =C19*G19 -> 0 | I19: =ROUND($F$22/$H$22*H19,2) -> 0 | J19: =H19-F19 -> -26114.4 | O19: =SUM(K19:N19) -> 0 | Q19: =J19+O19+P19 -> -26114.4 | S19: =ROUND($Q$22/$H$22*H19,2) -> 0
A20: Экскаватор JCB | B20: Биогаз | C20: 496.93 | D20: =22*8 -> 176 | E20: =C20*D20 -> 87459.68 | F20: =E20*0.6 -> 52475.808 | G20: 283 | H20: =C20*G20 -> 140631.19 | I20: =ROUND($F$22/$H$22*H20,2) -> 77329.76 | J20: =H20-F20 -> 88155.382 | K20: -12053.6 | N20: -30563.86 | O20: =SUM(K20:N20) -> -42617.46 | Q20: =J20+O20+P20 -> 45537.922 | S20: =ROUND($Q$22/$H$22*H20,2) -> 13489.99
A21: Автокран XCMG | B21: Биогаз | C21: 563.19 | D21: =5*8 -> 40 | E21: =C21*D21 -> 22527.6 | F21: =E21*0.6 -> 13516.56 | G21: 123 | H21: =C21*G21 -> 69272.37 | I21: =ROUND($F$22/$H$22*H21,2) -> 38091.24 | J21: =H21-F21 -> 55755.81 | K21: -11590 | N21: -13602.47 | O21: =SUM(K21:N21) -> -25192.47 | Q21: =J21+O21+P21 -> 30563.34 | S21: =ROUND($Q$22/$H$22*H21,2) -> 6644.92
A22: Вресте по объекту Биогаз | E22: =SUM(E18:E21) -> 267363.44 | F22: =SUM(F18:F21) -> 160418.06 | H22: =H18+H20+H21 -> 291734.8 | I22: =SUM(I18:I21) -> 160418.06 | J22: =SUM(J18:J21) -> 131316.74 | O22: =O18+O20+O21 -> -103332.2 | P22: =P18+P20+P21 -> 0 | Q22: =SUM(Q18:Q21) -> 27984.536 | R22: =J22+O22+P22 -> 27984.536 | S22: =SUM(S18:S21) -> 27984.54
A23: Телекоп №4 | B23: ЦО Спецтехника | I23: =ROUND($F$26/$H$26*H23,2) -> 0 | M23: -1872 | O23: =SUM(K23:N23) -> -1872 | Q23: =J23+O23+P23 -> -1872 | S23: =Q23 -> -1872
A24: Главный офис | B24: ЦО Спецтехника | I24: =ROUND($F$26/$H$26*H24,2) -> 0 | N24: -87035.89 | O24: =SUM(K24:N24) -> -87035.89 | Q24: =J24+O24+P24 -> -87035.89 | S24: =Q24 -> -87035.89
E26: =E22+E17+E12+E9 -> 943437.64 | F26: =ROUND(F9+F12+F17+F22,0) -> 599456 | H26: =H9+H12+H17+H22 -> 841249.89 | I26: =I9+I12+I17+I22 -> 599456.29 | J26: =J9+J12+J17+J22 -> 241793.6 | O26: =O9+O12+O17+O22+O23+O24 -> -472585.86 | P26: =P9+P12+P17+P22 -> 79700 | Q26: =Q9+Q12+Q17+Q22+Q23+Q24 -> -151092.26 | S26: =S9+S12+S17+S22+S23+S24 -> -151092.25
J27: =H26-I26 -> 241793.6 | Q27: =H26-I26+O26+P26 -> -151092.26

Sheet Староконстантинов
A1: Техника | B1: Объект | C1: Стоимость за 1 час, грн | D1: План | F1: предоплата 60% | G1: Факт | I1: Сумма к взаиморасчетам, грн | J1: Оплаты с Индастриалбуд | O1: Поступление на Индастриал от сторонних заказчиков, грн | P1: Сумма к взаиморасчетам с учетом движения ДС на р/с Индастриалбуд, грн
D2: кол-во часов | E2: сумма, грн | G2: Кол-во Часов | H2: Сума | J2: ЗП механизаторов с налогами, грн. | K2: Разрешительная документация, грн. | L2: Страховка, грн | M2: Топливо, грн | N2: вместе оплаченно, грн
A3: Телескоп 1 | B3: Староконстантинов | C3: =467.63 -> 467.63 | D3: =18*8 -> 144 | E3: =C3*D3 -> 67338.72 | F3: =E3*0.6 -> 40403.232 | G3: 155 | H3: =C3*G3 -> 72482.65 | I3: =H3-F3 -> 32079.418 | J3: 8187.98 | M3: 44609.48 | N3: =SUM(J3:M3) -> 52797.46 | P3: =I3-N3+O3 -> -20718.042
A4: Экскаватор JCB 220 | B4: Староконстантинов | C4: 995.97 | D4: =15*8 -> 120 | E4: =C4*D4 -> 119516.4 | F4: =E4*0.6 -> 71709.84 | G4: 22 | H4: =C4*G4 -> 21911.34 | I4: =H4-F4 -> -49798.5 | J4: 12053.6 | M4: 70565.54 | N4: =SUM(J4:M4) -> 82619.14 | O4: =12000+12000+12000+12000+9000+12000 -> 69000 | P4: =I4-N4+O4 -> -63417.64
A5: Виброкаток | B5: Староконстантинов | C5: 544.05 | D5: =5*8 -> 40 | E5: =C5*D5 -> 21762 | F5: =E5*0.6 -> 13057.2 | H5: =C5*G5 -> 0 | I5: =H5-F5 -> -13057.2 | J5: 860.11 | N5: =SUM(J5:M5) -> 860.11 | O5: 8800 | P5: =I5-N5+O5 -> -5117.31
A6: МАЗ 264 | B6: Староконстантинов | C6: 355.37 | D6: =15*8 -> 120 | E6: =C6*D6 -> 42644.4 | F6: =E6*0.6 -> 25586.64 | H6: =C6*G6 -> 0 | I6: =H6-F6 -> -25586.64 | J6: 6224 | M6: 969 | N6: =SUM(J6:M6) -> 7193 | P6: =I6-N6+O6 -> -32779.64
A7: РДК 250 | B7: Староконстантинов | C7: 304.15 | D7: =21*8 -> 168 | E7: =C7*D7 -> 51097.2 | F7: =E7*0.6 -> 30658.32 | H7: =C7*G7 -> 0 | I7: =H7-F7 -> -30658.32 | N7: =SUM(J7:M7) -> 0 | P7: =I7-N7+O7 -> -30658.32
A8: КАМАЗ | B8: Староконстантинов | C8: 430.84 | D8: =15*8 -> 120 | E8: =C8*D8 -> 51700.8 | F8: =E8*0.6 -> 31020.48 | G8: 15 | H8: =C8*G8 -> 6462.6 | I8: =H8-F8 -> -24557.88 | J8: 6224 | N8: =SUM(J8:M8) -> 6224 | P8: =I8-N8+O8 -> -30781.88
A9: Вместе по объекту Староконстантинов | E9: =SUM(E3:E8) -> 354059.52 | F9: =SUM(F3:F8) -> 212435.71 | H9: =SUM(H3:H8) -> 100856.59 | I9: =SUM(I3:I8) -> -111579.12 | N9: =SUM(N3:N8) -> 149693.71 | O9: =SUM(O3:O8) -> 77800 | P9: =SUM(P3:P8) -> -183472.83

Sheet Приднепровский МЕТАЛЛ
A1: Техника | B1: Объект | C1: Стоимость за 1 час, грн | D1: План | F1: предоплата 60% | G1: Факт | I1: Сумма к взаиморасчетам, грн | J1: Оплаты с Индастриалбуд | O1: Поступление на Индастриал от сторонних заказчиков, грн | P1: Сумма к взаиморасчетам с учетом движения ДС на р/с Индастриалбуд, грн
D2: кол-во часов | E2: сумма, грн | G2: Кол-во Часов | H2: Сума | J2: ЗП механизаторов с налогами, грн. | K2: Разрешительная документация, грн. | L2: Страховка, грн | M2: Топливо, грн | N2: вместе оплаченно, грн
A3: Телескоп 2 | B3: Приднепровский МЕТАЛЛ | C3: 467.63 | D3: =15*8 -> 120 | E3: =C3*D3 -> 56115.6 | F3: =E3*0.6 -> 33669.36 | G3: 149 | H3: =C3*G3 -> 69676.87 | I3: =H3-F3 -> 36007.51 | J3: 7578 | M3: 13042.04 | N3: =SUM(J3:M3) -> 20620.04 | P3: =I3-N3+O3 -> 15387.47
A4: Экскаватор JCB 2013 | B4: Приднепровский МЕТАЛЛ | C4: 496.93 | D4: =14*8 -> 112 | E4: =C4*D4 -> 55656.16 | F4: =E4*0.6 -> 33393.696 | G4: 88 | H4: =C4*G4 -> 43729.84 | I4: =H4-F4 -> 10336.144 | J4: 4475.6 | M4: 5888.21 | N4: =SUM(J4:M4) -> 10363.81 | O4: 1900 | P4: =I4-N4+O4 -> 1872.334
A5: Вместе по объекту Приднепровский МЕТАЛЛ | E5: =E3 -> 56115.6 | F5: =SUM(F3:F4) -> 67063.056 | H5: =SUM(H3:H4) -> 113406.71 | I5: =SUM(I3:I4) -> 46343.654 | N5: =SUM(N3:N4) -> 30983.85 | O5: =SUM(O3:O4) -> 1900 | P5: =SUM(P3:P4) -> 17259.804

Sheet Ретал
A1: Техника | B1: Объект | C1: Стоимость за 1 час, грн | D1: План | F1: предоплата 60% | G1: Факт | I1: Сумма к взаиморасчетам, грн | J1: Оплаты с Индастриалбуд | O1: Поступление на Индастриал от сторонних заказчиков, грн | P1: Сумма к взаиморасчетам с учетом движения ДС на р/с Индастриалбуд, грн
D2: кол-во часов | E2: сумма, грн | G2: Кол-во Часов | H2: Сума | J2: ЗП механизаторов с налогами, грн. | K2: Разрешительная документация, грн. | L2: Страховка, грн | M2: Топливо, грн | N2: вместе оплаченно, грн
A3: Телескоп 5 | B3: Ретал | C3: 467.63 | D3: =22*8 -> 176 | E3: =C3*D3 -> 82302.88 | F3: =E3*0.6 -> 49381.728 | G3: 280 | H3: =C3*G3 -> 130936.4 | I3: =H3-F3 -> 81554.672 | J3: 12053.6 | M3: 33558.39 | N3: =SUM(J3:M3) -> 45611.99 | P3: =I3-N3+O3 -> 35942.682
A4: Экскаватор JCB 2008 | B4: Ретал | C4: 496.93 | D4: =22*8 -> 176 | E4: =C4*D4 -> 87459.68 | F4: =E4*0.6 -> 52475.808 | G4: 153 | H4: =C4*G4 -> 76030.29 | I4: =H4-F4 -> 23554.482 | J4: 11480.73 | L4: 1872 | M4: 10562.68 | N4: =SUM(J4:M4) -> 23915.41 | P4: =I4-N4+O4 -> -360.928
A5: Haulotte | B5: Ретал | C5: 802.86 | D5: 22 | E5: =C5*D5 -> 17662.92 | F5: =E5*0.6 -> 10597.752 | G5: 26 | H5: =C5*G5 -> 20874.36 | I5: =H5-F5 -> 10276.608 | N5: =SUM(J5:M5) -> 0 | P5: =I5-N5+O5 -> 10276.608
A6: Клинцы | B6: Ретал | C6: 490.46 | D6: =20*8 -> 160 | E6: =C6*D6 -> 78473.6 | F6: =E6*0.6 -> 47084.16 | G6: 219 | H6: =C6*G6 -> 107410.74 | I6: =H6-F6 -> 60326.58 | J6: 12448 | K6: 960 | M6: 16732.81 | N6: =SUM(J6:M6) -> 30140.81 | P6: =I6-N6+O6 -> 30185.77
A7: Вместе по объекту Ретал | E7: =SUM(E3:E6) -> 265899.08 | F7: =SUM(F3:F6) -> 159539.45 | H7: =SUM(H3:H6) -> 335251.79 | I7: =SUM(I3:I6) -> 175712.34 | N7: =SUM(N3:N6) -> 99668.21 | O7: =SUM(O3:O6) -> 0 | P7: =P3+P6+P5 -> 76405.06

Sheet Биогаз
A1: Техника | B1: Объект | C1: Стоимость за 1 час, грн | D1: План | F1: предоплата 60% | G1: Факт | I1: Сумма к взаиморасчетам, грн | J1: Оплаты с Индастриалбуд | O1: Поступление на Индастриал от сторонних заказчиков, грн | P1: Сумма к взаиморасчетам с учетом движения ДС на р/с Индастриалбуд, грн
D2: кол-во часов | E2: сумма, грн | G2: Кол-во Часов | H2: Сума | J2: ЗП механизаторов с налогами, грн. | K2: Разрешительная документация, грн. | L2: Страховка, грн | M2: Топливо, грн | N2: вместе оплаченно, грн
A3: Ротор Пегасус | B3: Биогаз | C3: 592.98 | D3: =24*8 -> 192 | E3: =C3*D3 -> 113852.16 | F3: =E3*0.6 -> 68311.296 | G3: 138 | H3: =C3*G3 -> 81831.24 | I3: =H3-F3 -> 13519.944 | J3: 7902.27 | M3: 27620 | N3: =SUM(J3:M3) -> 35522.27 | P3: =I3-N3+O3 -> -22002.326
A4: Виброкаток | B4: Биогаз | C4: 544.05 | D4: =10*8 -> 80 | E4: =C4*D4 -> 43524 | F4: =E4*0.6 -> 26114.4 | H4: =C4*G4 -> 0 | I4: =H4-F4 -> -26114.4 | N4: =SUM(J4:M4) -> 0 | P4: =I4-N4+O4 -> -26114.4
A5: Экскаватор JCB | B5: Биогаз | C5: 496.93 | D5: =22*8 -> 176 | E5: =C5*D5 -> 87459.68 | F5: =E5*0.6 -> 52475.808 | G5: 283 | H5: =C5*G5 -> 140631.19 | I5: =H5-F5 -> 88155.382 | J5: 12053.6 | M5: 30563.86 | N5: =SUM(J5:M5) -> 42617.46 | P5: =I5-N5+O5 -> 45537.922
A6: Автокран XCMG | B6: Биогаз | C6: 563.19 | D6: =5*8 -> 40 | E6: =C6*D6 -> 22527.6 | F6: =E6*0.6 -> 13516.56 | G6: 123 | H6: =C6*G6 -> 69272.37 | I6: =H6-F6 -> 55755.81 | J6: 11590 | M6: 13602.47 | N6: =SUM(J6:M6) -> 25192.47 | P6: =I6-N6+O6 -> 30563.34
A7: Вресте по объекту Биогаз | E7: =SUM(E3:E6) -> 267363.44 | F7: =SUM(F3:F6) -> 160418.06 | H7: =H3+H5+H6 -> 291734.8 | I7: =SUM(I3:I6) -> 131316.74 | N7: =N3+N5+N6 -> 103332.2 | O7: =O3+O5+O6 -> 0 | P7: =SUM(P3:P6) -> 27984.536

Sheet ЦО
A1: Техника | B1: Объект | C1: Стоимость за 1 час, грн | D1: План | F1: предоплата 60% | G1: Факт | I1: Сумма к взаиморасчетам, грн | J1: Оплаты с Индастриалбуд | O1: Поступление на Индастриал от сторонних заказчиков, грн | P1: Сумма к взаиморасчетам с учетом движения ДС на р/с Индастриалбуд, грн
D2: кол-во часов | E2: сумма, грн | G2: Кол-во Часов | H2: Сума | J2: ЗП механизаторов с налогами, грн. | K2: Разрешительная документация, грн. | L2: Страховка, грн | M2: Топливо, грн | N2: вместе оплаченно, грн
A3: Телекоп №4 | B3: ЦО Спецтехника | L3: 1872 | N3: =SUM(J3:M3) -> 1872 | P3: =I3-N3+O3 -> -1872
A4: Главный офис | B4: ЦО Спецтехника | M4: 87035.89 | N4: =SUM(J4:M4) -> 87035.89 | P4: =I4-N4+O4 -> -87035.89

Sheet Бюджет Декабрь
A1: Техника | B1: Объект | C1: Кол-во смен | D1: Предоплаты на 01/12/22 | E1: План сумма за месяц, грн | F1: Плановая предоплата 60%, грн | G1: Предоплаты на декабрь | H1: Распределение по CF, грн
A2: Телескоп 1 | B2: Староконстантинов | C2: 22 смены | D2: -20718.042 | E2: 93526 | F2: =E2*0.6 -> 56115.6 | G2: =D2+F2 -> 35397.558 | H2: =$G$10/($G$2+$G$5+$G$9)*G2 -> 1536.4611
A3: Виброкаток | B3: Староконстантинов | D3: -5117.31 | G3: =D3+F3 -> -5117.31
A4: РДК 250 | B4: Староконстантинов | D4: -30658.32 | G4: =D4+F4 -> -30658.32
A5: Телескоп 4 | B5: Староконстантинов | C5: 10 смен | E5: 37410.4 | F5: =E5*0.6 -> 22446.24 | G5: =D5+F5 -> 22446.24 | H5: =$G$10/($G$2+$G$5+$G$9)*G5 -> 974.29811
A6: Экскаватор JCB 220 | B6: Староконстантинов | C6: 5 смен | D6: -63417.64 | E6: 39838.8 | F6: =E6*0.6 -> 23903.28 | G6: =D6+F6 -> -39514.36
A7: МАЗ 264 | B7: Староконстантинов | C7: 5 смен | D7: -32779.64 | E7: =14215-0.2 -> 14214.8 | F7: =E7*0.6 -> 8528.88 | G7: =D7+F7 -> -24250.76
A8: Самосвал Камаз | B8: Староконстантинов | C8: 5 смен | D8: -30781.88 | E8: 17233.6 | F8: =E8*0.6 -> 10340.16 | G8: =D8+F8 -> -20441.72
A9: Автокран XCMG | B9: Староконстантинов | C9: 25 смен | E9: 112638 | F9: =E9*0.6 -> 67582.8 | G9: =D9+F9 -> 67582.8 | H9: =$G$10/($G$2+$G$5+$G$9)*G9 -> 2933.4888
A10: Вместе по объекту Староконстантинов | D10: =SUM(D2:D9) -> -183472.83 | E10: =SUM(E2:E9) -> 314861.6 | F10: =SUM(F2:F9) -> 188916.96 | G10: =SUM(G2:G9)+0.12 -> 5444.248 | H10: =SUM(H2:H9) -> 5444.248
A11: Телескоп 2 | B11: Приднепровский МЕТАЛЛ | C11: 20 смен | D11: 15387.47 | E11: 74820.8 | F11: =E11*0.6 -> 44892.48 | G11: =D11+F11 -> 60279.95 | H11: =G11 -> 60279.95
A12: Экскаватор JCB 2013 | B12: Приднепровский МЕТАЛЛ | D12: 1872.334 | G12: =D12+F12 -> 1872.334 | H12: =G12 -> 1872.334
A13: Вместе по объекту Приднепровский МЕТАЛЛ | D13: =SUM(D11:D12) -> 17259.804 | E13: =SUM(E11:E12) -> 74820.8 | F13: =SUM(F11:F12) -> 44892.48 | G13: =SUM(G11:G12) -> 62152.284 | H13: =H11 -> 60279.95
A14: Экскаватор JCB 2013 | B14: МЭЗ СЕТИ | C14: 25 смен | E14: 99386 | F14: =E14*0.6 -> 59631.6 | G14: =F14 -> 59631.6 | H14: =G14 -> 59631.6
A15: МАЗ 265 | B15: МЭЗ СЕТИ | C15: 15 смен | E15: 42644.4 | F15: =E15*0.6 -> 25586.64 | G15: =F15 -> 25586.64 | H15: =G15 -> 25586.64
A16: Вместе по объекту МЭЗ СЕТИ | E16: =SUM(E14:E15) -> 142030.4 | F16: =SUM(F14:F15) -> 85218.24 | G16: =SUM(G14:G15) -> 85218.24 | H16: =SUM(H14:H15) -> 85218.24
A17: Телескоп 5 | B17: Ретал | C17: 25 смен | D17: 35942.682 | E17: 93526 | F17: =E17*0.6 -> 56115.6 | G17: =D17+F17 -> 92058.282 | H17: =G17 -> 92058.282
A18: Экскаватор JCB 2008 | B18: Ретал | C18: 25 смен | D18: -360.928 | E18: 99386 | F18: =E18*0.6 -> 59631.6 | G18: =D18+F18 -> 59270.672 | H18: =G18 -> 59270.672
A19: Haulotte | B19: Ретал | C19: 25 часов | D19: 10276.608 | E19: 20071.5 | F19: =E19*0.6 -> 12042.9 | G19: =D19+F19 -> 22319.508 | H19: =G19 -> 22319.508
A20: Клинцы | B20: Ретал | C20: 25 смен | D20: 30185.77 | E20: 98092 | F20: =E20*0.6 -> 58855.2 | G20: =D20+F20 -> 89040.97 | H20: =G20 -> 89040.97
A21: Вместе по объекту Ретал | D21: =SUM(D17:D20) -> 76044.132 | E21: =SUM(E17:E20) -> 311075.5 | F21: =SUM(F17:F20) -> 186645.3 | G21: =SUM(G17:G20) -> 262689.43 | H21: =SUM(H17:H20) -> 262689.43
A22: Ротор Пегасус | B22: Биогаз | C22: 25 смен | D22: -22002.326 | E22: 118596 | F22: =E22*0.6 -> 71157.6 | G22: =D22+F22 -> 49155.274 | H22: =$G$26/($G$22+$G$23+$G$25)*G22 -> 42685.364
A23: Экскаватор JCB | B23: Биогаз | C23: 25 смен | D23: 45537.922 | E23: 99386 | F23: =E23*0.6 -> 59631.6 | G23: =D23+F23 -> 105169.52 | H23: =$G$26/($G$22+$G$23+$G$25)*G23 -> 91326.911
A24: Виброкаток | B24: Биогаз | D24: -26114.4 | G24: =D24+F24 -> -26114.4
A25: Автокран XCMG | B25: Биогаз | C25: 5 смен | D25: 30563.34 | E25: 22527.6 | F25: =E25*0.6 -> 13516.56 | G25: =D25+F25 -> 44079.9 | H25: =$G$26/($G$22+$G$23+$G$25)*G25 -> 38278.02
A26: Вресте по объекту Биогаз | D26: =SUM(D22:D25) -> 27984.536 | E26: =SUM(E22:E25) -> 240509.6 | F26: =SUM(F22:F25) -> 144305.76 | G26: =SUM(G22:G25) -> 172290.3 | H26: =SUM(H22:H25) -> 172290.3
E28: =E10+E13+E16+E21+E26 -> 1083297.9 | F28: =F10+F13+F16+F21+F26 -> 649978.74 | H28: =H26+H21+H16+H13+H10 -> 585922.17
E29: =E28-'Декабрь факт'!E31 -> 0

Sheet Декабрь факт
A1: Техника | B1: Объект | C1: Стоимость за 1 час, грн | D1: План | F1: предоплата 60% | H1: Распределение предоплаты по факту отработанного на объектах | I1: Факт | K1: Сумма к взаиморасчетам, грн | L1: Оплаты с Индастриалбуд | Q1: Поступление на Индастриал от сторонних заказчиков, грн | R1: Сумма к взаиморасчетам с учетом движения ДС на р/с Индастриалбуд, грн
D2: кол-во часов | E2: сумма, грн | I2: Кол-во Часов | J2: Сума | L2: ЗП механизаторов с налогами, грн. | M2: Разрешительная документация, грн. | N2: Страховка, грн | O2: Топливо, грн | P2: вместе оплаченно, грн
A3: Телескоп 1 | B3: Староконстантинов | C3: =467.63 -> 467.63 | D3: =22*9 -> 198 | E3: =C3*D3+935.26 -> 93526 | H3: =$G$10/$J$10*J3 -> 1646.2393 | I3: =111+107+37 -> 255 | J3: =I3*C3 -> 119245.65 | L3: 11590 | O3: =15338.51-110000/365153.35*15338.51 -> 10717.887 | P3: =SUM(L3:O3) -> 22307.887 | Q3: =6000+4400 -> 10400
A4: Телескоп 4 | B4: Староконстантинов | C4: 467.63 | D4: =10*8 -> 80 | E4: =C4*D4 -> 37410.4 | H4: =$G$10/$J$10*J4 -> 942.55269 | I4: =33+73+40 -> 146 | J4: =I4*C4 -> 68273.98 | L4: 12053.6 | N4: 1872 | O4: =14273.45-110000/365153.35*14273.45 -> 9973.6688 | P4: =SUM(L4:O4) -> 23899.269
A5: Экскаватор JCB 220 | B5: Староконстантинов | C5: 995.97 | D5: =5*8 -> 40 | E5: =C5*D5 -> 39838.8 | H5: =$G$10/$J$10*J5 -> 1182.4836 | I5: =67+19 -> 86 | J5: =I5*C5 -> 85653.42 | L5: 9530.21 | O5: =5775-110000/365153.35*5775 -> 4035.3199 | P5: =SUM(L5:O5) -> 13565.53
A6: Автокран XCMG | B6: Староконстантинов | C6: 563.19 | D6: =25*8 -> 200 | E6: =C6*D6 -> 112638 | H6: =$G$10/$J$10*J6 -> 1352.8654 | I6: 174 | J6: =I6*C6 -> 97995.06 | L6: =11590/(I6+I23)*I6 -> 9934.2857 | O6: =(68415.84+8597.98)/(I6+I23)*I6-110000/365153.35*(68415.84+8597.98)/(I6+I23)*I6 -> 46126.22 | P6: =SUM(L6:O6) -> 56060.505
A7: МАЗ 264 | B7: Староконстантинов | C7: 355.37 | D7: =5*8 -> 40 | E7: =C7*D7 -> 14214.8 | H7: =$G$10/$J$10*J7 -> 260.02018 | I7: =36+17 -> 53 | J7: =I7*C7 -> 18834.61 | L7: 7087.64 | O7: =9980.32-110000/365153.35*9980.32 -> 6973.8155 | P7: =SUM(L7:O7) -> 14061.455
A8: Самосвал Камаз | B8: Староконстантинов | C8: 430.84 | D8: =5*8 -> 40 | E8: =C8*D8 -> 17233.6 | H8: =$G$10/$J$10*J8 -> 0 | J8: =I8*C8 -> 0 | P8: =SUM(L8:O8) -> 0
A9: Виброкаток | B9: Староконстантинов | C9: 544.05 | E9: =C9*D9 -> 0 | H9: =$G$10/$J$10*J9 -> 60.08682 | I9: 8 | J9: =I9*C9 -> 4352.4 | L9: =879.72/(I9+I20)*I9 -> 190.20973 | O9: =10971.23/(I9+I20)*I9-110000/365153.35*10971.23/(I9+I20)*I9 -> 1657.5612 | P9: =SUM(L9:O9) -> 1847.7709 | Q9: 26400
A10: Вместе по объекту Староконстантинов | E10: =SUM(E3:E9) -> 314861.6 | F10: ='Бюджет Декабрь'!F10 -> 188916.96 | G10: ='Бюджет Декабрь'!H10 -> 5444.248 | H10: =SUM(H3:H9) -> 5444.248 | J10: =SUM(J3:J9) -> 394355.12 | K10: =J10-F10 -> 205438.16 | P10: =SUM(P3:P9) -> 131742.42 | Q10: =SUM(Q3:Q9) -> 36800 | R10: =K10-P10+Q10 -> 110495.74 | S10: =J10-F10-P10+Q10 -> 110495.74
A11: Телескоп 2 | B11: Приднепровский МЕТАЛЛ | C11: 467.63 | D11: =20*8 -> 160 | E11: =C11*D11 -> 74820.8 | H11: =$G$13/$J$13*J11 -> 3955.4823 | I11: 5 | J11: =C11*I11 -> 2338.15 | L11: =6026.8/(I11+I27)*I11 -> 456.57576 | O11: =11183.64/(I11+I27)*I11-110000/365153.35*11183.64/(I11+I27)*I11 -> 592.01844 | P11: =SUM(L11:O11) -> 1048.5942
A12: Экскаватор JCB 2013 | B12: Приднепровский МЕТАЛЛ | C12: 496.93 | E12: =C12*D12 -> 0 | H12: =$G$13/$J$13*J12 -> 56324.468 | I12: 67 | J12: =C12*I12 -> 33294.31 | L12: =(2173.6+1926.6+7953.4)/(I12+I25)*I12 -> 3827.4464 | O12: =(24736.16+6668.32)/(I12+I25)*I12-110000/365153.35*(24736.16+6668.32)/(I12+I25)*I12 -> 6968.0288 | P12: =SUM(L12:O12) -> 10795.475
A13: Вместе по объекту Приднепровский МЕТАЛЛ | E13: =SUM(E11:E12) -> 74820.8 | F13: ='Бюджет Декабрь'!F13 -> 44892.48 | G13: ='Бюджет Декабрь'!H13 -> 60279.95 | H13: =SUM(H11:H12) -> 60279.95 | J13: =SUM(J11:J12) -> 35632.46 | K13: =J13-F13 -> -9260.02 | P13: =SUM(P11:P12) -> 11844.069 | Q13: =SUM(Q11:Q12) -> 0 | R13: =K13-P13+Q13 -> -21104.089 | S13: =J13-F13-P13 -> -21104.089
A14: Телескоп 5 | B14: Ретал | C14: 467.63 | D14: =25*8 -> 200 | E14: =C14*D14 -> 93526 | H14: =$G$18/$J$18*J14 -> 92637.667 | I14: 232 | J14: =C14*I14 -> 108490.16 | L14: 12053.6 | O14: =28600.01-110000/365153.35*28600.01 -> 19984.449 | P14: =SUM(L14:O14) -> 32038.049 | V14: ='Бюджет Декабрь'!F17 -> 56115.6 | W14: =J14 -> 108490.16 | X14: =W14-V14 -> 52374.56 | Y14: =P14 -> 32038.049 | Z14: =X14-Y14 -> 20336.511
A15: Экскаватор JCB 2008 | B15: Ретал | C15: 496.93 | D15: =25*8 -> 200 | E15: =C15*D15 -> 99386 | H15: =$G$18/$J$18*J15 -> 83166.523 | I15: 196 | J15: =C15*I15 -> 97398.28 | L15: 17917.08 | O15: =(16439.54+16101.36)-110000/365153.35*(16439.54+16101.36) -> 22738.172 | P15: =SUM(L15:O15) -> 40655.252 | V15: ='Бюджет Декабрь'!F18 -> 59631.6 | W15: =J15 -> 97398.28 | X15: =W15-V15 -> 37766.68 | Y15: =P15 -> 40655.252 | Z15: =X15-Y15 -> -2888.5719
A16: Haulotte | B16: Ретал | C16: 802.86 | D16: 25 | E16: =C16*D16 -> 20071.5 | H16: =$G$18/$J$18*J16 -> 12339.842 | I16: 18 | J16: =C16*I16 -> 14451.48 | M16: 13060.28 | P16: =SUM(L16:O16) -> 13060.28 | V16: ='Бюджет Декабрь'!F19 -> 12042.9 | W16: =J16 -> 14451.48 | X16: =W16-V16 -> 2408.58 | Y16: =P16 -> 13060.28 | Z16: =X16-Y16 -> -10651.7
A17: Клинцы | B17: Ретал | C17: 490.46 | D17: =25*8 -> 200 | E17: =C17*D17 -> 98092 | H17: =$G$18/$J$18*J17 -> 74545.401 | I17: 178 | J17: =C17*I17 -> 87301.88 | L17: 11590 | O17: =19097.36-110000/365153.35*19097.36 -> 13344.408 | P17: =SUM(L17:O17) -> 24934.408 | V17: ='Бюджет Декабрь'!F20 -> 58855.2 | W17: =J17 -> 87301.88 | X17: =W17-V17 -> 28446.68 | Y17: =P17 -> 24934.408 | Z17: =X17-Y17 -> 3512.2717
A18: Вместе по объекту Ретал | E18: =SUM(E14:E17) -> 311075.5 | F18: ='Бюджет Декабрь'!F21 -> 186645.3 | G18: ='Бюджет Декабрь'!H21 -> 262689.43 | H18: =SUM(H14:H17) -> 262689.43 | J18: =SUM(J14:J17) -> 307641.8 | K18: =J18-F18 -> 120996.5 | P18: =SUM(P14:P17) -> 110687.99 | Q18: =SUM(Q14:Q17) -> 0 | R18: =K18-P18+Q18 -> 10308.511 | S18: =J18-F18-P18 -> 10308.511 | V18: =SUM(V14:V17) -> 186645.3 | W18: =SUM(W14:W17) -> 307641.8 | X18: =SUM(X14:X17) -> 120996.5 | Y18: =SUM(Y14:Y17) -> 110687.99 | Z18: =SUM(Z14:Z17) -> 10308.511
A19: Ротор Пегасус | B19: Биогаз | C19: 592.98 | D19: =25*8 -> 200 | E19: =C19*D19 -> 118596 | H19: =$G$24/$J$24*J19 -> 67151.197 | I19: 225 | J19: =C19*I19 -> 133420.5 | L19: 11590 | O19: =39760.03-110000/365153.35*39760.03 -> 27782.587 | P19: =SUM(L19:O19) -> 39372.587
A20: Виброкаток | B20: Биогаз | C20: 544.05 | E20: =C20*D20 -> 0 | H20: =$G$24/$J$24*J20 -> 7940.8686 | I20: 29 | J20: =C20*I20 -> 15777.45 | L20: =879.72/(I20+I9)*I20 -> 689.51027 | O20: =10971.23/(I20+I9)*I20-110000/365153.35*10971.23/(I20+I9)*I20 -> 6008.6593 | P20: =SUM(L20:O20) -> 6698.1696
A21: Самосвал Камаз | B21: Биогаз | C21: 430.84 | E21: =C21*D21 -> 0 | H21: =$G$24/$J$24*J21 -> 16696.98 | I21: 77 | J21: =C21*I21 -> 33174.68 | L21: 8955.91 | O21: =(17084.48+6420)-110000/365153.35*(17084.48+6420) -> 16423.913 | P21: =SUM(L21:O21) -> 25379.823
A22: Экскаватор JCB | B22: Биогаз | C22: 496.93 | D22: =25*8 -> 200 | E22: =C22*D22 -> 99386 | H22: =$G$24/$J$24*J22 -> 72281.017 | I22: 289 | J22: =C22*I22 -> 143612.77 | L22: =12053.6 -> 12053.6 | O22: =45710.12-110000/365153.35*45710.12 -> 31940.253 | P22: =SUM(L22:O22) -> 43993.853
A23: Автокран XCMG | B23: Биогаз | C23: 563.19 | D23: =5*8 -> 40 | E23: =C23*D23 -> 22527.6 | H23: =$G$24/$J$24*J23 -> 8220.233 | I23: 29 | J23: =C23*I23 -> 16332.51 | L23: =11590/(I6+I23)*I23 -> 1655.7143 | O23: =(68415.84+8597.98)/(I6+I23)*I23-110000/365153.35*(68415.84+8597.98)/(I6+I23)*I23 -> 7687.7033 | P23: =SUM(L23:O23) -> 9343.4175
A24: Вресте по объекту Биогаз | E24: =SUM(E19:E23) -> 240509.6 | F24: ='Бюджет Декабрь'!F26 -> 144305.76 | G24: ='Бюджет Декабрь'!H26 -> 172290.3 | H24: =SUM(H19:H23) -> 172290.3 | J24: =SUM(J19:J23) -> 342317.91 | K24: =J24-F24 -> 198012.15 | P24: =SUM(P19:P23) -> 124787.85 | Q24: =SUM(Q19:Q23) -> 0 | R24: =K24-P24+Q24 -> 73224.3 | S24: =J24-F24-P24 -> 73224.3
A25: Экскаватор JCB 2013 | B25: МЕЗ Сети | C25: 496.93 | D25: =25*8 -> 200 | E25: =C25*D25 -> 99386 | H25: =$G$28/$J$28*J25 -> 60929.615 | I25: 144 | J25: =C25*I25 -> 71557.92 | L25: =12053.6/(I12+I25)*I25 -> 8226.1536 | O25: =45710.12/(I12+I25)*I25-110000/365153.35*45710.12/(I12+I25)*I25 -> 21798.087 | P25: =SUM(L25:O25) -> 30024.241
A26: МАЗ 264 | B26: МЕЗ Сети | C26: 355.37 | D26: =15*8 -> 120 | E26: =C26*D26 -> 42644.4 | H26: =$G$28/$J$28*J26 -> 0 | J26: =C26*I26 -> 0 | P26: =SUM(L26:O26) -> 0
A27: Телескоп 2 | B27: МЕЗ Сети | C27: 467.63 | E27: =C27*D27 -> 0 | H27: =$G$28/$J$28*J27 -> 24288.625 | I27: 61 | J27: =C27*I27 -> 28525.43 | L27: =11590/(I6+I23+I27)*I27 -> 2677.9924 | O27: =(68415.84+8597.98)/(I6+I23+I27)*I27-110000/365153.35*(68415.84+8597.98)/(I6+I23+I27)*I27 -> 12434.278 | P27: =SUM(L27:O27) -> 15112.27
A28: Вресте по объекту МЕЗ СЕТИ | E28: =SUM(E25:E27) -> 142030.4 | F28: ='Бюджет Декабрь'!F16 -> 85218.24 | G28: ='Бюджет Декабрь'!H16 -> 85218.24 | H28: =SUM(H25:H27) -> 85218.24 | J28: =SUM(J25:J27) -> 100083.35 | K28: =J28-F28 -> 14865.11 | P28: =SUM(P25:P27) -> 45136.511 | Q28: =SUM(Q25:Q27) -> 0 | R28: =K28-P28+Q28 -> -30271.401 | S28: =J28-F28-P28 -> -30271.401
A29: Главный офис | B29: ЦО Спецтехника | O29: =87035.89+334746.5-(O27+O25+O23+O22+O21+O20+O19+O17+O15+O14+O12+O11+O9+O7+O6+O5+O4+O3)-110000 -> 44595.362 | P29: =SUM(L29:O29) -> 44595.362
E31: =E24+E18+E13+E10+E28 -> 1083297.9 | F31: =F10+F13+F18+F24+F28 -> 649978.74 | G31: =G10+G13+G18+G24+G28 -> 585922.17 | H31: =H10+H13+H18+H24+H28 -> 585922.17 | J31: =J10+J13+J18+J24+J28 -> 1180030.6 | K31: =K10+K13+K18+K24+K28 -> 530051.9 | P31: =P10+P13+P18+P24+P28 -> 424198.84 | Q31: =Q10+Q13+Q18+Q24+Q28 -> 36800 | R31: =R10+R13+R18+R24+R28 -> 142653.06 | S31: =S28+S24+S18+S13+S10 -> 142653.06
H32: =F10+Ноябрь!S9+'Декабрь факт'!F13+Ноябрь!S12+'Декабрь факт'!F18+Ноябрь!S17+'Декабрь факт'!F24+Ноябрь!S22+'Декабрь факт'!F28+Ноябрь!S23 -> 585922.38 | S32: =J31-F31-P31+Q31 -> 142653.06
R33: =J31-F31-P31+Q31 -> 142653.06

Sheet Лист1
C1: ВСЕГО
B2: Телескоп 1 | C2: =SUM(E2:H2) -> 15338.51 | E2: 4392 | F2: 5456.51 | G2: 1098 | H2: 4392
B3: Телескоп 4 | C3: =SUM(E3:I3) -> 14273.45 | E3: 2195.45 | F3: 4392 | H3: 4392 | I3: 3294
B4: Экскаватор JCB 220 | C4: =SUM(E4:Z4) -> 5775 | E4: 5775
B5: Автокран XCMG | C5: =SUM(E5:Z5) -> 77013.82 | E5: 2196 | F5: 549 | G5: 2745 | I5: 1098 | J5: 4392 | K5: 4392 | L5: 1479.56 | M5: 5490 | N5: 5465.84 | O5: 5132.6 | P5: 583.59 | Q5: 5459.26 | R5: 4937.16 | S5: 5280.83 | T5: 4117.5 | U5: 2581.4 | V5: 1536.1 | W5: 2196 | X5: 4392 | Y5: 4392 | Z5: 8597.98
B6: МАЗ 264 | C6: =SUM(E6:Z6) -> 9980.32 | E6: 4760 | F6: 5220.32
B7: Виброкаток | C7: =SUM(E7:Z7) -> 10971.23 | E7: 3164.99 | F7: 952.52 | G7: 1098 | H7: 3761.2 | I7: 622.02 | J7: 1372.5
B8: Вместе по объекту Староконстантинов
B9: Телескоп 2 | C9: =SUM(E9:Z9) -> 11183.64 | E9: 11183.64
B10: Экскаватор JCB 2013 | C10: =SUM(E10:Z10) -> 31404.48 | E10: 6073.27 | F10: 4240 | G10: 5942.89 | H10: 4240 | I10: 4240 | J10: 6668.32
B11: Вместе по объекту Приднепровский МЕТАЛЛ
B12: Телескоп 5 | C12: =SUM(E12:Z12) -> 28600.01 | E12: 28600.01
B13: Экскаватор JCB 2008 | C13: =SUM(E13:Z13) -> 32540.9 | E13: 5839.54 | F13: 4240 | G13: 6360 | H13: 16101.36
B14: Haulotte | C14: =SUM(E14:Z14) -> 0
B15: Клинцы | C15: =SUM(E15:Z15) -> 19097.36 | E15: 19097.36
B16: Вместе по объекту Ретал
B17: Ротор Пегасус | C17: =SUM(E17:Z17) -> 39760.03 | E17: 39760.03
B18: Виброкаток | C18: =SUM(E18:Z18) -> 0
B19: Камаз | C19: =SUM(E19:Z19) -> 23504.48 | E19: 8542.24 | F19: 8542.24 | G19: 6420
B20: Экскаватор JCB | C20: =SUM(E20:Z20) -> 45710.12 | E20: 45710.12
B21: Автокран XCMG | C21: =SUM(E21:Z21) -> 0
B22: Вресте по объекту Биогаз
B23: Экскаватор JCB | C23: =SUM(E23:Z23) -> 0
B24: Автокран XCMG | C24: =SUM(E24:Z24) -> 0
B25: Вресте по объекту МЕЗ СЕТИ
B26: Главный офис

Sheet Бюджет Январь 23
A1: Техника | B1: Объект | C1: Кол-во смен | D1: сумма за месяц, грн | E1: предоплата 60%, грн | F1: Сумма к взаиморасчетам по декабрю, грн | G1: Итого, сумма предоплаты за январь, грн. | H1: ЯНВАРЬ ФАКТ | I1: предоплата декабрь | J1: Факт декабрь | K1: факт-пред | L1: Оплаты с индастриал | M1: ЛЕВАК | N1: Сумма к взаиморасчетам | O1: предоплата январь | P1: Итого предоплат за январь | Q1: 0.8 | R1: Цифра для распределения в казне
A2: Телескоп 1 | B2: Староконстантинов | C2: 15 смен | D2: 56115.6 | E2: =D2*0.6 -> 33669.36 | H2: 71079.76 | I2: =VLOOKUP(A2,'Бюджет Декабрь'!$A$2:$F$9,6,0) -> 56115.6 | J2: =VLOOKUP(A2,'Декабрь факт'!$A$3:$J$9,8,0) -> 1646.2393 | K2: =J2-I2 -> -54469.361 | L2: =VLOOKUP(A2,'Декабрь факт'!$A$3:$P$9,14,0) -> 0 | M2: =6000+4400 -> 10400 | N2: =K2-L2+M2 -> -44069.361 | O2: =E2 -> 33669.36 | P2: =N2+O2 -> -10400.001 | Q2: =P2*0.8 -> -8320.0006 | R2: =$Q$10/($Q$2+$Q$3+$Q$4+$Q$5+$Q$6+$Q$7)*Q2 -> -6596.7291
A3: Телескоп 4 | B3: Староконстантинов | C3: 15 смен | D3: 56115.6 | E3: =D3*0.6 -> 33669.36 | H3: 75288.43 | I3: =VLOOKUP(A3,'Бюджет Декабрь'!$A$2:$F$9,6,0) -> 22446.24 | J3: =VLOOKUP(A3,'Декабрь факт'!$A$3:$J$9,8,0) -> 942.55269 | K3: =J3-I3 -> -21503.687 | L3: =VLOOKUP(A3,'Декабрь факт'!$A$3:$P$9,14,0) -> 1872 | N3: =K3-L3+M3 -> -23375.687 | O3: =E3 -> 33669.36 | P3: =N3+O3 -> 10293.673 | Q3: =P3*0.8 -> 8234.9382 | R3: =$Q$10/($Q$2+$Q$3+$Q$4+$Q$5+$Q$6+$Q$7)*Q3 -> 6529.2851
A4: Экскаватор JCB 220 | B4: Староконстантинов | C4: 15 смен | D4: 119516.4 | E4: =D4*0.6 -> 71709.84 | H4: 0 | I4: =VLOOKUP(A4,'Бюджет Декабрь'!$A$2:$F$9,6,0) -> 23903.28 | J4: =VLOOKUP(A4,'Декабрь факт'!$A$3:$J$9,8,0) -> 1182.4836 | K4: =J4-I4 -> -22720.796 | L4: =VLOOKUP(A4,'Декабрь факт'!$A$3:$P$9,14,0) -> 0 | N4: =K4-L4+M4 -> -22720.796 | O4: =E4 -> 71709.84 | P4: =N4+O4 -> 48989.044 | Q4: =P4*0.8 -> 39191.235 | R4: =$Q$10/($Q$2+$Q$3+$Q$4+$Q$5+$Q$6+$Q$7)*Q4 -> 31073.791 | S4: =R4-51771.17 -> -20697.379
A5: МАЗ 264 | B5: Староконстантинов | C5: 5 смен | D5: 14214.8 | E5: =D5*0.6 -> 8528.88 | H5: 0 | I5: =VLOOKUP(A5,'Бюджет Декабрь'!$A$2:$F$9,6,0) -> 8528.88 | J5: =VLOOKUP(A5,'Декабрь факт'!$A$3:$J$9,8,0) -> 260.02018 | K5: =J5-I5 -> -8268.8598 | L5: =VLOOKUP(A5,'Декабрь факт'!$A$3:$P$9,14,0) -> 0 | N5: =K5-L5+M5 -> -8268.8598 | O5: =E5 -> 8528.88 | P5: =N5+O5 -> 260.02018 | Q5: =P5*0.8 -> 208.01614 | R5: =$Q$10/($Q$2+$Q$3+$Q$4+$Q$5+$Q$6+$Q$7)*Q5 -> 164.93101
A6: Автокран XCMG | B6: Староконстантинов | C6: 15 смен | D6: 67582.8 | E6: =D6*0.6 -> 40549.68 | H6: 86731.26 | I6: =VLOOKUP(A6,'Бюджет Декабрь'!$A$2:$F$9,6,0) -> 67582.8 | J6: =VLOOKUP(A6,'Декабрь факт'!$A$3:$J$9,8,0) -> 1352.8654 | K6: =J6-I6 -> -66229.935 | L6: =VLOOKUP(A6,'Декабрь факт'!$A$3:$P$9,14,0) -> 0 | N6: =K6-L6+M6 -> -66229.935 | O6: =E6 -> 40549.68 | P6: =N6+O6 -> -25680.255 | Q6: =P6*0.8 -> -20544.204 | R6: =$Q$10/($Q$2+$Q$3+$Q$4+$Q$5+$Q$6+$Q$7)*Q6 -> -16289.007
A7: Виброкаток | B7: Староконстантинов | J7: =VLOOKUP(A7,'Декабрь факт'!$A$3:$J$9,8,0) -> 60.08682 | K7: =J7-I7 -> 60.08682 | L7: =VLOOKUP(A7,'Декабрь факт'!$A$3:$P$9,14,0) -> 0 | M7: 26400 | N7: =K7-L7+M7 -> 26460.087 | O7: =E7 -> 0 | P7: =N7+O7 -> 26460.087 | Q7: =P7*0.8 -> 21168.069 | R7: =$Q$10/($Q$2+$Q$3+$Q$4+$Q$5+$Q$6+$Q$7)*Q7 -> 16783.655
A8: Самосвал Камаз | B8: Староконстантинов | I8: =VLOOKUP(A8,'Бюджет Декабрь'!$A$2:$F$9,6,0) -> 10340.16 | K8: =J8-I8 -> -10340.16 | N8: =K8-L8+M8 -> -10340.16 | P8: =N8+O8 -> -10340.16 | Q8: =P8*0.8 -> -8272.128
A9: Клинцы | B9: Староконстантинов | H9: 16675.64
A10: Вместе по объекту Староконстантинов | D10: =SUM(D2:D6) -> 313545.2 | E10: =SUM(E2:E6) -> 188127.12 | F10: ='Декабрь факт'!R10 -> 110495.74 | G10: =E10+F10 -> 298622.86 | H10: =SUM(H2:H9) -> 249775.09 | I10: =SUM(I2:I9) -> 188916.96 | J10: =SUM(J2:J9) -> 5444.248 | K10: =SUM(K2:K9) -> -183472.71 | L10: =SUM(L2:L9) -> 1872 | N10: =SUM(N2:N9) -> -148544.71 | O10: =SUM(O2:O9) -> 188127.12 | P10: =SUM(P2:P9) -> 39582.408 | Q10: =SUM(Q2:Q9) -> 31665.926 | R10: =SUM(R2:R9) -> 31665.926
A12: Вместе по объекту Приднепровский МЕТАЛЛ | D12: =D11 -> 0 | E12: =E11 -> 0 | F12: ='Декабрь факт'!R13 -> -21104.089 | G12: =E12+F12 -> -21104.089
A13: Экскаватор JCB 2013 | B13: МЭЗ СЕТИ | C13: 20 смен | D13: 79508.8 | E13: =D13*0.6 -> 47705.28 | H13: 110815.39 | I13: =VLOOKUP(A13,'Бюджет Декабрь'!$A$14:$F$15,6,0) -> 59631.6 | J13: =VLOOKUP(A13,'Декабрь факт'!$A$25:$J$27,8,0) -> 60929.615 | K13: =J13-I13 -> 1298.0152 | L13: =VLOOKUP(A13,'Декабрь факт'!$A$25:$P$27,14,0) -> 0 | N13: =K13-L13 -> 1298.0152 | O13: =E13 -> 47705.28 | P13: =N13+O13 -> 49003.295 | Q13: =P13*0.8 -> 39202.636 | R13: =$S$16/($Q$13+$Q$15)*Q13 -> 20673.993
A14: МАЗ 265 | H14: 28784.97 | I14: =VLOOKUP(A14,'Бюджет Декабрь'!$A$14:$F$15,6,0) -> 25586.64 | K14: =J14-I14 -> -25586.64 | N14: =K14-L14 -> -25586.64 | O14: =E14 -> 0 | P14: =N14+O14 -> -25586.64 | Q14: =P14*0.8 -> -20469.312
A15: Телескоп 2 | B15: МЭЗ СЕТИ | C15: 20 смен | D15: 74820.8 | E15: =D15*0.6 -> 44892.48 | H15: 43021.96 | J15: =VLOOKUP(A15,'Декабрь факт'!$A$25:$J$27,8,0) -> 24288.625 | K15: =J15-I15 -> 24288.625 | L15: =VLOOKUP(A15,'Декабрь факт'!$A$25:$P$27,14,0) -> 0 | N15: =K15-L15 -> 24288.625 | O15: =E15 -> 44892.48 | P15: =N15+O15 -> 69181.105 | Q15: =P15*0.8 -> 55344.884 | R15: =$S$16/($Q$13+$Q$15)*Q15 -> 29186.807
A16: Вместе по объекту МЭЗ СЕТИ | D16: =SUM(D13:D15) -> 154329.6 | E16: =SUM(E13:E15) -> 92597.76 | F16: ='Декабрь факт'!R28 -> -30271.401 | G16: =E16+F16 -> 62326.359 | H16: =SUM(H13:H15) -> 182622.32 | I16: =SUM(I13:I15) -> 85218.24 | J16: =SUM(J13:J15) -> 85218.24 | K16: =SUM(K13:K15) -> 0 | L16: =SUM(L13:L15) -> 0 | N16: =SUM(N13:N15) -> 0 | O16: =SUM(O13:O15) -> 92597.76 | P16: =SUM(P13:P15) -> 92597.76 | Q16: =SUM(Q13:Q15) -> 74078.208 | R16: =SUM(R13:R15) -> 49860.8 | S16: 49860.8
A17: Телескоп 5 | B17: Ретал | C17: 20 смен | D17: 74820.8 | E17: =D17*0.6 -> 44892.48 | H17: 77626.58 | I17: ='Бюджет Декабрь'!F17 -> 56115.6 | J17: ='Декабрь факт'!J14 -> 108490.16 | K17: =J17-I17 -> 52374.56 | L17: ='Декабрь факт'!P14 -> 32038.049 | N17: =K17-L17 -> 20336.511 | O17: =E17 -> 44892.48 | P17: =N17+O17 -> 65228.991 | Q17: =P17*0.8 -> 52183.193 | R17: =$Q$21/($Q$17+$Q$18+$Q$20)*Q17 -> 51808.157
A18: Экскаватор JCB 2008 | B18: Ретал | C18: 12 смен | D18: 47705.28 | E18: =D18*0.6 -> 28623.168 | H18: 73545.64 | I18: ='Бюджет Декабрь'!F18 -> 59631.6 | J18: ='Декабрь факт'!J15 -> 97398.28 | K18: =J18-I18 -> 37766.68 | L18: ='Декабрь факт'!P15 -> 40655.252 | N18: =K18-L18 -> -2888.5719 | O18: =E18 -> 28623.168 | P18: =N18+O18 -> 25734.596 | Q18: =P18*0.8 -> 20587.677 | R18: =$Q$21/($Q$17+$Q$18+$Q$20)*Q18 -> 20439.715
A19: Haulotte | B19: Ретал | C19: 20 смен | D19: 16057.2 | E19: =D19*0.6 -> 9634.32 | H19: 16057.2 | I19: ='Бюджет Декабрь'!F19 -> 12042.9 | J19: ='Декабрь факт'!J16 -> 14451.48 | K19: =J19-I19 -> 2408.58 | L19: ='Декабрь факт'!P16 -> 13060.28 | N19: =K19-L19 -> -10651.7 | O19: =E19 -> 9634.32 | P19: =N19+O19 -> -1017.38 | Q19: =P19*0.8 -> -813.904
A20: Клинцы | B20: Ретал | C20: 20 смен | D20: 78473.6 | E20: =D20*0.6 -> 47084.16 | H20: 48555.54 | I20: ='Бюджет Декабрь'!F20 -> 58855.2 | J20: ='Декабрь факт'!J17 -> 87301.88 | K20: =J20-I20 -> 28446.68 | L20: ='Декабрь факт'!P17 -> 24934.408 | N20: =K20-L20 -> 3512.2717 | O20: =E20 -> 47084.16 | P20: =N20+O20 -> 50596.432 | Q20: =P20*0.8 -> 40477.145 | R20: =$Q$21/($Q$17+$Q$18+$Q$20)*Q20 -> 40186.24
A21: Вместе по объекту Ретал | D21: =SUM(D17:D20) -> 217056.88 | E21: =SUM(E17:E20) -> 130234.13 | F21: ='Декабрь факт'!R18 -> 10308.511 | G21: =E21+F21 -> 140542.64 | H21: =SUM(H17:H20) -> 215784.96 | I21: =SUM(I17:I20) -> 186645.3 | J21: =SUM(J17:J20) -> 307641.8 | K21: =SUM(K17:K20) -> 120996.5 | L21: =SUM(L17:L20) -> 110687.99 | N21: =SUM(N17:N20) -> 10308.511 | O21: =SUM(O17:O20) -> 130234.13 | P21: =SUM(P17:P20) -> 140542.64 | Q21: =G21*0.8 -> 112434.11 | R21: =SUM(R17:R20) -> 112434.11
A22: Ротор Пегасус | B22: Биогаз | C22: 20 смен | D22: 94876.8 | E22: =D22*0.6 -> 56926.08 | H22: 49217.34 | I22: =VLOOKUP(A22,'Бюджет Декабрь'!$A$22:$F$25,6,0) -> 71157.6 | J22: =VLOOKUP(A22,'Декабрь факт'!$A$19:$J$23,8,0) -> 67151.197 | K22: =J22-I22 -> -4006.4029 | L22: =VLOOKUP(A22,'Декабрь факт'!$A$19:$P$23,14,0) -> 0 | N22: =K22-L22 -> -4006.4029 | O22: =E22 -> 56926.08 | P22: =N22+O22 -> 52919.677 | Q22: =P22*0.8+4017.43204722502 -> 46353.174 | R22: =$Q$27/($Q$22+$Q$23+$Q$24+$Q$25)*Q22 -> 46353.174
A23: Экскаватор JCB | B23: Биогаз | C23: 25 смен | D23: 79508.8 | E23: =D23*0.6 -> 47705.28 | H23: 134668.03 | I23: =VLOOKUP(A23,'Бюджет Декабрь'!$A$22:$F$25,6,0) -> 59631.6 | J23: =VLOOKUP(A23,'Декабрь факт'!$A$19:$J$23,8,0) -> 72281.017 | K23: =J23-I23 -> 12649.417 | L23: =VLOOKUP(A23,'Декабрь факт'!$A$19:$P$23,14,0) -> 0 | N23: =K23-L23 -> 12649.417 | O23: =E23 -> 47705.28 | P23: =N23+O23 -> 60354.697 | Q23: =P23*0.8+4413.86837200027 -> 52697.626 | R23: =$Q$27/($Q$22+$Q$23+$Q$24+$Q$25)*Q23 -> 52697.626
A24: Самосвал Камаз | B24: Биогаз | C24: 20 смен | D24: 68934.4 | E24: =D24*0.6 -> 41360.64 | H24: 40068.12 | J24: =VLOOKUP(A24,'Декабрь факт'!$A$19:$J$23,8,0) -> 16696.98 | K24: =J24-I24 -> 16696.98 | L24: =VLOOKUP(A24,'Декабрь факт'!$A$19:$P$23,14,0) -> 0 | N24: =K24-L24 -> 16696.98 | O24: =E24 -> 41360.64 | P24: =N24+O24 -> 58057.62 | Q24: =P24*0.8+2474.1643023936 -> 48920.261 | R24: =$Q$27/($Q$22+$Q$23+$Q$24+$Q$25)*Q24 -> 48920.261
A25: Виброкаток | H25: 13057.2 | J25: =VLOOKUP(A25,'Декабрь факт'!$A$19:$J$23,8,0) -> 7940.8686 | K25: =J25-I25 -> 7940.8686 | L25: =VLOOKUP(A25,'Декабрь факт'!$A$19:$P$23,14,0) -> 0 | N25: =K25-L25 -> 7940.8686 | O25: 0 | P25: =N25+O25 -> 7940.8686 | Q25: =P25*0.8+456.991239517727 -> 6809.6861 | R25: =$Q$27/($Q$22+$Q$23+$Q$24+$Q$25)*Q25 -> 6809.6861
A26: Автокран XCMG | H26: 0 | I26: =VLOOKUP(A26,'Бюджет Декабрь'!$A$22:$F$25,6,0) -> 13516.56 | J26: =VLOOKUP(A26,'Декабрь факт'!$A$19:$J$23,8,0) -> 8220.233 | K26: =J26-I26 -> -5296.327 | L26: =VLOOKUP(A26,'Декабрь факт'!$A$19:$P$23,14,0) -> 0 | N26: =K26-L26 -> -5296.327 | O26: 0 | P26: =N26+O26 -> -5296.327
A27: Вресте по объекту Биогаз | D27: =SUM(D22:D24) -> 243320 | E27: =SUM(E22:E24) -> 145992 | F27: ='Декабрь факт'!R24 -> 73224.3 | G27: =E27+F27 -> 219216.3 | H27: =SUM(H22:H26) -> 237010.69 | I27: =SUM(I22:I26) -> 144305.76 | J27: =SUM(J22:J26) -> 172290.3 | K27: =SUM(K22:K26) -> 27984.536 | L27: =SUM(L22:L26) -> 0 | N27: =SUM(N22:N26) -> 27984.536 | O27: =SUM(O22:O26) -> 145992 | P27: =SUM(P22:P26) -> 173976.54 | Q27: =SUM(Q22:Q26) -> 154780.75 | R27: =SUM(R22:R26) -> 154780.75
R28: переплата
D29: =D10+D12+D16+D21+D27 -> 928251.68 | E29: =E10+E12+E16+E21+E27 -> 556951.01 | F29: =F10+F12+F16+F21+F27 -> 142653.06 | G29: =G10+G12+G16+G21+G27 -> 699604.07 | P29: 239946.84

Sheet Январь23 факт
A1: Техника | B1: Объект | C1: Стоимость за 1 час, грн | D1: План | F1: предоплата 60% | H1: Распределение предоплаты по факту отработанного на объектах | I1: Факт | K1: Сумма к взаиморасчетам, грн | L1: Оплаты с Индастриалбуд | Q1: Поступление на Индастриал от сторонних заказчиков, грн | R1: Сумма к взаиморасчетам с учетом движения ДС на р/с Индастриалбуд, грн
D2: кол-во часов | E2: сумма, грн | I2: Кол-во Часов | J2: Сума | L2: ЗП механизаторов с налогами, грн. | M2: Разрешительная документация, грн. | N2: Страховка, грн | O2: Топливо, грн | P2: вместе оплаченно, грн
A3: Телескоп 1 | B3: Староконстантинов | C3: =467.63 -> 467.63 | D3: =15*8 -> 120 | E3: =C3*D3 -> 56115.6 | H3: =$G$11/$J$11*J3 -> 84980.618 | I3: 152 | J3: =I3*C3 -> 71079.76 | L3: 11420.04 | O3: =26326.67-71.54 -> 26255.13 | P3: =SUM(L3:O3) -> 37675.17
A4: Телескоп 4 | B4: Староконстантинов | C4: 467.63 | D4: =15*8 -> 120 | E4: =C4*D4 -> 56115.6 | H4: =$G$11/$J$11*J4 -> 90012.365 | I4: 161 | J4: =I4*C4 -> 75288.43 | L4: 11919.12 | O4: =19904.01-71.54 -> 19832.47 | P4: =SUM(L4:O4) -> 31751.59
A5: Экскаватор JCB 220 | B5: Староконстантинов | C5: 995.97 | D5: =15*8 -> 120 | E5: =C5*D5 -> 119516.4 | H5: =$G$11/$J$11*J5 -> 0 | J5: =I5*C5 -> 0 | P5: =SUM(L5:O5) -> 0 | Q5: =76560+64380 -> 140940
A6: Автокран XCMG | B6: Староконстантинов | C6: 563.19 | D6: =15*8 -> 120 | E6: =C6*D6 -> 67582.8 | H6: =$G$11/$J$11*J6 -> 103693.04 | I6: 154 | J6: =I6*C6 -> 86731.26 | L6: 11350.94 | O6: =19082.01-71.54 -> 19010.47 | P6: =SUM(L6:O6) -> 30361.41
A7: МАЗ 264 | B7: Староконстантинов | C7: 355.37 | D7: =5*8 -> 40 | E7: =C7*D7 -> 14214.8 | H7: =$G$11/$J$11*J7 -> 0 | J7: =I7*C7 -> 0 | P7: =SUM(L7:O7) -> 0
A8: Клинцы | B8: Староконстантинов | C8: 490.46 | E8: =C8*D8 -> 0 | H8: =$G$11/$J$11*J8 -> 19936.845 | I8: =24+10 -> 34 | J8: =I8*C8 -> 16675.64 | L8: =11590/(I8+I19)*I8 -> 2962.8571 | N8: =3074/(I8+I19)*I8 -> 785.83459 | O8: =21101.72/(I8+I19)*I8-71.54 -> 5322.8847 | P8: =SUM(L8:O8) -> 9071.5764
A9: КАМАЗ | B9: Староконстантинов | C9: 430.84 | E9: =C9*D9 -> 0 | H9: =$G$11/$J$11*J9 -> 0 | J9: =I9*C9 -> 0 | P9: =SUM(L9:O9) -> 0
A10: Виброкаток | B10: Староконстантинов | C10: 544.05 | E10: =C10*D10 -> 0 | H10: =$G$11/$J$11*J10 -> 0 | J10: =I10*C10 -> 0 | P10: =SUM(L10:O10) -> 0
A11: Вместе по объекту Староконстантинов | E11: =SUM(E3:E10) -> 313545.2 | F11: ='Бюджет Январь 23'!E10 -> 188127.12 | G11: =F11+'Декабрь факт'!S10 -> 298622.86 | H11: =SUM(H3:H9) -> 298622.86 | J11: =SUM(J3:J10) -> 249775.09 | K11: =IF(F11<0,F11+J11,J11-F11) -> 61647.97 | P11: =SUM(P3:P10) -> 108859.75 | Q11: =SUM(Q3:Q10) -> 140940 | R11: =K11-P11+Q11 -> 93728.224
A12: Телескоп 2 | B12: Приднепровский МЕТАЛЛ | C12: 467.63 | E12: =C12*D12 -> 0 | J12: =C12*I12 -> 0 | P12: =SUM(L12:O12) -> 0
A13: МАЗ 265 | B13: Приднепровский МЕТАЛЛ | C13: 355.37 | E13: =C13*D13 -> 0 | I13: 4 | J13: =C13*I13 -> 1421.48 | L13: =6655.82/(I13+I28)*I13 -> 313.21506 | O13: =12480/(I13+I28)*I13-71.54 -> 515.75412 | P13: =SUM(L13:O13) -> 828.96918
A14: Экскаватор JCB 2013 | B14: Приднепровский МЕТАЛЛ | C14: 496.93 | E14: =C14*D14 -> 0 | J14: =C14*I14 -> 0 | P14: =SUM(L14:O14) -> 0
A15: Вместе по объекту Приднепровский МЕТАЛЛ | E15: =SUM(E12:E14) -> 0 | F15: ='Бюджет Январь 23'!G12 -> -21104.089 | G15: =E15+'Декабрь факт'!R13 -> -21104.089 | H15: =SUM(H12:H13) -> 0 | J15: =SUM(J12:J14) -> 1421.48 | K15: =IF(F15<0,F15+J15,J15-F15) -> -19682.609 | P15: =SUM(P12:P14) -> 828.96918 | Q15: =SUM(Q12:Q14) -> 0 | R15: =K15-P15+Q15 -> -20511.579
A16: Телескоп 5 | B16: Ретал | C16: 467.63 | D16: =20*8 -> 160 | E16: =C16*D16 -> 74820.8 | H16: =$G$20/$J$20*J16 -> 50558.873 | I16: 166 | J16: =C16*I16 -> 77626.58 | L16: 12053.6 | O16: =20950.78-71.54 -> 20879.24 | P16: =SUM(L16:O16) -> 32932.84
A17: Экскаватор JCB 2008 | B17: Ретал | C17: 496.93 | D17: =12*8 -> 96 | E17: =C17*D17 -> 47705.28 | H17: =$G$20/$J$20*J17 -> 47900.921 | I17: 148 | J17: =C17*I17 -> 73545.64 | L17: 12053.6 | O17: =31883.08-71.54 -> 31811.54 | P17: =SUM(L17:O17) -> 43865.14
A18: Haulotte | B18: Ретал | C18: 802.86 | D18: =20 -> 20 | E18: =C18*D18 -> 16057.2 | H18: =$G$20/$J$20*J18 -> 10458.195 | I18: 20 | J18: =C18*I18 -> 16057.2 | P18: =SUM(L18:O18) -> 0
A19: Клинцы | B19: Ретал | C19: 490.46 | D19: =20*8 -> 160 | E19: =C19*D19 -> 78473.6 | H19: =$G$20/$J$20*J19 -> 31624.65 | I19: 99 | J19: =C19*I19 -> 48555.54 | L19: =11590/(I8+I19)*I19 -> 8627.1429 | N19: =3074/(I19+I8)*I19 -> 2288.1654 | O19: =21101.72/(I19+I8)*I19-71.54 -> 15635.755 | P19: =SUM(L19:O19) -> 26551.064
A20: Вместе по объекту Ретал | E20: =SUM(E16:E19) -> 217056.88 | F20: ='Бюджет Январь 23'!E21 -> 130234.13 | G20: =F20+'Декабрь факт'!S18 -> 140542.64 | H20: =SUM(H16:H19) -> 140542.64 | J20: =SUM(J16:J19) -> 215784.96 | K20: =IF(F20<0,F20+J20,J20-F20) -> 85550.832 | P20: =SUM(P16:P19) -> 103349.04 | Q20: =SUM(Q16:Q19) -> 0 | R20: =K20-P20+Q20 -> -17798.212
A21: Ротор Пегасус | B21: Биогаз | C21: 592.98 | D21: =20*8 -> 160 | E21: =C21*D21 -> 94876.8 | H21: =$G$26/$J$26*J21 -> 45522.179 | I21: 83 | J21: =C21*I21 -> 49217.34 | L21: 11590 | O21: =23830-71.54 -> 23758.46 | P21: =SUM(L21:O21) -> 35348.46
A22: Виброкаток | B22: Биогаз | C22: 544.05 | E22: =C22*D22 -> 0 | H22: =$G$26/$J$26*J22 -> 12076.886 | I22: 24 | J22: =C22*I22 -> 13057.2 | L22: 1328.23 | P22: =SUM(L22:O22) -> 1328.23
A23: КАМАЗ | B23: Биогаз | C23: 430.84 | D23: =20*8 -> 160 | E23: =C23*D23 -> 68934.4 | H23: =$G$26/$J$26*J23 -> 37059.869 | I23: 93 | J23: =C23*I23 -> 40068.12 | L23: 7100.86 | O23: =27127.94-71.54 -> 27056.4 | P23: =SUM(L23:O23) -> 34157.26
A24: Экскаватор JCB 2007 | B24: Биогаз | C24: 496.93 | D24: =25*8 -> 200 | E24: =C24*D24-19877.2 -> 79508.8 | H24: =$G$26/$J$26*J24 -> 124557.37 | I24: 271 | J24: =C24*I24 -> 134668.03 | L24: 12053.6 | O24: =30910.53-71.54 -> 30838.99 | P24: =SUM(L24:O24) -> 42892.59
A25: Автокран XCMG | B25: Биогаз | C25: 563.19 | E25: =C25*D25 -> 0 | H25: =$G$26/$J$26*J25 -> 0 | J25: =C25*I25 -> 0 | P25: =SUM(L25:O25) -> 0
A26: Вресте по объекту Биогаз | E26: =SUM(E21:E25) -> 243320 | F26: ='Бюджет Январь 23'!E27 -> 145992 | G26: =F26+'Декабрь факт'!S24 -> 219216.3 | H26: =SUM(H21:H25) -> 219216.3 | J26: =SUM(J21:J25) -> 237010.69 | K26: =IF(F26<0,F26+J26,J26-F26) -> 91018.69 | P26: =SUM(P21:P25) -> 113726.54 | Q26: =SUM(Q21:Q25) -> 0 | R26: =K26-P26+Q26 -> -22707.85
A27: Экскаватор JCB 2013 | B27: МЕЗ Сети | C27: 496.93 | D27: =20*8 -> 160 | E27: =C27*D27 -> 79508.8 | H27: =$G$30/$J$30*J27 -> 37819.692 | I27: 223 | J27: =C27*I27 -> 110815.39 | L27: 12053.6 | O27: =35721.08-71.54 -> 35649.54 | P27: =SUM(L27:O27) -> 47703.14
A28: МАЗ 265 | B28: МЕЗ Сети | C28: 355.37 | E28: =C28*D28 -> 0 | H28: =$G$30/$J$30*J28 -> 9823.8944 | I28: 81 | J28: =C28*I28 -> 28784.97 | L28: =6655.82/(I13+I28)*I28 -> 6342.6049 | O28: =12480/(I13+I28)*I28-71.54 -> 11821.166 | P28: =SUM(L28:O28) -> 18163.771
A29: Телескоп 2 | B29: МЕЗ Сети | C29: 467.63 | D29: =20*8 -> 160 | E29: =C29*D29 -> 74820.8 | H29: =$G$30/$J$30*J29 -> 14682.773 | I29: 92 | J29: =C29*I29 -> 43021.96 | L29: 11741.31 | O29: =14708.71-71.54 -> 14637.17 | P29: =SUM(L29:O29) -> 26378.48
A30: Вресте по объекту МЕЗ СЕТИ | E30: =SUM(E27:E29) -> 154329.6 | F30: ='Бюджет Январь 23'!E16 -> 92597.76 | G30: =F30+'Декабрь факт'!R28 -> 62326.359 | H30: =SUM(H27:H29) -> 62326.359 | J30: =SUM(J27:J29) -> 182622.32 | K30: =IF(F30<0,F30+J30,J30-F30) -> 90024.56 | P30: =SUM(P27:P29) -> 92245.391 | Q30: =SUM(Q27:Q29) -> 0 | R30: =K30-P30+Q30 -> -2220.8308
A31: Главный офис | B31: ЦО Спецтехника | J31: 50000 | P31: =SUM(L31:O31) -> 0
E33: =E26+E20+E15+E11+E30 -> 928251.68 | F33: =F11+F15+F20+F26+F30 -> 535846.92 | G33: =G30+G26+G20+G15+G11 -> 699604.07 | H33: =H11+G15+H20+H26+H30 -> 699604.07 | J33: =J11+J15+J20+J26+J30 -> 886614.54 | K33: =K11+K15+K20+K26+K30 -> 308559.44 | L33: =SUM(L3:L31) -> 132910.72 | O33: =SUM(O3:O31) -> 283024.97 | P33: =P11+P15+P20+P26+P30 -> 419009.69 | Q33: =Q11+Q15+Q20+Q26+Q30 -> 140940 | R33: =R11+R15+R20+R26+R30 -> 30489.753
E34: =E33-'Бюджет Январь 23'!D29 -> 0 | H34: =F33+'Декабрь факт'!S31-G15 -> 699604.07 | J34: =886614.54-J33 -> 0
R35: =J33-F33-P33+Q33 -> 72697.931
A37: Работа в аренде у других предприятий
A38: Экскаватор JCB 220 | B38: Староконстантинов | C38: 995.97 | D38: =15*8 -> 120 | E38: =C38*D38 -> 119516.4 | I38: 84 | J38: =I38*C38 -> 83661.48 | L38: 12053.6 | O38: =36974.5-71.54 -> 36902.96 | P38: =SUM(L38:O38) -> 48956.56 | Q38: =76560+64380 -> 140940 | T38: =Q38-P38 -> 91983.44

Sheet Бюджет Февраль 23
A1: Техника | B1: Объект | C1: Кол-во смен | D1: Ст-сть за 1 час, грн | E1: сумма за месяц, грн | F1: предоплата 60%, грн | G1: Сумма к взаиморасчетам по Январю, грн | H1: Незарегестрированный НДС | I1: Итого, сумма предоплаты за Февраль 2023, грн. | J1: п/оплата январь | K1: Факт январь | L1: факт-пред | M1: Оплаты с индастриал | N1: ЛЕВАК | O1: Сумма к взаиморасчетам | P1: пр/оплата февраль | Q1: Итого предоплат за февраль | R1: 0.8 | S1: Цифра для распределения в казне
A2: Телескоп 1 | B2: Староконстантинов | C2: 25 | D2: 467.63 | E2: =C2*8*D2 -> 93526 | F2: =E2*0.6 -> 56115.6 | J2: =VLOOKUP(A2,'Бюджет Январь 23'!$A:$G,5,FALSE) -> 33669.36 | K2: =VLOOKUP(A2,'Январь23 факт'!$A:$J,8,FALSE) -> 84980.618 | L2: =K2-J2 -> 51311.258 | M2: =VLOOKUP(A2,'Январь23 факт'!$A:$R,14,FALSE) -> 0 | O2: =L2-M2+N2 -> 51311.258 | P2: =F2 -> 56115.6
A3: Телескоп 4 | B3: Староконстантинов | C3: 25 | D3: 467.63 | E3: =C3*8*D3 -> 93526 | F3: =E3*0.6 -> 56115.6 | J3: =VLOOKUP(A3,'Бюджет Январь 23'!$A:$G,5,FALSE) -> 33669.36 | K3: =VLOOKUP(A3,'Январь23 факт'!$A:$J,8,FALSE) -> 90012.365 | L3: =K3-J3 -> 56343.005 | M3: =VLOOKUP(A3,'Январь23 факт'!$A:$R,14,FALSE) -> 0 | O3: =L3-M3+N3 -> 56343.005 | P3: =F3 -> 56115.6
A4: Экскаватор JCB 220 | B4: Староконстантинов | C4: 10 | D4: 995.97 | E4: =C4*8*D4 -> 79677.6 | F4: =E4*0.6 -> 47806.56 | J4: =VLOOKUP(A4,'Бюджет Январь 23'!$A:$G,5,FALSE) -> 71709.84 | K4: =VLOOKUP(A4,'Январь23 факт'!$A:$J,8,FALSE) -> 0 | L4: =K4-J4 -> -71709.84 | M4: =VLOOKUP(A4,'Январь23 факт'!$A:$R,14,FALSE) -> 0 | O4: =L4-M4+N4 -> -71709.84 | P4: =F4 -> 47806.56
A5: МАЗ 264 | B5: Староконстантинов | C5: 10 | D5: 355.37 | E5: =C5*8*D5 -> 28429.6 | F5: =E5*0.6 -> 17057.76 | J5: =VLOOKUP(A5,'Бюджет Январь 23'!$A:$G,5,FALSE) -> 8528.88 | K5: =VLOOKUP(A5,'Январь23 факт'!$A:$J,8,FALSE) -> 0 | L5: =K5-J5 -> -8528.88 | M5: =VLOOKUP(A5,'Январь23 факт'!$A:$R,14,FALSE) -> 0 | O5: =L5-M5+N5 -> -8528.88 | P5: =F5 -> 17057.76
A6: Клинцы | B6: Староконстантинов | C6: 25 | D6: 490.46 | E6: =C6*8*D6 -> 98092 | F6: =E6*0.6 -> 58855.2 | J6: =VLOOKUP(A6,'Бюджет Январь 23'!$A:$G,5,FALSE) -> 0 | K6: =VLOOKUP(A6,'Январь23 факт'!$A:$J,8,FALSE) -> 19936.845 | L6: =K6-J6 -> 19936.845 | M6: =VLOOKUP(A6,'Январь23 факт'!$A:$R,14,FALSE) -> 785.83459 | O6: =L6-M6+N6 -> 19151.011 | P6: =F6 -> 58855.2
A7: Автокран XCMG | B7: Староконстантинов | C7: 25 | D7: 563.19 | E7: =C7*8*D7 -> 112638 | F7: =E7*0.6 -> 67582.8 | J7: =VLOOKUP(A7,'Бюджет Январь 23'!$A:$G,5,FALSE) -> 40549.68 | K7: =VLOOKUP(A7,'Январь23 факт'!$A:$J,8,FALSE) -> 103693.04 | L7: =K7-J7 -> 63143.355 | M7: =VLOOKUP(A7,'Январь23 факт'!$A:$R,14,FALSE) -> 0 | O7: =L7-M7+N7 -> 63143.355 | P7: =F7 -> 67582.8
A8: Вместе по объекту Староконстантинов | E8: =SUM(E2:E7) -> 505889.2 | F8: =SUM(F2:F7) -> 303533.52 | G8: ='Январь23 факт'!R11 -> 93728.224 | H8: -31187.85 | I8: =F8+G8+H8 -> 366073.89 | J8: =SUM(J2:J7) -> 188127.12 | K8: =SUM(K2:K7) -> 298622.86 | L8: =K8-J8 -> 110495.74 | M8: =SUM(M2:M7) -> 785.83459 | N8: =SUM(N2:N7) -> 0 | O8: =L8-M8+N8 -> 109709.91 | P8: =SUM(P2:P7) -> 303533.52 | Q8: =SUM(Q2:Q7) -> 0 | R8: =SUM(R2:R7) -> 0 | S8: =SUM(S2:S7) -> 0
E9: =C9*8*D9 -> 0 | F9: =E9*0.6 -> 0 | L9: =K9-J9 -> 0 | O9: =L9-M9+N9 -> 0 | P9: =F9 -> 0
A10: Вместе по объекту Приднепровский МЕТАЛЛ | E10: =E9 -> 0 | F10: =F9 -> 0 | G10: ='Январь23 факт'!R15 -> -20511.579 | I10: =F10+G10+H10 -> -20511.579 | L10: =K10-J10 -> 0 | O10: =L10-M10+N10 -> 0 | P10: =F10 -> 0
A11: Экскаватор JCB 2013 | B11: МЭЗ СЕТИ | C11: 24 | D11: 496.93 | E11: =C11*8*D11 -> 95410.56 | F11: =E11*0.6 -> 57246.336 | J11: =VLOOKUP(A11,'Бюджет Январь 23'!$A:$G,5,FALSE) -> 47705.28 | K11: =VLOOKUP(A11,'Январь23 факт'!$A:$J,8,FALSE) -> 0 | L11: =K11-J11 -> -47705.28 | M11: =VLOOKUP(A11,'Январь23 факт'!$A:$R,14,FALSE) -> 0 | O11: =L11-M11+N11 -> -47705.28 | P11: =F11 -> 57246.336
A12: Телескоп 2 | B12: МЭЗ СЕТИ | C12: 24 | D12: 467.63 | E12: =C12*8*D12 -> 89784.96 | F12: =E12*0.6 -> 53870.976 | J12: =VLOOKUP(A12,'Бюджет Январь 23'!$A:$G,5,FALSE) -> 44892.48 | K12: =VLOOKUP(A12,'Январь23 факт'!$A:$J,8,FALSE) -> 0 | L12: =K12-J12 -> -44892.48 | M12: =VLOOKUP(A12,'Январь23 факт'!$A:$R,14,FALSE) -> 0 | O12: =L12-M12+N12 -> -44892.48 | P12: =F12 -> 53870.976
A13: МАЗ 265 | B13: МЭЗ СЕТИ | C13: 24 | D13: 355.37 | E13: =C13*8*D13 -> 68231.04 | F13: =E13*0.6 -> 40938.624 | J13: =VLOOKUP(A13,'Бюджет Январь 23'!$A:$G,5,FALSE) -> 0 | K13: =VLOOKUP(A13,'Январь23 факт'!$A:$J,8,FALSE) -> 0 | L13: =K13-J13 -> 0 | M13: =VLOOKUP(A13,'Январь23 факт'!$A:$R,14,FALSE) -> 0 | O13: =L13-M13+N13 -> 0 | P13: =F13 -> 40938.624
A14: Вместе по объекту МЭЗ СЕТИ | E14: =SUM(E11:E13) -> 253426.56 | F14: =SUM(F11:F13) -> 152055.94 | G14: ='Январь23 факт'!R30 -> -2220.8308 | I14: =F14+G14+H14 -> 149835.11 | J14: =SUM(J11:J13) -> 92597.76 | K14: =SUM(K11:K13) -> 0 | L14: =K14-J14 -> -92597.76 | M14: =SUM(M11:M13) -> 0 | N14: =SUM(N11:N13) -> 0 | O14: =L14-M14+N14 -> -92597.76 | P14: =SUM(P11:P13) -> 152055.94 | Q14: =SUM(Q11:Q13) -> 0 | R14: =SUM(R11:R13) -> 0 | S14: =SUM(S11:S13) -> 0
A15: Телескоп 5 | B15: Ретал | C15: 25 | D15: 467.63 | E15: =C15*8*D15 -> 93526 | F15: =E15*0.6 -> 56115.6 | J15: =VLOOKUP(A15,'Бюджет Январь 23'!$A:$G,5,FALSE) -> 44892.48 | K15: =VLOOKUP(A15,'Январь23 факт'!$A:$J,8,FALSE) -> 50558.873 | L15: =K15-J15 -> 5666.3932 | M15: =VLOOKUP(A15,'Январь23 факт'!$A:$R,14,FALSE) -> 0 | O15: =L15-M15+N15 -> 5666.3932 | P15: =F15 -> 56115.6
A16: Экскаватор JCB 2008 | B16: Ретал | C16: 25 | D16: 496.93 | E16: =C16*8*D16 -> 99386 | F16: =E16*0.6 -> 59631.6 | J16: =VLOOKUP(A16,'Бюджет Январь 23'!$A:$G,5,FALSE) -> 28623.168 | K16: =VLOOKUP(A16,'Январь23 факт'!$A:$J,8,FALSE) -> 47900.921 | L16: =K16-J16 -> 19277.753 | M16: =VLOOKUP(A16,'Январь23 факт'!$A:$R,14,FALSE) -> 0 | O16: =L16-M16+N16 -> 19277.753 | P16: =F16 -> 59631.6
A17: Haulotte | B17: Ретал | C17: 20 | D17: 802.86 | E17: =C17*D17 -> 16057.2 | F17: =E17*0.6 -> 9634.32 | J17: =VLOOKUP(A17,'Бюджет Январь 23'!$A:$G,5,FALSE) -> 9634.32 | K17: =VLOOKUP(A17,'Январь23 факт'!$A:$J,8,FALSE) -> 10458.195 | L17: =K17-J17 -> 823.87535 | M17: =VLOOKUP(A17,'Январь23 факт'!$A:$R,14,FALSE) -> 0 | O17: =L17-M17+N17 -> 823.87535 | P17: =F17 -> 9634.32
A18: Клинцы | B18: Ретал | E18: =C18*8*D18 -> 0 | F18: =E18*0.6 -> 0 | J18: 47084.16 | K18: =VLOOKUP(A18,'Январь23 факт'!$A:$J,8,FALSE) -> 19936.845 | L18: =K18-J18 -> -27147.315 | M18: 26551.064 | O18: =L18-M18+N18 -> -53698.378 | P18: =F18 -> 0
A19: Вместе по объекту Ретал | E19: =SUM(E15:E18) -> 208969.2 | F19: =SUM(F15:F18) -> 125381.52 | G19: ='Январь23 факт'!R20 -> -17798.212 | H19: -18739.02 | I19: =F19+G19+H19 -> 88844.288 | J19: =SUM(J15:J18) -> 130234.13 | K19: =SUM(K15:K18) -> 128854.84 | L19: =K19-J19 -> -1379.2929 | M19: =SUM(M15:M18) -> 26551.064 | N19: =SUM(N15:N18) -> 0 | O19: =L19-M19+N19 -> -27930.357 | P19: =SUM(P15:P18) -> 125381.52 | Q19: =SUM(Q15:Q18) -> 0 | R19: =SUM(R15:R18) -> 0 | S19: =SUM(S15:S18) -> 0
A20: Ротор Пегасус | B20: Биогаз | C20: 14 | D20: 592.98 | E20: =C20*8*D20 -> 66413.76 | F20: =E20*0.6 -> 39848.256 | J20: =VLOOKUP(A20,'Бюджет Январь 23'!$A:$G,5,FALSE) -> 56926.08 | K20: =VLOOKUP(A20,'Январь23 факт'!$A:$J,8,FALSE) -> 45522.179 | L20: =K20-J20 -> -11403.901 | M20: =VLOOKUP(A20,'Январь23 факт'!$A:$R,14,FALSE) -> 0 | O20: =L20-M20+N20 -> -11403.901 | P20: =F20 -> 39848.256
